Workbook

Sheet Odometro-Kilometraje
A1: Control Contador Kilometraje de Trenes
B2: 45383 | C2: 45384 | D2: 45385 | E2: 45386 | F2: 45387 | G2: 45388 | H2: 45389 | I2: 45390 | J2: 45391 | K2: 45392 | L2: 45393 | M2: 45394 | N2: 45395 | O2: 45396 | P2: 45397 | Q2: 45398 | R2: 45399 | S2: 45400 | T2: 45401 | U2: 45402 | V2: 45403 | W2: 45404 | X2: 45405 | Y2: 45406 | Z2: 45407 | AA2: 45408 | AB2: 45409 | AC2: 45410 | AD2: 45411 | AE2: 45412
B3: Contador | C3: Contador | D3: Contador | E3: Contador | F3: Contador | G3: Contador | H3: Contador | I3: Contador | J3: Contador | K3: Contador | L3: Contador | M3: Contador | N3: Contador | O3: Contador | P3: Contador | Q3: Contador | R3: Contador | S3: Contador | T3: Contador | U3: Contador | V3: Contador | W3: Contador | X3: Contador | Y3: Contador | Z3: Contador | AA3: Contador | AB3: Contador | AC3: Contador | AD3: Contador | AE3: Contador
A4: Tren | B4: Odómetro | C4: Odómetro | D4: Odómetro | E4: Odómetro | F4: Odómetro | G4: Odómetro | H4: Odómetro | I4: Odómetro | J4: Odómetro | K4: Odómetro | L4: Odómetro | M4: Odómetro | N4: Odómetro | O4: Odómetro | P4: Odómetro | Q4: Odómetro | R4: Odómetro | S4: Odómetro | T4: Odómetro | U4: Odómetro | V4: Odómetro | W4: Odómetro | X4: Odómetro | Y4: Odómetro | Z4: Odómetro | AA4: Odómetro | AB4: Odómetro | AC4: Odómetro | AD4: Odómetro | AE4: Odómetro
A5: M01 | B5: 1886814 | C5: 1887077 | D5: 1887168 | E5: 1887687 | F5: 1887969 | G5: 1887969 | H5: 1887969 | I5: 1888303 | J5: 1888514 | K5: 1888966 | L5: 1889316 | M5: 1889767 | N5: 1889767 | O5: 1889767 | P5: 1889982 | Q5: 1890304 | R5: 1890797 | S5: 1891266 | T5: 1891718 | U5: 1892151 | V5: 1892540 | W5: 1892948 | X5: 1893247 | Y5: 1893442 | Z5: 1893875 | AA5: 1894221 | AB5: 1894653 | AC5: 1895084 | AD5: 1895688 | AE5: 1896121
A6: M02 | B6: 1869918 | C6: 1870138 | D6: 1870590 | E6: 1870843 | F6: 1871210 | G6: 1871210 | H6: 1871210 | I6: 1871749 | J6: 1872311 | K6: 1872613 | L6: 1872791 | M6: 1873097 | N6: 1873097 | O6: 1873141 | P6: 1873659 | Q6: 1873919 | R6: 1874370 | S6: 1874908 | T6: 1874995 | U6: 1874995 | V6: 1874996 | W6: 1875393 | X6: 1875784 | Y6: 1876067 | Z6: 1876501 | AA6: 1876783 | AB6: 1877261 | AC6: 1877304 | AD6: 1877823 | AE6: 1878041
A7: M03 | B7: 1942377 | C7: 1942895 | D7: 1943285 | E7: 1943845 | F7: 1944363 | G7: 1944365 | H7: 1944544 | I7: 1945080 | J7: 1945408 | K7: 1945809 | L7: 1946195 | M7: 1946559 | N7: 1946561 | O7: 1946563 | P7: 1946996 | Q7: 1947560 | R7: 1948035 | S7: 1948405 | T7: 1948590 | U7: 1948590 | V7: 1948590 | W7: 1949109 | X7: 1949354 | Y7: 1949634 | Z7: 1949914 | AA7: 1950363 | AB7: 1950363 | AC7: 1950363 | AD7: 1950730 | AE7: 1951250
A8: M04 | B8: 1947098 | C8: 1947661 | D8: 1948136 | E8: 1948698 | F8: 1949192 | G8: 1949192 | H8: 1949192 | I8: 1949682 | J8: 1950133 | K8: 1950671 | L8: 1951122 | M8: 1951487 | N8: 1952009 | O8: 1952485 | P8: 1952979 | Q8: 1953191 | R8: 1953360 | S8: 1953626 | T8: 1954146 | U8: 1954664 | V8: 1955140 | W8: 1955634 | X8: 1955932 | Y8: 1956386 | Z8: 1956820 | AA8: 1957168 | AB8: 1957514 | AC8: 1957947 | AD8: 1958483 | AE8: 1958850
A9: M05 | B9: 1843964 | C9: 1844262 | D9: 1844560 | E9: 1844752 | F9: 1845182 | G9: 1845663 | H9: 1846095 | I9: 1846587 | J9: 1847177 | K9: 1847569 | L9: 1847876 | M9: 1848269 | N9: 1848314 | O9: 1848314 | P9: 1848832 | Q9: 1849025 | R9: 1849478 | S9: 1850039 | T9: 1850298 | U9: 1850342 | V9: 1850345 | W9: 1850863 | X9: 1851317 | Y9: 1851502 | Z9: 1851603 | AA9: 1851798 | AB9: 1852275 | AC9: 1852318 | AD9: 1852665 | AE9: 1853120
A10: M06 | B10: 1962982 | C10: 1963437 | D10: 1963980 | E10: 1964435 | F10: 1964736 | G10: 1964736 | H10: 1964736 | I10: 1965076 | J10: 1965532 | K10: 1965969 | L10: 1966492 | M10: 1967102 | N10: 1967539 | O10: 1967932 | P10: 1968259 | Q10: 1968802 | R10: 1969329 | S10: 1969770 | T10: 1970227 | U10: 1970227 | V10: 1970227 | W10: 1970599 | X10: 1971122 | Y10: 1971384 | Z10: 1971907 | AA10: 1972361 | AB10: 1972361 | AC10: 1972361 | AD10: 1972690 | AE10: 1972908
A11: M07 | B11: 1988250 | C11: 1988746 | D11: 1989285 | E11: 1989721 | F11: 1990072 | G11: 1990592 | H11: 1991068 | I11: 1991546 | J11: 1992069 | K11: 1992520 | L11: 1992932 | M11: 1993274 | N11: 1993751 | O11: 1994145 | P11: 1994751 | Q11: 1995203 | R11: 1995709 | S11: 1996229 | T11: 1996533 | U11: 1997012 | V11: 1997446 | W11: 1997966 | X11: 1998282 | Y11: 1998607 | Z11: 1999084 | AA11: 1999470 | AB11: 1999821 | AC11: 2000301 | AD11: 2000712 | AE11: 2000927
A12: M08 | B12: 1897666 | C12: 1898136 | D12: 1898655 | E12: 1899003 | F12: 1899395 | G12: 1899831 | H12: 1899875 | I12: 1900442 | J12: 1900850 | K12: 1901253 | L12: 1901818 | M12: 1902380 | N12: 1902901 | O12: 1903335 | P12: 1903512 | Q12: 1903963 | R12: 1904326 | S12: 1904545 | T12: 1905066 | U12: 1905542 | V12: 1905585 | W12: 1905848 | X12: 1906299 | Y12: 1906667 | Z12: 1906947 | AA12: 1907313 | AB12: 1907400 | AC12: 1907406 | AD12: 1907842 | AE12: 1908295
A13: M09 | B13: 1879619 | C13: 1879968 | D13: 1880361 | E13: 1880856 | F13: 1881153 | G13: 1881153 | H13: 1881153 | I13: 1881602 | J13: 1882078 | K13: 1882529 | L13: 1882742 | M13: 1883212 | N13: 1883212 | O13: 1883212 | P13: 1883625 | Q13: 1884019 | R13: 1884388 | S13: 1884654 | T13: 1884868 | U13: 1884868 | V13: 1884868 | W13: 1885083 | X13: 1885386 | Y13: 1885671 | Z13: 1885954 | AA13: 1886081 | AB13: 1886081 | AC13: 1886081 | AD13: 1886383 | AE13: 1886642
A14: M10 | B14: 1960905 | C14: 1961274 | D14: 1961657 | E14: 1962246 | F14: 1962699 | G14: 1962699 | H14: 1962699 | I14: 1962885 | J14: 1963339 | K14: 1963684 | L14: 1964138 | M14: 1964502 | N14: 1964934 | O14: 1965366 | P14: 1965715 | Q14: 1966015 | R14: 1966296 | S14: 1966481 | T14: 1967019 | U14: 1967105 | V14: 1967106 | W14: 1967543 | X14: 1967893 | Y14: 1968458 | Z14: 1968695 | AA14: 1968976 | AB14: 1969322 | AC14: 1969325 | AD14: 1969728 | AE14: 1970265
A15: M11 | B15: 1971176 | C15: 1971646 | D15: 1971944 | E15: 1972137 | F15: 1972229 | G15: 1972229 | H15: 1972406 | I15: 1972601 | J15: 1973139 | K15: 1973658 | L15: 1974091 | M15: 1974180 | N15: 1974232 | O15: 1974233 | P15: 1974672 | Q15: 1975278 | R15: 1975797 | S15: 1976316 | T15: 1976770 | U15: 1976770 | V15: 1976770 | W15: 1976966 | X15: 1977056 | Y15: 1977508 | Z15: 1977978 | AA15: 1978413 | AB15: 1978413 | AC15: 1978413 | AD15: 1978625 | AE15: 1978861
A16: M12 | B16: 1810154 | C16: 1810590 | D16: 1811152 | E16: 1811456 | F16: 1812017 | G16: 1812060 | H16: 1812534 | I16: 1812752 | J16: 1812974 | K16: 1813187 | L16: 1813637 | M16: 1814021 | N16: 1814498 | O16: 1814929 | P16: 1815163 | Q16: 1815471 | R16: 1815989 | S16: 1816360 | T16: 1816641 | U16: 1817076 | V16: 1817077 | W16: 1817637 | X16: 1817984 | Y16: 1818390 | Z16: 1818885 | AA16: 1819361 | AB16: 1819838 | AC16: 1819887 | AD16: 1820316 | AE16: 1820595
... A39: XM35 | B39: 572257 | C39: 572606 | D39: 572780 | E39: 572976 | F39: 573145 | G39: 573605 | H39: 573864 | I39: 574296 | J39: 574680 | K39: 575131 | L39: 575409 | M39: 575776 | N39: 575776 | O39: 575776 | P39: 576482 | Q39: 576933 | R39: 577213 | S39: 577578 | T39: 578046 | U39: 578046 | V39: 578046 | W39: 578327 | X39: 578779 | Y39: 579139 | Z39: 579614 | AA39: 580064 | AB39: 580064 | AC39: 580064 | AD39: 580515 | AE39: 580967
A41: Kilometraje Diario Recorrido
B42: 45383 | C42: 45384 | D42: 45385 | E42: 45386 | F42: 45387 | G42: 45388 | H42: 45389 | I42: 45390 | J42: 45391 | K42: 45392 | L42: 45393 | M42: 45394 | N42: 45395 | O42: 45396 | P42: 45397 | Q42: 45398 | R42: 45399 | S42: 45400 | T42: 45401 | U42: 45402 | V42: 45403 | W42: 45404 | X42: 45405 | Y42: 45406 | Z42: 45407 | AA42: 45408 | AB42: 45409 | AC42: 45410 | AD42: 45411 | AE42: 45412
B43: Kilometraje | C43: Kilometraje | D43: Kilometraje | E43: Kilometraje | F43: Kilometraje | G43: Kilometraje | H43: Kilometraje | I43: Kilometraje | J43: Kilometraje | K43: Kilometraje | L43: Kilometraje | M43: Kilometraje | N43: Kilometraje | O43: Kilometraje | P43: Kilometraje | Q43: Kilometraje | R43: Kilometraje | S43: Kilometraje | T43: Kilometraje | U43: Kilometraje | V43: Kilometraje | W43: Kilometraje | X43: Kilometraje | Y43: Kilometraje | Z43: Kilometraje | AA43: Kilometraje | AB43: Kilometraje | AC43: Kilometraje | AD43: Kilometraje | AE43: Kilometraje
A44: Tren | B44: Diario | C44: Diario | D44: Diario | E44: Diario | F44: Diario | G44: Diario | H44: Diario | I44: Diario | J44: Diario | K44: Diario | L44: Diario | M44: Diario | N44: Diario | O44: Diario | P44: Diario | Q44: Diario | R44: Diario | S44: Diario | T44: Diario | U44: Diario | V44: Diario | W44: Diario | X44: Diario | Y44: Diario | Z44: Diario | AA44: Diario | AB44: Diario | AC44: Diario | AD44: Diario | AE44: Diario
A45: M01 | B45: 436 | C45: =C5-B5 -> 263 | D45: =D5-C5 -> 91 | E45: =E5-D5 -> 519 | F45: =F5-E5 -> 282 | G45: =G5-F5 -> 0 | H45: =H5-G5 -> 0 | I45: =I5-H5 -> 334 | J45: =J5-I5 -> 211 | ... AE45: =AE5-AD5 -> 433
A46: M02 | B46: 581 | C46: =C6-B6 -> 220 | D46: =D6-C6 -> 452 | E46: =E6-D6 -> 253 | F46: =F6-E6 -> 367 | G46: =G6-F6 -> 0 | H46: =H6-G6 -> 0 | I46: =I6-H6 -> 539 | J46: =J6-I6 -> 562 | ... AE46: =AE6-AD6 -> 218
A47: M03 | B47: 433 | C47: =C7-B7 -> 518 | D47: =D7-C7 -> 390 | E47: =E7-D7 -> 560 | F47: =F7-E7 -> 518 | G47: =G7-F7 -> 2 | H47: =H7-G7 -> 179 | I47: =I7-H7 -> 536 | J47: =J7-I7 -> 328 | ... AE47: =AE7-AD7 -> 520
A48: M04 | B48: 291 | C48: =C8-B8 -> 563 | D48: =D8-C8 -> 475 | E48: =E8-D8 -> 562 | F48: =F8-E8 -> 494 | G48: =G8-F8 -> 0 | H48: =H8-G8 -> 0 | I48: =I8-H8 -> 490 | J48: =J8-I8 -> 451 | ... AE48: =AE8-AD8 -> 367
A49: M05 | B49: 494 | C49: =C9-B9 -> 298 | D49: =D9-C9 -> 298 | E49: =E9-D9 -> 192 | F49: =F9-E9 -> 430 | G49: =G9-F9 -> 481 | H49: =H9-G9 -> 432 | I49: =I9-H9 -> 492 | J49: =J9-I9 -> 590 | ... AE49: =AE9-AD9 -> 455
A50: M06 | B50: 541 | C50: =C10-B10 -> 455 | D50: =D10-C10 -> 543 | E50: =E10-D10 -> 455 | F50: =F10-E10 -> 301 | G50: =G10-F10 -> 0 | H50: =H10-G10 -> 0 | I50: =I10-H10 -> 340 | J50: =J10-I10 -> 456 | ... AE50: =AE10-AD10 -> 218
A51: M07 | B51: 562 | C51: =C11-B11 -> 496 | D51: =D11-C11 -> 539 | E51: =E11-D11 -> 436 | F51: =F11-E11 -> 351 | G51: =G11-F11 -> 520 | H51: =H11-G11 -> 476 | I51: =I11-H11 -> 478 | J51: =J11-I11 -> 523 | ... AE51: =AE11-AD11 -> 215
A52: M08 | B52: 538 | C52: =C12-B12 -> 470 | D52: =D12-C12 -> 519 | E52: =E12-D12 -> 348 | F52: =F12-E12 -> 392 | G52: =G12-F12 -> 436 | H52: =H12-G12 -> 44 | I52: =I12-H12 -> 567 | J52: =J12-I12 -> 408 | ... AE52: =AE12-AD12 -> 453
A53: M09 | B53: 351 | C53: =C13-B13 -> 349 | D53: =D13-C13 -> 393 | E53: =E13-D13 -> 495 | F53: =F13-E13 -> 297 | G53: =G13-F13 -> 0 | H53: =H13-G13 -> 0 | I53: =I13-H13 -> 449 | J53: =J13-I13 -> 476 | ... AE53: =AE13-AD13 -> 259
A54: M10 | B54: 305 | C54: =C14-B14 -> 369 | D54: =D14-C14 -> 383 | E54: =E14-D14 -> 589 | F54: =F14-E14 -> 453 | G54: =G14-F14 -> 0 | H54: =H14-G14 -> 0 | I54: =I14-H14 -> 186 | J54: =J14-I14 -> 454 | ... AE54: =AE14-AD14 -> 537
A55: M11 | B55: 212 | C55: =C15-B15 -> 470 | D55: =D15-C15 -> 298 | E55: =E15-D15 -> 193 | F55: =F15-E15 -> 92 | G55: =G15-F15 -> 0 | H55: =H15-G15 -> 177 | I55: =I15-H15 -> 195 | J55: =J15-I15 -> 538 | ... AE55: =AE15-AD15 -> 236
A56: M12 | B56: 517 | C56: =C16-B16 -> 436 | D56: =D16-C16 -> 562 | E56: =E16-D16 -> 304 | F56: =F16-E16 -> 561 | G56: =G16-F16 -> 43 | H56: =H16-G16 -> 474 | I56: =I16-H16 -> 218 | J56: =J16-I16 -> 222 | ... AE56: =AE16-AD16 -> 279
... A79: XM35 | B79: 89 | C79: =C39-B39 -> 349 | D79: =D39-C39 -> 174 | E79: =E39-D39 -> 196 | F79: =F39-E39 -> 169 | G79: =G39-F39 -> 460 | H79: =H39-G39 -> 259 | I79: =I39-H39 -> 432 | J79: =J39-I39 -> 384 | ... AE79: =AE39-AD39 -> 452
A81: Kilometraje Diario | B81: =SUM(B45:B79) -> 13154 | C81: =SUM(C45:C79) -> 13031 | D81: =SUM(D45:D79) -> 12936 | E81: =SUM(E45:E79) -> 12983 | F81: =SUM(F45:F79) -> 12895 | G81: =SUM(G45:G79) -> 6334 | H81: =SUM(H45:H79) -> 4964 | I81: =SUM(I45:I79) -> 13108 | ... AE81: =SUM(AE45:AE79) -> 12374
AE86: =SUM(B81:AE81) -> 328645

Sheet KM-Servicio
G1: SA-MI | H1: 21.7 | I1: EB-PU | J1: 25.4 | K1: PU-SA | L1: 29.11 | M1: QU-LI / LI-QU | N1: 21.7 | O1: VM-PU | P1: 8.3 | Q1: VM-LI | R1: 34.83 | S1: PU-ES | T1: 11.7
B2: CANTIDAD DE SERVICIOS | D2: CANTIDAD DE SERVICIOS | G2: PU-PE | H2: 30.4 | I2: PO-SA | J2: 25.4 | K2: PU-LI | L2: 43.13 | M2: MI-LI / LI-MI | N2: 35.73 | O2: HO-LI/LI-HO | P2: 33.97 | Q2: PU-MI | R2: 7.4 | S2: PE-LI | T2: 12.73
B3: PROGRAMADOS | D3: REALIZADOS | F3: Origen-Destino | G3: Total Trenes | H3: Total Servicios | I3: Kms.xTrenes | J3: Kmsxservicios. | K3: Asientos x Kms. | L3: Disp x Km. | M3: Total Odómetro | N3: % Uso Trenes | P3: Cortes | S3: Acoples | V3: KmTren R
B4: Simples | C4: Dobles | D4: Simples | E4: Dobles | P4: EB | Q4: SA | R4: PE | S4: EB | T4: SA | U4: PE
A5: 45383 | B5: 39 | C5: 53 | D5: ='Data Ocupacion'!D32 -> 35 | E5: ='Data Ocupacion'!E32 -> 57 | F5: PU-LI | G5: =D5+E5*2 -> 149 | H5: =D5+E5 -> 92 | I5: =G5*L$2 -> 6426.37 | J5: =H5*L$2 -> 3967.96 | K5: =I5*104 -> 668342.48 | L5: =H5*104 -> 9568 | S5: 4 | V5: =I5-(P5*($L$2-$J$1)+(Q5*($L$2-$L$1))+ (R5*($L$2-$H$2))+ (S5*($J$1))) -> 6324.77
A6: 008 Planilla Lun-Vie marzo Ver 9 | B6: 37 | C6: 53 | D6: ='Data Ocupacion'!D33 -> 37 | E6: ='Data Ocupacion'!E33 -> 53 | F6: LI-PU | G6: =D6+E6*2 -> 143 | H6: =D6+E6 -> 90 | I6: =G6*L$2 -> 6167.59 | J6: =H6*L$2 -> 3881.7 | K6: =I6*104 -> 641429.36 | L6: =H6*104 -> 9360 | V6: =I6-(S6*($L$2-$J$1)+(T6*($L$2-$L$1))) -> 6167.59
B7: 0 | C7: 0 | D7: ='Data Ocupacion'!D34 -> 0 | E7: ='Data Ocupacion'!E34 -> 0 | F7: PU-SA | G7: =D7+E7*2 -> 0 | H7: =D7+E7 -> 0 | I7: =G7*L$1 -> 0 | J7: =H7*L$1 -> 0 | K7: =I7*104 -> 0 | L7: =H7*104 -> 0 | V7: =I7-(P7*($L$1-$J$1)) -> 0
B8: 1 | C8: 0 | D8: ='Data Ocupacion'!D35 -> 1 | E8: ='Data Ocupacion'!E35 -> 0 | F8: SA-PU | G8: =D8+E8*2 -> 1 | H8: =D8+E8 -> 1 | I8: =G8*L$1 -> 29.11 | J8: =H8*L$1 -> 29.11 | K8: =I8*104 -> 3027.44 | L8: =H8*104 -> 104 | V8: =I8 -> 29.11
B9: 0 | C9: 0 | D9: ='Data Ocupacion'!D36 -> 0 | E9: ='Data Ocupacion'!E36 -> 0 | F9: PU-EB | G9: =D9+E9*2 -> 0 | H9: =D9+E9 -> 0 | I9: =G9*J$1 -> 0 | J9: =H9*J$1 -> 0 | K9: =I9*104 -> 0 | L9: =H9*104 -> 0 | V9: =I9 -> 0
B10: 1 | C10: 0 | D10: ='Data Ocupacion'!D37 -> 1 | E10: ='Data Ocupacion'!E37 -> 0 | F10: EB-PU | G10: =D10+E10*2 -> 1 | H10: =D10+E10 -> 1 | I10: =G10*J$1 -> 25.4 | J10: =H10*J$1 -> 25.4 | K10: =I10*104 -> 2641.6 | L10: =H10*104 -> 104 | V10: =I10 -> 25.4
B11: =SUM(B5:B10) -> 78 | C11: =SUM(C5:C10) -> 106 | D11: =SUM(D5:D10) -> 74 | E11: =SUM(E5:E10) -> 110 | G11: =SUM(G5:G10) -> 294 | H11: =SUM(H5:H10) -> 184 | I11: =SUM(I5:I10) -> 12648.47 | J11: =SUM(J5:J10) -> 7904.17 | K11: =SUM(K5:K10) -> 1315440.9 | L11: =SUM(L5:L10) -> 19136 | M11: ='Odometro-Kilometraje'!B81 -> 13154 | N11: =(V11/M11)*100 -> 95.384446 | V11: =SUM(V5:V10) -> 12546.87
A12: =A5+1 -> 45384 | B12: 39 | C12: 53 | D12: ='Data Ocupacion'!F32 -> 33 | E12: ='Data Ocupacion'!G32 -> 59 | F12: PU-LI | G12: =D12+E12*2 -> 151 | H12: =D12+E12 -> 92 | I12: =G12*L$2 -> 6512.63 | J12: =H12*L$2 -> 3967.96 | K12: =I12*104 -> 677313.52 | L12: =H12*104 -> 9568 | P12: 5 | V12: =I12-(P12*($L$2-$J$1)+(Q12*($L$2-$L$1))+ (R12*($L$2-$H$2))+ (S12*($L$2-$J$1))) -> 6423.98
B13: 37 | C13: 53 | D13: ='Data Ocupacion'!F33 -> 37 | E13: ='Data Ocupacion'!G33 -> 53 | F13: LI-PU | G13: =D13+E13*2 -> 143 | H13: =D13+E13 -> 90 | I13: =G13*L$2 -> 6167.59 | J13: =H13*L$2 -> 3881.7 | K13: =I13*104 -> 641429.36 | L13: =H13*104 -> 9360 | V13: =I13-(S13*($L$2-$J$1)+(T13*($L$2-$L$1))) -> 6167.59
B14: 0 | C14: 0 | D14: ='Data Ocupacion'!F34 -> 0 | E14: ='Data Ocupacion'!G34 -> 0 | F14: PU-SA | G14: =D14+E14*2 -> 0 | H14: =D14+E14 -> 0 | I14: =G14*L$1 -> 0 | J14: =H14*L$1 -> 0 | K14: =I14*104 -> 0 | L14: =H14*104 -> 0 | V14: =I14-(P14*($L$1-$J$1)) -> 0
B15: 1 | C15: 0 | D15: ='Data Ocupacion'!F35 -> 1 | E15: ='Data Ocupacion'!G35 -> 0 | F15: SA-PU | G15: =D15+E15*2 -> 1 | H15: =D15+E15 -> 1 | I15: =G15*L$1 -> 29.11 | J15: =H15*L$1 -> 29.11 | K15: =I15*104 -> 3027.44 | L15: =H15*104 -> 104 | V15: =I15 -> 29.11
B16: 0 | C16: 0 | D16: ='Data Ocupacion'!F36 -> 0 | E16: ='Data Ocupacion'!G36 -> 0 | F16: PU-EB | G16: =D16+E16*2 -> 0 | H16: =D16+E16 -> 0 | I16: =G16*J$1 -> 0 | J16: =H16*J$1 -> 0 | K16: =I16*104 -> 0 | L16: =H16*104 -> 0 | V16: =I16 -> 0
B17: 1 | C17: 0 | D17: ='Data Ocupacion'!F37 -> 1 | E17: ='Data Ocupacion'!G37 -> 0 | F17: EB-PU | G17: =D17+E17*2 -> 1 | H17: =D17+E17 -> 1 | I17: =G17*J$1 -> 25.4 | J17: =H17*J$1 -> 25.4 | K17: =I17*104 -> 2641.6 | L17: =H17*104 -> 104 | V17: =I17 -> 25.4
B18: =SUM(B12:B17) -> 78 | C18: =SUM(C12:C17) -> 106 | D18: =SUM(D12:D17) -> 72 | E18: =SUM(E12:E17) -> 112 | G18: =SUM(G12:G17) -> 296 | H18: =SUM(H12:H17) -> 184 | I18: =SUM(I12:I17) -> 12734.73 | J18: =SUM(J12:J17) -> 7904.17 | K18: =SUM(K12:K17) -> 1324411.9 | L18: =SUM(L12:L17) -> 19136 | M18: ='Odometro-Kilometraje'!C81 -> 13031 | N18: =(V18/M18)*100 -> 97.046121 | V18: =SUM(V12:V17) -> 12646.08
A19: =A12+1 -> 45385 | B19: 39 | C19: 53 | D19: ='Data Ocupacion'!H32 -> 39 | E19: ='Data Ocupacion'!I32 -> 52 | F19: PU-LI | G19: =D19+E19*2 -> 143 | H19: =D19+E19 -> 91 | I19: =G19*L$2 -> 6167.59 | J19: =H19*L$2 -> 3924.83 | K19: =I19*104 -> 641429.36 | L19: =H19*104 -> 9464 | P19: 6 | V19: =I19-(P19*($L$2-$J$1)+(Q19*($L$2-$L$1))+ (R19*($L$2-$H$2))) -> 6061.21
B20: 37 | C20: 53 | D20: ='Data Ocupacion'!H33 -> 38 | E20: ='Data Ocupacion'!I33 -> 52 | F20: LI-PU | G20: =D20+E20*2 -> 142 | H20: =D20+E20 -> 90 | I20: =G20*L$2 -> 6124.46 | J20: =H20*L$2 -> 3881.7 | K20: =I20*104 -> 636943.84 | L20: =H20*104 -> 9360 | V20: =I20-(S20*($L$2-$J$1)+(T20*($L$2-$L$1))) -> 6124.46
B21: 0 | C21: 0 | D21: ='Data Ocupacion'!H34 -> 0 | E21: ='Data Ocupacion'!I34 -> 0 | F21: PU-SA | G21: =D21+E21*2 -> 0 | H21: =D21+E21 -> 0 | I21: =G21*L$1 -> 0 | J21: =H21*L$1 -> 0 | K21: =I21*104 -> 0 | L21: =H21*104 -> 0 | V21: =I21-(P21*($L$1-$J$1)) -> 0
B22: 1 | C22: 0 | D22: ='Data Ocupacion'!H35 -> 1 | E22: ='Data Ocupacion'!I35 -> 0 | F22: SA-PU | G22: =D22+E22*2 -> 1 | H22: =D22+E22 -> 1 | I22: =G22*L$1 -> 29.11 | J22: =H22*L$1 -> 29.11 | K22: =I22*104 -> 3027.44 | L22: =H22*104 -> 104 | V22: =I22 -> 29.11
B23: 0 | C23: 0 | D23: ='Data Ocupacion'!H36 -> 0 | E23: ='Data Ocupacion'!I36 -> 0 | F23: PU-EB | G23: =D23+E23*2 -> 0 | H23: =D23+E23 -> 0 | I23: =G23*J$1 -> 0 | J23: =H23*J$1 -> 0 | K23: =I23*104 -> 0 | L23: =H23*104 -> 0 | V23: =I23 -> 0
B24: 1 | C24: 0 | D24: ='Data Ocupacion'!H37 -> 1 | E24: ='Data Ocupacion'!I37 -> 0 | F24: EB-PU | G24: =D24+E24*2 -> 1 | H24: =D24+E24 -> 1 | I24: =G24*J$1 -> 25.4 | J24: =H24*J$1 -> 25.4 | K24: =I24*104 -> 2641.6 | L24: =H24*104 -> 104 | V24: =I24 -> 25.4
B25: =SUM(B19:B24) -> 78 | C25: =SUM(C19:C24) -> 106 | D25: =SUM(D19:D24) -> 79 | E25: =SUM(E19:E24) -> 104 | G25: =SUM(G19:G24) -> 287 | H25: =SUM(H19:H24) -> 183 | I25: =SUM(I19:I24) -> 12346.56 | J25: =SUM(J19:J24) -> 7861.04 | K25: =SUM(K19:K24) -> 1284042.2 | L25: =SUM(L19:L24) -> 19032 | M25: ='Odometro-Kilometraje'!D81 -> 12936 | N25: =(V25/M25)*100 -> 94.621058 | V25: =SUM(V19:V24) -> 12240.18
A26: =A19+1 -> 45386 | B26: 39 | C26: 53 | D26: ='Data Ocupacion'!J32 -> 36 | E26: ='Data Ocupacion'!K32 -> 56 | F26: PU-LI | G26: =D26+E26*2 -> 148 | H26: =D26+E26 -> 92 | I26: =G26*L$2 -> 6383.24 | J26: =H26*L$2 -> 3967.96 | K26: =I26*104 -> 663856.96 | L26: =H26*104 -> 9568 | P26: 5 | V26: =I26-(P26*($L$2-$J$1)+(Q26*($L$2-$L$1))+ (R26*($L$2-$H$2))) -> 6294.59
B27: 37 | C27: 53 | D27: ='Data Ocupacion'!J33 -> 37 | E27: ='Data Ocupacion'!K33 -> 53 | F27: LI-PU | G27: =D27+E27*2 -> 143 | H27: =D27+E27 -> 90 | I27: =G27*L$2 -> 6167.59 | J27: =H27*L$2 -> 3881.7 | K27: =I27*104 -> 641429.36 | L27: =H27*104 -> 9360 | V27: =I27-(S27*($L$2-$J$1)+(T27*($L$2-$L$1))+(U27*($L$2-$H$2))) -> 6167.59
B28: 0 | C28: 0 | D28: ='Data Ocupacion'!J34 -> 0 | E28: ='Data Ocupacion'!K34 -> 0 | F28: PU-SA | G28: =D28+E28*2 -> 0 | H28: =D28+E28 -> 0 | I28: =G28*L$1 -> 0 | J28: =H28*L$1 -> 0 | K28: =I28*104 -> 0 | L28: =H28*104 -> 0 | V28: =I28-(P28*($L$1-$J$1)) -> 0
B29: 1 | C29: 0 | D29: ='Data Ocupacion'!J35 -> 1 | E29: ='Data Ocupacion'!K35 -> 0 | F29: SA-PU | G29: =D29+E29*2 -> 1 | H29: =D29+E29 -> 1 | I29: =G29*L$1 -> 29.11 | J29: =H29*L$1 -> 29.11 | K29: =I29*104 -> 3027.44 | L29: =H29*104 -> 104 | V29: =I29 -> 29.11
B30: 0 | C30: 0 | D30: ='Data Ocupacion'!J36 -> 0 | E30: ='Data Ocupacion'!K36 -> 0 | F30: PU-EB | G30: =D30+E30*2 -> 0 | H30: =D30+E30 -> 0 | I30: =G30*J$1 -> 0 | J30: =H30*J$1 -> 0 | K30: =I30*104 -> 0 | L30: =H30*104 -> 0 | V30: =I30 -> 0
B31: 1 | C31: 0 | D31: ='Data Ocupacion'!J37 -> 1 | E31: ='Data Ocupacion'!K37 -> 0 | F31: EB-PU | G31: =D31+E31*2 -> 1 | H31: =D31+E31 -> 1 | I31: =G31*J$1 -> 25.4 | J31: =H31*J$1 -> 25.4 | K31: =I31*104 -> 2641.6 | L31: =H31*104 -> 104 | V31: =I31 -> 25.4
B32: =SUM(B26:B31) -> 78 | C32: =SUM(C26:C31) -> 106 | D32: =SUM(D26:D31) -> 75 | E32: =SUM(E26:E31) -> 109 | G32: =SUM(G26:G31) -> 293 | H32: =SUM(H26:H31) -> 184 | I32: =SUM(I26:I31) -> 12605.34 | J32: =SUM(J26:J31) -> 7904.17 | K32: =SUM(K26:K31) -> 1310955.4 | L32: =SUM(L26:L31) -> 19136 | M32: ='Odometro-Kilometraje'!E81 -> 12983 | N32: =(V32/M32)*100 -> 96.408303 | V32: =SUM(V26:V31) -> 12516.69
A33: =A26+1 -> 45387 | B33: 39 | C33: 53 | D33: ='Data Ocupacion'!L32 -> 36 | E33: ='Data Ocupacion'!M32 -> 55 | F33: PU-LI | G33: =D33+E33*2 -> 146 | H33: =D33+E33 -> 91 | I33: =G33*L$2 -> 6296.98 | J33: =H33*L$2 -> 3924.83 | K33: =I33*104 -> 654885.92 | L33: =H33*104 -> 9464 | P33: 5 | V33: =I33-((P33*($L$2-$J$1)))-(S33*($J$1)) -> 6208.33
B34: 37 | C34: 53 | D34: ='Data Ocupacion'!L33 -> 37 | E34: ='Data Ocupacion'!M33 -> 53 | F34: LI-PU | G34: =D34+E34*2 -> 143 | H34: =D34+E34 -> 90 | I34: =G34*L$2 -> 6167.59 | J34: =H34*L$2 -> 3881.7 | K34: =I34*104 -> 641429.36 | L34: =H34*104 -> 9360 | V34: =I34-(S34*($L$2-$J$1)+(T34*($L$2-$L$1))) -> 6167.59
B35: 0 | C35: 0 | D35: ='Data Ocupacion'!L34 -> 0 | E35: ='Data Ocupacion'!M34 -> 0 | F35: PU-SA | G35: =D35+E35*2 -> 0 | H35: =D35+E35 -> 0 | I35: =G35*L$1 -> 0 | J35: =H35*L$1 -> 0 | K35: =I35*104 -> 0 | L35: =H35*104 -> 0 | V35: =I35-(P35*($L$1-$J$1)) -> 0
B36: 1 | C36: 0 | D36: ='Data Ocupacion'!L35 -> 1 | E36: ='Data Ocupacion'!M35 -> 0 | F36: SA-PU | G36: =D36+E36*2 -> 1 | H36: =D36+E36 -> 1 | I36: =G36*L$1 -> 29.11 | J36: =H36*L$1 -> 29.11 | K36: =I36*104 -> 3027.44 | L36: =H36*104 -> 104 | V36: =I36 -> 29.11
B37: 0 | C37: 0 | D37: ='Data Ocupacion'!L36 -> 0 | E37: ='Data Ocupacion'!M36 -> 0 | F37: PU-EB | G37: =D37+E37*2 -> 0 | H37: =D37+E37 -> 0 | I37: =G37*J$1 -> 0 | J37: =H37*J$1 -> 0 | K37: =I37*104 -> 0 | L37: =H37*104 -> 0 | V37: =I37 -> 0
B38: 1 | C38: 0 | D38: ='Data Ocupacion'!L37 -> 1 | E38: ='Data Ocupacion'!M37 -> 0 | F38: EB-PU | G38: =D38+E38*2 -> 1 | H38: =D38+E38 -> 1 | I38: =G38*J$1 -> 25.4 | J38: =H38*J$1 -> 25.4 | K38: =I38*104 -> 2641.6 | L38: =H38*104 -> 104 | V38: =I38 -> 25.4
B39: =SUM(B33:B38) -> 78 | C39: =SUM(C33:C38) -> 106 | D39: =SUM(D33:D38) -> 75 | E39: =SUM(E33:E38) -> 108 | G39: =SUM(G33:G38) -> 291 | H39: =SUM(H33:H38) -> 183 | I39: =SUM(I33:I38) -> 12519.08 | J39: =SUM(J33:J38) -> 7861.04 | K39: =SUM(K33:K38) -> 1301984.3 | L39: =SUM(L33:L38) -> 19032 | M39: ='Odometro-Kilometraje'!F81 -> 12895 | N39: =(V39/M39)*100 -> 96.397286 | V39: =SUM(V33:V38) -> 12430.43
A40: =A33+1 -> 45388 | B40: 67 | C40: 3 | D40: ='Data Ocupacion'!N32 -> 67 | E40: ='Data Ocupacion'!O32 -> 3 | F40: PU-LI | G40: =D40+E40*2 -> 73 | H40: =D40+E40 -> 70 | I40: =G40*L$2 -> 3148.49 | J40: =H40*L$2 -> 3019.1 | K40: =I40*104 -> 327442.96 | L40: =H40*104 -> 7280 | V40: =I40-((P40*($L$2-$J$1)))-(S40*($J$1)) -> 3148.49
...

Sheet Oferta Diaria
A1: Oferta Abril 2024
C3: 45383 | D3: 45384 | E3: 45385 | F3: 45386 | G3: 45387 | H3: 45388 | I3: 45389 | J3: 45390 | K3: 45391 | L3: 45392 | M3: 45393 | N3: 45394 | O3: 45395 | P3: 45396 | Q3: 45397 | R3: 45398 | S3: 45399 | T3: 45400 | U3: 45401 | V3: 45402 | W3: 45403 | X3: 45404 | Y3: 45405 | Z3: 45406 | AA3: 45407 | AB3: 45408 | AC3: 45409 | AD3: 45410 | AE3: 45411 | AF3: 45412
A4: HÁBIL | B4: km
A5: Servicios PU-LI | B5: 43.13 | C5: ='Data Ocupacion'!D43 -> 92 | D5: ='Data Ocupacion'!F43 -> 92 | E5: ='Data Ocupacion'!H43 -> 91 | F5: ='Data Ocupacion'!J43 -> 92 | G5: ='Data Ocupacion'!L43 -> 91 | H5: ='Data Ocupacion'!N43 -> 70 | I5: ='Data Ocupacion'!P43 -> 54 | J5: ='Data Ocupacion'!R43 -> 92 | K5: ='Data Ocupacion'!T43 -> 92 | L5: ='Data Ocupacion'!V43 -> 92 | M5: ='Data Ocupacion'!X43 -> 92 | N5: ='Data Ocupacion'!Z43 -> 92 | O5: ='Data Ocupacion'!AB43 -> 70 | P5: ='Data Ocupacion'!AD43 -> 54 | Q5: ='Data Ocupacion'!AF43 -> 92 | R5: ='Data Ocupacion'!AH43 -> 92 | S5: ='Data Ocupacion'!AJ43 -> 92 | T5: ='Data Ocupacion'!AL43 -> 92 | U5: ='Data Ocupacion'!AN43 -> 92 | V5: ='Data Ocupacion'!AP43 -> 70 | W5: ='Data Ocupacion'!AR43 -> 54 | X5: ='Data Ocupacion'!AT43 -> 92 | Y5: ='Data Ocupacion'!AV43 -> 92 | Z5: ='Data Ocupacion'!AX43 -> 92 | AA5: ='Data Ocupacion'!AZ43 -> 85 | AB5: ='Data Ocupacion'!BB43 -> 86 | AC5: ='Data Ocupacion'!BD43 -> 70 | AD5: ='Data Ocupacion'!BF43 -> 54 | AE5: ='Data Ocupacion'!BH43 -> 92 | AF5: ='Data Ocupacion'!BJ43 -> 86
A6: Servicios LI-PU | B6: 43.13 | C6: ='Data Ocupacion'!D44 -> 90 | D6: ='Data Ocupacion'!F44 -> 90 | E6: ='Data Ocupacion'!H44 -> 90 | F6: ='Data Ocupacion'!J44 -> 90 | G6: ='Data Ocupacion'!L44 -> 90 | H6: ='Data Ocupacion'!N44 -> 73 | I6: ='Data Ocupacion'!P44 -> 57 | J6: ='Data Ocupacion'!R44 -> 90 | K6: ='Data Ocupacion'!T44 -> 90 | L6: ='Data Ocupacion'!V44 -> 90 | M6: ='Data Ocupacion'!X44 -> 90 | N6: ='Data Ocupacion'!Z44 -> 89 | O6: ='Data Ocupacion'!AB44 -> 73 | P6: ='Data Ocupacion'!AD44 -> 57 | Q6: ='Data Ocupacion'!AF44 -> 90 | R6: ='Data Ocupacion'!AH44 -> 90 | S6: ='Data Ocupacion'!AJ44 -> 90 | T6: ='Data Ocupacion'!AL44 -> 90 | U6: ='Data Ocupacion'!AN44 -> 90 | V6: ='Data Ocupacion'!AP44 -> 73 | W6: ='Data Ocupacion'!AR44 -> 57 | X6: ='Data Ocupacion'!AT44 -> 90 | Y6: ='Data Ocupacion'!AV44 -> 90 | Z6: ='Data Ocupacion'!AX44 -> 90 | AA6: ='Data Ocupacion'!AZ44 -> 85 | AB6: ='Data Ocupacion'!BB44 -> 84 | AC6: ='Data Ocupacion'!BD44 -> 73 | AD6: ='Data Ocupacion'!BF44 -> 57 | AE6: ='Data Ocupacion'!BH44 -> 90 | AF6: ='Data Ocupacion'!BJ44 -> 84
A7: Servicios PU-SA | B7: 29.11 | C7: ='Data Ocupacion'!D45 -> 0 | D7: ='Data Ocupacion'!F45 -> 0 | E7: ='Data Ocupacion'!H45 -> 0 | F7: ='Data Ocupacion'!J45 -> 0 | G7: ='Data Ocupacion'!L45 -> 0 | H7: ='Data Ocupacion'!N45 -> 0 | I7: ='Data Ocupacion'!P45 -> 0 | J7: ='Data Ocupacion'!R45 -> 0 | K7: ='Data Ocupacion'!T45 -> 0 | L7: ='Data Ocupacion'!V45 -> 0 | M7: ='Data Ocupacion'!X45 -> 0 | N7: ='Data Ocupacion'!Z45 -> 0 | O7: ='Data Ocupacion'!AB45 -> 0 | P7: ='Data Ocupacion'!AD45 -> 0 | Q7: ='Data Ocupacion'!AF45 -> 0 | R7: ='Data Ocupacion'!AH45 -> 0 | S7: ='Data Ocupacion'!AJ45 -> 0 | T7: ='Data Ocupacion'!AL45 -> 0 | U7: ='Data Ocupacion'!AN45 -> 0 | V7: ='Data Ocupacion'!AP45 -> 0 | W7: ='Data Ocupacion'!AR45 -> 0 | X7: ='Data Ocupacion'!AT45 -> 0 | Y7: ='Data Ocupacion'!AV45 -> 0 | Z7: ='Data Ocupacion'!AX45 -> 0 | AA7: ='Data Ocupacion'!AZ45 -> 0 | AB7: ='Data Ocupacion'!BB45 -> 0 | AC7: ='Data Ocupacion'!BD45 -> 0 | AD7: ='Data Ocupacion'!BF45 -> 0 | AE7: ='Data Ocupacion'!BH45 -> 0 | AF7: ='Data Ocupacion'!BJ45 -> 0
A8: Servicios SA-PU | B8: 29.11 | C8: ='Data Ocupacion'!D46 -> 1 | D8: ='Data Ocupacion'!F46 -> 1 | E8: ='Data Ocupacion'!H46 -> 1 | F8: ='Data Ocupacion'!J46 -> 1 | G8: ='Data Ocupacion'!L46 -> 1 | H8: ='Data Ocupacion'!N46 -> 0 | I8: ='Data Ocupacion'!P46 -> 0 | J8: ='Data Ocupacion'!R46 -> 1 | K8: ='Data Ocupacion'!T46 -> 1 | L8: ='Data Ocupacion'!V46 -> 1 | M8: ='Data Ocupacion'!X46 -> 1 | N8: ='Data Ocupacion'!Z46 -> 1 | O8: ='Data Ocupacion'!AB46 -> 0 | P8: ='Data Ocupacion'!AD46 -> 0 | Q8: ='Data Ocupacion'!AF46 -> 1 | R8: ='Data Ocupacion'!AH46 -> 1 | S8: ='Data Ocupacion'!AJ46 -> 1 | T8: ='Data Ocupacion'!AL46 -> 1 | U8: ='Data Ocupacion'!AN46 -> 1 | V8: ='Data Ocupacion'!AP46 -> 0 | W8: ='Data Ocupacion'!AR46 -> 0 | X8: ='Data Ocupacion'!AT46 -> 1 | Y8: ='Data Ocupacion'!AV46 -> 1 | Z8: ='Data Ocupacion'!AX46 -> 1 | AA8: ='Data Ocupacion'!AZ46 -> 1 | AB8: ='Data Ocupacion'!BB46 -> 1 | AC8: ='Data Ocupacion'!BD46 -> 0 | AD8: ='Data Ocupacion'!BF46 -> 0 | AE8: ='Data Ocupacion'!BH46 -> 1 | AF8: ='Data Ocupacion'!BJ46 -> 1
A9: Servicios PU-EB | B9: 25.4 | C9: ='Data Ocupacion'!D47 -> 0 | D9: ='Data Ocupacion'!F47 -> 0 | E9: ='Data Ocupacion'!H47 -> 0 | F9: ='Data Ocupacion'!J47 -> 0 | G9: ='Data Ocupacion'!L47 -> 0 | H9: ='Data Ocupacion'!N47 -> 0 | I9: ='Data Ocupacion'!P47 -> 0 | J9: ='Data Ocupacion'!R47 -> 0 | K9: ='Data Ocupacion'!T47 -> 0 | L9: ='Data Ocupacion'!V47 -> 0 | M9: ='Data Ocupacion'!X47 -> 0 | N9: ='Data Ocupacion'!Z47 -> 0 | O9: ='Data Ocupacion'!AB47 -> 0 | P9: ='Data Ocupacion'!AD47 -> 0 | Q9: ='Data Ocupacion'!AF47 -> 0 | R9: ='Data Ocupacion'!AH47 -> 0 | S9: ='Data Ocupacion'!AJ47 -> 0 | T9: ='Data Ocupacion'!AL47 -> 0 | U9: ='Data Ocupacion'!AN47 -> 0 | V9: ='Data Ocupacion'!AP47 -> 0 | W9: ='Data Ocupacion'!AR47 -> 0 | X9: ='Data Ocupacion'!AT47 -> 0 | Y9: ='Data Ocupacion'!AV47 -> 0 | Z9: ='Data Ocupacion'!AX47 -> 0 | AA9: ='Data Ocupacion'!AZ47 -> 0 | AB9: ='Data Ocupacion'!BB47 -> 0 | AC9: ='Data Ocupacion'!BD47 -> 0 | AD9: ='Data Ocupacion'!BF47 -> 0 | AE9: ='Data Ocupacion'!BH47 -> 0 | AF9: ='Data Ocupacion'!BJ47 -> 0
A10: Servicios EB-PU | B10: 25.4 | C10: ='Data Ocupacion'!D48 -> 1 | D10: ='Data Ocupacion'!F48 -> 1 | E10: ='Data Ocupacion'!H48 -> 1 | F10: ='Data Ocupacion'!J48 -> 1 | G10: ='Data Ocupacion'!L48 -> 1 | H10: ='Data Ocupacion'!N48 -> 0 | I10: ='Data Ocupacion'!P48 -> 0 | J10: ='Data Ocupacion'!R48 -> 1 | K10: ='Data Ocupacion'!T48 -> 1 | L10: ='Data Ocupacion'!V48 -> 1 | M10: ='Data Ocupacion'!X48 -> 1 | N10: ='Data Ocupacion'!Z48 -> 1 | O10: ='Data Ocupacion'!AB48 -> 0 | P10: ='Data Ocupacion'!AD48 -> 0 | Q10: ='Data Ocupacion'!AF48 -> 1 | R10: ='Data Ocupacion'!AH48 -> 1 | S10: ='Data Ocupacion'!AJ48 -> 1 | T10: ='Data Ocupacion'!AL48 -> 1 | U10: ='Data Ocupacion'!AN48 -> 1 | V10: ='Data Ocupacion'!AP48 -> 0 | W10: ='Data Ocupacion'!AR48 -> 0 | X10: ='Data Ocupacion'!AT48 -> 1 | Y10: ='Data Ocupacion'!AV48 -> 1 | Z10: ='Data Ocupacion'!AX48 -> 1 | AA10: ='Data Ocupacion'!AZ48 -> 1 | AB10: ='Data Ocupacion'!BB48 -> 1 | AC10: ='Data Ocupacion'!BD48 -> 0 | AD10: ='Data Ocupacion'!BF48 -> 0 | AE10: ='Data Ocupacion'!BH48 -> 1 | AF10: ='Data Ocupacion'!BJ48 -> 1
A11: Servicios VM-LI | B11: 34.83 | C11: ='Data Ocupacion'!D49 -> 0 | D11: ='Data Ocupacion'!F49 -> 0 | AB11: ='Data Ocupacion'!BB49 -> 0 | AC11: ='Data Ocupacion'!BD49 -> 0 | AD11: ='Data Ocupacion'!BF49 -> 0 | AE11: ='Data Ocupacion'!BH49 -> 0 | AF11: ='Data Ocupacion'!BJ49 -> 0
A12: Servicios VM-PU | B12: 8.3 | C12: ='Data Ocupacion'!D50 -> 0 | D12: ='Data Ocupacion'!F50 -> 0 | AB12: ='Data Ocupacion'!BB50 -> 0 | AC12: ='Data Ocupacion'!BD50 -> 0 | AD12: ='Data Ocupacion'!BF50 -> 0 | AE12: ='Data Ocupacion'!BH50 -> 0 | AF12: ='Data Ocupacion'!BJ50 -> 0
A14: Trenes PU-LI | B14: 43.13 | C14: ='Data Ocupacion'!D53 -> 149 | D14: ='Data Ocupacion'!F53 -> 151 | E14: ='Data Ocupacion'!H53 -> 143 | F14: ='Data Ocupacion'!J53 -> 148 | G14: ='Data Ocupacion'!L53 -> 146 | H14: ='Data Ocupacion'!N53 -> 73 | I14: ='Data Ocupacion'!P53 -> 57 | J14: ='Data Ocupacion'!R53 -> 143 | K14: ='Data Ocupacion'!T53 -> 142 | L14: ='Data Ocupacion'!V53 -> 140 | M14: ='Data Ocupacion'!X53 -> 143 | N14: ='Data Ocupacion'!Z53 -> 142 | O14: ='Data Ocupacion'!AB53 -> 73 | P14: ='Data Ocupacion'!AD53 -> 57 | Q14: ='Data Ocupacion'!AF53 -> 144 | R14: ='Data Ocupacion'!AH53 -> 149 | S14: ='Data Ocupacion'!AJ53 -> 149 | T14: ='Data Ocupacion'!AL53 -> 153 | U14: ='Data Ocupacion'!AN53 -> 143 | V14: ='Data Ocupacion'!AP53 -> 73 | W14: ='Data Ocupacion'!AR53 -> 57 | X14: ='Data Ocupacion'!AT53 -> 145 | Y14: ='Data Ocupacion'!AV53 -> 145 | Z14: ='Data Ocupacion'!AX53 -> 145 | AA14: ='Data Ocupacion'!AZ53 -> 143 | AB14: ='Data Ocupacion'!BB53 -> 136 | AC14: ='Data Ocupacion'!BD53 -> 73 | AD14: ='Data Ocupacion'!BF53 -> 57 | AE14: ='Data Ocupacion'!BH53 -> 150 | AF14: ='Data Ocupacion'!BJ53 -> 145
A15: Trenes LI-PU | B15: 43.13 | C15: ='Data Ocupacion'!D54 -> 143 | D15: ='Data Ocupacion'!F54 -> 143 | E15: ='Data Ocupacion'!H54 -> 142 | F15: ='Data Ocupacion'!J54 -> 143 | G15: ='Data Ocupacion'!L54 -> 143 | H15: ='Data Ocupacion'!N54 -> 73 | I15: ='Data Ocupacion'!P54 -> 57 | J15: ='Data Ocupacion'!R54 -> 140 | K15: ='Data Ocupacion'!T54 -> 140 | L15: ='Data Ocupacion'!V54 -> 138 | M15: ='Data Ocupacion'!X54 -> 141 | N15: ='Data Ocupacion'!Z54 -> 140 | O15: ='Data Ocupacion'!AB54 -> 73 | P15: ='Data Ocupacion'!AD54 -> 57 | Q15: ='Data Ocupacion'!AF54 -> 142 | R15: ='Data Ocupacion'!AH54 -> 141 | S15: ='Data Ocupacion'!AJ54 -> 143 | T15: ='Data Ocupacion'!AL54 -> 144 | U15: ='Data Ocupacion'!AN54 -> 141 | V15: ='Data Ocupacion'!AP54 -> 73 | W15: ='Data Ocupacion'!AR54 -> 57 | X15: ='Data Ocupacion'!AT54 -> 143 | Y15: ='Data Ocupacion'!AV54 -> 143 | Z15: ='Data Ocupacion'!AX54 -> 143 | AA15: ='Data Ocupacion'!AZ54 -> 135 | AB15: ='Data Ocupacion'!BB54 -> 134 | AC15: ='Data Ocupacion'!BD54 -> 73 | AD15: ='Data Ocupacion'!BF54 -> 57 | AE15: ='Data Ocupacion'!BH54 -> 143 | AF15: ='Data Ocupacion'!BJ54 -> 135
A16: Trenes PU-SA | B16: 29.11 | C16: ='Data Ocupacion'!D55 -> 0 | D16: ='Data Ocupacion'!F55 -> 0 | E16: ='Data Ocupacion'!H55 -> 0 | F16: ='Data Ocupacion'!J55 -> 0 | G16: ='Data Ocupacion'!L55 -> 0 | H16: ='Data Ocupacion'!N55 -> 0 | I16: ='Data Ocupacion'!P55 -> 0 | J16: ='Data Ocupacion'!R55 -> 0 | K16: ='Data Ocupacion'!T55 -> 0 | L16: ='Data Ocupacion'!V55 -> 0 | M16: ='Data Ocupacion'!X55 -> 0 | N16: ='Data Ocupacion'!Z55 -> 0 | O16: ='Data Ocupacion'!AB55 -> 0 | P16: ='Data Ocupacion'!AD55 -> 0 | Q16: ='Data Ocupacion'!AF55 -> 0 | R16: ='Data Ocupacion'!AH55 -> 0 | S16: ='Data Ocupacion'!AJ55 -> 0 | T16: ='Data Ocupacion'!AL55 -> 0 | U16: ='Data Ocupacion'!AN55 -> 0 | V16: ='Data Ocupacion'!AP55 -> 0 | W16: ='Data Ocupacion'!AR55 -> 0 | X16: ='Data Ocupacion'!AT55 -> 0 | Y16: ='Data Ocupacion'!AV55 -> 0 | Z16: ='Data Ocupacion'!AX55 -> 0 | AA16: ='Data Ocupacion'!AZ55 -> 0 | AB16: ='Data Ocupacion'!BB55 -> 0 | AC16: ='Data Ocupacion'!BD55 -> 0 | AD16: ='Data Ocupacion'!BF55 -> 0 | AE16: ='Data Ocupacion'!BH55 -> 0 | AF16: ='Data Ocupacion'!BJ55 -> 0
A17: Trenes SA-PU | B17: 29.11 | C17: ='Data Ocupacion'!D56 -> 1 | D17: ='Data Ocupacion'!F56 -> 1 | E17: ='Data Ocupacion'!H56 -> 1 | F17: ='Data Ocupacion'!J56 -> 1 | G17: ='Data Ocupacion'!L56 -> 1 | H17: ='Data Ocupacion'!N56 -> 0 | I17: ='Data Ocupacion'!P56 -> 0 | J17: ='Data Ocupacion'!R56 -> 1 | K17: ='Data Ocupacion'!T56 -> 1 | L17: ='Data Ocupacion'!V56 -> 1 | M17: ='Data Ocupacion'!X56 -> 1 | N17: ='Data Ocupacion'!Z56 -> 1 | O17: ='Data Ocupacion'!AB56 -> 0 | P17: ='Data Ocupacion'!AD56 -> 0 | Q17: ='Data Ocupacion'!AF56 -> 1 | R17: ='Data Ocupacion'!AH56 -> 1 | S17: ='Data Ocupacion'!AJ56 -> 1 | T17: ='Data Ocupacion'!AL56 -> 1 | U17: ='Data Ocupacion'!AN56 -> 1 | V17: ='Data Ocupacion'!AP56 -> 0 | W17: ='Data Ocupacion'!AR56 -> 0 | X17: ='Data Ocupacion'!AT56 -> 1 | Y17: ='Data Ocupacion'!AV56 -> 1 | Z17: ='Data Ocupacion'!AX56 -> 1 | AA17: ='Data Ocupacion'!AZ56 -> 1 | AB17: ='Data Ocupacion'!BB56 -> 1 | AC17: ='Data Ocupacion'!BD56 -> 0 | AD17: ='Data Ocupacion'!BF56 -> 0 | AE17: ='Data Ocupacion'!BH56 -> 1 | AF17: ='Data Ocupacion'!BJ56 -> 2
A18: Trenes EB-PU | B18: 25.4 | C18: ='Data Ocupacion'!D58 -> 1 | D18: ='Data Ocupacion'!F58 -> 1 | E18: ='Data Ocupacion'!H58 -> 1 | F18: ='Data Ocupacion'!J58 -> 1 | G18: ='Data Ocupacion'!L58 -> 1 | H18: ='Data Ocupacion'!N58 -> 0 | I18: ='Data Ocupacion'!P58 -> 0 | J18: ='Data Ocupacion'!R58 -> 1 | K18: ='Data Ocupacion'!T58 -> 1 | L18: ='Data Ocupacion'!V58 -> 1 | M18: ='Data Ocupacion'!X58 -> 1 | N18: ='Data Ocupacion'!Z58 -> 1 | O18: ='Data Ocupacion'!AB58 -> 0 | P18: ='Data Ocupacion'!AD58 -> 0 | Q18: ='Data Ocupacion'!AF58 -> 1 | R18: ='Data Ocupacion'!AH58 -> 1 | S18: ='Data Ocupacion'!AJ58 -> 1 | T18: ='Data Ocupacion'!AL58 -> 1 | U18: ='Data Ocupacion'!AN58 -> 1 | V18: ='Data Ocupacion'!AP58 -> 0 | W18: ='Data Ocupacion'!AR58 -> 0 | X18: ='Data Ocupacion'!AT58 -> 1 | Y18: ='Data Ocupacion'!AV58 -> 1 | Z18: ='Data Ocupacion'!AX58 -> 1 | AA18: ='Data Ocupacion'!AZ58 -> 1 | AB18: ='Data Ocupacion'!BB58 -> 1 | AC18: ='Data Ocupacion'!BD58 -> 0 | AD18: ='Data Ocupacion'!BF58 -> 0 | AE18: ='Data Ocupacion'!BH58 -> 1 | AF18: ='Data Ocupacion'!BJ58 -> 1
A19: Trenes PU-EB | B19: 25.4 | C19: 0 | D19: 0 | E19: 0 | F19: 0 | G19: 0 | H19: ='Data Ocupacion'!N57 -> 0 | I19: ='Data Ocupacion'!P57 -> 0 | J19: ='Data Ocupacion'!R57 -> 0 | K19: ='Data Ocupacion'!T57 -> 0 | L19: 0 | M19: 0 | N19: 0 | O19: 0 | P19: 0 | Q19: 0 | R19: 0 | S19: 0 | T19: 0 | U19: 0 | V19: 0 | W19: 0 | X19: 0 | Y19: 0 | Z19: 0 | AA19: 0 | AB19: 0 | AC19: 0 | AD19: 0 | AE19: 0 | AF19: 0
A20: Trenes PU-ES | B20: 11.7
A21: Trenes LI-QU | B21: 21.7
A22: Trenes VM-LI | B22: 34.83 | C22: ='Data Ocupacion'!D59 -> 0 | D22: ='Data Ocupacion'!F59 -> 0 | AB22: ='Data Ocupacion'!BB59 -> 0 | AC22: ='Data Ocupacion'!BD59 -> 0 | AD22: ='Data Ocupacion'!BF59 -> 0 | AE22: ='Data Ocupacion'!BH59 -> 0 | AF22: ='Data Ocupacion'!BJ59 -> 0
A23: Trenes VM-PU | B23: 8.3 | C23: ='Data Ocupacion'!D60 -> 0 | D23: ='Data Ocupacion'!F60 -> 0 | AB23: ='Data Ocupacion'!BB60 -> 0 | AC23: ='Data Ocupacion'!BD60 -> 0 | AD23: ='Data Ocupacion'!BF60 -> 0 | AE23: ='Data Ocupacion'!BH60 -> 0 | AF23: ='Data Ocupacion'!BJ60 -> 0
A25: Corte EB (600) | B25: -17.73 | C25: ='KM-Servicio'!P5 -> 0 | D25: ='KM-Servicio'!P12 -> 5 | E25: ='KM-Servicio'!P19 -> 6 | F25: ='KM-Servicio'!P26 -> 5 | G25: ='KM-Servicio'!P33 -> 5 | H25: ='KM-Servicio'!P40 -> 0 | I25: ='KM-Servicio'!P47 -> 0 | J25: ='KM-Servicio'!P54 -> 0 | K25: ='KM-Servicio'!P61 -> 3 | L25: ='KM-Servicio'!P68 -> 2 | M25: ='KM-Servicio'!P75 -> 0 | N25: ='KM-Servicio'!P82 -> 5 | O25: ='KM-Servicio'!P89 -> 0 | P25: ='KM-Servicio'!P96 -> 0 | Q25: ='KM-Servicio'!P103 -> 4 | R25: ='KM-Servicio'!P110 -> 4 | S25: ='KM-Servicio'!P117 -> 4 | T25: ='KM-Servicio'!P124 -> 5 | U25: ='KM-Servicio'!P131 -> 4 | V25: ='KM-Servicio'!P138 -> 0 | W25: ='KM-Servicio'!P145 -> 0 | X25: ='KM-Servicio'!P152 -> 5 | Y25: ='KM-Servicio'!P159 -> 6 | Z25: ='KM-Servicio'!P166 -> 4 | AA25: ='KM-Servicio'!P173 -> 5 | AB25: ='KM-Servicio'!P180 -> 3 | AC25: ='KM-Servicio'!P187 -> 0 | AD25: ='KM-Servicio'!P194 -> 0 | AE25: ='KM-Servicio'!P201 -> 4 | AF25: ='KM-Servicio'!P208 -> 5 | AH25: =SUM(C25:AF25) -> 84
A26: Acople EB (600) | B26: -17.73 | C26: ='KM-Servicio'!S6 -> 0 | D26: ='KM-Servicio'!S13 -> 0 | E26: ='KM-Servicio'!S20 -> 0 | F26: ='KM-Servicio'!S27 -> 0 | G26: ='KM-Servicio'!S34 -> 0 | H26: ='KM-Servicio'!S41 -> 0 | I26: ='KM-Servicio'!S48 -> 0 | J26: ='KM-Servicio'!S55 -> 0 | K26: ='KM-Servicio'!S62 -> 0 | L26: ='KM-Servicio'!S69 -> 0 | M26: ='KM-Servicio'!S76 -> 0 | N26: ='KM-Servicio'!S83 -> 0 | O26: ='KM-Servicio'!S90 -> 0 | P26: ='KM-Servicio'!S97 -> 0 | Q26: ='KM-Servicio'!S104 -> 0 | R26: ='KM-Servicio'!S111 -> 0 | S26: ='KM-Servicio'!S118 -> 0 | T26: ='KM-Servicio'!S125 -> 0 | U26: ='KM-Servicio'!S132 -> 0 | V26: ='KM-Servicio'!S139 -> 0 | W26: ='KM-Servicio'!S146 -> 0 | X26: ='KM-Servicio'!S153 -> 0 | Y26: ='KM-Servicio'!S160 -> 0 | Z26: ='KM-Servicio'!S167 -> 0 | AA26: ='KM-Servicio'!S174 -> 0 | AB26: ='KM-Servicio'!S181 -> 0 | AC26: ='KM-Servicio'!S188 -> 0 | AD26: ='KM-Servicio'!S195 -> 0 | AE26: ='KM-Servicio'!S202 -> 0 | AF26: ='KM-Servicio'!S209 -> 0
A27: Acople/Corte SA (600) | B27: -14.02 | C27: ='KM-Servicio'!T6 -> 0 | D27: ='KM-Servicio'!T13 -> 0 | E27: ='KM-Servicio'!T20 -> 0 | F27: ='KM-Servicio'!T27 -> 0 | G27: ='KM-Servicio'!T34 -> 0 | H27: ='KM-Servicio'!T41 -> 0 | I27: ='KM-Servicio'!T48 -> 0 | J27: ='KM-Servicio'!T55 -> 0 | K27: ='KM-Servicio'!T62 -> 0 | L27: ='KM-Servicio'!T69 -> 0 | M27: ='KM-Servicio'!T76 -> 0 | N27: ='KM-Servicio'!T83 -> 0 | O27: ='KM-Servicio'!T90 -> 0 | P27: ='KM-Servicio'!T97 -> 0 | Q27: ='KM-Servicio'!T104 -> 0 | R27: ='KM-Servicio'!T111 -> 0 | S27: ='KM-Servicio'!T118 -> 0 | T27: ='KM-Servicio'!T125 -> 0 | U27: ='KM-Servicio'!T132 -> 0 | V27: ='KM-Servicio'!T139 -> 0 | W27: ='KM-Servicio'!T146 -> 0 | X27: ='KM-Servicio'!T153 -> 0 | Y27: ='KM-Servicio'!T160 -> 0 | Z27: ='KM-Servicio'!T167 -> 0 | AA27: ='KM-Servicio'!T174 -> 0 | AB27: ='KM-Servicio'!T181 -> 0 | AC27: ='KM-Servicio'!T188 -> 0 | AD27: ='KM-Servicio'!T195 -> 0 | AE27: ='KM-Servicio'!T202 -> 0 | AF27: ='KM-Servicio'!T209 -> 0
A28: Corte EB (400) | B28: -3.71 | E28: ='KM-Servicio'!P21 -> 0 | G28: ='KM-Servicio'!P35 -> 0 | N28: ='KM-Servicio'!P84 -> 0
A29: Acople EB (600) vía 1 | B29: -25.4 | C29: 4 | J29: 6 | K29: 3 | L29: 6 | M29: 7 | N29: 5 | Q29: 4 | R29: 5 | S29: 4 | T29: 7 | U29: 4 | X29: 4 | Y29: 6 | Z29: 5 | AA29: 6 | AB29: 5 | AE29: 5 | AF29: 7 | AH29: =SUM(C29:AF29) -> 93
A30: Corte PE (600) vía 1 | B30: -12.73
A31: Corte PE (600) | B31: -12.73
A32: Corte EB (600) vía 2 | B32: -25.4 | AC32: 0
A34: Servicios | B34: =SUM(C34:AF34) -> 5025 | C34: =SUM(C5:C12) -> 184 | D34: =SUM(D5:D12) -> 184 | E34: =SUM(E5:E10) -> 183 | F34: =SUM(F5:F10) -> 184 | G34: =SUM(G5:G10) -> 183 | H34: =SUM(H5:H10) -> 143 | I34: =SUM(I5:I10) -> 111 | J34: =SUM(J5:J10) -> 184 | K34: =SUM(K5:K12) -> 184 | L34: =SUM(L5:L10) -> 184 | M34: =SUM(M5:M10) -> 184 | N34: =SUM(N5:N10) -> 183 | O34: =SUM(O5:O10) -> 143 | P34: =SUM(P5:P10) -> 111 | Q34: =SUM(Q5:Q10) -> 184 | R34: =SUM(R5:R10) -> 184 | S34: =SUM(S5:S10) -> 184 | ... AA34: =SUM(AA5:AA10) -> 172 | AB34: =SUM(AB5:AB12) -> 172 | AC34: =SUM(AC5:AC12) -> 143 | AD34: =SUM(AD5:AD12) -> 111 | AE34: =SUM(AE5:AE12) -> 184 | AF34: =SUM(AF5:AF12) -> 172
A35: Trenes | B35: =SUM(C35:AF35) -> 7379 | C35: =SUM(C14:C23) -> 294 | D35: =SUM(D14:D23) -> 296 | E35: =SUM(E14:E19) -> 287 | F35: =SUM(F14:F19) -> 293 | G35: =SUM(G14:G19) -> 291 | H35: =SUM(H14:H19) -> 146 | I35: =SUM(I14:I19) -> 114 | J35: =SUM(J14:J19) -> 285 | K35: =SUM(K14:K21) -> 284 | L35: =SUM(L14:L19) -> 280 | M35: =SUM(M14:M19) -> 286 | N35: =SUM(N14:N19) -> 284 | O35: =SUM(O14:O19) -> 146 | P35: =SUM(P14:P19) -> 114 | Q35: =SUM(Q14:Q19) -> 288 | R35: =SUM(R14:R19) -> 292 | S35: =SUM(S14:S19) -> 294 | ... AA35: =SUM(AA14:AA19) -> 280 | AB35: =SUM(AB14:AB23) -> 272 | AC35: =SUM(AC14:AC23) -> 146 | AD35: =SUM(AD14:AD23) -> 114 | AE35: =SUM(AE14:AE23) -> 295 | AF35: =SUM(AF14:AF23) -> 283
A36: Trenes KM | B36: =SUM(C36:AF36) -> 313692.23 | C36: =(C14*$B$14+C15*$B$15+C16*$B$16+C17*$B$17+C19*$B$19+C22*B22+C23*B23+C26*$B$26+C18*$B$18+C25*$B$25+C27*B27+C29*B29) -> 12546.87 | D36: =(D14*$B$14+D15*$B$15+D16*$B$16+D17*$B$17+D19*$B$19+D22*B22+D23*B23+D26*$B$26+D18*$B$18+D25*$B$25+D27*B27+D29*B29) -> 12646.08 | E36: =(E14*$B$14+E15*$B$15+E16*$B$16+E17*$B$17+E19*$B$19+E26*$B$26+E18*$B$18+E25*$B$25+E27*B27+E28*B28) -> 12240.18 | F36: =(F14*$B$14+F15*$B$15+F16*$B$16+F17*$B$17+F19*$B$19+F26*$B$26+F18*$B$18+F25*$B$25+F29*B29) -> 12516.69 | G36: =(G14*$B$14+G15*$B$15+G16*$B$16+G17*$B$17+G19*$B$19+G26*$B$26+G18*$B$18+G25*$B$25+G27*B27+G28*B28+G29*B29) -> 12430.43 | H36: =(H14*$B$14+H15*$B$15+H16*$B$16+H17*$B$17+H19*$B$19+H26*$B$26+H18*$B$18+H25*$B$25+H27*B27+H28*B28+H29*B29) -> 6296.98 | I36: =(I14*$B$14+I15*$B$15+I16*$B$16+I17*$B$17+I19*$B$19+I26*$B$26+I18*$B$18+I25*$B$25+I27*B27+I28*B28+I29*B29) -> 4916.82 | J36: =(J14*$B$14+J15*$B$15+J16*$B$16+J17*$B$17+J19*$B$19+J26*$B$26+J18*$B$18+J25*$B$25+J27*B27+J28*B28+J29*B29) -> 12107.9 | K36: =(K14*$B$14+K15*$B$15+K16*$B$16+K17*$B$17+K19*$B$19+K26*$B$26+K18*$B$18+K25*$B$25+K27*B27+K28*B28+K29*B29) -> 12087.78 | L36: =(L14*$B$14+L15*$B$15+L16*$B$16+L17*$B$17+L19*$B$19+L26*$B$26+L18*$B$18+L25*$B$25+L27*B27+L28*B28+L29*B29) -> 11856.79 | M36: =(M14*$B$14+M15*$B$15+M16*$B$16+M17*$B$17+M19*$B$19+M26*$B$26+M18*$B$18+M25*$B$25+M29*B29) -> 12125.63 | N36: =(N14*$B$14+N15*$B$15+N16*$B$16+N17*$B$17+N19*$B$19+N26*$B$26+N18*$B$18+N25*$B$25+N27*B27+N28*B28+N29*B29) -> 12001.52 | O36: =(O14*$B$14+O15*$B$15+O16*$B$16+O17*$B$17+O19*$B$19+O26*$B$26+O18*$B$18+O25*$B$25+O29*B29) -> 6296.98 | P36: =(P14*$B$14+P15*$B$15+P16*$B$16+P17*$B$17+P19*$B$19+P26*$B$26+P18*$B$18+P25*$B$25+P29*B29) -> 4916.82 | Q36: =(Q14*$B$14+Q15*$B$15+Q16*$B$16+Q17*$B$17+Q19*$B$19+Q26*$B$26+Q18*$B$18+Q25*$B$25+Q29*B29) -> 12217.17 | R36: =(R14*$B$14+R15*$B$15+R16*$B$16+R17*$B$17+R19*$B$19+R26*$B$26+R18*$B$18+R25*$B$25+R29*B29) -> 12364.29 | S36: =(S14*$B$14+S15*$B$15+S16*$B$16+S17*$B$17+S19*$B$19+S26*$B$26+S18*$B$18+S25*$B$25+S29*$B$29) -> 12475.95 | T36: =(T14*$B$14+T15*$B$15+T16*$B$16+T17*$B$17+T19*$B$19+T26*$B$26+T18*$B$18+T25*$B$25+T29*$B$29) -> 12597.67 | U36: =(U14*$B$14+U15*$B$15+U16*$B$16+U17*$B$17+U19*$B$19+U26*$B$26+U18*$B$18+U25*$B$25+U29*$B$29) -> 12130.91 | V36: =(V14*$B$14+V15*$B$15+V16*$B$16+V17*$B$17+V19*$B$19+V26*$B$26+V18*$B$18+V25*$B$25+V29*$B$29) -> 6296.98 | W36: =(W14*$B$14+W15*$B$15+W16*$B$16+W17*$B$17+W19*$B$19+W26*$B$26+W18*$B$18+W25*$B$25+W29*$B$29) -> 4916.82 | X36: =(X14*$B$14+X15*$B$15+X16*$B$16+X17*$B$17+X19*$B$19+X26*$B$26+X18*$B$18+X25*$B$25+X29*$B$29) -> 12285.7 | Y36: =(Y14*$B$14+Y15*$B$15+Y16*$B$16+Y17*$B$17+Y19*$B$19+Y26*$B$26+Y18*$B$18+Y25*$B$25+Y29*$B$29) -> 12217.17 | Z36: =(Z14*$B$14+Z15*$B$15+Z16*$B$16+Z17*$B$17+Z19*$B$19+Z26*$B$26+Z18*$B$18+Z25*$B$25+Z29*$B$29) -> 12278.03 | ... AF36: =(AF14*$B$14+AF15*$B$15+AF16*$B$16+AF17*$B$17+AF19*$B$19+AF26*$B$26+AF18*$B$18+AF25*$B$25+AF29*$B$29) -> 11893.57
A37: Servicios KM | B37: =SUM(C37:AF37) -> 216029.75 | C37: =$B$5*C5+$B$6*C6+$B$7*C7+$B$8*C8+$B$10*C10+$B$9*C9+C11*B11+C12*B12 -> 7904.17 | D37: =$B$5*D5+$B$6*D6+$B$7*D7+$B$8*D8+$B$10*D10+$B$9*D9+D11*B11+D12*B12 -> 7904.17 | E37: =$B$5*E5+$B$6*E6+$B$7*E7+$B$8*E8+$B$10*E10+$B$9*E9 -> 7861.04 | F37: =$B$5*F5+$B$6*F6+$B$7*F7+$B$8*F8+$B$10*F10+$B$9*F9 -> 7904.17 | G37: =$B$5*G5+$B$6*G6+$B$7*G7+$B$8*G8+$B$10*G10+$B$9*G9 -> 7861.04 | H37: =$B$5*H5+$B$6*H6+$B$7*H7+$B$8*H8+$B$10*H10+$B$9*H9 -> 6167.59 | I37: =$B$5*I5+$B$6*I6+$B$7*I7+$B$8*I8+$B$10*I10+$B$9*I9 -> 4787.43 | J37: =$B$5*J5+$B$6*J6+$B$7*J7+$B$8*J8+$B$10*J10+$B$9*J9 -> 7904.17 | K37: =$B$5*K5+$B$6*K6+$B$7*K7+$B$8*K8+$B$10*K10+$B$9*K9 -> 7904.17 | L37: =$B$5*L5+$B$6*L6+$B$7*L7+$B$8*L8+$B$10*L10+$B$9*L9 -> 7904.17 | ... AA37: =$B$5*AA5+$B$6*AA6+$B$7*AA7+$B$8*AA8+$B$10*AA10+$B$9*AA9 -> 7386.61 | AB37: =$B$5*AB5+$B$6*AB6+$B$7*AB7+$B$8*AB8+$B$10*AB10+$B$9*AB9+AB11*B11+AB12*B12 -> 7386.61 | AC37: =$B$5*AC5+$B$6*AC6+$B$7*AC7+$B$8*AC8+$B$10*AC10+$B$9*AC9+AC11*B11+AC12*B12 -> 6167.59 | AD37: =$B$5*AD5+$B$6*AD6+$B$7*AD7+$B$8*AD8+$B$10*AD10+$B$9*AD9+AD11*B11+AD12*B12 -> 4787.43 | AE37: =$B$5*AE5+$B$6*AE6+$B$7*AE7+$B$8*AE8+$B$10*AE10+$B$9*AE9+AE11*B11+AE12*B12 -> 7904.17 | AF37: =$B$5*AF5+$B$6*AF6+$B$7*AF7+$B$8*AF8+$B$10*AF10+$B$9*AF9+AF11*C11+AF12*C12 -> 7386.61
A38: Asientos KM | B38: =SUM(C38:AF38) -> 32623992 | C38: =C36*104 -> 1304874.5 | D38: =D36*104 -> 1315192.3 | E38: =E36*104 -> 1272978.7 | F38: =F36*104 -> 1301735.8 | G38: =G36*104 -> 1292764.7 | H38: =H36*104 -> 654885.92 | I38: =I36*104 -> 511349.28 | J38: =J36*104 -> 1259221.6 | ... AF38: =AF36*104 -> 1236931.3
A39: Coches KM | B39: =SUM(C39:AF39) -> 627384.46 | C39: =C36*2 -> 25093.74 | D39: =D36*2 -> 25292.16 | E39: =E36*2 -> 24480.36 | F39: =F36*2 -> 25033.38 | G39: =G36*2 -> 24860.86 | H39: =H36*2 -> 12593.96 | I39: =I36*2 -> 9833.64 | J39: =J36*2 -> 24215.8 | ... AF39: =AF36*2 -> 23787.14
A40: Capacidad Total | B40: =SUM(C40:AF40) -> 2671198 | C40: =+C35*362 -> 106428 | D40: =+D35*362 -> 107152 | E40: =+E35*362 -> 103894 | F40: =+F35*362 -> 106066 | G40: =+G35*362 -> 105342 | H40: =+H35*362 -> 52852 | I40: =+I35*362 -> 41268 | J40: =+J35*362 -> 103170 | ... AF40: =+AF35*362 -> 102446
A41: Ton Km Brutas | B41: =SUM(C41:AF41) -> 24875794 | C41: =C36*79.3 -> 994966.79 | D41: =D36*79.3 -> 1002834.1 | E41: =E36*79.3 -> 970646.27 | F41: =F36*79.3 -> 992573.52 | G41: =G36*79.3 -> 985733.1 | H41: =H36*79.3 -> 499350.51 | I41: =I36*79.3 -> 389903.83 | J41: =J36*79.3 -> 960156.47 | ... AF41: =AF36*79.3 -> 943160.1
E47: 313692.23

Sheet Data Ocupacion
D1: 45383 | F1: 45384 | H1: 45385 | J1: 45386 | L1: 45387 | N1: 45388 | P1: 45389 | R1: 45390 | T1: 45391 | V1: 45392 | X1: 45393 | Z1: 45394 | AB1: 45395 | AD1: 45396 | AF1: 45397 | AH1: 45398 | AJ1: 45399 | AL1: 45400 | AN1: 45401 | AP1: 45402 | AR1: 45403 | AT1: 45404 | AV1: 45405 | AX1: 45406 | AZ1: 45407 | BB1: 45408 | BD1: 45409 | BF1: 45410 | BH1: 45411 | BJ1: 45412
D2: S | E2: M | F2: S | G2: M | H2: S | I2: M | J2: S | K2: M | L2: S | M2: M | N2: S | O2: M | P2: S | Q2: M | R2: S | S2: M | T2: S | U2: M | V2: S | W2: M | X2: S | Y2: M | Z2: S | AA2: M | AB2: S | AC2: M | AD2: S | AE2: M | AF2: S | AG2: M | AH2: S | AI2: M | AJ2: S | AK2: M | AL2: S | AM2: M | AN2: S | AO2: M | AP2: S | AQ2: M | AR2: S | AS2: M | AT2: S | AU2: M | AV2: S | AW2: M | AX2: S | AY2: M | AZ2: S | BA2: M | BB2: S | BC2: M | BD2: S | BE2: M | BF2: S | BG2: M | BH2: S | BI2: M | BJ2: S | BK2: M
A3: Servicios PU-SA | D3: 0 | E3: 0 | F3: 0 | G3: 0 | H3: 0 | I3: 0 | J3: 0 | K3: 0 | L3: 0 | M3: 0 | N3: 0 | O3: 0 | P3: 0 | Q3: 0 | R3: 0 | S3: 0 | T3: 0 | U3: 0 | V3: 0 | W3: 0 | X3: 0 | Y3: 0 | Z3: 0 | AA3: 0 | AB3: 0 | AC3: 0 | AD3: 0 | AE3: 0 | AF3: 0 | AG3: 0 | AH3: 0 | AI3: 0 | AJ3: 0 | AK3: 0 | AL3: 0 | AM3: 0 | AN3: 0 | AO3: 0 | AP3: 0 | AQ3: 0 | AR3: 0 | AS3: 0 | AT3: 0 | AU3: 0 | AV3: 0 | AW3: 0 | AX3: 0 | AY3: 0 | AZ3: 0 | BA3: 0 | BB3: 0 | BC3: 0 | BD3: 0 | BE3: 0 | BF3: 0 | BG3: 0 | BH3: 0 | BI3: 0 | BJ3: 0 | BK3: 0
A4: Servicios PU-EB | D4: 0 | E4: 0 | F4: 0 | G4: 0 | H4: 0 | I4: 0 | J4: 0 | K4: 0 | L4: 0 | M4: 0 | N4: 0 | O4: 0 | P4: 0 | Q4: 0 | R4: 0 | S4: 0 | T4: 0 | U4: 0 | V4: 0 | W4: 0 | X4: 0 | Y4: 0 | Z4: 0 | AA4: 0 | AB4: 0 | AC4: 0 | AD4: 0 | AE4: 0 | AF4: 0 | AG4: 0 | AH4: 0 | AI4: 0 | AJ4: 0 | AK4: 0 | AL4: 0 | AM4: 0 | AN4: 0 | AO4: 0 | AP4: 0 | AQ4: 0 | AR4: 0 | AS4: 0 | AT4: 0 | AU4: 0 | AV4: 0 | AW4: 0 | AX4: 0 | AY4: 0 | AZ4: 0 | BA4: 0 | BB4: 0 | BC4: 0 | BD4: 0 | BE4: 0 | BF4: 0 | BG4: 0 | BH4: 0 | BI4: 0 | BJ4: 0 | BK4: 0
A5: Servicios PU-LI | D5: 1 | E5: 14 | F5: 1 | G5: 14 | H5: 2 | I5: 13 | J5: 1 | K5: 14 | L5: 1 | M5: 14 | N5: 0 | O5: 0 | P5: 0 | Q5: 0 | R5: 1 | S5: 14 | T5: 3 | U5: 12 | V5: 5 | W5: 10 | X5: 3 | Y5: 12 | Z5: 3 | AA5: 12 | AB5: 0 | AC5: 0 | AD5: 0 | AE5: 0 | AF5: 2 | AG5: 13 | AH5: 3 | AI5: 12 | AJ5: 1 | AK5: 14 | AL5: 1 | AM5: 14 | AN5: 1 | AO5: 14 | AP5: 0 | AQ5: 0 | AR5: 0 | AS5: 0 | AT5: 1 | AU5: 14 | AV5: 1 | AW5: 14 | AX5: 1 | AY5: 14 | AZ5: 1 | BA5: 14 | BB5: 1 | BC5: 11 | BD5: 0 | BE5: 0 | BF5: 0 | BG5: 0 | BH5: 1 | BI5: 14 | BJ5: 0 | BK5: 12
A6: Servicios SA-PU | D6: 0 | E6: 0 | F6: 0 | G6: 0 | H6: 0 | I6: 0 | J6: 0 | K6: 0 | L6: 0 | M6: 0 | N6: 0 | O6: 0 | P6: 0 | Q6: 0 | R6: 0 | S6: 0 | T6: 0 | U6: 0 | V6: 0 | W6: 0 | X6: 0 | Y6: 0 | Z6: 0 | AA6: 0 | AB6: 0 | AC6: 0 | AD6: 0 | AE6: 0 | AF6: 0 | AG6: 0 | AH6: 0 | AI6: 0 | AJ6: 0 | AK6: 0 | AL6: 0 | AM6: 0 | AN6: 0 | AO6: 0 | AP6: 0 | AQ6: 0 | AR6: 0 | AS6: 0 | AT6: 0 | AU6: 0 | AV6: 0 | AW6: 0 | AX6: 0 | AY6: 0 | AZ6: 0 | BA6: 0 | BB6: 0 | BC6: 0 | BD6: 0 | BE6: 0 | BF6: 0 | BG6: 0 | BH6: 0 | BI6: 0 | BJ6: 0 | BK6: 0
A7: Servicios EB-PU | D7: 0 | E7: 0 | F7: 0 | G7: 0 | H7: 0 | I7: 0 | J7: 0 | K7: 0 | L7: 0 | M7: 0 | N7: 0 | O7: 0 | P7: 0 | Q7: 0 | R7: 0 | S7: 0 | T7: 0 | U7: 0 | V7: 0 | W7: 0 | X7: 0 | Y7: 0 | Z7: 0 | AA7: 0 | AB7: 0 | AC7: 0 | AD7: 0 | AE7: 0 | AF7: 0 | AG7: 0 | AH7: 0 | AI7: 0 | AJ7: 0 | AK7: 0 | AL7: 0 | AM7: 0 | AN7: 0 | AO7: 0 | AP7: 0 | AQ7: 0 | AR7: 0 | AS7: 0 | AT7: 0 | AU7: 0 | AV7: 0 | AW7: 0 | AX7: 0 | AY7: 0 | AZ7: 0 | BA7: 0 | BB7: 0 | BC7: 0 | BD7: 0 | BE7: 0 | BF7: 0 | BG7: 0 | BH7: 0 | BI7: 0 | BJ7: 0 | BK7: 0
A8: Servicios LI-PU | D8: 3 | E8: 11 | F8: 3 | G8: 11 | H8: 4 | I8: 10 | J8: 3 | K8: 11 | L8: 3 | M8: 11 | N8: 0 | O8: 0 | P8: 0 | Q8: 0 | R8: 3 | S8: 11 | T8: 5 | U8: 9 | V8: 7 | W8: 7 | X8: 5 | Y8: 9 | Z8: 5 | AA8: 9 | AB8: 0 | AC8: 0 | AD8: 0 | AE8: 0 | AF8: 4 | AG8: 10 | AH8: 5 | AI8: 9 | AJ8: 3 | AK8: 11 | AL8: 3 | AM8: 11 | AN8: 4 | AO8: 10 | AP8: 0 | AQ8: 0 | AR8: 0 | AS8: 0 | AT8: 3 | AU8: 11 | AV8: 3 | AW8: 11 | AX8: 3 | AY8: 11 | AZ8: 2 | BA8: 11 | BB8: 0 | BC8: 10 | BD8: 0 | BE8: 0 | BF8: 0 | BG8: 0 | BH8: 3 | BI8: 11 | BJ8: 0 | BK8: 10
A10: Servicios PU-SA | D10: 0 | E10: 0 | F10: 0 | G10: 0 | H10: 0 | I10: 0 | J10: 0 | K10: 0 | L10: 0 | M10: 0 | N10: 0 | O10: 0 | P10: 0 | Q10: 0 | R10: 0 | S10: 0 | T10: 0 | U10: 0 | V10: 0 | W10: 0 | X10: 0 | Y10: 0 | Z10: 0 | AA10: 0 | AB10: 0 | AC10: 0 | AD10: 0 | AE10: 0 | AF10: 0 | AG10: 0 | AH10: 0 | AI10: 0 | AJ10: 0 | AK10: 0 | AL10: 0 | AM10: 0 | AN10: 0 | AO10: 0 | AP10: 0 | AQ10: 0 | AR10: 0 | AS10: 0 | AT10: 0 | AU10: 0 | AV10: 0 | AW10: 0 | AX10: 0 | AY10: 0 | AZ10: 0 | BA10: 0 | BB10: 0 | BC10: 0 | BD10: 0 | BE10: 0 | BF10: 0 | BG10: 0 | BH10: 0 | BI10: 0 | BJ10: 0 | BK10: 0
A11: Servicios PU-EB | D11: 0 | E11: 0 | F11: 0 | G11: 0 | H11: 0 | I11: 0 | J11: 0 | K11: 0 | L11: 0 | M11: 0 | N11: 0 | O11: 0 | P11: 0 | Q11: 0 | R11: 0 | S11: 0 | T11: 0 | U11: 0 | V11: 0 | W11: 0 | X11: 0 | Y11: 0 | Z11: 0 | AA11: 0 | AB11: 0 | AC11: 0 | AD11: 0 | AE11: 0 | AF11: 0 | AG11: 0 | AH11: 0 | AI11: 0 | AJ11: 0 | AK11: 0 | AL11: 0 | AM11: 0 | AN11: 0 | AO11: 0 | AP11: 0 | AQ11: 0 | AR11: 0 | AS11: 0 | AT11: 0 | AU11: 0 | AV11: 0 | AW11: 0 | AX11: 0 | AY11: 0 | AZ11: 0 | BA11: 0 | BB11: 0 | BC11: 0 | BD11: 0 | BE11: 0 | BF11: 0 | BG11: 0 | BH11: 0 | BI11: 0 | BJ11: 0 | BK11: 0
A12: Servicios PU-LI | D12: 34 | E12: 34 | F12: 32 | G12: 36 | H12: 37 | I12: 30 | J12: 35 | K12: 33 | L12: 35 | M12: 32 | N12: 67 | O12: 3 | P12: 51 | Q12: 3 | R12: 36 | S12: 32 | T12: 38 | U12: 30 | V12: 38 | W12: 30 | X12: 38 | Y12: 30 | Z12: 38 | AA12: 30 | AB12: 67 | AC12: 3 | AD12: 51 | AE12: 3 | AF12: 38 | AG12: 30 | AH12: 32 | AI12: 36 | AJ12: 34 | AK12: 34 | AL12: 30 | AM12: 38 | AN12: 39 | AO12: 29 | AP12: 67 | AQ12: 3 | AR12: 51 | AS12: 3 | AT12: 38 | AU12: 30 | AV12: 38 | AW12: 30 | AX12: 38 | AY12: 30 | AZ12: 26 | BA12: 35 | BB12: 35 | BC12: 31 | BD12: 67 | BE12: 3 | BF12: 51 | BG12: 3 | BH12: 33 | BI12: 35 | BJ12: 27 | BK12: 38
A13: Servicios SA-PU | D13: 1 | E13: 0 | F13: 1 | G13: 0 | H13: 1 | I13: 0 | J13: 1 | K13: 0 | L13: 1 | M13: 0 | N13: 0 | O13: 0 | P13: 0 | Q13: 0 | R13: 1 | S13: 0 | T13: 1 | U13: 0 | V13: 1 | W13: 0 | X13: 1 | Y13: 0 | Z13: 1 | AA13: 0 | AB13: 0 | AC13: 0 | AD13: 0 | AE13: 0 | AF13: 1 | AG13: 0 | AH13: 1 | AI13: 0 | AJ13: 1 | AK13: 0 | AL13: 1 | AM13: 0 | AN13: 1 | AO13: 0 | AP13: 0 | AQ13: 0 | AR13: 0 | AS13: 0 | AT13: 1 | AU13: 0 | AV13: 1 | AW13: 0 | AX13: 1 | AY13: 0 | AZ13: 1 | BA13: 0 | BB13: 1 | BC13: 0 | BD13: 0 | BE13: 0 | BF13: 0 | BG13: 0 | BH13: 1 | BI13: 0 | BJ13: 0 | BK13: 1
A14: Servicios EB-PU | D14: 1 | E14: 0 | F14: 1 | G14: 0 | H14: 1 | I14: 0 | J14: 1 | K14: 0 | L14: 1 | M14: 0 | N14: 0 | O14: 0 | P14: 0 | Q14: 0 | R14: 1 | S14: 0 | T14: 1 | U14: 0 | V14: 1 | W14: 0 | X14: 1 | Y14: 0 | Z14: 1 | AA14: 0 | AB14: 0 | AC14: 0 | AD14: 0 | AE14: 0 | AF14: 1 | AG14: 0 | AH14: 1 | AI14: 0 | AJ14: 1 | AK14: 0 | AL14: 1 | AM14: 0 | AN14: 1 | AO14: 0 | AP14: 0 | AQ14: 0 | AR14: 0 | AS14: 0 | AT14: 1 | AU14: 0 | AV14: 1 | AW14: 0 | AX14: 1 | AY14: 0 | AZ14: 1 | BA14: 0 | BB14: 1 | BC14: 0 | BD14: 0 | BE14: 0 | BF14: 0 | BG14: 0 | BH14: 1 | BI14: 0 | BJ14: 1 | BK14: 0
A15: Servicios LI-PU | D15: 33 | E15: 36 | F15: 33 | G15: 36 | H15: 33 | I15: 36 | J15: 33 | K15: 36 | L15: 33 | M15: 36 | N15: 73 | O15: 0 | P15: 57 | Q15: 0 | R15: 36 | S15: 33 | T15: 34 | U15: 35 | V15: 34 | W15: 35 | X15: 33 | Y15: 36 | Z15: 32 | AA15: 36 | AB15: 73 | AC15: 0 | AD15: 57 | AE15: 0 | AF15: 33 | AG15: 36 | AH15: 33 | AI15: 36 | AJ15: 33 | AK15: 36 | AL15: 32 | AM15: 37 | AN15: 34 | AO15: 35 | AP15: 73 | AQ15: 0 | AR15: 57 | AS15: 0 | AT15: 33 | AU15: 36 | AV15: 33 | AW15: 36 | AX15: 33 | AY15: 36 | AZ15: 30 | BA15: 34 | BB15: 33 | BC15: 34 | BD15: 73 | BE15: 0 | BF15: 57 | BG15: 0 | BH15: 33 | BI15: 36 | BJ15: 32 | BK15: 35
... A22: Servicios LI-PU | D22: 1 | E22: 6 | F22: 1 | G22: 6 | H22: 1 | I22: 6 | J22: 1 | K22: 6 | L22: 1 | M22: 6 | N22: 0 | O22: 0 | P22: 0 | Q22: 0 | R22: 1 | S22: 6 | T22: 1 | U22: 6 | V22: 1 | W22: 6 | X22: 1 | Y22: 6 | Z22: 1 | AA22: 6 | AB22: 0 | AC22: 0 | AD22: 0 | AE22: 0 | AF22: 1 | AG22: 6 | AH22: 1 | AI22: 6 | AJ22: 1 | AK22: 6 | AL22: 1 | AM22: 6 | AN22: 1 | AO22: 6 | AP22: 0 | AQ22: 0 | AR22: 0 | AS22: 0 | AT22: 1 | AU22: 6 | AV22: 1 | AW22: 6 | AX22: 1 | AY22: 6 | AZ22: 3 | BA22: 5 | BB22: 1 | BC22: 6 | BD22: 0 | BE22: 0 | BF22: 0 | BG22: 0 | BH22: 1 | BI22: 6 | BJ22: 1 | BK22: 6
D25: =SUM(D3:D22) -> 74 | E25: =SUM(E3:E22) -> 110 | F25: =SUM(F3:F22) -> 72 | G25: =SUM(G3:G22) -> 112 | H25: =SUM(H3:H22) -> 79 | I25: =SUM(I3:I22) -> 104 | J25: =SUM(J3:J22) -> 75 | K25: =SUM(K3:K22) -> 109 | ... BK25: =SUM(BK3:BK22) -> 111
A31: Km Servicio
A32: PU - LI | D32: =D5+D12+D19 -> 35 | E32: =E5+E12+E19 -> 57 | F32: =F5+F12+F19 -> 33 | G32: =G5+G12+G19 -> 59 | H32: =H5+H12+H19 -> 39 | I32: =I5+I12+I19 -> 52 | J32: =J5+J12+J19 -> 36 | K32: =K5+K12+K19 -> 56 | ... BK32: =BK5+BK12+BK19 -> 59
A33: LI - PU | D33: =D8+D15+D22 -> 37 | E33: =E8+E15+E22 -> 53 | F33: =F8+F15+F22 -> 37 | G33: =G8+G15+G22 -> 53 | H33: =H8+H15+H22 -> 38 | I33: =I8+I15+I22 -> 52 | J33: =J8+J15+J22 -> 37 | K33: =K8+K15+K22 -> 53 | ... BK33: =BK8+BK15+BK22 -> 51
A34: PU - SA | D34: =D3+D10+D17 -> 0 | E34: =E3+E10+E17 -> 0 | F34: =F3+F10+F17 -> 0 | G34: =G3+G10+G17 -> 0 | H34: =H3+H10+H17 -> 0 | I34: =I3+I10+I17 -> 0 | J34: =J3+J10+J17 -> 0 | K34: =K3+K10+K17 -> 0 | ... BK34: =BK3+BK10+BK17 -> 0
A35: SA - PU | D35: =D6+D13+D20 -> 1 | E35: =E6+E13+E20 -> 0 | F35: =F6+F13+F20 -> 1 | G35: =G6+G13+G20 -> 0 | H35: =H6+H13+H20 -> 1 | I35: =I6+I13+I20 -> 0 | J35: =J6+J13+J20 -> 1 | K35: =K6+K13+K20 -> 0 | ... BK35: =BK6+BK13+BK20 -> 1
A36: PU-EB | D36: =D4+D11+D18 -> 0 | E36: =E4+E11+E18 -> 0 | F36: =F4+F11+F18 -> 0 | G36: =G4+G11+G18 -> 0 | H36: =H4+H11+H18 -> 0 | I36: =I4+I11+I18 -> 0 | J36: =J4+J11+J18 -> 0 | K36: =K4+K11+K18 -> 0 | ... BK36: =BK4+BK11+BK18 -> 0
A37: EB-PU | D37: =D7+D14+D21 -> 1 | E37: =E7+E14+E21 -> 0 | F37: =F7+F14+F21 -> 1 | G37: =G7+G14+G21 -> 0 | H37: =H7+H14+H21 -> 1 | I37: =I7+I14+I21 -> 0 | J37: =J7+J14+J21 -> 1 | K37: =K7+K14+K21 -> 0 | ... BK37: =BK7+BK14+BK21 -> 0
A38: VM-LI
A39: VM-PU
A40: total | D40: =SUM(D32:D39) -> 74 | E40: =SUM(E32:E39) -> 110 | F40: =SUM(F32:F39) -> 72 | G40: =SUM(G32:G39) -> 112 | H40: =SUM(H32:H37) -> 79 | I40: =SUM(I32:I37) -> 104 | J40: =SUM(J32:J37) -> 75 | K40: =SUM(K32:K37) -> 109 | L40: =SUM(L32:L37) -> 75 | M40: =SUM(M32:M37) -> 108 | N40: =SUM(N32:N37) -> 140 | O40: =SUM(O32:O37) -> 3 | ... BA40: =SUM(BA32:BA37) -> 108 | BB40: =SUM(BB32:BB39) -> 72 | BC40: =SUM(BC32:BC39) -> 100 | BD40: =SUM(BD32:BD39) -> 140 | BE40: =SUM(BE32:BE39) -> 3 | BF40: =SUM(BF32:BF39) -> 108 | BG40: =SUM(BG32:BG39) -> 3 | BH40: =SUM(BH32:BH39) -> 73 | BI40: =SUM(BI32:BI39) -> 111 | ... BK40: =SUM(BK32:BK39) -> 111
A42: Servicios
A43: PU - LI | D43: =D5+E5+D12+E12+D19+E19 -> 92 | F43: =F5+G5+F12+G12+F19+G19 -> 92 | H43: =H5+I5+H12+I12+H19+I19 -> 91 | J43: =J5+K5+J12+K12+J19+K19 -> 92 | L43: =L5+M5+L12+M12+L19+M19 -> 91 | N43: =N5+O5+N12+O12+N19+O19 -> 70 | P43: =P5+Q5+P12+Q12+P19+Q19 -> 54 | R43: =R5+S5+R12+S12+R19+S19 -> 92 | T43: =T5+U5+T12+U12+T19+U19 -> 92 | V43: =V5+W5+V12+W12+V19+W19 -> 92 | X43: =X5+Y5+X12+Y12+X19+Y19 -> 92 | Z43: =Z5+AA5+Z12+AA12+Z19+AA19 -> 92 | AB43: =AB5+AC5+AB12+AC12+AB19+AC19 -> 70 | AD43: =AD5+AE5+AD12+AE12+AD19+AE19 -> 54 | AF43: =AF5+AG5+AF12+AG12+AF19+AG19 -> 92 | AH43: =AH5+AI5+AH12+AI12+AH19+AI19 -> 92 | AJ43: =AJ5+AK5+AJ12+AK12+AJ19+AK19 -> 92 | AL43: =AL5+AM5+AL12+AM12+AL19+AM19 -> 92 | AN43: =AN5+AO5+AN12+AO12+AN19+AO19 -> 92 | AP43: =AP5+AQ5+AP12+AQ12+AP19+AQ19 -> 70 | AR43: =AR5+AS5+AR12+AS12+AR19+AS19 -> 54 | AT43: =AT5+AU5+AT12+AU12+AT19+AU19 -> 92 | AV43: =AV5+AW5+AV12+AW12+AV19+AW19 -> 92 | AX43: =AX5+AY5+AX12+AY12+AX19+AY19 -> 92 | AZ43: =AZ5+BA5+AZ12+BA12+AZ19+BA19 -> 85 | BB43: =BB5+BC5+BB12+BC12+BB19+BC19 -> 86 | BD43: =BD5+BE5+BD12+BE12+BD19+BE19 -> 70 | BF43: =BF5+BG5+BF12+BG12+BF19+BG19 -> 54 | BH43: =BH5+BI5+BH12+BI12+BH19+BI19 -> 92 | BJ43: =BJ5+BK5+BJ12+BK12+BJ19+BK19 -> 86
