Workbook

Sheet Odometro-Kilometraje
A1: Control Contador Kilometraje de Trenes
B2: 45870 | C2: 45871 | D2: 45872 | E2: 45873 | F2: 45874 | G2: 45875 | H2: 45876 | I2: 45877 | J2: 45878 | K2: 45879 | L2: 45880 | M2: 45881 | N2: 45882 | O2: 45883 | P2: 45884 | Q2: 45885 | R2: 45886 | S2: 45887 | T2: 45888 | U2: 45889 | V2: 45890 | W2: 45891 | X2: 45892 | Y2: 45893 | Z2: 45894 | AA2: 45895 | AB2: 45896 | AC2: 45897 | AD2: 45898 | AE2: 45899 | AF2: 45900
B3: Contador | C3: Contador | D3: Contador | E3: Contador | F3: Contador | G3: Contador | H3: Contador | I3: Contador | J3: Contador | K3: Contador | L3: Contador | M3: Contador | N3: Contador | O3: Contador | P3: Contador | Q3: Contador | R3: Contador | S3: Contador | T3: Contador | U3: Contador | V3: Contador | W3: Contador | X3: Contador | Y3: Contador | Z3: Contador | AA3: Contador | AB3: Contador | AC3: Contador | AD3: Contador | AE3: Contador | AF3: Contador
A4: Tren | B4: Odómetro | C4: Odómetro | D4: Odómetro | E4: Odómetro | F4: Odómetro | G4: Odómetro | H4: Odómetro | I4: Odómetro | J4: Odómetro | K4: Odómetro | L4: Odómetro | M4: Odómetro | N4: Odómetro | O4: Odómetro | P4: Odómetro | Q4: Odómetro | R4: Odómetro | S4: Odómetro | T4: Odómetro | U4: Odómetro | V4: Odómetro | W4: Odómetro | X4: Odómetro | Y4: Odómetro | Z4: Odómetro | AA4: Odómetro | AB4: Odómetro | AC4: Odómetro | AD4: Odómetro | AE4: Odómetro | AF4: Odómetro
A5: M01 | B5: 2029259 | C5: 2029819 | D5: 2030293 | E5: 2030853 | F5: 2031165 | G5: 2031725 | H5: 2032328 | I5: 2032892 | J5: 2032935 | K5: 2033411 | L5: 2033971 | M5: 2034171 | N5: 2034303 | O5: 2034676 | P5: 2034676 | Q5: 2034676 | R5: 2034676 | S5: 2034871 | T5: 2035440 | U5: 2035874 | V5: 2036477 | W5: 2037038 | X5: 2037339 | Y5: 2037684 | Z5: 2037825 | AA5: 2038258 | AB5: 2038861 | AC5: 2039424 | AD5: 2039607 | AE5: 2039607 | AF5: 2039607
A6: M02 | B6: 2001728 | C6: 2001773 | D6: 2001778 | E6: 2001981 | F6: 2002568 | G6: 2003089 | H6: 2003650 | I6: 2003833 | J6: 2003833 | K6: 2003884 | L6: 2004100 | M6: 2004229 | N6: 2004480 | O6: 2004730 | P6: 2004730 | Q6: 2004730 | R6: 2004730 | S6: 2004984 | T6: 2005295 | U6: 2005562 | V6: 2005791 | W6: 2006395 | X6: 2006654 | Y6: 2007172 | Z6: 2007776 | AA6: 2008126 | AB6: 2008388 | AC6: 2008838 | AD6: 2009006 | AE6: 2009567 | AF6: 2009961
A7: M03 | B7: 2089968 | C7: 2089968 | D7: 2089968 | E7: 2090183 | F7: 2090417 | G7: 2090507 | H7: 2090757 | I7: 2090949 | J7: 2090949 | K7: 2090968 | L7: 2091401 | M7: 2091605 | N7: 2091857 | O7: 2092116 | P7: 2092159 | Q7: 2092678 | R7: 2092765 | S7: 2093286 | T7: 2093525 | U7: 2093615 | V7: 2094092 | W7: 2094351 | X7: 2094830 | Y7: 2094874 | Z7: 2095439 | AA7: 2095924 | AB7: 2096316 | AC7: 2096881 | AD7: 2097188 | AE7: 2097793 | AF7: 2098311
A8: M04 | B8: 2087225 | C8: 2087225 | D8: 2087225 | E8: 2087420 | F8: 2087852 | G8: 2088125 | H8: 2088687 | I8: 2089121 | J8: 2089686 | K8: 2089729 | L8: 2090097 | M8: 2090347 | N8: 2090602 | O8: 2090806 | P8: 2090806 | Q8: 2090806 | R8: 2090806 | S8: 2091059 | T8: 2091578 | U8: 2092183 | V8: 2092504 | W8: 2092719 | X8: 2092719 | Y8: 2092850 | Z8: 2093070 | AA8: 2093524 | AB8: 2094052 | AC8: 2094297 | AD8: 2094550 | AE8: 2094550 | AF8: 2094550
A9: M05 | B9: 1999805 | C9: 2000323 | D9: 2000841 | E9: 2001125 | F9: 2001376 | G9: 2001647 | H9: 2002122 | I9: 2002468 | J9: 2002986 | K9: 2003503 | L9: 2004063 | M9: 2004470 | N9: 2004664 | O9: 2004916 | P9: 2005347 | Q9: 2005779 | R9: 2006256 | S9: 2006816 | T9: 2007096 | U9: 2007349 | V9: 2007577 | W9: 2007584 | X9: 2007629 | Y9: 2007631 | Z9: 2008021 | AA9: 2008191 | AB9: 2008711 | AC9: 2008972 | AD9: 2009230 | AE9: 2009230 | AF9: 2009230
A10: M06 | B10: 2109961 | C10: 2109961 | D10: 2109967 | E10: 2110142 | F10: 2110592 | G10: 2110664 | H10: 2111098 | I10: 2111551 | J10: 2111551 | K10: 2111551 | L10: 2111857 | M10: 2112035 | N10: 2112555 | O10: 2113006 | P10: 2113006 | Q10: 2113006 | R10: 2113006 | S10: 2113320 | T10: 2113880 | U10: 2114356 | V10: 2114586 | W10: 2114772 | X10: 2114772 | Y10: 2114772 | Z10: 2115112 | AA10: 2115564 | AB10: 2115759 | AC10: 2116244 | AD10: 2116763 | AE10: 2117281 | AF10: 2117756
A11: M07 | B11: 2140680 | C11: 2141258 | D11: 2141779 | E11: 2142300 | F11: 2142737 | G11: 2142913 | H11: 2143092 | I11: 2143531 | J11: 2143531 | K11: 2143531 | L11: 2144141 | M11: 2144580 | N11: 2145103 | O11: 2145376 | P11: 2145376 | Q11: 2145376 | R11: 2145376 | S11: 2145642 | T11: 2145813 | U11: 2146216 | V11: 2146559 | W11: 2146744 | X11: 2146744 | Y11: 2146744 | Z11: 2147267 | AA11: 2147498 | AB11: 2148019 | AC11: 2148542 | AD11: 2149066 | AE11: 2149630 | AF11: 2150110
A12: M08 | B12: 2045923 | C12: 2045923 | D12: 2045923 | E12: 2046176 | F12: 2046447 | G12: 2046639 | H12: 2046889 | I12: 2047081 | J12: 2047081 | K12: 2047081 | L12: 2047275 | M12: 2047525 | N12: 2047776 | O12: 2048027 | P12: 2048027 | Q12: 2048027 | R12: 2048027 | S12: 2048324 | T12: 2048570 | U12: 2048821 | V12: 2049073 | W12: 2049203 | X12: 2049203 | Y12: 2049203 | Z12: 2049519 | AA12: 2050081 | AB12: 2050687 | AC12: 2051250 | AD12: 2051455 | AE12: 2051455 | AF12: 2051476
A13: M09 | B13: 2028407 | C13: 2028407 | D13: 2028407 | E13: 2028407 | F13: 2028447 | G13: 2028762 | H13: 2028939 | I13: 2029501 | J13: 2030018 | K13: 2030496 | L13: 2031056 | M13: 2031576 | N13: 2032017 | O13: 2032620 | P13: 2032622 | Q13: 2033185 | R13: 2033229 | S13: 2033663 | T13: 2034119 | U13: 2034370 | V13: 2034687 | W13: 2034796 | X13: 2034796 | Y13: 2034796 | Z13: 2035047 | AA13: 2035359 | AB13: 2035792 | AC13: 2036355 | AD13: 2036914 | AE13: 2037432 | AF13: 2037949
A14: M10 | B14: 2101478 | C14: 2101478 | D14: 2101479 | E14: 2101479 | F14: 2101479 | G14: 2101479 | H14: 2101479 | I14: 2101479 | J14: 2101479 | K14: 2101479 | L14: 2101479 | M14: 2101479 | N14: 2101479 | O14: 2101586 | P14: 2101586 | Q14: 2101586 | R14: 2101586 | S14: 2101779 | T14: 2102030 | U14: 2102281 | V14: 2102614 | W14: 2102867 | X14: 2103428 | Y14: 2103902 | Z14: 2104506 | AA14: 2104958 | AB14: 2105151 | AC14: 2105402 | AD14: 2105654 | AE14: 2105654 | AF14: 2105654
A15: M11 | B15: 2120684 | C15: 2121205 | D15: 2121683 | E15: 2121955 | F15: 2122208 | G15: 2122472 | H15: 2122726 | I15: 2122990 | J15: 2123554 | K15: 2123598 | L15: 2123950 | M15: 2124404 | N15: 2124590 | O15: 2124845 | P15: 2125367 | Q15: 2125890 | R15: 2126364 | S15: 2126675 | T15: 2127153 | U15: 2127564 | V15: 2127809 | W15: 2128048 | X15: 2128048 | Y15: 2128048 | Z15: 2128301 | AA15: 2128556 | AB15: 2128840 | AC15: 2129036 | AD15: 2129289 | AE15: 2129289 | AF15: 2129310
A16: M12 | B16: 1967557 | C16: 1968079 | D16: 1968557 | E16: 1968810 | F16: 1969009 | G16: 1969444 | H16: 1969554 | I16: 1969798 | J16: 1970316 | K16: 1970749 | L16: 1970890 | M16: 1971409 | N16: 1972014 | O16: 1972277 | P16: 1972795 | Q16: 1973357 | R16: 1973400 | S16: 1973770 | T16: 1974145 | U16: 1974752 | V16: 1975211 | W16: 1975523 | X16: 1976042 | Y16: 1976563 | Z16: 1976834 | AA16: 1977087 | AB16: 1977339 | AC16: 1977832 | AD16: 1978137 | AE16: 1978702 | AF16: 1978746
... A39: XM35 | B39: 676576 | C39: 676576 | D39: 676576 | E39: 676834 | F39: 677096 | G39: 677613 | H39: 677962 | I39: 678140 | J39: 678140 | K39: 678140 | L39: 678229 | M39: 678661 | N39: 678923 | O39: 679064 | P39: 679064 | Q39: 679064 | R39: 679064 | S39: 679496 | T39: 679587 | U39: 679976 | V39: 680541 | W39: 681145 | X39: 681666 | Y39: 681668 | Z39: 682230 | AA39: 682707 | AB39: 682849 | AC39: 683115 | AD39: 683461 | AE39: 683461 | AF39: 683461
A41: Kilometraje Diario Recorrido
B42: 45870 | C42: 45871 | D42: 45872 | E42: 45873 | F42: 45874 | G42: 45875 | H42: 45876 | I42: 45877 | J42: 45878 | K42: 45879 | L42: 45880 | M42: 45881 | N42: 45882 | O42: 45883 | P42: 45884 | Q42: 45885 | R42: 45886 | S42: 45887 | T42: 45888 | U42: 45889 | V42: 45890 | W42: 45891 | X42: 45892 | Y42: 45893 | Z42: 45894 | AA42: 45895 | AB42: 45896 | AC42: 45897 | AD42: 45898 | AE42: 45899 | AF42: 45900
B43: Kilometraje | C43: Kilometraje | D43: Kilometraje | E43: Kilometraje | F43: Kilometraje | G43: Kilometraje | H43: Kilometraje | I43: Kilometraje | J43: Kilometraje | K43: Kilometraje | L43: Kilometraje | M43: Kilometraje | N43: Kilometraje | O43: Kilometraje | P43: Kilometraje | Q43: Kilometraje | R43: Kilometraje | S43: Kilometraje | T43: Kilometraje | U43: Kilometraje | V43: Kilometraje | W43: Kilometraje | X43: Kilometraje | Y43: Kilometraje | Z43: Kilometraje | AA43: Kilometraje | AB43: Kilometraje | AC43: Kilometraje | AD43: Kilometraje | AE43: Kilometraje | AF43: Kilometraje
A44: Tren | B44: Diario | C44: Diario | D44: Diario | E44: Diario | F44: Diario | G44: Diario | H44: Diario | I44: Diario | J44: Diario | K44: Diario | L44: Diario | M44: Diario | N44: Diario | O44: Diario | P44: Diario | Q44: Diario | R44: Diario | S44: Diario | T44: Diario | U44: Diario | V44: Diario | W44: Diario | X44: Diario | Y44: Diario | Z44: Diario | AA44: Diario | AB44: Diario | AC44: Diario | AD44: Diario | AE44: Diario | AF44: Diario
A45: M01 | B45: 570 | C45: =C5-B5 -> 560 | D45: =D5-C5 -> 474 | E45: =E5-D5 -> 560 | F45: =F5-E5 -> 312 | G45: =G5-F5 -> 560 | H45: =H5-G5 -> 603 | I45: =I5-H5 -> 564 | J45: =J5-I5 -> 43 | ... AF45: =AF5-AE5 -> 0
A46: M02 | B46: 562 | C46: =C6-B6 -> 45 | D46: =D6-C6 -> 5 | E46: =E6-D6 -> 203 | F46: =F6-E6 -> 587 | G46: =G6-F6 -> 521 | H46: =H6-G6 -> 561 | I46: =I6-H6 -> 183 | J46: =J6-I6 -> 0 | ... AF46: =AF6-AE6 -> 394
A47: M03 | B47: 0 | C47: =C7-B7 -> 0 | D47: =D7-C7 -> 0 | E47: =E7-D7 -> 215 | F47: =F7-E7 -> 234 | G47: =G7-F7 -> 90 | H47: =H7-G7 -> 250 | I47: =I7-H7 -> 192 | J47: =J7-I7 -> 0 | ... AF47: =AF7-AE7 -> 518
A48: M04 | B48: 216 | C48: =C8-B8 -> 0 | D48: =D8-C8 -> 0 | E48: =E8-D8 -> 195 | F48: =F8-E8 -> 432 | G48: =G8-F8 -> 273 | H48: =H8-G8 -> 562 | I48: =I8-H8 -> 434 | J48: =J8-I8 -> 565 | ... AF48: =AF8-AE8 -> 0
A49: M05 | B49: 162 | C49: =C9-B9 -> 518 | D49: =D9-C9 -> 518 | E49: =E9-D9 -> 284 | F49: =F9-E9 -> 251 | G49: =G9-F9 -> 271 | H49: =H9-G9 -> 475 | I49: =I9-H9 -> 346 | J49: =J9-I9 -> 518 | ... AF49: =AF9-AE9 -> 0
A50: M06 | B50: 133 | C50: =C10-B10 -> 0 | D50: =D10-C10 -> 6 | E50: =E10-D10 -> 175 | F50: =F10-E10 -> 450 | G50: =G10-F10 -> 72 | H50: =H10-G10 -> 434 | I50: =I10-H10 -> 453 | J50: =J10-I10 -> 0 | ... AF50: =AF10-AE10 -> 475
A51: M07 | B51: 0 | C51: =C11-B11 -> 578 | D51: =D11-C11 -> 521 | E51: =E11-D11 -> 521 | F51: =F11-E11 -> 437 | G51: =G11-F11 -> 176 | H51: =H11-G11 -> 179 | I51: =I11-H11 -> 439 | J51: =J11-I11 -> 0 | ... AF51: =AF11-AE11 -> 480
A52: M08 | B52: 232 | C52: =C12-B12 -> 0 | D52: =D12-C12 -> 0 | E52: =E12-D12 -> 253 | F52: =F12-E12 -> 271 | G52: =G12-F12 -> 192 | H52: =H12-G12 -> 250 | I52: =I12-H12 -> 192 | J52: =J12-I12 -> 0 | ... AF52: =AF12-AE12 -> 21
A53: M09 | B53: 2 | C53: =C13-B13 -> 0 | D53: =D13-C13 -> 0 | E53: =E13-D13 -> 0 | F53: =F13-E13 -> 40 | G53: =G13-F13 -> 315 | H53: =H13-G13 -> 177 | I53: =I13-H13 -> 562 | J53: =J13-I13 -> 517 | ... AF53: =AF13-AE13 -> 517
A54: M10 | B54: 174 | C54: =C14-B14 -> 0 | D54: =D14-C14 -> 1 | E54: =E14-D14 -> 0 | F54: =F14-E14 -> 0 | G54: =G14-F14 -> 0 | H54: =H14-G14 -> 0 | I54: =I14-H14 -> 0 | J54: =J14-I14 -> 0 | ... AF54: =AF14-AE14 -> 0
A55: M11 | B55: 530 | C55: =C15-B15 -> 521 | D55: =D15-C15 -> 478 | E55: =E15-D15 -> 272 | F55: =F15-E15 -> 253 | G55: =G15-F15 -> 264 | H55: =H15-G15 -> 254 | I55: =I15-H15 -> 264 | J55: =J15-I15 -> 564 | ... AF55: =AF15-AE15 -> 21
A56: M12 | B56: 562 | C56: =C16-B16 -> 522 | D56: =D16-C16 -> 478 | E56: =E16-D16 -> 253 | F56: =F16-E16 -> 199 | G56: =G16-F16 -> 435 | H56: =H16-G16 -> 110 | I56: =I16-H16 -> 244 | J56: =J16-I16 -> 518 | ... AF56: =AF16-AE16 -> 44
... A79: XM35 | B79: 372 | C79: =C39-B39 -> 0 | D79: =D39-C39 -> 0 | E79: =E39-D39 -> 258 | F79: =F39-E39 -> 262 | G79: =G39-F39 -> 517 | H79: =H39-G39 -> 349 | I79: =I39-H39 -> 178 | J79: =J39-I39 -> 0 | ... AF79: =AF39-AE39 -> 0
A81: Kilometraje Diario | B81: =SUM(B45:B79) -> 9875 | C81: =SUM(C45:C79) -> 6549 | D81: =SUM(D45:D79) -> 5082 | E81: =SUM(E45:E79) -> 10440 | F81: =SUM(F45:F79) -> 10651 | G81: =SUM(G45:G79) -> 10486 | H81: =SUM(H45:H79) -> 10611 | I81: =SUM(I45:I79) -> 10674 | ... AF81: =SUM(AF45:AF79) -> 5120

Sheet KM-Servicio
E1: SA-QU/QU-SA | F1: 7.68 | H1: SA-MI | I1: 21.7 | J1: EB-PU | K1: 25.4 | L1: PU-SA | M1: 29.11 | N1: QU-LI / LI-QU | O1: 21.7 | P1: VM-PU | Q1: 8.3 | R1: VM-LI | S1: 34.83 | T1: LI-PO | U1: 39.19 | W1: PU-ES/ES-PU | X1: 11.71 | Y1: PU-RE | Z1: 6 | AA1: PU-BA | AB1: 2.2 | AC1: SA-VM | AD1: 20.81
B2: CANTIDAD DE SERVICIOS | D2: CANTIDAD DE SERVICIOS | F2: EB-LI | G2: =M2-K1 -> 17.73 | H2: PU-PE | I2: 30.4 | J2: PO-SA | K2: 25.4 | L2: PU-LI | M2: 43.13 | N2: MI-LI / LI-MI | O2: 35.73 | P2: HO-LI/LI-HO | Q2: 33.97 | R2: PU-MI | S2: 7.4 | T2: LI-PE | U2: 12.72 | W2: MI-SA | X2: 21.7 | Y2: PU-PO | Z2: 3.9 | AA2: AM-QU | AB2: =(26.4-21.43) -> 4.97 | AC2: PU-CH | AD2: 10.55
B3: PROGRAMADOS | D3: REALIZADOS | F3: Origen-Destino | G3: Total Trenes | H3: Total Trenes P | I3: Total Servicios | J3: Kms.xTrenes | K3: Kmsxservicios. | L3: Asientos x Kms. | M3: Disp x Km. | N3: Total Odómetro | O3: % Uso Trenes | Q3: Cortes | T3: Acoples | W3: KmTren R | X3: KmTren P
B4: Simples | C4: Dobles | D4: Simples | E4: Dobles | Q4: EB | R4: SA | S4: PE | T4: EB | U4: SA | V4: PE
A5: 45870 | B5: 60 | C5: 19 | D5: ='Data Ocupacion'!D33 -> 68 | E5: ='Data Ocupacion'!E33 -> 11 | F5: PU-LI | G5: =D5+E5*2 -> 90 | H5: =B5+C5*2 -> 98 | I5: =D5+E5 -> 79 | J5: =G5*M$2 -> 3881.7 | K5: =I5*M$2 -> 3407.27 | L5: =J5*104 -> 403696.8 | M5: =I5*104 -> 8216 | Q5: 1 | W5: =J5-(Q5*($M$2-$K$1))-(R5*($M$2-$M$1))- (S5*($M$2-$I$2))+ (T5*($G$2)) -> 3863.97 | X5: =H5*$M$2 -> 4226.74
B6: 58 | C6: 20 | D6: ='Data Ocupacion'!D34 -> 66 | E6: ='Data Ocupacion'!E34 -> 12 | F6: LI-PU | G6: =D6+E6*2 -> 90 | H6: =B6+C6*2 -> 98 | I6: =D6+E6 -> 78 | J6: =G6*M$2 -> 3881.7 | K6: =I6*M$2 -> 3364.14 | L6: =J6*104 -> 403696.8 | M6: =I6*104 -> 8112 | W6: =J6-(T6*($M$2-$K$1)+(U6*($M$2-$M$1))) -> 3881.7 | X6: =H6*$M$2 -> 4226.74
A7: Indisponibilidad hora punta AM/PM por avería 12 incidentes | B7: 33 | C7: 0 | D7: ='Data Ocupacion'!D35 -> 29 | E7: ='Data Ocupacion'!E35 -> 0 | F7: PU-SA | G7: =D7+E7*2 -> 29 | H7: =B7+C7*2 -> 33 | I7: =D7+E7 -> 29 | J7: =G7*M$1 -> 844.19 | K7: =I7*M$1 -> 844.19 | L7: =J7*104 -> 87795.76 | M7: =I7*104 -> 3016 | W7: =J7-(Q7*($M$1-$K$1)) -> 844.19 | X7: =H7*$M$1 -> 960.63
B8: 32 | C8: 0 | D8: ='Data Ocupacion'!D36 -> 29 | E8: ='Data Ocupacion'!E36 -> 0 | F8: SA-PU | G8: =D8+E8*2 -> 29 | H8: =B8+C8*2 -> 32 | I8: =D8+E8 -> 29 | J8: =G8*M$1 -> 844.19 | K8: =I8*M$1 -> 844.19 | L8: =J8*104 -> 87795.76 | M8: =I8*104 -> 3016 | W8: =J8 -> 844.19 | X8: =H8*$M$1 -> 931.52
B9: 0 | C9: 0 | D9: ='Data Ocupacion'!D37 -> 0 | E9: ='Data Ocupacion'!E37 -> 0 | F9: PU-EB | G9: =D9+E9*2 -> 0 | H9: =B9+C9*2 -> 0 | I9: =D9+E9 -> 0 | J9: =G9*K$1 -> 0 | K9: =I9*K$1 -> 0 | L9: =J9*104 -> 0 | M9: =I9*104 -> 0 | W9: =J9 -> 0 | X9: =H9*$K$1 -> 0
B10: 1 | C10: 0 | D10: ='Data Ocupacion'!D38 -> 1 | E10: ='Data Ocupacion'!E38 -> 0 | F10: EB-PU | G10: =D10+E10*2 -> 1 | H10: =B10+C10*2 -> 1 | I10: =D10+E10 -> 1 | J10: =G10*K$1 -> 25.4 | K10: =I10*K$1 -> 25.4 | L10: =J10*104 -> 2641.6 | M10: =I10*104 -> 104 | W10: =J10 -> 25.4 | X10: =H10*$K$1 -> 25.4
B11: 0 | C11: 0 | D11: ='Data Ocupacion'!D39 -> 1 | E11: ='Data Ocupacion'!E39 -> 0 | F11: PU-CH | G11: =D11+E11*2 -> 1 | H11: =B11+C11*2 -> 0 | I11: =D11+E11 -> 1 | J11: =G11*AD$2 -> 10.55 | K11: =AD2 -> 10.55 | L11: =J11*104 -> 1097.2 | M11: =I11*104 -> 104 | W11: =J11 -> 10.55 | X11: =H11*$K$1 -> 0
B12: =SUM(B5:B11) -> 184 | C12: =SUM(C5:C11) -> 39 | D12: =SUM(D5:D11) -> 194 | E12: =SUM(E5:E11) -> 23 | G12: =SUM(G5:G11) -> 240 | H12: =SUM(H5:H11) -> 262 | I12: =SUM(I5:I11) -> 217 | J12: =SUM(J5:J11) -> 9487.73 | K12: =SUM(K5:K11) -> 8495.74 | L12: =SUM(L5:L11) -> 986723.92 | M12: =SUM(M5:M11) -> 22568 | N12: ='Odometro-Kilometraje'!B81 -> 9875 | O12: =(W12/N12)*100 -> 95.898734 | W12: =SUM(W5:W11) -> 9470 | X12: =SUM(X5:X11) -> 10371.03
A13: =A5+1 -> 45871 | B13: 69 | C13: 3 | D13: ='Data Ocupacion'!F33 -> 69 | E13: ='Data Ocupacion'!G33 -> 3 | F13: PU-LI | G13: =D13+E13*2 -> 75 | H13: =B13+C13*2 -> 75 | I13: =D13+E13 -> 72 | J13: =G13*M$2 -> 3234.75 | K13: =I13*M$2 -> 3105.36 | L13: =J13*104 -> 336414 | M13: =I13*104 -> 7488 | W13: =J13-(Q13*($M$2-$K$1))-(R13*($M$2-$M$1))- (S13*($M$2-$I$2))+ (T13*($G$2)) -> 3234.75 | X13: =H13*$M$2 -> 3234.75
B14: 75 | C14: 0 | D14: ='Data Ocupacion'!F34 -> 75 | E14: ='Data Ocupacion'!G34 -> 0 | F14: LI-PU | G14: =D14+E14*2 -> 75 | H14: =B14+C14*2 -> 75 | I14: =D14+E14 -> 75 | J14: =G14*M$2 -> 3234.75 | K14: =I14*M$2 -> 3234.75 | L14: =J14*104 -> 336414 | M14: =I14*104 -> 7800 | W14: =J14-(T14*($M$2-$K$1)+(U14*($M$2-$M$1))) -> 3234.75 | X14: =H14*$M$2 -> 3234.75
B15: 0 | C15: 0 | D15: ='Data Ocupacion'!F35 -> 0 | E15: ='Data Ocupacion'!G35 -> 0 | F15: PU-SA | G15: =D15+E15*2 -> 0 | H15: =B15+C15*2 -> 0 | I15: =D15+E15 -> 0 | J15: =G15*M$1 -> 0 | K15: =I15*M$1 -> 0 | L15: =J15*104 -> 0 | M15: =I15*104 -> 0 | W15: =J15-(Q15*($M$1-$K$1)) -> 0 | X15: =H15*$M$1 -> 0
B16: 0 | C16: 0 | D16: ='Data Ocupacion'!F36 -> 0 | E16: ='Data Ocupacion'!G36 -> 0 | F16: SA-PU | G16: =D16+E16*2 -> 0 | H16: =B16+C16*2 -> 0 | I16: =D16+E16 -> 0 | J16: =G16*M$1 -> 0 | K16: =I16*M$1 -> 0 | L16: =J16*104 -> 0 | M16: =I16*104 -> 0 | W16: =J16 -> 0 | X16: =H16*$M$1 -> 0
B17: 0 | C17: 0 | D17: ='Data Ocupacion'!F37 -> 0 | E17: ='Data Ocupacion'!G37 -> 0 | F17: PU-EB | G17: =D17+E17*2 -> 0 | H17: =B17+C17*2 -> 0 | I17: =D17+E17 -> 0 | J17: =G17*K$1 -> 0 | K17: =I17*K$1 -> 0 | L17: =J17*104 -> 0 | M17: =I17*104 -> 0 | W17: =J17 -> 0 | X17: =H17*$K$1 -> 0
B18: 0 | C18: 0 | D18: ='Data Ocupacion'!F38 -> 0 | E18: ='Data Ocupacion'!G38 -> 0 | F18: EB-PU | G18: =D18+E18*2 -> 0 | H18: =B18+C18*2 -> 0 | I18: =D18+E18 -> 0 | J18: =G18*K$1 -> 0 | K18: =I18*K$1 -> 0 | L18: =J18*104 -> 0 | M18: =I18*104 -> 0 | W18: =J18 -> 0 | X18: =H18*$K$1 -> 0
B19: =SUM(B13:B18) -> 144 | C19: =SUM(C13:C18) -> 3 | D19: =SUM(D13:D18) -> 144 | E19: =SUM(E13:E18) -> 3 | G19: =SUM(G13:G18) -> 150 | H19: =SUM(H13:H18) -> 150 | I19: =SUM(I13:I18) -> 147 | J19: =SUM(J13:J18) -> 6469.5 | K19: =SUM(K13:K18) -> 6340.11 | L19: =SUM(L13:L18) -> 672828 | M19: =SUM(M13:M18) -> 15288 | N19: ='Odometro-Kilometraje'!C81 -> 6549 | O19: =(W19/N19)*100 -> 98.786074 | W19: =SUM(W13:W18) -> 6469.5 | X19: =SUM(X13:X18) -> 6469.5
A20: =A13+1 -> 45872 | B20: 51 | C20: 3 | D20: ='Data Ocupacion'!H33 -> 51 | E20: ='Data Ocupacion'!I33 -> 3 | F20: PU-LI | G20: =D20+E20*2 -> 57 | H20: =B20+C20*2 -> 57 | I20: =D20+E20 -> 54 | J20: =G20*M$2 -> 2458.41 | K20: =I20*M$2 -> 2329.02 | L20: =J20*104 -> 255674.64 | M20: =I20*104 -> 5616 | W20: =J20-(Q20*($M$2-$K$1))-(R20*($M$2-$M$1))- (S20*($M$2-$I$2))+ (T20*($G$2)) -> 2458.41 | X20: =H20*$M$2 -> 2458.41
B21: 57 | C21: 0 | D21: ='Data Ocupacion'!H34 -> 57 | E21: ='Data Ocupacion'!I34 -> 0 | F21: LI-PU | G21: =D21+E21*2 -> 57 | H21: =B21+C21*2 -> 57 | I21: =D21+E21 -> 57 | J21: =G21*M$2 -> 2458.41 | K21: =I21*M$2 -> 2458.41 | L21: =J21*104 -> 255674.64 | M21: =I21*104 -> 5928 | W21: =J21-(T21*($M$2-$K$1)+(U21*($M$2-$M$1))) -> 2458.41 | X21: =H21*$M$2 -> 2458.41
B22: 0 | C22: 0 | D22: ='Data Ocupacion'!H35 -> 0 | E22: ='Data Ocupacion'!I35 -> 0 | F22: PU-SA | G22: =D22+E22*2 -> 0 | H22: =B22+C22*2 -> 0 | I22: =D22+E22 -> 0 | J22: =G22*M$1 -> 0 | K22: =I22*M$1 -> 0 | L22: =J22*104 -> 0 | M22: =I22*104 -> 0 | W22: =J22-(Q22*($M$1-$K$1)) -> 0 | X22: =H22*$M$1 -> 0
B23: 0 | C23: 0 | D23: ='Data Ocupacion'!H36 -> 0 | E23: ='Data Ocupacion'!I36 -> 0 | F23: SA-PU | G23: =D23+E23*2 -> 0 | H23: =B23+C23*2 -> 0 | I23: =D23+E23 -> 0 | J23: =G23*M$1 -> 0 | K23: =I23*M$1 -> 0 | L23: =J23*104 -> 0 | M23: =I23*104 -> 0 | W23: =J23 -> 0 | X23: =H23*$M$1 -> 0
B24: 0 | C24: 0 | D24: ='Data Ocupacion'!H37 -> 0 | E24: ='Data Ocupacion'!I37 -> 0 | F24: PU-EB | G24: =D24+E24*2 -> 0 | H24: =B24+C24*2 -> 0 | I24: =D24+E24 -> 0 | J24: =G24*K$1 -> 0 | K24: =I24*K$1 -> 0 | L24: =J24*104 -> 0 | M24: =I24*104 -> 0 | W24: =J24 -> 0 | X24: =H24*$K$1 -> 0
B25: 0 | C25: 0 | D25: ='Data Ocupacion'!H38 -> 0 | E25: ='Data Ocupacion'!I38 -> 0 | F25: EB-PU | G25: =D25+E25*2 -> 0 | H25: =B25+C25*2 -> 0 | I25: =D25+E25 -> 0 | J25: =G25*K$1 -> 0 | K25: =I25*K$1 -> 0 | L25: =J25*104 -> 0 | M25: =I25*104 -> 0 | W25: =J25 -> 0 | X25: =H25*$K$1 -> 0
B26: =SUM(B20:B25) -> 108 | C26: =SUM(C20:C25) -> 3 | D26: =SUM(D20:D25) -> 108 | E26: =SUM(E20:E25) -> 3 | G26: =SUM(G20:G25) -> 114 | H26: =SUM(H20:H25) -> 114 | I26: =SUM(I20:I25) -> 111 | J26: =SUM(J20:J25) -> 4916.82 | K26: =SUM(K20:K25) -> 4787.43 | L26: =SUM(L20:L25) -> 511349.28 | M26: =SUM(M20:M25) -> 11544 | N26: ='Odometro-Kilometraje'!D81 -> 5082 | O26: =(W26/N26)*100 -> 96.749705 | W26: =SUM(W20:W25) -> 4916.82 | X26: =SUM(X20:X25) -> 4916.82
A27: =A20+1 -> 45873 | B27: 60 | C27: 19 | D27: ='Data Ocupacion'!J33 -> 61 | E27: ='Data Ocupacion'!K33 -> 18 | F27: PU-LI | G27: =D27+E27*2 -> 97 | H27: =B27+C27*2 -> 98 | I27: =D27+E27 -> 79 | J27: =G27*M$2 -> 4183.61 | K27: =I27*M$2 -> 3407.27 | L27: =J27*104 -> 435095.44 | M27: =I27*104 -> 8216 | Q27: 4 | W27: =J27-(Q27*($M$2-$K$1))-(R27*($M$2-$M$1))- (S27*($M$2-$I$2))+ (T27*($G$2)) -> 4112.69 | X27: =H27*$M$2 -> 4226.74
B28: 58 | C28: 20 | D28: ='Data Ocupacion'!J34 -> 59 | E28: ='Data Ocupacion'!K34 -> 19 | F28: LI-PU | G28: =D28+E28*2 -> 97 | H28: =B28+C28*2 -> 98 | I28: =D28+E28 -> 78 | J28: =G28*M$2 -> 4183.61 | K28: =I28*M$2 -> 3364.14 | L28: =J28*104 -> 435095.44 | M28: =I28*104 -> 8112 | T28: 1 | W28: =J28-(T28*($M$2-$K$1)+(U28*($M$2-$M$1))+(V28*($M$2-$I$2))) -> 4165.88 | X28: =H28*$M$2 -> 4226.74
B29: 33 | C29: 0 | D29: ='Data Ocupacion'!J35 -> 33 | E29: ='Data Ocupacion'!K35 -> 0 | F29: PU-SA | G29: =D29+E29*2 -> 33 | H29: =B29+C29*2 -> 33 | I29: =D29+E29 -> 33 | J29: =G29*M$1 -> 960.63 | K29: =I29*M$1 -> 960.63 | L29: =J29*104 -> 99905.52 | M29: =I29*104 -> 3432 | W29: =J29-(Q29*($M$1-$K$1)) -> 960.63 | X29: =H29*$M$1 -> 960.63
B30: 32 | C30: 0 | D30: ='Data Ocupacion'!J36 -> 32 | E30: ='Data Ocupacion'!K36 -> 0 | F30: SA-PU | G30: =D30+E30*2 -> 32 | H30: =B30+C30*2 -> 32 | I30: =D30+E30 -> 32 | J30: =G30*M$1 -> 931.52 | K30: =I30*M$1 -> 931.52 | L30: =J30*104 -> 96878.08 | M30: =I30*104 -> 3328 | W30: =J30 -> 931.52 | X30: =H30*$M$1 -> 931.52
B31: 0 | C31: 0 | D31: ='Data Ocupacion'!J37 -> 0 | E31: ='Data Ocupacion'!K37 -> 0 | F31: PU-EB | G31: =D31+E31*2 -> 0 | H31: =B31+C31*2 -> 0 | I31: =D31+E31 -> 0 | J31: =G31*K$1 -> 0 | K31: =I31*K$1 -> 0 | L31: =J31*104 -> 0 | M31: =I31*104 -> 0 | W31: =J31 -> 0 | X31: =H31*$K$1 -> 0
B32: 1 | C32: 0 | D32: ='Data Ocupacion'!J38 -> 1 | E32: ='Data Ocupacion'!K38 -> 0 | F32: EB-PU | G32: =D32+E32*2 -> 1 | H32: =B32+C32*2 -> 1 | I32: =D32+E32 -> 1 | J32: =G32*K$1 -> 25.4 | K32: =I32*K$1 -> 25.4 | L32: =J32*104 -> 2641.6 | M32: =I32*104 -> 104 | W32: =J32 -> 25.4 | X32: =H32*$K$1 -> 25.4
B33: =SUM(B27:B32) -> 184 | C33: =SUM(C27:C32) -> 39 | D33: =SUM(D27:D32) -> 186 | E33: =SUM(E27:E32) -> 37 | G33: =SUM(G27:G32) -> 260 | H33: =SUM(H27:H32) -> 262 | I33: =SUM(I27:I32) -> 223 | J33: =SUM(J27:J32) -> 10284.77 | K33: =SUM(K27:K32) -> 8688.96 | L33: =SUM(L27:L32) -> 1069616.1 | M33: =SUM(M27:M32) -> 23192 | N33: ='Odometro-Kilometraje'!E81 -> 10440 | O33: =(W33/N33)*100 -> 97.663985 | W33: =SUM(W27:W32) -> 10196.12 | X33: =SUM(X27:X32) -> 10371.03
A34: =A27+1 -> 45874 | B34: 60 | C34: 19 | D34: ='Data Ocupacion'!L33 -> 60 | E34: ='Data Ocupacion'!M33 -> 19 | F34: PU-LI | G34: =D34+E34*2 -> 98 | H34: =B34+C34*2 -> 98 | I34: =D34+E34 -> 79 | J34: =G34*M$2 -> 4226.74 | K34: =I34*M$2 -> 3407.27 | L34: =J34*104 -> 439580.96 | M34: =I34*104 -> 8216 | Q34: 2 | W34: =J34-(Q34*($M$2-$K$1))-(R34*($M$2-$M$1))- (S34*($M$2-$I$2))+ (T34*($G$2)) -> 4191.28 | X34: =H34*$M$2 -> 4226.74
B35: 58 | C35: 20 | D35: ='Data Ocupacion'!L34 -> 58 | E35: ='Data Ocupacion'!M34 -> 20 | F35: LI-PU | G35: =D35+E35*2 -> 98 | H35: =B35+C35*2 -> 98 | I35: =D35+E35 -> 78 | J35: =G35*M$2 -> 4226.74 | K35: =I35*M$2 -> 3364.14 | L35: =J35*104 -> 439580.96 | M35: =I35*104 -> 8112 | T35: 3 | W35: =J35-(T35*($M$2-$K$1)+(U35*($M$2-$M$1))) -> 4173.55 | X35: =H35*$M$2 -> 4226.74
B36: 33 | C36: 0 | D36: ='Data Ocupacion'!L35 -> 33 | E36: ='Data Ocupacion'!M35 -> 0 | F36: PU-SA | G36: =D36+E36*2 -> 33 | H36: =B36+C36*2 -> 33 | I36: =D36+E36 -> 33 | J36: =G36*M$1 -> 960.63 | K36: =I36*M$1 -> 960.63 | L36: =J36*104 -> 99905.52 | M36: =I36*104 -> 3432 | W36: =J36-(Q36*($M$1-$K$1)) -> 960.63 | X36: =H36*$M$1 -> 960.63
B37: 32 | C37: 0 | D37: ='Data Ocupacion'!L36 -> 32 | E37: ='Data Ocupacion'!M36 -> 0 | F37: SA-PU | G37: =D37+E37*2 -> 32 | H37: =B37+C37*2 -> 32 | I37: =D37+E37 -> 32 | J37: =G37*M$1 -> 931.52 | K37: =I37*M$1 -> 931.52 | L37: =J37*104 -> 96878.08 | M37: =I37*104 -> 3328 | W37: =J37 -> 931.52 | X37: =H37*$M$1 -> 931.52
B38: 0 | C38: 0 | D38: ='Data Ocupacion'!L37 -> 0 | E38: ='Data Ocupacion'!M37 -> 0 | F38: PU-EB | G38: =D38+E38*2 -> 0 | H38: =B38+C38*2 -> 0 | I38: =D38+E38 -> 0 | J38: =G38*K$1 -> 0 | K38: =I38*K$1 -> 0 | L38: =J38*104 -> 0 | M38: =I38*104 -> 0 | W38: =J38 -> 0 | X38: =H38*$K$1 -> 0
B39: 1 | C39: 0 | D39: ='Data Ocupacion'!L38 -> 1 | E39: ='Data Ocupacion'!M38 -> 0 | F39: EB-PU | G39: =D39+E39*2 -> 1 | H39: =B39+C39*2 -> 1 | I39: =D39+E39 -> 1 | J39: =G39*K$1 -> 25.4 | K39: =I39*K$1 -> 25.4 | L39: =J39*104 -> 2641.6 | M39: =I39*104 -> 104 | W39: =J39 -> 25.4 | X39: =H39*$K$1 -> 25.4
B40: =SUM(B34:B39) -> 184 | C40: =SUM(C34:C39) -> 39 | D40: =SUM(D34:D39) -> 184 | E40: =SUM(E34:E39) -> 39 | G40: =SUM(G34:G39) -> 262 | H40: =SUM(H34:H39) -> 262 | I40: =SUM(I34:I39) -> 223 | J40: =SUM(J34:J39) -> 10371.03 | K40: =SUM(K34:K39) -> 8688.96 | L40: =SUM(L34:L39) -> 1078587.1 | M40: =SUM(M34:M39) -> 23192 | N40: ='Odometro-Kilometraje'!F81 -> 10651 | O40: =(W40/N40)*100 -> 96.539104 | W40: =SUM(W34:W39) -> 10282.38 | X40: =SUM(X34:X39) -> 10371.03
...

Sheet Data Ocupacion
D1: 45870 | F1: 45871 | H1: 45872 | J1: 45873 | L1: 45874 | N1: 45875 | P1: 45876 | R1: 45877 | T1: 45878 | V1: 45879 | X1: 45880 | Z1: 45881 | AB1: 45882 | AD1: 45883 | AF1: 45884 | AH1: 45885 | AJ1: 45886 | AL1: 45887 | AN1: 45888 | AP1: 45889 | AR1: 45890 | AT1: 45891 | AV1: 45892 | AX1: 45893 | AZ1: 45894 | BB1: 45895 | BD1: 45896 | BF1: 45897 | BH1: 45898 | BJ1: 45899 | BL1: 45900
D2: S | E2: M | F2: S | G2: M | H2: S | I2: M | J2: S | K2: M | L2: S | M2: M | N2: S | O2: M | P2: S | Q2: M | R2: S | S2: M | T2: S | U2: M | V2: S | W2: M | X2: S | Y2: M | Z2: S | AA2: M | AB2: S | AC2: M | AD2: S | AE2: M | AF2: S | AG2: M | AH2: S | AI2: M | AJ2: S | AK2: M | AL2: S | AM2: M | AN2: S | AO2: M | AP2: S | AQ2: M | AR2: S | AS2: M | AT2: S | AU2: M | AV2: S | AW2: M | AX2: S | AY2: M | AZ2: S | BA2: M | BB2: S | BC2: M | BD2: S | BE2: M | BF2: S | BG2: M | BH2: S | BI2: M | BJ2: S | BK2: M | BL2: S | BM2: M
A3: Servicios PU-SA | D3: 10 | E3: 0 | F3: 0 | G3: 0 | H3: 0 | I3: 0 | J3: 10 | K3: 0 | L3: 10 | M3: 0 | N3: 10 | O3: 0 | P3: 10 | Q3: 0 | R3: 10 | S3: 0 | T3: 0 | U3: 0 | V3: 0 | W3: 0 | X3: 7 | Y3: 3 | Z3: 7 | AA3: 3 | AB3: 7 | AC3: 3 | AD3: 7 | AE3: 3 | AF3: 0 | AG3: 0 | AH3: 0 | AI3: 0 | AJ3: 0 | AK3: 0 | AL3: 7 | AM3: 3 | AN3: 7 | AO3: 3 | AP3: 7 | AQ3: 3 | AR3: 7 | AS3: 3 | AT3: 10 | AU3: 0 | AV3: 0 | AW3: 0 | AX3: 0 | AY3: 0 | AZ3: 7 | BA3: 3 | BB3: 7 | BC3: 3 | BD3: 7 | BE3: 3 | BF3: 7 | BG3: 3 | BH3: 7 | BI3: 3 | BJ3: 0 | BK3: 0 | BL3: 0 | BM3: 0
A4: Servicios PU-EB | D4: 0 | E4: 0 | F4: 0 | G4: 0 | H4: 0 | I4: 0 | J4: 0 | K4: 0 | L4: 0 | M4: 0 | N4: 0 | O4: 0 | P4: 0 | Q4: 0 | R4: 0 | S4: 0 | T4: 0 | U4: 0 | V4: 0 | W4: 0 | X4: 0 | Y4: 0 | Z4: 0 | AA4: 0 | AB4: 0 | AC4: 0 | AD4: 0 | AE4: 0 | AF4: 0 | AG4: 0 | AH4: 0 | AI4: 0 | AJ4: 0 | AK4: 0 | AL4: 0 | AM4: 0 | AN4: 0 | AO4: 0 | AP4: 0 | AQ4: 0 | AR4: 0 | AS4: 0 | AT4: 0 | AU4: 0 | AV4: 0 | AW4: 0 | AX4: 0 | AY4: 0 | AZ4: 0 | BA4: 0 | BB4: 0 | BC4: 0 | BD4: 0 | BE4: 0 | BF4: 0 | BG4: 0 | BH4: 0 | BI4: 0 | BJ4: 0 | BK4: 0 | BL4: 0 | BM4: 0
A5: Servicios PU-LI | D5: 2 | E5: 8 | F5: 0 | G5: 0 | H5: 0 | I5: 0 | J5: 2 | K5: 8 | L5: 1 | M5: 9 | N5: 1 | O5: 9 | P5: 1 | Q5: 9 | R5: 1 | S5: 9 | T5: 0 | U5: 0 | V5: 0 | W5: 0 | X5: 1 | Y5: 9 | Z5: 1 | AA5: 9 | AB5: 1 | AC5: 9 | AD5: 2 | AE5: 8 | AF5: 0 | AG5: 0 | AH5: 0 | AI5: 0 | AJ5: 0 | AK5: 0 | AL5: 2 | AM5: 8 | AN5: 1 | AO5: 9 | AP5: 1 | AQ5: 9 | AR5: 1 | AS5: 9 | AT5: 4 | AU5: 6 | AV5: 0 | AW5: 0 | AX5: 0 | AY5: 0 | AZ5: 1 | BA5: 9 | BB5: 1 | BC5: 9 | BD5: 1 | BE5: 9 | BF5: 1 | BG5: 9 | BH5: 1 | BI5: 9 | BJ5: 0 | BK5: 0 | BL5: 0 | BM5: 0
A6: Servicios SA-PU | D6: 10 | E6: 0 | F6: 0 | G6: 0 | H6: 0 | I6: 0 | J6: 10 | K6: 0 | L6: 10 | M6: 0 | N6: 10 | O6: 0 | P6: 10 | Q6: 0 | R6: 10 | S6: 0 | T6: 0 | U6: 0 | V6: 0 | W6: 0 | X6: 10 | Y6: 0 | Z6: 10 | AA6: 0 | AB6: 10 | AC6: 0 | AD6: 10 | AE6: 0 | AF6: 0 | AG6: 0 | AH6: 0 | AI6: 0 | AJ6: 0 | AK6: 0 | AL6: 9 | AM6: 1 | AN6: 9 | AO6: 1 | AP6: 10 | AQ6: 0 | AR6: 10 | AS6: 0 | AT6: 10 | AU6: 0 | AV6: 0 | AW6: 0 | AX6: 0 | AY6: 0 | AZ6: 10 | BA6: 0 | BB6: 9 | BC6: 1 | BD6: 9 | BE6: 1 | BF6: 10 | BG6: 0 | BH6: 10 | BI6: 0 | BJ6: 0 | BK6: 0 | BL6: 0 | BM6: 0
A7: Servicios EB-PU | D7: 0 | E7: 0 | F7: 0 | G7: 0 | H7: 0 | I7: 0 | J7: 0 | K7: 0 | L7: 0 | M7: 0 | N7: 0 | O7: 0 | P7: 0 | Q7: 0 | R7: 0 | S7: 0 | T7: 0 | U7: 0 | V7: 0 | W7: 0 | X7: 0 | Y7: 0 | Z7: 0 | AA7: 0 | AB7: 0 | AC7: 0 | AD7: 0 | AE7: 0 | AF7: 0 | AG7: 0 | AH7: 0 | AI7: 0 | AJ7: 0 | AK7: 0 | AL7: 0 | AM7: 0 | AN7: 0 | AO7: 0 | AP7: 0 | AQ7: 0 | AR7: 0 | AS7: 0 | AT7: 0 | AU7: 0 | AV7: 0 | AW7: 0 | AX7: 0 | AY7: 0 | AZ7: 0 | BA7: 0 | BB7: 0 | BC7: 0 | BD7: 0 | BE7: 0 | BF7: 0 | BG7: 0 | BH7: 0 | BI7: 0 | BJ7: 0 | BK7: 0 | BL7: 0 | BM7: 0
A8: Servicios LI-PU | D8: 7 | E8: 3 | F8: 0 | G8: 0 | H8: 0 | I8: 0 | J8: 7 | K8: 3 | L8: 6 | M8: 4 | N8: 6 | O8: 4 | P8: 6 | Q8: 4 | R8: 6 | S8: 4 | T8: 0 | U8: 0 | V8: 0 | W8: 0 | X8: 4 | Y8: 6 | Z8: 4 | AA8: 6 | AB8: 4 | AC8: 6 | AD8: 5 | AE8: 5 | AF8: 0 | AG8: 0 | AH8: 0 | AI8: 0 | AJ8: 0 | AK8: 0 | AL8: 4 | AM8: 6 | AN8: 4 | AO8: 6 | AP8: 4 | AQ8: 6 | AR8: 4 | AS8: 6 | AT8: 5 | AU8: 5 | AV8: 0 | AW8: 0 | AX8: 0 | AY8: 0 | AZ8: 4 | BA8: 6 | BB8: 4 | BC8: 6 | BD8: 4 | BE8: 6 | BF8: 4 | BG8: 6 | BH8: 4 | BI8: 6 | BJ8: 0 | BK8: 0 | BL8: 0 | BM8: 0
A10: Servicios PU-SA | D10: 12 | E10: 0 | F10: 0 | G10: 0 | H10: 0 | I10: 0 | J10: 16 | K10: 0 | L10: 16 | M10: 0 | N10: 16 | O10: 0 | P10: 16 | Q10: 0 | R10: 16 | S10: 0 | T10: 0 | U10: 0 | V10: 0 | W10: 0 | X10: 16 | Y10: 0 | Z10: 16 | AA10: 0 | AB10: 16 | AC10: 0 | AD10: 16 | AE10: 0 | AF10: 0 | AG10: 0 | AH10: 0 | AI10: 0 | AJ10: 0 | AK10: 0 | AL10: 15 | AM10: 1 | AN10: 15 | AO10: 1 | AP10: 16 | AQ10: 0 | AR10: 14 | AS10: 0 | AT10: 16 | AU10: 0 | AV10: 0 | AW10: 0 | AX10: 0 | AY10: 0 | AZ10: 16 | BA10: 0 | BB10: 12 | BC10: 1 | BD10: 15 | BE10: 1 | BF10: 16 | BG10: 0 | BH10: 16 | BI10: 0 | BJ10: 0 | BK10: 0 | BL10: 0 | BM10: 0
A11: Servicios PU-EB | D11: 0 | E11: 0 | F11: 0 | G11: 0 | H11: 0 | I11: 0 | J11: 0 | K11: 0 | L11: 0 | M11: 0 | N11: 0 | O11: 0 | P11: 0 | Q11: 0 | R11: 0 | S11: 0 | T11: 0 | U11: 0 | V11: 0 | W11: 0 | X11: 0 | Y11: 0 | Z11: 0 | AA11: 0 | AB11: 0 | AC11: 0 | AD11: 0 | AE11: 0 | AF11: 0 | AG11: 0 | AH11: 0 | AI11: 0 | AJ11: 0 | AK11: 0 | AL11: 0 | AM11: 0 | AN11: 0 | AO11: 0 | AP11: 0 | AQ11: 0 | AR11: 0 | AS11: 0 | AT11: 0 | AU11: 0 | AV11: 0 | AW11: 0 | AX11: 0 | AY11: 0 | AZ11: 0 | BA11: 0 | BB11: 0 | BC11: 0 | BD11: 0 | BE11: 0 | BF11: 0 | BG11: 0 | BH11: 0 | BI11: 0 | BJ11: 0 | BK11: 0 | BL11: 0 | BM11: 0
A12: Servicios PU-LI | D12: 60 | E12: 1 | F12: 69 | G12: 3 | H12: 51 | I12: 3 | J12: 55 | K12: 6 | L12: 55 | M12: 6 | N12: 55 | O12: 6 | P12: 55 | Q12: 6 | R12: 55 | S12: 6 | T12: 69 | U12: 3 | V12: 51 | W12: 3 | X12: 47 | Y12: 14 | Z12: 47 | AA12: 14 | AB12: 47 | AC12: 14 | AD12: 47 | AE12: 14 | AF12: 51 | AG12: 3 | AH12: 69 | AI12: 3 | AJ12: 51 | AK12: 3 | AL12: 43 | AM12: 17 | AN12: 44 | AO12: 17 | AP12: 42 | AQ12: 19 | AR12: 44 | AS12: 17 | AT12: 49 | AU12: 12 | AV12: 69 | AW12: 3 | AX12: 51 | AY12: 3 | AZ12: 44 | BA12: 17 | BB12: 45 | BC12: 17 | BD12: 43 | BE12: 18 | BF12: 44 | BG12: 17 | BH12: 44 | BI12: 17 | BJ12: 69 | BK12: 3 | BL12: 51 | BM12: 3
A13: Servicios SA-PU | D13: 15 | E13: 0 | F13: 0 | G13: 0 | H13: 0 | I13: 0 | J13: 16 | K13: 0 | L13: 16 | M13: 0 | N13: 16 | O13: 0 | P13: 16 | Q13: 0 | R13: 16 | S13: 0 | T13: 0 | U13: 0 | V13: 0 | W13: 0 | X13: 13 | Y13: 3 | Z13: 13 | AA13: 3 | AB13: 12 | AC13: 3 | AD13: 13 | AE13: 3 | AF13: 0 | AG13: 0 | AH13: 0 | AI13: 0 | AJ13: 0 | AK13: 0 | AL13: 13 | AM13: 3 | AN13: 13 | AO13: 3 | AP13: 13 | AQ13: 3 | AR13: 13 | AS13: 3 | AT13: 16 | AU13: 0 | AV13: 0 | AW13: 0 | AX13: 0 | AY13: 0 | AZ13: 13 | BA13: 3 | BB13: 12 | BC13: 3 | BD13: 13 | BE13: 3 | BF13: 13 | BG13: 3 | BH13: 13 | BI13: 3 | BJ13: 0 | BK13: 0 | BL13: 0 | BM13: 0
A14: Servicios EB-PU | D14: 1 | E14: 0 | F14: 0 | G14: 0 | H14: 0 | I14: 0 | J14: 1 | K14: 0 | L14: 1 | M14: 0 | N14: 1 | O14: 0 | P14: 1 | Q14: 0 | R14: 1 | S14: 0 | T14: 0 | U14: 0 | V14: 0 | W14: 0 | X14: 1 | Y14: 0 | Z14: 1 | AA14: 0 | AB14: 1 | AC14: 0 | AD14: 1 | AE14: 0 | AF14: 0 | AG14: 0 | AH14: 0 | AI14: 0 | AJ14: 0 | AK14: 0 | AL14: 1 | AM14: 0 | AN14: 1 | AO14: 0 | AP14: 1 | AQ14: 0 | AR14: 1 | AS14: 0 | AT14: 1 | AU14: 0 | AV14: 0 | AW14: 0 | AX14: 0 | AY14: 0 | AZ14: 1 | BA14: 0 | BB14: 1 | BC14: 0 | BD14: 1 | BE14: 0 | BF14: 1 | BG14: 0 | BH14: 1 | BI14: 0 | BJ14: 0 | BK14: 0 | BL14: 0 | BM14: 0
A15: Servicios LI-PU | D15: 52 | E15: 9 | F15: 75 | G15: 0 | H15: 57 | I15: 0 | J15: 45 | K15: 16 | L15: 45 | M15: 16 | N15: 45 | O15: 16 | P15: 45 | Q15: 16 | R15: 45 | S15: 16 | T15: 75 | U15: 0 | V15: 57 | W15: 0 | X15: 39 | Y15: 22 | Z15: 39 | AA15: 22 | AB15: 40 | AC15: 21 | AD15: 39 | AE15: 22 | AF15: 57 | AG15: 0 | AH15: 75 | AI15: 0 | AJ15: 57 | AK15: 0 | AL15: 34 | AM15: 27 | AN15: 35 | AO15: 26 | AP15: 33 | AQ15: 28 | AR15: 34 | AS15: 27 | AT15: 42 | AU15: 19 | AV15: 75 | AW15: 0 | AX15: 57 | AY15: 0 | AZ15: 35 | BA15: 26 | BB15: 36 | BC15: 25 | BD15: 35 | BE15: 26 | BF15: 37 | BG15: 24 | BH15: 35 | BI15: 26 | BJ15: 75 | BK15: 0 | BL15: 57 | BM15: 0
... A22: Servicios LI-PU | D22: 7 | E22: 0 | F22: 0 | G22: 0 | H22: 0 | I22: 0 | J22: 7 | K22: 0 | L22: 7 | M22: 0 | N22: 7 | O22: 0 | P22: 7 | Q22: 0 | R22: 7 | S22: 0 | T22: 0 | U22: 0 | V22: 0 | W22: 0 | X22: 5 | Y22: 2 | Z22: 5 | AA22: 2 | AB22: 5 | AC22: 2 | AD22: 5 | AE22: 2 | AF22: 0 | AG22: 0 | AH22: 0 | AI22: 0 | AJ22: 0 | AK22: 0 | AL22: 6 | AM22: 1 | AN22: 6 | AO22: 1 | AP22: 6 | AQ22: 1 | AR22: 6 | AS22: 1 | AT22: 6 | AU22: 1 | AV22: 0 | AW22: 0 | AX22: 0 | AY22: 0 | AZ22: 6 | BA22: 1 | BB22: 6 | BC22: 1 | BD22: 6 | BE22: 1 | BF22: 6 | BG22: 1 | BH22: 6 | BI22: 1 | BJ22: 0 | BK22: 0 | BL22: 0 | BM22: 0
A24: Servicios PU-CH | D24: 1 | E24: 0
D26: =SUM(D3:D24) -> 194 | E26: =SUM(E3:E24) -> 23 | F26: =SUM(F3:F22) -> 144 | G26: =SUM(G3:G22) -> 3 | H26: =SUM(H3:H22) -> 108 | I26: =SUM(I3:I22) -> 3 | J26: =SUM(J3:J22) -> 186 | K26: =SUM(K3:K22) -> 37 | L26: =SUM(L3:L22) -> 184 | M26: =SUM(M3:M22) -> 39 | ... BM26: =SUM(BM3:BM22) -> 3
A32: Km Servicio
A33: PU - LI | D33: =D5+D12+D19 -> 68 | E33: =E5+E12+E19 -> 11 | F33: =F5+F12+F19 -> 69 | G33: =G5+G12+G19 -> 3 | H33: =H5+H12+H19 -> 51 | I33: =I5+I12+I19 -> 3 | J33: =J5+J12+J19 -> 61 | K33: =K5+K12+K19 -> 18 | ... BM33: =BM5+BM12+BM19 -> 3
A34: LI - PU | D34: =D8+D15+D22 -> 66 | E34: =E8+E15+E22 -> 12 | F34: =F8+F15+F22 -> 75 | G34: =G8+G15+G22 -> 0 | H34: =H8+H15+H22 -> 57 | I34: =I8+I15+I22 -> 0 | J34: =J8+J15+J22 -> 59 | K34: =K8+K15+K22 -> 19 | ... BM34: =BM8+BM15+BM22 -> 0
A35: PU - SA | D35: =D3+D10+D17 -> 29 | E35: =E3+E10+E17 -> 0 | F35: =F3+F10+F17 -> 0 | G35: =G3+G10+G17 -> 0 | H35: =H3+H10+H17 -> 0 | I35: =I3+I10+I17 -> 0 | J35: =J3+J10+J17 -> 33 | K35: =K3+K10+K17 -> 0 | ... BM35: =BM3+BM10+BM17 -> 0
A36: SA - PU | D36: =D6+D13+D20 -> 29 | E36: =E6+E13+E20 -> 0 | F36: =F6+F13+F20 -> 0 | G36: =G6+G13+G20 -> 0 | H36: =H6+H13+H20 -> 0 | I36: =I6+I13+I20 -> 0 | J36: =J6+J13+J20 -> 32 | K36: =K6+K13+K20 -> 0 | ... BM36: =BM6+BM13+BM20 -> 0
A37: PU-EB | D37: =D4+D11+D18 -> 0 | E37: =E4+E11+E18 -> 0 | F37: =F4+F11+F18 -> 0 | G37: =G4+G11+G18 -> 0 | H37: =H4+H11+H18 -> 0 | I37: =I4+I11+I18 -> 0 | J37: =J4+J11+J18 -> 0 | K37: =K4+K11+K18 -> 0 | ... BM37: =BM4+BM11+BM18 -> 0
A38: EB-PU | D38: =D7+D14+D21 -> 1 | E38: =E7+E14+E21 -> 0 | F38: =F7+F14+F21 -> 0 | G38: =G7+G14+G21 -> 0 | H38: =H7+H14+H21 -> 0 | I38: =I7+I14+I21 -> 0 | J38: =J7+J14+J21 -> 1 | K38: =K7+K14+K21 -> 0 | ... BM38: =BM7+BM14+BM21 -> 0
A39: PU-CH | D39: =D24 -> 1
A40: total | D40: =SUM(D33:D39) -> 194 | E40: =SUM(E33:E38) -> 23 | F40: =SUM(F33:F38) -> 144 | G40: =SUM(G33:G38) -> 3 | H40: =SUM(H33:H38) -> 108 | I40: =SUM(I33:I38) -> 3 | J40: =SUM(J33:J38) -> 186 | K40: =SUM(K33:K38) -> 37 | L40: =SUM(L33:L38) -> 184 | ... BM40: =SUM(BM33:BM38) -> 3
A42: Servicios
A43: PU - LI | D43: =D5+E5+D12+E12+D19+E19 -> 79 | F43: =F5+G5+F12+G12+F19+G19 -> 72 | H43: =H5+I5+H12+I12+H19+I19 -> 54 | J43: =J5+K5+J12+K12+J19+K19 -> 79 | L43: =L5+M5+L12+M12+L19+M19 -> 79 | N43: =N5+O5+N12+O12+N19+O19 -> 79 | P43: =P5+Q5+P12+Q12+P19+Q19 -> 79 | R43: =R5+S5+R12+S12+R19+S19 -> 79 | T43: =T5+U5+T12+U12+T19+U19 -> 72 | V43: =V5+W5+V12+W12+V19+W19 -> 54 | X43: =X5+Y5+X12+Y12+X19+Y19 -> 79 | Z43: =Z5+AA5+Z12+AA12+Z19+AA19 -> 79 | AB43: =AB5+AC5+AB12+AC12+AB19+AC19 -> 80 | AD43: =AD5+AE5+AD12+AE12+AD19+AE19 -> 79 | AF43: =AF5+AG5+AF12+AG12+AF19+AG19 -> 54 | AH43: =AH5+AI5+AH12+AI12+AH19+AI19 -> 72 | AJ43: =AJ5+AK5+AJ12+AK12+AJ19+AK19 -> 54 | AL43: =AL5+AM5+AL12+AM12+AL19+AM19 -> 78 | AN43: =AN5+AO5+AN12+AO12+AN19+AO19 -> 79 | AP43: =AP5+AQ5+AP12+AQ12+AP19+AQ19 -> 79 | AR43: =AR5+AS5+AR12+AS12+AR19+AS19 -> 80 | AT43: =AT5+AU5+AT12+AU12+AT19+AU19 -> 79 | AV43: =AV5+AW5+AV12+AW12+AV19+AW19 -> 72 | AX43: =AX5+AY5+AX12+AY12+AX19+AY19 -> 54 | AZ43: =AZ5+BA5+AZ12+BA12+AZ19+BA19 -> 79 | BB43: =BB5+BC5+BB12+BC12+BB19+BC19 -> 80 | BD43: =BD5+BE5+BD12+BE12+BD19+BE19 -> 79 | BF43: =BF5+BG5+BF12+BG12+BF19+BG19 -> 79 | BH43: =BH5+BI5+BH12+BI12+BH19+BI19 -> 79 | BJ43: =BJ5+BK5+BJ12+BK12+BJ19+BK19 -> 72 | BL43: =BL5+BM5+BL12+BM12+BL19+BM19 -> 54
A44: LI - PU | D44: =D8+E8+D15+E15+D22+E22 -> 78 | F44: =F8+G8+F15+G15+F22+G22 -> 75 | H44: =H8+I8+H15+I15+H22+I22 -> 57 | J44: =J8+K8+J15+K15+J22+K22 -> 78 | L44: =L8+M8+L15+M15+L22+M22 -> 78 | N44: =N8+O8+N15+O15+N22+O22 -> 78 | P44: =P8+Q8+P15+Q15+P22+Q22 -> 78 | R44: =R8+S8+R15+S15+R22+S22 -> 78 | T44: =T8+U8+T15+U15+T22+U22 -> 75 | V44: =V8+W8+V15+W15+V22+W22 -> 57 | X44: =X8+Y8+X15+Y15+X22+Y22 -> 78 | Z44: =Z8+AA8+Z15+AA15+Z22+AA22 -> 78 | AB44: =AB8+AC8+AB15+AC15+AB22+AC22 -> 78 | AD44: =AD8+AE8+AD15+AE15+AD22+AE22 -> 78 | AF44: =AF8+AG8+AF15+AG15+AF22+AG22 -> 57 | AH44: =AH8+AI8+AH15+AI15+AH22+AI22 -> 75 | AJ44: =AJ8+AK8+AJ15+AK15+AJ22+AK22 -> 57 | AL44: =AL8+AM8+AL15+AM15+AL22+AM22 -> 78 | AN44: =AN8+AO8+AN15+AO15+AN22+AO22 -> 78 | AP44: =AP8+AQ8+AP15+AQ15+AP22+AQ22 -> 78 | AR44: =AR8+AS8+AR15+AS15+AR22+AS22 -> 78 | AT44: =AT8+AU8+AT15+AU15+AT22+AU22 -> 78 | AV44: =AV8+AW8+AV15+AW15+AV22+AW22 -> 75 | AX44: =AX8+AY8+AX15+AY15+AX22+AY22 -> 57 | AZ44: =AZ8+BA8+AZ15+BA15+AZ22+BA22 -> 78 | BB44: =BB8+BC8+BB15+BC15+BB22+BC22 -> 78 | BD44: =BD8+BE8+BD15+BE15+BD22+BE22 -> 78 | BF44: =BF8+BG8+BF15+BG15+BF22+BG22 -> 78 | BH44: =BH8+BI8+BH15+BI15+BH22+BI22 -> 78 | BJ44: =BJ8+BK8+BJ15+BK15+BJ22+BK22 -> 75 | BL44: =BL8+BM8+BL15+BM15+BL22+BM22 -> 57
A45: PU - SA | D45: =D3+E3+D10+E10+D17+E17 -> 29 | F45: =F3+G3+F10+G10+F17+G17 -> 0 | H45: =H3+I3+H10+I10+H17+I17 -> 0 | J45: =J3+K3+J10+K10+J17+K17 -> 33 | L45: =L3+M3+L10+M10+L17+M17 -> 33 | N45: =N3+O3+N10+O10+N17+O17 -> 33 | P45: =P3+Q3+P10+Q10+P17+Q17 -> 33 | R45: =R3+S3+R10+S10+R17+S17 -> 33 | T45: =T3+U3+T10+U10+T17+U17 -> 0 | V45: =V3+W3+V10+W10+V17+W17 -> 0 | X45: =X3+Y3+X10+Y10+X17+Y17 -> 33 | Z45: =Z3+AA3+Z10+AA10+Z17+AA17 -> 33 | AB45: =AB3+AC3+AB10+AC10+AB17+AC17 -> 32 | AD45: =AD3+AE3+AD10+AE10+AD17+AE17 -> 33 | AF45: =AF3+AG3+AF10+AG10+AF17+AG17 -> 0 | AH45: =AH3+AI3+AH10+AI10+AH17+AI17 -> 0 | AJ45: =AJ3+AK3+AJ10+AK10+AJ17+AK17 -> 0 | AL45: =AL3+AM3+AL10+AM10+AL17+AM17 -> 33 | AN45: =AN3+AO3+AN10+AO10+AN17+AO17 -> 33 | AP45: =AP3+AQ3+AP10+AQ10+AP17+AQ17 -> 33 | AR45: =AR3+AS3+AR10+AS10+AR17+AS17 -> 30 | AT45: =AT3+AU3+AT10+AU10+AT17+AU17 -> 33 | AV45: =AV3+AW3+AV10+AW10+AV17+AW17 -> 0 | AX45: =AX3+AY3+AX10+AY10+AX17+AY17 -> 0 | AZ45: =AZ3+BA3+AZ10+BA10+AZ17+BA17 -> 33 | BB45: =BB3+BC3+BB10+BC10+BB17+BC17 -> 30 | BD45: =BD3+BE3+BD10+BE10+BD17+BE17 -> 33 | BF45: =BF3+BG3+BF10+BG10+BF17+BG17 -> 33 | BH45: =BH3+BI3+BH10+BI10+BH17+BI17 -> 33 | BJ45: =BJ3+BK3+BJ10+BK10+BJ17+BK17 -> 0 | BL45: =BL3+BM3+BL10+BM10+BL17+BM17 -> 0
A46: SA - PU | D46: =D6+E6+D13+E13+D20+E20 -> 29 | F46: =F6+G6+F13+G13+F20+G20 -> 0 | H46: =H6+I6+H13+I13+H20+I20 -> 0 | J46: =J6+K6+J13+K13+J20+K20 -> 32 | L46: =L6+M6+L13+M13+L20+M20 -> 32 | N46: =N6+O6+N13+O13+N20+O20 -> 32 | P46: =P6+Q6+P13+Q13+P20+Q20 -> 32 | R46: =R6+S6+R13+S13+R20+S20 -> 32 | T46: =T6+U6+T13+U13+T20+U20 -> 0 | V46: =V6+W6+V13+W13+V20+W20 -> 0 | X46: =X6+Y6+X13+Y13+X20+Y20 -> 32 | Z46: =Z6+AA6+Z13+AA13+Z20+AA20 -> 32 | AB46: =AB6+AC6+AB13+AC13+AB20+AC20 -> 31 | AD46: =AD6+AE6+AD13+AE13+AD20+AE20 -> 32 | AF46: =AF6+AG6+AF13+AG13+AF20+AG20 -> 0 | AH46: =AH6+AI6+AH13+AI13+AH20+AI20 -> 0 | AJ46: =AJ6+AK6+AJ13+AK13+AJ20+AK20 -> 0 | AL46: =AL6+AM6+AL13+AM13+AL20+AM20 -> 32 | AN46: =AN6+AO6+AN13+AO13+AN20+AO20 -> 32 | AP46: =AP6+AQ6+AP13+AQ13+AP20+AQ20 -> 32 | AR46: =AR6+AS6+AR13+AS13+AR20+AS20 -> 32 | AT46: =AT6+AU6+AT13+AU13+AT20+AU20 -> 32 | AV46: =AV6+AW6+AV13+AW13+AV20+AW20 -> 0 | AX46: =AX6+AY6+AX13+AY13+AX20+AY20 -> 0 | AZ46: =AZ6+BA6+AZ13+BA13+AZ20+BA20 -> 32 | BB46: =BB6+BC6+BB13+BC13+BB20+BC20 -> 31 | BD46: =BD6+BE6+BD13+BE13+BD20+BE20 -> 32 | BF46: =BF6+BG6+BF13+BG13+BF20+BG20 -> 32 | BH46: =BH6+BI6+BH13+BI13+BH20+BI20 -> 32 | BJ46: =BJ6+BK6+BJ13+BK13+BJ20+BK20 -> 0 | BL46: =BL6+BM6+BL13+BM13+BL20+BM20 -> 0
A47: PU-EB | D47: =D4+E4+D11+E11+D18+E18 -> 0 | F47: =F4+G4+F11+G11+F18+G18 -> 0 | H47: =H4+I4+H11+I11+H18+I18 -> 0 | J47: =J4+K4+J11+K11+J18+K18 -> 0 | L47: =L4+M4+L11+M11+L18+M18 -> 0 | N47: =N4+O4+N11+O11+N18+O18 -> 0 | P47: =P4+Q4+P11+Q11+P18+Q18 -> 0 | R47: =R4+S4+R11+S11+R18+S18 -> 0 | T47: =T4+U4+T11+U11+T18+U18 -> 0 | V47: =V4+W4+V11+W11+V18+W18 -> 0 | X47: =X4+Y4+X11+Y11+X18+Y18 -> 0 | Z47: =Z4+AA4+Z11+AA11+Z18+AA18 -> 0 | AB47: =AB4+AC4+AB11+AC11+AB18+AC18 -> 0 | AD47: =AD4+AE4+AD11+AE11+AD18+AE18 -> 0 | AF47: =AF4+AG4+AF11+AG11+AF18+AG18 -> 0 | AH47: =AH4+AI4+AH11+AI11+AH18+AI18 -> 0 | AJ47: =AJ4+AK4+AJ11+AK11+AJ18+AK18 -> 0 | AL47: =AL4+AM4+AL11+AM11+AL18+AM18 -> 0 | AN47: =AN4+AO4+AN11+AO11+AN18+AO18 -> 0 | AP47: =AP4+AQ4+AP11+AQ11+AP18+AQ18 -> 0 | AR47: =AR4+AS4+AR11+AS11+AR18+AS18 -> 0 | AT47: =AT4+AU4+AT11+AU11+AT18+AU18 -> 0 | AV47: =AV4+AW4+AV11+AW11+AV18+AW18 -> 0 | AX47: =AX4+AY4+AX11+AY11+AX18+AY18 -> 0 | AZ47: =AZ4+BA4+AZ11+BA11+AZ18+BA18 -> 0 | BB47: =BB4+BC4+BB11+BC11+BB18+BC18 -> 0 | BD47: =BD4+BE4+BD11+BE11+BD18+BE18 -> 0 | BF47: =BF4+BG4+BF11+BG11+BF18+BG18 -> 0 | BH47: =BH4+BI4+BH11+BI11+BH18+BI18 -> 0 | BJ47: =BJ4+BK4+BJ11+BK11+BJ18+BK18 -> 0 | BL47: =BL4+BM4+BL11+BM11+BL18+BM18 -> 0
A48: EB-PU | D48: =D7+E7+D14+E14+D21+E21 -> 1 | F48: =F7+G7+F14+G14+F21+G21 -> 0 | H48: =H7+I7+H14+I14+H21+I21 -> 0 | J48: =J7+K7+J14+K14+J21+K21 -> 1 | L48: =L7+M7+L14+M14+L21+M21 -> 1 | N48: =N7+O7+N14+O14+N21+O21 -> 1 | P48: =P7+Q7+P14+Q14+P21+Q21 -> 1 | R48: =R7+S7+R14+S14+R21+S21 -> 1 | T48: =T7+U7+T14+U14+T21+U21 -> 0 | V48: =V7+W7+V14+W14+V21+W21 -> 0 | X48: =X7+Y7+X14+Y14+X21+Y21 -> 1 | Z48: =Z7+AA7+Z14+AA14+Z21+AA21 -> 1 | AB48: =AB7+AC7+AB14+AC14+AB21+AC21 -> 1 | AD48: =AD7+AE7+AD14+AE14+AD21+AE21 -> 1 | AF48: =AF7+AG7+AF14+AG14+AF21+AG21 -> 0 | AH48: =AH7+AI7+AH14+AI14+AH21+AI21 -> 0 | AJ48: =AJ7+AK7+AJ14+AK14+AJ21+AK21 -> 0 | AL48: =AL7+AM7+AL14+AM14+AL21+AM21 -> 1 | AN48: =AN7+AO7+AN14+AO14+AN21+AO21 -> 1 | AP48: =AP7+AQ7+AP14+AQ14+AP21+AQ21 -> 1 | AR48: =AR7+AS7+AR14+AS14+AR21+AS21 -> 1 | AT48: =AT7+AU7+AT14+AU14+AT21+AU21 -> 1 | AV48: =AV7+AW7+AV14+AW14+AV21+AW21 -> 0 | AX48: =AX7+AY7+AX14+AY14+AX21+AY21 -> 0 | AZ48: =AZ7+BA7+AZ14+BA14+AZ21+BA21 -> 1 | BB48: =BB7+BC7+BB14+BC14+BB21+BC21 -> 1 | BD48: =BD7+BE7+BD14+BE14+BD21+BE21 -> 1 | BF48: =BF7+BG7+BF14+BG14+BF21+BG21 -> 1 | BH48: =BH7+BI7+BH14+BI14+BH21+BI21 -> 1 | BJ48: =BJ7+BK7+BJ14+BK14+BJ21+BK21 -> 0 | BL48: =BL7+BM7+BL14+BM14+BL21+BM21 -> 0
A49: PU-CH | D49: =D24+E24 -> 1
A51: Trenes
A52: PU - LI | D52: =(D5+D12+D19)+2*(E5+E12+E19) -> 90 | F52: =(F5+F12+F19)+2*(G5+G12+G19) -> 75 | H52: =(H5+H12+H19)+2*(I5+I12+I19) -> 57 | J52: =(J5+J12+J19)+2*(K5+K12+K19) -> 97 | L52: =(L5+L12+L19)+2*(M5+M12+M19) -> 98 | N52: =(N5+N12+N19)+2*(O5+O12+O19) -> 98 | P52: =(P5+P12+P19)+2*(Q5+Q12+Q19) -> 98 | R52: =(R5+R12+R19)+2*(S5+S12+S19) -> 98 | T52: =(T5+T12+T19)+2*(U5+U12+U19) -> 75 | V52: =(V5+V12+V19)+2*(W5+W12+W19) -> 57 | X52: =(X5+X12+X19)+2*(Y5+Y12+Y19) -> 108 | Z52: =(Z5+Z12+Z19)+2*(AA5+AA12+AA19) -> 108 | AB52: =(AB5+AB12+AB19)+2*(AC5+AC12+AC19) -> 107 | AD52: =(AD5+AD12+AD19)+2*(AE5+AE12+AE19) -> 107 | AF52: =(AF5+AF12+AF19)+2*(AG5+AG12+AG19) -> 57 | AH52: =(AH5+AH12+AH19)+2*(AI5+AI12+AI19) -> 75 | AJ52: =(AJ5+AJ12+AJ19)+2*(AK5+AK12+AK19) -> 57 | AL52: =(AL5+AL12+AL19)+2*(AM5+AM12+AM19) -> 109 | AN52: =(AN5+AN12+AN19)+2*(AO5+AO12+AO19) -> 111 | AP52: =(AP5+AP12+AP19)+2*(AQ5+AQ12+AQ19) -> 113 | AR52: =(AR5+AR12+AR19)+2*(AS5+AS12+AS19) -> 111 | AT52: =(AT5+AT12+AT19)+2*(AU5+AU12+AU19) -> 103 | AV52: =(AV5+AV12+AV19)+2*(AW5+AW12+AW19) -> 75 | AX52: =(AX5+AX12+AX19)+2*(AY5+AY12+AY19) -> 57 | AZ52: =(AZ5+AZ12+AZ19)+2*(BA5+BA12+BA19) -> 111 | BB52: =(BB5+BB12+BB19)+2*(BC5+BC12+BC19) -> 111 | BD52: =(BD5+BD12+BD19)+2*(BE5+BE12+BE19) -> 112 | BF52: =(BF5+BF12+BF19)+2*(BG5+BG12+BG19) -> 111 | BH52: =(BH5+BH12+BH19)+2*(BI5+BI12+BI19) -> 111 | BJ52: =(BJ5+BJ12+BJ19)+2*(BK5+BK12+BK19) -> 75 | BL52: =(BL5+BL12+BL19)+2*(BM5+BM12+BM19) -> 57
A53: LI - PU | D53: =(D8+D15+D22)+2*(E8+E15+E22) -> 90 | F53: =(F8+F15+F22)+2*(G8+G15+G22) -> 75 | H53: =(H8+H15+H22)+2*(I8+I15+I22) -> 57 | J53: =(J8+J15+J22)+2*(K8+K15+K22) -> 97 | L53: =(L8+L15+L22)+2*(M8+M15+M22) -> 98 | N53: =(N8+N15+N22)+2*(O8+O15+O22) -> 98 | P53: =(P8+P15+P22)+2*(Q8+Q15+Q22) -> 98 | R53: =(R8+R15+R22)+2*(S8+S15+S22) -> 98 | T53: =(T8+T15+T22)+2*(U8+U15+U22) -> 75 | V53: =(V8+V15+V22)+2*(W8+W15+W22) -> 57 | X53: =(X8+X15+X22)+2*(Y8+Y15+Y22) -> 108 | Z53: =(Z8+Z15+Z22)+2*(AA8+AA15+AA22) -> 108 | AB53: =(AB8+AB15+AB22)+2*(AC8+AC15+AC22) -> 107 | AD53: =(AD8+AD15+AD22)+2*(AE8+AE15+AE22) -> 107 | AF53: =(AF8+AF15+AF22)+2*(AG8+AG15+AG22) -> 57 | AH53: =(AH8+AH15+AH22)+2*(AI8+AI15+AI22) -> 75 | AJ53: =(AJ8+AJ15+AJ22)+2*(AK8+AK15+AK22) -> 57 | AL53: =(AL8+AL15+AL22)+2*(AM8+AM15+AM22) -> 112 | AN53: =(AN8+AN15+AN22)+2*(AO8+AO15+AO22) -> 111 | AP53: =(AP8+AP15+AP22)+2*(AQ8+AQ15+AQ22) -> 113 | AR53: =(AR8+AR15+AR22)+2*(AS8+AS15+AS22) -> 112 | AT53: =(AT8+AT15+AT22)+2*(AU8+AU15+AU22) -> 103 | AV53: =(AV8+AV15+AV22)+2*(AW8+AW15+AW22) -> 75 | AX53: =(AX8+AX15+AX22)+2*(AY8+AY15+AY22) -> 57 | AZ53: =(AZ8+AZ15+AZ22)+2*(BA8+BA15+BA22) -> 111 | BB53: =(BB8+BB15+BB22)+2*(BC8+BC15+BC22) -> 110 | BD53: =(BD8+BD15+BD22)+2*(BE8+BE15+BE22) -> 111 | BF53: =(BF8+BF15+BF22)+2*(BG8+BG15+BG22) -> 109 | BH53: =(BH8+BH15+BH22)+2*(BI8+BI15+BI22) -> 111 | BJ53: =(BJ8+BJ15+BJ22)+2*(BK8+BK15+BK22) -> 75 | BL53: =(BL8+BL15+BL22)+2*(BM8+BM15+BM22) -> 57
A54: PU - SA | D54: =(D3+D10+D17)+2*(E3+E10+E17) -> 29 | F54: =(F3+F10+F17)+2*(G3+G10+G17) -> 0 | H54: =(H3+H10+H17)+2*(I3+I10+I17) -> 0 | J54: =(J3+J10+J17)+2*(K3+K10+K17) -> 33 | L54: =(L3+L10+L17)+2*(M3+M10+M17) -> 33 | N54: =(N3+N10+N17)+2*(O3+O10+O17) -> 33 | P54: =(P3+P10+P17)+2*(Q3+Q10+Q17) -> 33 | R54: =(R3+R10+R17)+2*(S3+S10+S17) -> 33 | T54: =(T3+T10+T17)+2*(U3+U10+U17) -> 0 | V54: =(V3+V10+V17)+2*(W3+W10+W17) -> 0 | X54: =(X3+X10+X17)+2*(Y3+Y10+Y17) -> 36 | Z54: =(Z3+Z10+Z17)+2*(AA3+AA10+AA17) -> 36 | AB54: =(AB3+AB10+AB17)+2*(AC3+AC10+AC17) -> 35 | AD54: =(AD3+AD10+AD17)+2*(AE3+AE10+AE17) -> 36 | AF54: =(AF3+AF10+AF17)+2*(AG3+AG10+AG17) -> 0 | AH54: =(AH3+AH10+AH17)+2*(AI3+AI10+AI17) -> 0 | AJ54: =(AJ3+AJ10+AJ17)+2*(AK3+AK10+AK17) -> 0 | AL54: =(AL3+AL10+AL17)+2*(AM3+AM10+AM17) -> 37 | AN54: =(AN3+AN10+AN17)+2*(AO3+AO10+AO17) -> 37 | AP54: =(AP3+AP10+AP17)+2*(AQ3+AQ10+AQ17) -> 36 | AR54: =(AR3+AR10+AR17)+2*(AS3+AS10+AS17) -> 33 | AT54: =(AT3+AT10+AT17)+2*(AU3+AU10+AU17) -> 33 | AV54: =(AV3+AV10+AV17)+2*(AW3+AW10+AW17) -> 0 | AX54: =(AX3+AX10+AX17)+2*(AY3+AY10+AY17) -> 0 | AZ54: =(AZ3+AZ10+AZ17)+2*(BA3+BA10+BA17) -> 36 | BB54: =(BB3+BB10+BB17)+2*(BC3+BC10+BC17) -> 34 | BD54: =(BD3+BD10+BD17)+2*(BE3+BE10+BE17) -> 37 | BF54: =(BF3+BF10+BF17)+2*(BG3+BG10+BG17) -> 36 | BH54: =(BH3+BH10+BH17)+2*(BI3+BI10+BI17) -> 36 | BJ54: =(BJ3+BJ10+BJ17)+2*(BK3+BK10+BK17) -> 0 | BL54: =(BL3+BL10+BL17)+2*(BM3+BM10+BM17) -> 0
A55: SA - PU | D55: =(D6+D13+D20)+2*(E6+E13+E20) -> 29 | F55: =(F6+F13+F20)+2*(G6+G13+G20) -> 0 | H55: =(H6+H13+H20)+2*(I6+I13+I20) -> 0 | J55: =(J6+J13+J20)+2*(K6+K13+K20) -> 32 | L55: =(L6+L13+L20)+2*(M6+M13+M20) -> 32 | N55: =(N6+N13+N20)+2*(O6+O13+O20) -> 32 | P55: =(P6+P13+P20)+2*(Q6+Q13+Q20) -> 32 | R55: =(R6+R13+R20)+2*(S6+S13+S20) -> 32 | T55: =(T6+T13+T20)+2*(U6+U13+U20) -> 0 | V55: =(V6+V13+V20)+2*(W6+W13+W20) -> 0 | X55: =(X6+X13+X20)+2*(Y6+Y13+Y20) -> 35 | Z55: =(Z6+Z13+Z20)+2*(AA6+AA13+AA20) -> 35 | AB55: =(AB6+AB13+AB20)+2*(AC6+AC13+AC20) -> 34 | AD55: =(AD6+AD13+AD20)+2*(AE6+AE13+AE20) -> 35 | AF55: =(AF6+AF13+AF20)+2*(AG6+AG13+AG20) -> 0 | AH55: =(AH6+AH13+AH20)+2*(AI6+AI13+AI20) -> 0 | AJ55: =(AJ6+AJ13+AJ20)+2*(AK6+AK13+AK20) -> 0 | AL55: =(AL6+AL13+AL20)+2*(AM6+AM13+AM20) -> 36 | AN55: =(AN6+AN13+AN20)+2*(AO6+AO13+AO20) -> 36 | AP55: =(AP6+AP13+AP20)+2*(AQ6+AQ13+AQ20) -> 35 | AR55: =(AR6+AR13+AR20)+2*(AS6+AS13+AS20) -> 35 | AT55: =(AT6+AT13+AT20)+2*(AU6+AU13+AU20) -> 32 | AV55: =(AV6+AV13+AV20)+2*(AW6+AW13+AW20) -> 0 | AX55: =(AX6+AX13+AX20)+2*(AY6+AY13+AY20) -> 0 | AZ55: =(AZ6+AZ13+AZ20)+2*(BA6+BA13+BA20) -> 35 | BB55: =(BB6+BB13+BB20)+2*(BC6+BC13+BC20) -> 35 | BD55: =(BD6+BD13+BD20)+2*(BE6+BE13+BE20) -> 36 | BF55: =(BF6+BF13+BF20)+2*(BG6+BG13+BG20) -> 35 | BH55: =(BH6+BH13+BH20)+2*(BI6+BI13+BI20) -> 35 | BJ55: =(BJ6+BJ13+BJ20)+2*(BK6+BK13+BK20) -> 0 | BL55: =(BL6+BL13+BL20)+2*(BM6+BM13+BM20) -> 0
A56: PU-EB | D56: =(D4+D11+D18)+2*(E4+E11+E18) -> 0 | F56: =(F4+F11+F18)+2*(G4+G11+G18) -> 0 | H56: =(H4+H11+H18)+2*(I4+I11+I18) -> 0 | J56: =(J4+J11+J18)+2*(K4+K11+K18) -> 0 | L56: =(L4+L11+L18)+2*(M4+M11+M18) -> 0 | N56: =(N4+N11+N18)+2*(O4+O11+O18) -> 0 | P56: =(P4+P11+P18)+2*(Q4+Q11+Q18) -> 0 | R56: =(R4+R11+R18)+2*(S4+S11+S18) -> 0 | T56: =(T4+T11+T18)+2*(U4+U11+U18) -> 0 | V56: =(V4+V11+V18)+2*(W4+W11+W18) -> 0 | X56: =(X4+X11+X18)+2*(Y4+Y11+Y18) -> 0 | Z56: =(Z4+Z11+Z18)+2*(AA4+AA11+AA18) -> 0 | AB56: =(AB4+AB11+AB18)+2*(AC4+AC11+AC18) -> 0 | AD56: =(AD4+AD11+AD18)+2*(AE4+AE11+AE18) -> 0 | AF56: =(AF4+AF11+AF18)+2*(AG4+AG11+AG18) -> 0 | AH56: =(AH4+AH11+AH18)+2*(AI4+AI11+AI18) -> 0 | AJ56: =(AJ4+AJ11+AJ18)+2*(AK4+AK11+AK18) -> 0 | AL56: =(AL4+AL11+AL18)+2*(AM4+AM11+AM18) -> 0 | AN56: =(AN4+AN11+AN18)+2*(AO4+AO11+AO18) -> 0 | AP56: =(AP4+AP11+AP18)+2*(AQ4+AQ11+AQ18) -> 0 | AR56: =(AR4+AR11+AR18)+2*(AS4+AS11+AS18) -> 0 | AT56: =(AT4+AT11+AT18)+2*(AU4+AU11+AU18) -> 0 | AV56: =(AV4+AV11+AV18)+2*(AW4+AW11+AW18) -> 0 | AX56: =(AX4+AX11+AX18)+2*(AY4+AY11+AY18) -> 0 | AZ56: =(AZ4+AZ11+AZ18)+2*(BA4+BA11+BA18) -> 0 | BB56: =(BB4+BB11+BB18)+2*(BC4+BC11+BC18) -> 0 | BD56: =(BD4+BD11+BD18)+2*(BE4+BE11+BE18) -> 0 | BF56: =(BF4+BF11+BF18)+2*(BG4+BG11+BG18) -> 0 | BH56: =(BH4+BH11+BH18)+2*(BI4+BI11+BI18) -> 0 | BJ56: =(BJ4+BJ11+BJ18)+2*(BK4+BK11+BK18) -> 0 | BL56: =(BL4+BL11+BL18)+2*(BM4+BM11+BM18) -> 0
...

Sheet Oferta Diaria
A1: Oferta Agosto 2025
C3: 45870 | D3: 45871 | E3: 45872 | F3: 45873 | G3: 45874 | H3: 45875 | I3: 45876 | J3: 45877 | K3: 45878 | L3: 45879 | M3: 45880 | N3: 45881 | O3: 45882 | P3: 45883 | Q3: 45884 | R3: 45885 | S3: 45886 | T3: 45887 | U3: 45888 | V3: 45889 | W3: 45890 | X3: 45891 | Y3: 45892 | Z3: 45893 | AA3: 45894 | AB3: 45895 | AC3: 45896 | AD3: 45897 | AE3: 45898 | AF3: 45899 | AG3: 45900
A4: HÁBIL | B4: km
A5: Servicios PU-LI | B5: 43.13 | C5: ='Data Ocupacion'!D43 -> 79 | D5: ='Data Ocupacion'!F43 -> 72 | E5: ='Data Ocupacion'!H43 -> 54 | F5: ='Data Ocupacion'!J43 -> 79 | G5: ='Data Ocupacion'!L43 -> 79 | H5: ='Data Ocupacion'!N43 -> 79 | I5: ='Data Ocupacion'!P43 -> 79 | J5: ='Data Ocupacion'!R43 -> 79 | K5: ='Data Ocupacion'!T43 -> 72 | L5: ='Data Ocupacion'!V43 -> 54 | M5: ='Data Ocupacion'!X43 -> 79 | N5: ='Data Ocupacion'!Z43 -> 79 | O5: ='Data Ocupacion'!AB43 -> 80 | P5: ='Data Ocupacion'!AD43 -> 79 | Q5: ='Data Ocupacion'!AF43 -> 54 | R5: ='Data Ocupacion'!AH43 -> 72 | S5: ='Data Ocupacion'!AJ43 -> 54 | T5: ='Data Ocupacion'!AL43 -> 78 | U5: ='Data Ocupacion'!AN43 -> 79 | V5: ='Data Ocupacion'!AP43 -> 79 | W5: ='Data Ocupacion'!AR43 -> 80 | X5: ='Data Ocupacion'!AT43 -> 79 | Y5: ='Data Ocupacion'!AV43 -> 72 | Z5: ='Data Ocupacion'!AX43 -> 54 | AA5: ='Data Ocupacion'!AZ43 -> 79 | AB5: ='Data Ocupacion'!BB43 -> 80 | AC5: ='Data Ocupacion'!BD43 -> 79 | AD5: ='Data Ocupacion'!BF43 -> 79 | AE5: ='Data Ocupacion'!BH43 -> 79 | AF5: ='Data Ocupacion'!BJ43 -> 72 | AG5: ='Data Ocupacion'!BL43 -> 54
A6: Servicios LI-PU | B6: 43.13 | C6: ='Data Ocupacion'!D44 -> 78 | D6: ='Data Ocupacion'!F44 -> 75 | E6: ='Data Ocupacion'!H44 -> 57 | F6: ='Data Ocupacion'!J44 -> 78 | G6: ='Data Ocupacion'!L44 -> 78 | H6: ='Data Ocupacion'!N44 -> 78 | I6: ='Data Ocupacion'!P44 -> 78 | J6: ='Data Ocupacion'!R44 -> 78 | K6: ='Data Ocupacion'!T44 -> 75 | L6: ='Data Ocupacion'!V44 -> 57 | M6: ='Data Ocupacion'!X44 -> 78 | N6: ='Data Ocupacion'!Z44 -> 78 | O6: ='Data Ocupacion'!AB44 -> 78 | P6: ='Data Ocupacion'!AD44 -> 78 | Q6: ='Data Ocupacion'!AF44 -> 57 | R6: ='Data Ocupacion'!AH44 -> 75 | S6: ='Data Ocupacion'!AJ44 -> 57 | T6: ='Data Ocupacion'!AL44 -> 78 | U6: ='Data Ocupacion'!AN44 -> 78 | V6: ='Data Ocupacion'!AP44 -> 78 | W6: ='Data Ocupacion'!AR44 -> 78 | X6: ='Data Ocupacion'!AT44 -> 78 | Y6: ='Data Ocupacion'!AV44 -> 75 | Z6: ='Data Ocupacion'!AX44 -> 57 | AA6: ='Data Ocupacion'!AZ44 -> 78 | AB6: ='Data Ocupacion'!BB44 -> 78 | AC6: ='Data Ocupacion'!BD44 -> 78 | AD6: ='Data Ocupacion'!BF44 -> 78 | AE6: ='Data Ocupacion'!BH44 -> 78 | AF6: ='Data Ocupacion'!BJ44 -> 75 | AG6: ='Data Ocupacion'!BL44 -> 57
A7: Servicios PU-SA | B7: 29.11 | C7: ='Data Ocupacion'!D45 -> 29 | D7: ='Data Ocupacion'!F45 -> 0 | E7: ='Data Ocupacion'!H45 -> 0 | F7: ='Data Ocupacion'!J45 -> 33 | G7: ='Data Ocupacion'!L45 -> 33 | H7: ='Data Ocupacion'!N45 -> 33 | I7: ='Data Ocupacion'!P45 -> 33 | J7: ='Data Ocupacion'!R45 -> 33 | K7: ='Data Ocupacion'!T45 -> 0 | L7: ='Data Ocupacion'!V45 -> 0 | M7: ='Data Ocupacion'!X45 -> 33 | N7: ='Data Ocupacion'!Z45 -> 33 | O7: ='Data Ocupacion'!AB45 -> 32 | P7: ='Data Ocupacion'!AD45 -> 33 | Q7: ='Data Ocupacion'!AF45 -> 0 | R7: ='Data Ocupacion'!AH45 -> 0 | S7: ='Data Ocupacion'!AJ45 -> 0 | T7: ='Data Ocupacion'!AL45 -> 33 | U7: ='Data Ocupacion'!AN45 -> 33 | V7: ='Data Ocupacion'!AP45 -> 33 | W7: ='Data Ocupacion'!AR45 -> 30 | X7: ='Data Ocupacion'!AT45 -> 33 | Y7: ='Data Ocupacion'!AV45 -> 0 | Z7: ='Data Ocupacion'!AX45 -> 0 | AA7: ='Data Ocupacion'!AZ45 -> 33 | AB7: ='Data Ocupacion'!BB45 -> 30 | AC7: ='Data Ocupacion'!BD45 -> 33 | AD7: ='Data Ocupacion'!BF45 -> 33 | AE7: ='Data Ocupacion'!BH45 -> 33 | AF7: ='Data Ocupacion'!BJ45 -> 0 | AG7: ='Data Ocupacion'!BK45 -> 0
A8: Servicios SA-PU | B8: 29.11 | C8: ='Data Ocupacion'!D46 -> 29 | D8: ='Data Ocupacion'!F46 -> 0 | E8: ='Data Ocupacion'!H46 -> 0 | F8: ='Data Ocupacion'!J46 -> 32 | G8: ='Data Ocupacion'!L46 -> 32 | H8: ='Data Ocupacion'!N46 -> 32 | I8: ='Data Ocupacion'!P46 -> 32 | J8: ='Data Ocupacion'!R46 -> 32 | K8: ='Data Ocupacion'!T46 -> 0 | L8: ='Data Ocupacion'!V46 -> 0 | M8: ='Data Ocupacion'!X46 -> 32 | N8: ='Data Ocupacion'!Z46 -> 32 | O8: ='Data Ocupacion'!AB46 -> 31 | P8: ='Data Ocupacion'!AD46 -> 32 | Q8: ='Data Ocupacion'!AF46 -> 0 | R8: ='Data Ocupacion'!AH46 -> 0 | S8: ='Data Ocupacion'!AJ46 -> 0 | T8: ='Data Ocupacion'!AL46 -> 32 | U8: ='Data Ocupacion'!AN46 -> 32 | V8: ='Data Ocupacion'!AP46 -> 32 | W8: ='Data Ocupacion'!AR46 -> 32 | X8: ='Data Ocupacion'!AT46 -> 32 | Y8: ='Data Ocupacion'!AV46 -> 0 | Z8: ='Data Ocupacion'!AX46 -> 0 | AA8: ='Data Ocupacion'!AZ46 -> 32 | AB8: ='Data Ocupacion'!BB46 -> 31 | AC8: ='Data Ocupacion'!BD46 -> 32 | AD8: ='Data Ocupacion'!BF46 -> 32 | AE8: ='Data Ocupacion'!BH46 -> 32 | AF8: ='Data Ocupacion'!BJ46 -> 0 | AG8: ='Data Ocupacion'!BK46 -> 0
A9: Servicios PU-EB | B9: 25.4 | C9: ='Data Ocupacion'!D47 -> 0 | D9: ='Data Ocupacion'!F47 -> 0 | E9: ='Data Ocupacion'!H47 -> 0 | F9: ='Data Ocupacion'!J47 -> 0 | G9: ='Data Ocupacion'!L47 -> 0 | H9: ='Data Ocupacion'!N47 -> 0 | I9: ='Data Ocupacion'!P47 -> 0 | J9: ='Data Ocupacion'!R47 -> 0 | K9: ='Data Ocupacion'!T47 -> 0 | L9: ='Data Ocupacion'!V47 -> 0 | M9: ='Data Ocupacion'!X47 -> 0 | N9: ='Data Ocupacion'!Z47 -> 0 | O9: ='Data Ocupacion'!AB47 -> 0 | P9: ='Data Ocupacion'!AD47 -> 0 | Q9: ='Data Ocupacion'!AF47 -> 0 | R9: ='Data Ocupacion'!AH47 -> 0 | S9: ='Data Ocupacion'!AJ47 -> 0 | T9: ='Data Ocupacion'!AL47 -> 0 | U9: ='Data Ocupacion'!AN47 -> 0 | V9: ='Data Ocupacion'!AP47 -> 0 | W9: ='Data Ocupacion'!AR47 -> 0 | X9: ='Data Ocupacion'!AT47 -> 0 | Y9: ='Data Ocupacion'!AV47 -> 0 | Z9: ='Data Ocupacion'!AX47 -> 0 | AA9: ='Data Ocupacion'!AZ47 -> 0 | AB9: ='Data Ocupacion'!BB47 -> 0 | AC9: ='Data Ocupacion'!BD47 -> 0 | AD9: ='Data Ocupacion'!BF47 -> 0 | AE9: ='Data Ocupacion'!BH47 -> 0 | AF9: ='Data Ocupacion'!BJ47 -> 0 | AG9: ='Data Ocupacion'!BK47 -> 0
A10: Servicios EB-PU | B10: 25.4 | C10: ='Data Ocupacion'!D48 -> 1 | D10: ='Data Ocupacion'!F48 -> 0 | E10: ='Data Ocupacion'!H48 -> 0 | F10: ='Data Ocupacion'!J48 -> 1 | G10: ='Data Ocupacion'!L48 -> 1 | H10: ='Data Ocupacion'!N48 -> 1 | I10: ='Data Ocupacion'!P48 -> 1 | J10: ='Data Ocupacion'!R48 -> 1 | K10: ='Data Ocupacion'!T48 -> 0 | L10: ='Data Ocupacion'!V48 -> 0 | M10: ='Data Ocupacion'!X48 -> 1 | N10: ='Data Ocupacion'!Z48 -> 1 | O10: ='Data Ocupacion'!AB48 -> 1 | P10: ='Data Ocupacion'!AD48 -> 1 | Q10: ='Data Ocupacion'!AF48 -> 0 | R10: ='Data Ocupacion'!AH48 -> 0 | S10: ='Data Ocupacion'!AJ48 -> 0 | T10: ='Data Ocupacion'!AL48 -> 1 | U10: ='Data Ocupacion'!AN48 -> 1 | V10: ='Data Ocupacion'!AP48 -> 1 | W10: ='Data Ocupacion'!AR48 -> 1 | X10: ='Data Ocupacion'!AT48 -> 1 | Y10: ='Data Ocupacion'!AV48 -> 0 | Z10: ='Data Ocupacion'!AX48 -> 0 | AA10: ='Data Ocupacion'!AZ48 -> 1 | AB10: ='Data Ocupacion'!BB48 -> 1 | AC10: ='Data Ocupacion'!BD48 -> 1 | AD10: ='Data Ocupacion'!BF48 -> 1 | AE10: ='Data Ocupacion'!BH48 -> 1 | AF10: ='Data Ocupacion'!BJ48 -> 0 | AG10: ='Data Ocupacion'!BK48 -> 0
A11: Servicios PU-CH | B11: 10.55 | C11: ='Data Ocupacion'!D49 -> 1
A13: Trenes PU-LI | B13: 43.13 | C13: ='Data Ocupacion'!D52 -> 90 | D13: ='Data Ocupacion'!F52 -> 75 | E13: ='Data Ocupacion'!H52 -> 57 | F13: ='Data Ocupacion'!J52 -> 97 | G13: ='Data Ocupacion'!L52 -> 98 | H13: ='Data Ocupacion'!N52 -> 98 | I13: ='Data Ocupacion'!P52 -> 98 | J13: ='Data Ocupacion'!R52 -> 98 | K13: ='Data Ocupacion'!T52 -> 75 | L13: ='Data Ocupacion'!V52 -> 57 | M13: ='Data Ocupacion'!X52 -> 108 | N13: ='Data Ocupacion'!Z52 -> 108 | O13: ='Data Ocupacion'!AB52 -> 107 | P13: ='Data Ocupacion'!AD52 -> 107 | Q13: ='Data Ocupacion'!AF52 -> 57 | R13: ='Data Ocupacion'!AH52 -> 75 | S13: ='Data Ocupacion'!AJ52 -> 57 | T13: ='Data Ocupacion'!AL52 -> 109 | U13: ='Data Ocupacion'!AN52 -> 111 | V13: ='Data Ocupacion'!AP52 -> 113 | W13: ='Data Ocupacion'!AR52 -> 111 | X13: ='Data Ocupacion'!AT52 -> 103 | Y13: ='Data Ocupacion'!AV52 -> 75 | Z13: ='Data Ocupacion'!AX52 -> 57 | AA13: ='Data Ocupacion'!AZ52 -> 111 | AB13: ='Data Ocupacion'!BB52 -> 111 | AC13: ='Data Ocupacion'!BD52 -> 112 | AD13: ='Data Ocupacion'!BF52 -> 111 | AE13: ='Data Ocupacion'!BH52 -> 111 | AF13: ='Data Ocupacion'!BJ52 -> 75 | AG13: ='Data Ocupacion'!BL52 -> 57
