Workbook

Sheet Odometro-Kilometraje
A1: Control Contador Kilometraje de Trenes
B2: 46054 | C2: 46055 | D2: 46056 | E2: 46057 | F2: 46058 | G2: 46059 | H2: 46060 | I2: 46061 | J2: 46062 | K2: 46063 | L2: 46064 | M2: 46065 | N2: 46066 | O2: 46067 | P2: 46068 | Q2: 46069 | R2: 46070 | S2: 46071 | T2: 46072 | U2: 46073 | V2: 46074 | W2: 46075 | X2: 46076 | Y2: 46077 | Z2: 46078 | AA2: 46079 | AB2: 46080 | AC2: 46081
B3: Contador | C3: Contador | D3: Contador | E3: Contador | F3: Contador | G3: Contador | H3: Contador | I3: Contador | J3: Contador | K3: Contador | L3: Contador | M3: Contador | N3: Contador | O3: Contador | P3: Contador | Q3: Contador | R3: Contador | S3: Contador | T3: Contador | U3: Contador | V3: Contador | W3: Contador | X3: Contador | Y3: Contador | Z3: Contador | AA3: Contador | AB3: Contador | AC3: Contador
A4: Tren | B4: Odómetro | C4: Odómetro | D4: Odómetro | E4: Odómetro | F4: Odómetro | G4: Odómetro | H4: Odómetro | I4: Odómetro | J4: Odómetro | K4: Odómetro | L4: Odómetro | M4: Odómetro | N4: Odómetro | O4: Odómetro | P4: Odómetro | Q4: Odómetro | R4: Odómetro | S4: Odómetro | T4: Odómetro | U4: Odómetro | V4: Odómetro | W4: Odómetro | X4: Odómetro | Y4: Odómetro | Z4: Odómetro | AA4: Odómetro | AB4: Odómetro | AC4: Odómetro
A5: M01 | B5: 2093394 | C5: 2093802 | D5: 2093936 | E5: 2094015 | F5: 2094190 | G5: 2094647 | H5: 2094647 | I5: 2094647 | J5: 2094851 | K5: 2095129 | L5: 2095372 | M5: 2095937 | N5: 2096001 | O5: 2096001 | P5: 2096001 | Q5: 2096001 | R5: 2096039 | S5: 2096510 | T5: 2096735 | U5: 2097323 | V5: 2097842 | W5: 2098276 | X5: 2098282 | Y5: 2098458 | Z5: 2098976 | AA5: 2099153 | AB5: 2099672 | AC5: 2100190
A6: M02 | B6: 2057024 | C6: 2057095 | D6: 2057597 | E6: 2058115 | F6: 2058570 | G6: 2058570 | H6: 2058570 | I6: 2058570 | J6: 2058571 | K6: 2058571 | L6: 2058572 | M6: 2058705 | N6: 2059139 | O6: 2059139 | P6: 2059139 | Q6: 2059436 | R6: 2059912 | S6: 2060473 | T6: 2061035 | U6: 2061640 | V6: 2062202 | W6: 2062246 | X6: 2062423 | Y6: 2062493 | Z6: 2062866 | AA6: 2063429 | AB6: 2063949 | AC6: 2064582
A7: M03 | B7: 2135111 | C7: 2135128 | D7: 2135152 | E7: 2135152 | F7: 2135152 | G7: 2135152 | H7: 2135152 | I7: 2135152 | J7: 2135347 | K7: 2135908 | L7: 2136385 | M7: 2136836 | N7: 2136837 | O7: 2136837 | P7: 2136837 | Q7: 2136837 | R7: 2137002 | S7: 2137453 | T7: 2137697 | U7: 2138304 | V7: 2138822 | W7: 2139189 | X7: 2139303 | Y7: 2139908 | Z7: 2140245 | AA7: 2140375 | AB7: 2140965 | AC7: 2141008
A8: M04 | B8: 2141498 | C8: 2142059 | D8: 2142319 | E8: 2142580 | F8: 2142930 | G8: 2143148 | H8: 2143191 | I8: 2143668 | J8: 2144143 | K8: 2144143 | L8: 2144416 | M8: 2144418 | N8: 2144418 | O8: 2144418 | P8: 2144418 | Q8: 2144419 | R8: 2144670 | S8: 2144923 | T8: 2145440 | U8: 2145460 | V8: 2145460 | W8: 2145460 | X8: 2145534 | Y8: 2145753 | Z8: 2146357 | AA8: 2146977 | AB8: 2147202 | AC8: 2147676
A9: M05 | B9: 2056779 | C9: 2056872 | D9: 2057206 | E9: 2057590 | F9: 2057722 | G9: 2058129 | H9: 2058129 | I9: 2058129 | J9: 2058133 | K9: 2058153 | L9: 2058500 | M9: 2059063 | N9: 2059367 | O9: 2059800 | P9: 2059802 | Q9: 2060283 | R9: 2060847 | S9: 2061366 | T9: 2061817 | U9: 2061838 | V9: 2062015 | W9: 2062534 | X9: 2062863 | Y9: 2063494 | Z9: 2064057 | AA9: 2064147 | AB9: 2064245 | AC9: 2064245
A10: M06 | B10: 2165790 | C10: 2166395 | D10: 2166745 | E10: 2166935 | F10: 2167201 | G10: 2167635 | H10: 2167635 | I10: 2167637 | J10: 2168005 | K10: 2168106 | L10: 2168357 | M10: 2168551 | N10: 2168802 | O10: 2168802 | P10: 2168802 | Q10: 2169053 | R10: 2169305 | S10: 2169438 | T10: 2169693 | U10: 2170131 | V10: 2170649 | W10: 2171123 | X10: 2171841 | Y10: 2172135 | Z10: 2172336 | AA10: 2172672 | AB10: 2172752 | AC10: 2172752
A11: M07 | B11: 2200578 | C11: 2201006 | D11: 2201609 | E11: 2201929 | F11: 2202028 | G11: 2202028 | H11: 2202028 | I11: 2202028 | J11: 2202101 | K11: 2202101 | L11: 2202251 | M11: 2202854 | N11: 2202918 | O11: 2202918 | P11: 2203161 | Q11: 2203679 | R11: 2204197 | S11: 2204756 | T11: 2205249 | U11: 2205383 | V11: 2205383 | W11: 2205495 | X11: 2206098 | Y11: 2206355 | Z11: 2206341 | AA11: 2206732 | AB11: 2206966 | AC11: 2207597
A12: M08 | B12: 2102585 | C12: 2102938 | D12: 2103209 | E12: 2103611 | F12: 2103891 | G12: 2103891 | H12: 2103891 | I12: 2103891 | J12: 2104082 | K12: 2104355 | L12: 2104355 | M12: 2104960 | N12: 2105113 | O12: 2105113 | P12: 2105183 | Q12: 2105788 | R12: 2105997 | S12: 2106431 | T12: 2106536 | U12: 2106538 | V12: 2106538 | W12: 2106538 | X12: 2106738 | Y12: 2107259 | Z12: 2107712 | AA12: 2107809 | AB12: 2107966 | AC12: 2108485
A13: M09 | B13: 2081197 | C13: 2081398 | D13: 2081577 | E13: 2081599 | F13: 2081938 | G13: 2082189 | H13: 2082337 | I13: 2082380 | J13: 2082943 | K13: 2083231 | L13: 2083838 | M13: 2084269 | N13: 2084830 | O13: 2085218 | P13: 2085650 | Q13: 2086167 | R13: 2086169 | S13: 2086554 | T13: 2086645 | U13: 2086908 | V13: 2087512 | W13: 2088031 | X13: 2088552 | Y13: 2088685 | Z13: 2088765 | AA13: 2089199 | AB13: 2089874 | AC13: 2090391
A14: M10 | B14: 2154100 | C14: 2154351 | D14: 2154353 | E14: 2154939 | F14: 2155200 | G14: 2155461 | H14: 2155911 | I14: 2155911 | J14: 2156241 | K14: 2156401 | L14: 2156920 | M14: 2157097 | N14: 2157360 | O14: 2157364 | P14: 2157366 | Q14: 2157540 | R14: 2157887 | S14: 2158168 | T14: 2158421 | U14: 2158700 | V14: 2158700 | W14: 2158700 | X14: 2158833 | Y14: 2159087 | Z14: 2159351 | AA14: 2159958 | AB14: 2160322 | AC14: 2160322
A15: M11 | B15: 2177007 | C15: 2177373 | D15: 2177630 | E15: 2177729 | F15: 2177862 | G15: 2178121 | H15: 2178642 | I15: 2179117 | J15: 2179506 | K15: 2179531 | L15: 2179685 | M15: 2179947 | N15: 2180302 | O15: 2180863 | P15: 2181079 | Q15: 2181684 | R15: 2181899 | S15: 2182418 | T15: 2183024 | U15: 2183587 | V15: 2183631 | W15: 2184107 | X15: 2184685 | Y15: 2185360 | Z15: 2185432 | AA15: 2185681 | AB15: 2186357 | AC15: 2186948
A16: M12 | B16: 2025230 | C16: 2025451 | D16: 2025859 | E16: 2025992 | F16: 2026578 | G16: 2027095 | H16: 2027655 | I16: 2027699 | J16: 2027809 | K16: 2027941 | L16: 2028226 | M16: 2028487 | N16: 2029006 | O16: 2029523 | P16: 2029799 | Q16: 2030062 | R16: 2030390 | S16: 2030781 | T16: 2031025 | U16: 2031611 | V16: 2032128 | W16: 2032130 | X16: 2032221 | Y16: 2032472 | Z16: 2032723 | AA16: 2033224 | AB16: 2033897 | AC16: 2034330
... A39: XM35 | B39: 711453 | C39: 711562 | D39: 711562 | E39: 711562 | F39: 711562 | G39: 711562 | H39: 711562 | I39: 711562 | J39: 711600 | K39: 711600 | L39: 711640 | M39: 711659 | N39: 711834 | O39: 712265 | P39: 712265 | Q39: 712417 | R39: 712688 | S39: 712919 | T39: 713151 | U39: 713422 | V39: 713422 | W39: 713422 | X39: 713673 | Y39: 713936 | Z39: 714188 | AA39: 714534 | AB39: 714553 | AC39: 714553
A41: Kilometraje Diario Recorrido
B42: 46054 | C42: 46055 | D42: 46056 | E42: 46057 | F42: 46058 | G42: 46059 | H42: 46060 | I42: 46061 | J42: 46062 | K42: 46063 | L42: 46064 | M42: 46065 | N42: 46066 | O42: 46067 | P42: 46068 | Q42: 46069 | R42: 46070 | S42: 46071 | T42: 46072 | U42: 46073 | V42: 46074 | W42: 46075 | X42: 46076 | Y42: 46077 | Z42: 46078 | AA42: 46079 | AB42: 46080 | AC42: 46081
B43: Kilometraje | C43: Kilometraje | D43: Kilometraje | E43: Kilometraje | F43: Kilometraje | G43: Kilometraje | H43: Kilometraje | I43: Kilometraje | J43: Kilometraje | K43: Kilometraje | L43: Kilometraje | M43: Kilometraje | N43: Kilometraje | O43: Kilometraje | P43: Kilometraje | Q43: Kilometraje | R43: Kilometraje | S43: Kilometraje | T43: Kilometraje | U43: Kilometraje | V43: Kilometraje | W43: Kilometraje | X43: Kilometraje | Y43: Kilometraje | Z43: Kilometraje | AA43: Kilometraje | AB43: Kilometraje | AC43: Kilometraje
A44: Tren | B44: Diario | C44: Diario | D44: Diario | E44: Diario | F44: Diario | G44: Diario | H44: Diario | I44: Diario | J44: Diario | K44: Diario | L44: Diario | M44: Diario | N44: Diario | O44: Diario | P44: Diario | Q44: Diario | R44: Diario | S44: Diario | T44: Diario | U44: Diario | V44: Diario | W44: Diario | X44: Diario | Y44: Diario | Z44: Diario | AA44: Diario | AB44: Diario | AC44: Diario
A45: M01 | B45: 475 | C45: =C5-B5 -> 408 | D45: =D5-C5 -> 134 | E45: =E5-D5 -> 79 | F45: =F5-E5 -> 175 | G45: =G5-F5 -> 457 | H45: =H5-G5 -> 0 | I45: =I5-H5 -> 0 | J45: =J5-I5 -> 204 | ... AC45: =AC5-AB5 -> 518
A46: M02 | B46: 475 | C46: =C6-B6 -> 71 | D46: =D6-C6 -> 502 | E46: =E6-D6 -> 518 | F46: =F6-E6 -> 455 | G46: =G6-F6 -> 0 | H46: =H6-G6 -> 0 | I46: =I6-H6 -> 0 | J46: =J6-I6 -> 1 | ... AC46: =AC6-AB6 -> 633
A47: M03 | B47: 0 | C47: =C7-B7 -> 17 | D47: =D7-C7 -> 24 | E47: =E7-D7 -> 0 | F47: =F7-E7 -> 0 | G47: =G7-F7 -> 0 | H47: =H7-G7 -> 0 | I47: =I7-H7 -> 0 | J47: =J7-I7 -> 195 | ... AC47: =AC7-AB7 -> 43
A48: M04 | B48: 475 | C48: =C8-B8 -> 561 | D48: =D8-C8 -> 260 | E48: =E8-D8 -> 261 | F48: =F8-E8 -> 350 | G48: =G8-F8 -> 218 | H48: =H8-G8 -> 43 | I48: =I8-H8 -> 477 | J48: =J8-I8 -> 475 | ... AC48: =AC8-AB8 -> 474
A49: M05 | B49: 0 | C49: =C9-B9 -> 93 | D49: =D9-C9 -> 334 | E49: =E9-D9 -> 384 | F49: =F9-E9 -> 132 | G49: =G9-F9 -> 407 | H49: =H9-G9 -> 0 | I49: =I9-H9 -> 0 | J49: =J9-I9 -> 4 | ... AC49: =AC9-AB9 -> 0
A50: M06 | B50: 518 | C50: =C10-B10 -> 605 | D50: =D10-C10 -> 350 | E50: =E10-D10 -> 190 | F50: =F10-E10 -> 266 | G50: =G10-F10 -> 434 | H50: =H10-G10 -> 0 | I50: =I10-H10 -> 2 | J50: =J10-I10 -> 368 | ... AC50: =AC10-AB10 -> 0
A51: M07 | B51: 0 | C51: =C11-B11 -> 428 | D51: =D11-C11 -> 603 | E51: =E11-D11 -> 320 | F51: =F11-E11 -> 99 | G51: =G11-F11 -> 0 | H51: =H11-G11 -> 0 | I51: =I11-H11 -> 0 | J51: =J11-I11 -> 73 | ... AC51: =AC11-AB11 -> 631
A52: M08 | B52: 520 | C52: =C12-B12 -> 353 | D52: =D12-C12 -> 271 | E52: =E12-D12 -> 402 | F52: =F12-E12 -> 280 | G52: =G12-F12 -> 0 | H52: =H12-G12 -> 0 | I52: =I12-H12 -> 0 | J52: =J12-I12 -> 191 | ... AC52: =AC12-AB12 -> 519
A53: M09 | B53: 0 | C53: =C13-B13 -> 201 | D53: =D13-C13 -> 179 | E53: =E13-D13 -> 22 | F53: =F13-E13 -> 339 | G53: =G13-F13 -> 251 | H53: =H13-G13 -> 148 | I53: =I13-H13 -> 43 | J53: =J13-I13 -> 563 | ... AC53: =AC13-AB13 -> 517
A54: M10 | B54: 0 | C54: =C14-B14 -> 251 | D54: =D14-C14 -> 2 | E54: =E14-D14 -> 586 | F54: =F14-E14 -> 261 | G54: =G14-F14 -> 261 | H54: =H14-G14 -> 450 | I54: =I14-H14 -> 0 | J54: =J14-I14 -> 330 | ... AC54: =AC14-AB14 -> 0
A55: M11 | B55: 44 | C55: =C15-B15 -> 366 | D55: =D15-C15 -> 257 | E55: =E15-D15 -> 99 | F55: =F15-E15 -> 133 | G55: =G15-F15 -> 259 | H55: =H15-G15 -> 521 | I55: =I15-H15 -> 475 | J55: =J15-I15 -> 389 | ... AC55: =AC15-AB15 -> 591
A56: M12 | B56: 0 | C56: =C16-B16 -> 221 | D56: =D16-C16 -> 408 | E56: =E16-D16 -> 133 | F56: =F16-E16 -> 586 | G56: =G16-F16 -> 517 | H56: =H16-G16 -> 560 | I56: =I16-H16 -> 44 | J56: =J16-I16 -> 110 | ... AC56: =AC16-AB16 -> 433
... A79: XM35 | B79: 0 | C79: =C39-B39 -> 109 | D79: =D39-C39 -> 0 | E79: =E39-D39 -> 0 | F79: =F39-E39 -> 0 | G79: =G39-F39 -> 0 | H79: =H39-G39 -> 0 | I79: =I39-H39 -> 0 | J79: =J39-I39 -> 38 | ... AC79: =AC39-AB39 -> 0
A81: Kilometraje Diario | B81: =SUM(B45:B79) -> 4986 | C81: =SUM(C45:C79) -> 9799 | D81: =SUM(D45:D79) -> 9348 | E81: =SUM(E45:E79) -> 9354 | F81: =SUM(F45:F79) -> 9275 | G81: =SUM(G45:G79) -> 9261 | H81: =SUM(H45:H79) -> 6567 | I81: =SUM(I45:I79) -> 4940 | ... AC81: =SUM(AC45:AC79) -> 6803

Sheet KM-Servicio
E1: SA-QU/QU-SA | F1: 7.68 | H1: SA-MI | I1: 21.7 | J1: EB-PU | K1: 25.4 | L1: PU-SA | M1: 29.11 | N1: QU-LI / LI-QU | O1: 21.7 | P1: VM-PU | Q1: 8.3 | R1: VM-LI | S1: 34.83 | T1: LI-PO | U1: 39.19 | W1: PU-ES/ES-PU | X1: 11.71 | Y1: PU-RE | Z1: 6 | AA1: PU-BA | AB1: 2.2 | AC1: SA-VM | AD1: 20.81 | AE1: PU-QU | AF1: 21.43
B2: CANTIDAD DE SERVICIOS | D2: CANTIDAD DE SERVICIOS | F2: EB-LI | G2: =M2-K1 -> 17.73 | H2: PU-PE | I2: 30.4 | J2: PO-SA | K2: 25.4 | L2: PU-LI | M2: 43.13 | N2: MI-LI / LI-MI | O2: 35.73 | P2: HO-LI/LI-HO | Q2: 33.97 | R2: PU-MI | S2: 7.4 | T2: LI-PE | U2: 12.72 | W2: MI-SA | X2: 21.7 | Y2: PU-PO | Z2: 3.9 | AA2: AM-QU | AB2: =(26.4-21.43) -> 4.97 | AC2: PU-CH | AD2: 10.55
B3: PROGRAMADOS | D3: REALIZADOS | F3: Origen-Destino | G3: Total Trenes | H3: Total Trenes P | I3: Total Servicios | J3: Kms.xTrenes | K3: Kmsxservicios. | L3: Asientos x Kms. | M3: Disp x Km. | N3: Total Odómetro | O3: % Uso Trenes | Q3: Cortes | T3: Acoples | W3: KmTren R | X3: KmTren P
B4: Simples | C4: Dobles | D4: Simples | E4: Dobles | Q4: EB | R4: SA | S4: PE | T4: EB | U4: SA | V4: PE
A5: 46054 | B5: 51 | C5: 3 | D5: ='Data Ocupacion'!D33 -> 51 | E5: ='Data Ocupacion'!E33 -> 3 | F5: PU-LI | G5: =D5+E5*2 -> 57 | H5: =B5+C5*2 -> 57 | I5: =D5+E5 -> 54 | J5: =G5*M$2 -> 2458.41 | K5: =I5*M$2 -> 2329.02 | L5: =J5*104 -> 255674.64 | M5: =I5*104 -> 5616 | W5: =J5-(Q5*($M$2-$K$1))-(R5*($M$2-$M$1))- (S5*($M$2-$I$2))+ (T5*($G$2)) -> 2458.41 | X5: =H5*$M$2 -> 2458.41
B6: 57 | C6: 0 | D6: ='Data Ocupacion'!D34 -> 57 | E6: ='Data Ocupacion'!E34 -> 0 | F6: LI-PU | G6: =D6+E6*2 -> 57 | H6: =B6+C6*2 -> 57 | I6: =D6+E6 -> 57 | J6: =G6*M$2 -> 2458.41 | K6: =I6*M$2 -> 2458.41 | L6: =J6*104 -> 255674.64 | M6: =I6*104 -> 5928 | W6: =J6-(T6*($M$2-$K$1)+(U6*($M$2-$M$1))) -> 2458.41 | X6: =H6*$M$2 -> 2458.41
B7: 0 | C7: 0 | D7: ='Data Ocupacion'!D35 -> 0 | E7: ='Data Ocupacion'!E35 -> 0 | F7: PU-SA | G7: =D7+E7*2 -> 0 | H7: =B7+C7*2 -> 0 | I7: =D7+E7 -> 0 | J7: =G7*M$1 -> 0 | K7: =I7*M$1 -> 0 | L7: =J7*104 -> 0 | M7: =I7*104 -> 0 | W7: =J7-(Q7*($M$1-$K$1)) -> 0 | X7: =H7*$M$1 -> 0
B8: 0 | C8: 0 | D8: ='Data Ocupacion'!D36 -> 0 | E8: ='Data Ocupacion'!E36 -> 0 | F8: SA-PU | G8: =D8+E8*2 -> 0 | H8: =B8+C8*2 -> 0 | I8: =D8+E8 -> 0 | J8: =G8*M$1 -> 0 | K8: =I8*M$1 -> 0 | L8: =J8*104 -> 0 | M8: =I8*104 -> 0 | W8: =J8 -> 0 | X8: =H8*$M$1 -> 0
B9: 0 | C9: 0 | D9: ='Data Ocupacion'!D37 -> 0 | E9: ='Data Ocupacion'!E37 -> 0 | F9: PU-EB | G9: =D9+E9*2 -> 0 | H9: =B9+C9*2 -> 0 | I9: =D9+E9 -> 0 | J9: =G9*K$1 -> 0 | K9: =I9*K$1 -> 0 | L9: =J9*104 -> 0 | M9: =I9*104 -> 0 | W9: =J9 -> 0 | X9: =H9*$K$1 -> 0
B10: 0 | C10: 0 | D10: ='Data Ocupacion'!D38 -> 0 | E10: ='Data Ocupacion'!E38 -> 0 | F10: EB-PU | G10: =D10+E10*2 -> 0 | H10: =B10+C10*2 -> 0 | I10: =D10+E10 -> 0 | J10: =G10*K$1 -> 0 | K10: =I10*K$1 -> 0 | L10: =J10*104 -> 0 | M10: =I10*104 -> 0 | W10: =J10 -> 0 | X10: =H10*$K$1 -> 0
B11: =SUM(B5:B10) -> 108 | C11: =SUM(C5:C10) -> 3 | D11: =SUM(D5:D10) -> 108 | E11: =SUM(E5:E10) -> 3 | G11: =SUM(G5:G10) -> 114 | H11: =SUM(H5:H10) -> 114 | I11: =SUM(I5:I10) -> 111 | J11: =SUM(J5:J10) -> 4916.82 | K11: =SUM(K5:K10) -> 4787.43 | L11: =SUM(L5:L10) -> 511349.28 | M11: =SUM(M5:M10) -> 11544 | N11: ='Odometro-Kilometraje'!B81 -> 4986 | O11: =(W11/N11)*100 -> 98.612515 | W11: =SUM(W5:W10) -> 4916.82 | X11: =SUM(X5:X10) -> 4916.82 | Z11: =J11-W11 -> 0
A12: =A5+1 -> 46055 | B12: 71 | C12: 8 | D12: 71 | E12: 8 | F12: PU-LI | G12: =D12+E12*2 -> 87 | H12: =B12+C12*2 -> 87 | I12: =D12+E12 -> 79 | J12: =G12*M$2 -> 3752.31 | K12: =I12*M$2 -> 3407.27 | L12: =J12*104 -> 390240.24 | M12: =I12*104 -> 8216 | Q12: 5 | W12: =J12-(Q12*($M$2-$K$1))-(R12*($M$2-$M$1))- (S12*($M$2-$I$2))+ (T12*($G$2)) -> 3663.66 | X12: =H12*$M$2 -> 3752.31
A13: Planilla 025 Laboral ver 14 transición a ver 15 | B13: 70 | C13: 8 | D13: 70 | E13: 8 | F13: LI-PU | G13: =D13+E13*2 -> 86 | H13: =B13+C13*2 -> 86 | I13: =D13+E13 -> 78 | J13: =G13*M$2 -> 3709.18 | K13: =I13*M$2 -> 3364.14 | L13: =J13*104 -> 385754.72 | M13: =I13*104 -> 8112 | W13: =J13-(T13*($M$2-$K$1)+(U13*($M$2-$M$1))) -> 3709.18 | X13: =H13*$M$2 -> 3709.18
B14: 33 | C14: 0 | D14: 31 | E14: 0 | F14: PU-SA | G14: =D14+E14*2 -> 31 | H14: =B14+C14*2 -> 33 | I14: =D14+E14 -> 31 | J14: =G14*M$1 -> 902.41 | K14: =I14*M$1 -> 902.41 | L14: =J14*104 -> 93850.64 | M14: =I14*104 -> 3224 | W14: =J14-(Q14*($M$1-$K$1)) -> 902.41 | X14: =H14*$M$1 -> 960.63
B15: 32 | C15: 0 | D15: 32 | E15: 0 | F15: SA-PU | G15: =D15+E15*2 -> 32 | H15: =B15+C15*2 -> 32 | I15: =D15+E15 -> 32 | J15: =G15*M$1 -> 931.52 | K15: =I15*M$1 -> 931.52 | L15: =J15*104 -> 96878.08 | M15: =I15*104 -> 3328 | W15: =J15 -> 931.52 | X15: =H15*$M$1 -> 931.52
B16: 0 | C16: 0 | D16: 2 | E16: 0 | F16: PU-EB | G16: =D16+E16*2 -> 2 | H16: =B16+C16*2 -> 0 | I16: =D16+E16 -> 2 | J16: =G16*K$1 -> 50.8 | K16: =I16*K$1 -> 50.8 | L16: =J16*104 -> 5283.2 | M16: =I16*104 -> 208 | W16: =J16 -> 50.8 | X16: =H16*$K$1 -> 0
B17: 1 | C17: 0 | D17: 1 | E17: 0 | F17: EB-PU | G17: =D17+E17*2 -> 1 | H17: =B17+C17*2 -> 1 | I17: =D17+E17 -> 1 | J17: =G17*K$1 -> 25.4 | K17: =I17*K$1 -> 25.4 | L17: =J17*104 -> 2641.6 | M17: =I17*104 -> 104 | W17: =J17 -> 25.4 | X17: =H17*$K$1 -> 25.4
B18: =SUM(B12:B17) -> 207 | C18: =SUM(C12:C17) -> 16 | D18: =SUM(D12:D17) -> 207 | E18: =SUM(E12:E17) -> 16 | G18: =SUM(G12:G17) -> 239 | H18: =SUM(H12:H17) -> 239 | I18: =SUM(I12:I17) -> 223 | J18: =SUM(J12:J17) -> 9371.62 | K18: =SUM(K12:K17) -> 8681.54 | L18: =SUM(L12:L17) -> 974648.48 | M18: =SUM(M12:M17) -> 23192 | N18: ='Odometro-Kilometraje'!C81 -> 9799 | O18: =(W18/N18)*100 -> 94.73385 | W18: =SUM(W12:W17) -> 9282.97 | X18: =SUM(X12:X17) -> 9379.04 | Z18: =J18-W18 -> 88.65
A19: =A12+1 -> 46056 | B19: 78 | C19: 1 | D19: ='Data Ocupacion'!H33 -> 78 | E19: ='Data Ocupacion'!I33 -> 1 | F19: PU-LI | G19: =D19+E19*2 -> 80 | H19: =B19+C19*2 -> 80 | I19: =D19+E19 -> 79 | J19: =G19*M$2 -> 3450.4 | K19: =I19*M$2 -> 3407.27 | L19: =J19*104 -> 358841.6 | M19: =I19*104 -> 8216 | W19: =J19-(Q19*($M$2-$K$1))-(R19*($M$2-$M$1))- (S19*($M$2-$I$2))+ (T19*($G$2)) -> 3450.4 | X19: =H19*$M$2 -> 3450.4
A20: Planilla 025 Laboral ver 15 | B20: 76 | C20: 2 | D20: ='Data Ocupacion'!H34 -> 76 | E20: ='Data Ocupacion'!I34 -> 2 | F20: LI-PU | G20: =D20+E20*2 -> 80 | H20: =B20+C20*2 -> 80 | I20: =D20+E20 -> 78 | J20: =G20*M$2 -> 3450.4 | K20: =I20*M$2 -> 3364.14 | L20: =J20*104 -> 358841.6 | M20: =I20*104 -> 8112 | W20: =J20-(T20*($M$2-$K$1)+(U20*($M$2-$M$1))) -> 3450.4 | X20: =H20*$M$2 -> 3450.4
B21: 33 | C21: 0 | D21: ='Data Ocupacion'!H35 -> 33 | E21: ='Data Ocupacion'!I35 -> 0 | F21: PU-SA | G21: =D21+E21*2 -> 33 | H21: =B21+C21*2 -> 33 | I21: =D21+E21 -> 33 | J21: =G21*M$1 -> 960.63 | K21: =I21*M$1 -> 960.63 | L21: =J21*104 -> 99905.52 | M21: =I21*104 -> 3432 | W21: =J21-(Q21*($M$1-$K$1)) -> 960.63 | X21: =H21*$M$1 -> 960.63
B22: 32 | C22: 0 | D22: ='Data Ocupacion'!H36 -> 32 | E22: ='Data Ocupacion'!I36 -> 0 | F22: SA-PU | G22: =D22+E22*2 -> 32 | H22: =B22+C22*2 -> 32 | I22: =D22+E22 -> 32 | J22: =G22*M$1 -> 931.52 | K22: =I22*M$1 -> 931.52 | L22: =J22*104 -> 96878.08 | M22: =I22*104 -> 3328 | W22: =J22 -> 931.52 | X22: =H22*$M$1 -> 931.52
B23: 0 | C23: 0 | D23: ='Data Ocupacion'!H37 -> 0 | E23: ='Data Ocupacion'!I37 -> 0 | F23: PU-EB | G23: =D23+E23*2 -> 0 | H23: =B23+C23*2 -> 0 | I23: =D23+E23 -> 0 | J23: =G23*K$1 -> 0 | K23: =I23*K$1 -> 0 | L23: =J23*104 -> 0 | M23: =I23*104 -> 0 | W23: =J23 -> 0 | X23: =H23*$K$1 -> 0
B24: 1 | C24: 0 | D24: ='Data Ocupacion'!H38 -> 1 | E24: ='Data Ocupacion'!I38 -> 0 | F24: EB-PU | G24: =D24+E24*2 -> 1 | H24: =B24+C24*2 -> 1 | I24: =D24+E24 -> 1 | J24: =G24*K$1 -> 25.4 | K24: =I24*K$1 -> 25.4 | L24: =J24*104 -> 2641.6 | M24: =I24*104 -> 104 | W24: =J24 -> 25.4 | X24: =H24*$K$1 -> 25.4
B25: =SUM(B19:B24) -> 220 | C25: =SUM(C19:C24) -> 3 | D25: =SUM(D19:D24) -> 220 | E25: =SUM(E19:E24) -> 3 | G25: =SUM(G19:G24) -> 226 | H25: =SUM(H19:H24) -> 226 | I25: =SUM(I19:I24) -> 223 | J25: =SUM(J19:J24) -> 8818.35 | K25: =SUM(K19:K24) -> 8688.96 | L25: =SUM(L19:L24) -> 917108.4 | M25: =SUM(M19:M24) -> 23192 | N25: ='Odometro-Kilometraje'!D81 -> 9348 | O25: =(W25/N25)*100 -> 94.334082 | W25: =SUM(W19:W24) -> 8818.35 | X25: =SUM(X19:X24) -> 8818.35 | Z25: =J25-W25 -> 0
A26: =A19+1 -> 46057 | B26: 78 | C26: 1 | D26: ='Data Ocupacion'!J33 -> 76 | E26: ='Data Ocupacion'!K33 -> 3 | F26: PU-LI | G26: =D26+E26*2 -> 82 | H26: =B26+C26*2 -> 80 | I26: =D26+E26 -> 79 | J26: =G26*M$2 -> 3536.66 | K26: =I26*M$2 -> 3407.27 | L26: =J26*104 -> 367812.64 | M26: =I26*104 -> 8216 | W26: =J26-(Q26*($M$2-$K$1))-(R26*($M$2-$M$1))- (S26*($M$2-$I$2))+ (T26*($G$2)) -> 3536.66 | X26: =H26*$M$2 -> 3450.4
A27: 6 Servicio suprimidos por averias MR | B27: 76 | C27: 2 | D27: ='Data Ocupacion'!J34 -> 75 | E27: ='Data Ocupacion'!K34 -> 3 | F27: LI-PU | G27: =D27+E27*2 -> 81 | H27: =B27+C27*2 -> 80 | I27: =D27+E27 -> 78 | J27: =G27*M$2 -> 3493.53 | K27: =I27*M$2 -> 3364.14 | L27: =J27*104 -> 363327.12 | M27: =I27*104 -> 8112 | W27: =J27-(T27*($M$2-$K$1)+(U27*($M$2-$M$1))+(V27*($M$2-$I$2))) -> 3493.53 | X27: =H27*$M$2 -> 3450.4
B28: 33 | C28: 0 | D28: ='Data Ocupacion'!J35 -> 30 | E28: ='Data Ocupacion'!K35 -> 0 | F28: PU-SA | G28: =D28+E28*2 -> 30 | H28: =B28+C28*2 -> 33 | I28: =D28+E28 -> 30 | J28: =G28*M$1 -> 873.3 | K28: =I28*M$1 -> 873.3 | L28: =J28*104 -> 90823.2 | M28: =I28*104 -> 3120 | W28: =J28-(Q28*($M$1-$K$1)) -> 873.3 | X28: =H28*$M$1 -> 960.63
B29: 32 | C29: 0 | D29: ='Data Ocupacion'!J36 -> 28 | E29: ='Data Ocupacion'!K36 -> 1 | F29: SA-PU | G29: =D29+E29*2 -> 30 | H29: =B29+C29*2 -> 32 | I29: =D29+E29 -> 29 | J29: =G29*M$1 -> 873.3 | K29: =I29*M$1 -> 844.19 | L29: =J29*104 -> 90823.2 | M29: =I29*104 -> 3016 | W29: =J29 -> 873.3 | X29: =H29*$M$1 -> 931.52
B30: 0 | C30: 0 | D30: ='Data Ocupacion'!J37 -> 0 | E30: ='Data Ocupacion'!K37 -> 0 | F30: PU-EB | G30: =D30+E30*2 -> 0 | H30: =B30+C30*2 -> 0 | I30: =D30+E30 -> 0 | J30: =G30*K$1 -> 0 | K30: =I30*K$1 -> 0 | L30: =J30*104 -> 0 | M30: =I30*104 -> 0 | W30: =J30 -> 0 | X30: =H30*$K$1 -> 0
B31: 1 | C31: 0 | D31: ='Data Ocupacion'!J38 -> 1 | E31: ='Data Ocupacion'!K38 -> 0 | F31: EB-PU | G31: =D31+E31*2 -> 1 | H31: =B31+C31*2 -> 1 | I31: =D31+E31 -> 1 | J31: =G31*K$1 -> 25.4 | K31: =I31*K$1 -> 25.4 | L31: =J31*104 -> 2641.6 | M31: =I31*104 -> 104 | W31: =J31 -> 25.4 | X31: =H31*$K$1 -> 25.4
B32: =SUM(B26:B31) -> 220 | C32: =SUM(C26:C31) -> 3 | D32: =SUM(D26:D31) -> 210 | E32: =SUM(E26:E31) -> 7 | G32: =SUM(G26:G31) -> 224 | H32: =SUM(H26:H31) -> 226 | I32: =SUM(I26:I31) -> 217 | J32: =SUM(J26:J31) -> 8802.19 | K32: =SUM(K26:K31) -> 8514.3 | L32: =SUM(L26:L31) -> 915427.76 | M32: =SUM(M26:M31) -> 22568 | N32: ='Odometro-Kilometraje'!E81 -> 9354 | O32: =(W32/N32)*100 -> 94.100812 | W32: =SUM(W26:W31) -> 8802.19 | X32: =SUM(X26:X31) -> 8818.35 | Z32: =J32-W32 -> 0
A33: =A26+1 -> 46058 | B33: 78 | C33: 1 | D33: ='Data Ocupacion'!L33 -> 77 | E33: ='Data Ocupacion'!M33 -> 2 | F33: PU-LI | G33: =D33+E33*2 -> 81 | H33: =B33+C33*2 -> 80 | I33: =D33+E33 -> 79 | J33: =G33*M$2 -> 3493.53 | K33: =I33*M$2 -> 3407.27 | L33: =J33*104 -> 363327.12 | M33: =I33*104 -> 8216 | W33: =J33-(Q33*($M$2-$K$1))-(R33*($M$2-$M$1))- (S33*($M$2-$I$2))+ (T33*($G$2)) -> 3493.53 | X33: =H33*$M$2 -> 3450.4
B34: 76 | C34: 2 | D34: ='Data Ocupacion'!L34 -> 76 | E34: ='Data Ocupacion'!M34 -> 2 | F34: LI-PU | G34: =D34+E34*2 -> 80 | H34: =B34+C34*2 -> 80 | I34: =D34+E34 -> 78 | J34: =G34*M$2 -> 3450.4 | K34: =I34*M$2 -> 3364.14 | L34: =J34*104 -> 358841.6 | M34: =I34*104 -> 8112 | T34: 1 | W34: =J34-(T34*($M$2-$K$1)+(U34*($M$2-$M$1))+(V34*($M$2-$I$2))) -> 3432.67 | X34: =H34*$M$2 -> 3450.4
B35: 33 | C35: 0 | D35: ='Data Ocupacion'!L35 -> 33 | E35: ='Data Ocupacion'!M35 -> 0 | F35: PU-SA | G35: =D35+E35*2 -> 33 | H35: =B35+C35*2 -> 33 | I35: =D35+E35 -> 33 | J35: =G35*M$1 -> 960.63 | K35: =I35*M$1 -> 960.63 | L35: =J35*104 -> 99905.52 | M35: =I35*104 -> 3432 | W35: =J35-(Q35*($M$1-$K$1)) -> 960.63 | X35: =H35*$M$1 -> 960.63
B36: 32 | C36: 0 | D36: ='Data Ocupacion'!L36 -> 32 | E36: ='Data Ocupacion'!M36 -> 0 | F36: SA-PU | G36: =D36+E36*2 -> 32 | H36: =B36+C36*2 -> 32 | I36: =D36+E36 -> 32 | J36: =G36*M$1 -> 931.52 | K36: =I36*M$1 -> 931.52 | L36: =J36*104 -> 96878.08 | M36: =I36*104 -> 3328 | W36: =J36 -> 931.52 | X36: =H36*$M$1 -> 931.52
B37: 0 | C37: 0 | D37: ='Data Ocupacion'!L37 -> 0 | E37: ='Data Ocupacion'!M37 -> 0 | F37: PU-EB | G37: =D37+E37*2 -> 0 | H37: =B37+C37*2 -> 0 | I37: =D37+E37 -> 0 | J37: =G37*K$1 -> 0 | K37: =I37*K$1 -> 0 | L37: =J37*104 -> 0 | M37: =I37*104 -> 0 | W37: =J37 -> 0 | X37: =H37*$K$1 -> 0
B38: 1 | C38: 0 | D38: ='Data Ocupacion'!L38 -> 1 | E38: ='Data Ocupacion'!M38 -> 0 | F38: EB-PU | G38: =D38+E38*2 -> 1 | H38: =B38+C38*2 -> 1 | I38: =D38+E38 -> 1 | J38: =G38*K$1 -> 25.4 | K38: =I38*K$1 -> 25.4 | L38: =J38*104 -> 2641.6 | M38: =I38*104 -> 104 | W38: =J38 -> 25.4 | X38: =H38*$K$1 -> 25.4
B39: =SUM(B33:B38) -> 220 | C39: =SUM(C33:C38) -> 3 | D39: =SUM(D33:D38) -> 219 | E39: =SUM(E33:E38) -> 4 | G39: =SUM(G33:G38) -> 227 | H39: =SUM(H33:H38) -> 226 | I39: =SUM(I33:I38) -> 223 | J39: =SUM(J33:J38) -> 8861.48 | K39: =SUM(K33:K38) -> 8688.96 | L39: =SUM(L33:L38) -> 921593.92 | M39: =SUM(M33:M38) -> 23192 | N39: ='Odometro-Kilometraje'!F81 -> 9275 | O39: =(W39/N39)*100 -> 95.350404 | W39: =SUM(W33:W38) -> 8843.75 | X39: =SUM(X33:X38) -> 8818.35 | Z39: =J39-W39 -> 17.73
A40: =A33+1 -> 46059 | B40: 78 | C40: 1 | D40: ='Data Ocupacion'!N33 -> 77 | E40: ='Data Ocupacion'!O33 -> 2 | F40: PU-LI | G40: =D40+E40*2 -> 81 | H40: =B40+C40*2 -> 80 | I40: =D40+E40 -> 79 | J40: =G40*M$2 -> 3493.53 | K40: =I40*M$2 -> 3407.27 | L40: =J40*104 -> 363327.12 | M40: =I40*104 -> 8216 | W40: =J40-(Q40*($M$2-$K$1))-(R40*($M$2-$M$1))- (S40*($M$2-$I$2))+ (T40*($G$2)) -> 3493.53 | X40: =H40*$M$2 -> 3450.4
...

Sheet Data Ocupacion
D1: 46054 | F1: 46055 | H1: 46056 | J1: 46057 | L1: 46058 | N1: 46059 | P1: 46060 | R1: 46061 | T1: 46062 | V1: 46063 | X1: 46064 | Z1: 46065 | AB1: 46066 | AD1: 46067 | AF1: 46068 | AH1: 46069 | AJ1: 46070 | AL1: 46071 | AN1: 46072 | AP1: 46073 | AR1: 46074 | AT1: 46075 | AV1: 46076 | AX1: 46077 | AZ1: 46078 | BB1: 46079 | BD1: 46080 | BF1: 46081
D2: S | E2: M | F2: S | G2: M | H2: S | I2: M | J2: S | K2: M | L2: S | M2: M | N2: S | O2: M | P2: S | Q2: M | R2: S | S2: M | T2: S | U2: M | V2: S | W2: M | X2: S | Y2: M | Z2: S | AA2: M | AB2: S | AC2: M | AD2: S | AE2: M | AF2: S | AG2: M | AH2: S | AI2: M | AJ2: S | AK2: M | AL2: S | AM2: M | AN2: S | AO2: M | AP2: S | AQ2: M | AR2: S | AS2: M | AT2: S | AU2: M | AV2: S | AW2: M | AX2: S | AY2: M | AZ2: S | BA2: M | BB2: S | BC2: M | BD2: S | BE2: M | BF2: S | BG2: M
A3: Servicios PU-SA | D3: 0 | E3: 0 | F3: 10 | G3: 0 | H3: 10 | I3: 0 | J3: 9 | K3: 0 | L3: 10 | M3: 0 | N3: 10 | O3: 0 | P3: 0 | Q3: 0 | R3: 0 | S3: 0 | T3: 10 | U3: 0 | V3: 10 | W3: 0 | X3: 10 | Y3: 0 | Z3: 10 | AA3: 0 | AB3: 10 | AC3: 0 | AD3: 0 | AE3: 0 | AF3: 0 | AG3: 0 | AH3: 10 | AI3: 0 | AJ3: 10 | AK3: 0 | AL3: 10 | AM3: 0 | AN3: 10 | AO3: 0 | AP3: 10 | AQ3: 0 | AR3: 0 | AS3: 0 | AT3: 0 | AU3: 0 | AV3: 10 | AW3: 0 | AX3: 10 | AY3: 0 | AZ3: 10 | BA3: 0 | BB3: 10 | BC3: 0 | BD3: 10 | BE3: 0 | BF3: 0 | BG3: 0
A4: Servicios PU-EB | D4: 0 | E4: 0 | F4: 0 | G4: 0 | H4: 0 | I4: 0 | J4: 0 | K4: 0 | L4: 0 | M4: 0 | N4: 0 | O4: 0 | P4: 0 | Q4: 0 | R4: 0 | S4: 0 | T4: 0 | U4: 0 | V4: 0 | W4: 0 | X4: 0 | Y4: 0 | Z4: 0 | AA4: 0 | AB4: 0 | AC4: 0 | AD4: 0 | AE4: 0 | AF4: 0 | AG4: 0 | AH4: 0 | AI4: 0 | AJ4: 0 | AK4: 0 | AL4: 0 | AM4: 0 | AN4: 0 | AO4: 0 | AP4: 0 | AQ4: 0 | AR4: 0 | AS4: 0 | AT4: 0 | AU4: 0 | AV4: 0 | AW4: 0 | AX4: 0 | AY4: 0 | AZ4: 0 | BA4: 0 | BB4: 0 | BC4: 0 | BD4: 0 | BE4: 0 | BF4: 0 | BG4: 0
A5: Servicios PU-LI | D5: 0 | E5: 0 | F5: 4 | G5: 6 | H5: 10 | I5: 0 | J5: 10 | K5: 0 | L5: 10 | M5: 0 | N5: 10 | O5: 0 | P5: 0 | Q5: 0 | R5: 0 | S5: 0 | T5: 10 | U5: 0 | V5: 10 | W5: 0 | X5: 10 | Y5: 0 | Z5: 10 | AA5: 0 | AB5: 10 | AC5: 0 | AD5: 0 | AE5: 0 | AF5: 0 | AG5: 0 | AH5: 10 | AI5: 0 | AJ5: 10 | AK5: 0 | AL5: 3 | AM5: 7 | AN5: 10 | AO5: 0 | AP5: 10 | AQ5: 0 | AR5: 0 | AS5: 0 | AT5: 0 | AU5: 0 | AV5: 10 | AW5: 0 | AX5: 10 | AY5: 0 | AZ5: 10 | BA5: 0 | BB5: 10 | BC5: 0 | BD5: 10 | BE5: 0 | BF5: 0 | BG5: 0
A6: Servicios SA-PU | D6: 0 | E6: 0 | F6: 10 | G6: 0 | H6: 10 | I6: 0 | J6: 8 | K6: 1 | L6: 10 | M6: 0 | N6: 10 | O6: 0 | P6: 0 | Q6: 0 | R6: 0 | S6: 0 | T6: 10 | U6: 0 | V6: 10 | W6: 0 | X6: 10 | Y6: 0 | Z6: 10 | AA6: 0 | AB6: 10 | AC6: 0 | AD6: 0 | AE6: 0 | AF6: 0 | AG6: 0 | AH6: 10 | AI6: 0 | AJ6: 10 | AK6: 0 | AL6: 10 | AM6: 0 | AN6: 10 | AO6: 0 | AP6: 10 | AQ6: 0 | AR6: 0 | AS6: 0 | AT6: 0 | AU6: 0 | AV6: 10 | AW6: 0 | AX6: 10 | AY6: 0 | AZ6: 10 | BA6: 0 | BB6: 10 | BC6: 0 | BD6: 10 | BE6: 0 | BF6: 0 | BG6: 0
A7: Servicios EB-PU | D7: 0 | E7: 0 | F7: 0 | G7: 0 | H7: 0 | I7: 0 | J7: 0 | K7: 0 | L7: 0 | M7: 0 | N7: 0 | O7: 0 | P7: 0 | Q7: 0 | R7: 0 | S7: 0 | T7: 0 | U7: 0 | V7: 0 | W7: 0 | X7: 0 | Y7: 0 | Z7: 0 | AA7: 0 | AB7: 0 | AC7: 0 | AD7: 0 | AE7: 0 | AF7: 0 | AG7: 0 | AH7: 0 | AI7: 0 | AJ7: 0 | AK7: 0 | AL7: 0 | AM7: 0 | AN7: 0 | AO7: 0 | AP7: 0 | AQ7: 0 | AR7: 0 | AS7: 0 | AT7: 0 | AU7: 0 | AV7: 0 | AW7: 0 | AX7: 0 | AY7: 0 | AZ7: 0 | BA7: 0 | BB7: 0 | BC7: 0 | BD7: 0 | BE7: 0 | BF7: 0 | BG7: 0
A8: Servicios LI-PU | D8: 0 | E8: 0 | F8: 7 | G8: 3 | H8: 10 | I8: 0 | J8: 10 | K8: 0 | L8: 10 | M8: 0 | N8: 10 | O8: 0 | P8: 0 | Q8: 0 | R8: 0 | S8: 0 | T8: 10 | U8: 0 | V8: 10 | W8: 0 | X8: 10 | Y8: 0 | Z8: 10 | AA8: 0 | AB8: 10 | AC8: 0 | AD8: 0 | AE8: 0 | AF8: 0 | AG8: 0 | AH8: 10 | AI8: 0 | AJ8: 10 | AK8: 0 | AL8: 2 | AM8: 8 | AN8: 10 | AO8: 0 | AP8: 10 | AQ8: 0 | AR8: 0 | AS8: 0 | AT8: 0 | AU8: 0 | AV8: 10 | AW8: 0 | AX8: 10 | AY8: 0 | AZ8: 10 | BA8: 0 | BB8: 10 | BC8: 0 | BD8: 10 | BE8: 0 | BF8: 0 | BG8: 0
A10: Servicios PU-SA | D10: 0 | E10: 0 | F10: 16 | G10: 0 | H10: 16 | I10: 0 | J10: 14 | K10: 0 | L10: 16 | M10: 0 | N10: 16 | O10: 0 | P10: 0 | Q10: 0 | R10: 0 | S10: 0 | T10: 16 | U10: 0 | V10: 16 | W10: 0 | X10: 16 | Y10: 0 | Z10: 15 | AA10: 0 | AB10: 16 | AC10: 0 | AD10: 0 | AE10: 0 | AF10: 0 | AG10: 0 | AH10: 16 | AI10: 0 | AJ10: 15 | AK10: 0 | AL10: 15 | AM10: 0 | AN10: 16 | AO10: 0 | AP10: 14 | AQ10: 0 | AR10: 0 | AS10: 0 | AT10: 0 | AU10: 0 | AV10: 16 | AW10: 0 | AX10: 16 | AY10: 0 | AZ10: 16 | BA10: 0 | BB10: 16 | BC10: 0 | BD10: 16 | BE10: 0 | BF10: 0 | BG10: 0
A11: Servicios PU-EB | D11: 0 | E11: 0 | F11: 0 | G11: 0 | H11: 0 | I11: 0 | J11: 0 | K11: 0 | L11: 0 | M11: 0 | N11: 0 | O11: 0 | P11: 0 | Q11: 0 | R11: 0 | S11: 0 | T11: 0 | U11: 0 | V11: 0 | W11: 0 | X11: 0 | Y11: 0 | Z11: 0 | AA11: 0 | AB11: 0 | AC11: 0 | AD11: 0 | AE11: 0 | AF11: 0 | AG11: 0 | AH11: 0 | AI11: 0 | AJ11: 0 | AK11: 0 | AL11: 0 | AM11: 0 | AN11: 0 | AO11: 0 | AP11: 0 | AQ11: 0 | AR11: 0 | AS11: 0 | AT11: 0 | AU11: 0 | AV11: 0 | AW11: 0 | AX11: 0 | AY11: 0 | AZ11: 0 | BA11: 0 | BB11: 0 | BC11: 0 | BD11: 0 | BE11: 0 | BF11: 0 | BG11: 0
A12: Servicios PU-LI | D12: 51 | E12: 3 | F12: 59 | G12: 2 | H12: 60 | I12: 1 | J12: 58 | K12: 3 | L12: 59 | M12: 2 | N12: 59 | O12: 2 | P12: 69 | Q12: 3 | R12: 51 | S12: 3 | T12: 60 | U12: 1 | V12: 60 | W12: 1 | X12: 60 | Y12: 1 | Z12: 61 | AA12: 1 | AB12: 59 | AC12: 2 | AD12: 69 | AE12: 3 | AF12: 46 | AG12: 8 | AH12: 60 | AI12: 1 | AJ12: 61 | AK12: 1 | AL12: 46 | AM12: 15 | AN12: 55 | AO12: 6 | AP12: 60 | AQ12: 1 | AR12: 69 | AS12: 3 | AT12: 42 | AU12: 12 | AV12: 60 | AW12: 1 | AX12: 60 | AY12: 1 | AZ12: 60 | BA12: 1 | BB12: 60 | BC12: 1 | BD12: 60 | BE12: 1 | BF12: 70 | BG12: 2
A13: Servicios SA-PU | D13: 0 | E13: 0 | F13: 16 | G13: 0 | H13: 16 | I13: 0 | J13: 14 | K13: 0 | L13: 16 | M13: 0 | N13: 16 | O13: 0 | P13: 0 | Q13: 0 | R13: 0 | S13: 0 | T13: 16 | U13: 0 | V13: 16 | W13: 0 | X13: 16 | Y13: 0 | Z13: 16 | AA13: 0 | AB13: 16 | AC13: 0 | AD13: 0 | AE13: 0 | AF13: 0 | AG13: 0 | AH13: 16 | AI13: 0 | AJ13: 16 | AK13: 0 | AL13: 16 | AM13: 0 | AN13: 16 | AO13: 0 | AP13: 16 | AQ13: 0 | AR13: 0 | AS13: 0 | AT13: 0 | AU13: 0 | AV13: 16 | AW13: 0 | AX13: 16 | AY13: 0 | AZ13: 16 | BA13: 0 | BB13: 16 | BC13: 0 | BD13: 16 | BE13: 0 | BF13: 0 | BG13: 0
A14: Servicios EB-PU | D14: 0 | E14: 0 | F14: 1 | G14: 0 | H14: 1 | I14: 0 | J14: 1 | K14: 0 | L14: 1 | M14: 0 | N14: 1 | O14: 0 | P14: 0 | Q14: 0 | R14: 0 | S14: 0 | T14: 1 | U14: 0 | V14: 1 | W14: 0 | X14: 1 | Y14: 0 | Z14: 1 | AA14: 0 | AB14: 1 | AC14: 0 | AD14: 0 | AE14: 0 | AF14: 0 | AG14: 0 | AH14: 1 | AI14: 0 | AJ14: 1 | AK14: 0 | AL14: 1 | AM14: 0 | AN14: 1 | AO14: 0 | AP14: 1 | AQ14: 0 | AR14: 0 | AS14: 0 | AT14: 0 | AU14: 0 | AV14: 1 | AW14: 0 | AX14: 1 | AY14: 0 | AZ14: 1 | BA14: 0 | BB14: 1 | BC14: 0 | BD14: 1 | BE14: 0 | BF14: 0 | BG14: 0
A15: Servicios LI-PU | D15: 57 | E15: 0 | F15: 56 | G15: 5 | H15: 59 | I15: 2 | J15: 58 | K15: 3 | L15: 59 | M15: 2 | N15: 58 | O15: 3 | P15: 75 | Q15: 0 | R15: 57 | S15: 0 | T15: 59 | U15: 2 | V15: 59 | W15: 2 | X15: 59 | Y15: 2 | Z15: 59 | AA15: 2 | AB15: 58 | AC15: 3 | AD15: 75 | AE15: 0 | AF15: 52 | AG15: 5 | AH15: 59 | AI15: 2 | AJ15: 59 | AK15: 2 | AL15: 41 | AM15: 20 | AN15: 48 | AO15: 13 | AP15: 59 | AQ15: 2 | AR15: 75 | AS15: 0 | AT15: 48 | AU15: 9 | AV15: 59 | AW15: 2 | AX15: 59 | AY15: 2 | AZ15: 59 | BA15: 2 | BB15: 59 | BC15: 2 | BD15: 59 | BE15: 2 | BF15: 75 | BG15: 0
A16: Servicios VM-LI | AV16: 3 | AW16: 1 | AX16: 3 | AY16: 1 | AZ16: 3 | BA16: 1 | BB16: 3 | BC16: 1 | BD16: 3 | BE16: 1 | BF16: 3 | BG16: 1
A17: Servicios VM-PU | AV17: 2 | AW17: 0 | AX17: 2 | AY17: 0 | AZ17: 2 | BA17: 0 | BB17: 2 | BC17: 0 | BD17: 2 | BE17: 0 | BF17: 2 | BG17: 0
A19: Servicios PU-SA | D19: 0 | E19: 0 | F19: 7 | G19: 0 | H19: 7 | I19: 0 | J19: 7 | K19: 0 | L19: 7 | M19: 0 | N19: 7 | O19: 0 | P19: 0 | Q19: 0 | R19: 0 | S19: 0 | T19: 7 | U19: 0 | V19: 7 | W19: 0 | X19: 7 | Y19: 0 | Z19: 7 | AA19: 0 | AB19: 7 | AC19: 0 | AD19: 0 | AE19: 0 | AF19: 0 | AG19: 0 | AH19: 7 | AI19: 0 | AJ19: 7 | AK19: 0 | AL19: 7 | AM19: 0 | AN19: 7 | AO19: 0 | AP19: 7 | AQ19: 0 | AR19: 0 | AS19: 0 | AT19: 0 | AU19: 0 | AV19: 7 | AW19: 0 | AX19: 7 | AY19: 0 | AZ19: 7 | BA19: 0 | BB19: 7 | BC19: 0 | BD19: 7 | BE19: 0 | BF19: 0 | BG19: 0
A20: Servicios PU-EB | D20: 0 | E20: 0 | F20: 0 | G20: 0 | H20: 0 | I20: 0 | J20: 0 | K20: 0 | L20: 0 | M20: 0 | N20: 0 | O20: 0 | P20: 0 | Q20: 0 | R20: 0 | S20: 0 | T20: 0 | U20: 0 | V20: 0 | W20: 0 | X20: 0 | Y20: 0 | Z20: 0 | AA20: 0 | AB20: 0 | AC20: 0 | AD20: 0 | AE20: 0 | AF20: 0 | AG20: 0 | AH20: 0 | AI20: 0 | AJ20: 0 | AK20: 0 | AL20: 0 | AM20: 0 | AN20: 0 | AO20: 0 | AP20: 0 | AQ20: 0 | AR20: 0 | AS20: 0 | AT20: 0 | AU20: 0 | AV20: 0 | AW20: 0 | AX20: 0 | AY20: 0 | AZ20: 0 | BA20: 0 | BB20: 0 | BC20: 0 | BD20: 0 | BE20: 0 | BF20: 0 | BG20: 0
A21: Servicios PU-LI | D21: 0 | E21: 0 | F21: 8 | G21: 0 | H21: 8 | I21: 0 | J21: 8 | K21: 0 | L21: 8 | M21: 0 | N21: 8 | O21: 0 | P21: 0 | Q21: 0 | R21: 0 | S21: 0 | T21: 8 | U21: 0 | V21: 8 | W21: 0 | X21: 8 | Y21: 0 | Z21: 8 | AA21: 0 | AB21: 8 | AC21: 0 | AD21: 0 | AE21: 0 | AF21: 0 | AG21: 0 | AH21: 8 | AI21: 0 | AJ21: 8 | AK21: 0 | AL21: 1 | AM21: 7 | AN21: 1 | AO21: 7 | AP21: 8 | AQ21: 0 | AR21: 0 | AS21: 0 | AT21: 0 | AU21: 0 | AV21: 6 | AW21: 2 | AX21: 6 | AY21: 2 | AZ21: 6 | BA21: 2 | BB21: 6 | BC21: 2 | BD21: 6 | BE21: 2 | BF21: 0 | BG21: 0
A22: Servicios SA-PU | D22: 0 | E22: 0 | F22: 6 | G22: 0 | H22: 6 | I22: 0 | J22: 6 | K22: 0 | L22: 6 | M22: 0 | N22: 6 | O22: 0 | P22: 0 | Q22: 0 | R22: 0 | S22: 0 | T22: 6 | U22: 0 | V22: 6 | W22: 0 | X22: 6 | Y22: 0 | Z22: 5 | AA22: 0 | AB22: 6 | AC22: 0 | AD22: 0 | AE22: 0 | AF22: 0 | AG22: 0 | AH22: 6 | AI22: 0 | AJ22: 6 | AK22: 0 | AL22: 6 | AM22: 0 | AN22: 6 | AO22: 0 | AP22: 5 | AQ22: 0 | AR22: 0 | AS22: 0 | AT22: 0 | AU22: 0 | AV22: 6 | AW22: 0 | AX22: 6 | AY22: 0 | AZ22: 6 | BA22: 0 | BB22: 6 | BC22: 0 | BD22: 6 | BE22: 0 | BF22: 0 | BG22: 0
A23: Servicios EB-PU | D23: 0 | E23: 0 | F23: 0 | G23: 0 | H23: 0 | I23: 0 | J23: 0 | K23: 0 | L23: 0 | M23: 0 | N23: 0 | O23: 0 | P23: 0 | Q23: 0 | R23: 0 | S23: 0 | T23: 0 | U23: 0 | V23: 0 | W23: 0 | X23: 0 | Y23: 0 | Z23: 1 | AA23: 0 | AB23: 0 | AC23: 0 | AD23: 0 | AE23: 0 | AF23: 0 | AG23: 0 | AH23: 0 | AI23: 0 | AJ23: 0 | AK23: 0 | AL23: 0 | AM23: 0 | AN23: 0 | AO23: 0 | AP23: 0 | AQ23: 0 | AR23: 0 | AS23: 0 | AT23: 0 | AU23: 0 | AV23: 0 | AW23: 0 | AX23: 0 | AY23: 0 | AZ23: 0 | BA23: 0 | BB23: 0 | BC23: 0 | BD23: 0 | BE23: 0 | BF23: 0 | BG23: 0
A24: Servicios LI-PU | D24: 0 | E24: 0 | F24: 7 | G24: 0 | H24: 7 | I24: 0 | J24: 7 | K24: 0 | L24: 7 | M24: 0 | N24: 7 | O24: 0 | P24: 0 | Q24: 0 | R24: 0 | S24: 0 | T24: 7 | U24: 0 | V24: 7 | W24: 0 | X24: 7 | Y24: 0 | Z24: 7 | AA24: 0 | AB24: 7 | AC24: 0 | AD24: 0 | AE24: 0 | AF24: 0 | AG24: 0 | AH24: 7 | AI24: 0 | AJ24: 7 | AK24: 0 | AL24: 6 | AM24: 1 | AN24: 6 | AO24: 1 | AP24: 7 | AQ24: 0 | AR24: 0 | AS24: 0 | AT24: 0 | AU24: 0 | AV24: 5 | AW24: 2 | AX24: 5 | AY24: 2 | AZ24: 5 | BA24: 2 | BB24: 5 | BC24: 2 | BD24: 5 | BE24: 2 | BF24: 0 | BG24: 0
D26: =SUM(D3:D24) -> 108 | E26: =SUM(E3:E24) -> 3 | F26: =SUM(F3:F24) -> 207 | G26: =SUM(G3:G24) -> 16 | H26: =SUM(H3:H24) -> 220 | I26: =SUM(I3:I24) -> 3 | J26: =SUM(J3:J24) -> 210 | K26: =SUM(K3:K24) -> 7 | ... BC26: =SUM(BC3:BC24) -> 8 | BD26: 221 | BE26: 8 | BF26: =SUM(BF3:BF24) -> 150 | BG26: =SUM(BG3:BG24) -> 3
A32: Km Servicio
A33: PU - LI | D33: =D5+D12+D21 -> 51 | E33: =E5+E12+E21 -> 3 | F33: =F5+F12+F21 -> 71 | G33: =G5+G12+G21 -> 8 | H33: =H5+H12+H21 -> 78 | I33: =I5+I12+I21 -> 1 | J33: =J5+J12+J21 -> 76 | K33: =K5+K12+K21 -> 3 | ... BG33: =BG5+BG12+BG21 -> 2
A34: LI - PU | D34: =D8+D15+D24 -> 57 | E34: =E8+E15+E24 -> 0 | F34: =F8+F15+F24 -> 70 | G34: =G8+G15+G24 -> 8 | H34: =H8+H15+H24 -> 76 | I34: =I8+I15+I24 -> 2 | J34: =J8+J15+J24 -> 75 | K34: =K8+K15+K24 -> 3 | ... BG34: =BG8+BG15+BG24 -> 0
A35: PU - SA | D35: =D3+D10+D19 -> 0 | E35: =E3+E10+E19 -> 0 | F35: =F3+F10+F19 -> 33 | G35: =G3+G10+G19 -> 0 | H35: =H3+H10+H19 -> 33 | I35: =I3+I10+I19 -> 0 | J35: =J3+J10+J19 -> 30 | K35: =K3+K10+K19 -> 0 | ... BG35: =BG3+BG10+BG19 -> 0
A36: SA - PU | D36: =D6+D13+D22 -> 0 | E36: =E6+E13+E22 -> 0 | F36: =F6+F13+F22 -> 32 | G36: =G6+G13+G22 -> 0 | H36: =H6+H13+H22 -> 32 | I36: =I6+I13+I22 -> 0 | J36: =J6+J13+J22 -> 28 | K36: =K6+K13+K22 -> 1 | ... BG36: =BG6+BG13+BG22 -> 0
A37: PU-EB | D37: =D4+D11+D20 -> 0 | E37: =E4+E11+E20 -> 0 | F37: =F4+F11+F20 -> 0 | G37: =G4+G11+G20 -> 0 | H37: =H4+H11+H20 -> 0 | I37: =I4+I11+I20 -> 0 | J37: =J4+J11+J20 -> 0 | K37: =K4+K11+K20 -> 0 | ... BG37: =BG4+BG11+BG20 -> 0
A38: EB-PU | D38: =D7+D14+D23 -> 0 | E38: =E7+E14+E23 -> 0 | F38: =F7+F14+F23 -> 1 | G38: =G7+G14+G23 -> 0 | H38: =H7+H14+H23 -> 1 | I38: =I7+I14+I23 -> 0 | J38: =J7+J14+J23 -> 1 | K38: =K7+K14+K23 -> 0 | ... BG38: =BG7+BG14+BG23 -> 0
A39: VM-LI | AV39: =AV16 -> 3 | AW39: =AW16 -> 1 | AX39: =AX16 -> 3 | AY39: =AY16 -> 1 | AZ39: =AZ16 -> 3 | BA39: =BA16 -> 1 | BB39: =BB16 -> 3 | BC39: =BC16 -> 1 | ... BG39: =BG16 -> 1
A40: VM-PU | AV40: =AV17 -> 2 | AW40: =AW17 -> 0 | AX40: =AX17 -> 2 | AY40: =AY17 -> 0 | AZ40: =AZ17 -> 2 | BA40: =BA17 -> 0 | BB40: =BB17 -> 2 | BC40: =BC17 -> 0 | ... BG40: =BG17 -> 0
A41: total | D41: =SUM(D33:D38) -> 108 | E41: =SUM(E33:E38) -> 3 | F41: =SUM(F33:F38) -> 207 | G41: =SUM(G33:G38) -> 16 | H41: =SUM(H33:H38) -> 220 | I41: =SUM(I33:I38) -> 3 | J41: =SUM(J33:J38) -> 210 | K41: =SUM(K33:K38) -> 7 | ... AU41: =SUM(AU33:AU38) -> 21 | AV41: =SUM(AV33:AV40) -> 221 | AW41: =SUM(AW33:AW40) -> 8 | AX41: =SUM(AX33:AX40) -> 221 | AY41: =SUM(AY33:AY40) -> 8 | AZ41: =SUM(AZ33:AZ40) -> 221 | BA41: =SUM(BA33:BA40) -> 8 | BB41: =SUM(BB33:BB40) -> 221 | BC41: =SUM(BC33:BC40) -> 8 | ... BG41: =SUM(BG33:BG40) -> 3
A43: Servicios
A44: PU - LI | D44: =D5+E5+D12+E12+D21+E21 -> 54 | F44: =F5+G5+F12+G12+F21+G21 -> 79 | H44: =H5+I5+H12+I12+H21+I21 -> 79 | J44: =J5+K5+J12+K12+J21+K21 -> 79 | L44: =L5+M5+L12+M12+L21+M21 -> 79 | N44: =N5+O5+N12+O12+N21+O21 -> 79 | P44: =P5+Q5+P12+Q12+P21+Q21 -> 72 | R44: =R5+S5+R12+S12+R21+S21 -> 54 | T44: =T5+U5+T12+U12+T21+U21 -> 79 | V44: =V5+W5+V12+W12+V21+W21 -> 79 | X44: =X5+Y5+X12+Y12+X21+Y21 -> 79 | Z44: =Z5+AA5+Z12+AA12+Z21+AA21 -> 80 | AB44: =AB5+AC5+AB12+AC12+AB21+AC21 -> 79 | AD44: =AD5+AE5+AD12+AE12+AD21+AE21 -> 72 | AF44: =AF5+AG5+AF12+AG12+AF21+AG21 -> 54 | AH44: =AH5+AI5+AH12+AI12+AH21+AI21 -> 79 | AJ44: =AJ5+AK5+AJ12+AK12+AJ21+AK21 -> 80 | AL44: =AL5+AM5+AL12+AM12+AL21+AM21 -> 79 | AN44: =AN5+AO5+AN12+AO12+AN21+AO21 -> 79 | AP44: =AP5+AQ5+AP12+AQ12+AP21+AQ21 -> 79 | AR44: =AR5+AS5+AR12+AS12+AR21+AS21 -> 72 | AT44: =AT5+AU5+AT12+AU12+AT21+AU21 -> 54 | AV44: =AV5+AW5+AV12+AW12+AV21+AW21 -> 79 | AX44: =AX5+AY5+AX12+AY12+AX21+AY21 -> 79 | AZ44: =AZ5+BA5+AZ12+BA12+AZ21+BA21 -> 79 | BB44: =BB5+BC5+BB12+BC12+BB21+BC21 -> 79 | BD44: =BD5+BE5+BD12+BE12+BD21+BE21 -> 79 | BF44: =BF5+BG5+BF12+BG12+BF21+BG21 -> 72
A45: LI - PU | D45: =D8+E8+D15+E15+D24+E24 -> 57 | F45: =F8+G8+F15+G15+F24+G24 -> 78 | H45: =H8+I8+H15+I15+H24+I24 -> 78 | J45: =J8+K8+J15+K15+J24+K24 -> 78 | L45: =L8+M8+L15+M15+L24+M24 -> 78 | N45: =N8+O8+N15+O15+N24+O24 -> 78 | P45: =P8+Q8+P15+Q15+P24+Q24 -> 75 | R45: =R8+S8+R15+S15+R24+S24 -> 57 | T45: =T8+U8+T15+U15+T24+U24 -> 78 | V45: =V8+W8+V15+W15+V24+W24 -> 78 | X45: =X8+Y8+X15+Y15+X24+Y24 -> 78 | Z45: =Z8+AA8+Z15+AA15+Z24+AA24 -> 78 | AB45: =AB8+AC8+AB15+AC15+AB24+AC24 -> 78 | AD45: =AD8+AE8+AD15+AE15+AD24+AE24 -> 75 | AF45: =AF8+AG8+AF15+AG15+AF24+AG24 -> 57 | AH45: =AH8+AI8+AH15+AI15+AH24+AI24 -> 78 | AJ45: =AJ8+AK8+AJ15+AK15+AJ24+AK24 -> 78 | AL45: =AL8+AM8+AL15+AM15+AL24+AM24 -> 78 | AN45: =AN8+AO8+AN15+AO15+AN24+AO24 -> 78 | AP45: =AP8+AQ8+AP15+AQ15+AP24+AQ24 -> 78 | AR45: =AR8+AS8+AR15+AS15+AR24+AS24 -> 75 | AT45: =AT8+AU8+AT15+AU15+AT24+AU24 -> 57 | AV45: =AV8+AW8+AV15+AW15+AV24+AW24 -> 78 | AX45: =AX8+AY8+AX15+AY15+AX24+AY24 -> 78 | AZ45: =AZ8+BA8+AZ15+BA15+AZ24+BA24 -> 78 | BB45: =BB8+BC8+BB15+BC15+BB24+BC24 -> 78 | BD45: =BD8+BE8+BD15+BE15+BD24+BE24 -> 78 | BF45: =BF8+BG8+BF15+BG15+BF24+BG24 -> 75
A46: PU - SA | D46: =D3+E3+D10+E10+D19+E19 -> 0 | F46: =F3+G3+F10+G10+F19+G19 -> 33 | H46: =H3+I3+H10+I10+H19+I19 -> 33 | J46: =J3+K3+J10+K10+J19+K19 -> 30 | L46: =L3+M3+L10+M10+L19+M19 -> 33 | N46: =N3+O3+N10+O10+N19+O19 -> 33 | P46: =P3+Q3+P10+Q10+P19+Q19 -> 0 | R46: =R3+S3+R10+S10+R19+S19 -> 0 | T46: =T3+U3+T10+U10+T19+U19 -> 33 | V46: =V3+W3+V10+W10+V19+W19 -> 33 | X46: =X3+Y3+X10+Y10+X19+Y19 -> 33 | Z46: =Z3+AA3+Z10+AA10+Z19+AA19 -> 32 | AB46: =AB3+AC3+AB10+AC10+AB19+AC19 -> 33 | AD46: =AD3+AE3+AD10+AE10+AD19+AE19 -> 0 | AF46: =AF3+AG3+AF10+AG10+AF19+AG19 -> 0 | AH46: =AH3+AI3+AH10+AI10+AH19+AI19 -> 33 | AJ46: =AJ3+AK3+AJ10+AK10+AJ19+AK19 -> 32 | AL46: =AL3+AM3+AL10+AM10+AL19+AM19 -> 32 | AN46: =AN3+AO3+AN10+AO10+AN19+AO19 -> 33 | AP46: =AP3+AQ3+AP10+AQ10+AP19+AQ19 -> 31 | AR46: =AR3+AS3+AR10+AS10+AR19+AS19 -> 0 | AT46: =AT3+AU3+AT10+AU10+AT19+AU19 -> 0 | AV46: =AV3+AW3+AV10+AW10+AV19+AW19 -> 33 | AX46: =AX3+AY3+AX10+AY10+AX19+AY19 -> 33 | AZ46: =AZ3+BA3+AZ10+BA10+AZ19+BA19 -> 33 | BB46: =BB3+BC3+BB10+BC10+BB19+BC19 -> 33 | BD46: =BD3+BE3+BD10+BE10+BD19+BE19 -> 33 | BF46: =BF3+BG3+BF10+BG10+BF19+BG19 -> 0
A47: SA - PU | D47: =D6+E6+D13+E13+D22+E22 -> 0 | F47: =F6+G6+F13+G13+F22+G22 -> 32 | H47: =H6+I6+H13+I13+H22+I22 -> 32 | J47: =J6+K6+J13+K13+J22+K22 -> 29 | L47: =L6+M6+L13+M13+L22+M22 -> 32 | N47: =N6+O6+N13+O13+N22+O22 -> 32 | P47: =P6+Q6+P13+Q13+P22+Q22 -> 0 | R47: =R6+S6+R13+S13+R22+S22 -> 0 | T47: =T6+U6+T13+U13+T22+U22 -> 32 | V47: =V6+W6+V13+W13+V22+W22 -> 32 | X47: =X6+Y6+X13+Y13+X22+Y22 -> 32 | Z47: =Z6+AA6+Z13+AA13+Z22+AA22 -> 31 | AB47: =AB6+AC6+AB13+AC13+AB22+AC22 -> 32 | AD47: =AD6+AE6+AD13+AE13+AD22+AE22 -> 0 | AF47: =AF6+AG6+AF13+AG13+AF22+AG22 -> 0 | AH47: =AH6+AI6+AH13+AI13+AH22+AI22 -> 32 | AJ47: =AJ6+AK6+AJ13+AK13+AJ22+AK22 -> 32 | AL47: =AL6+AM6+AL13+AM13+AL22+AM22 -> 32 | AN47: =AN6+AO6+AN13+AO13+AN22+AO22 -> 32 | AP47: =AP6+AQ6+AP13+AQ13+AP22+AQ22 -> 31 | AR47: =AR6+AS6+AR13+AS13+AR22+AS22 -> 0 | AT47: =AT6+AU6+AT13+AU13+AT22+AU22 -> 0 | AV47: =AV6+AW6+AV13+AW13+AV22+AW22 -> 32 | AX47: =AX6+AY6+AX13+AY13+AX22+AY22 -> 32 | AZ47: =AZ6+BA6+AZ13+BA13+AZ22+BA22 -> 32 | BB47: =BB6+BC6+BB13+BC13+BB22+BC22 -> 32 | BD47: =BD6+BE6+BD13+BE13+BD22+BE22 -> 32 | BF47: =BF6+BG6+BF13+BG13+BF22+BG22 -> 0
A48: PU-EB | D48: =D4+E4+D11+E11+D20+E20 -> 0 | F48: =F4+G4+F11+G11+F20+G20 -> 0 | H48: =H4+I4+H11+I11+H20+I20 -> 0 | J48: =J4+K4+J11+K11+J20+K20 -> 0 | L48: =L4+M4+L11+M11+L20+M20 -> 0 | N48: =N4+O4+N11+O11+N20+O20 -> 0 | P48: =P4+Q4+P11+Q11+P20+Q20 -> 0 | R48: =R4+S4+R11+S11+R20+S20 -> 0 | T48: =T4+U4+T11+U11+T20+U20 -> 0 | V48: =V4+W4+V11+W11+V20+W20 -> 0 | X48: =X4+Y4+X11+Y11+X20+Y20 -> 0 | Z48: =Z4+AA4+Z11+AA11+Z20+AA20 -> 0 | AB48: =AB4+AC4+AB11+AC11+AB20+AC20 -> 0 | AD48: =AD4+AE4+AD11+AE11+AD20+AE20 -> 0 | AF48: =AF4+AG4+AF11+AG11+AF20+AG20 -> 0 | AH48: =AH4+AI4+AH11+AI11+AH20+AI20 -> 0 | AJ48: =AJ4+AK4+AJ11+AK11+AJ20+AK20 -> 0 | AL48: =AL4+AM4+AL11+AM11+AL20+AM20 -> 0 | AN48: =AN4+AO4+AN11+AO11+AN20+AO20 -> 0 | AP48: =AP4+AQ4+AP11+AQ11+AP20+AQ20 -> 0 | AR48: =AR4+AS4+AR11+AS11+AR20+AS20 -> 0 | AT48: =AT4+AU4+AT11+AU11+AT20+AU20 -> 0 | AV48: =AV4+AW4+AV11+AW11+AV20+AW20 -> 0 | AX48: =AX4+AY4+AX11+AY11+AX20+AY20 -> 0 | AZ48: =AZ4+BA4+AZ11+BA11+AZ20+BA20 -> 0 | BB48: =BB4+BC4+BB11+BC11+BB20+BC20 -> 0 | BD48: =BD4+BE4+BD11+BE11+BD20+BE20 -> 0 | BF48: =BF4+BG4+BF11+BG11+BF20+BG20 -> 0
A49: EB-PU | D49: =D7+E7+D14+E14+D23+E23 -> 0 | F49: =F7+G7+F14+G14+F23+G23 -> 1 | H49: =H7+I7+H14+I14+H23+I23 -> 1 | J49: =J7+K7+J14+K14+J23+K23 -> 1 | L49: =L7+M7+L14+M14+L23+M23 -> 1 | N49: =N7+O7+N14+O14+N23+O23 -> 1 | P49: =P7+Q7+P14+Q14+P23+Q23 -> 0 | R49: =R7+S7+R14+S14+R23+S23 -> 0 | T49: =T7+U7+T14+U14+T23+U23 -> 1 | V49: =V7+W7+V14+W14+V23+W23 -> 1 | X49: =X7+Y7+X14+Y14+X23+Y23 -> 1 | Z49: =Z7+AA7+Z14+AA14+Z23+AA23 -> 2 | AB49: =AB7+AC7+AB14+AC14+AB23+AC23 -> 1 | AD49: =AD7+AE7+AD14+AE14+AD23+AE23 -> 0 | AF49: =AF7+AG7+AF14+AG14+AF23+AG23 -> 0 | AH49: =AH7+AI7+AH14+AI14+AH23+AI23 -> 1 | AJ49: =AJ7+AK7+AJ14+AK14+AJ23+AK23 -> 1 | AL49: =AL7+AM7+AL14+AM14+AL23+AM23 -> 1 | AN49: =AN7+AO7+AN14+AO14+AN23+AO23 -> 1 | AP49: =AP7+AQ7+AP14+AQ14+AP23+AQ23 -> 1 | AR49: =AR7+AS7+AR14+AS14+AR23+AS23 -> 0 | AT49: =AT7+AU7+AT14+AU14+AT23+AU23 -> 0 | AV49: =AV7+AW7+AV14+AW14+AV23+AW23 -> 1 | AX49: =AX7+AY7+AX14+AY14+AX23+AY23 -> 1 | AZ49: =AZ7+BA7+AZ14+BA14+AZ23+BA23 -> 1 | BB49: =BB7+BC7+BB14+BC14+BB23+BC23 -> 1 | BD49: =BD7+BE7+BD14+BE14+BD23+BE23 -> 1 | BF49: =BF7+BG7+BF14+BG14+BF23+BG23 -> 0
...

Sheet Oferta Diaria
A1: Oferta Enero 2026
C3: 46054 | D3: 46055 | E3: 46056 | F3: 46057 | G3: 46058 | H3: 46059 | I3: 46060 | J3: 46061 | K3: 46062 | L3: 46063 | M3: 46064 | N3: 46065 | O3: 46066 | P3: 46067 | Q3: 46068 | R3: 46069 | S3: 46070 | T3: 46071 | U3: 46072 | V3: 46073 | W3: 46074 | X3: 46075 | Y3: 46076 | Z3: 46077 | AA3: 46078 | AB3: 46079 | AC3: 46080 | AD3: 46081
A4: HÁBIL | B4: km
A5: Servicios PU-LI | B5: 43.13 | C5: ='Data Ocupacion'!D44 -> 54 | D5: ='Data Ocupacion'!F44 -> 79 | E5: ='Data Ocupacion'!H44 -> 79 | F5: ='Data Ocupacion'!J44 -> 79 | G5: ='Data Ocupacion'!L44 -> 79 | H5: ='Data Ocupacion'!N44 -> 79 | I5: ='Data Ocupacion'!P44 -> 72 | J5: ='Data Ocupacion'!R44 -> 54 | K5: ='Data Ocupacion'!T44 -> 79 | L5: ='Data Ocupacion'!V44 -> 79 | M5: ='Data Ocupacion'!X44 -> 79 | N5: ='Data Ocupacion'!Z44 -> 80 | O5: ='Data Ocupacion'!AB44 -> 79 | P5: ='Data Ocupacion'!AD44 -> 72 | Q5: ='Data Ocupacion'!AF44 -> 54 | R5: ='Data Ocupacion'!AH44 -> 79 | S5: ='Data Ocupacion'!AJ44 -> 80 | T5: ='Data Ocupacion'!AL44 -> 79 | U5: ='Data Ocupacion'!AN44 -> 79 | V5: ='Data Ocupacion'!AP44 -> 79 | W5: ='Data Ocupacion'!AR44 -> 72 | X5: ='Data Ocupacion'!AT44 -> 54 | Y5: ='Data Ocupacion'!AV44 -> 79 | Z5: ='Data Ocupacion'!AX44 -> 79 | AA5: ='Data Ocupacion'!AZ44 -> 79 | AB5: ='Data Ocupacion'!BB44 -> 79 | AC5: ='Data Ocupacion'!BD44 -> 79 | AD5: ='Data Ocupacion'!BF44 -> 72
A6: Servicios LI-PU | B6: 43.13 | C6: ='Data Ocupacion'!D45 -> 57 | D6: ='Data Ocupacion'!F45 -> 78 | E6: ='Data Ocupacion'!H45 -> 78 | F6: ='Data Ocupacion'!J45 -> 78 | G6: ='Data Ocupacion'!L45 -> 78 | H6: ='Data Ocupacion'!N45 -> 78 | I6: ='Data Ocupacion'!P45 -> 75 | J6: ='Data Ocupacion'!R45 -> 57 | K6: ='Data Ocupacion'!T45 -> 78 | L6: ='Data Ocupacion'!V45 -> 78 | M6: ='Data Ocupacion'!X45 -> 78 | N6: ='Data Ocupacion'!Z45 -> 78 | O6: ='Data Ocupacion'!AB45 -> 78 | P6: ='Data Ocupacion'!AD45 -> 75 | Q6: ='Data Ocupacion'!AF45 -> 57 | R6: ='Data Ocupacion'!AH45 -> 78 | S6: ='Data Ocupacion'!AJ45 -> 78 | T6: ='Data Ocupacion'!AL45 -> 78 | U6: ='Data Ocupacion'!AN45 -> 78 | V6: ='Data Ocupacion'!AP45 -> 78 | W6: ='Data Ocupacion'!AR45 -> 75 | X6: ='Data Ocupacion'!AT45 -> 57 | Y6: ='Data Ocupacion'!AV45 -> 78 | Z6: ='Data Ocupacion'!AX45 -> 78 | AA6: ='Data Ocupacion'!AZ45 -> 78 | AB6: ='Data Ocupacion'!BB45 -> 78 | AC6: ='Data Ocupacion'!BD45 -> 78 | AD6: ='Data Ocupacion'!BF45 -> 75
A7: Servicios PU-SA | B7: 29.11 | C7: ='Data Ocupacion'!D46 -> 0 | D7: ='Data Ocupacion'!F46 -> 33 | E7: ='Data Ocupacion'!H46 -> 33 | F7: ='Data Ocupacion'!J46 -> 30 | G7: ='Data Ocupacion'!L46 -> 33 | H7: ='Data Ocupacion'!N46 -> 33 | I7: ='Data Ocupacion'!P46 -> 0 | J7: ='Data Ocupacion'!R46 -> 0 | K7: ='Data Ocupacion'!T46 -> 33 | L7: ='Data Ocupacion'!V46 -> 33 | M7: ='Data Ocupacion'!X46 -> 33 | N7: ='Data Ocupacion'!Z46 -> 32 | O7: ='Data Ocupacion'!AB46 -> 33 | P7: ='Data Ocupacion'!AD46 -> 0 | Q7: ='Data Ocupacion'!AF46 -> 0 | R7: ='Data Ocupacion'!AH46 -> 33 | S7: ='Data Ocupacion'!AJ46 -> 32 | T7: ='Data Ocupacion'!AL46 -> 32 | U7: ='Data Ocupacion'!AN46 -> 33 | V7: ='Data Ocupacion'!AP46 -> 31 | W7: ='Data Ocupacion'!AR46 -> 0 | X7: ='Data Ocupacion'!AT46 -> 0 | Y7: ='Data Ocupacion'!AV46 -> 33 | Z7: ='Data Ocupacion'!AX46 -> 33 | AA7: ='Data Ocupacion'!AZ46 -> 33 | AB7: ='Data Ocupacion'!BB46 -> 33 | AC7: ='Data Ocupacion'!BD46 -> 33 | AD7: ='Data Ocupacion'!BF46 -> 0
A8: Servicios SA-PU | B8: 29.11 | C8: ='Data Ocupacion'!D47 -> 0 | D8: ='Data Ocupacion'!F47 -> 32 | E8: ='Data Ocupacion'!H47 -> 32 | F8: ='Data Ocupacion'!J47 -> 29 | G8: ='Data Ocupacion'!L47 -> 32 | H8: ='Data Ocupacion'!N47 -> 32 | I8: ='Data Ocupacion'!P47 -> 0 | J8: ='Data Ocupacion'!R47 -> 0 | K8: ='Data Ocupacion'!T47 -> 32 | L8: ='Data Ocupacion'!V47 -> 32 | M8: ='Data Ocupacion'!X47 -> 32 | N8: ='Data Ocupacion'!Z47 -> 31 | O8: ='Data Ocupacion'!AB47 -> 32 | P8: ='Data Ocupacion'!AD47 -> 0 | Q8: ='Data Ocupacion'!AF47 -> 0 | R8: ='Data Ocupacion'!AH47 -> 32 | S8: ='Data Ocupacion'!AJ47 -> 32 | T8: ='Data Ocupacion'!AL47 -> 32 | U8: ='Data Ocupacion'!AN47 -> 32 | V8: ='Data Ocupacion'!AP47 -> 31 | W8: ='Data Ocupacion'!AR47 -> 0 | X8: ='Data Ocupacion'!AT47 -> 0 | Y8: ='Data Ocupacion'!AV47 -> 32 | Z8: ='Data Ocupacion'!AX47 -> 32 | AA8: ='Data Ocupacion'!AZ47 -> 32 | AB8: ='Data Ocupacion'!BB47 -> 32 | AC8: ='Data Ocupacion'!BD47 -> 32 | AD8: ='Data Ocupacion'!BF47 -> 0
A9: Servicios PU-EB | B9: 25.4 | C9: ='Data Ocupacion'!D48 -> 0 | D9: ='Data Ocupacion'!F48 -> 0 | E9: ='Data Ocupacion'!H48 -> 0 | F9: ='Data Ocupacion'!J48 -> 0 | G9: ='Data Ocupacion'!L48 -> 0 | H9: ='Data Ocupacion'!N48 -> 0 | I9: ='Data Ocupacion'!P48 -> 0 | J9: ='Data Ocupacion'!R48 -> 0 | K9: ='Data Ocupacion'!T48 -> 0 | L9: ='Data Ocupacion'!V48 -> 0 | M9: ='Data Ocupacion'!X48 -> 0 | N9: ='Data Ocupacion'!Z48 -> 0 | O9: ='Data Ocupacion'!AB48 -> 0 | P9: ='Data Ocupacion'!AD48 -> 0 | Q9: ='Data Ocupacion'!AF48 -> 0 | R9: ='Data Ocupacion'!AH48 -> 0 | S9: ='Data Ocupacion'!AJ48 -> 0 | T9: ='Data Ocupacion'!AL48 -> 0 | U9: ='Data Ocupacion'!AN48 -> 0 | V9: ='Data Ocupacion'!AP48 -> 0 | W9: ='Data Ocupacion'!AR48 -> 0 | X9: ='Data Ocupacion'!AT48 -> 0 | Y9: ='Data Ocupacion'!AV48 -> 0 | Z9: ='Data Ocupacion'!AX48 -> 0 | AA9: ='Data Ocupacion'!AZ48 -> 0 | AB9: ='Data Ocupacion'!BB48 -> 0 | AC9: ='Data Ocupacion'!BD48 -> 0 | AD9: ='Data Ocupacion'!BF48 -> 0
A10: Servicios EB-PU | B10: 25.4 | C10: ='Data Ocupacion'!D49 -> 0 | D10: ='Data Ocupacion'!F49 -> 1 | E10: ='Data Ocupacion'!H49 -> 1 | F10: ='Data Ocupacion'!J49 -> 1 | G10: ='Data Ocupacion'!L49 -> 1 | H10: ='Data Ocupacion'!N49 -> 1 | I10: ='Data Ocupacion'!P49 -> 0 | J10: ='Data Ocupacion'!R49 -> 0 | K10: ='Data Ocupacion'!T49 -> 1 | L10: ='Data Ocupacion'!V49 -> 1 | M10: ='Data Ocupacion'!X49 -> 1 | N10: ='Data Ocupacion'!Z49 -> 2 | O10: ='Data Ocupacion'!AB49 -> 1 | P10: ='Data Ocupacion'!AD49 -> 0 | Q10: ='Data Ocupacion'!AF49 -> 0 | R10: ='Data Ocupacion'!AH49 -> 1 | S10: ='Data Ocupacion'!AJ49 -> 1 | T10: ='Data Ocupacion'!AL49 -> 1 | U10: ='Data Ocupacion'!AN49 -> 1 | V10: ='Data Ocupacion'!AP49 -> 1 | W10: ='Data Ocupacion'!AR49 -> 0 | X10: ='Data Ocupacion'!AT49 -> 0 | Y10: ='Data Ocupacion'!AV49 -> 1 | Z10: ='Data Ocupacion'!AX49 -> 1 | AA10: ='Data Ocupacion'!AZ49 -> 1 | AB10: ='Data Ocupacion'!BB49 -> 1 | AC10: ='Data Ocupacion'!BD49 -> 1 | AD10: ='Data Ocupacion'!BF49 -> 0
A11: Servicios VM-LI | B11: 34.83 | Y11: ='Data Ocupacion'!AV50 -> 4 | Z11: ='Data Ocupacion'!AX50 -> 4 | AA11: ='Data Ocupacion'!AZ50 -> 4 | AB11: ='Data Ocupacion'!BB50 -> 4 | AC11: ='Data Ocupacion'!BD50 -> 4 | AD11: ='Data Ocupacion'!BF50 -> 4
A12: Servicios VM-PU | B12: 8.3 | Y12: ='Data Ocupacion'!AV51 -> 2 | Z12: ='Data Ocupacion'!AX51 -> 2 | AA12: ='Data Ocupacion'!AZ51 -> 2 | AB12: ='Data Ocupacion'!BB51 -> 2 | AC12: ='Data Ocupacion'!BD51 -> 2 | AD12: ='Data Ocupacion'!BF51 -> 2
A14: Trenes PU-LI | B14: 43.13 | C14: ='Data Ocupacion'!D54 -> 57 | D14: ='Data Ocupacion'!F54 -> 87 | E14: ='Data Ocupacion'!H54 -> 80 | F14: ='Data Ocupacion'!J54 -> 82 | G14: ='Data Ocupacion'!L54 -> 81 | H14: ='Data Ocupacion'!N54 -> 81 | I14: ='Data Ocupacion'!P54 -> 75 | J14: ='Data Ocupacion'!R54 -> 57 | K14: ='Data Ocupacion'!T54 -> 80 | L14: ='Data Ocupacion'!V54 -> 80 | M14: ='Data Ocupacion'!X54 -> 80 | N14: ='Data Ocupacion'!Z54 -> 81 | O14: ='Data Ocupacion'!AB54 -> 81 | P14: ='Data Ocupacion'!AD54 -> 75 | Q14: ='Data Ocupacion'!AF54 -> 62 | R14: ='Data Ocupacion'!AH54 -> 80 | S14: ='Data Ocupacion'!AJ54 -> 81 | T14: ='Data Ocupacion'!AL54 -> 108 | U14: ='Data Ocupacion'!AN54 -> 92 | V14: ='Data Ocupacion'!AP54 -> 80 | W14: ='Data Ocupacion'!AR54 -> 75 | X14: ='Data Ocupacion'!AT54 -> 66 | Y14: ='Data Ocupacion'!AV54 -> 82 | Z14: ='Data Ocupacion'!AX54 -> 82 | AA14: ='Data Ocupacion'!AZ54 -> 82 | AB14: ='Data Ocupacion'!BB54 -> 82 | AC14: ='Data Ocupacion'!BD54 -> 82 | AD14: ='Data Ocupacion'!BF54 -> 74
A15: Trenes LI-PU | B15: 43.13 | C15: ='Data Ocupacion'!D55 -> 57 | D15: ='Data Ocupacion'!F55 -> 86 | E15: ='Data Ocupacion'!H55 -> 80 | F15: ='Data Ocupacion'!J55 -> 81 | G15: ='Data Ocupacion'!L55 -> 80 | H15: ='Data Ocupacion'!N55 -> 81 | I15: ='Data Ocupacion'!P55 -> 75 | J15: ='Data Ocupacion'!R55 -> 57 | K15: ='Data Ocupacion'!T55 -> 80 | L15: ='Data Ocupacion'!V55 -> 80 | M15: ='Data Ocupacion'!X55 -> 80 | N15: ='Data Ocupacion'!Z55 -> 80 | O15: ='Data Ocupacion'!AB55 -> 81 | P15: ='Data Ocupacion'!AD55 -> 75 | Q15: ='Data Ocupacion'!AF55 -> 62 | R15: ='Data Ocupacion'!AH55 -> 80 | S15: ='Data Ocupacion'!AJ55 -> 80 | T15: ='Data Ocupacion'!AL55 -> 107 | U15: ='Data Ocupacion'!AN55 -> 92 | V15: ='Data Ocupacion'!AP55 -> 80 | W15: ='Data Ocupacion'!AR55 -> 75 | X15: ='Data Ocupacion'!AT55 -> 66 | Y15: ='Data Ocupacion'!AV55 -> 82 | Z15: ='Data Ocupacion'!AX55 -> 82 | AA15: ='Data Ocupacion'!AZ55 -> 82 | AB15: ='Data Ocupacion'!BB55 -> 82 | AC15: ='Data Ocupacion'!BD55 -> 82 | AD15: ='Data Ocupacion'!BF55 -> 75
A16: Trenes PU-SA | B16: 29.11 | C16: ='Data Ocupacion'!D56 -> 0 | D16: ='Data Ocupacion'!F56 -> 33 | E16: ='Data Ocupacion'!H56 -> 33 | F16: ='Data Ocupacion'!J56 -> 30 | G16: ='Data Ocupacion'!L56 -> 33 | H16: ='Data Ocupacion'!N56 -> 33 | I16: ='Data Ocupacion'!P56 -> 0 | J16: ='Data Ocupacion'!R56 -> 0 | K16: ='Data Ocupacion'!T56 -> 33 | L16: ='Data Ocupacion'!V56 -> 33 | M16: ='Data Ocupacion'!X56 -> 33 | N16: ='Data Ocupacion'!Z56 -> 32 | O16: ='Data Ocupacion'!AB56 -> 33 | P16: ='Data Ocupacion'!AD56 -> 0 | Q16: ='Data Ocupacion'!AF56 -> 0 | R16: ='Data Ocupacion'!AH56 -> 33 | S16: ='Data Ocupacion'!AJ56 -> 32 | T16: ='Data Ocupacion'!AL56 -> 32 | U16: ='Data Ocupacion'!AN56 -> 33 | V16: ='Data Ocupacion'!AP56 -> 31 | W16: ='Data Ocupacion'!AR56 -> 0 | X16: ='Data Ocupacion'!AT56 -> 0 | Y16: ='Data Ocupacion'!AV56 -> 33 | Z16: ='Data Ocupacion'!AX56 -> 33 | AA16: ='Data Ocupacion'!AZ56 -> 33 | AB16: ='Data Ocupacion'!BB56 -> 33 | AC16: ='Data Ocupacion'!BD56 -> 33 | AD16: ='Data Ocupacion'!BF56 -> 0
A17: Trenes SA-PU | B17: 29.11 | C17: ='Data Ocupacion'!D57 -> 0 | D17: ='Data Ocupacion'!F57 -> 32 | E17: ='Data Ocupacion'!H57 -> 32 | F17: ='Data Ocupacion'!J57 -> 30 | G17: ='Data Ocupacion'!L57 -> 32 | H17: ='Data Ocupacion'!N57 -> 32 | I17: ='Data Ocupacion'!P57 -> 0 | J17: ='Data Ocupacion'!R57 -> 0 | K17: ='Data Ocupacion'!T57 -> 32 | L17: ='Data Ocupacion'!V57 -> 32 | M17: ='Data Ocupacion'!X57 -> 32 | N17: ='Data Ocupacion'!Z57 -> 31 | O17: ='Data Ocupacion'!AB57 -> 32 | P17: ='Data Ocupacion'!AD57 -> 0 | Q17: ='Data Ocupacion'!AF57 -> 0 | R17: ='Data Ocupacion'!AH57 -> 32 | S17: ='Data Ocupacion'!AJ57 -> 32 | T17: ='Data Ocupacion'!AL57 -> 32 | U17: ='Data Ocupacion'!AN57 -> 32 | V17: ='Data Ocupacion'!AP57 -> 31 | W17: ='Data Ocupacion'!AR57 -> 0 | X17: ='Data Ocupacion'!AT57 -> 0 | Y17: ='Data Ocupacion'!AV57 -> 32 | Z17: ='Data Ocupacion'!AX57 -> 32 | AA17: ='Data Ocupacion'!AZ57 -> 32 | AB17: ='Data Ocupacion'!BB57 -> 32 | AC17: ='Data Ocupacion'!BD57 -> 32 | AD17: ='Data Ocupacion'!BF57 -> 0
A18: Trenes EB-PU | B18: 25.4 | C18: ='Data Ocupacion'!D59 -> 0 | D18: ='Data Ocupacion'!F59 -> 1 | E18: ='Data Ocupacion'!H59 -> 1 | F18: ='Data Ocupacion'!J59 -> 1 | G18: ='Data Ocupacion'!L59 -> 1 | H18: ='Data Ocupacion'!N59 -> 1 | I18: ='Data Ocupacion'!P59 -> 0 | J18: ='Data Ocupacion'!R59 -> 0 | K18: ='Data Ocupacion'!T59 -> 1 | L18: ='Data Ocupacion'!V59 -> 1 | M18: ='Data Ocupacion'!X59 -> 1 | N18: ='Data Ocupacion'!Z59 -> 2 | O18: ='Data Ocupacion'!AB59 -> 1 | P18: ='Data Ocupacion'!AD59 -> 0 | Q18: ='Data Ocupacion'!AF59 -> 0 | R18: ='Data Ocupacion'!AH59 -> 1 | S18: ='Data Ocupacion'!AJ59 -> 1 | T18: ='Data Ocupacion'!AL59 -> 1 | U18: ='Data Ocupacion'!AN59 -> 1 | V18: ='Data Ocupacion'!AP59 -> 1 | W18: ='Data Ocupacion'!AR59 -> 0 | X18: ='Data Ocupacion'!AT59 -> 0 | Y18: ='Data Ocupacion'!AV59 -> 1 | Z18: ='Data Ocupacion'!AX59 -> 1 | AA18: ='Data Ocupacion'!AZ59 -> 1 | AB18: ='Data Ocupacion'!BB59 -> 1 | AC18: ='Data Ocupacion'!BD59 -> 1 | AD18: ='Data Ocupacion'!BF59 -> 0
A19: Trenes PU-EB | B19: 25.4 | C19: 0 | D19: 0 | E19: 0 | F19: 0 | G19: 0 | H19: 0 | I19: 0 | K19: 0 | L19: 0 | M19: 0 | N19: 0 | O19: 0 | P19: 0 | Q19: 0 | R19: 0 | S19: 0 | T19: 0 | U19: 0 | V19: 0 | W19: 0 | X19: 0 | Y19: 0 | Z19: 0 | AA19: 0 | AB19: 0 | AC19: 0 | AD19: 0
A20: Trenes VM-LI | B20: 34.83 | Y20: ='Data Ocupacion'!AV60 -> 5 | Z20: ='Data Ocupacion'!AX60 -> 5 | AA20: ='Data Ocupacion'!AZ60 -> 5 | AB20: ='Data Ocupacion'!BB60 -> 5 | AC20: ='Data Ocupacion'!BD60 -> 5 | AD20: ='Data Ocupacion'!BF60 -> 5
A21: Trenes VM-PU | B21: 8.3 | Y21: ='Data Ocupacion'!AV61 -> 2 | Z21: ='Data Ocupacion'!AX61 -> 2 | AA21: ='Data Ocupacion'!AZ61 -> 2 | AB21: ='Data Ocupacion'!BB61 -> 2 | AC21: ='Data Ocupacion'!BD61 -> 2 | AD21: ='Data Ocupacion'!BF61 -> 2
A23: Corte EB (600) V1 | B23: -17.73 | C23: ='KM-Servicio'!Q5 -> 0 | D23: ='KM-Servicio'!Q12 -> 5 | E23: ='KM-Servicio'!Q19 -> 0 | F23: ='KM-Servicio'!Q26 -> 0 | G23: ='KM-Servicio'!Q33 -> 0 | H23: ='KM-Servicio'!Q40 -> 0 | I23: ='KM-Servicio'!Q47 -> 0 | J23: ='KM-Servicio'!Q54 -> 0 | K23: ='KM-Servicio'!Q61 -> 0 | L23: ='KM-Servicio'!Q68 -> 0 | M23: ='KM-Servicio'!Q75 -> 0 | N23: ='KM-Servicio'!Q82 -> 0 | O23: ='KM-Servicio'!Q89 -> 0 | P23: ='KM-Servicio'!Q96 -> 0 | Q23: ='KM-Servicio'!Q103 -> 0 | R23: ='KM-Servicio'!Q110 -> 0 | S23: ='KM-Servicio'!Q117 -> 0 | T23: ='KM-Servicio'!Q124 -> 1 | U23: ='KM-Servicio'!Q131 -> 0 | V23: ='KM-Servicio'!Q138 -> 0 | W23: ='KM-Servicio'!Q145 -> 0 | X23: ='KM-Servicio'!Q152 -> 0 | Y23: ='KM-Servicio'!Q159 -> 0 | Z23: ='KM-Servicio'!Q168 -> 0 | AA23: ='KM-Servicio'!Q177 -> 0 | AB23: ='KM-Servicio'!Q186 -> 0 | AC23: ='KM-Servicio'!Q195 -> 0 | AD23: ='KM-Servicio'!Q204 -> 0
