Workbook

Sheet Odometro-Kilometraje
A1: Control Contador Kilometraje de Trenes
B2: 45566 | C2: 45567 | D2: 45568 | E2: 45569 | F2: 45570 | G2: 45571 | H2: 45572 | I2: 45573 | J2: 45574 | K2: 45575 | L2: 45576 | M2: 45577 | N2: 45578 | O2: 45579 | P2: 45580 | Q2: 45581 | R2: 45582 | S2: 45583 | T2: 45584 | U2: 45585 | V2: 45586 | W2: 45587 | X2: 45588 | Y2: 45589 | Z2: 45590 | AA2: 45591 | AB2: 45592 | AC2: 45593 | AD2: 45594 | AE2: 45595 | AF2: 45596
B3: Contador | C3: Contador | D3: Contador | E3: Contador | F3: Contador | G3: Contador | H3: Contador | I3: Contador | J3: Contador | K3: Contador | L3: Contador | M3: Contador | N3: Contador | O3: Contador | P3: Contador | Q3: Contador | R3: Contador | S3: Contador | T3: Contador | U3: Contador | V3: Contador | W3: Contador | X3: Contador | Y3: Contador | Z3: Contador | AA3: Contador | AB3: Contador | AC3: Contador | AD3: Contador | AE3: Contador | AF3: Contador
A4: Tren | B4: Odómetro | C4: Odómetro | D4: Odómetro | E4: Odómetro | F4: Odómetro | G4: Odómetro | H4: Odómetro | I4: Odómetro | J4: Odómetro | K4: Odómetro | L4: Odómetro | M4: Odómetro | N4: Odómetro | O4: Odómetro | P4: Odómetro | Q4: Odómetro | R4: Odómetro | S4: Odómetro | T4: Odómetro | U4: Odómetro | V4: Odómetro | W4: Odómetro | X4: Odómetro | Y4: Odómetro | Z4: Odómetro | AA4: Odómetro | AB4: Odómetro | AC4: Odómetro | AD4: Odómetro | AE4: Odómetro | AF4: Odómetro
A5: M01 | B5: 1939579 | C5: 1939930 | D5: 1940491 | E5: 1940797 | F5: 1941316 | G5: 1941752 | H5: 1942016 | I5: 1942579 | J5: 1942727 | K5: 1943264 | L5: 1943648 | M5: 1944085 | N5: 1944260 | O5: 1944778 | P5: 1945349 | Q5: 1945688 | R5: 1946085 | S5: 1946393 | T5: 1946456 | U5: 1946456 | V5: 1946822 | W5: 1947299 | X5: 1947653 | Y5: 1948085 | Z5: 1948346 | AA5: 1948736 | AB5: 1949211 | AC5: 1949728 | AD5: 1950009 | AE5: 1950194 | AF5: 1950473
A6: M02 | B6: 1923188 | C6: 1923538 | D6: 1923716 | E6: 1924238 | F6: 1924714 | G6: 1925147 | H6: 1925666 | I6: 1926141 | J6: 1926613 | K6: 1927176 | L6: 1927568 | M6: 1928006 | N6: 1928008 | O6: 1928377 | P6: 1928657 | Q6: 1928938 | R6: 1929193 | S6: 1929629 | T6: 1930149 | U6: 1930585 | V6: 1931037 | W6: 1931282 | X6: 1931715 | Y6: 1932168 | Z6: 1932354 | AA6: 1932528 | AB6: 1932848 | AC6: 1933049 | AD6: 1933146 | AE6: 1933641 | AF6: 1934072
A7: M03 | B7: 1997183 | C7: 1997438 | D7: 1997956 | E7: 1998430 | F7: 1998905 | G7: 1998906 | H7: 1999014 | I7: 1999111 | J7: 1999399 | K7: 1999893 | L7: 2000138 | M7: 2000553 | N7: 2000918 | O7: 2001439 | P7: 2001870 | Q7: 2002321 | R7: 2002471 | S7: 2002886 | T7: 2003017 | U7: 2003148 | V7: 2003516 | W7: 2003685 | X7: 2003998 | Y7: 2004450 | Z7: 2004747 | AA7: 2005050 | AB7: 2005484 | AC7: 2005934 | AD7: 2006153 | AE7: 2006628 | AF7: 2007060
A8: M04 | B8: 2001332 | C8: 2001741 | D8: 2001929 | E8: 2002086 | F8: 2002604 | G8: 2003036 | H8: 2003514 | I8: 2003987 | J8: 2004437 | K8: 2004665 | L8: 2005097 | M8: 2005097 | N8: 2005097 | O8: 2005571 | P8: 2006062 | Q8: 2006309 | R8: 2006826 | S8: 2007277 | T8: 2007277 | U8: 2007277 | V8: 2007814 | W8: 2008041 | X8: 2008493 | Y8: 2008748 | Z8: 2009197 | AA8: 2009603 | AB8: 2010120 | AC8: 2010552 | AD8: 2010941 | AE8: 2011461 | AF8: 2011893
A9: M05 | B9: 1904425 | C9: 1904875 | D9: 1905026 | E9: 1905212 | F9: 1905212 | G9: 1905212 | H9: 1905580 | I9: 1906101 | J9: 1906381 | K9: 1906767 | L9: 1907329 | M9: 1907761 | N9: 1907847 | O9: 1908366 | P9: 1908785 | Q9: 1908882 | R9: 1908965 | S9: 1909485 | T9: 1909918 | U9: 1910350 | V9: 1910629 | W9: 1910840 | X9: 1911316 | Y9: 1911460 | Z9: 1911896 | AA9: 1912175 | AB9: 1912281 | AC9: 1912733 | AD9: 1912832 | AE9: 1912992 | AF9: 1912992
A10: M06 | B10: 2017118 | C10: 2017642 | D10: 2018098 | E10: 2018259 | F10: 2018259 | G10: 2018259 | H10: 2018517 | I10: 2018866 | J10: 2019306 | K10: 2019468 | L10: 2019967 | M10: 2020360 | N10: 2020796 | O10: 2021251 | P10: 2021352 | Q10: 2021424 | R10: 2021949 | S10: 2022473 | T10: 2022999 | U10: 2023129 | V10: 2023653 | W10: 2024137 | X10: 2024595 | Y10: 2024966 | Z10: 2025147 | AA10: 2025147 | AB10: 2025172 | AC10: 2025271 | AD10: 2025726 | AE10: 2026094 | AF10: 2026094
A11: M07 | B11: 2043835 | C11: 2044287 | D11: 2044485 | E11: 2044645 | F11: 2044645 | G11: 2044645 | H11: 2045031 | I11: 2045217 | J11: 2045319 | K11: 2045688 | L11: 2046143 | M11: 2046534 | N11: 2046967 | O11: 2047445 | P11: 2047899 | Q11: 2048182 | R11: 2048659 | S11: 2049154 | T11: 2049154 | U11: 2049173 | V11: 2049626 | W11: 2049951 | X11: 2050472 | Y11: 2050992 | Z11: 2051262 | AA11: 2051438 | AB11: 2051526 | AC11: 2051963 | AD11: 2052417 | AE11: 2052768 | AF11: 2052768
A12: M08 | B12: 1952905 | C12: 1953422 | D12: 1953939 | E12: 1954390 | F12: 1954390 | G12: 1954390 | H12: 1954542 | I12: 1954729 | J12: 1955026 | K12: 1955264 | L12: 1955526 | M12: 1955526 | N12: 1955526 | O12: 1955958 | P12: 1956223 | Q12: 1956590 | R12: 1956768 | S12: 1957065 | T12: 1957196 | U12: 1957216 | V12: 1957322 | W12: 1957840 | X12: 1958276 | Y12: 1958708 | Z12: 1958970 | AA12: 1959405 | AB12: 1959922 | AC12: 1960373 | AD12: 1960738 | AE12: 1961257 | AF12: 1961431
A13: M09 | B13: 1935608 | C13: 1936064 | D13: 1936234 | E13: 1936691 | F13: 1936929 | G13: 1937371 | H13: 1937680 | I13: 1938136 | J13: 1938394 | K13: 1938850 | L13: 1939110 | M13: 1939547 | N13: 1939984 | O13: 1940303 | P13: 1940742 | Q13: 1941181 | R13: 1941533 | S13: 1941989 | T13: 1941989 | U13: 1941989 | V13: 1942246 | W13: 1942684 | X13: 1943003 | Y13: 1943357 | Z13: 1943542 | AA13: 1943825 | AB13: 1944194 | AC13: 1944442 | AD13: 1944899 | AE13: 1945427 | AF13: 1945513
A14: M10 | B14: 2009033 | C14: 2009260 | D14: 2009711 | E14: 2009964 | F14: 2010442 | G14: 2010485 | H14: 2010933 | I14: 2011152 | J14: 2011669 | K14: 2012186 | L14: 2012359 | M14: 2012359 | N14: 2012379 | O14: 2012565 | P14: 2012742 | Q14: 2012839 | R14: 2013382 | S14: 2013790 | T14: 2013790 | U14: 2013790 | V14: 2013998 | W14: 2014430 | X14: 2014882 | Y14: 2015138 | Z14: 2015450 | AA14: 2015605 | AB14: 2015712 | AC14: 2016228 | AD14: 2016792 | AE14: 2017181 | AF14: 2017614
A15: M11 | B15: 2026006 | C15: 2026192 | D15: 2026536 | E15: 2027061 | F15: 2027582 | G15: 2028017 | H15: 2028470 | I15: 2028941 | J15: 2029120 | K15: 2029674 | L15: 2029876 | M15: 2029876 | N15: 2029876 | O15: 2030064 | P15: 2030320 | Q15: 2030585 | R15: 2030674 | S15: 2031108 | T15: 2031628 | U15: 2031889 | V15: 2032365 | W15: 2032756 | X15: 2032985 | Y15: 2033466 | Z15: 2033943 | AA15: 2034118 | AB15: 2034423 | AC15: 2034918 | AD15: 2035250 | AE15: 2035701 | AF15: 2035701
A16: M12 | B16: 1863761 | C16: 1863902 | D16: 1864423 | E16: 1864898 | F16: 1865115 | G16: 1865116 | H16: 1865226 | I16: 1865506 | J16: 1866024 | K16: 1866239 | L16: 1866800 | M16: 1867104 | N16: 1867540 | O16: 1867841 | P16: 1868262 | Q16: 1868449 | R16: 1868874 | S16: 1869325 | T16: 1869325 | U16: 1869325 | V16: 1869483 | W16: 1870000 | X16: 1870435 | Y16: 1870888 | Z16: 1871346 | AA16: 1871780 | AB16: 1872298 | AC16: 1872816 | AD16: 1873335 | AE16: 1873643 | AF16: 1874075
... A39: XM35 | B39: 612757 | C39: 613019 | D39: 613196 | E39: 613321 | F39: 613321 | G39: 613321 | H39: 613753 | I39: 614228 | J39: 614619 | K39: 615051 | L39: 615228 | M39: 615316 | N39: 615318 | O39: 615768 | P39: 615867 | Q39: 616302 | R39: 616480 | S39: 616577 | T39: 616577 | U39: 616577 | V39: 616935 | W39: 617032 | X39: 617298 | Y39: 617423 | Z39: 617805 | AA39: 617805 | AB39: 617930 | AC39: 618270 | AD39: 618619 | AE39: 619070 | AF39: 619070
A41: Kilometraje Diario Recorrido
B42: 45566 | C42: 45567 | D42: 45568 | E42: 45569 | F42: 45570 | G42: 45571 | H42: 45572 | I42: 45573 | J42: 45574 | K42: 45575 | L42: 45576 | M42: 45577 | N42: 45578 | O42: 45579 | P42: 45580 | Q42: 45581 | R42: 45582 | S42: 45583 | T42: 45584 | U42: 45585 | V42: 45586 | W42: 45587 | X42: 45588 | Y42: 45589 | Z42: 45590 | AA42: 45591 | AB42: 45592 | AC42: 45593 | AD42: 45594 | AE42: 45595 | AF42: 45596
B43: Kilometraje | C43: Kilometraje | D43: Kilometraje | E43: Kilometraje | F43: Kilometraje | G43: Kilometraje | H43: Kilometraje | I43: Kilometraje | J43: Kilometraje | K43: Kilometraje | L43: Kilometraje | M43: Kilometraje | N43: Kilometraje | O43: Kilometraje | P43: Kilometraje | Q43: Kilometraje | R43: Kilometraje | S43: Kilometraje | T43: Kilometraje | U43: Kilometraje | V43: Kilometraje | W43: Kilometraje | X43: Kilometraje | Y43: Kilometraje | Z43: Kilometraje | AA43: Kilometraje | AB43: Kilometraje | AC43: Kilometraje | AD43: Kilometraje | AE43: Kilometraje | AF43: Kilometraje
A44: Tren | B44: Diario | C44: Diario | D44: Diario | E44: Diario | F44: Diario | G44: Diario | H44: Diario | I44: Diario | J44: Diario | K44: Diario | L44: Diario | M44: Diario | N44: Diario | O44: Diario | P44: Diario | Q44: Diario | R44: Diario | S44: Diario | T44: Diario | U44: Diario | V44: Diario | W44: Diario | X44: Diario | Y44: Diario | Z44: Diario | AA44: Diario | AB44: Diario | AC44: Diario | AD44: Diario | AE44: Diario | AF44: Diario
A45: M01 | B45: 245 | C45: =C5-B5 -> 351 | D45: =D5-C5 -> 561 | E45: =E5-D5 -> 306 | F45: =F5-E5 -> 519 | G45: =G5-F5 -> 436 | H45: =H5-G5 -> 264 | I45: =I5-H5 -> 563 | J45: =J5-I5 -> 148 | ... AF45: =AF5-AE5 -> 279
A46: M02 | B46: 167 | C46: =C6-B6 -> 350 | D46: =D6-C6 -> 178 | E46: =E6-D6 -> 522 | F46: =F6-E6 -> 476 | G46: =G6-F6 -> 433 | H46: =H6-G6 -> 519 | I46: =I6-H6 -> 475 | J46: =J6-I6 -> 472 | ... AF46: =AF6-AE6 -> 431
A47: M03 | B47: 202 | C47: =C7-B7 -> 255 | D47: =D7-C7 -> 518 | E47: =E7-D7 -> 474 | F47: =F7-E7 -> 475 | G47: =G7-F7 -> 1 | H47: =H7-G7 -> 108 | I47: =I7-H7 -> 97 | J47: =J7-I7 -> 288 | ... AF47: =AF7-AE7 -> 432
A48: M04 | B48: 475 | C48: =C8-B8 -> 409 | D48: =D8-C8 -> 188 | E48: =E8-D8 -> 157 | F48: =F8-E8 -> 518 | G48: =G8-F8 -> 432 | H48: =H8-G8 -> 478 | I48: =I8-H8 -> 473 | J48: =J8-I8 -> 450 | ... AF48: =AF8-AE8 -> 432
A49: M05 | B49: 560 | C49: =C9-B9 -> 450 | D49: =D9-C9 -> 151 | E49: =E9-D9 -> 186 | F49: =F9-E9 -> 0 | G49: =G9-F9 -> 0 | H49: =H9-G9 -> 368 | I49: =I9-H9 -> 521 | J49: =J9-I9 -> 280 | ... AF49: =AF9-AE9 -> 0
A50: M06 | B50: 352 | C50: =C10-B10 -> 524 | D50: =D10-C10 -> 456 | E50: =E10-D10 -> 161 | F50: =F10-E10 -> 0 | G50: =G10-F10 -> 0 | H50: =H10-G10 -> 258 | I50: =I10-H10 -> 349 | J50: =J10-I10 -> 440 | ... AF50: =AF10-AE10 -> 0
A51: M07 | B51: 325 | C51: =C11-B11 -> 452 | D51: =D11-C11 -> 198 | E51: =E11-D11 -> 160 | F51: =F11-E11 -> 0 | G51: =G11-F11 -> 0 | H51: =H11-G11 -> 386 | I51: =I11-H11 -> 186 | J51: =J11-I11 -> 102 | ... AF51: =AF11-AE11 -> 0
A52: M08 | B52: 132 | C52: =C12-B12 -> 517 | D52: =D12-C12 -> 517 | E52: =E12-D12 -> 451 | F52: =F12-E12 -> 0 | G52: =G12-F12 -> 0 | H52: =H12-G12 -> 152 | I52: =I12-H12 -> 187 | J52: =J12-I12 -> 297 | ... AF52: =AF12-AE12 -> 174
A53: M09 | B53: 228 | C53: =C13-B13 -> 456 | D53: =D13-C13 -> 170 | E53: =E13-D13 -> 457 | F53: =F13-E13 -> 238 | G53: =G13-F13 -> 442 | H53: =H13-G13 -> 309 | I53: =I13-H13 -> 456 | J53: =J13-I13 -> 258 | ... AF53: =AF13-AE13 -> 86
A54: M10 | B54: 79 | C54: =C14-B14 -> 227 | D54: =D14-C14 -> 451 | E54: =E14-D14 -> 253 | F54: =F14-E14 -> 478 | G54: =G14-F14 -> 43 | H54: =H14-G14 -> 448 | I54: =I14-H14 -> 219 | J54: =J14-I14 -> 517 | ... AF54: =AF14-AE14 -> 433
A55: M11 | B55: 471 | C55: =C15-B15 -> 186 | D55: =D15-C15 -> 344 | E55: =E15-D15 -> 525 | F55: =F15-E15 -> 521 | G55: =G15-F15 -> 435 | H55: =H15-G15 -> 453 | I55: =I15-H15 -> 471 | J55: =J15-I15 -> 179 | ... AF55: =AF15-AE15 -> 0
A56: M12 | B56: 298 | C56: =C16-B16 -> 141 | D56: =D16-C16 -> 521 | E56: =E16-D16 -> 475 | F56: =F16-E16 -> 217 | G56: =G16-F16 -> 1 | H56: =H16-G16 -> 110 | I56: =I16-H16 -> 280 | J56: =J16-I16 -> 518 | ... AF56: =AF16-AE16 -> 432
... A79: XM35 | B79: 177 | C79: =C39-B39 -> 262 | D79: =D39-C39 -> 177 | E79: =E39-D39 -> 125 | F79: =F39-E39 -> 0 | G79: =G39-F39 -> 0 | H79: =H39-G39 -> 432 | I79: =I39-H39 -> 475 | J79: =J39-I39 -> 391 | ... AF79: =AF39-AE39 -> 0
A81: Kilometraje Diario | B81: =SUM(B45:B79) -> 11811 | C81: =SUM(C45:C79) -> 11745 | D81: =SUM(D45:D79) -> 11781 | E81: =SUM(E45:E79) -> 11884 | F81: =SUM(F45:F79) -> 6606 | G81: =SUM(G45:G79) -> 4952 | H81: =SUM(H45:H79) -> 11786 | I81: =SUM(I45:I79) -> 11731 | ... AF81: =SUM(AF45:AF79) -> 4988
W86: XT-1 | X86: 1950194 | Y86: 1950473 | Z86: 279 | AA86: 17.83 | AB86: 258.78 | AC86: 2.39
W87: XT-2 | X87: 1933641 | Y87: 1934072 | Z87: 431 | AA87: 0 | AB87: 431.3 | AC87: -0.3
W88: XT-3 | X88: 2006628 | Y88: 2007060 | Z88: 432 | AA88: 0 | AB88: 431.3 | AC88: 0.7
W89: XT-4 | X89: 2011461 | Y89: 2011893 | Z89: 432 | AA89: 0 | AB89: 431.3 | AC89: 0.7
W90: XT-5 | X90: 1912992 | Y90: 1912992 | Z90: 0 | AA90: 0 | AB90: 0 | AC90: 0
...

Sheet KM-Servicio
G1: SA-MI | H1: 21.7 | I1: EB-PU | J1: 25.4 | K1: PU-SA | L1: 29.11 | M1: QU-LI / LI-QU | N1: 21.7 | O1: VM-PU | P1: 8.3 | Q1: VM-LI | R1: 34.83 | S1: PU-ES | T1: 11.7 | U1: PU-QU
B2: CANTIDAD DE SERVICIOS | D2: CANTIDAD DE SERVICIOS | G2: PU-PE | H2: 30.4 | I2: PO-SA | J2: 25.4 | K2: PU-LI | L2: 43.13 | M2: MI-LI / LI-MI | N2: 35.73 | O2: HO-LI/LI-HO | P2: 33.97 | Q2: PU-MI | R2: 7.4 | S2: PE-LI | T2: 12.73 | U2: 21.4
B3: PROGRAMADOS | D3: REALIZADOS | F3: Origen-Destino | G3: Total Trenes | H3: Total Servicios | I3: Kms.xTrenes | J3: Kmsxservicios. | K3: Asientos x Kms. | L3: Disp x Km. | M3: Total Odómetro | N3: % Uso Trenes | P3: Cortes | S3: Acoples | U3: KmTren R
B4: Simples | C4: Dobles | D4: Simples | E4: Dobles | P4: EB | Q4: SA | R4: PE | S4: EB | T4: SA
A5: 45566 | B5: 36 | C5: 47 | D5: ='Data Ocupacion'!D32 -> 35 | E5: ='Data Ocupacion'!E32 -> 48 | F5: PU-LI | G5: =D5+E5*2 -> 131 | H5: =D5+E5 -> 83 | I5: =G5*L$2 -> 5650.03 | J5: =H5*L$2 -> 3579.79 | K5: =I5*104 -> 587603.12 | L5: =H5*104 -> 8632 | P5: 5 | U5: =I5-((P5*($L$2-$J$1)))-(S5*($J$1)) -> 5561.38
B6: 35 | C6: 44 | D6: ='Data Ocupacion'!D33 -> 34 | E6: ='Data Ocupacion'!E33 -> 45 | F6: LI-PU | G6: =D6+E6*2 -> 124 | H6: =D6+E6 -> 79 | I6: =G6*L$2 -> 5348.12 | J6: =H6*L$2 -> 3407.27 | K6: =I6*104 -> 556204.48 | L6: =H6*104 -> 8216 | U6: =I6-(S6*($L$2-$J$1)+(T6*($L$2-$L$1))) -> 5348.12
B7: 0 | C7: 2 | D7: ='Data Ocupacion'!D34 -> 0 | E7: ='Data Ocupacion'!E34 -> 2 | F7: PU-SA | G7: =D7+E7*2 -> 4 | H7: =D7+E7 -> 2 | I7: =G7*L$1 -> 116.44 | J7: =H7*L$1 -> 58.22 | K7: =I7*104 -> 12109.76 | L7: =H7*104 -> 208 | P7: 1 | U7: =I7-(P7*($L$1-$J$1)) -> 112.73
B8: 0 | C8: 3 | D8: ='Data Ocupacion'!D35 -> 0 | E8: ='Data Ocupacion'!E35 -> 3 | F8: SA-PU | G8: =D8+E8*2 -> 6 | H8: =D8+E8 -> 3 | I8: =G8*L$1 -> 174.66 | J8: =H8*L$1 -> 87.33 | K8: =I8*104 -> 18164.64 | L8: =H8*104 -> 312 | U8: =I8 -> 174.66
B9: 0 | C9: 0 | D9: ='Data Ocupacion'!D36 -> 0 | E9: ='Data Ocupacion'!E36 -> 0 | F9: PU-EB | G9: =D9+E9*2 -> 0 | H9: =D9+E9 -> 0 | I9: =G9*J$1 -> 0 | J9: =H9*J$1 -> 0 | K9: =I9*104 -> 0 | L9: =H9*104 -> 0 | U9: =I9 -> 0
B10: 1 | C10: 2 | D10: ='Data Ocupacion'!D37 -> 1 | E10: ='Data Ocupacion'!E37 -> 2 | F10: EB-PU | G10: =D10+E10*2 -> 5 | H10: =D10+E10 -> 3 | I10: =G10*J$1 -> 127 | J10: =H10*J$1 -> 76.2 | K10: =I10*104 -> 13208 | L10: =H10*104 -> 312 | U10: =I10 -> 127
B11: =SUM(B5:B10) -> 72 | C11: =SUM(C5:C10) -> 98 | D11: =SUM(D5:D10) -> 70 | E11: =SUM(E5:E10) -> 100 | G11: =SUM(G5:G10) -> 270 | H11: =SUM(H5:H10) -> 170 | I11: =SUM(I5:I10) -> 11416.25 | J11: =SUM(J5:J10) -> 7208.81 | K11: =SUM(K5:K10) -> 1187290 | L11: =SUM(L5:L10) -> 17680 | M11: ='Odometro-Kilometraje'!B81 -> 11811 | N11: =(U11/M11)*100 -> 95.875794 | U11: =SUM(U5:U10) -> 11323.89
A12: =A5+1 -> 45567 | B12: 36 | C12: 47 | D12: ='Data Ocupacion'!F32 -> 36 | E12: ='Data Ocupacion'!G32 -> 47 | F12: PU-LI | G12: =D12+E12*2 -> 130 | H12: =D12+E12 -> 83 | I12: =G12*L$2 -> 5606.9 | J12: =H12*L$2 -> 3579.79 | K12: =I12*104 -> 583117.6 | L12: =H12*104 -> 8632 | P12: 3 | U12: =I12-((P12*($L$2-$J$1)))-(S12*($J$1)) -> 5553.71
B13: 35 | C13: 44 | D13: ='Data Ocupacion'!F33 -> 35 | E13: ='Data Ocupacion'!G33 -> 44 | F13: LI-PU | G13: =D13+E13*2 -> 123 | H13: =D13+E13 -> 79 | I13: =G13*L$2 -> 5304.99 | J13: =H13*L$2 -> 3407.27 | K13: =I13*104 -> 551718.96 | L13: =H13*104 -> 8216 | U13: =I13-(S13*($L$2-$J$1)+(T13*($L$2-$L$1))) -> 5304.99
B14: 0 | C14: 2 | D14: ='Data Ocupacion'!F34 -> 0 | E14: ='Data Ocupacion'!G34 -> 2 | F14: PU-SA | G14: =D14+E14*2 -> 4 | H14: =D14+E14 -> 2 | I14: =G14*L$1 -> 116.44 | J14: =H14*L$1 -> 58.22 | K14: =I14*104 -> 12109.76 | L14: =H14*104 -> 208 | U14: =I14-(P14*($L$1-$J$1)) -> 116.44
B15: 0 | C15: 3 | D15: ='Data Ocupacion'!F35 -> 0 | E15: ='Data Ocupacion'!G35 -> 3 | F15: SA-PU | G15: =D15+E15*2 -> 6 | H15: =D15+E15 -> 3 | I15: =G15*L$1 -> 174.66 | J15: =H15*L$1 -> 87.33 | K15: =I15*104 -> 18164.64 | L15: =H15*104 -> 312 | U15: =I15 -> 174.66
B16: 0 | C16: 0 | D16: ='Data Ocupacion'!F36 -> 0 | E16: ='Data Ocupacion'!G36 -> 0 | F16: PU-EB | G16: =D16+E16*2 -> 0 | H16: =D16+E16 -> 0 | I16: =G16*J$1 -> 0 | J16: =H16*J$1 -> 0 | K16: =I16*104 -> 0 | L16: =H16*104 -> 0 | U16: =I16 -> 0
B17: 1 | C17: 2 | D17: ='Data Ocupacion'!F37 -> 1 | E17: ='Data Ocupacion'!G37 -> 2 | F17: EB-PU | G17: =D17+E17*2 -> 5 | H17: =D17+E17 -> 3 | I17: =G17*J$1 -> 127 | J17: =H17*J$1 -> 76.2 | K17: =I17*104 -> 13208 | L17: =H17*104 -> 312 | U17: =I17 -> 127
B18: =SUM(B12:B17) -> 72 | C18: =SUM(C12:C17) -> 98 | D18: =SUM(D12:D17) -> 72 | E18: =SUM(E12:E17) -> 98 | G18: =SUM(G12:G17) -> 268 | H18: =SUM(H12:H17) -> 170 | I18: =SUM(I12:I17) -> 11329.99 | J18: =SUM(J12:J17) -> 7208.81 | K18: =SUM(K12:K17) -> 1178319 | L18: =SUM(L12:L17) -> 17680 | M18: ='Odometro-Kilometraje'!C81 -> 11745 | N18: =(U18/M18)*100 -> 96.013623 | U18: =SUM(U12:U17) -> 11276.8
A19: =A12+1 -> 45568 | B19: 36 | C19: 47 | D19: ='Data Ocupacion'!H32 -> 36 | E19: ='Data Ocupacion'!I32 -> 48 | F19: PU-LI | G19: =D19+E19*2 -> 132 | H19: =D19+E19 -> 84 | I19: =G19*L$2 -> 5693.16 | J19: =H19*L$2 -> 3622.92 | K19: =I19*104 -> 592088.64 | L19: =H19*104 -> 8736 | P19: 3 | S19: 2 | U19: =I19-((P19*($L$2-$J$1)))-(S19*($J$1)) -> 5589.17
B20: 35 | C20: 44 | D20: ='Data Ocupacion'!H33 -> 36 | E20: ='Data Ocupacion'!I33 -> 43 | F20: LI-PU | G20: =D20+E20*2 -> 122 | H20: =D20+E20 -> 79 | I20: =G20*L$2 -> 5261.86 | J20: =H20*L$2 -> 3407.27 | K20: =I20*104 -> 547233.44 | L20: =H20*104 -> 8216 | U20: =I20-(S20*($L$2-$J$1)+(T20*($L$2-$L$1))) -> 5261.86
B21: 0 | C21: 2 | D21: ='Data Ocupacion'!H34 -> 0 | E21: ='Data Ocupacion'!I34 -> 2 | F21: PU-SA | G21: =D21+E21*2 -> 4 | H21: =D21+E21 -> 2 | I21: =G21*L$1 -> 116.44 | J21: =H21*L$1 -> 58.22 | K21: =I21*104 -> 12109.76 | L21: =H21*104 -> 208 | U21: =I21-(P21*($L$1-$J$1)) -> 116.44
B22: 0 | C22: 3 | D22: ='Data Ocupacion'!H35 -> 0 | E22: ='Data Ocupacion'!I35 -> 3 | F22: SA-PU | G22: =D22+E22*2 -> 6 | H22: =D22+E22 -> 3 | I22: =G22*L$1 -> 174.66 | J22: =H22*L$1 -> 87.33 | K22: =I22*104 -> 18164.64 | L22: =H22*104 -> 312 | U22: =I22 -> 174.66
B23: 0 | C23: 0 | D23: ='Data Ocupacion'!H36 -> 0 | E23: ='Data Ocupacion'!I36 -> 0 | F23: PU-EB | G23: =D23+E23*2 -> 0 | H23: =D23+E23 -> 0 | I23: =G23*J$1 -> 0 | J23: =H23*J$1 -> 0 | K23: =I23*104 -> 0 | L23: =H23*104 -> 0 | U23: =I23 -> 0
B24: 1 | C24: 2 | D24: ='Data Ocupacion'!H37 -> 1 | E24: ='Data Ocupacion'!I37 -> 2 | F24: EB-PU | G24: =D24+E24*2 -> 5 | H24: =D24+E24 -> 3 | I24: =G24*J$1 -> 127 | J24: =H24*J$1 -> 76.2 | K24: =I24*104 -> 13208 | L24: =H24*104 -> 312 | U24: =I24 -> 127
B25: =SUM(B19:B24) -> 72 | C25: =SUM(C19:C24) -> 98 | D25: =SUM(D19:D24) -> 73 | E25: =SUM(E19:E24) -> 98 | G25: =SUM(G19:G24) -> 269 | H25: =SUM(H19:H24) -> 171 | I25: =SUM(I19:I24) -> 11373.12 | J25: =SUM(J19:J24) -> 7251.94 | K25: =SUM(K19:K24) -> 1182804.5 | L25: =SUM(L19:L24) -> 17784 | M25: ='Odometro-Kilometraje'!D81 -> 11781 | N25: =(U25/M25)*100 -> 95.655123 | U25: =SUM(U19:U24) -> 11269.13
A26: =A19+1 -> 45569 | B26: 36 | C26: 47 | D26: ='Data Ocupacion'!J32 -> 33 | E26: ='Data Ocupacion'!K32 -> 50 | F26: PU-LI | G26: =D26+E26*2 -> 133 | H26: =D26+E26 -> 83 | I26: =G26*L$2 -> 5736.29 | J26: =H26*L$2 -> 3579.79 | K26: =I26*104 -> 596574.16 | L26: =H26*104 -> 8632 | P26: 2 | S26: 3 | U26: =I26-((P26*($L$2-$J$1)))-(S26*($J$1)) -> 5624.63
B27: 35 | C27: 44 | D27: ='Data Ocupacion'!J33 -> 35 | E27: ='Data Ocupacion'!K33 -> 44 | F27: LI-PU | G27: =D27+E27*2 -> 123 | H27: =D27+E27 -> 79 | I27: =G27*L$2 -> 5304.99 | J27: =H27*L$2 -> 3407.27 | K27: =I27*104 -> 551718.96 | L27: =H27*104 -> 8216 | U27: =I27-(S27*($L$2-$J$1)+(T27*($L$2-$L$1))) -> 5304.99
B28: 0 | C28: 2 | D28: ='Data Ocupacion'!J34 -> 0 | E28: ='Data Ocupacion'!K34 -> 2 | F28: PU-SA | G28: =D28+E28*2 -> 4 | H28: =D28+E28 -> 2 | I28: =G28*L$1 -> 116.44 | J28: =H28*L$1 -> 58.22 | K28: =I28*104 -> 12109.76 | L28: =H28*104 -> 208 | U28: =I28-(P28*($L$1-$J$1)) -> 116.44
B29: 0 | C29: 3 | D29: ='Data Ocupacion'!J35 -> 0 | E29: ='Data Ocupacion'!K35 -> 3 | F29: SA-PU | G29: =D29+E29*2 -> 6 | H29: =D29+E29 -> 3 | I29: =G29*L$1 -> 174.66 | J29: =H29*L$1 -> 87.33 | K29: =I29*104 -> 18164.64 | L29: =H29*104 -> 312 | U29: =I29 -> 174.66
B30: 0 | C30: 0 | D30: ='Data Ocupacion'!J36 -> 0 | E30: ='Data Ocupacion'!K36 -> 0 | F30: PU-EB | G30: =D30+E30*2 -> 0 | H30: =D30+E30 -> 0 | I30: =G30*J$1 -> 0 | J30: =H30*J$1 -> 0 | K30: =I30*104 -> 0 | L30: =H30*104 -> 0 | U30: =I30 -> 0
B31: 1 | C31: 2 | D31: ='Data Ocupacion'!J37 -> 1 | E31: ='Data Ocupacion'!K37 -> 2 | F31: EB-PU | G31: =D31+E31*2 -> 5 | H31: =D31+E31 -> 3 | I31: =G31*J$1 -> 127 | J31: =H31*J$1 -> 76.2 | K31: =I31*104 -> 13208 | L31: =H31*104 -> 312 | U31: =I31 -> 127
B32: =SUM(B26:B31) -> 72 | C32: =SUM(C26:C31) -> 98 | D32: =SUM(D26:D31) -> 69 | E32: =SUM(E26:E31) -> 101 | G32: =SUM(G26:G31) -> 271 | H32: =SUM(H26:H31) -> 170 | I32: =SUM(I26:I31) -> 11459.38 | J32: =SUM(J26:J31) -> 7208.81 | K32: =SUM(K26:K31) -> 1191775.5 | L32: =SUM(L26:L31) -> 17680 | M32: ='Odometro-Kilometraje'!E81 -> 11884 | N32: =(U32/M32)*100 -> 95.487378 | U32: =SUM(U26:U31) -> 11347.72
A33: =A26+1 -> 45570 | B33: 69 | C33: 3 | D33: ='Data Ocupacion'!L32 -> 69 | E33: ='Data Ocupacion'!M32 -> 3 | F33: PU-LI | G33: =D33+E33*2 -> 75 | H33: =D33+E33 -> 72 | I33: =G33*L$2 -> 3234.75 | J33: =H33*L$2 -> 3105.36 | K33: =I33*104 -> 336414 | L33: =H33*104 -> 7488 | U33: =I33-((P33*($L$2-$J$1)))-(S33*($J$1)) -> 3234.75
B34: 75 | C34: 0 | D34: ='Data Ocupacion'!L33 -> 74 | E34: ='Data Ocupacion'!M33 -> 1 | F34: LI-PU | G34: =D34+E34*2 -> 76 | H34: =D34+E34 -> 75 | I34: =G34*L$2 -> 3277.88 | J34: =H34*L$2 -> 3234.75 | K34: =I34*104 -> 340899.52 | L34: =H34*104 -> 7800 | U34: =I34-(S34*($L$2-$J$1)+(T34*($L$2-$L$1))) -> 3277.88
B35: 0 | C35: 0 | D35: ='Data Ocupacion'!L34 -> 0 | E35: ='Data Ocupacion'!M34 -> 0 | F35: PU-SA | G35: =D35+E35*2 -> 0 | H35: =D35+E35 -> 0 | I35: =G35*L$1 -> 0 | J35: =H35*L$1 -> 0 | K35: =I35*104 -> 0 | L35: =H35*104 -> 0 | U35: =I35-(P35*($L$1-$J$1)) -> 0
B36: 0 | C36: 0 | D36: ='Data Ocupacion'!L35 -> 0 | E36: ='Data Ocupacion'!M35 -> 0 | F36: SA-PU | G36: =D36+E36*2 -> 0 | H36: =D36+E36 -> 0 | I36: =G36*L$1 -> 0 | J36: =H36*L$1 -> 0 | K36: =I36*104 -> 0 | L36: =H36*104 -> 0 | U36: =I36 -> 0
B37: 0 | C37: 0 | D37: ='Data Ocupacion'!L36 -> 0 | E37: ='Data Ocupacion'!M36 -> 0 | F37: PU-EB | G37: =D37+E37*2 -> 0 | H37: =D37+E37 -> 0 | I37: =G37*J$1 -> 0 | J37: =H37*J$1 -> 0 | K37: =I37*104 -> 0 | L37: =H37*104 -> 0 | U37: =I37 -> 0
B38: 0 | C38: 0 | D38: ='Data Ocupacion'!L37 -> 0 | E38: ='Data Ocupacion'!M37 -> 0 | F38: EB-PU | G38: =D38+E38*2 -> 0 | H38: =D38+E38 -> 0 | I38: =G38*J$1 -> 0 | J38: =H38*J$1 -> 0 | K38: =I38*104 -> 0 | L38: =H38*104 -> 0 | U38: =I38 -> 0
B39: =SUM(B33:B38) -> 144 | C39: =SUM(C33:C38) -> 3 | D39: =SUM(D33:D38) -> 143 | E39: =SUM(E33:E38) -> 4 | G39: =SUM(G33:G38) -> 151 | H39: =SUM(H33:H38) -> 147 | I39: =SUM(I33:I38) -> 6512.63 | J39: =SUM(J33:J38) -> 6340.11 | K39: =SUM(K33:K38) -> 677313.52 | L39: =SUM(L33:L38) -> 15288 | M39: ='Odometro-Kilometraje'!F81 -> 6606 | N39: =(U39/M39)*100 -> 98.586588 | U39: =SUM(U33:U38) -> 6512.63
A40: =A33+1 -> 45571 | B40: 51 | C40: 3 | D40: ='Data Ocupacion'!N32 -> 51 | E40: ='Data Ocupacion'!O32 -> 3 | F40: PU-LI | G40: =D40+E40*2 -> 57 | H40: =D40+E40 -> 54 | I40: =G40*L$2 -> 2458.41 | J40: =H40*L$2 -> 2329.02 | K40: =I40*104 -> 255674.64 | L40: =H40*104 -> 5616 | U40: =I40-((P40*($L$2-$J$1)))-(S40*($J$1)) -> 2458.41
...

Sheet Oferta Diaria
A1: Oferta Octubre 2024
C3: 45566 | D3: 45567 | E3: 45568 | F3: 45569 | G3: 45570 | H3: 45571 | I3: 45572 | J3: 45573 | K3: 45574 | L3: 45575 | M3: 45576 | N3: 45577 | O3: 45578 | P3: 45579 | Q3: 45580 | R3: 45581 | S3: 45582 | T3: 45583 | U3: 45584 | V3: 45585 | W3: 45586 | X3: 45587 | Y3: 45588 | Z3: 45589 | AA3: 45590 | AB3: 45591 | AC3: 45592 | AD3: 45593 | AE3: 45594 | AF3: 45595 | AG3: 45596
A4: HÁBIL | B4: km
A5: Servicios PU-LI | B5: 43.13 | C5: ='Data Ocupacion'!D41 -> 83 | D5: ='Data Ocupacion'!F41 -> 83 | E5: ='Data Ocupacion'!H41 -> 84 | F5: ='Data Ocupacion'!J41 -> 83 | G5: ='Data Ocupacion'!L41 -> 72 | H5: ='Data Ocupacion'!N41 -> 54 | I5: ='Data Ocupacion'!P41 -> 83 | J5: ='Data Ocupacion'!R41 -> 83 | K5: ='Data Ocupacion'!T41 -> 83 | L5: ='Data Ocupacion'!V41 -> 83 | M5: ='Data Ocupacion'!X41 -> 83 | N5: ='Data Ocupacion'!Z41 -> 54 | O5: ='Data Ocupacion'!AB41 -> 54 | P5: ='Data Ocupacion'!AD41 -> 83 | Q5: ='Data Ocupacion'!AF41 -> 83 | R5: ='Data Ocupacion'!AH41 -> 83 | S5: ='Data Ocupacion'!AJ41 -> 83 | T5: ='Data Ocupacion'!AL41 -> 83 | U5: ='Data Ocupacion'!AN41 -> 72 | V5: ='Data Ocupacion'!AP41 -> 54 | W5: ='Data Ocupacion'!AR41 -> 83 | X5: ='Data Ocupacion'!AT41 -> 83 | Y5: ='Data Ocupacion'!AV41 -> 83 | Z5: ='Data Ocupacion'!AX41 -> 83 | AA5: ='Data Ocupacion'!AZ41 -> 84 | AB5: ='Data Ocupacion'!BB41 -> 75 | AC5: ='Data Ocupacion'!BD41 -> 74 | AD5: ='Data Ocupacion'!BF41 -> 83 | AE5: ='Data Ocupacion'!BH41 -> 83 | AF5: ='Data Ocupacion'!BJ41 -> 83 | AG5: ='Data Ocupacion'!BL41 -> 54
A6: Servicios LI-PU | B6: 43.13 | C6: ='Data Ocupacion'!D42 -> 79 | D6: ='Data Ocupacion'!F42 -> 79 | E6: ='Data Ocupacion'!H42 -> 79 | F6: ='Data Ocupacion'!J42 -> 79 | G6: ='Data Ocupacion'!L42 -> 75 | H6: ='Data Ocupacion'!N42 -> 57 | I6: ='Data Ocupacion'!P42 -> 79 | J6: ='Data Ocupacion'!R42 -> 79 | K6: ='Data Ocupacion'!T42 -> 79 | L6: ='Data Ocupacion'!V42 -> 79 | M6: ='Data Ocupacion'!X42 -> 79 | N6: ='Data Ocupacion'!Z42 -> 57 | O6: ='Data Ocupacion'!AB42 -> 57 | P6: ='Data Ocupacion'!AD42 -> 79 | Q6: ='Data Ocupacion'!AF42 -> 79 | R6: ='Data Ocupacion'!AH42 -> 79 | S6: ='Data Ocupacion'!AJ42 -> 79 | T6: ='Data Ocupacion'!AL42 -> 79 | U6: ='Data Ocupacion'!AN42 -> 75 | V6: ='Data Ocupacion'!AP42 -> 57 | W6: ='Data Ocupacion'!AR42 -> 79 | X6: ='Data Ocupacion'!AT42 -> 79 | Y6: ='Data Ocupacion'!AV42 -> 79 | Z6: ='Data Ocupacion'!AX42 -> 79 | AA6: ='Data Ocupacion'!AZ42 -> 79 | AB6: ='Data Ocupacion'!BB42 -> 75 | AC6: ='Data Ocupacion'!BD42 -> 74 | AD6: ='Data Ocupacion'!BF42 -> 79 | AE6: ='Data Ocupacion'!BH42 -> 79 | AF6: ='Data Ocupacion'!BJ42 -> 79 | AG6: ='Data Ocupacion'!BL42 -> 57
A7: Servicios PU-SA | B7: 29.11 | C7: ='Data Ocupacion'!D43 -> 2 | D7: ='Data Ocupacion'!F43 -> 2 | E7: ='Data Ocupacion'!H43 -> 2 | F7: ='Data Ocupacion'!J43 -> 2 | G7: ='Data Ocupacion'!L43 -> 0 | H7: ='Data Ocupacion'!N43 -> 0 | I7: ='Data Ocupacion'!P43 -> 2 | J7: ='Data Ocupacion'!R43 -> 2 | K7: ='Data Ocupacion'!T43 -> 2 | L7: ='Data Ocupacion'!V43 -> 2 | M7: ='Data Ocupacion'!X43 -> 2 | N7: ='Data Ocupacion'!Z43 -> 0 | O7: ='Data Ocupacion'!AB43 -> 0 | P7: ='Data Ocupacion'!AD43 -> 2 | Q7: ='Data Ocupacion'!AF43 -> 2 | R7: ='Data Ocupacion'!AH43 -> 2 | S7: ='Data Ocupacion'!AJ43 -> 2 | T7: ='Data Ocupacion'!AL43 -> 2 | U7: ='Data Ocupacion'!AN43 -> 0 | V7: ='Data Ocupacion'!AP43 -> 0 | W7: ='Data Ocupacion'!AR43 -> 2 | X7: ='Data Ocupacion'!AT43 -> 2 | Y7: ='Data Ocupacion'!AV43 -> 2 | Z7: ='Data Ocupacion'!AX43 -> 2 | AA7: ='Data Ocupacion'!AZ43 -> 2 | AB7: ='Data Ocupacion'!BB43 -> 0 | AC7: ='Data Ocupacion'!BD43 -> 0 | AD7: ='Data Ocupacion'!BF43 -> 2 | AE7: ='Data Ocupacion'!BH43 -> 2 | AF7: ='Data Ocupacion'!BJ43 -> 2 | AG7: ='Data Ocupacion'!BL43 -> 0
A8: Servicios SA-PU | B8: 29.11 | C8: ='Data Ocupacion'!D44 -> 3 | D8: ='Data Ocupacion'!F44 -> 3 | E8: ='Data Ocupacion'!H44 -> 3 | F8: ='Data Ocupacion'!J44 -> 3 | G8: ='Data Ocupacion'!L44 -> 0 | H8: ='Data Ocupacion'!N44 -> 0 | I8: ='Data Ocupacion'!P44 -> 3 | J8: ='Data Ocupacion'!R44 -> 3 | K8: ='Data Ocupacion'!T44 -> 3 | L8: ='Data Ocupacion'!V44 -> 3 | M8: ='Data Ocupacion'!X44 -> 3 | N8: ='Data Ocupacion'!Z44 -> 0 | O8: ='Data Ocupacion'!AB44 -> 0 | P8: ='Data Ocupacion'!AD44 -> 3 | Q8: ='Data Ocupacion'!AF44 -> 3 | R8: ='Data Ocupacion'!AH44 -> 3 | S8: ='Data Ocupacion'!AJ44 -> 3 | T8: ='Data Ocupacion'!AL44 -> 3 | U8: ='Data Ocupacion'!AN44 -> 0 | V8: ='Data Ocupacion'!AP44 -> 0 | W8: ='Data Ocupacion'!AR44 -> 3 | X8: ='Data Ocupacion'!AT44 -> 3 | Y8: ='Data Ocupacion'!AV44 -> 3 | Z8: ='Data Ocupacion'!AX44 -> 3 | AA8: ='Data Ocupacion'!AZ44 -> 3 | AB8: ='Data Ocupacion'!BB44 -> 0 | AC8: ='Data Ocupacion'!BD44 -> 0 | AD8: ='Data Ocupacion'!BF44 -> 3 | AE8: ='Data Ocupacion'!BH44 -> 3 | AF8: ='Data Ocupacion'!BJ44 -> 3 | AG8: ='Data Ocupacion'!BL44 -> 0
A9: Servicios PU-EB | B9: 25.4 | C9: ='Data Ocupacion'!D45 -> 0 | D9: ='Data Ocupacion'!F45 -> 0 | E9: ='Data Ocupacion'!H45 -> 0 | F9: ='Data Ocupacion'!J45 -> 0 | G9: ='Data Ocupacion'!L45 -> 0 | H9: ='Data Ocupacion'!N45 -> 0 | I9: ='Data Ocupacion'!P45 -> 0 | J9: ='Data Ocupacion'!R45 -> 0 | K9: ='Data Ocupacion'!T45 -> 0 | L9: ='Data Ocupacion'!V45 -> 0 | M9: ='Data Ocupacion'!X45 -> 0 | N9: ='Data Ocupacion'!Z45 -> 0 | O9: ='Data Ocupacion'!AB45 -> 0 | P9: ='Data Ocupacion'!AD45 -> 0 | Q9: ='Data Ocupacion'!AF45 -> 0 | R9: ='Data Ocupacion'!AH45 -> 0 | S9: ='Data Ocupacion'!AJ45 -> 0 | T9: ='Data Ocupacion'!AL45 -> 0 | U9: ='Data Ocupacion'!AN45 -> 0 | V9: ='Data Ocupacion'!AP45 -> 0 | W9: ='Data Ocupacion'!AR45 -> 0 | X9: ='Data Ocupacion'!AT45 -> 0 | Y9: ='Data Ocupacion'!AV45 -> 0 | Z9: ='Data Ocupacion'!AX45 -> 0 | AA9: ='Data Ocupacion'!AZ45 -> 0 | AB9: ='Data Ocupacion'!BB45 -> 0 | AC9: ='Data Ocupacion'!BD45 -> 0 | AD9: ='Data Ocupacion'!BF45 -> 0 | AE9: ='Data Ocupacion'!BH45 -> 0 | AF9: ='Data Ocupacion'!BJ45 -> 0 | AG9: ='Data Ocupacion'!BL45 -> 0
A10: Servicios EB-PU | B10: 25.4 | C10: ='Data Ocupacion'!D46 -> 3 | D10: ='Data Ocupacion'!F46 -> 3 | E10: ='Data Ocupacion'!H46 -> 3 | F10: ='Data Ocupacion'!J46 -> 3 | G10: ='Data Ocupacion'!L46 -> 0 | H10: ='Data Ocupacion'!N46 -> 0 | I10: ='Data Ocupacion'!P46 -> 3 | J10: ='Data Ocupacion'!R46 -> 3 | K10: ='Data Ocupacion'!T46 -> 3 | L10: ='Data Ocupacion'!V46 -> 3 | M10: ='Data Ocupacion'!X46 -> 3 | N10: ='Data Ocupacion'!Z46 -> 0 | O10: ='Data Ocupacion'!AB46 -> 0 | P10: ='Data Ocupacion'!AD46 -> 3 | Q10: ='Data Ocupacion'!AF46 -> 3 | R10: ='Data Ocupacion'!AH46 -> 3 | S10: ='Data Ocupacion'!AJ46 -> 3 | T10: ='Data Ocupacion'!AL46 -> 3 | U10: ='Data Ocupacion'!AN46 -> 0 | V10: ='Data Ocupacion'!AP46 -> 0 | W10: ='Data Ocupacion'!AR46 -> 3 | X10: ='Data Ocupacion'!AT46 -> 3 | Y10: ='Data Ocupacion'!AV46 -> 3 | Z10: ='Data Ocupacion'!AX46 -> 3 | AA10: ='Data Ocupacion'!AZ46 -> 3 | AB10: ='Data Ocupacion'!BB46 -> 0 | AC10: ='Data Ocupacion'!BD46 -> 0 | AD10: ='Data Ocupacion'!BF46 -> 3 | AE10: ='Data Ocupacion'!BH46 -> 3 | AF10: ='Data Ocupacion'!BJ46 -> 3 | AG10: ='Data Ocupacion'!BL46 -> 0
A11: Servicios PU-ES | B11: 11.7
A12: Servicios ES-PU | B12: 11.7
A13: Servicios LI-QU | B13: 21.7
A14: Servicios QU-LI | B14: 21.7
A16: Trenes PU-LI | B16: 43.13 | C16: ='Data Ocupacion'!D49 -> 131 | D16: ='Data Ocupacion'!F49 -> 130 | E16: ='Data Ocupacion'!H49 -> 132 | F16: ='Data Ocupacion'!J49 -> 133 | G16: ='Data Ocupacion'!L49 -> 75 | H16: ='Data Ocupacion'!N49 -> 57 | I16: ='Data Ocupacion'!P49 -> 130 | J16: ='Data Ocupacion'!R49 -> 130 | K16: ='Data Ocupacion'!T49 -> 130 | L16: ='Data Ocupacion'!V49 -> 130 | M16: ='Data Ocupacion'!X49 -> 130 | N16: ='Data Ocupacion'!Z49 -> 56 | O16: ='Data Ocupacion'!AB49 -> 56 | P16: ='Data Ocupacion'!AD49 -> 131 | Q16: ='Data Ocupacion'!AF49 -> 131 | R16: ='Data Ocupacion'!AH49 -> 131 | S16: ='Data Ocupacion'!AJ49 -> 131 | T16: ='Data Ocupacion'!AL49 -> 130 | U16: ='Data Ocupacion'!AN49 -> 75 | V16: ='Data Ocupacion'!AP49 -> 57 | W16: ='Data Ocupacion'!AR49 -> 130 | X16: ='Data Ocupacion'!AT49 -> 130 | Y16: ='Data Ocupacion'!AV49 -> 130 | Z16: ='Data Ocupacion'!AX49 -> 130 | AA16: ='Data Ocupacion'!AZ49 -> 130 | AB16: ='Data Ocupacion'!BB49 -> 91 | AC16: ='Data Ocupacion'!BD49 -> 92 | AD16: ='Data Ocupacion'!BF49 -> 129 | AE16: ='Data Ocupacion'!BH49 -> 128 | AF16: ='Data Ocupacion'!BJ49 -> 129 | AG16: ='Data Ocupacion'!BL49 -> 57
A17: Trenes LI-PU | B17: 43.13 | C17: ='Data Ocupacion'!D50 -> 124 | D17: ='Data Ocupacion'!F50 -> 123 | E17: ='Data Ocupacion'!H50 -> 122 | F17: ='Data Ocupacion'!J50 -> 123 | G17: ='Data Ocupacion'!L50 -> 76 | H17: ='Data Ocupacion'!N50 -> 57 | I17: ='Data Ocupacion'!P50 -> 123 | J17: ='Data Ocupacion'!R50 -> 123 | K17: ='Data Ocupacion'!T50 -> 123 | L17: ='Data Ocupacion'!V50 -> 123 | M17: ='Data Ocupacion'!X50 -> 123 | N17: ='Data Ocupacion'!Z50 -> 57 | O17: ='Data Ocupacion'!AB50 -> 57 | P17: ='Data Ocupacion'!AD50 -> 123 | Q17: ='Data Ocupacion'!AF50 -> 123 | R17: ='Data Ocupacion'!AH50 -> 123 | S17: ='Data Ocupacion'!AJ50 -> 123 | T17: ='Data Ocupacion'!AL50 -> 123 | U17: ='Data Ocupacion'!AN50 -> 75 | V17: ='Data Ocupacion'!AP50 -> 57 | W17: ='Data Ocupacion'!AR50 -> 123 | X17: ='Data Ocupacion'!AT50 -> 123 | Y17: ='Data Ocupacion'!AV50 -> 123 | Z17: ='Data Ocupacion'!AX50 -> 123 | AA17: ='Data Ocupacion'!AZ50 -> 124 | AB17: ='Data Ocupacion'!BB50 -> 93 | AC17: ='Data Ocupacion'!BD50 -> 92 | AD17: ='Data Ocupacion'!BF50 -> 121 | AE17: ='Data Ocupacion'!BH50 -> 121 | AF17: ='Data Ocupacion'!BJ50 -> 122 | AG17: ='Data Ocupacion'!BL50 -> 57
A18: Trenes PU-SA | B18: 29.11 | C18: ='Data Ocupacion'!D51 -> 4 | D18: ='Data Ocupacion'!F51 -> 4 | E18: ='Data Ocupacion'!H51 -> 4 | F18: ='Data Ocupacion'!J51 -> 4 | G18: ='Data Ocupacion'!L51 -> 0 | H18: ='Data Ocupacion'!N51 -> 0 | I18: ='Data Ocupacion'!P51 -> 4 | J18: ='Data Ocupacion'!R51 -> 4 | K18: ='Data Ocupacion'!T51 -> 4 | L18: ='Data Ocupacion'!V51 -> 4 | M18: ='Data Ocupacion'!X51 -> 4 | N18: ='Data Ocupacion'!Z51 -> 0 | O18: ='Data Ocupacion'!AB51 -> 0 | P18: ='Data Ocupacion'!AD51 -> 4 | Q18: ='Data Ocupacion'!AF51 -> 4 | R18: ='Data Ocupacion'!AH51 -> 4 | S18: ='Data Ocupacion'!AJ51 -> 4 | T18: ='Data Ocupacion'!AL51 -> 4 | U18: ='Data Ocupacion'!AN51 -> 0 | V18: ='Data Ocupacion'!AP51 -> 0 | W18: ='Data Ocupacion'!AR51 -> 4 | X18: ='Data Ocupacion'!AT51 -> 4 | Y18: ='Data Ocupacion'!AV51 -> 4 | Z18: ='Data Ocupacion'!AX51 -> 4 | AA18: ='Data Ocupacion'!AZ51 -> 4 | AB18: ='Data Ocupacion'!BB51 -> 0 | AC18: ='Data Ocupacion'!BD51 -> 0 | AD18: ='Data Ocupacion'!BF51 -> 4 | AE18: ='Data Ocupacion'!BH51 -> 4 | AF18: ='Data Ocupacion'!BJ51 -> 4 | AG18: ='Data Ocupacion'!BL51 -> 0
A19: Trenes SA-PU | B19: 29.11 | C19: ='Data Ocupacion'!D52 -> 6 | D19: ='Data Ocupacion'!F52 -> 6 | E19: ='Data Ocupacion'!H52 -> 6 | F19: ='Data Ocupacion'!J52 -> 6 | G19: ='Data Ocupacion'!L52 -> 0 | H19: ='Data Ocupacion'!N52 -> 0 | I19: ='Data Ocupacion'!P52 -> 6 | J19: ='Data Ocupacion'!R52 -> 6 | K19: ='Data Ocupacion'!T52 -> 6 | L19: ='Data Ocupacion'!V52 -> 6 | M19: ='Data Ocupacion'!X52 -> 6 | N19: ='Data Ocupacion'!Z52 -> 0 | O19: ='Data Ocupacion'!AB52 -> 0 | P19: ='Data Ocupacion'!AD52 -> 6 | Q19: ='Data Ocupacion'!AF52 -> 6 | R19: ='Data Ocupacion'!AH52 -> 6 | S19: ='Data Ocupacion'!AJ52 -> 6 | T19: ='Data Ocupacion'!AL52 -> 6 | U19: ='Data Ocupacion'!AN52 -> 0 | V19: ='Data Ocupacion'!AP52 -> 0 | W19: ='Data Ocupacion'!AR52 -> 6 | X19: ='Data Ocupacion'!AT52 -> 6 | Y19: ='Data Ocupacion'!AV52 -> 6 | Z19: ='Data Ocupacion'!AX52 -> 6 | AA19: ='Data Ocupacion'!AZ52 -> 6 | AB19: ='Data Ocupacion'!BB52 -> 0 | AC19: ='Data Ocupacion'!BD52 -> 0 | AD19: ='Data Ocupacion'!BF52 -> 6 | AE19: ='Data Ocupacion'!BH52 -> 6 | AF19: ='Data Ocupacion'!BJ52 -> 6 | AG19: ='Data Ocupacion'!BL52 -> 0
A20: Trenes EB-PU | B20: 25.4 | C20: ='Data Ocupacion'!D54 -> 5 | D20: ='Data Ocupacion'!F54 -> 5 | E20: ='Data Ocupacion'!H54 -> 5 | F20: ='Data Ocupacion'!J54 -> 5 | G20: ='Data Ocupacion'!L54 -> 0 | H20: ='Data Ocupacion'!N54 -> 0 | I20: ='Data Ocupacion'!P54 -> 5 | J20: ='Data Ocupacion'!R54 -> 5 | K20: ='Data Ocupacion'!T54 -> 5 | L20: ='Data Ocupacion'!V54 -> 5 | M20: ='Data Ocupacion'!X54 -> 5 | N20: ='Data Ocupacion'!Z54 -> 0 | O20: ='Data Ocupacion'!AB54 -> 0 | P20: ='Data Ocupacion'!AD54 -> 5 | Q20: ='Data Ocupacion'!AF54 -> 5 | R20: ='Data Ocupacion'!AH54 -> 5 | S20: ='Data Ocupacion'!AJ54 -> 5 | T20: ='Data Ocupacion'!AL54 -> 5 | U20: ='Data Ocupacion'!AN54 -> 0 | V20: ='Data Ocupacion'!AP54 -> 0 | W20: ='Data Ocupacion'!AR54 -> 5 | X20: ='Data Ocupacion'!AT54 -> 5 | Y20: ='Data Ocupacion'!AV54 -> 5 | Z20: ='Data Ocupacion'!AX54 -> 5 | AA20: ='Data Ocupacion'!AZ54 -> 4 | AB20: ='Data Ocupacion'!BB54 -> 0 | AC20: ='Data Ocupacion'!BD54 -> 0 | AD20: ='Data Ocupacion'!BF54 -> 5 | AE20: ='Data Ocupacion'!BH54 -> 5 | AF20: ='Data Ocupacion'!BJ54 -> 5 | AG20: ='Data Ocupacion'!BL53 -> 0
A21: Trenes PU-EB | B21: 25.4 | C21: 0 | D21: 0 | E21: 0 | F21: 0 | G21: 0 | H21: ='Data Ocupacion'!N53 -> 0 | I21: ='Data Ocupacion'!P53 -> 0 | J21: ='Data Ocupacion'!R53 -> 0 | K21: ='Data Ocupacion'!T53 -> 0 | L21: 0 | M21: 0 | N21: 0 | O21: 0 | P21: 0 | Q21: 0 | R21: 0 | S21: 0 | T21: 0 | U21: 0 | V21: 0 | W21: 0 | X21: 0 | Y21: 0 | Z21: 0 | AA21: 0 | AB21: 0 | AC21: 0 | AD21: 0 | AE21: 0 | AF21: 0 | AG21: ='Data Ocupacion'!BL54 -> 0
A22: Trenes PU-ES | B22: 11.7
A23: Trenes ES-PU | B23: 11.7
A24: Trenes LI-QU | B24: 21.7
A25: Trenes QU-LI | B25: 21.7
A27: Corte EB (600) | B27: -17.73 | C27: ='KM-Servicio'!P5 -> 5 | D27: ='KM-Servicio'!P12 -> 3 | E27: ='KM-Servicio'!P19 -> 3 | F27: ='KM-Servicio'!P26 -> 2 | G27: ='KM-Servicio'!P33 -> 0 | H27: ='KM-Servicio'!P40 -> 0 | I27: ='KM-Servicio'!P47 -> 0 | J27: ='KM-Servicio'!P54 -> 0 | K27: ='KM-Servicio'!P61 -> 0 | L27: ='KM-Servicio'!P68 -> 3 | M27: ='KM-Servicio'!P75 -> 0 | N27: ='KM-Servicio'!P82 -> 0 | O27: ='KM-Servicio'!P89 -> 0 | P27: ='KM-Servicio'!P96 -> 5 | Q27: ='KM-Servicio'!P103 -> 5 | R27: ='KM-Servicio'!P110 -> 4 | S27: ='KM-Servicio'!P117 -> 5 | T27: ='KM-Servicio'!P124 -> 6 | U27: ='KM-Servicio'!P131 -> 0 | V27: ='KM-Servicio'!P138 -> 0 | W27: ='KM-Servicio'!P145 -> 8 | X27: ='KM-Servicio'!P152 -> 4 | Y27: ='KM-Servicio'!P159 -> 0 | Z27: ='KM-Servicio'!P166 -> 4 | AA27: ='KM-Servicio'!P173 -> 5 | AB27: ='KM-Servicio'!P180 -> 3 | AC27: ='KM-Servicio'!P187 -> 6 | AD27: ='KM-Servicio'!P194 -> 5 | AE27: ='KM-Servicio'!P201 -> 6 | AF27: ='KM-Servicio'!AO33 -> 0 | AG27: ='KM-Servicio'!AP33 -> 0
A28: Acople EB (600) | B28: -17.73 | C28: ='KM-Servicio'!S6 -> 0 | D28: ='KM-Servicio'!S13 -> 0 | E28: ='KM-Servicio'!S20 -> 0 | F28: ='KM-Servicio'!S27 -> 0 | G28: ='KM-Servicio'!S34 -> 0 | H28: ='KM-Servicio'!S40 -> 0 | I28: ='KM-Servicio'!S48 -> 0 | J28: ='KM-Servicio'!S55 -> 0 | K28: ='KM-Servicio'!S62 -> 0 | L28: ='KM-Servicio'!S69 -> 0 | M28: ='KM-Servicio'!S76 -> 0 | N28: ='KM-Servicio'!S83 -> 0 | O28: ='KM-Servicio'!S90 -> 0 | P28: ='KM-Servicio'!S97 -> 0 | Q28: ='KM-Servicio'!S104 -> 2 | R28: ='KM-Servicio'!S111 -> 0 | S28: ='KM-Servicio'!S118 -> 2 | T28: ='KM-Servicio'!S125 -> 2 | U28: ='KM-Servicio'!S132 -> 0 | V28: ='KM-Servicio'!S139 -> 0 | W28: ='KM-Servicio'!S146 -> 1 | X28: ='KM-Servicio'!S153 -> 1 | Y28: ='KM-Servicio'!S160 -> 0 | Z28: ='KM-Servicio'!S167 -> 1 | AA28: ='KM-Servicio'!S174 -> 1 | AB28: ='KM-Servicio'!S181 -> 0 | AC28: ='KM-Servicio'!S188 -> 0 | AD28: ='KM-Servicio'!S195 -> 0 | AE28: ='KM-Servicio'!S202 -> 0 | AF28: ='KM-Servicio'!AR34 -> 0 | AG28: ='KM-Servicio'!AS34 -> 0
A29: Acople/Corte SA (600) | B29: -14.02 | C29: ='KM-Servicio'!T6 -> 0 | D29: ='KM-Servicio'!T13 -> 0 | E29: ='KM-Servicio'!T20 -> 0 | F29: ='KM-Servicio'!T27 -> 0 | G29: ='KM-Servicio'!T34 -> 0 | H29: ='KM-Servicio'!T40 -> 0 | I29: ='KM-Servicio'!T48 -> 0 | J29: ='KM-Servicio'!T55 -> 0 | K29: ='KM-Servicio'!T62 -> 0 | L29: ='KM-Servicio'!T69 -> 0 | M29: ='KM-Servicio'!T76 -> 0 | N29: ='KM-Servicio'!T83 -> 0 | O29: ='KM-Servicio'!T90 -> 0 | P29: ='KM-Servicio'!T97 -> 0 | Q29: ='KM-Servicio'!T104 -> 0 | R29: ='KM-Servicio'!T111 -> 0 | S29: ='KM-Servicio'!T118 -> 0 | T29: ='KM-Servicio'!T125 -> 0 | U29: ='KM-Servicio'!T132 -> 0 | V29: ='KM-Servicio'!T139 -> 0 | W29: ='KM-Servicio'!T146 -> 0 | X29: ='KM-Servicio'!T153 -> 0 | Y29: ='KM-Servicio'!T160 -> 0 | Z29: ='KM-Servicio'!T167 -> 0 | AA29: ='KM-Servicio'!T174 -> 0 | AB29: ='KM-Servicio'!T181 -> 0 | AC29: ='KM-Servicio'!T188 -> 0 | AD29: ='KM-Servicio'!T195 -> 0 | AE29: ='KM-Servicio'!T202 -> 0 | AF29: ='KM-Servicio'!AS34 -> 0 | AG29: ='KM-Servicio'!AT34 -> 0
A30: Corte EB (400) | B30: -3.71 | C30: 1 | AA30: 1
A31: Acople EB (600) vía 1 | B31: -25.4 | E31: 2 | F31: 3 | I31: 1 | J31: 1 | K31: 1 | L31: 1 | M31: 2 | P31: 1 | Q31: 1 | R31: 1 | W31: 2 | X31: 1 | Y31: 1
A32: Corte PE (600) vía 1 | B32: -12.73
A33: Corte PE (600) | B33: -12.73
A34: Corte EB (600) vía 2 | B34: -25.4
A36: Servicios | B36: =SUM(C36:AG36) -> 4889 | C36: =SUM(C5:C14) -> 170 | D36: =SUM(D5:D14) -> 170 | E36: =SUM(E5:E10) -> 171 | F36: =SUM(F5:F10) -> 170 | G36: =SUM(G5:G10) -> 147 | H36: =SUM(H5:H10) -> 111 | I36: =SUM(I5:I10) -> 170 | J36: =SUM(J5:J10) -> 170 | K36: =SUM(K5:K14) -> 170 | L36: =SUM(L5:L10) -> 170 | M36: =SUM(M5:M10) -> 170 | N36: =SUM(N5:N10) -> 111 | O36: =SUM(O5:O10) -> 111 | P36: =SUM(P5:P10) -> 170 | Q36: =SUM(Q5:Q10) -> 170 | R36: =SUM(R5:R10) -> 170 | S36: =SUM(S5:S14) -> 170 | T36: =SUM(T5:T10) -> 170 | U36: =SUM(U5:U14) -> 147 | V36: =SUM(V5:V14) -> 111 | W36: =SUM(W5:W14) -> 170 | X36: =SUM(X5:X14) -> 170 | Y36: =SUM(Y5:Y10) -> 170 | Z36: =SUM(Z5:Z10) -> 170 | AA36: =SUM(AA5:AA10) -> 171 | AB36: =SUM(AB5:AB14) -> 150 | AC36: =SUM(AC5:AC14) -> 148 | AD36: =SUM(AD5:AD14) -> 170 | AE36: =SUM(AE5:AE14) -> 170 | AF36: =SUM(AF5:AF14) -> 170 | AG36: =SUM(AG5:AG14) -> 111
A37: Trenes | B37: =SUM(C37:AG37) -> 7134 | C37: =SUM(C16:C25) -> 270 | D37: =SUM(D16:D25) -> 268 | E37: =SUM(E16:E21) -> 269 | F37: =SUM(F16:F21) -> 271 | G37: =SUM(G16:G21) -> 151 | H37: =SUM(H16:H21) -> 114 | I37: =SUM(I16:I21) -> 268 | J37: =SUM(J16:J21) -> 268 | K37: =SUM(K16:K23) -> 268 | L37: =SUM(L16:L21) -> 268 | M37: =SUM(M16:M21) -> 268 | N37: =SUM(N16:N21) -> 113 | O37: =SUM(O16:O21) -> 113 | P37: =SUM(P16:P21) -> 269 | Q37: =SUM(Q16:Q21) -> 269 | R37: =SUM(R16:R21) -> 269 | S37: =SUM(S16:S25) -> 269 | T37: =SUM(T16:T21) -> 268 | U37: =SUM(U16:U25) -> 150 | V37: =SUM(V16:V25) -> 114 | W37: =SUM(W16:W25) -> 268 | X37: =SUM(X16:X25) -> 268 | Y37: =SUM(Y16:Y21) -> 268 | Z37: =SUM(Z16:Z21) -> 268 | AA37: =SUM(AA16:AA21) -> 268 | AB37: =SUM(AB16:AB25) -> 184 | AC37: =SUM(AC16:AC25) -> 184 | AD37: =SUM(AD16:AD25) -> 265 | AE37: =SUM(AE16:AE25) -> 264 | AF37: =SUM(AF16:AF25) -> 266 | AG37: =SUM(AG16:AG25) -> 114
A38: Trenes KM | B38: =SUM(C38:AG38) -> 300576.67 | C38: =(C16*$B$16+C17*$B$17+C18*$B$18+C19*$B$19+C21*$B$21+C24*B24+C25*B25+C28*$B$28+C20*$B$20+C27*$B$27+C29*B29+C31*B31+C30*B30) -> 11323.89 | D38: =(D16*$B$16+D17*$B$17+D18*$B$18+D19*$B$19+D21*$B$21+D24*B24+D25*B25+D28*$B$28+D20*$B$20+D27*$B$27+D29*B29+D31*B31) -> 11276.8 | E38: =(E16*$B$16+E17*$B$17+E18*$B$18+E19*$B$19+E21*$B$21+E24*B24+E25*B25+E28*$B$28+E20*$B$20+E27*$B$27+E29*B29+E31*B31) -> 11269.13 | F38: =(F16*$B$16+F17*$B$17+F18*$B$18+F19*$B$19+F21*$B$21+F24*B24+F25*B25+F28*$B$28+F20*$B$20+F27*$B$27+F29*B29+F31*B31) -> 11347.72 | G38: =(G16*$B$16+G17*$B$17+G18*$B$18+G19*$B$19+G21*$B$21+G24*B24+G25*B25+G28*$B$28+G20*$B$20+G27*$B$27+G29*B29+G31*B31) -> 6512.63 | H38: =(H16*$B$16+H17*$B$17+H18*$B$18+H19*$B$19+H21*$B$21+H24*B24+H25*B25+H28*$B$28+H20*$B$20+H27*$B$27+H29*B29+H31*B31) -> 4916.82 | I38: =(I16*$B$16+I17*$B$17+I18*$B$18+I19*$B$19+I21*$B$21+I28*$B$28+I20*$B$20+I27*$B$27+I29*B29+I30*B30+I31*B31) -> 11304.59 | J38: =(J16*$B$16+J17*$B$17+J18*$B$18+J19*$B$19+J21*$B$21+J28*$B$28+J20*$B$20+J27*$B$27+J29*B29+J30*B30+J31*B31) -> 11304.59 | K38: =(K16*$B$16+K17*$B$17+K18*$B$18+K19*$B$19+K21*$B$21+K28*$B$28+K20*$B$20+K27*$B$27+K29*B29+K30*B30+K31*B31) -> 11304.59 | L38: =(L16*$B$16+L17*$B$17+L18*$B$18+L19*$B$19+L21*$B$21+L28*$B$28+L20*$B$20+L27*$B$27+L29*B29+L30*B30+L31*B31) -> 11251.4 | M38: =(M16*$B$16+M17*$B$17+M18*$B$18+M19*$B$19+M21*$B$21+M28*$B$28+M20*$B$20+M27*$B$27+M31*B31) -> 11279.19 | N38: =(N16*$B$16+N17*$B$17+N18*$B$18+N19*$B$19+N21*$B$21+N28*$B$28+N20*$B$20+N27*$B$27+N29*B29+N30*B30+N31*B31) -> 4873.69 | O38: =(O16*$B$16+O17*$B$17+O18*$B$18+O19*$B$19+O21*$B$21+O28*$B$28+O20*$B$20+O27*$B$27+O31*B31) -> 4873.69 | P38: =(P16*$B$16+P17*$B$17+P18*$B$18+P19*$B$19+P21*$B$21+P28*$B$28+P20*$B$20+P27*$B$27+P31*B31) -> 11259.07 | Q38: =(Q16*$B$16+Q17*$B$17+Q18*$B$18+Q19*$B$19+Q21*$B$21+Q28*$B$28+Q20*$B$20+Q27*$B$27+Q31*B31) -> 11223.61 | R38: =(R16*$B$16+R17*$B$17+R18*$B$18+R19*$B$19+R21*$B$21+R28*$B$28+R20*$B$20+R27*$B$27+R31*B31) -> 11276.8 | S38: =(S16*$B$16+S17*$B$17+S18*$B$18+S19*$B$19+S21*$B$21+S28*$B$28+S20*$B$20+S27*$B$27+S31*$B$31+S22*B22+S23*B23+S24*B24+S25*B25) -> 11249.01 | T38: =(T16*$B$16+T17*$B$17+T18*$B$18+T19*$B$19+T21*$B$21+T28*$B$28+T20*$B$20+T27*$B$27+T31*$B$31) -> 11188.15 | U38: =(U16*$B$16+U17*$B$17+U18*$B$18+U19*$B$19+U21*$B$21+U28*$B$28+U20*$B$20+U27*$B$27+U31*$B$31+U22*B22+U23*B23+U24*B24+U25*B25) -> 6469.5 | V38: =(V16*$B$16+V17*$B$17+V18*$B$18+V19*$B$19+V21*$B$21+V28*$B$28+V20*$B$20+V27*$B$27+V31*$B$31+V22*B22+V23*B23+V24*B24+V25*B25) -> 4916.82 | W38: =(W16*$B$16+W17*$B$17+W18*$B$18+W19*$B$19+W21*$B$21+W28*$B$28+W20*$B$20+W27*$B$27+W31*$B$31+W22*B22+W23*B23+W24*B24+W25*B25) -> 11119.62 | X38: =(X16*$B$16+X17*$B$17+X18*$B$18+X19*$B$19+X21*$B$21+X28*$B$28+X20*$B$20+X27*$B$27+X31*$B$31+X22*B22+X23*B23+X24*B24+X25*B25) -> 11215.94 | Y38: =(Y16*$B$16+Y17*$B$17+Y18*$B$18+Y19*$B$19+Y21*$B$21+Y28*$B$28+Y20*$B$20+Y27*$B$27+Y31*$B$31) -> 11304.59 | Z38: =(Z16*$B$16+Z17*$B$17+Z18*$B$18+Z19*$B$19+Z21*$B$21+Z28*$B$28+Z20*$B$20+Z27*$B$27+Z31*$B$31) -> 11241.34 | AA38: =(AA16*$B$16+AA17*$B$17+AA18*$B$18+AA19*$B$19+AA21*$B$21+AA28*$B$28+AA20*$B$20+AA27*$B$27+AA31*$B$31+AA30*B30) -> 11237.63 | AB38: =(AB16*$B$16+AB17*$B$17+AB18*$B$18+AB19*$B$19+AB21*$B$21+AB28*$B$28+AB20*$B$20+AB27*$B$27+AB31*$B$31) -> 7882.73 | AC38: =(AC16*$B$16+AC17*$B$17+AC18*$B$18+AC19*$B$19+AC21*$B$21+AC28*$B$28+AC20*$B$20+AC27*$B$27+AC31*$B$31) -> 7829.54 | AD38: =(AD16*$B$16+AD17*$B$17+AD18*$B$18+AD19*$B$19+AD21*$B$21+AD28*$B$28+AD20*$B$20+AD27*$B$27+AD31*$B$31) -> 11111.95 | AE38: =(AE16*$B$16+AE17*$B$17+AE18*$B$18+AE19*$B$19+AE21*$B$21+AE28*$B$28+AE20*$B$20+AE27*$B$27+AE31*$B$31) -> 11051.09 | AF38: =(AF16*$B$16+AF17*$B$17+AF18*$B$18+AF19*$B$19+AF21*$B$21+AF28*$B$28+AF20*$B$20+AF27*$B$27+AF31*$B$31) -> 11243.73 | AG38: =(AG16*$B$16+AG17*$B$17+AG18*$B$18+AG19*$B$19+AG21*$B$21+AG28*$B$28+AG20*$B$20+AG27*$B$27+AG31*$B$31) -> 4916.82
A39: Servicios KM | B39: =SUM(C39:AG39) -> 208150.19 | C39: =$B$5*C5+$B$6*C6+$B$7*C7+$B$8*C8+$B$10*C10+$B$9*C9+C11*B11+C14*B14 -> 7208.81 | D39: =$B$5*D5+$B$6*D6+$B$7*D7+$B$8*D8+$B$10*D10+$B$9*D9+D11*B11+D14*B14 -> 7208.81 | E39: =$B$5*E5+$B$6*E6+$B$7*E7+$B$8*E8+$B$10*E10+$B$9*E9 -> 7251.94 | F39: =$B$5*F5+$B$6*F6+$B$7*F7+$B$8*F8+$B$10*F10+$B$9*F9 -> 7208.81 | G39: =$B$5*G5+$B$6*G6+$B$7*G7+$B$8*G8+$B$10*G10+$B$9*G9 -> 6340.11 | H39: =$B$5*H5+$B$6*H6+$B$7*H7+$B$8*H8+$B$10*H10+$B$9*H9 -> 4787.43 | I39: =$B$5*I5+$B$6*I6+$B$7*I7+$B$8*I8+$B$10*I10+$B$9*I9 -> 7208.81 | J39: =$B$5*J5+$B$6*J6+$B$7*J7+$B$8*J8+$B$10*J10+$B$9*J9 -> 7208.81 | K39: =$B$5*K5+$B$6*K6+$B$7*K7+$B$8*K8+$B$10*K10+$B$9*K9 -> 7208.81 | L39: =$B$5*L5+$B$6*L6+$B$7*L7+$B$8*L8+$B$10*L10+$B$9*L9 -> 7208.81 | ... R39: =$B$5*R5+$B$6*R6+$B$7*R7+$B$8*R8+$B$10*R10+$B$9*R9 -> 7208.81 | S39: =$B$5*S5+$B$6*S6+$B$7*S7+$B$8*S8+$B$10*S10+$B$9*S9+S11*B11+S12*B12+S13*B13+S14*B14 -> 7208.81 | T39: =$B$5*T5+$B$6*T6+$B$7*T7+$B$8*T8+$B$10*T10+$B$9*T9 -> 7208.81 | U39: =$B$5*U5+$B$6*U6+$B$7*U7+$B$8*U8+$B$10*U10+$B$9*U9+U11*B11+U12*B12+U13*B13+U14*B14 -> 6340.11 | V39: =$B$5*V5+$B$6*V6+$B$7*V7+$B$8*V8+$B$10*V10+$B$9*V9+V11*B11+V12*B12+V13*B13+V14*B14 -> 4787.43 | W39: =$B$5*W5+$B$6*W6+$B$7*W7+$B$8*W8+$B$10*W10+$B$9*W9+W11*B11+W12*B12+W13*B13+W14*B14 -> 7208.81 | X39: =$B$5*X5+$B$6*X6+$B$7*X7+$B$8*X8+$B$10*X10+$B$9*X9+X11*B11+X12*B12+X13*B13+X14*B14 -> 7208.81 | Y39: =$B$5*Y5+$B$6*Y6+$B$7*Y7+$B$8*Y8+$B$10*Y10+$B$9*Y9 -> 7208.81 | Z39: =$B$5*Z5+$B$6*Z6+$B$7*Z7+$B$8*Z8+$B$10*Z10+$B$9*Z9 -> 7208.81 | AA39: =$B$5*AA5+$B$6*AA6+$B$7*AA7+$B$8*AA8+$B$10*AA10+$B$9*AA9 -> 7251.94 | AB39: =$B$5*AB5+$B$6*AB6+$B$7*AB7+$B$8*AB8+$B$10*AB10+$B$9*AB9+AB11*B11+AB14*B14 -> 6469.5 | AC39: =$B$5*AC5+$B$6*AC6+$B$7*AC7+$B$8*AC8+$B$10*AC10+$B$9*AC9+AC11*B11+AC14*B14 -> 6383.24 | AD39: =$B$5*AD5+$B$6*AD6+$B$7*AD7+$B$8*AD8+$B$10*AD10+$B$9*AD9+AD11*B11+AD14*B14 -> 7208.81 | AE39: =$B$5*AE5+$B$6*AE6+$B$7*AE7+$B$8*AE8+$B$10*AE10+$B$9*AE9+AE11*B11+AE14*B14 -> 7208.81 | AF39: =$B$5*AF5+$B$6*AF6+$B$7*AF7+$B$8*AF8+$B$10*AF10+$B$9*AF9+AF11*C11+AF14*C14 -> 7208.81 | AG39: =$B$5*AG5+$B$6*AG6+$B$7*AG7+$B$8*AG8+$B$10*AG10+$B$9*AG9+AG11*D11+AG14*D14 -> 4787.43
A40: Asientos KM | B40: =SUM(C40:AG40) -> 31259974 | C40: =C38*104 -> 1177684.6 | D40: =D38*104 -> 1172787.2 | E40: =E38*104 -> 1171989.5 | F40: =F38*104 -> 1180162.9 | G40: =G38*104 -> 677313.52 | H40: =H38*104 -> 511349.28 | I40: =I38*104 -> 1175677.4 | J40: =J38*104 -> 1175677.4 | ... AG40: =AG38*104 -> 511349.28
A41: Coches KM | B41: =SUM(C41:AG41) -> 601153.34 | C41: =C38*2 -> 22647.78 | D41: =D38*2 -> 22553.6 | E41: =E38*2 -> 22538.26 | F41: =F38*2 -> 22695.44 | G41: =G38*2 -> 13025.26 | H41: =H38*2 -> 9833.64 | I41: =I38*2 -> 22609.18 | J41: =J38*2 -> 22609.18 | ... AG41: =AG38*2 -> 9833.64
A42: Capacidad Total | B42: =SUM(C42:AG42) -> 2582508 | C42: =+C37*362 -> 97740 | D42: =+D37*362 -> 97016 | E42: =+E37*362 -> 97378 | F42: =+F37*362 -> 98102 | G42: =+G37*362 -> 54662 | H42: =+H37*362 -> 41268 | I42: =+I37*362 -> 97016 | J42: =+J37*362 -> 97016 | ... AG42: =+AG37*362 -> 41268
A43: Ton Km Brutas | B43: =SUM(C43:AG43) -> 23835730 | C43: =C38*79.3 -> 897984.48 | D43: =D38*79.3 -> 894250.24 | E43: =E38*79.3 -> 893642.01 | F43: =F38*79.3 -> 899874.2 | G43: =G38*79.3 -> 516451.56 | H43: =H38*79.3 -> 389903.83 | I43: =I38*79.3 -> 896453.99 | J43: =J38*79.3 -> 896453.99 | ... AG43: =AG38*79.3 -> 389903.83
E48: 300414.46

Sheet Data Ocupacion
D1: 45566 | F1: 45567 | H1: 45568 | J1: 45569 | L1: 45570 | N1: 45571 | P1: 45572 | R1: 45573 | T1: 45574 | V1: 45575 | X1: 45576 | Z1: 45577 | AB1: 45578 | AD1: 45579 | AF1: 45580 | AH1: 45581 | AJ1: 45582 | AL1: 45583 | AN1: 45584 | AP1: 45585 | AR1: 45586 | AT1: 45587 | AV1: 45588 | AX1: 45589 | AZ1: 45590 | BB1: 45591 | BD1: 45592 | BF1: 45593 | BH1: 45594 | BJ1: 45595 | BL1: 45596
D2: S | E2: M | F2: S | G2: M | H2: S | I2: M | J2: S | K2: M | L2: S | M2: M | N2: S | O2: M | P2: S | Q2: M | R2: S | S2: M | T2: S | U2: M | V2: S | W2: M | X2: S | Y2: M | Z2: S | AA2: M | AB2: S | AC2: M | AD2: S | AE2: M | AF2: S | AG2: M | AH2: S | AI2: M | AJ2: S | AK2: M | AL2: S | AM2: M | AN2: S | AO2: M | AP2: S | AQ2: M | AR2: S | AS2: M | AT2: S | AU2: M | AV2: S | AW2: M | AX2: S | AY2: M | AZ2: S | BA2: M | BB2: S | BC2: M | BD2: S | BE2: M | BF2: S | BG2: M | BH2: S | BI2: M | BJ2: S | BK2: M | BL2: S | BM2: M
A3: Servicios PU-SA | D3: 0 | E3: 2 | F3: 0 | G3: 2 | H3: 0 | I3: 2 | J3: 0 | K3: 2 | L3: 0 | M3: 0 | N3: 0 | O3: 0 | P3: 0 | Q3: 2 | R3: 0 | S3: 2 | T3: 0 | U3: 0 | V3: 0 | W3: 2 | X3: 0 | Y3: 2 | Z3: 0 | AA3: 0 | AB3: 0 | AC3: 0 | AD3: 0 | AE3: 2 | AF3: 0 | AG3: 2 | AH3: 0 | AI3: 2 | AJ3: 0 | AK3: 2 | AL3: 0 | AM3: 2 | AN3: 0 | AO3: 0 | AP3: 0 | AQ3: 0 | AR3: 0 | AS3: 2 | AT3: 0 | AU3: 2 | AV3: 0 | AW3: 2 | AX3: 0 | AY3: 2 | AZ3: 0 | BA3: 2 | BB3: 0 | BC3: 0 | BD3: 0 | BE3: 0 | BF3: 0 | BG3: 2 | BH3: 0 | BI3: 2 | BJ3: 0 | BK3: 2 | BL3: 0 | BM3: 0
A4: Servicios PU-EB | D4: 0 | E4: 0 | F4: 0 | G4: 0 | H4: 0 | I4: 0 | J4: 0 | K4: 0 | L4: 0 | M4: 0 | N4: 0 | O4: 0 | P4: 0 | Q4: 0 | R4: 0 | S4: 0 | T4: 0 | U4: 0 | V4: 0 | W4: 0 | X4: 0 | Y4: 0 | Z4: 0 | AA4: 0 | AB4: 0 | AC4: 0 | AD4: 0 | AE4: 0 | AF4: 0 | AG4: 0 | AH4: 0 | AI4: 0 | AJ4: 0 | AK4: 0 | AL4: 0 | AM4: 0 | AN4: 0 | AO4: 0 | AP4: 0 | AQ4: 0 | AR4: 0 | AS4: 0 | AT4: 0 | AU4: 0 | AV4: 0 | AW4: 0 | AX4: 0 | AY4: 0 | AZ4: 0 | BA4: 0 | BB4: 0 | BC4: 0 | BD4: 0 | BE4: 0 | BF4: 0 | BG4: 0 | BH4: 0 | BI4: 0 | BJ4: 0 | BK4: 0 | BL4: 0 | BM4: 0
A5: Servicios PU-LI | D5: 0 | E5: 10 | F5: 0 | G5: 10 | H5: 0 | I5: 10 | J5: 0 | K5: 10 | L5: 0 | M5: 0 | N5: 0 | O5: 0 | P5: 0 | Q5: 10 | R5: 0 | S5: 10 | T5: 0 | U5: 0 | V5: 0 | W5: 10 | X5: 0 | Y5: 10 | Z5: 0 | AA5: 0 | AB5: 0 | AC5: 0 | AD5: 0 | AE5: 10 | AF5: 0 | AG5: 10 | AH5: 0 | AI5: 10 | AJ5: 0 | AK5: 10 | AL5: 0 | AM5: 10 | AN5: 0 | AO5: 0 | AP5: 0 | AQ5: 0 | AR5: 0 | AS5: 10 | AT5: 0 | AU5: 10 | AV5: 0 | AW5: 10 | AX5: 0 | AY5: 10 | AZ5: 0 | BA5: 10 | BB5: 0 | BC5: 0 | BD5: 0 | BE5: 0 | BF5: 0 | BG5: 10 | BH5: 0 | BI5: 10 | BJ5: 0 | BK5: 10 | BL5: 0 | BM5: 0
A6: Servicios SA-PU | D6: 0 | E6: 1 | F6: 0 | G6: 1 | H6: 0 | I6: 1 | J6: 0 | K6: 1 | L6: 0 | M6: 0 | N6: 0 | O6: 0 | P6: 0 | Q6: 1 | R6: 0 | S6: 1 | T6: 0 | U6: 0 | V6: 0 | W6: 1 | X6: 0 | Y6: 1 | Z6: 0 | AA6: 0 | AB6: 0 | AC6: 0 | AD6: 0 | AE6: 1 | AF6: 0 | AG6: 1 | AH6: 0 | AI6: 1 | AJ6: 0 | AK6: 1 | AL6: 0 | AM6: 1 | AN6: 0 | AO6: 0 | AP6: 0 | AQ6: 0 | AR6: 0 | AS6: 1 | AT6: 0 | AU6: 1 | AV6: 0 | AW6: 1 | AX6: 0 | AY6: 1 | AZ6: 0 | BA6: 1 | BB6: 0 | BC6: 0 | BD6: 0 | BE6: 0 | BF6: 0 | BG6: 1 | BH6: 0 | BI6: 1 | BJ6: 0 | BK6: 1 | BL6: 0 | BM6: 0
A7: Servicios EB-PU | D7: 0 | E7: 0 | F7: 0 | G7: 0 | H7: 0 | I7: 0 | J7: 0 | K7: 0 | L7: 0 | M7: 0 | N7: 0 | O7: 0 | P7: 0 | Q7: 0 | R7: 0 | S7: 0 | T7: 0 | U7: 0 | V7: 0 | W7: 0 | X7: 0 | Y7: 0 | Z7: 0 | AA7: 0 | AB7: 0 | AC7: 0 | AD7: 0 | AE7: 0 | AF7: 0 | AG7: 0 | AH7: 0 | AI7: 0 | AJ7: 0 | AK7: 0 | AL7: 0 | AM7: 0 | AN7: 0 | AO7: 0 | AP7: 0 | AQ7: 0 | AR7: 0 | AS7: 0 | AT7: 0 | AU7: 0 | AV7: 0 | AW7: 0 | AX7: 0 | AY7: 0 | AZ7: 0 | BA7: 0 | BB7: 0 | BC7: 0 | BD7: 0 | BE7: 0 | BF7: 0 | BG7: 0 | BH7: 0 | BI7: 0 | BJ7: 0 | BK7: 0 | BL7: 0 | BM7: 0
A8: Servicios LI-PU | D8: 0 | E8: 10 | F8: 0 | G8: 10 | H8: 0 | I8: 10 | J8: 0 | K8: 10 | L8: 0 | M8: 0 | N8: 0 | O8: 0 | P8: 0 | Q8: 10 | R8: 0 | S8: 10 | T8: 0 | U8: 0 | V8: 0 | W8: 10 | X8: 0 | Y8: 10 | Z8: 0 | AA8: 0 | AB8: 0 | AC8: 0 | AD8: 0 | AE8: 10 | AF8: 0 | AG8: 10 | AH8: 0 | AI8: 10 | AJ8: 0 | AK8: 10 | AL8: 0 | AM8: 10 | AN8: 0 | AO8: 0 | AP8: 0 | AQ8: 0 | AR8: 0 | AS8: 10 | AT8: 0 | AU8: 10 | AV8: 0 | AW8: 10 | AX8: 0 | AY8: 10 | AZ8: 0 | BA8: 10 | BB8: 0 | BC8: 0 | BD8: 0 | BE8: 0 | BF8: 0 | BG8: 10 | BH8: 1 | BI8: 9 | BJ8: 1 | BK8: 9 | BL8: 0 | BM8: 0
A10: Servicios PU-SA | D10: 0 | E10: 0 | F10: 0 | G10: 0 | H10: 0 | I10: 0 | J10: 0 | K10: 0 | L10: 0 | M10: 0 | N10: 0 | O10: 0 | P10: 0 | Q10: 0 | R10: 0 | S10: 0 | T10: 0 | U10: 2 | V10: 0 | W10: 0 | X10: 0 | Y10: 0 | Z10: 0 | AA10: 0 | AB10: 0 | AC10: 0 | AD10: 0 | AE10: 0 | AF10: 0 | AG10: 0 | AH10: 0 | AI10: 0 | AJ10: 0 | AK10: 0 | AL10: 0 | AM10: 0 | AN10: 0 | AO10: 0 | AP10: 0 | AQ10: 0 | AR10: 0 | AS10: 0 | AT10: 0 | AU10: 0 | AV10: 0 | AW10: 0 | AX10: 0 | AY10: 0 | AZ10: 0 | BA10: 0 | BB10: 0 | BC10: 0 | BD10: 0 | BE10: 0 | BF10: 0 | BG10: 0 | BH10: 0 | BI10: 0 | BJ10: 0 | BK10: 0 | BL10: 0 | BM10: 0
A11: Servicios PU-EB | D11: 0 | E11: 0 | F11: 0 | G11: 0 | H11: 0 | I11: 0 | J11: 0 | K11: 0 | L11: 0 | M11: 0 | N11: 0 | O11: 0 | P11: 0 | Q11: 0 | R11: 0 | S11: 0 | T11: 0 | U11: 0 | V11: 0 | W11: 0 | X11: 0 | Y11: 0 | Z11: 0 | AA11: 0 | AB11: 0 | AC11: 0 | AD11: 0 | AE11: 0 | AF11: 0 | AG11: 0 | AH11: 0 | AI11: 0 | AJ11: 0 | AK11: 0 | AL11: 0 | AM11: 0 | AN11: 0 | AO11: 0 | AP11: 0 | AQ11: 0 | AR11: 0 | AS11: 0 | AT11: 0 | AU11: 0 | AV11: 0 | AW11: 0 | AX11: 0 | AY11: 0 | AZ11: 0 | BA11: 0 | BB11: 0 | BC11: 0 | BD11: 0 | BE11: 0 | BF11: 0 | BG11: 0 | BH11: 0 | BI11: 0 | BJ11: 0 | BK11: 0 | BL11: 0 | BM11: 0
A12: Servicios PU-LI | D12: 35 | E12: 27 | F12: 35 | G12: 27 | H12: 35 | I12: 28 | J12: 33 | K12: 29 | L12: 69 | M12: 3 | N12: 51 | O12: 3 | P12: 36 | Q12: 26 | R12: 36 | S12: 26 | T12: 36 | U12: 47 | V12: 36 | W12: 26 | X12: 36 | Y12: 26 | Z12: 52 | AA12: 2 | AB12: 52 | AC12: 2 | AD12: 35 | AE12: 27 | AF12: 35 | AG12: 27 | AH12: 35 | AI12: 27 | AJ12: 35 | AK12: 27 | AL12: 36 | AM12: 26 | AN12: 69 | AO12: 3 | AP12: 51 | AQ12: 3 | AR12: 36 | AS12: 26 | AT12: 36 | AU12: 26 | AV12: 36 | AW12: 26 | AX12: 36 | AY12: 26 | AZ12: 37 | BA12: 26 | BB12: 59 | BC12: 16 | BD12: 56 | BE12: 18 | BF12: 35 | BG12: 27 | BH12: 37 | BI12: 25 | BJ12: 37 | BK12: 25 | BL12: 51 | BM12: 3
A13: Servicios SA-PU | D13: 0 | E13: 2 | F13: 0 | G13: 2 | H13: 0 | I13: 2 | J13: 0 | K13: 2 | L13: 0 | M13: 0 | N13: 0 | O13: 0 | P13: 0 | Q13: 2 | R13: 0 | S13: 2 | T13: 0 | U13: 3 | V13: 0 | W13: 2 | X13: 0 | Y13: 2 | Z13: 0 | AA13: 0 | AB13: 0 | AC13: 0 | AD13: 0 | AE13: 2 | AF13: 0 | AG13: 2 | AH13: 0 | AI13: 2 | AJ13: 0 | AK13: 2 | AL13: 0 | AM13: 2 | AN13: 0 | AO13: 0 | AP13: 0 | AQ13: 0 | AR13: 0 | AS13: 2 | AT13: 0 | AU13: 2 | AV13: 0 | AW13: 2 | AX13: 0 | AY13: 2 | AZ13: 0 | BA13: 2 | BB13: 0 | BC13: 0 | BD13: 0 | BE13: 0 | BF13: 0 | BG13: 2 | BH13: 0 | BI13: 2 | BJ13: 0 | BK13: 2 | BL13: 0 | BM13: 0
A14: Servicios EB-PU | D14: 1 | E14: 1 | F14: 1 | G14: 1 | H14: 1 | I14: 1 | J14: 1 | K14: 1 | L14: 0 | M14: 0 | N14: 0 | O14: 0 | P14: 1 | Q14: 1 | R14: 1 | S14: 1 | T14: 1 | U14: 2 | V14: 1 | W14: 1 | X14: 1 | Y14: 1 | Z14: 0 | AA14: 0 | AB14: 0 | AC14: 0 | AD14: 1 | AE14: 1 | AF14: 1 | AG14: 1 | AH14: 1 | AI14: 1 | AJ14: 1 | AK14: 1 | AL14: 1 | AM14: 1 | AN14: 0 | AO14: 0 | AP14: 0 | AQ14: 0 | AR14: 1 | AS14: 1 | AT14: 1 | AU14: 1 | AV14: 1 | AW14: 1 | AX14: 1 | AY14: 1 | AZ14: 2 | BA14: 0 | BB14: 0 | BC14: 0 | BD14: 0 | BE14: 0 | BF14: 1 | BG14: 1 | BH14: 1 | BI14: 1 | BJ14: 1 | BK14: 1 | BL14: 0 | BM14: 0
A15: Servicios LI-PU | D15: 32 | E15: 30 | F15: 33 | G15: 29 | H15: 34 | I15: 28 | J15: 33 | K15: 29 | L15: 74 | M15: 1 | N15: 57 | O15: 0 | P15: 33 | Q15: 29 | R15: 33 | S15: 29 | T15: 35 | U15: 44 | V15: 33 | W15: 29 | X15: 33 | Y15: 29 | Z15: 57 | AA15: 0 | AB15: 57 | AC15: 0 | AD15: 33 | AE15: 29 | AF15: 33 | AG15: 29 | AH15: 33 | AI15: 29 | AJ15: 33 | AK15: 29 | AL15: 33 | AM15: 29 | AN15: 75 | AO15: 0 | AP15: 57 | AQ15: 0 | AR15: 33 | AS15: 29 | AT15: 33 | AU15: 29 | AV15: 33 | AW15: 29 | AX15: 33 | AY15: 29 | AZ15: 32 | BA15: 30 | BB15: 57 | BC15: 18 | BD15: 56 | BE15: 18 | BF15: 35 | BG15: 27 | BH15: 34 | BI15: 28 | BJ15: 33 | BK15: 29 | BL15: 57 | BM15: 0
... A22: Servicios LI-PU | D22: 2 | E22: 5 | F22: 2 | G22: 5 | H22: 2 | I22: 5 | J22: 2 | K22: 5 | L22: 0 | M22: 0 | N22: 0 | O22: 0 | P22: 2 | Q22: 5 | R22: 2 | S22: 5 | T22: 0 | U22: 0 | V22: 2 | W22: 5 | X22: 2 | Y22: 5 | Z22: 0 | AA22: 0 | AB22: 0 | AC22: 0 | AD22: 2 | AE22: 5 | AF22: 2 | AG22: 5 | AH22: 2 | AI22: 5 | AJ22: 2 | AK22: 5 | AL22: 2 | AM22: 5 | AN22: 0 | AO22: 0 | AP22: 0 | AQ22: 0 | AR22: 2 | AS22: 5 | AT22: 2 | AU22: 5 | AV22: 2 | AW22: 5 | AX22: 2 | AY22: 5 | AZ22: 2 | BA22: 5 | BB22: 0 | BC22: 0 | BD22: 0 | BE22: 0 | BF22: 2 | BG22: 5 | BH22: 2 | BI22: 5 | BJ22: 2 | BK22: 5 | BL22: 0 | BM22: 0
D25: =SUM(D3:D22) -> 70 | E25: =SUM(E3:E22) -> 100 | F25: =SUM(F3:F22) -> 72 | G25: =SUM(G3:G22) -> 98 | H25: =SUM(H3:H22) -> 73 | I25: =SUM(I3:I22) -> 98 | J25: =SUM(J3:J22) -> 69 | K25: =SUM(K3:K22) -> 101 | ... BM25: =SUM(BM3:BM22) -> 3
A31: Km Servicio
A32: PU - LI | D32: =D5+D12+D19 -> 35 | E32: =E5+E12+E19 -> 48 | F32: =F5+F12+F19 -> 36 | G32: =G5+G12+G19 -> 47 | H32: =H5+H12+H19 -> 36 | I32: =I5+I12+I19 -> 48 | J32: =J5+J12+J19 -> 33 | K32: =K5+K12+K19 -> 50 | ... BM32: =BM5+BM12+BM19 -> 3
A33: LI - PU | D33: =D8+D15+D22 -> 34 | E33: =E8+E15+E22 -> 45 | F33: =F8+F15+F22 -> 35 | G33: =G8+G15+G22 -> 44 | H33: =H8+H15+H22 -> 36 | I33: =I8+I15+I22 -> 43 | J33: =J8+J15+J22 -> 35 | K33: =K8+K15+K22 -> 44 | ... BM33: =BM8+BM15+BM22 -> 0
A34: PU - SA | D34: =D3+D10+D17 -> 0 | E34: =E3+E10+E17 -> 2 | F34: =F3+F10+F17 -> 0 | G34: =G3+G10+G17 -> 2 | H34: =H3+H10+H17 -> 0 | I34: =I3+I10+I17 -> 2 | J34: =J3+J10+J17 -> 0 | K34: =K3+K10+K17 -> 2 | ... BM34: =BM3+BM10+BM17 -> 0
