Workbook

Sheet Odometro-Kilometraje
A1: Control Contador Kilometraje de Trenes
B2: 46204 | C2: 46205 | D2: 46206 | E2: 46207 | F2: 46208 | G2: 46209 | H2: 46210 | I2: 46211 | J2: 46212 | K2: 46213 | L2: 46214 | M2: 46215 | N2: 46216 | O2: 46217 | P2: 46218 | Q2: 46219 | R2: 46220 | S2: 46221 | T2: 46222 | U2: 46223 | V2: 46224 | W2: 46225 | X2: 46226 | Y2: 46227 | Z2: 46228 | AA2: 46229 | AB2: 46230 | AC2: 46231 | AD2: 46232 | AE2: 46233 | AF2: 46234
B3: Contador | C3: Contador | D3: Contador | E3: Contador | F3: Contador | G3: Contador | H3: Contador | I3: Contador | J3: Contador | K3: Contador | L3: Contador | M3: Contador | N3: Contador | O3: Contador | P3: Contador | Q3: Contador | R3: Contador | S3: Contador | T3: Contador | U3: Contador | V3: Contador | W3: Contador | X3: Contador | Y3: Contador | Z3: Contador | AA3: Contador | AB3: Contador | AC3: Contador | AD3: Contador | AE3: Contador | AF3: Contador
A4: Tren | B4: Odómetro | C4: Odómetro | D4: Odómetro | E4: Odómetro | F4: Odómetro | G4: Odómetro | H4: Odómetro | I4: Odómetro | J4: Odómetro | K4: Odómetro | L4: Odómetro | M4: Odómetro | N4: Odómetro | O4: Odómetro | P4: Odómetro | Q4: Odómetro | R4: Odómetro | S4: Odómetro | T4: Odómetro | U4: Odómetro | V4: Odómetro | W4: Odómetro | X4: Odómetro | Y4: Odómetro | Z4: Odómetro | AA4: Odómetro | AB4: Odómetro | AC4: Odómetro | AD4: Odómetro | AE4: Odómetro | AF4: Odómetro
A5: M01 | B5: 2140832 | C5: 2141376 | D5: 2141936 | E5: 2142453 | F5: 2142887 | G5: 2143174 | H5: 2143471 | I5: 2144032 | J5: 2144634 | K5: 2144835 | L5: 2144835 | M5: 2144835 | N5: 2145082 | O5: 2145422 | P5: 2145769 | Q5: 2145899 | R5: 2146252 | S5: 2146252 | T5: 2146252 | U5: 2146305 | V5: 2146678 | W5: 2147043 | X5: 2147275 | Y5: 2147552 | Z5: 2147552 | AA5: 2147552 | AB5: 2147682 | AC5: 2147812 | AD5: 2148395 | AE5: 2149001 | AF5: 2149604
A6: M02 | B6: 2104854 | C6: 2105339 | D6: 2105669 | E6: 2105669 | F6: 2105669 | G6: 2106171 | H6: 2106521 | I6: 2106891 | J6: 2107023 | K6: 2107206 | L6: 2107206 | M6: 2107224 | N6: 2107590 | O6: 2107727 | P6: 2107999 | Q6: 2108476 | R6: 2108653 | S6: 2108655 | T6: 2108657 | U6: 2109177 | V6: 2109681 | W6: 2110287 | X6: 2110895 | Y6: 2111099 | Z6: 2111099 | AA6: 2111099 | AB6: 2111345 | AC6: 2111596 | AD6: 2111788 | AE6: 2111958 | AF6: 2112244
A7: M03 | B7: 2183884 | C7: 2184253 | D7: 2184448 | E7: 2184448 | F7: 2184448 | G7: 2184657 | H7: 2185093 | I7: 2185351 | J7: 2185666 | K7: 2185990 | L7: 2186335 | M7: 2186767 | N7: 2187287 | O7: 2187737 | P7: 2187827 | Q7: 2187827 | R7: 2187827 | S7: 2187827 | T7: 2187846 | U7: 2187846 | V7: 2187980 | W7: 2188541 | X7: 2188741 | Y7: 2188992 | Z7: 2188992 | AA7: 2188992 | AB7: 2189503 | AC7: 2189765 | AD7: 2189964 | AE7: 2190465 | AF7: 2191029
A8: M04 | B8: 2186922 | C8: 2187176 | D8: 2187737 | E8: 2188254 | F8: 2188297 | G8: 2188749 | H8: 2188943 | I8: 2189193 | J8: 2189679 | K8: 2190200 | L8: 2190719 | M8: 2191238 | N8: 2191510 | O8: 2191761 | P8: 2192109 | Q8: 2192109 | R8: 2192109 | S8: 2192678 | T8: 2193105 | U8: 2193686 | V8: 2194103 | W8: 2194352 | X8: 2194726 | Y8: 2195080 | Z8: 2195599 | AA8: 2196075 | AB8: 2196188 | AC8: 2196699 | AD8: 2197150 | AE8: 2197316 | AF8: 2197519
A9: M05 | B9: 2102988 | C9: 2103548 | D9: 2104152 | E9: 2104713 | F9: 2105101 | G9: 2105470 | H9: 2105888 | I9: 2106208 | J9: 2106718 | K9: 2107279 | L9: 2107586 | M9: 2108017 | N9: 2108105 | O9: 2108420 | P9: 2108851 | Q9: 2108851 | R9: 2109045 | S9: 2109512 | T9: 2109987 | U9: 2110299 | V9: 2110319 | W9: 2110451 | X9: 2110713 | Y9: 2111025 | Z9: 2111586 | AA9: 2112061 | AB9: 2112234 | AC9: 2112754 | AD9: 2113024 | AE9: 2113275 | AF9: 2113677
A10: M06 | B10: 2211410 | C10: 2211929 | D10: 2212347 | E10: 2212390 | F10: 2212865 | G10: 2213123 | H10: 2213646 | I10: 2213826 | J10: 2213959 | K10: 2214126 | L10: 2214126 | M10: 2214346 | N10: 2214907 | O10: 2215428 | P10: 2215826 | Q10: 2216260 | R10: 2216260 | S10: 2216260 | T10: 2216260 | U10: 2216260 | V10: 2216260 | W10: 2216281 | X10: 2216485 | Y10: 2216751 | Z10: 2216865 | AA10: 2217129 | AB10: 2217392 | AC10: 2217913 | AD10: 2218518 | AE10: 2218722 | AF10: 2219259
A11: M07 | B11: 2248115 | C11: 2248272 | D11: 2248793 | E11: 2249314 | F11: 2249790 | G11: 2250284 | H11: 2250659 | I11: 2251221 | J11: 2251722 | K11: 2251905 | L11: 2251905 | M11: 2251905 | N11: 2252108 | O11: 2252291 | P11: 2252881 | Q11: 2253143 | R11: 2253143 | S11: 2253231 | T11: 2253231 | U11: 2253318 | V11: 2253743 | W11: 2254067 | X11: 2254317 | Y11: 2254580 | Z11: 2254580 | AA11: 2254580 | AB11: 2254710 | AC11: 2255067 | AD11: 2255392 | AE11: 2255689 | AF11: 2256183
A12: M08 | B12: 2146385 | C12: 2146664 | D12: 2146858 | E12: 2146858 | F12: 2146858 | G12: 2147089 | H12: 2147677 | I12: 2148197 | J12: 2148647 | K12: 2148868 | L12: 2148868 | M12: 2148868 | N12: 2149119 | O12: 2149337 | P12: 2149695 | Q12: 2149695 | R12: 2149695 | S12: 2149695 | T12: 2149695 | U12: 2149888 | V12: 2149891 | W12: 2149896 | X12: 2150089 | Y12: 2150351 | Z12: 2150351 | AA12: 2150351 | AB12: 2150423 | AC12: 2150617 | AD12: 2151178 | AE12: 2151458 | AF12: 2151744
A13: M09 | B13: 2131811 | C13: 2132261 | D13: 2132428 | E13: 2132428 | F13: 2132470 | G13: 2132794 | H13: 2133080 | I13: 2133682 | J13: 2134027 | K13: 2134225 | L13: 2134225 | M13: 2134225 | N13: 2134429 | O13: 2134679 | P13: 2134819 | Q13: 2134819 | R13: 2135004 | S13: 2135004 | T13: 2135004 | U13: 2135004 | V13: 2135056 | W13: 2135334 | X13: 2135583 | Y13: 2136100 | Z13: 2136100 | AA13: 2136100 | AB13: 2136347 | AC13: 2136610 | AD13: 2136922 | AE13: 2137439 | AF13: 2137673
A14: M10 | B14: 2199907 | C14: 2199977 | D14: 2200066 | E14: 2200066 | F14: 2200066 | G14: 2200427 | H14: 2200577 | I14: 2201096 | J14: 2201355 | K14: 2201547 | L14: 2201547 | M14: 2201547 | N14: 2201776 | O14: 2202326 | P14: 2202743 | Q14: 2202743 | R14: 2202982 | S14: 2203500 | T14: 2204017 | U14: 2204386 | V14: 2204478 | W14: 2204478 | X14: 2204478 | Y14: 2204478 | Z14: 2204478 | AA14: 2204478 | AB14: 2204478 | AC14: 2204478 | AD14: 2204478 | AE14: 2204478 | AF14: 2204478
A15: M11 | B15: 2226695 | C15: 2227299 | D15: 2227859 | E15: 2228420 | F15: 2228809 | G15: 2229259 | H15: 2229337 | I15: 2229549 | J15: 2229800 | K15: 2230041 | L15: 2230041 | M15: 2230041 | N15: 2230600 | O15: 2230866 | P15: 2231470 | Q15: 2231947 | R15: 2231947 | S15: 2231947 | T15: 2231947 | U15: 2231947 | V15: 2231967 | W15: 2232247 | X15: 2232441 | Y15: 2232698 | Z15: 2232698 | AA15: 2232698 | AB15: 2233027 | AC15: 2233477 | AD15: 2233895 | AE15: 2234244 | AF15: 2234804
A16: M12 | B16: 2072121 | C16: 2072315 | D16: 2072490 | E16: 2072490 | F16: 2072490 | G16: 2072990 | H16: 2073551 | I16: 2074154 | J16: 2074509 | K16: 2075113 | L16: 2075630 | M16: 2075890 | N16: 2076195 | O16: 2076801 | P16: 2077044 | Q16: 2077044 | R16: 2077045 | S16: 2077045 | T16: 2077045 | U16: 2077065 | V16: 2077046 | W16: 2077177 | X16: 2077689 | Y16: 2077927 | Z16: 2077927 | AA16: 2077927 | AB16: 2078146 | AC16: 2078571 | AD16: 2079174 | AE16: 2079324 | AF16: 2079325
... A45: SFE-414 | B45: 2123 | C45: 2123 | D45: 2123 | E45: 2123 | F45: 2123 | G45: 2123 | H45: 2123 | I45: 2123 | J45: 2123 | K45: 2123 | L45: 2123 | M45: 2123 | N45: 2123 | O45: 2123 | P45: 2123 | Q45: 2123 | R45: 2123 | S45: 2123 | T45: 2123 | U45: 2123 | V45: 2123 | W45: 2123 | X45: 2123 | Y45: 2123 | Z45: 2123 | AA45: 2123 | AB45: 2123 | AC45: 2123 | AD45: 2123 | AE45: 2123 | AF45: 2123
A47: Kilometraje Diario Recorrido
B48: 46204 | C48: 46205 | D48: 46206 | E48: 46207 | F48: 46208 | G48: 46209 | H48: 46210 | I48: 46211 | J48: 46212 | K48: 46213 | L48: 46214 | M48: 46215 | N48: 46216 | O48: 46217 | P48: 46218 | Q48: 46219 | R48: 46220 | S48: 46221 | T48: 46222 | U48: 46223 | V48: 46224 | W48: 46225 | X48: 46226 | Y48: 46227 | Z48: 46228 | AA48: 46229 | AB48: 46230 | AC48: 46231 | AD48: 46232 | AE48: 46233 | AF48: 46234
B49: Kilometraje | C49: Kilometraje | D49: Kilometraje | E49: Kilometraje | F49: Kilometraje | G49: Kilometraje | H49: Kilometraje | I49: Kilometraje | J49: Kilometraje | K49: Kilometraje | L49: Kilometraje | M49: Kilometraje | N49: Kilometraje | O49: Kilometraje | P49: Kilometraje | Q49: Kilometraje | R49: Kilometraje | S49: Kilometraje | T49: Kilometraje | U49: Kilometraje | V49: Kilometraje | W49: Kilometraje | X49: Kilometraje | Y49: Kilometraje | Z49: Kilometraje | AA49: Kilometraje | AB49: Kilometraje | AC49: Kilometraje | AD49: Kilometraje | AE49: Kilometraje | AF49: Kilometraje
A50: Tren | B50: Diario | C50: Diario | D50: Diario | E50: Diario | F50: Diario | G50: Diario | H50: Diario | I50: Diario | J50: Diario | K50: Diario | L50: Diario | M50: Diario | N50: Diario | O50: Diario | P50: Diario | Q50: Diario | R50: Diario | S50: Diario | T50: Diario | U50: Diario | V50: Diario | W50: Diario | X50: Diario | Y50: Diario | Z50: Diario | AA50: Diario | AB50: Diario | AC50: Diario | AD50: Diario | AE50: Diario | AF50: Diario
A51: M01 | B51: 249 | C51: =C5-B5 -> 544 | D51: =D5-C5 -> 560 | E51: =E5-D5 -> 517 | F51: =F5-E5 -> 434 | G51: =G5-F5 -> 287 | H51: =H5-G5 -> 297 | I51: =I5-H5 -> 561 | J51: =J5-I5 -> 602 | ... AF51: =AF5-AE5 -> 603
A52: M02 | B52: 192 | C52: =C6-B6 -> 485 | D52: =D6-C6 -> 330 | E52: =E6-D6 -> 0 | F52: =F6-E6 -> 0 | G52: =G6-F6 -> 502 | H52: =H6-G6 -> 350 | I52: =I6-H6 -> 370 | J52: =J6-I6 -> 132 | ... AF52: =AF6-AE6 -> 286
A53: M03 | B53: 435 | C53: =C7-B7 -> 369 | D53: =D7-C7 -> 195 | E53: =E7-D7 -> 0 | F53: =F7-E7 -> 0 | G53: =G7-F7 -> 209 | H53: =H7-G7 -> 436 | I53: =I7-H7 -> 258 | J53: =J7-I7 -> 315 | ... AF53: =AF7-AE7 -> 564
A54: M04 | B54: 194 | C54: =C8-B8 -> 254 | D54: =D8-C8 -> 561 | E54: =E8-D8 -> 517 | F54: =F8-E8 -> 43 | G54: =G8-F8 -> 452 | H54: =H8-G8 -> 194 | I54: =I8-H8 -> 250 | J54: =J8-I8 -> 486 | ... AF54: =AF8-AE8 -> 203
A55: M05 | B55: 417 | C55: =C9-B9 -> 560 | D55: =D9-C9 -> 604 | E55: =E9-D9 -> 561 | F55: =F9-E9 -> 388 | G55: =G9-F9 -> 369 | H55: =H9-G9 -> 418 | I55: =I9-H9 -> 320 | J55: =J9-I9 -> 510 | ... AF55: =AF9-AE9 -> 402
A56: M06 | B56: 181 | C56: =C10-B10 -> 519 | D56: =D10-C10 -> 418 | E56: =E10-D10 -> 43 | F56: =F10-E10 -> 475 | G56: =G10-F10 -> 258 | H56: =H10-G10 -> 523 | I56: =I10-H10 -> 180 | J56: =J10-I10 -> 133 | ... AF56: =AF10-AE10 -> 537
A57: M07 | B57: 499 | C57: =C11-B11 -> 157 | D57: =D11-C11 -> 521 | E57: =E11-D11 -> 521 | F57: =F11-E11 -> 476 | G57: =G11-F11 -> 494 | H57: =H11-G11 -> 375 | I57: =I11-H11 -> 562 | J57: =J11-I11 -> 501 | ... AF57: =AF11-AE11 -> 494
A58: M08 | B58: 519 | C58: =C12-B12 -> 279 | D58: =D12-C12 -> 194 | E58: =E12-D12 -> 0 | F58: =F12-E12 -> 0 | G58: =G12-F12 -> 231 | H58: =H12-G12 -> 588 | I58: =I12-H12 -> 520 | J58: =J12-I12 -> 450 | ... AF58: =AF12-AE12 -> 286
A59: M09 | B59: 560 | C59: =C13-B13 -> 450 | D59: =D13-C13 -> 167 | E59: =E13-D13 -> 0 | F59: =F13-E13 -> 42 | G59: =G13-F13 -> 324 | H59: =H13-G13 -> 286 | I59: =I13-H13 -> 602 | J59: =J13-I13 -> 345 | ... AF59: =AF13-AE13 -> 234
A60: M10 | B60: 194 | C60: =C14-B14 -> 70 | D60: =D14-C14 -> 89 | E60: =E14-D14 -> 0 | F60: =F14-E14 -> 0 | G60: =G14-F14 -> 361 | H60: =H14-G14 -> 150 | I60: =I14-H14 -> 519 | J60: =J14-I14 -> 259 | ... AF60: =AF14-AE14 -> 0
A61: M11 | B61: 476 | C61: =C15-B15 -> 604 | D61: =D15-C15 -> 560 | E61: =E15-D15 -> 561 | F61: =F15-E15 -> 389 | G61: =G15-F15 -> 450 | H61: =H15-G15 -> 78 | I61: =I15-H15 -> 212 | J61: =J15-I15 -> 251 | ... AF61: =AF15-AE15 -> 560
A62: M12 | B62: 451 | C62: =C16-B16 -> 194 | D62: =D16-C16 -> 175 | E62: =E16-D16 -> 0 | F62: =F16-E16 -> 0 | G62: =G16-F16 -> 500 | H62: =H16-G16 -> 561 | I62: =I16-H16 -> 603 | J62: =J16-I16 -> 355 | ... AF62: =AF16-AE16 -> 1
... A85: XM35 | B85: 520 | C85: =C39-B39 -> 434 | D85: =D39-C39 -> 346 | E85: =E39-D39 -> 0 | F85: =F39-E39 -> 0 | G85: =G39-F39 -> 204 | H85: =H39-G39 -> 416 | I85: =I39-H39 -> 197 | J85: =J39-I39 -> 295 | ... AF85: =AF39-AE39 -> 23
A86: SFE-412 | B86: 172 | C86: =C43-B43 -> 128 | D86: =D43-C43 -> 87 | E86: =E43-D43 -> 0 | F86: =F43-E43 -> 0 | G86: =G43-F43 -> 175 | H86: =H43-G43 -> 174 | I86: =I43-H43 -> 348 | J86: =J43-I43 -> 124 | ... AF86: =AF43-AE43 -> 211
A88: Kilometraje Diario | B88: =SUM(B51:B86) -> 12929 | C88: =SUM(C51:C86) -> 13146 | D88: =SUM(D51:D86) -> 12747 | E88: =SUM(E51:E86) -> 6527 | F88: =SUM(F51:F86) -> 4977 | G88: =SUM(G51:G86) -> 12739 | H88: =SUM(H51:H86) -> 12682 | I88: =SUM(I51:I86) -> 12504 | ... AF88: =SUM(AF51:AF86) -> 9786
A90: SFE-410 | B90: 0 | C90: =C41-B41 -> 0 | D90: =D41-C41 -> 0 | E90: =E41-D41 -> 0 | F90: =F41-E41 -> 0 | G90: =G41-F41 -> 0 | H90: =H41-G41 -> 0 | I90: =I41-H41 -> 0 | J90: =J42-I42 -> 0 | K90: =K41-J41 -> 0 | L90: =L41-K41 -> 0 | M90: =M41-L41 -> 0 | N90: =N41-M41 -> 0 | O90: =O41-N41 -> 0 | P90: =P41-O41 -> 0 | Q90: =Q41-P41 -> 0 | R90: =R41-Q41 -> 0 | ... T90: =T41-S41 -> 0 | U90: =U42-T42 -> 0 | V90: =V42-U42 -> 0 | W90: =W41-V41 -> 0 | X90: =X41-W41 -> 0 | Y90: =Y41-X41 -> 0 | Z90: =Z41-Y41 -> 0 | AA90: =AA41-Z41 -> 0 | AB90: =AB41-AA41 -> 0 | AC90: =AC41-AB41 -> 0 | AD90: =AD41-AC41 -> 0 | ... AF90: =AF41-AE41 -> 0
A91: SFE-411 | B91: 0 | C91: =C42-B42 -> 0 | D91: =D42-C42 -> 0 | E91: =E42-D42 -> 0 | F91: =F42-E42 -> 0 | G91: =G42-F42 -> 0 | H91: =H42-G42 -> 0 | I91: 0 | J91: 0 | K91: 0 | L91: 0 | M91: 0 | N91: 0 | O91: 0 | P91: 0 | Q91: =Q42-P42 -> 0 | R91: =R42-Q42 -> 0 | S91: =S42-R42 -> 0 | T91: =T42-S42 -> 0 | U91: =U42-T42 -> 0 | V91: =V42-U42 -> 0 | W91: =W42-V42 -> 0 | X91: =X42-W42 -> 0 | ... AF91: =AF42-AE42 -> 0
A92: SFE-413 | B92: 0 | C92: =C44-B44 -> 0 | D92: =D44-C44 -> 0 | E92: =E44-D44 -> 0 | F92: =F44-E44 -> 0 | G92: =G44-F44 -> 0 | H92: =H44-G44 -> 0 | I92: =H44-G44 -> 0 | J92: =J44-I44 -> 0 | K92: =K44-J44 -> 0 | L92: =L44-K44 -> 0 | M92: =M44-L44 -> 0 | N92: =N44-M44 -> 0 | O92: =O44-N44 -> 0 | P92: =P44-O44 -> 0 | Q92: =Q44-P44 -> 0 | ... AF92: =AF44-AE44 -> 0
A93: SFE-414 | B93: 0 | C93: =C45-B45 -> 0 | D93: =D45-C45 -> 0 | E93: =E45-D45 -> 0 | F93: =F45-E45 -> 0 | G93: =G45-F45 -> 0 | H93: =H45-G45 -> 0 | I93: =H45-G45 -> 0 | J93: =I45-H45 -> 0 | K93: =J45-I45 -> 0 | L93: =L45-K45 -> 0 | M93: =M45-L45 -> 0 | N93: =N45-M45 -> 0 | O93: =O45-N45 -> 0 | P93: =P45-O45 -> 0 | Q93: =Q45-P45 -> 0 | R93: =R45-Q45 -> 0 | S93: =S45-R45 -> 0 | ... AF93: =AF45-AE45 -> 0

Sheet KM-Servicio
E1: SA-QU/QU-SA | F1: 7.68 | H1: SA-MI | I1: 21.7 | J1: EB-PU | K1: 25.4 | L1: PU-SA | M1: 29.11 | N1: QU-LI / LI-QU | O1: 21.7 | P1: VM-PU | Q1: 8.3 | R1: VM-LI | S1: 34.83 | T1: LI-PO | U1: 39.19 | V1: PU-AM | W1: PU-ES/ES-PU | X1: 11.71 | Y1: PU-RE | Z1: 6 | AA1: PU-BA | AB1: 2.2 | AC1: SA-VM | AD1: 20.81 | AE1: PU-QU | AF1: 21.43 | AG1: PU-BE | AH1: 0.72 | AI1: RE-LI | AJ1: =M2-Z1 -> 37.13 | AK1: CO-PU | AL1: 27
B2: CANTIDAD DE SERVICIOS | D2: CANTIDAD DE SERVICIOS | F2: EB-LI | G2: =M2-K1 -> 17.73 | H2: PU-PE | I2: 30.4 | J2: PO-SA | K2: 25.4 | L2: PU-LI | M2: 43.13 | N2: MI-LI / LI-MI | O2: 35.73 | P2: HO-LI/LI-HO | Q2: 33.97 | R2: PU-MI | S2: 7.4 | T2: LI-PE | U2: 12.72 | V2: 26.5 | W2: MI-SA | X2: 21.7 | Y2: PU-PO | Z2: 3.9 | AA2: AM-QU | AB2: =(26.4-21.43) -> 4.97 | AC2: PU-CH | AD2: 10.55 | AE2: PU-VL | AF2: 19 | AG2: ES-LI | AH2: 31.42 | AI2: ES-SA | AJ2: =M1-X1 -> 17.4 | AK2: LI-PO | AL2: 39.23
B3: PROGRAMADOS | D3: REALIZADOS | F3: Origen-Destino | G3: Total Trenes | H3: Total Trenes P | I3: Total Servicios | J3: Kms.xTrenes | K3: Kmsxservicios. | L3: Asientos x Kms. | M3: Disp x Km. | N3: Total Odómetro | O3: % Uso Trenes | Q3: Cortes | T3: Acoples | W3: KmTren R | X3: KmTren P | Y3: PU-FR | Z3: 1.56
B4: Simples | C4: Dobles | D4: Simples | E4: Dobles | Q4: EB | R4: SA | S4: PE | T4: EB | U4: SA | V4: PE
A5: 46204 | B5: 38 | C5: 41 | D5: ='Data Ocupacion'!D31 -> 38 | E5: ='Data Ocupacion'!E31 -> 41 | F5: PU-LI | G5: =D5+E5*2 -> 120 | H5: =B5+C5*2 -> 120 | I5: =D5+E5 -> 79 | J5: =G5*M$2 -> 5175.6 | K5: =I5*M$2 -> 3407.27 | L5: =J5*104 -> 538262.4 | M5: =I5*104 -> 8216 | W5: =J5-(Q5*($M$2-$K$1))-(R5*($M$2-$M$1))- (S5*($M$2-$I$2))+ (T5*($G$2)) -> 5175.6 | X5: =H5*$M$2 -> 5175.6
B6: 36 | C6: 42 | D6: ='Data Ocupacion'!D32 -> 36 | E6: ='Data Ocupacion'!E32 -> 42 | F6: LI-PU | G6: =D6+E6*2 -> 120 | H6: =B6+C6*2 -> 120 | I6: =D6+E6 -> 78 | J6: =G6*M$2 -> 5175.6 | K6: =I6*M$2 -> 3364.14 | L6: =J6*104 -> 538262.4 | M6: =I6*104 -> 8112 | T6: 4 | W6: =J6-(T6*($M$2-$K$1)+(U6*($M$2-$M$1))) -> 5104.68 | X6: =H6*$M$2 -> 5175.6
B7: 33 | C7: 3 | D7: ='Data Ocupacion'!D33 -> 33 | E7: ='Data Ocupacion'!E33 -> 3 | F7: PU-SA | G7: =D7+E7*2 -> 39 | H7: =B7+C7*2 -> 39 | I7: =D7+E7 -> 36 | J7: =G7*M$1 -> 1135.29 | K7: =I7*M$1 -> 1047.96 | L7: =J7*104 -> 118070.16 | M7: =I7*104 -> 3744 | Q7: 3 | W7: =J7-(Q7*($M$1-$K$1)) -> 1124.16 | X7: =H7*$M$1 -> 1135.29
B8: 29 | C8: 3 | D8: ='Data Ocupacion'!D34 -> 29 | E8: ='Data Ocupacion'!E34 -> 3 | F8: SA-PU | G8: =D8+E8*2 -> 35 | H8: =B8+C8*2 -> 35 | I8: =D8+E8 -> 32 | J8: =G8*M$1 -> 1018.85 | K8: =I8*M$1 -> 931.52 | L8: =J8*104 -> 105960.4 | M8: =I8*104 -> 3328 | W8: =J8 -> 1018.85 | X8: =H8*$M$1 -> 1018.85
B9: 0 | C9: 0 | D9: ='Data Ocupacion'!D35 -> 0 | E9: ='Data Ocupacion'!E35 -> 0 | F9: PU-EB | G9: =D9+E9*2 -> 0 | H9: =B9+C9*2 -> 0 | I9: =D9+E9 -> 0 | J9: =G9*K$1 -> 0 | K9: =I9*K$1 -> 0 | L9: =J9*104 -> 0 | M9: =I9*104 -> 0 | W9: =J9 -> 0 | X9: =H9*$K$1 -> 0
B10: 4 | C10: 0 | D10: ='Data Ocupacion'!D36 -> 4 | E10: ='Data Ocupacion'!E36 -> 0 | F10: EB-PU | G10: =D10+E10*2 -> 4 | H10: =B10+C10*2 -> 4 | I10: =D10+E10 -> 4 | J10: =G10*K$1 -> 101.6 | K10: =I10*K$1 -> 101.6 | L10: =J10*104 -> 10566.4 | M10: =I10*104 -> 416 | W10: =J10 -> 101.6 | X10: =H10*$K$1 -> 101.6
B11: =SUM(B5:B10) -> 140 | C11: =SUM(C5:C10) -> 89 | D11: =SUM(D5:D10) -> 140 | E11: =SUM(E5:E10) -> 89 | G11: =SUM(G5:G10) -> 318 | H11: =SUM(H5:H10) -> 318 | I11: =SUM(I5:I10) -> 229 | J11: =SUM(J5:J10) -> 12606.94 | K11: =SUM(K5:K10) -> 8852.49 | L11: =SUM(L5:L10) -> 1311121.8 | M11: =SUM(M5:M10) -> 23816 | N11: ='Odometro-Kilometraje'!B88 -> 12929 | O11: =(W11/N11)*100 -> 96.874391 | W11: =SUM(W5:W10) -> 12524.89 | X11: =SUM(X5:X10) -> 12606.94
A12: =A5+1 -> 46205 | B12: 38 | C12: 41 | D12: ='Data Ocupacion'!F31 -> 39 | E12: ='Data Ocupacion'!G31 -> 40 | F12: PU-LI | G12: =D12+E12*2 -> 119 | H12: =B12+C12*2 -> 120 | I12: =D12+E12 -> 79 | J12: =G12*M$2 -> 5132.47 | K12: =I12*M$2 -> 3407.27 | L12: =J12*104 -> 533776.88 | M12: =I12*104 -> 8216 | Q12: 1 | W12: =J12-(Q12*($M$2-$K$1))-(R12*($M$2-$M$1))- (S12*($M$2-$I$2))+ (T12*($G$2)) -> 5114.74 | X12: =H12*$M$2 -> 5175.6
B13: 36 | C13: 42 | D13: ='Data Ocupacion'!F32 -> 37 | E13: ='Data Ocupacion'!G32 -> 41 | F13: LI-PU | G13: =D13+E13*2 -> 119 | H13: =B13+C13*2 -> 120 | I13: =D13+E13 -> 78 | J13: =G13*M$2 -> 5132.47 | K13: =I13*M$2 -> 3364.14 | L13: =J13*104 -> 533776.88 | M13: =I13*104 -> 8112 | W13: =J13-(T13*($M$2-$K$1)+(U13*($M$2-$M$1))) -> 5132.47 | X13: =H13*$M$2 -> 5175.6
B14: 33 | C14: 3 | D14: ='Data Ocupacion'!F33 -> 34 | E14: ='Data Ocupacion'!G33 -> 2 | F14: PU-SA | G14: =D14+E14*2 -> 38 | H14: =B14+C14*2 -> 39 | I14: =D14+E14 -> 36 | J14: =G14*M$1 -> 1106.18 | K14: =I14*M$1 -> 1047.96 | L14: =J14*104 -> 115042.72 | M14: =I14*104 -> 3744 | Q14: 2 | W14: =J14-(Q14*($M$1-$K$1)) -> 1098.76 | X14: =H14*$M$1 -> 1135.29
B15: 29 | C15: 3 | D15: ='Data Ocupacion'!F34 -> 30 | E15: ='Data Ocupacion'!G34 -> 2 | F15: SA-PU | G15: =D15+E15*2 -> 34 | H15: =B15+C15*2 -> 35 | I15: =D15+E15 -> 32 | J15: =G15*M$1 -> 989.74 | K15: =I15*M$1 -> 931.52 | L15: =J15*104 -> 102932.96 | M15: =I15*104 -> 3328 | W15: =J15 -> 989.74 | X15: =H15*$M$1 -> 1018.85
B16: 0 | C16: 0 | D16: ='Data Ocupacion'!F35 -> 0 | E16: ='Data Ocupacion'!G35 -> 0 | F16: PU-EB | G16: =D16+E16*2 -> 0 | H16: =B16+C16*2 -> 0 | I16: =D16+E16 -> 0 | J16: =G16*K$1 -> 0 | K16: =I16*K$1 -> 0 | L16: =J16*104 -> 0 | M16: =I16*104 -> 0 | W16: =J16 -> 0 | X16: =H16*$K$1 -> 0
B17: 4 | C17: 0 | D17: ='Data Ocupacion'!F36 -> 4 | E17: ='Data Ocupacion'!G36 -> 0 | F17: EB-PU | G17: =D17+E17*2 -> 4 | H17: =B17+C17*2 -> 4 | I17: =D17+E17 -> 4 | J17: =G17*K$1 -> 101.6 | K17: =I17*K$1 -> 101.6 | L17: =J17*104 -> 10566.4 | M17: =I17*104 -> 416 | W17: =J17 -> 101.6 | X17: =H17*$K$1 -> 101.6
B18: =SUM(B12:B17) -> 140 | C18: =SUM(C12:C17) -> 89 | D18: =SUM(D12:D17) -> 144 | E18: =SUM(E12:E17) -> 85 | G18: =SUM(G12:G17) -> 314 | H18: =SUM(H12:H17) -> 318 | I18: =SUM(I12:I17) -> 229 | J18: =SUM(J12:J17) -> 12462.46 | K18: =SUM(K12:K17) -> 8852.49 | L18: =SUM(L12:L17) -> 1296095.8 | M18: =SUM(M12:M17) -> 23816 | N18: ='Odometro-Kilometraje'!C88 -> 13146 | O18: =(W18/N18)*100 -> 94.609083 | W18: =SUM(W12:W17) -> 12437.31 | X18: =SUM(X12:X17) -> 12606.94
A19: =A12+1 -> 46206 | B19: 38 | C19: 41 | D19: ='Data Ocupacion'!H31 -> 40 | E19: ='Data Ocupacion'!I31 -> 39 | F19: PU-LI | G19: =D19+E19*2 -> 118 | H19: =B19+C19*2 -> 120 | I19: =D19+E19 -> 79 | J19: =G19*M$2 -> 5089.34 | K19: =I19*M$2 -> 3407.27 | L19: =J19*104 -> 529291.36 | M19: =I19*104 -> 8216 | Q19: 2 | W19: =J19-(Q19*($M$2-$K$1))-(R19*($M$2-$M$1))- (S19*($M$2-$I$2))+ (T19*($G$2)) -> 5053.88 | X19: =H19*$M$2 -> 5175.6
B20: 36 | C20: 42 | D20: ='Data Ocupacion'!H32 -> 38 | E20: ='Data Ocupacion'!I32 -> 40 | F20: LI-PU | G20: =D20+E20*2 -> 118 | H20: =B20+C20*2 -> 120 | I20: =D20+E20 -> 78 | J20: =G20*M$2 -> 5089.34 | K20: =I20*M$2 -> 3364.14 | L20: =J20*104 -> 529291.36 | M20: =I20*104 -> 8112 | T20: 2 | W20: =J20-(T20*($M$2-$K$1)+(U20*($M$2-$M$1))) -> 5053.88 | X20: =H20*$M$2 -> 5175.6
B21: 33 | C21: 3 | D21: ='Data Ocupacion'!H33 -> 34 | E21: ='Data Ocupacion'!I33 -> 2 | F21: PU-SA | G21: =D21+E21*2 -> 38 | H21: =B21+C21*2 -> 39 | I21: =D21+E21 -> 36 | J21: =G21*M$1 -> 1106.18 | K21: =I21*M$1 -> 1047.96 | L21: =J21*104 -> 115042.72 | M21: =I21*104 -> 3744 | Q21: 2 | W21: =J21-(Q21*($M$1-$K$1)) -> 1098.76 | X21: =H21*$M$1 -> 1135.29
B22: 29 | C22: 3 | D22: ='Data Ocupacion'!H34 -> 30 | E22: ='Data Ocupacion'!I34 -> 2 | F22: SA-PU | G22: =D22+E22*2 -> 34 | H22: =B22+C22*2 -> 35 | I22: =D22+E22 -> 32 | J22: =G22*M$1 -> 989.74 | K22: =I22*M$1 -> 931.52 | L22: =J22*104 -> 102932.96 | M22: =I22*104 -> 3328 | W22: =J22 -> 989.74 | X22: =H22*$M$1 -> 1018.85
B23: 0 | C23: 0 | D23: ='Data Ocupacion'!H35 -> 0 | E23: ='Data Ocupacion'!I35 -> 0 | F23: PU-EB | G23: =D23+E23*2 -> 0 | H23: =B23+C23*2 -> 0 | I23: =D23+E23 -> 0 | J23: =G23*K$1 -> 0 | K23: =I23*K$1 -> 0 | L23: =J23*104 -> 0 | M23: =I23*104 -> 0 | W23: =J23 -> 0 | X23: =H23*$K$1 -> 0
B24: 4 | C24: 0 | D24: ='Data Ocupacion'!H36 -> 4 | E24: ='Data Ocupacion'!I36 -> 0 | F24: EB-PU | G24: =D24+E24*2 -> 4 | H24: =B24+C24*2 -> 4 | I24: =D24+E24 -> 4 | J24: =G24*K$1 -> 101.6 | K24: =I24*K$1 -> 101.6 | L24: =J24*104 -> 10566.4 | M24: =I24*104 -> 416 | W24: =J24 -> 101.6 | X24: =H24*$K$1 -> 101.6
B25: =SUM(B19:B24) -> 140 | C25: =SUM(C19:C24) -> 89 | D25: =SUM(D19:D24) -> 146 | E25: =SUM(E19:E24) -> 83 | G25: =SUM(G19:G24) -> 312 | H25: =SUM(H19:H24) -> 318 | I25: =SUM(I19:I24) -> 229 | J25: =SUM(J19:J24) -> 12376.2 | K25: =SUM(K19:K24) -> 8852.49 | L25: =SUM(L19:L24) -> 1287124.8 | M25: =SUM(M19:M24) -> 23816 | N25: ='Odometro-Kilometraje'!D88 -> 12747 | O25: =(W25/N25)*100 -> 96.476504 | W25: =SUM(W19:W24) -> 12297.86 | X25: =SUM(X19:X24) -> 12606.94
A26: =A19+1 -> 46207 | B26: 69 | C26: 3 | D26: ='Data Ocupacion'!J31 -> 69 | E26: ='Data Ocupacion'!K31 -> 3 | F26: PU-LI | G26: =D26+E26*2 -> 75 | H26: =B26+C26*2 -> 75 | I26: =D26+E26 -> 72 | J26: =G26*M$2 -> 3234.75 | K26: =I26*M$2 -> 3105.36 | L26: =J26*104 -> 336414 | M26: =I26*104 -> 7488 | W26: =J26-(Q26*($M$2-$K$1))-(R26*($M$2-$M$1))- (S26*($M$2-$I$2))+ (T26*($G$2)) -> 3234.75 | X26: =H26*$M$2 -> 3234.75
B27: 75 | C27: 0 | D27: ='Data Ocupacion'!J32 -> 75 | E27: ='Data Ocupacion'!K32 -> 0 | F27: LI-PU | G27: =D27+E27*2 -> 75 | H27: =B27+C27*2 -> 75 | I27: =D27+E27 -> 75 | J27: =G27*M$2 -> 3234.75 | K27: =I27*M$2 -> 3234.75 | L27: =J27*104 -> 336414 | M27: =I27*104 -> 7800 | W27: =J27-(T27*($M$2-$K$1)+(U27*($M$2-$M$1))+(V27*($M$2-$I$2))) -> 3234.75 | X27: =H27*$M$2 -> 3234.75
B28: 0 | C28: 0 | D28: ='Data Ocupacion'!J33 -> 0 | E28: ='Data Ocupacion'!K33 -> 0 | F28: PU-SA | G28: =D28+E28*2 -> 0 | H28: =B28+C28*2 -> 0 | I28: =D28+E28 -> 0 | J28: =G28*M$1 -> 0 | K28: =I28*M$1 -> 0 | L28: =J28*104 -> 0 | M28: =I28*104 -> 0 | W28: =J28-(Q28*($M$1-$K$1)) -> 0 | X28: =H28*$M$1 -> 0
B29: 0 | C29: 0 | D29: ='Data Ocupacion'!J34 -> 0 | E29: ='Data Ocupacion'!K34 -> 0 | F29: SA-PU | G29: =D29+E29*2 -> 0 | H29: =B29+C29*2 -> 0 | I29: =D29+E29 -> 0 | J29: =G29*M$1 -> 0 | K29: =I29*M$1 -> 0 | L29: =J29*104 -> 0 | M29: =I29*104 -> 0 | W29: =J29 -> 0 | X29: =H29*$M$1 -> 0
B30: 0 | C30: 0 | D30: ='Data Ocupacion'!J35 -> 0 | E30: ='Data Ocupacion'!K35 -> 0 | F30: PU-EB | G30: =D30+E30*2 -> 0 | H30: =B30+C30*2 -> 0 | I30: =D30+E30 -> 0 | J30: =G30*K$1 -> 0 | K30: =I30*K$1 -> 0 | L30: =J30*104 -> 0 | M30: =I30*104 -> 0 | W30: =J30 -> 0 | X30: =H30*$K$1 -> 0
B31: 0 | C31: 0 | D31: ='Data Ocupacion'!J36 -> 0 | E31: ='Data Ocupacion'!K36 -> 0 | F31: EB-PU | G31: =D31+E31*2 -> 0 | H31: =B31+C31*2 -> 0 | I31: =D31+E31 -> 0 | J31: =G31*K$1 -> 0 | K31: =I31*K$1 -> 0 | L31: =J31*104 -> 0 | M31: =I31*104 -> 0 | W31: =J31 -> 0 | X31: =H31*$K$1 -> 0
B32: =SUM(B26:B31) -> 144 | C32: =SUM(C26:C31) -> 3 | D32: =SUM(D26:D31) -> 144 | E32: =SUM(E26:E31) -> 3 | G32: =SUM(G26:G31) -> 150 | H32: =SUM(H26:H31) -> 150 | I32: =SUM(I26:I31) -> 147 | J32: =SUM(J26:J31) -> 6469.5 | K32: =SUM(K26:K31) -> 6340.11 | L32: =SUM(L26:L31) -> 672828 | M32: =SUM(M26:M31) -> 15288 | N32: ='Odometro-Kilometraje'!E88 -> 6527 | O32: =(W32/N32)*100 -> 99.119044 | W32: =SUM(W26:W31) -> 6469.5 | X32: =SUM(X26:X31) -> 6469.5
A33: =A26+1 -> 46208 | B33: 51 | C33: 3 | D33: ='Data Ocupacion'!L31 -> 51 | E33: ='Data Ocupacion'!M31 -> 3 | F33: PU-LI | G33: =D33+E33*2 -> 57 | H33: =B33+C33*2 -> 57 | I33: =D33+E33 -> 54 | J33: =G33*M$2 -> 2458.41 | K33: =I33*M$2 -> 2329.02 | L33: =J33*104 -> 255674.64 | M33: =I33*104 -> 5616 | W33: =J33-(Q33*($M$2-$K$1))-(R33*($M$2-$M$1))- (S33*($M$2-$I$2))+ (T33*($G$2)) -> 2458.41 | X33: =H33*$M$2 -> 2458.41
B34: 57 | C34: 0 | D34: ='Data Ocupacion'!L32 -> 57 | E34: ='Data Ocupacion'!M32 -> 0 | F34: LI-PU | G34: =D34+E34*2 -> 57 | H34: =B34+C34*2 -> 57 | I34: =D34+E34 -> 57 | J34: =G34*M$2 -> 2458.41 | K34: =I34*M$2 -> 2458.41 | L34: =J34*104 -> 255674.64 | M34: =I34*104 -> 5928 | W34: =J34-(T34*($M$2-$K$1)+(U34*($M$2-$M$1))+(V34*($M$2-$I$2))) -> 2458.41 | X34: =H34*$M$2 -> 2458.41
B35: 0 | C35: 0 | D35: ='Data Ocupacion'!L33 -> 0 | E35: ='Data Ocupacion'!M33 -> 0 | F35: PU-SA | G35: =D35+E35*2 -> 0 | H35: =B35+C35*2 -> 0 | I35: =D35+E35 -> 0 | J35: =G35*M$1 -> 0 | K35: =I35*M$1 -> 0 | L35: =J35*104 -> 0 | M35: =I35*104 -> 0 | W35: =J35-(Q35*($M$1-$K$1)) -> 0 | X35: =H35*$M$1 -> 0
B36: 0 | C36: 0 | D36: ='Data Ocupacion'!L34 -> 0 | E36: ='Data Ocupacion'!M34 -> 0 | F36: SA-PU | G36: =D36+E36*2 -> 0 | H36: =B36+C36*2 -> 0 | I36: =D36+E36 -> 0 | J36: =G36*M$1 -> 0 | K36: =I36*M$1 -> 0 | L36: =J36*104 -> 0 | M36: =I36*104 -> 0 | W36: =J36 -> 0 | X36: =H36*$M$1 -> 0
B37: 0 | C37: 0 | D37: ='Data Ocupacion'!L35 -> 0 | E37: ='Data Ocupacion'!M35 -> 0 | F37: PU-EB | G37: =D37+E37*2 -> 0 | H37: =B37+C37*2 -> 0 | I37: =D37+E37 -> 0 | J37: =G37*K$1 -> 0 | K37: =I37*K$1 -> 0 | L37: =J37*104 -> 0 | M37: =I37*104 -> 0 | W37: =J37 -> 0 | X37: =H37*$K$1 -> 0
B38: 0 | C38: 0 | D38: ='Data Ocupacion'!L36 -> 0 | E38: ='Data Ocupacion'!M36 -> 0 | F38: EB-PU | G38: =D38+E38*2 -> 0 | H38: =B38+C38*2 -> 0 | I38: =D38+E38 -> 0 | J38: =G38*K$1 -> 0 | K38: =I38*K$1 -> 0 | L38: =J38*104 -> 0 | M38: =I38*104 -> 0 | W38: =J38 -> 0 | X38: =H38*$K$1 -> 0
B39: =SUM(B33:B38) -> 108 | C39: =SUM(C33:C38) -> 3 | D39: =SUM(D33:D38) -> 108 | E39: =SUM(E33:E38) -> 3 | G39: =SUM(G33:G38) -> 114 | H39: =SUM(H33:H38) -> 114 | I39: =SUM(I33:I38) -> 111 | J39: =SUM(J33:J38) -> 4916.82 | K39: =SUM(K33:K38) -> 4787.43 | L39: =SUM(L33:L38) -> 511349.28 | M39: =SUM(M33:M38) -> 11544 | N39: ='Odometro-Kilometraje'!F88 -> 4977 | O39: =(W39/N39)*100 -> 98.790838 | W39: =SUM(W33:W38) -> 4916.82 | X39: =SUM(X33:X38) -> 4916.82
A40: =A33+1 -> 46209 | B40: 38 | C40: 41 | D40: ='Data Ocupacion'!N31 -> 40 | E40: ='Data Ocupacion'!O31 -> 39 | F40: PU-LI | G40: =D40+E40*2 -> 118 | H40: =B40+C40*2 -> 120 | I40: =D40+E40 -> 79 | J40: =G40*M$2 -> 5089.34 | K40: =I40*M$2 -> 3407.27 | L40: =J40*104 -> 529291.36 | M40: =I40*104 -> 8216 | Q40: 3 | W40: =J40-(Q40*($M$2-$K$1))-(R40*($M$2-$M$1))- (S40*($M$2-$I$2))+ (T40*($G$2)) -> 5036.15 | X40: =H40*$M$2 -> 5175.6
...

Sheet Data Ocupacion
D1: 46204 | F1: 46205 | H1: 46206 | J1: 46207 | L1: 46208 | N1: 46209 | P1: 46210 | R1: 46211 | T1: 46212 | V1: 46213 | X1: 46214 | Z1: 46215 | AB1: 46216 | AD1: 46217 | AF1: 46218 | AH1: 46219 | AJ1: 46220 | AL1: 46221 | AN1: 46222 | AP1: 46223 | AR1: 46224 | AT1: 46225 | AV1: 46226 | AX1: 46227 | AZ1: 46228 | BB1: 46229 | BD1: 46230 | BF1: 46231 | BH1: 46232 | BJ1: 46233 | BL1: 46234
D2: S | E2: M | F2: S | G2: M | H2: S | I2: M | J2: S | K2: M | L2: S | M2: M | N2: S | O2: M | P2: S | Q2: M | R2: S | S2: M | T2: S | U2: M | V2: S | W2: M | X2: S | Y2: M | Z2: S | AA2: M | AB2: S | AC2: M | AD2: S | AE2: M | AF2: S | AG2: M | AH2: S | AI2: M | AJ2: S | AK2: M | AL2: S | AM2: M | AN2: S | AO2: M | AP2: S | AQ2: M | AR2: S | AS2: M | AT2: S | AU2: M | AV2: S | AW2: M | AX2: S | AY2: M | AZ2: S | BA2: M | BB2: S | BC2: M | BD2: S | BE2: M | BF2: S | BG2: M | BH2: S | BI2: M | BJ2: S | BK2: M | BL2: S | BM2: M
A3: Servicios PU-SA | D3: 9 | E3: 3 | F3: 10 | G3: 2 | H3: 10 | I3: 2 | J3: 0 | K3: 0 | L3: 0 | M3: 0 | N3: 10 | O3: 2 | P3: 10 | Q3: 2 | R3: 10 | S3: 2 | T3: 12 | U3: 0 | V3: 12 | W3: 0 | X3: 0 | Y3: 0 | Z3: 0 | AA3: 0 | AB3: 12 | AC3: 0 | AD3: 9 | AE3: 0 | AF3: 12 | AG3: 0 | AH3: 0 | AI3: 0 | AJ3: 6 | AK3: 0 | AL3: 0 | AM3: 0 | AN3: 0 | AO3: 0 | AP3: 2 | AQ3: 0 | AR3: 0 | AS3: 0 | AT3: 5 | AU3: 0 | AV3: 10 | AW3: 0 | AX3: 10 | AY3: 0 | AZ3: 0 | BA3: 0 | BB3: 0 | BC3: 0 | BD3: 10 | BE3: 0 | BF3: 9 | BG3: 0 | BH3: 9 | BI3: 0 | BJ3: 9 | BK3: 0 | BL3: 2 | BM3: 0
A4: Servicios PU-EB | D4: 0 | E4: 0 | F4: 0 | G4: 0 | H4: 0 | I4: 0 | J4: 0 | K4: 0 | L4: 0 | M4: 0 | N4: 0 | O4: 0 | P4: 0 | Q4: 0 | R4: 0 | S4: 0 | T4: 0 | U4: 0 | V4: 0 | W4: 0 | X4: 0 | Y4: 0 | Z4: 0 | AA4: 0 | AB4: 0 | AC4: 0 | AD4: 0 | AE4: 0 | AF4: 0 | AG4: 0 | AH4: 0 | AI4: 0 | AJ4: 0 | AK4: 0 | AL4: 0 | AM4: 0 | AN4: 0 | AO4: 0 | AP4: 0 | AQ4: 0 | AR4: 0 | AS4: 0 | AT4: 0 | AU4: 0 | AV4: 0 | AW4: 0 | AX4: 0 | AY4: 0 | AZ4: 0 | BA4: 0 | BB4: 0 | BC4: 0 | BD4: 0 | BE4: 0 | BF4: 0 | BG4: 0 | BH4: 0 | BI4: 0 | BJ4: 0 | BK4: 0 | BL4: 0 | BM4: 0
A5: Servicios PU-LI | D5: 2 | E5: 8 | F5: 2 | G5: 8 | H5: 3 | I5: 7 | J5: 0 | K5: 0 | L5: 0 | M5: 0 | N5: 2 | O5: 8 | P5: 2 | Q5: 8 | R5: 2 | S5: 8 | T5: 2 | U5: 8 | V5: 2 | W5: 8 | X5: 0 | Y5: 0 | Z5: 0 | AA5: 0 | AB5: 1 | AC5: 9 | AD5: 2 | AE5: 8 | AF5: 1 | AG5: 9 | AH5: 0 | AI5: 0 | AJ5: 10 | AK5: 0 | AL5: 0 | AM5: 0 | AN5: 0 | AO5: 0 | AP5: 8 | AQ5: 2 | AR5: 6 | AS5: 4 | AT5: 2 | AU5: 8 | AV5: 2 | AW5: 8 | AX5: 2 | AY5: 8 | AZ5: 0 | BA5: 0 | BB5: 0 | BC5: 0 | BD5: 2 | BE5: 8 | BF5: 4 | BG5: 6 | BH5: 2 | BI5: 8 | BJ5: 2 | BK5: 8 | BL5: 2 | BM5: 7
A6: Servicios SA-PU | D6: 10 | E6: 0 | F6: 10 | G6: 0 | H6: 10 | I6: 0 | J6: 0 | K6: 0 | L6: 0 | M6: 0 | N6: 9 | O6: 0 | P6: 10 | Q6: 0 | R6: 10 | S6: 0 | T6: 10 | U6: 0 | V6: 10 | W6: 0 | X6: 0 | Y6: 0 | Z6: 0 | AA6: 0 | AB6: 10 | AC6: 0 | AD6: 8 | AE6: 0 | AF6: 10 | AG6: 0 | AH6: 0 | AI6: 0 | AJ6: 7 | AK6: 0 | AL6: 0 | AM6: 0 | AN6: 0 | AO6: 0 | AP6: 3 | AQ6: 0 | AR6: 2 | AS6: 0 | AT6: 6 | AU6: 0 | AV6: 10 | AW6: 0 | AX6: 10 | AY6: 0 | AZ6: 0 | BA6: 0 | BB6: 0 | BC6: 0 | BD6: 10 | BE6: 0 | BF6: 10 | BG6: 0 | BH6: 10 | BI6: 0 | BJ6: 10 | BK6: 0 | BL6: 0 | BM6: 0
A7: Servicios EB-PU | D7: 1 | E7: 0 | F7: 1 | G7: 0 | H7: 1 | I7: 0 | J7: 0 | K7: 0 | L7: 0 | M7: 0 | N7: 1 | O7: 0 | P7: 1 | Q7: 0 | R7: 1 | S7: 0 | T7: 1 | U7: 0 | V7: 1 | W7: 0 | X7: 0 | Y7: 0 | Z7: 0 | AA7: 0 | AB7: 1 | AC7: 0 | AD7: 3 | AE7: 0 | AF7: 1 | AG7: 0 | AH7: 0 | AI7: 0 | AJ7: 0 | AK7: 0 | AL7: 0 | AM7: 0 | AN7: 0 | AO7: 0 | AP7: 0 | AQ7: 0 | AR7: 0 | AS7: 0 | AT7: 0 | AU7: 0 | AV7: 0 | AW7: 0 | AX7: 0 | AY7: 0 | AZ7: 0 | BA7: 0 | BB7: 0 | BC7: 0 | BD7: 0 | BE7: 0 | BF7: 0 | BG7: 0 | BH7: 0 | BI7: 0 | BJ7: 0 | BK7: 0 | BL7: 0 | BM7: 0
A8: Servicios LI-PU | D8: 4 | E8: 6 | F8: 4 | G8: 6 | H8: 5 | I8: 5 | J8: 0 | K8: 0 | L8: 0 | M8: 0 | N8: 4 | O8: 6 | P8: 4 | Q8: 6 | R8: 4 | S8: 6 | T8: 6 | U8: 4 | V8: 6 | W8: 4 | X8: 0 | Y8: 0 | Z8: 0 | AA8: 0 | AB8: 5 | AC8: 5 | AD8: 5 | AE8: 5 | AF8: 5 | AG8: 5 | AH8: 0 | AI8: 0 | AJ8: 10 | AK8: 0 | AL8: 0 | AM8: 0 | AN8: 0 | AO8: 0 | AP8: 10 | AQ8: 0 | AR8: 8 | AS8: 2 | AT8: 7 | AU8: 3 | AV8: 6 | AW8: 4 | AX8: 6 | AY8: 4 | AZ8: 0 | BA8: 0 | BB8: 0 | BC8: 0 | BD8: 6 | BE8: 4 | BF8: 8 | BG8: 2 | BH8: 6 | BI8: 4 | BJ8: 6 | BK8: 4 | BL8: 7 | BM8: 4
A10: Servicios PU-SA | D10: 17 | E10: 0 | F10: 17 | G10: 0 | H10: 17 | I10: 0 | J10: 0 | K10: 0 | L10: 0 | M10: 0 | N10: 15 | O10: 0 | P10: 15 | Q10: 0 | R10: 17 | S10: 0 | T10: 17 | U10: 0 | V10: 17 | W10: 0 | X10: 0 | Y10: 0 | Z10: 0 | AA10: 0 | AB10: 17 | AC10: 0 | AD10: 16 | AE10: 0 | AF10: 17 | AG10: 0 | AH10: 0 | AI10: 0 | AJ10: 3 | AK10: 0 | AL10: 0 | AM10: 0 | AN10: 0 | AO10: 0 | AP10: 2 | AQ10: 0 | AR10: 6 | AS10: 1 | AT10: 14 | AU10: 0 | AV10: 17 | AW10: 0 | AX10: 17 | AY10: 0 | AZ10: 0 | BA10: 0 | BB10: 0 | BC10: 0 | BD10: 16 | BE10: 0 | BF10: 17 | BG10: 0 | BH10: 17 | BI10: 0 | BJ10: 15 | BK10: 1 | BL10: 8 | BM10: 2
A11: Servicios PU-EB | D11: 0 | E11: 0 | F11: 0 | G11: 0 | H11: 0 | I11: 0 | J11: 0 | K11: 0 | L11: 0 | M11: 0 | N11: 0 | O11: 0 | P11: 0 | Q11: 0 | R11: 0 | S11: 0 | T11: 0 | U11: 0 | V11: 0 | W11: 0 | X11: 0 | Y11: 0 | Z11: 0 | AA11: 0 | AB11: 0 | AC11: 0 | AD11: 0 | AE11: 0 | AF11: 0 | AG11: 0 | AH11: 0 | AI11: 0 | AJ11: 0 | AK11: 0 | AL11: 0 | AM11: 0 | AN11: 0 | AO11: 0 | AP11: 0 | AQ11: 0 | AR11: 0 | AS11: 0 | AT11: 0 | AU11: 0 | AV11: 0 | AW11: 0 | AX11: 0 | AY11: 0 | AZ11: 0 | BA11: 0 | BB11: 0 | BC11: 0 | BD11: 0 | BE11: 0 | BF11: 0 | BG11: 0 | BH11: 0 | BI11: 0 | BJ11: 0 | BK11: 0 | BL11: 0 | BM11: 0
A12: Servicios PU-LI | D12: 35 | E12: 26 | F12: 36 | G12: 25 | H12: 36 | I12: 25 | J12: 69 | K12: 3 | L12: 51 | M12: 3 | N12: 37 | O12: 24 | P12: 38 | Q12: 26 | R12: 37 | S12: 24 | T12: 44 | U12: 17 | V12: 44 | W12: 17 | X12: 69 | Y12: 3 | Z12: 51 | AA12: 3 | AB12: 44 | AC12: 17 | AD12: 43 | AE12: 19 | AF12: 44 | AG12: 17 | AH12: 51 | AI12: 3 | AJ12: 16 | AK12: 1 | AL12: 59 | AM12: 0 | AN12: 50 | AO12: 4 | AP12: 52 | AQ12: 9 | AR12: 48 | AS12: 9 | AT12: 48 | AU12: 14 | AV12: 50 | AW12: 11 | AX12: 48 | AY12: 13 | AZ12: 69 | BA12: 3 | BB12: 51 | BC12: 3 | BD12: 54 | BE12: 7 | BF12: 46 | BG12: 15 | BH12: 48 | BI12: 13 | BJ12: 47 | BK12: 14 | BL12: 55 | BM12: 6
A13: Servicios SA-PU | D13: 13 | E13: 3 | F13: 14 | G13: 2 | H13: 14 | I13: 2 | J13: 0 | K13: 0 | L13: 0 | M13: 0 | N13: 14 | O13: 2 | P13: 14 | Q13: 2 | R13: 14 | S13: 2 | T13: 16 | U13: 0 | V13: 16 | W13: 0 | X13: 0 | Y13: 0 | Z13: 0 | AA13: 0 | AB13: 16 | AC13: 0 | AD13: 16 | AE13: 0 | AF13: 16 | AG13: 0 | AH13: 0 | AI13: 0 | AJ13: 4 | AK13: 0 | AL13: 0 | AM13: 0 | AN13: 0 | AO13: 0 | AP13: 3 | AQ13: 0 | AR13: 8 | AS13: 1 | AT13: 14 | AU13: 0 | AV13: 16 | AW13: 0 | AX13: 16 | AY13: 0 | AZ13: 0 | BA13: 0 | BB13: 0 | BC13: 0 | BD13: 15 | BE13: 0 | BF13: 16 | BG13: 0 | BH13: 16 | BI13: 0 | BJ13: 15 | BK13: 0 | BL13: 13 | BM13: 0
A14: Servicios EB-PU | D14: 3 | E14: 0 | F14: 3 | G14: 0 | H14: 3 | I14: 0 | J14: 0 | K14: 0 | L14: 0 | M14: 0 | N14: 3 | O14: 0 | P14: 3 | Q14: 0 | R14: 3 | S14: 0 | T14: 3 | U14: 0 | V14: 3 | W14: 0 | X14: 0 | Y14: 0 | Z14: 0 | AA14: 0 | AB14: 3 | AC14: 0 | AD14: 2 | AE14: 0 | AF14: 3 | AG14: 0 | AH14: 0 | AI14: 0 | AJ14: 1 | AK14: 0 | AL14: 0 | AM14: 0 | AN14: 0 | AO14: 0 | AP14: 1 | AQ14: 0 | AR14: 1 | AS14: 0 | AT14: 1 | AU14: 0 | AV14: 2 | AW14: 0 | AX14: 2 | AY14: 0 | AZ14: 0 | BA14: 0 | BB14: 0 | BC14: 0 | BD14: 2 | BE14: 0 | BF14: 1 | BG14: 0 | BH14: 1 | BI14: 0 | BJ14: 2 | BK14: 0 | BL14: 1 | BM14: 0
A15: Servicios LI-PU | D15: 28 | E15: 33 | F15: 29 | G15: 32 | H15: 29 | I15: 32 | J15: 75 | K15: 0 | L15: 57 | M15: 0 | N15: 30 | O15: 31 | P15: 30 | Q15: 31 | R15: 30 | S15: 31 | T15: 36 | U15: 25 | V15: 36 | W15: 25 | X15: 75 | Y15: 0 | Z15: 57 | AA15: 0 | AB15: 36 | AC15: 25 | AD15: 37 | AE15: 24 | AF15: 37 | AG15: 24 | AH15: 57 | AI15: 0 | AJ15: 16 | AK15: 0 | AL15: 62 | AM15: 0 | AN15: 56 | AO15: 1 | AP15: 51 | AQ15: 10 | AR15: 48 | AS15: 8 | AT15: 40 | AU15: 21 | AV15: 42 | AW15: 19 | AX15: 40 | AY15: 21 | AZ15: 75 | BA15: 0 | BB15: 57 | BC15: 0 | BD15: 47 | BE15: 14 | BF15: 38 | BG15: 23 | BH15: 40 | BI15: 21 | BJ15: 42 | BK15: 19 | BL15: 47 | BM15: 14
... A22: Servicios LI-PU | D22: 4 | E22: 3 | F22: 4 | G22: 3 | H22: 4 | I22: 3 | J22: 0 | K22: 0 | L22: 0 | M22: 0 | N22: 4 | O22: 3 | P22: 4 | Q22: 3 | R22: 5 | S22: 2 | T22: 5 | U22: 2 | V22: 5 | W22: 2 | X22: 0 | Y22: 0 | Z22: 0 | AA22: 0 | AB22: 5 | AC22: 2 | AD22: 5 | AE22: 2 | AF22: 5 | AG22: 2 | AH22: 0 | AI22: 0 | AJ22: 2 | AK22: 0 | AL22: 0 | AM22: 0 | AN22: 0 | AO22: 0 | AP22: 5 | AQ22: 2 | AR22: 4 | AS22: 3 | AT22: 5 | AU22: 2 | AV22: 5 | AW22: 2 | AX22: 5 | AY22: 2 | AZ22: 0 | BA22: 0 | BB22: 0 | BC22: 0 | BD22: 6 | BE22: 1 | BF22: 5 | BG22: 2 | BH22: 5 | BI22: 2 | BJ22: 5 | BK22: 2 | BL22: 6 | BM22: 1
D24: =SUM(D3:D22) -> 140 | E24: =SUM(E3:E22) -> 89 | F24: =SUM(F3:F22) -> 144 | G24: =SUM(G3:G22) -> 85 | H24: =SUM(H3:H22) -> 146 | I24: =SUM(I3:I22) -> 83 | J24: =SUM(J3:J22) -> 144 | K24: =SUM(K3:K22) -> 3 | ... BM24: =SUM(BM3:BM22) -> 38
A30: Km Servicio
A31: PU - LI | D31: =D5+D12+D19 -> 38 | E31: =E5+E12+E19 -> 41 | F31: =F5+F12+F19 -> 39 | G31: =G5+G12+G19 -> 40 | H31: =H5+H12+H19 -> 40 | I31: =I5+I12+I19 -> 39 | J31: =J5+J12+J19 -> 69 | K31: =K5+K12+K19 -> 3 | ... BM31: =BM5+BM12+BM19 -> 16
A32: LI - PU | D32: =D8+D15+D22 -> 36 | E32: =E8+E15+E22 -> 42 | F32: =F8+F15+F22 -> 37 | G32: =G8+G15+G22 -> 41 | H32: =H8+H15+H22 -> 38 | I32: =I8+I15+I22 -> 40 | J32: =J8+J15+J22 -> 75 | K32: =K8+K15+K22 -> 0 | ... BM32: =BM8+BM15+BM22 -> 19
A33: PU - SA | D33: =D3+D10+D17 -> 33 | E33: =E3+E10+E17 -> 3 | F33: =F3+F10+F17 -> 34 | G33: =G3+G10+G17 -> 2 | H33: =H3+H10+H17 -> 34 | I33: =I3+I10+I17 -> 2 | J33: =J3+J10+J17 -> 0 | K33: =K3+K10+K17 -> 0 | ... BM33: =BM3+BM10+BM17 -> 2
A34: SA - PU | D34: =D6+D13+D20 -> 29 | E34: =E6+E13+E20 -> 3 | F34: =F6+F13+F20 -> 30 | G34: =G6+G13+G20 -> 2 | H34: =H6+H13+H20 -> 30 | I34: =I6+I13+I20 -> 2 | J34: =J6+J13+J20 -> 0 | K34: =K6+K13+K20 -> 0 | ... BM34: =BM6+BM13+BM20 -> 1
A35: PU-EB | D35: =D4+D11+D18 -> 0 | E35: =E4+E11+E18 -> 0 | F35: =F4+F11+F18 -> 0 | G35: =G4+G11+G18 -> 0 | H35: =H4+H11+H18 -> 0 | I35: =I4+I11+I18 -> 0 | J35: =J4+J11+J18 -> 0 | K35: =K4+K11+K18 -> 0 | ... BM35: =BM4+BM11+BM18 -> 0
A36: EB-PU | D36: =D7+D14+D21 -> 4 | E36: =E7+E14+E21 -> 0 | F36: =F7+F14+F21 -> 4 | G36: =G7+G14+G21 -> 0 | H36: =H7+H14+H21 -> 4 | I36: =I7+I14+I21 -> 0 | J36: =J7+J14+J21 -> 0 | K36: =K7+K14+K21 -> 0 | ... BM36: =BM7+BM14+BM21 -> 0
A37: total | D37: =SUM(D31:D36) -> 140 | E37: =SUM(E31:E36) -> 89 | F37: =SUM(F31:F36) -> 144 | G37: =SUM(G31:G36) -> 85 | H37: =SUM(H31:H36) -> 146 | I37: =SUM(I31:I36) -> 83 | J37: =SUM(J31:J36) -> 144 | K37: =SUM(K31:K36) -> 3 | ... BM37: =SUM(BM31:BM36) -> 38
A39: Servicios
A40: PU - LI | D40: =D5+E5+D12+E12+D19+E19 -> 79 | F40: =F5+G5+F12+G12+F19+G19 -> 79 | H40: =H5+I5+H12+I12+H19+I19 -> 79 | J40: =J5+K5+J12+K12+J19+K19 -> 72 | L40: =L5+M5+L12+M12+L19+M19 -> 54 | N40: =N5+O5+N12+O12+N19+O19 -> 79 | P40: =P5+Q5+P12+Q12+P19+Q19 -> 82 | R40: =R5+S5+R12+S12+R19+S19 -> 79 | T40: =T5+U5+T12+U12+T19+U19 -> 79 | V40: =V5+W5+V12+W12+V19+W19 -> 79 | X40: =X5+Y5+X12+Y12+X19+Y19 -> 72 | Z40: =Z5+AA5+Z12+AA12+Z19+AA19 -> 54 | AB40: =AB5+AC5+AB12+AC12+AB19+AC19 -> 79 | AD40: =AD5+AE5+AD12+AE12+AD19+AE19 -> 80 | AF40: =AF5+AG5+AF12+AG12+AF19+AG19 -> 79 | AH40: =AH5+AI5+AH12+AI12+AH19+AI19 -> 54 | AJ40: =AJ5+AK5+AJ12+AK12+AJ19+AK19 -> 30 | AL40: =AL5+AM5+AL12+AM12+AL19+AM19 -> 59 | AN40: =AN5+AO5+AN12+AO12+AN19+AO19 -> 54 | AP40: =AP5+AQ5+AP12+AQ12+AP19+AQ19 -> 78 | AR40: =AR5+AS5+AR12+AS12+AR19+AS19 -> 75 | AT40: =AT5+AU5+AT12+AU12+AT19+AU19 -> 80 | AV40: =AV5+AW5+AV12+AW12+AV19+AW19 -> 79 | AX40: =AX5+AY5+AX12+AY12+AX19+AY19 -> 79 | AZ40: =AZ5+BA5+AZ12+BA12+AZ19+BA19 -> 72 | BB40: =BB5+BC5+BB12+BC12+BB19+BC19 -> 54 | BD40: =BD5+BE5+BD12+BE12+BD19+BE19 -> 79 | BF40: =BF5+BG5+BF12+BG12+BF19+BG19 -> 79 | BH40: =BH5+BI5+BH12+BI12+BH19+BI19 -> 79 | BJ40: =BJ5+BK5+BJ12+BK12+BJ19+BK19 -> 79 | BL40: =BL5+BM5+BL12+BM12+BL19+BM19 -> 78
A41: LI - PU | D41: =D8+E8+D15+E15+D22+E22 -> 78 | F41: =F8+G8+F15+G15+F22+G22 -> 78 | H41: =H8+I8+H15+I15+H22+I22 -> 78 | J41: =J8+K8+J15+K15+J22+K22 -> 75 | L41: =L8+M8+L15+M15+L22+M22 -> 57 | N41: =N8+O8+N15+O15+N22+O22 -> 78 | P41: =P8+Q8+P15+Q15+P22+Q22 -> 78 | R41: =R8+S8+R15+S15+R22+S22 -> 78 | T41: =T8+U8+T15+U15+T22+U22 -> 78 | V41: =V8+W8+V15+W15+V22+W22 -> 78 | X41: =X8+Y8+X15+Y15+X22+Y22 -> 75 | Z41: =Z8+AA8+Z15+AA15+Z22+AA22 -> 57 | AB41: =AB8+AC8+AB15+AC15+AB22+AC22 -> 78 | AD41: =AD8+AE8+AD15+AE15+AD22+AE22 -> 78 | AF41: =AF8+AG8+AF15+AG15+AF22+AG22 -> 78 | AH41: =AH8+AI8+AH15+AI15+AH22+AI22 -> 57 | AJ41: =AJ8+AK8+AJ15+AK15+AJ22+AK22 -> 28 | AL41: =AL8+AM8+AL15+AM15+AL22+AM22 -> 62 | AN41: =AN8+AO8+AN15+AO15+AN22+AO22 -> 57 | AP41: =AP8+AQ8+AP15+AQ15+AP22+AQ22 -> 78 | AR41: =AR8+AS8+AR15+AS15+AR22+AS22 -> 73 | AT41: =AT8+AU8+AT15+AU15+AT22+AU22 -> 78 | AV41: =AV8+AW8+AV15+AW15+AV22+AW22 -> 78 | AX41: =AX8+AY8+AX15+AY15+AX22+AY22 -> 78 | AZ41: =AZ8+BA8+AZ15+BA15+AZ22+BA22 -> 75 | BB41: =BB8+BC8+BB15+BC15+BB22+BC22 -> 57 | BD41: =BD8+BE8+BD15+BE15+BD22+BE22 -> 78 | BF41: =BF8+BG8+BF15+BG15+BF22+BG22 -> 78 | BH41: =BH8+BI8+BH15+BI15+BH22+BI22 -> 78 | BJ41: =BJ8+BK8+BJ15+BK15+BJ22+BK22 -> 78 | BL41: =BL8+BM8+BL15+BM15+BL22+BM22 -> 79
A42: PU - SA | D42: =D3+E3+D10+E10+D17+E17 -> 36 | F42: =F3+G3+F10+G10+F17+G17 -> 36 | H42: =H3+I3+H10+I10+H17+I17 -> 36 | J42: =J3+K3+J10+K10+J17+K17 -> 0 | L42: =L3+M3+L10+M10+L17+M17 -> 0 | N42: =N3+O3+N10+O10+N17+O17 -> 34 | P42: =P3+Q3+P10+Q10+P17+Q17 -> 29 | R42: =R3+S3+R10+S10+R17+S17 -> 36 | T42: =T3+U3+T10+U10+T17+U17 -> 36 | V42: =V3+W3+V10+W10+V17+W17 -> 36 | X42: =X3+Y3+X10+Y10+X17+Y17 -> 0 | Z42: =Z3+AA3+Z10+AA10+Z17+AA17 -> 0 | AB42: =AB3+AC3+AB10+AC10+AB17+AC17 -> 36 | AD42: =AD3+AE3+AD10+AE10+AD17+AE17 -> 32 | AF42: =AF3+AG3+AF10+AG10+AF17+AG17 -> 36 | AH42: =AH3+AI3+AH10+AI10+AH17+AI17 -> 0 | AJ42: =AJ3+AK3+AJ10+AK10+AJ17+AK17 -> 9 | AL42: =AL3+AM3+AL10+AM10+AL17+AM17 -> 0 | AN42: =AN3+AO3+AN10+AO10+AN17+AO17 -> 0 | AP42: =AP3+AQ3+AP10+AQ10+AP17+AQ17 -> 8 | AR42: =AR3+AS3+AR10+AS10+AR17+AS17 -> 13 | AT42: =AT3+AU3+AT10+AU10+AT17+AU17 -> 26 | AV42: =AV3+AW3+AV10+AW10+AV17+AW17 -> 34 | AX42: =AX3+AY3+AX10+AY10+AX17+AY17 -> 34 | AZ42: =AZ3+BA3+AZ10+BA10+AZ17+BA17 -> 0 | BB42: =BB3+BC3+BB10+BC10+BB17+BC17 -> 0 | BD42: =BD3+BE3+BD10+BE10+BD17+BE17 -> 33 | BF42: =BF3+BG3+BF10+BG10+BF17+BG17 -> 33 | BH42: =BH3+BI3+BH10+BI10+BH17+BI17 -> 33 | BJ42: =BJ3+BK3+BJ10+BK10+BJ17+BK17 -> 31 | BL42: =BL3+BM3+BL10+BM10+BL17+BM17 -> 14
A43: SA - PU | D43: =D6+E6+D13+E13+D20+E20 -> 32 | F43: =F6+G6+F13+G13+F20+G20 -> 32 | H43: =H6+I6+H13+I13+H20+I20 -> 32 | J43: =J6+K6+J13+K13+J20+K20 -> 0 | L43: =L6+M6+L13+M13+L20+M20 -> 0 | N43: =N6+O6+N13+O13+N20+O20 -> 31 | P43: =P6+Q6+P13+Q13+P20+Q20 -> 29 | R43: =R6+S6+R13+S13+R20+S20 -> 32 | T43: =T6+U6+T13+U13+T20+U20 -> 32 | V43: =V6+W6+V13+W13+V20+W20 -> 32 | X43: =X6+Y6+X13+Y13+X20+Y20 -> 0 | Z43: =Z6+AA6+Z13+AA13+Z20+AA20 -> 0 | AB43: =AB6+AC6+AB13+AC13+AB20+AC20 -> 32 | AD43: =AD6+AE6+AD13+AE13+AD20+AE20 -> 30 | AF43: =AF6+AG6+AF13+AG13+AF20+AG20 -> 32 | AH43: =AH6+AI6+AH13+AI13+AH20+AI20 -> 0 | AJ43: =AJ6+AK6+AJ13+AK13+AJ20+AK20 -> 11 | AL43: =AL6+AM6+AL13+AM13+AL20+AM20 -> 0 | AN43: =AN6+AO6+AN13+AO13+AN20+AO20 -> 0 | AP43: =AP6+AQ6+AP13+AQ13+AP20+AQ20 -> 8 | AR43: =AR6+AS6+AR13+AS13+AR20+AS20 -> 15 | AT43: =AT6+AU6+AT13+AU13+AT20+AU20 -> 26 | AV43: =AV6+AW6+AV13+AW13+AV20+AW20 -> 32 | AX43: =AX6+AY6+AX13+AY13+AX20+AY20 -> 32 | AZ43: =AZ6+BA6+AZ13+BA13+AZ20+BA20 -> 0 | BB43: =BB6+BC6+BB13+BC13+BB20+BC20 -> 0 | BD43: =BD6+BE6+BD13+BE13+BD20+BE20 -> 31 | BF43: =BF6+BG6+BF13+BG13+BF20+BG20 -> 32 | BH43: =BH6+BI6+BH13+BI13+BH20+BI20 -> 32 | BJ43: =BJ6+BK6+BJ13+BK13+BJ20+BK20 -> 30 | BL43: =BL6+BM6+BL13+BM13+BL20+BM20 -> 16
A44: PU-EB | D44: =D4+E4+D11+E11+D18+E18 -> 0 | F44: =F4+G4+F11+G11+F18+G18 -> 0 | H44: =H4+I4+H11+I11+H18+I18 -> 0 | J44: =J4+K4+J11+K11+J18+K18 -> 0 | L44: =L4+M4+L11+M11+L18+M18 -> 0 | N44: =N4+O4+N11+O11+N18+O18 -> 0 | P44: =P4+Q4+P11+Q11+P18+Q18 -> 0 | R44: =R4+S4+R11+S11+R18+S18 -> 0 | T44: =T4+U4+T11+U11+T18+U18 -> 0 | V44: =V4+W4+V11+W11+V18+W18 -> 0 | X44: =X4+Y4+X11+Y11+X18+Y18 -> 0 | Z44: =Z4+AA4+Z11+AA11+Z18+AA18 -> 0 | AB44: =AB4+AC4+AB11+AC11+AB18+AC18 -> 0 | AD44: =AD4+AE4+AD11+AE11+AD18+AE18 -> 0 | AF44: =AF4+AG4+AF11+AG11+AF18+AG18 -> 0 | AH44: =AH4+AI4+AH11+AI11+AH18+AI18 -> 0 | AJ44: =AJ4+AK4+AJ11+AK11+AJ18+AK18 -> 0 | AL44: =AL4+AM4+AL11+AM11+AL18+AM18 -> 0 | AN44: =AN4+AO4+AN11+AO11+AN18+AO18 -> 0 | AP44: =AP4+AQ4+AP11+AQ11+AP18+AQ18 -> 0 | AR44: =AR4+AS4+AR11+AS11+AR18+AS18 -> 0 | AT44: =AT4+AU4+AT11+AU11+AT18+AU18 -> 0 | AV44: =AV4+AW4+AV11+AW11+AV18+AW18 -> 0 | AX44: =AX4+AY4+AX11+AY11+AX18+AY18 -> 0 | AZ44: =AZ4+BA4+AZ11+BA11+AZ18+BA18 -> 0 | BB44: =BB4+BC4+BB11+BC11+BB18+BC18 -> 0 | BD44: =BD4+BE4+BD11+BE11+BD18+BE18 -> 0 | BF44: =BF4+BG4+BF11+BG11+BF18+BG18 -> 0 | BH44: =BH4+BI4+BH11+BI11+BH18+BI18 -> 0 | BJ44: =BJ4+BK4+BJ11+BK11+BJ18+BK18 -> 0 | BL44: =BL4+BM4+BL11+BM11+BL18+BM18 -> 0
A45: EB-PU | D45: =D7+E7+D14+E14+D21+E21 -> 4 | F45: =F7+G7+F14+G14+F21+G21 -> 4 | H45: =H7+I7+H14+I14+H21+I21 -> 4 | J45: =J7+K7+J14+K14+J21+K21 -> 0 | L45: =L7+M7+L14+M14+L21+M21 -> 0 | N45: =N7+O7+N14+O14+N21+O21 -> 4 | P45: =P7+Q7+P14+Q14+P21+Q21 -> 4 | R45: =R7+S7+R14+S14+R21+S21 -> 4 | T45: =T7+U7+T14+U14+T21+U21 -> 4 | V45: =V7+W7+V14+W14+V21+W21 -> 4 | X45: =X7+Y7+X14+Y14+X21+Y21 -> 0 | Z45: =Z7+AA7+Z14+AA14+Z21+AA21 -> 0 | AB45: =AB7+AC7+AB14+AC14+AB21+AC21 -> 4 | AD45: =AD7+AE7+AD14+AE14+AD21+AE21 -> 5 | AF45: =AF7+AG7+AF14+AG14+AF21+AG21 -> 4 | AH45: =AH7+AI7+AH14+AI14+AH21+AI21 -> 0 | AJ45: =AJ7+AK7+AJ14+AK14+AJ21+AK21 -> 1 | AL45: =AL7+AM7+AL14+AM14+AL21+AM21 -> 0 | AN45: =AN7+AO7+AN14+AO14+AN21+AO21 -> 0 | AP45: =AP7+AQ7+AP14+AQ14+AP21+AQ21 -> 1 | AR45: =AR7+AS7+AR14+AS14+AR21+AS21 -> 1 | AT45: =AT7+AU7+AT14+AU14+AT21+AU21 -> 1 | AV45: =AV7+AW7+AV14+AW14+AV21+AW21 -> 2 | AX45: =AX7+AY7+AX14+AY14+AX21+AY21 -> 2 | AZ45: =AZ7+BA7+AZ14+BA14+AZ21+BA21 -> 0 | BB45: =BB7+BC7+BB14+BC14+BB21+BC21 -> 0 | BD45: =BD7+BE7+BD14+BE14+BD21+BE21 -> 2 | BF45: =BF7+BG7+BF14+BG14+BF21+BG21 -> 1 | BH45: =BH7+BI7+BH14+BI14+BH21+BI21 -> 1 | BJ45: =BJ7+BK7+BJ14+BK14+BJ21+BK21 -> 2 | BL45: =BL7+BM7+BL14+BM14+BL21+BM21 -> 1
A47: Trenes
A48: PU - LI | D48: =(D5+D12+D19)+2*(E5+E12+E19) -> 120 | F48: =(F5+F12+F19)+2*(G5+G12+G19) -> 119 | H48: =(H5+H12+H19)+2*(I5+I12+I19) -> 118 | J48: =(J5+J12+J19)+2*(K5+K12+K19) -> 75 | L48: =(L5+L12+L19)+2*(M5+M12+M19) -> 57 | N48: =(N5+N12+N19)+2*(O5+O12+O19) -> 118 | P48: =(P5+P12+P19)+2*(Q5+Q12+Q19) -> 122 | R48: =(R5+R12+R19)+2*(S5+S12+S19) -> 117 | T48: =(T5+T12+T19)+2*(U5+U12+U19) -> 109 | V48: =(V5+V12+V19)+2*(W5+W12+W19) -> 109 | X48: =(X5+X12+X19)+2*(Y5+Y12+Y19) -> 75 | Z48: =(Z5+Z12+Z19)+2*(AA5+AA12+AA19) -> 57 | AB48: =(AB5+AB12+AB19)+2*(AC5+AC12+AC19) -> 110 | AD48: =(AD5+AD12+AD19)+2*(AE5+AE12+AE19) -> 112 | AF48: =(AF5+AF12+AF19)+2*(AG5+AG12+AG19) -> 109 | AH48: =(AH5+AH12+AH19)+2*(AI5+AI12+AI19) -> 57 | AJ48: =(AJ5+AJ12+AJ19)+2*(AK5+AK12+AK19) -> 31 | AL48: =(AL5+AL12+AL19)+2*(AM5+AM12+AM19) -> 59 | AN48: =(AN5+AN12+AN19)+2*(AO5+AO12+AO19) -> 58 | AP48: =(AP5+AP12+AP19)+2*(AQ5+AQ12+AQ19) -> 92 | AR48: =(AR5+AR12+AR19)+2*(AS5+AS12+AS19) -> 90 | AT48: =(AT5+AT12+AT19)+2*(AU5+AU12+AU19) -> 105 | AV48: =(AV5+AV12+AV19)+2*(AW5+AW12+AW19) -> 103 | AX48: =(AX5+AX12+AX19)+2*(AY5+AY12+AY19) -> 105 | AZ48: =(AZ5+AZ12+AZ19)+2*(BA5+BA12+BA19) -> 75 | BB48: =(BB5+BB12+BB19)+2*(BC5+BC12+BC19) -> 57 | BD48: =(BD5+BD12+BD19)+2*(BE5+BE12+BE19) -> 97 | BF48: =(BF5+BF12+BF19)+2*(BG5+BG12+BG19) -> 105 | BH48: =(BH5+BH12+BH19)+2*(BI5+BI12+BI19) -> 105 | BJ48: =(BJ5+BJ12+BJ19)+2*(BK5+BK12+BK19) -> 104 | BL48: =(BL5+BL12+BL19)+2*(BM5+BM12+BM19) -> 94
A49: LI - PU | D49: =(D8+D15+D22)+2*(E8+E15+E22) -> 120 | F49: =(F8+F15+F22)+2*(G8+G15+G22) -> 119 | H49: =(H8+H15+H22)+2*(I8+I15+I22) -> 118 | J49: =(J8+J15+J22)+2*(K8+K15+K22) -> 75 | L49: =(L8+L15+L22)+2*(M8+M15+M22) -> 57 | N49: =(N8+N15+N22)+2*(O8+O15+O22) -> 118 | P49: =(P8+P15+P22)+2*(Q8+Q15+Q22) -> 118 | R49: =(R8+R15+R22)+2*(S8+S15+S22) -> 117 | T49: =(T8+T15+T22)+2*(U8+U15+U22) -> 109 | V49: =(V8+V15+V22)+2*(W8+W15+W22) -> 109 | X49: =(X8+X15+X22)+2*(Y8+Y15+Y22) -> 75 | Z49: =(Z8+Z15+Z22)+2*(AA8+AA15+AA22) -> 57 | AB49: =(AB8+AB15+AB22)+2*(AC8+AC15+AC22) -> 110 | AD49: =(AD8+AD15+AD22)+2*(AE8+AE15+AE22) -> 109 | AF49: =(AF8+AF15+AF22)+2*(AG8+AG15+AG22) -> 109 | AH49: =(AH8+AH15+AH22)+2*(AI8+AI15+AI22) -> 57 | AJ49: =(AJ8+AJ15+AJ22)+2*(AK8+AK15+AK22) -> 28 | AL49: =(AL8+AL15+AL22)+2*(AM8+AM15+AM22) -> 62 | AN49: =(AN8+AN15+AN22)+2*(AO8+AO15+AO22) -> 58 | AP49: =(AP8+AP15+AP22)+2*(AQ8+AQ15+AQ22) -> 90 | AR49: =(AR8+AR15+AR22)+2*(AS8+AS15+AS22) -> 86 | AT49: =(AT8+AT15+AT22)+2*(AU8+AU15+AU22) -> 104 | AV49: =(AV8+AV15+AV22)+2*(AW8+AW15+AW22) -> 103 | AX49: =(AX8+AX15+AX22)+2*(AY8+AY15+AY22) -> 105 | AZ49: =(AZ8+AZ15+AZ22)+2*(BA8+BA15+BA22) -> 75 | BB49: =(BB8+BB15+BB22)+2*(BC8+BC15+BC22) -> 57 | BD49: =(BD8+BD15+BD22)+2*(BE8+BE15+BE22) -> 97 | BF49: =(BF8+BF15+BF22)+2*(BG8+BG15+BG22) -> 105 | BH49: =(BH8+BH15+BH22)+2*(BI8+BI15+BI22) -> 105 | BJ49: =(BJ8+BJ15+BJ22)+2*(BK8+BK15+BK22) -> 103 | BL49: =(BL8+BL15+BL22)+2*(BM8+BM15+BM22) -> 98
A50: PU - SA | D50: =(D3+D10+D17)+2*(E3+E10+E17) -> 39 | F50: =(F3+F10+F17)+2*(G3+G10+G17) -> 38 | H50: =(H3+H10+H17)+2*(I3+I10+I17) -> 38 | J50: =(J3+J10+J17)+2*(K3+K10+K17) -> 0 | L50: =(L3+L10+L17)+2*(M3+M10+M17) -> 0 | N50: =(N3+N10+N17)+2*(O3+O10+O17) -> 36 | P50: =(P3+P10+P17)+2*(Q3+Q10+Q17) -> 31 | R50: =(R3+R10+R17)+2*(S3+S10+S17) -> 38 | T50: =(T3+T10+T17)+2*(U3+U10+U17) -> 36 | V50: =(V3+V10+V17)+2*(W3+W10+W17) -> 36 | X50: =(X3+X10+X17)+2*(Y3+Y10+Y17) -> 0 | Z50: =(Z3+Z10+Z17)+2*(AA3+AA10+AA17) -> 0 | AB50: =(AB3+AB10+AB17)+2*(AC3+AC10+AC17) -> 36 | AD50: =(AD3+AD10+AD17)+2*(AE3+AE10+AE17) -> 32 | AF50: =(AF3+AF10+AF17)+2*(AG3+AG10+AG17) -> 36 | AH50: =(AH3+AH10+AH17)+2*(AI3+AI10+AI17) -> 0 | AJ50: =(AJ3+AJ10+AJ17)+2*(AK3+AK10+AK17) -> 9 | AL50: =(AL3+AL10+AL17)+2*(AM3+AM10+AM17) -> 0 | AN50: =(AN3+AN10+AN17)+2*(AO3+AO10+AO17) -> 0 | AP50: =(AP3+AP10+AP17)+2*(AQ3+AQ10+AQ17) -> 8 | AR50: =(AR3+AR10+AR17)+2*(AS3+AS10+AS17) -> 14 | AT50: =(AT3+AT10+AT17)+2*(AU3+AU10+AU17) -> 26 | AV50: =(AV3+AV10+AV17)+2*(AW3+AW10+AW17) -> 34 | AX50: =(AX3+AX10+AX17)+2*(AY3+AY10+AY17) -> 34 | AZ50: =(AZ3+AZ10+AZ17)+2*(BA3+BA10+BA17) -> 0 | BB50: =(BB3+BB10+BB17)+2*(BC3+BC10+BC17) -> 0 | BD50: =(BD3+BD10+BD17)+2*(BE3+BE10+BE17) -> 33 | BF50: =(BF3+BF10+BF17)+2*(BG3+BG10+BG17) -> 33 | BH50: =(BH3+BH10+BH17)+2*(BI3+BI10+BI17) -> 33 | BJ50: =(BJ3+BJ10+BJ17)+2*(BK3+BK10+BK17) -> 32 | BL50: =(BL3+BL10+BL17)+2*(BM3+BM10+BM17) -> 16
A51: SA - PU | D51: =(D6+D13+D20)+2*(E6+E13+E20) -> 35 | F51: =(F6+F13+F20)+2*(G6+G13+G20) -> 34 | H51: =(H6+H13+H20)+2*(I6+I13+I20) -> 34 | J51: =(J6+J13+J20)+2*(K6+K13+K20) -> 0 | L51: =(L6+L13+L20)+2*(M6+M13+M20) -> 0 | N51: =(N6+N13+N20)+2*(O6+O13+O20) -> 33 | P51: =(P6+P13+P20)+2*(Q6+Q13+Q20) -> 31 | R51: =(R6+R13+R20)+2*(S6+S13+S20) -> 34 | T51: =(T6+T13+T20)+2*(U6+U13+U20) -> 32 | V51: =(V6+V13+V20)+2*(W6+W13+W20) -> 32 | X51: =(X6+X13+X20)+2*(Y6+Y13+Y20) -> 0 | Z51: =(Z6+Z13+Z20)+2*(AA6+AA13+AA20) -> 0 | AB51: =(AB6+AB13+AB20)+2*(AC6+AC13+AC20) -> 32 | AD51: =(AD6+AD13+AD20)+2*(AE6+AE13+AE20) -> 30 | AF51: =(AF6+AF13+AF20)+2*(AG6+AG13+AG20) -> 32 | AH51: =(AH6+AH13+AH20)+2*(AI6+AI13+AI20) -> 0 | AJ51: =(AJ6+AJ13+AJ20)+2*(AK6+AK13+AK20) -> 11 | AL51: =(AL6+AL13+AL20)+2*(AM6+AM13+AM20) -> 0 | AN51: =(AN6+AN13+AN20)+2*(AO6+AO13+AO20) -> 0 | AP51: =(AP6+AP13+AP20)+2*(AQ6+AQ13+AQ20) -> 9 | AR51: =(AR6+AR13+AR20)+2*(AS6+AS13+AS20) -> 16 | AT51: =(AT6+AT13+AT20)+2*(AU6+AU13+AU20) -> 26 | AV51: =(AV6+AV13+AV20)+2*(AW6+AW13+AW20) -> 32 | AX51: =(AX6+AX13+AX20)+2*(AY6+AY13+AY20) -> 32 | AZ51: =(AZ6+AZ13+AZ20)+2*(BA6+BA13+BA20) -> 0 | BB51: =(BB6+BB13+BB20)+2*(BC6+BC13+BC20) -> 0 | BD51: =(BD6+BD13+BD20)+2*(BE6+BE13+BE20) -> 31 | BF51: =(BF6+BF13+BF20)+2*(BG6+BG13+BG20) -> 32 | BH51: =(BH6+BH13+BH20)+2*(BI6+BI13+BI20) -> 32 | BJ51: =(BJ6+BJ13+BJ20)+2*(BK6+BK13+BK20) -> 30 | BL51: =(BL6+BL13+BL20)+2*(BM6+BM13+BM20) -> 17
A52: PU-EB | D52: =(D4+D11+D18)+2*(E4+E11+E18) -> 0 | F52: =(F4+F11+F18)+2*(G4+G11+G18) -> 0 | H52: =(H4+H11+H18)+2*(I4+I11+I18) -> 0 | J52: =(J4+J11+J18)+2*(K4+K11+K18) -> 0 | L52: =(L4+L11+L18)+2*(M4+M11+M18) -> 0 | N52: =(N4+N11+N18)+2*(O4+O11+O18) -> 0 | P52: =(P4+P11+P18)+2*(Q4+Q11+Q18) -> 0 | R52: =(R4+R11+R18)+2*(S4+S11+S18) -> 0 | T52: =(T4+T11+T18)+2*(U4+U11+U18) -> 0 | V52: =(V4+V11+V18)+2*(W4+W11+W18) -> 0 | X52: =(X4+X11+X18)+2*(Y4+Y11+Y18) -> 0 | Z52: =(Z4+Z11+Z18)+2*(AA4+AA11+AA18) -> 0 | AB52: =(AB4+AB11+AB18)+2*(AC4+AC11+AC18) -> 0 | AD52: =(AD4+AD11+AD18)+2*(AE4+AE11+AE18) -> 0 | AF52: =(AF4+AF11+AF18)+2*(AG4+AG11+AG18) -> 0 | AH52: =(AH4+AH11+AH18)+2*(AI4+AI11+AI18) -> 0 | AJ52: =(AJ4+AJ11+AJ18)+2*(AK4+AK11+AK18) -> 0 | AL52: =(AL4+AL11+AL18)+2*(AM4+AM11+AM18) -> 0 | AN52: =(AN4+AN11+AN18)+2*(AO4+AO11+AO18) -> 0 | AP52: =(AP4+AP11+AP18)+2*(AQ4+AQ11+AQ18) -> 0 | AR52: =(AR4+AR11+AR18)+2*(AS4+AS11+AS18) -> 0 | AT52: =(AT4+AT11+AT18)+2*(AU4+AU11+AU18) -> 0 | AV52: =(AV4+AV11+AV18)+2*(AW4+AW11+AW18) -> 0 | AX52: =(AX4+AX11+AX18)+2*(AY4+AY11+AY18) -> 0 | AZ52: =(AZ4+AZ11+AZ18)+2*(BA4+BA11+BA18) -> 0 | BB52: =(BB4+BB11+BB18)+2*(BC4+BC11+BC18) -> 0 | BD52: =(BD4+BD11+BD18)+2*(BE4+BE11+BE18) -> 0 | BF52: =(BF4+BF11+BF18)+2*(BG4+BG11+BG18) -> 0 | BH52: =(BH4+BH11+BH18)+2*(BI4+BI11+BI18) -> 0 | BJ52: =(BJ4+BJ11+BJ18)+2*(BK4+BK11+BK18) -> 0 | BL52: =(BL4+BL11+BL18)+2*(BM4+BM11+BM18) -> 0
A53: EB-PU | D53: =(D7+D14+D21)+2*(E7+E14+E21) -> 4 | F53: =(F7+F14+F21)+2*(G7+G14+G21) -> 4 | H53: =(H7+H14+H21)+2*(I7+I14+I21) -> 4 | J53: =(J7+J14+J21)+2*(K7+K14+K21) -> 0 | L53: =(L7+L14+L21)+2*(M7+M14+M21) -> 0 | N53: =(N7+N14+N21)+2*(O7+O14+O21) -> 4 | P53: =(P7+P14+P21)+2*(Q7+Q14+Q21) -> 4 | R53: =(R7+R14+R21)+2*(S7+S14+S21) -> 4 | T53: =(T7+T14+T21)+2*(U7+U14+U21) -> 4 | V53: =(V7+V14+V21)+2*(W7+W14+W21) -> 4 | X53: =(X7+X14+X21)+2*(Y7+Y14+Y21) -> 0 | Z53: =(Z7+Z14+Z21)+2*(AA7+AA14+AA21) -> 0 | AB53: =(AB7+AB14+AB21)+2*(AC7+AC14+AC21) -> 4 | AD53: =(AD7+AD14+AD21)+2*(AE7+AE14+AE21) -> 5 | AF53: =(AF7+AF14+AF21)+2*(AG7+AG14+AG21) -> 4 | AH53: =(AH7+AH14+AH21)+2*(AI7+AI14+AI21) -> 0 | AJ53: =(AJ7+AJ14+AJ21)+2*(AK7+AK14+AK21) -> 1 | AL53: =(AL7+AL14+AL21)+2*(AM7+AM14+AM21) -> 0 | AN53: =(AN7+AN14+AN21)+2*(AO7+AO14+AO21) -> 0 | AP53: =(AP7+AP14+AP21)+2*(AQ7+AQ14+AQ21) -> 1 | AR53: =(AR7+AR14+AR21)+2*(AS7+AS14+AS21) -> 1 | AT53: =(AT7+AT14+AT21)+2*(AU7+AU14+AU21) -> 1 | AV53: =(AV7+AV14+AV21)+2*(AW7+AW14+AW21) -> 2 | AX53: =(AX7+AX14+AX21)+2*(AY7+AY14+AY21) -> 2 | AZ53: =(AZ7+AZ14+AZ21)+2*(BA7+BA14+BA21) -> 0 | BB53: =(BB7+BB14+BB21)+2*(BC7+BC14+BC21) -> 0 | BD53: =(BD7+BD14+BD21)+2*(BE7+BE14+BE21) -> 2 | BF53: =(BF7+BF14+BF21)+2*(BG7+BG14+BG21) -> 1 | BH53: =(BH7+BH14+BH21)+2*(BI7+BI14+BI21) -> 1 | BJ53: =(BJ7+BJ14+BJ21)+2*(BK7+BK14+BK21) -> 2 | BL53: =(BL7+BL14+BL21)+2*(BM7+BM14+BM21) -> 1

Sheet Oferta Diaria
A1: Oferta Julio 2026
C3: 46204 | D3: 46205 | E3: 46206 | F3: 46207 | G3: 46208 | H3: 46209 | I3: 46210 | J3: 46211 | K3: 46212 | L3: 46213 | M3: 46214 | N3: 46215 | O3: 46216 | P3: 46217 | Q3: 46218 | R3: 46219 | S3: 46220 | T3: 46221 | U3: 46222 | V3: 46223 | W3: 46224 | X3: 46225 | Y3: 46226 | Z3: 46227 | AA3: 46228 | AB3: 46229 | AC3: 46230 | AD3: 46231 | AE3: 46232 | AF3: 46233 | AG3: 46234
A4: HÁBIL | B4: km
A5: Servicios PU-LI | B5: 43.13 | C5: ='Data Ocupacion'!D40 -> 79 | D5: ='Data Ocupacion'!F40 -> 79 | E5: ='Data Ocupacion'!H40 -> 79 | F5: ='Data Ocupacion'!J40 -> 72 | G5: ='Data Ocupacion'!L40 -> 54 | H5: ='Data Ocupacion'!N40 -> 79 | I5: ='Data Ocupacion'!P40 -> 82 | J5: ='Data Ocupacion'!R40 -> 79 | K5: ='Data Ocupacion'!T40 -> 79 | L5: ='Data Ocupacion'!V40 -> 79 | M5: ='Data Ocupacion'!X40 -> 72 | N5: ='Data Ocupacion'!Z40 -> 54 | O5: ='Data Ocupacion'!AB40 -> 79 | P5: ='Data Ocupacion'!AD40 -> 80 | Q5: ='Data Ocupacion'!AF40 -> 79 | R5: ='Data Ocupacion'!AH40 -> 54 | S5: ='Data Ocupacion'!AJ40 -> 30 | T5: ='Data Ocupacion'!AL40 -> 59 | U5: ='Data Ocupacion'!AN40 -> 54 | V5: ='Data Ocupacion'!AP40 -> 78 | W5: ='Data Ocupacion'!AR40 -> 75 | X5: ='Data Ocupacion'!AT40 -> 80 | Y5: ='Data Ocupacion'!AV40 -> 79 | Z5: ='Data Ocupacion'!AX40 -> 79 | AA5: ='Data Ocupacion'!AZ40 -> 72 | AB5: ='Data Ocupacion'!BB40 -> 54 | AC5: ='Data Ocupacion'!BD40 -> 79 | AD5: ='Data Ocupacion'!BF40 -> 79 | AE5: ='Data Ocupacion'!BH40 -> 79 | AF5: ='Data Ocupacion'!BJ40 -> 79 | AG5: ='Data Ocupacion'!BL40 -> 78
A6: Servicios LI-PU | B6: 43.13 | C6: ='Data Ocupacion'!D41 -> 78 | D6: ='Data Ocupacion'!F41 -> 78 | E6: ='Data Ocupacion'!H41 -> 78 | F6: ='Data Ocupacion'!J41 -> 75 | G6: ='Data Ocupacion'!L41 -> 57 | H6: ='Data Ocupacion'!N41 -> 78 | I6: ='Data Ocupacion'!P41 -> 78 | J6: ='Data Ocupacion'!R41 -> 78 | K6: ='Data Ocupacion'!T41 -> 78 | L6: ='Data Ocupacion'!V41 -> 78 | M6: ='Data Ocupacion'!X41 -> 75 | N6: ='Data Ocupacion'!Z41 -> 57 | O6: ='Data Ocupacion'!AB41 -> 78 | P6: ='Data Ocupacion'!AD41 -> 78 | Q6: ='Data Ocupacion'!AF41 -> 78 | R6: ='Data Ocupacion'!AH41 -> 57 | S6: ='Data Ocupacion'!AJ41 -> 28 | T6: ='Data Ocupacion'!AL41 -> 62 | U6: ='Data Ocupacion'!AN41 -> 57 | V6: ='Data Ocupacion'!AP41 -> 78 | W6: ='Data Ocupacion'!AR41 -> 73 | X6: ='Data Ocupacion'!AT41 -> 78 | Y6: ='Data Ocupacion'!AV41 -> 78 | Z6: ='Data Ocupacion'!AX41 -> 78 | AA6: ='Data Ocupacion'!AZ41 -> 75 | AB6: ='Data Ocupacion'!BB41 -> 57 | AC6: ='Data Ocupacion'!BD41 -> 78 | AD6: ='Data Ocupacion'!BF41 -> 78 | AE6: ='Data Ocupacion'!BH41 -> 78 | AF6: ='Data Ocupacion'!BJ41 -> 78 | AG6: ='Data Ocupacion'!BL41 -> 79
A7: Servicios PU-SA | B7: 29.11 | C7: ='Data Ocupacion'!D42 -> 36 | D7: ='Data Ocupacion'!F42 -> 36 | E7: ='Data Ocupacion'!H42 -> 36 | F7: ='Data Ocupacion'!J42 -> 0 | G7: ='Data Ocupacion'!L42 -> 0 | H7: ='Data Ocupacion'!N42 -> 34 | I7: ='Data Ocupacion'!P42 -> 29 | J7: ='Data Ocupacion'!R42 -> 36 | K7: ='Data Ocupacion'!T42 -> 36 | L7: ='Data Ocupacion'!V42 -> 36 | M7: ='Data Ocupacion'!X42 -> 0 | N7: ='Data Ocupacion'!Z42 -> 0 | O7: ='Data Ocupacion'!AB42 -> 36 | P7: ='Data Ocupacion'!AD42 -> 32 | Q7: ='Data Ocupacion'!AF42 -> 36 | R7: ='Data Ocupacion'!AH42 -> 0 | S7: ='Data Ocupacion'!AJ42 -> 9 | T7: ='Data Ocupacion'!AL42 -> 0 | U7: ='Data Ocupacion'!AN42 -> 0 | V7: ='Data Ocupacion'!AP42 -> 8 | W7: ='Data Ocupacion'!AR42 -> 13 | X7: ='Data Ocupacion'!AT42 -> 26 | Y7: ='Data Ocupacion'!AV42 -> 34 | Z7: ='Data Ocupacion'!AX42 -> 34 | AA7: ='Data Ocupacion'!AZ42 -> 0 | AB7: ='Data Ocupacion'!BB42 -> 0 | AC7: ='Data Ocupacion'!BD42 -> 33 | AD7: ='Data Ocupacion'!BF42 -> 33 | AE7: ='Data Ocupacion'!BH42 -> 33 | AF7: ='Data Ocupacion'!BJ42 -> 31 | AG7: ='Data Ocupacion'!BL42 -> 14
