Workbook

Sheet Odometro-Kilometraje
A1: Control Contador Kilometraje de Trenes
B2: 45689 | C2: 45690 | D2: 45691 | E2: 45692 | F2: 45693 | G2: 45694 | H2: 45695 | I2: 45696 | J2: 45697 | K2: 45698 | L2: 45699 | M2: 45700 | N2: 45701 | O2: 45702 | P2: 45703 | Q2: 45704 | R2: 45705 | S2: 45706 | T2: 45707 | U2: 45708 | V2: 45709 | W2: 45710 | X2: 45711 | Y2: 45712 | Z2: 45713 | AA2: 45714 | AB2: 45715 | AC2: 45716
B3: Contador | C3: Contador | D3: Contador | E3: Contador | F3: Contador | G3: Contador | H3: Contador | I3: Contador | J3: Contador | K3: Contador | L3: Contador | M3: Contador | N3: Contador | O3: Contador | P3: Contador | Q3: Contador | R3: Contador | S3: Contador | T3: Contador | U3: Contador | V3: Contador | W3: Contador | X3: Contador | Y3: Contador | Z3: Contador | AA3: Contador | AB3: Contador | AC3: Contador
A4: Tren | B4: Odómetro | C4: Odómetro | D4: Odómetro | E4: Odómetro | F4: Odómetro | G4: Odómetro | H4: Odómetro | I4: Odómetro | J4: Odómetro | K4: Odómetro | L4: Odómetro | M4: Odómetro | N4: Odómetro | O4: Odómetro | P4: Odómetro | Q4: Odómetro | R4: Odómetro | S4: Odómetro | T4: Odómetro | U4: Odómetro | V4: Odómetro | W4: Odómetro | X4: Odómetro | Y4: Odómetro | Z4: Odómetro | AA4: Odómetro | AB4: Odómetro | AC4: Odómetro
A5: M01 | B5: 1980652 | C5: 1980652 | D5: 1980843 | E5: 1980845 | F5: 1981012 | G5: 1981615 | H5: 1982175 | I5: 1982691 | J5: 1983036 | K5: 1983231 | L5: 1983740 | M5: 1984190 | N5: 1984271 | O5: 1984409 | P5: 1984409 | Q5: 1984409 | R5: 1984412 | S5: 1984611 | T5: 1985128 | U5: 1985563 | V5: 1985875 | W5: 1985875 | X5: 1985875 | Y5: 1986461 | Z5: 1986482 | AA5: 1986673 | AB5: 1986924 | AC5: 1987509
A6: M02 | B6: 1968063 | C6: 1968169 | D6: 1968715 | E6: 1968893 | F6: 1969045 | G6: 1969236 | H6: 1969427 | I6: 1969427 | J6: 1969427 | K6: 1970015 | L6: 1970577 | M6: 1970771 | N6: 1971358 | O6: 1971919 | P6: 1971962 | Q6: 1972439 | R6: 1973000 | S6: 1973152 | T6: 1973404 | U6: 1973602 | V6: 1973629 | W6: 1973629 | X6: 1973629 | Y6: 1973629 | Z6: 1973629 | AA6: 1973629 | AB6: 1973650 | AC6: 1973652
A7: M03 | B7: 2032577 | C7: 2033095 | D7: 2033613 | E7: 2034217 | F7: 2034217 | G7: 2034498 | H7: 2034590 | I7: 2035109 | J7: 2035456 | K7: 2036017 | L7: 2036080 | M7: 2036212 | N7: 2036463 | O7: 2036622 | P7: 2037186 | Q7: 2037229 | R7: 2037834 | S7: 2038441 | T7: 2039002 | U7: 2039563 | V7: 2039929 | W7: 2040103 | X7: 2040469 | Y7: 2040636 | Z7: 2040914 | AA7: 2041192 | AB7: 2041624 | AC7: 2041887
A8: M04 | B8: 2038412 | C8: 2038412 | D8: 2038436 | E8: 2038436 | F8: 2038436 | G8: 2038436 | H8: 2038436 | I8: 2038436 | J8: 2038436 | K8: 2038783 | L8: 2039388 | M8: 2039760 | N8: 2039893 | O8: 2040178 | P8: 2040740 | Q8: 2041219 | R8: 2041784 | S8: 2041915 | T8: 2041916 | U8: 2041937 | V8: 2042128 | W8: 2042128 | X8: 2042363 | Y8: 2042838 | Z8: 2043057 | AA8: 2043534 | AB8: 2043685 | AC8: 2043937
A9: M05 | B9: 1946383 | C9: 1946383 | D9: 1946463 | E9: 1946680 | F9: 1946931 | G9: 1947519 | H9: 1947971 | I9: 1947971 | J9: 1947971 | K9: 1947971 | L9: 1948225 | M9: 1948477 | N9: 1948557 | O9: 1948557 | P9: 1948557 | Q9: 1948557 | R9: 1948579 | S9: 1948659 | T9: 1948679 | U9: 1948931 | V9: 1949459 | W9: 1950021 | X9: 1950538 | Y9: 1951214 | Z9: 1951372 | AA9: 1951825 | AB9: 1952030 | AC9: 1952281
A10: M06 | B10: 2054640 | C10: 2054640 | D10: 2054891 | E10: 2055494 | F10: 2056054 | G10: 2056248 | H10: 2056507 | I10: 2057024 | J10: 2057196 | K10: 2057715 | L10: 2057951 | M10: 2058453 | N10: 2058473 | O10: 2058475 | P10: 2058475 | Q10: 2058475 | R10: 2058614 | S10: 2059047 | T10: 2059420 | U10: 2059560 | V10: 2060036 | W10: 2060596 | X10: 2061113 | Y10: 2061634 | Z10: 2061767 | AA10: 2062353 | AB10: 2063028 | AC10: 2063615
A11: M07 | B11: 2083331 | C11: 2083333 | D11: 2083735 | E11: 2083736 | F11: 2083928 | G11: 2084182 | H11: 2084442 | I11: 2084794 | J11: 2084797 | K11: 2084888 | L11: 2084892 | M11: 2085025 | N11: 2085589 | O11: 2085593 | P11: 2086117 | Q11: 2086597 | R11: 2086662 | S11: 2086742 | T11: 2087003 | U11: 2087610 | V11: 2087901 | W11: 2087901 | X11: 2088137 | Y11: 2088632 | Z11: 2088632 | AA11: 2088982 | AB11: 2089506 | AC11: 2089640
A12: M08 | B12: 1988125 | C12: 1988645 | D12: 1988991 | E12: 1989081 | F12: 1989642 | G12: 1990049 | H12: 1990122 | I12: 1990122 | J12: 1990122 | K12: 1990357 | L12: 1990490 | M12: 1990974 | N12: 1991492 | O12: 1991512 | P12: 1991512 | Q12: 1991533 | R12: 1991536 | S12: 1992012 | T12: 1992617 | U12: 1992679 | V12: 1992870 | W12: 1992870 | X12: 1992870 | Y12: 1993121 | Z12: 1993449 | AA12: 1993601 | AB12: 1994188 | AC12: 1994451
A13: M09 | B13: 1971688 | C13: 1971688 | D13: 1972091 | E13: 1972172 | F13: 1972333 | G13: 1972336 | H13: 1972599 | I13: 1972762 | J13: 1973113 | K13: 1973533 | L13: 1973790 | M13: 1973831 | N13: 1974359 | O13: 1974975 | P13: 1974978 | Q13: 1975419 | R13: 1975857 | S13: 1976385 | T13: 1976741 | U13: 1976761 | V13: 1976763 | W13: 1976763 | X13: 1976763 | Y13: 1977018 | Z13: 1977222 | AA13: 1977313 | AB13: 1977909 | AC13: 1978420
A14: M10 | B14: 2048160 | C14: 2048204 | D14: 2048692 | E14: 2048956 | F14: 2049220 | G14: 2049420 | H14: 2049899 | I14: 2049942 | J14: 2050031 | K14: 2050034 | L14: 2050468 | M14: 2051033 | N14: 2051510 | O14: 2051650 | P14: 2051650 | Q14: 2051650 | R14: 2051931 | S14: 2052496 | T14: 2052630 | U14: 2053191 | V14: 2053752 | W14: 2054312 | X14: 2054528 | Y14: 2054679 | Z14: 2054806 | AA14: 2055199 | AB14: 2055351 | AC14: 2055614
A15: M11 | B15: 2063983 | C15: 2064460 | D15: 2065005 | E15: 2065208 | F15: 2065730 | G15: 2066250 | H15: 2066859 | I15: 2067380 | J15: 2067559 | K15: 2067719 | L15: 2067809 | M15: 2067812 | N15: 2067813 | O15: 2067813 | P15: 2067813 | Q15: 2067813 | R15: 2068094 | S15: 2068227 | T15: 2068481 | U15: 2068883 | V15: 2069490 | W15: 2070010 | X15: 2070376 | Y15: 2070517 | Z15: 2070641 | AA15: 2070870 | AB15: 2071131 | AC15: 2071551
A16: M12 | B16: 1905739 | C16: 1906257 | D16: 1906346 | E16: 1906479 | F16: 1906807 | G16: 1906888 | H16: 1906909 | I16: 1906909 | J16: 1906909 | K16: 1906988 | L16: 1907078 | M16: 1907254 | N16: 1907254 | O16: 1907335 | P16: 1907335 | Q16: 1907355 | R16: 1907502 | S16: 1908021 | T16: 1908291 | U16: 1908542 | V16: 1908794 | W16: 1908794 | X16: 1908794 | Y16: 1909194 | Z16: 1909612 | AA16: 1910063 | AB16: 1910341 | AC16: 1910972
... A39: XM35 | B39: 641961 | C39: 642392 | D39: 642479 | E39: 642479 | F39: 642479 | G39: 642500 | H39: 642501 | I39: 642501 | J39: 642501 | K39: 642985 | L39: 643418 | M39: 643982 | N39: 644389 | O39: 644391 | P39: 644391 | Q39: 644391 | R39: 644589 | S39: 644590 | T39: 644590 | U39: 644591 | V39: 644591 | W39: 644591 | X39: 644767 | Y39: 645284 | Z39: 645306 | AA39: 645437 | AB39: 645687 | AC39: 645879
A41: Kilometraje Diario Recorrido
B42: 45689 | C42: 45690 | D42: 45691 | E42: 45692 | F42: 45693 | G42: 45694 | H42: 45695 | I42: 45696 | J42: 45697 | K42: 45698 | L42: 45699 | M42: 45700 | N42: 45701 | O42: 45702 | P42: 45703 | Q42: 45704 | R42: 45705 | S42: 45706 | T42: 45707 | U42: 45708 | V42: 45709 | W42: 45710 | X42: 45711 | Y42: 45712 | Z42: 45713 | AA42: 45714 | AB42: 45715 | AC42: 45716
B43: Kilometraje | C43: Kilometraje | D43: Kilometraje | E43: Kilometraje | F43: Kilometraje | G43: Kilometraje | H43: Kilometraje | I43: Kilometraje | J43: Kilometraje | K43: Kilometraje | L43: Kilometraje | M43: Kilometraje | N43: Kilometraje | O43: Kilometraje | P43: Kilometraje | Q43: Kilometraje | R43: Kilometraje | S43: Kilometraje | T43: Kilometraje | U43: Kilometraje | V43: Kilometraje | W43: Kilometraje | X43: Kilometraje | Y43: Kilometraje | Z43: Kilometraje | AA43: Kilometraje | AB43: Kilometraje | AC43: Kilometraje
A44: Tren | B44: Diario | C44: Diario | D44: Diario | E44: Diario | F44: Diario | G44: Diario | H44: Diario | I44: Diario | J44: Diario | K44: Diario | L44: Diario | M44: Diario | N44: Diario | O44: Diario | P44: Diario | Q44: Diario | R44: Diario | S44: Diario | T44: Diario | U44: Diario | V44: Diario | W44: Diario | X44: Diario | Y44: Diario | Z44: Diario | AA44: Diario | AB44: Diario | AC44: Diario
A45: M01 | B45: 0 | C45: =C5-B5 -> 0 | D45: =D5-C5 -> 191 | E45: =E5-D5 -> 2 | F45: =F5-E5 -> 167 | G45: =G5-F5 -> 603 | H45: =H5-G5 -> 560 | I45: =I5-H5 -> 516 | J45: =J5-I5 -> 345 | ... AC45: =AC5-AB5 -> 585
A46: M02 | B46: 3 | C46: =C6-B6 -> 106 | D46: =D6-C6 -> 546 | E46: =E6-D6 -> 178 | F46: =F6-E6 -> 152 | G46: =G6-F6 -> 191 | H46: =H6-G6 -> 191 | I46: =I6-H6 -> 0 | J46: =J6-I6 -> 0 | ... AC46: =AC6-AB6 -> 2
A47: M03 | B47: 86 | C47: =C7-B7 -> 518 | D47: =D7-C7 -> 518 | E47: =E7-D7 -> 604 | F47: =F7-E7 -> 0 | G47: =G7-F7 -> 281 | H47: =H7-G7 -> 92 | I47: =I7-H7 -> 519 | J47: =J7-I7 -> 347 | ... AC47: =AC7-AB7 -> 263
A48: M04 | B48: 0 | C48: =C8-B8 -> 0 | D48: =D8-C8 -> 24 | E48: =E8-D8 -> 0 | F48: =F8-E8 -> 0 | G48: =G8-F8 -> 0 | H48: =H8-G8 -> 0 | I48: =I8-H8 -> 0 | J48: =J8-I8 -> 0 | ... AC48: =AC8-AB8 -> 252
A49: M05 | B49: 0 | C49: =C9-B9 -> 0 | D49: =D9-C9 -> 80 | E49: =E9-D9 -> 217 | F49: =F9-E9 -> 251 | G49: =G9-F9 -> 588 | H49: =H9-G9 -> 452 | I49: =I9-H9 -> 0 | J49: =J9-I9 -> 0 | ... AC49: =AC9-AB9 -> 251
A50: M06 | B50: 0 | C50: =C10-B10 -> 0 | D50: =D10-C10 -> 251 | E50: =E10-D10 -> 603 | F50: =F10-E10 -> 560 | G50: =G10-F10 -> 194 | H50: =H10-G10 -> 259 | I50: =I10-H10 -> 517 | J50: =J10-I10 -> 172 | ... AC50: =AC10-AB10 -> 587
A51: M07 | B51: 479 | C51: =C11-B11 -> 2 | D51: =D11-C11 -> 402 | E51: =E11-D11 -> 1 | F51: =F11-E11 -> 192 | G51: =G11-F11 -> 254 | H51: =H11-G11 -> 260 | I51: =I11-H11 -> 352 | J51: =J11-I11 -> 3 | ... AC51: =AC11-AB11 -> 134
A52: M08 | B52: 561 | C52: =C12-B12 -> 520 | D52: =D12-C12 -> 346 | E52: =E12-D12 -> 90 | F52: =F12-E12 -> 561 | G52: =G12-F12 -> 407 | H52: =H12-G12 -> 73 | I52: =I12-H12 -> 0 | J52: =J12-I12 -> 0 | ... AC52: =AC12-AB12 -> 263
A53: M09 | B53: 0 | C53: =C13-B13 -> 0 | D53: =D13-C13 -> 403 | E53: =E13-D13 -> 81 | F53: =F13-E13 -> 161 | G53: =G13-F13 -> 3 | H53: =H13-G13 -> 263 | I53: =I13-H13 -> 163 | J53: =J13-I13 -> 351 | ... AC53: =AC13-AB13 -> 511
A54: M10 | B54: 564 | C54: =C14-B14 -> 44 | D54: =D14-C14 -> 488 | E54: =E14-D14 -> 264 | F54: =F14-E14 -> 264 | G54: =G14-F14 -> 200 | H54: =H14-G14 -> 479 | I54: =I14-H14 -> 43 | J54: =J14-I14 -> 89 | ... AC54: =AC14-AB14 -> 263
A55: M11 | B55: 523 | C55: =C15-B15 -> 477 | D55: =D15-C15 -> 545 | E55: =E15-D15 -> 203 | F55: =F15-E15 -> 522 | G55: =G15-F15 -> 520 | H55: =H15-G15 -> 609 | I55: =I15-H15 -> 521 | J55: =J15-I15 -> 179 | ... AC55: =AC15-AB15 -> 420
A56: M12 | B56: 518 | C56: =C16-B16 -> 518 | D56: =D16-C16 -> 89 | E56: =E16-D16 -> 133 | F56: =F16-E16 -> 328 | G56: =G16-F16 -> 81 | H56: =H16-G16 -> 21 | I56: =I16-H16 -> 0 | J56: =J16-I16 -> 0 | ... AC56: =AC16-AB16 -> 631
... A79: XM35 | B79: 519 | C79: =C39-B39 -> 431 | D79: =D39-C39 -> 87 | E79: =E39-D39 -> 0 | F79: =F39-E39 -> 0 | G79: =G39-F39 -> 21 | H79: =H39-G39 -> 1 | I79: =I39-H39 -> 0 | J79: =J39-I39 -> 0 | ... AC79: =AC39-AB39 -> 192
A81: Kilometraje Diario | B81: =SUM(B45:B79) -> 6503 | C81: =SUM(C45:C79) -> 5048 | D81: =SUM(D45:D79) -> 8735 | E81: =SUM(E45:E79) -> 9144 | F81: =SUM(F45:F79) -> 9207 | G81: =SUM(G45:G79) -> 9301 | H81: =SUM(H45:H79) -> 9173 | I81: =SUM(I45:I79) -> 6414 | ... AC81: =SUM(AC45:AC79) -> 11004

Sheet KM-Servicio
H1: SA-MI | I1: 21.7 | J1: EB-PU | K1: 25.4 | L1: PU-SA | M1: 29.11 | N1: QU-LI / LI-QU | O1: 21.7 | P1: VM-PU | Q1: 8.3 | R1: VM-LI | S1: 34.83 | W1: PU-ES/ES-PU | X1: 11.71
B2: CANTIDAD DE SERVICIOS | D2: CANTIDAD DE SERVICIOS | H2: PU-PE | I2: 30.4 | J2: PO-SA | K2: 25.4 | L2: PU-LI | M2: 43.13 | N2: MI-LI / LI-MI | O2: 35.73 | P2: HO-LI/LI-HO | Q2: 33.97 | R2: PU-MI | S2: 7.4
B3: PROGRAMADOS | D3: REALIZADOS | F3: Origen-Destino | G3: Total Trenes | H3: Total Trenes P | I3: Total Servicios | J3: Kms.xTrenes | K3: Kmsxservicios. | L3: Asientos x Kms. | M3: Disp x Km. | N3: Total Odómetro | O3: % Uso Trenes | Q3: Cortes | T3: Acoples | W3: KmTren R | X3: KmTren P
B4: Simples | C4: Dobles | D4: Simples | E4: Dobles | Q4: EB | R4: SA | S4: PE | T4: EB | U4: SA | V4: PE
A5: 45689 | B5: 69 | C5: 3 | D5: ='Data Ocupacion'!D36 -> 69 | E5: ='Data Ocupacion'!E36 -> 3 | F5: PU-LI | G5: =D5+E5*2 -> 75 | H5: =B5+C5*2 -> 75 | I5: =D5+E5 -> 72 | J5: =G5*M$2 -> 3234.75 | K5: =I5*M$2 -> 3105.36 | L5: =J5*104 -> 336414 | M5: =I5*104 -> 7488 | W5: =J5-(Q5*($M$2-$K$1)+(R5*($M$2-$M$1))+ (S5*($M$2-$I$2))) -> 3234.75 | X5: =H5*$M$2 -> 3234.75
B6: 75 | C6: 0 | D6: ='Data Ocupacion'!D37 -> 75 | E6: ='Data Ocupacion'!E37 -> 0 | F6: LI-PU | G6: =D6+E6*2 -> 75 | H6: =B6+C6*2 -> 75 | I6: =D6+E6 -> 75 | J6: =G6*M$2 -> 3234.75 | K6: =I6*M$2 -> 3234.75 | L6: =J6*104 -> 336414 | M6: =I6*104 -> 7800 | W6: =J6-(T6*($M$2-$K$1)+(U6*($M$2-$M$1))) -> 3234.75 | X6: =H6*$M$2 -> 3234.75
B7: 0 | C7: 0 | D7: ='Data Ocupacion'!D38 -> 0 | E7: ='Data Ocupacion'!E38 -> 0 | F7: PU-SA | G7: =D7+E7*2 -> 0 | H7: =B7+C7*2 -> 0 | I7: =D7+E7 -> 0 | J7: =G7*M$1 -> 0 | K7: =I7*M$1 -> 0 | L7: =J7*104 -> 0 | M7: =I7*104 -> 0 | W7: =J7-(Q7*($M$1-$K$1)) -> 0 | X7: =H7*$M$1 -> 0
B8: 0 | C8: 0 | D8: ='Data Ocupacion'!D39 -> 0 | E8: ='Data Ocupacion'!E39 -> 0 | F8: SA-PU | G8: =D8+E8*2 -> 0 | H8: =B8+C8*2 -> 0 | I8: =D8+E8 -> 0 | J8: =G8*M$1 -> 0 | K8: =I8*M$1 -> 0 | L8: =J8*104 -> 0 | M8: =I8*104 -> 0 | W8: =J8 -> 0 | X8: =H8*$M$1 -> 0
B9: 0 | C9: 0 | D9: ='Data Ocupacion'!D40 -> 0 | E9: ='Data Ocupacion'!E40 -> 0 | F9: PU-EB | G9: =D9+E9*2 -> 0 | H9: =B9+C9*2 -> 0 | I9: =D9+E9 -> 0 | J9: =G9*K$1 -> 0 | K9: =I9*K$1 -> 0 | L9: =J9*104 -> 0 | M9: =I9*104 -> 0 | W9: =J9 -> 0 | X9: =H9*$K$1 -> 0
B10: 0 | C10: 0 | D10: ='Data Ocupacion'!D41 -> 0 | E10: ='Data Ocupacion'!E41 -> 0 | F10: EB-PU | G10: =D10+E10*2 -> 0 | H10: =B10+C10*2 -> 0 | I10: =D10+E10 -> 0 | J10: =G10*K$1 -> 0 | K10: =I10*K$1 -> 0 | L10: =J10*104 -> 0 | M10: =I10*104 -> 0 | W10: =J10 -> 0 | X10: =H10*$K$1 -> 0
B11: =SUM(B5:B10) -> 144 | C11: =SUM(C5:C10) -> 3 | D11: =SUM(D5:D10) -> 144 | E11: =SUM(E5:E10) -> 3 | G11: =SUM(G5:G10) -> 150 | H11: =D11+E11*2 -> 150 | I11: =SUM(I5:I10) -> 147 | J11: =SUM(J5:J10) -> 6469.5 | K11: =SUM(K5:K10) -> 6340.11 | L11: =SUM(L5:L10) -> 672828 | M11: =SUM(M5:M10) -> 15288 | N11: ='Odometro-Kilometraje'!B81 -> 6503 | O11: =(W11/N11)*100 -> 99.484853 | W11: =SUM(W5:W10) -> 6469.5 | X11: =SUM(X5:X10) -> 6469.5
A12: =A5+1 -> 45690 | B12: 51 | C12: 3 | D12: ='Data Ocupacion'!F36 -> 51 | E12: ='Data Ocupacion'!G36 -> 3 | F12: PU-LI | G12: =D12+E12*2 -> 57 | H12: =B12+C12*2 -> 57 | I12: =D12+E12 -> 54 | J12: =G12*M$2 -> 2458.41 | K12: =I12*M$2 -> 2329.02 | L12: =J12*104 -> 255674.64 | M12: =I12*104 -> 5616 | W12: =J12-(Q12*($M$2-$K$1)+(R12*($M$2-$M$1))+ (S12*($M$2-$I$2))+ (T12*($M$2-$K$1))) -> 2458.41 | X12: =H12*$M$2 -> 2458.41
B13: 57 | C13: 0 | D13: ='Data Ocupacion'!F37 -> 57 | E13: ='Data Ocupacion'!G37 -> 0 | F13: LI-PU | G13: =D13+E13*2 -> 57 | H13: =B13+C13*2 -> 57 | I13: =D13+E13 -> 57 | J13: =G13*M$2 -> 2458.41 | K13: =I13*M$2 -> 2458.41 | L13: =J13*104 -> 255674.64 | M13: =I13*104 -> 5928 | W13: =J13-(T13*($M$2-$K$1)+(U13*($M$2-$M$1))) -> 2458.41 | X13: =H13*$M$2 -> 2458.41
B14: 0 | C14: 0 | D14: ='Data Ocupacion'!F38 -> 0 | E14: ='Data Ocupacion'!G38 -> 0 | F14: PU-SA | G14: =D14+E14*2 -> 0 | H14: =B14+C14*2 -> 0 | I14: =D14+E14 -> 0 | J14: =G14*M$1 -> 0 | K14: =I14*M$1 -> 0 | L14: =J14*104 -> 0 | M14: =I14*104 -> 0 | W14: =J14-(Q14*($M$1-$K$1)) -> 0 | X14: =H15*$M$1 -> 0
B15: 0 | C15: 0 | D15: ='Data Ocupacion'!F39 -> 0 | E15: ='Data Ocupacion'!G39 -> 0 | F15: SA-PU | G15: =D15+E15*2 -> 0 | H15: =B15+C15*2 -> 0 | I15: =D15+E15 -> 0 | J15: =G15*M$1 -> 0 | K15: =I15*M$1 -> 0 | L15: =J15*104 -> 0 | M15: =I15*104 -> 0 | W15: =J15 -> 0 | X15: =H16*$M$1 -> 0
B16: 0 | C16: 0 | D16: ='Data Ocupacion'!F40 -> 0 | E16: ='Data Ocupacion'!G40 -> 0 | F16: PU-EB | G16: =D16+E16*2 -> 0 | H16: =B16+C16*2 -> 0 | I16: =D16+E16 -> 0 | J16: =G16*K$1 -> 0 | K16: =I16*K$1 -> 0 | L16: =J16*104 -> 0 | M16: =I16*104 -> 0 | W16: =J16 -> 0 | X16: =H17*$K$1 -> 0
B17: 0 | C17: 0 | D17: ='Data Ocupacion'!F41 -> 0 | E17: ='Data Ocupacion'!G41 -> 0 | F17: EB-PU | G17: =D17+E17*2 -> 0 | H17: =B17+C17*2 -> 0 | I17: =D17+E17 -> 0 | J17: =G17*K$1 -> 0 | K17: =I17*K$1 -> 0 | L17: =J17*104 -> 0 | M17: =I17*104 -> 0 | W17: =J17 -> 0 | X17: =H17*$K$1 -> 0
B18: =SUM(B12:B17) -> 108 | C18: =SUM(C12:C17) -> 3 | D18: =SUM(D12:D17) -> 108 | E18: =SUM(E12:E17) -> 3 | G18: =SUM(G12:G17) -> 114 | H18: =D18+E18*2 -> 114 | I18: =SUM(I12:I17) -> 111 | J18: =SUM(J12:J17) -> 4916.82 | K18: =SUM(K12:K17) -> 4787.43 | L18: =SUM(L12:L17) -> 511349.28 | M18: =SUM(M12:M17) -> 11544 | N18: ='Odometro-Kilometraje'!C81 -> 5048 | O18: =(W18/N18)*100 -> 97.401347 | W18: =SUM(W12:W17) -> 4916.82 | X18: =SUM(X12:X17) -> 4916.82
A19: =A12+1 -> 45691 | B19: 78 | C19: 1 | D19: ='Data Ocupacion'!H36 -> 66 | E19: ='Data Ocupacion'!I36 -> 3 | F19: PU-LI | G19: =D19+E19*2 -> 72 | H19: =B19+C19*2 -> 80 | I19: =D19+E19 -> 69 | J19: =G19*M$2 -> 3105.36 | K19: =I19*M$2 -> 2975.97 | L19: =J19*104 -> 322957.44 | M19: =I19*104 -> 7176 | W19: =J19-(Q19*($M$2-$K$1)+(R19*($M$2-$M$1))+ (S19*($M$2-$I$2))+(T19*$K$1)) -> 3105.36 | X19: =H19*$M$2 -> 3450.4
A20: Rige nueva planilla servicios siemples PU-Liy LI-PU | B20: 76 | C20: 2 | D20: ='Data Ocupacion'!H37 -> 68 | E20: ='Data Ocupacion'!I37 -> 3 | F20: LI-PU | G20: =D20+E20*2 -> 74 | H20: =B20+C20*2 -> 80 | I20: =D20+E20 -> 71 | J20: =G20*M$2 -> 3191.62 | K20: =I20*M$2 -> 3062.23 | L20: =J20*104 -> 331928.48 | M20: =I20*104 -> 7384 | W20: =J20-(T20*($M$2-$K$1)+(U20*($M$2-$M$1))) -> 3191.62 | X20: =H20*$M$2 -> 3450.4
B21: 33 | C21: 0 | D21: ='Data Ocupacion'!H38 -> 30 | E21: ='Data Ocupacion'!I38 -> 0 | F21: PU-SA | G21: =D21+E21*2 -> 30 | H21: =B21+C21*2 -> 33 | I21: =D21+E21 -> 30 | J21: =G21*M$1 -> 873.3 | K21: =I21*M$1 -> 873.3 | L21: =J21*104 -> 90823.2 | M21: =I21*104 -> 3120 | W21: =J21-(Q21*($M$1-$K$1)) -> 873.3 | X21: =H21*$M$1 -> 960.63
B22: 32 | C22: 0 | D22: ='Data Ocupacion'!H39 -> 29 | E22: ='Data Ocupacion'!I39 -> 0 | F22: SA-PU | G22: =D22+E22*2 -> 29 | H22: =B22+C22*2 -> 32 | I22: =D22+E22 -> 29 | J22: =G22*M$1 -> 844.19 | K22: =I22*M$1 -> 844.19 | L22: =J22*104 -> 87795.76 | M22: =I22*104 -> 3016 | W22: =J22 -> 844.19 | X22: =H22*$M$1 -> 931.52
B23: 0 | C23: 0 | D23: 0 | E23: ='Data Ocupacion'!I40 -> 0 | F23: PU-EB | G23: =D23+E23*2 -> 0 | H23: =B23+C23*2 -> 0 | I23: =D23+E23 -> 0 | J23: =G23*K$1 -> 0 | K23: =I23*K$1 -> 0 | L23: =J23*104 -> 0 | M23: =I23*104 -> 0 | W23: =J23 -> 0 | X23: =H23*$K$1 -> 0
B24: 0 | C24: 0 | D24: ='Data Ocupacion'!H42 -> 6 | E24: 0 | F24: PU-ES | G24: =D24+E24*2 -> 6 | H24: =B24+C24*2 -> 0 | I24: =D24+E24 -> 6 | J24: =G24*X$1 -> 70.26 | K24: =I24*X$1 -> 70.26 | L24: =J24*104 -> 7307.04 | M24: =I24*104 -> 624 | W24: =J24 -> 70.26 | X24: =H24*$X$1 -> 0
B25: 0 | C25: 0 | D25: ='Data Ocupacion'!H43 -> 4 | E25: 0 | F25: ES-PU | G25: =D25+E25*2 -> 4 | H25: =B25+C25*2 -> 0 | I25: =D25+E25 -> 4 | J25: =G25*X$1 -> 46.84 | K25: =I25*X$1 -> 46.84 | L25: =J25*104 -> 4871.36 | M25: =I25*104 -> 416 | W25: =J25 -> 46.84 | X25: =H25*$X$1 -> 0
B26: 1 | C26: 0 | D26: ='Data Ocupacion'!H41 -> 1 | E26: ='Data Ocupacion'!I41 -> 0 | F26: EB-PU | G26: =D26+E26*2 -> 1 | H26: =B26+C26*2 -> 1 | I26: =D26+E26 -> 1 | J26: =G26*K$1 -> 25.4 | K26: =I26*K$1 -> 25.4 | L26: =J26*104 -> 2641.6 | M26: =I26*104 -> 104 | W26: =J26 -> 25.4 | X26: =H26*$K$1 -> 25.4
B27: =SUM(B19:B26) -> 220 | C27: =SUM(C19:C26) -> 3 | D27: =SUM(D19:D26) -> 204 | E27: =SUM(E19:E26) -> 6 | G27: =SUM(G19:G26) -> 216 | H27: =D27+E27*2 -> 216 | I27: =SUM(I19:I26) -> 210 | J27: =SUM(J19:J26) -> 8156.97 | K27: =SUM(K19:K26) -> 7898.19 | L27: =SUM(L19:L26) -> 848324.88 | M27: =SUM(M19:M26) -> 21840 | N27: ='Odometro-Kilometraje'!D81 -> 8735 | O27: =(W27/N27)*100 -> 93.382599 | W27: =SUM(W19:W26) -> 8156.97 | X27: =SUM(X19:X26) -> 8818.35
A28: =A19+1 -> 45692 | B28: 78 | C28: 1 | D28: ='Data Ocupacion'!J36 -> 77 | E28: ='Data Ocupacion'!K36 -> 2 | F28: PU-LI | G28: =D28+E28*2 -> 81 | H28: =B28+C28*2 -> 80 | I28: =D28+E28 -> 79 | J28: =G28*M$2 -> 3493.53 | K28: =I28*M$2 -> 3407.27 | L28: =J28*104 -> 363327.12 | M28: =I28*104 -> 8216 | W28: =J28-(Q28*($M$2-$K$1)+(R28*($M$2-$M$1))+ (S28*($M$2-$I$2))) -> 3493.53 | X28: =H28*$M$2 -> 3450.4
B29: 76 | C29: 2 | D29: ='Data Ocupacion'!J37 -> 75 | E29: ='Data Ocupacion'!K37 -> 3 | F29: LI-PU | G29: =D29+E29*2 -> 81 | H29: =B29+C29*2 -> 80 | I29: =D29+E29 -> 78 | J29: =G29*M$2 -> 3493.53 | K29: =I29*M$2 -> 3364.14 | L29: =J29*104 -> 363327.12 | M29: =I29*104 -> 8112 | W29: =J29-(T29*($M$2-$K$1)+(U29*($M$2-$M$1))+(V29*($M$2-$I$2))) -> 3493.53 | X29: =H28*$M$2 -> 3450.4
B30: 33 | C30: 0 | D30: ='Data Ocupacion'!J38 -> 33 | E30: ='Data Ocupacion'!K38 -> 0 | F30: PU-SA | G30: =D30+E30*2 -> 33 | H30: =B30+C30*2 -> 33 | I30: =D30+E30 -> 33 | J30: =G30*M$1 -> 960.63 | K30: =I30*M$1 -> 960.63 | L30: =J30*104 -> 99905.52 | M30: =I30*104 -> 3432 | W30: =J30-(Q30*($M$1-$K$1)) -> 960.63 | X30: =H30*$M$1 -> 960.63
B31: 32 | C31: 0 | D31: ='Data Ocupacion'!J39 -> 32 | E31: ='Data Ocupacion'!K39 -> 0 | F31: SA-PU | G31: =D31+E31*2 -> 32 | H31: =B31+C31*2 -> 32 | I31: =D31+E31 -> 32 | J31: =G31*M$1 -> 931.52 | K31: =I31*M$1 -> 931.52 | L31: =J31*104 -> 96878.08 | M31: =I31*104 -> 3328 | W31: =J31 -> 931.52 | X31: =H31*$M$1 -> 931.52
B32: 0 | C32: 0 | D32: ='Data Ocupacion'!J40 -> 0 | E32: ='Data Ocupacion'!K40 -> 0 | F32: PU-EB | G32: =D32+E32*2 -> 0 | H32: =B32+C32*2 -> 0 | I32: =D32+E32 -> 0 | J32: =G32*K$1 -> 0 | K32: =I32*K$1 -> 0 | L32: =J32*104 -> 0 | M32: =I32*104 -> 0 | W32: =J32 -> 0 | X32: =H32*$K$1 -> 0
B33: 1 | C33: 0 | D33: ='Data Ocupacion'!J41 -> 1 | E33: ='Data Ocupacion'!K41 -> 0 | F33: EB-PU | G33: =D33+E33*2 -> 1 | H33: =B33+C33*2 -> 1 | I33: =D33+E33 -> 1 | J33: =G33*K$1 -> 25.4 | K33: =I33*K$1 -> 25.4 | L33: =J33*104 -> 2641.6 | M33: =I33*104 -> 104 | W33: =J33 -> 25.4 | X33: =H33*$K$1 -> 25.4
B34: =SUM(B28:B33) -> 220 | C34: =SUM(C28:C33) -> 3 | D34: =SUM(D28:D33) -> 218 | E34: =SUM(E28:E33) -> 5 | G34: =SUM(G28:G33) -> 228 | H34: =D34+E34*2 -> 228 | I34: =SUM(I28:I33) -> 223 | J34: =SUM(J28:J33) -> 8904.61 | K34: =SUM(K28:K33) -> 8688.96 | L34: =SUM(L28:L33) -> 926079.44 | M34: =SUM(M28:M33) -> 23192 | N34: ='Odometro-Kilometraje'!E81 -> 9144 | O34: =(W34/N34)*100 -> 97.381999 | W34: =SUM(W28:W33) -> 8904.61 | X34: =SUM(X28:X33) -> 8818.35
A35: =A28+1 -> 45693 | B35: 78 | C35: 1 | D35: ='Data Ocupacion'!L36 -> 78 | E35: ='Data Ocupacion'!M36 -> 1 | F35: PU-LI | G35: =D35+E35*2 -> 80 | H35: =B35+C35*2 -> 80 | I35: =D35+E35 -> 79 | J35: =G35*M$2 -> 3450.4 | K35: =I35*M$2 -> 3407.27 | L35: =J35*104 -> 358841.6 | M35: =I35*104 -> 8216 | W35: =J35-(Q35*($M$2-$K$1)+(R35*($M$2-$M$1))+ (S35*($M$2-$I$2))) -> 3450.4 | X35: =H35*$M$2 -> 3450.4
B36: 76 | C36: 2 | D36: ='Data Ocupacion'!L37 -> 76 | E36: ='Data Ocupacion'!M37 -> 2 | F36: LI-PU | G36: =D36+E36*2 -> 80 | H36: =B36+C36*2 -> 80 | I36: =D36+E36 -> 78 | J36: =G36*M$2 -> 3450.4 | K36: =I36*M$2 -> 3364.14 | L36: =J36*104 -> 358841.6 | M36: =I36*104 -> 8112 | W36: =J36-(T36*($M$2-$K$1)+(U36*($M$2-$M$1))) -> 3450.4 | X36: =H35*$M$2 -> 3450.4
B37: 33 | C37: 0 | D37: ='Data Ocupacion'!L38 -> 33 | E37: ='Data Ocupacion'!M38 -> 0 | F37: PU-SA | G37: =D37+E37*2 -> 33 | H37: =B37+C37*2 -> 33 | I37: =D37+E37 -> 33 | J37: =G37*M$1 -> 960.63 | K37: =I37*M$1 -> 960.63 | L37: =J37*104 -> 99905.52 | M37: =I37*104 -> 3432 | W37: =J37-(Q37*($M$1-$K$1)) -> 960.63 | X37: =H37*$M$1 -> 960.63
B38: 32 | C38: 0 | D38: ='Data Ocupacion'!L39 -> 32 | E38: ='Data Ocupacion'!M39 -> 0 | F38: SA-PU | G38: =D38+E38*2 -> 32 | H38: =B38+C38*2 -> 32 | I38: =D38+E38 -> 32 | J38: =G38*M$1 -> 931.52 | K38: =I38*M$1 -> 931.52 | L38: =J38*104 -> 96878.08 | M38: =I38*104 -> 3328 | W38: =J38 -> 931.52 | X38: =H38*$M$1 -> 931.52
B39: 0 | C39: 0 | D39: ='Data Ocupacion'!L40 -> 0 | E39: ='Data Ocupacion'!M40 -> 0 | F39: PU-EB | G39: =D39+E39*2 -> 0 | H39: =B39+C39*2 -> 0 | I39: =D39+E39 -> 0 | J39: =G39*K$1 -> 0 | K39: =I39*K$1 -> 0 | L39: =J39*104 -> 0 | M39: =I39*104 -> 0 | W39: =J39 -> 0 | X39: =H39*$K$1 -> 0
B40: 1 | C40: 0 | D40: ='Data Ocupacion'!L41 -> 1 | E40: ='Data Ocupacion'!M41 -> 0 | F40: EB-PU | G40: =D40+E40*2 -> 1 | H40: =B40+C40*2 -> 1 | I40: =D40+E40 -> 1 | J40: =G40*K$1 -> 25.4 | K40: =I40*K$1 -> 25.4 | L40: =J40*104 -> 2641.6 | M40: =I40*104 -> 104 | W40: =J40 -> 25.4 | X40: =H40*$K$1 -> 25.4
...

Sheet Data Ocupacion
D1: 45689 | F1: 45690 | H1: 45691 | J1: 45692 | L1: 45693 | N1: 45694 | P1: 45695 | R1: 45696 | T1: 45697 | V1: 45698 | X1: 45699 | Z1: 45700 | AB1: 45701 | AD1: 45702 | AF1: 45703 | AH1: 45704 | AJ1: 45705 | AL1: 45706 | AN1: 45707 | AP1: 45708 | AR1: 45709 | AT1: 45710 | AV1: 45711 | AX1: 45712 | AZ1: 45713 | BB1: 45714 | BD1: 45715 | BF1: 45716
D2: S | E2: M | F2: S | G2: M | H2: S | I2: M | J2: S | K2: M | L2: S | M2: M | N2: S | O2: M | P2: S | Q2: M | R2: S | S2: M | T2: S | U2: M | V2: S | W2: M | X2: S | Y2: M | Z2: S | AA2: M | AB2: S | AC2: M | AD2: S | AE2: M | AF2: S | AG2: M | AH2: S | AI2: M | AJ2: S | AK2: M | AL2: S | AM2: M | AN2: S | AO2: M | AP2: S | AQ2: M | AR2: S | AS2: M | AT2: S | AU2: M | AV2: S | AW2: M | AX2: S | AY2: M | AZ2: S | BA2: M | BB2: S | BC2: M | BD2: S | BE2: M | BF2: S | BG2: M
A3: Servicios PU-SA | D3: 0 | E3: 0 | F3: 0 | G3: 0 | H3: 10 | I3: 0 | J3: 10 | K3: 0 | L3: 10 | M3: 0 | N3: 10 | O3: 0 | P3: 10 | Q3: 0 | R3: 0 | S3: 0 | T3: 0 | U3: 0 | V3: 10 | W3: 0 | X3: 10 | Y3: 0 | Z3: 10 | AA3: 0 | AB3: 10 | AC3: 0 | AD3: 10 | AE3: 0 | AF3: 0 | AG3: 0 | AH3: 0 | AI3: 0 | AJ3: 10 | AK3: 0 | AL3: 10 | AM3: 0 | AN3: 10 | AO3: 0 | AP3: 10 | AQ3: 0 | AR3: 10 | AS3: 0 | AT3: 0 | AU3: 0 | AV3: 0 | AW3: 0 | AX3: 10 | AY3: 0 | AZ3: 10 | BA3: 0 | BB3: 10 | BC3: 0 | BD3: 10 | BE3: 0 | BF3: 10 | BG3: 0
A4: Servicios PU-EB | D4: 0 | E4: 0 | F4: 0 | G4: 0 | H4: 0 | I4: 0 | J4: 0 | K4: 0 | L4: 0 | M4: 0 | N4: 0 | O4: 0 | P4: 0 | Q4: 0 | R4: 0 | S4: 0 | T4: 0 | U4: 0 | V4: 0 | W4: 0 | X4: 0 | Y4: 0 | Z4: 0 | AA4: 0 | AB4: 0 | AC4: 0 | AD4: 0 | AE4: 0 | AF4: 0 | AG4: 0 | AH4: 0 | AI4: 0 | AJ4: 0 | AK4: 0 | AL4: 0 | AM4: 0 | AN4: 0 | AO4: 0 | AP4: 0 | AQ4: 0 | AR4: 0 | AS4: 0 | AT4: 0 | AU4: 0 | AV4: 0 | AW4: 0 | AX4: 0 | AY4: 0 | AZ4: 0 | BA4: 0 | BB4: 0 | BC4: 0 | BD4: 0 | BE4: 0 | BF4: 0 | BG4: 0
A5: Servicios PU-LI | D5: 0 | E5: 0 | F5: 0 | G5: 0 | H5: 10 | I5: 0 | J5: 10 | K5: 0 | L5: 10 | M5: 0 | N5: 10 | O5: 0 | P5: 10 | Q5: 0 | R5: 0 | S5: 0 | T5: 0 | U5: 0 | V5: 10 | W5: 0 | X5: 10 | Y5: 0 | Z5: 10 | AA5: 0 | AB5: 10 | AC5: 0 | AD5: 10 | AE5: 0 | AF5: 0 | AG5: 0 | AH5: 0 | AI5: 0 | AJ5: 10 | AK5: 0 | AL5: 10 | AM5: 0 | AN5: 10 | AO5: 0 | AP5: 10 | AQ5: 0 | AR5: 10 | AS5: 0 | AT5: 0 | AU5: 0 | AV5: 0 | AW5: 0 | AX5: 10 | AY5: 0 | AZ5: 10 | BA5: 0 | BB5: 10 | BC5: 0 | BD5: 10 | BE5: 0 | BF5: 10 | BG5: 0
A6: Servicios SA-PU | D6: 0 | E6: 0 | F6: 0 | G6: 0 | H6: 10 | I6: 0 | J6: 10 | K6: 0 | L6: 10 | M6: 0 | N6: 10 | O6: 0 | P6: 10 | Q6: 0 | R6: 0 | S6: 0 | T6: 0 | U6: 0 | V6: 10 | W6: 0 | X6: 10 | Y6: 0 | Z6: 10 | AA6: 0 | AB6: 10 | AC6: 0 | AD6: 10 | AE6: 0 | AF6: 0 | AG6: 0 | AH6: 0 | AI6: 0 | AJ6: 10 | AK6: 0 | AL6: 10 | AM6: 0 | AN6: 10 | AO6: 0 | AP6: 10 | AQ6: 0 | AR6: 10 | AS6: 0 | AT6: 0 | AU6: 0 | AV6: 0 | AW6: 0 | AX6: 10 | AY6: 0 | AZ6: 10 | BA6: 0 | BB6: 10 | BC6: 0 | BD6: 10 | BE6: 0 | BF6: 10 | BG6: 0
A7: Servicios EB-PU | D7: 0 | E7: 0 | F7: 0 | G7: 0 | H7: 0 | I7: 0 | J7: 0 | K7: 0 | L7: 0 | M7: 0 | N7: 0 | O7: 0 | P7: 0 | Q7: 0 | R7: 0 | S7: 0 | T7: 0 | U7: 0 | V7: 0 | W7: 0 | X7: 0 | Y7: 0 | Z7: 0 | AA7: 0 | AB7: 0 | AC7: 0 | AD7: 0 | AE7: 0 | AF7: 0 | AG7: 0 | AH7: 0 | AI7: 0 | AJ7: 0 | AK7: 0 | AL7: 0 | AM7: 0 | AN7: 0 | AO7: 0 | AP7: 0 | AQ7: 0 | AR7: 0 | AS7: 0 | AT7: 0 | AU7: 0 | AV7: 0 | AW7: 0 | AX7: 0 | AY7: 0 | AZ7: 0 | BA7: 0 | BB7: 0 | BC7: 0 | BD7: 0 | BE7: 0 | BF7: 0 | BG7: 0
A8: Servicios LI-PU | D8: 0 | E8: 0 | F8: 0 | G8: 0 | H8: 10 | I8: 0 | J8: 10 | K8: 0 | L8: 10 | M8: 0 | N8: 10 | O8: 0 | P8: 10 | Q8: 0 | R8: 0 | S8: 0 | T8: 0 | U8: 0 | V8: 10 | W8: 0 | X8: 10 | Y8: 0 | Z8: 10 | AA8: 0 | AB8: 10 | AC8: 0 | AD8: 10 | AE8: 0 | AF8: 0 | AG8: 0 | AH8: 0 | AI8: 0 | AJ8: 10 | AK8: 0 | AL8: 10 | AM8: 0 | AN8: 10 | AO8: 0 | AP8: 10 | AQ8: 0 | AR8: 10 | AS8: 0 | AT8: 0 | AU8: 0 | AV8: 0 | AW8: 0 | AX8: 10 | AY8: 0 | AZ8: 10 | BA8: 0 | BB8: 10 | BC8: 0 | BD8: 10 | BE8: 0 | BF8: 10 | BG8: 0
A10: Servicios PU-SA | D10: 0 | E10: 0 | F10: 0 | G10: 0 | H10: 13 | I10: 0 | J10: 16 | K10: 0 | L10: 16 | M10: 0 | N10: 16 | O10: 0 | P10: 16 | Q10: 0 | R10: 0 | S10: 0 | T10: 0 | U10: 0 | V10: 16 | W10: 0 | X10: 16 | Y10: 0 | Z10: 16 | AA10: 0 | AB10: 16 | AC10: 0 | AD10: 16 | AE10: 0 | AF10: 0 | AG10: 0 | AH10: 0 | AI10: 0 | AJ10: 16 | AK10: 0 | AL10: 16 | AM10: 0 | AN10: 16 | AO10: 0 | AP10: 16 | AQ10: 0 | AR10: 16 | AS10: 0 | AT10: 0 | AU10: 0 | AV10: 0 | AW10: 0 | AX10: 16 | AY10: 0 | AZ10: 3 | BA10: 0 | BB10: 16 | BC10: 0 | BD10: 16 | BE10: 0 | BF10: 16 | BG10: 0
A11: Servicios PU-EB | D11: 0 | E11: 0 | F11: 0 | G11: 0 | H11: 0 | I11: 0 | J11: 0 | K11: 0 | L11: 0 | M11: 0 | N11: 0 | O11: 0 | P11: 0 | Q11: 0 | R11: 0 | S11: 0 | T11: 0 | U11: 0 | V11: 0 | W11: 0 | X11: 0 | Y11: 0 | Z11: 0 | AA11: 0 | AB11: 0 | AC11: 0 | AD11: 0 | AE11: 0 | AF11: 0 | AG11: 0 | AH11: 0 | AI11: 0 | AJ11: 0 | AK11: 0 | AL11: 0 | AM11: 0 | AN11: 0 | AO11: 0 | AP11: 0 | AQ11: 0 | AR11: 0 | AS11: 0 | AT11: 0 | AU11: 0 | AV11: 0 | AW11: 0 | AX11: 0 | AY11: 0 | AZ11: 0 | BA11: 0 | BB11: 0 | BC11: 0 | BD11: 0 | BE11: 0 | BF11: 0 | BG11: 0
A12: Servicios PU-LI | D12: 69 | E12: 3 | F12: 51 | G12: 3 | H12: 50 | I12: 1 | J12: 59 | K12: 2 | L12: 60 | M12: 1 | N12: 60 | O12: 1 | P12: 60 | Q12: 1 | R12: 61 | S12: 6 | T12: 0 | U12: 25 | V12: 60 | W12: 1 | X12: 60 | Y12: 1 | Z12: 60 | AA12: 1 | AB12: 60 | AC12: 1 | AD12: 60 | AE12: 1 | AF12: 69 | AG12: 3 | AH12: 51 | AI12: 3 | AJ12: 60 | AK12: 1 | AL12: 60 | AM12: 1 | AN12: 60 | AO12: 1 | AP12: 60 | AQ12: 1 | AR12: 60 | AS12: 1 | AT12: 69 | AU12: 3 | AV12: 32 | AW12: 22 | AX12: 51 | AY12: 10 | AZ12: 34 | BA12: 0 | BB12: 52 | BC12: 9 | BD12: 52 | BE12: 9 | BF12: 51 | BG12: 10
A13: Servicios SA-PU | D13: 0 | E13: 0 | F13: 0 | G13: 0 | H13: 13 | I13: 0 | J13: 16 | K13: 0 | L13: 16 | M13: 0 | N13: 16 | O13: 0 | P13: 16 | Q13: 0 | R13: 0 | S13: 0 | T13: 0 | U13: 0 | V13: 16 | W13: 0 | X13: 16 | Y13: 0 | Z13: 16 | AA13: 0 | AB13: 16 | AC13: 0 | AD13: 16 | AE13: 0 | AF13: 0 | AG13: 0 | AH13: 0 | AI13: 0 | AJ13: 16 | AK13: 0 | AL13: 16 | AM13: 0 | AN13: 16 | AO13: 0 | AP13: 16 | AQ13: 0 | AR13: 16 | AS13: 0 | AT13: 0 | AU13: 0 | AV13: 0 | AW13: 0 | AX13: 16 | AY13: 0 | AZ13: 4 | BA13: 0 | BB13: 16 | BC13: 0 | BD13: 16 | BE13: 0 | BF13: 16 | BG13: 0
A14: Servicios EB-PU | D14: 0 | E14: 0 | F14: 0 | G14: 0 | H14: 1 | I14: 0 | J14: 1 | K14: 0 | L14: 1 | M14: 0 | N14: 1 | O14: 0 | P14: 1 | Q14: 0 | R14: 0 | S14: 0 | T14: 0 | U14: 0 | V14: 1 | W14: 0 | X14: 1 | Y14: 0 | Z14: 1 | AA14: 0 | AB14: 1 | AC14: 0 | AD14: 1 | AE14: 0 | AF14: 0 | AG14: 0 | AH14: 0 | AI14: 0 | AJ14: 1 | AK14: 0 | AL14: 1 | AM14: 0 | AN14: 1 | AO14: 0 | AP14: 1 | AQ14: 0 | AR14: 1 | AS14: 0 | AT14: 0 | AU14: 0 | AV14: 0 | AW14: 0 | AX14: 1 | AY14: 0 | AZ14: 1 | BA14: 0 | BB14: 1 | BC14: 0 | BD14: 1 | BE14: 0 | BF14: 1 | BG14: 0
A15: Servicios LI-PU | D15: 75 | E15: 0 | F15: 57 | G15: 0 | H15: 51 | I15: 3 | J15: 58 | K15: 3 | L15: 59 | M15: 2 | N15: 59 | O15: 2 | P15: 59 | Q15: 2 | R15: 69 | S15: 2 | T15: 2 | U15: 25 | V15: 59 | W15: 2 | X15: 59 | Y15: 2 | Z15: 59 | AA15: 2 | AB15: 59 | AC15: 2 | AD15: 59 | AE15: 2 | AF15: 75 | AG15: 0 | AH15: 57 | AI15: 0 | AJ15: 59 | AK15: 2 | AL15: 59 | AM15: 2 | AN15: 59 | AO15: 2 | AP15: 59 | AQ15: 2 | AR15: 59 | AS15: 2 | AT15: 75 | AU15: 0 | AV15: 42 | AW15: 15 | AX15: 44 | AY15: 17 | AZ15: 35 | BA15: 0 | BB15: 49 | BC15: 12 | BD15: 45 | BE15: 16 | BF15: 45 | BG15: 16
A16: Servicios PU-ES | H16: 6 | I16: 0
A17: Servicios ES-PU | H17: 4 | I17: 0
A18: Servicios VM-LI | AX18: 4 | AY18: 0 | AZ18: 4 | BA18: 0 | BD18: 4 | BE18: 0 | BF18: 4 | BG18: 0
A19: Servicios VM-PU | AX19: 2 | AY19: 0 | AZ19: 2 | BA19: 0 | BD19: 2 | BE19: 0 | BF19: 2 | BG19: 0
A21: Servicios PU-SA | D21: 0 | E21: 0 | F21: 0 | G21: 0 | H21: 7 | I21: 0 | J21: 7 | K21: 0 | L21: 7 | M21: 0 | N21: 7 | O21: 0 | P21: 7 | Q21: 0 | R21: 0 | S21: 0 | T21: 0 | U21: 0 | V21: 5 | W21: 0 | X21: 7 | Y21: 0 | Z21: 7 | AA21: 0 | AB21: 7 | AC21: 0 | AD21: 7 | AE21: 0 | AF21: 0 | AG21: 0 | AH21: 0 | AI21: 0 | AJ21: 7 | AK21: 0 | AL21: 7 | AM21: 0 | AN21: 7 | AO21: 0 | AP21: 7 | AQ21: 0 | AR21: 7 | AS21: 0 | AT21: 0 | AU21: 0 | AV21: 0 | AW21: 0 | AX21: 7 | AY21: 0 | AZ21: 0 | BA21: 0 | BB21: 7 | BC21: 0 | BD21: 7 | BE21: 0 | BF21: 7 | BG21: 0
A22: Servicios PU-EB | D22: 0 | E22: 0 | F22: 0 | G22: 0 | H22: 0 | I22: 0 | J22: 0 | K22: 0 | L22: 0 | M22: 0 | N22: 0 | O22: 0 | P22: 0 | Q22: 0 | R22: 0 | S22: 0 | T22: 0 | U22: 0 | V22: 0 | W22: 0 | X22: 0 | Y22: 0 | Z22: 0 | AA22: 0 | AB22: 0 | AC22: 0 | AD22: 0 | AE22: 0 | AF22: 0 | AG22: 0 | AH22: 0 | AI22: 0 | AJ22: 0 | AK22: 0 | AL22: 0 | AM22: 0 | AN22: 0 | AO22: 0 | AP22: 0 | AQ22: 0 | AR22: 0 | AS22: 0 | AT22: 0 | AU22: 0 | AV22: 0 | AW22: 0 | AX22: 0 | AY22: 0 | AZ22: 0 | BA22: 0 | BB22: 0 | BC22: 0 | BD22: 0 | BE22: 0 | BF22: 0 | BG22: 0
A23: Servicios PU-LI | D23: 0 | E23: 0 | F23: 0 | G23: 0 | H23: 6 | I23: 2 | J23: 8 | K23: 0 | L23: 8 | M23: 0 | N23: 8 | O23: 0 | P23: 8 | Q23: 0 | R23: 0 | S23: 0 | T23: 0 | U23: 0 | V23: 9 | W23: 0 | X23: 8 | Y23: 0 | Z23: 8 | AA23: 0 | AB23: 8 | AC23: 0 | AD23: 8 | AE23: 0 | AF23: 0 | AG23: 0 | AH23: 0 | AI23: 0 | AJ23: 8 | AK23: 0 | AL23: 8 | AM23: 0 | AN23: 8 | AO23: 0 | AP23: 8 | AQ23: 0 | AR23: 8 | AS23: 0 | AT23: 0 | AU23: 0 | AV23: 0 | AW23: 0 | AX23: 0 | AY23: 8 | AZ23: 0 | BA23: 0 | BB23: 3 | BC23: 5 | BD23: 0 | BE23: 8 | BF23: 1 | BG23: 7
A24: Servicios SA-PU | D24: 0 | E24: 0 | F24: 0 | G24: 0 | H24: 6 | I24: 0 | J24: 6 | K24: 0 | L24: 6 | M24: 0 | N24: 6 | O24: 0 | P24: 6 | Q24: 0 | R24: 0 | S24: 0 | T24: 0 | U24: 0 | V24: 6 | W24: 0 | X24: 6 | Y24: 0 | Z24: 6 | AA24: 0 | AB24: 6 | AC24: 0 | AD24: 6 | AE24: 0 | AF24: 0 | AG24: 0 | AH24: 0 | AI24: 0 | AJ24: 6 | AK24: 0 | AL24: 6 | AM24: 0 | AN24: 6 | AO24: 0 | AP24: 6 | AQ24: 0 | AR24: 6 | AS24: 0 | AT24: 0 | AU24: 0 | AV24: 0 | AW24: 0 | AX24: 6 | AY24: 0 | AZ24: 0 | BA24: 0 | BB24: 6 | BC24: 0 | BD24: 6 | BE24: 0 | BF24: 6 | BG24: 0
A25: Servicios EB-PU | D25: 0 | E25: 0 | F25: 0 | G25: 0 | H25: 0 | I25: 0 | J25: 0 | K25: 0 | L25: 0 | M25: 0 | N25: 0 | O25: 0 | P25: 0 | Q25: 0 | R25: 0 | S25: 0 | T25: 0 | U25: 0 | V25: 0 | W25: 0 | X25: 0 | Y25: 0 | Z25: 0 | AA25: 0 | AB25: 0 | AC25: 0 | AD25: 0 | AE25: 0 | AF25: 0 | AG25: 0 | AH25: 0 | AI25: 0 | AJ25: 0 | AK25: 0 | AL25: 0 | AM25: 0 | AN25: 0 | AO25: 0 | AP25: 0 | AQ25: 0 | AR25: 0 | AS25: 0 | AT25: 0 | AU25: 0 | AV25: 0 | AW25: 0 | AX25: 0 | AY25: 0 | AZ25: 0 | BA25: 0 | BB25: 0 | BC25: 0 | BD25: 0 | BE25: 0 | BF25: 0 | BG25: 0
A26: Servicios LI-PU | D26: 0 | E26: 0 | F26: 0 | G26: 0 | H26: 7 | I26: 0 | J26: 7 | K26: 0 | L26: 7 | M26: 0 | N26: 7 | O26: 0 | P26: 7 | Q26: 0 | R26: 0 | S26: 0 | T26: 0 | U26: 0 | V26: 7 | W26: 0 | X26: 7 | Y26: 0 | Z26: 7 | AA26: 0 | AB26: 7 | AC26: 0 | AD26: 7 | AE26: 0 | AF26: 0 | AG26: 0 | AH26: 0 | AI26: 0 | AJ26: 7 | AK26: 0 | AL26: 7 | AM26: 0 | AN26: 7 | AO26: 0 | AP26: 7 | AQ26: 0 | AR26: 7 | AS26: 0 | AT26: 0 | AU26: 0 | AV26: 0 | AW26: 0 | AX26: 5 | AY26: 2 | AZ26: 0 | BA26: 0 | BB26: 5 | BC26: 2 | BD26: 5 | BE26: 2 | BF26: 5 | BG26: 2
D29: =SUM(D3:D26) -> 144 | E29: =SUM(E3:E26) -> 3 | F29: =SUM(F3:F26) -> 108 | G29: =SUM(G3:G26) -> 3 | H29: =SUM(H3:H26) -> 204 | I29: =SUM(I3:I26) -> 6 | J29: =SUM(J3:J26) -> 218 | K29: =SUM(K3:K26) -> 5 | ... BG29: =SUM(BG3:BG26) -> 35
A35: Km Servicio
A36: PU - LI | D36: =D5+D12+D23 -> 69 | E36: =E5+E12+E23 -> 3 | F36: =F5+F12+F23 -> 51 | G36: =G5+G12+G23 -> 3 | H36: =H5+H12+H23 -> 66 | I36: =I5+I12+I23 -> 3 | J36: =J5+J12+J23 -> 77 | K36: =K5+K12+K23 -> 2 | ... BG36: =BG5+BG12+BG23 -> 17
A37: LI - PU | D37: =D8+D15+D26 -> 75 | E37: =E8+E15+E26 -> 0 | F37: =F8+F15+F26 -> 57 | G37: =G8+G15+G26 -> 0 | H37: =H8+H15+H26 -> 68 | I37: =I8+I15+I26 -> 3 | J37: =J8+J15+J26 -> 75 | K37: =K8+K15+K26 -> 3 | ... BG37: =BG8+BG15+BG26 -> 18
A38: PU - SA | D38: =D3+D10+D21 -> 0 | E38: =E3+E10+E21 -> 0 | F38: =F3+F10+F21 -> 0 | G38: =G3+G10+G21 -> 0 | H38: =H3+H10+H21 -> 30 | I38: =I3+I10+I21 -> 0 | J38: =J3+J10+J21 -> 33 | K38: =K3+K10+K21 -> 0 | ... BG38: =BG3+BG10+BG21 -> 0
A39: SA - PU | D39: =D6+D13+D24 -> 0 | E39: =E6+E13+E24 -> 0 | F39: =F6+F13+F24 -> 0 | G39: =G6+G13+G24 -> 0 | H39: =H6+H13+H24 -> 29 | I39: =I6+I13+I24 -> 0 | J39: =J6+J13+J24 -> 32 | K39: =K6+K13+K24 -> 0 | ... BG39: =BG6+BG13+BG24 -> 0
A40: PU-EB | D40: =D4+D11+D22 -> 0 | E40: =E4+E11+E22 -> 0 | F40: =F4+F11+F22 -> 0 | G40: =G4+G11+G22 -> 0 | H40: =H4+H11+H22 -> 0 | I40: =I4+I11+I22 -> 0 | J40: =J4+J11+J22 -> 0 | K40: =K4+K11+K22 -> 0 | ... BG40: =BG4+BG11+BG22 -> 0
A41: EB-PU | D41: =D7+D14+D25 -> 0 | E41: =E7+E14+E25 -> 0 | F41: =F7+F14+F25 -> 0 | G41: =G7+G14+G25 -> 0 | H41: =H7+H14+H25 -> 1 | I41: =I7+I14+I25 -> 0 | J41: =J7+J14+J25 -> 1 | K41: =K7+K14+K25 -> 0 | ... BG41: =BG7+BG14+BG25 -> 0
A42: PU-ES | H42: =H16 -> 6 | I42: 0
A43: ES-PU | H43: =H17 -> 4 | I43: =I17 -> 0
A44: VM-LI | AX44: =AX18 -> 4 | AY44: =AY18 -> 0 | AZ44: =AZ18 -> 4 | BA44: =BA18 -> 0 | BB44: =BB18 -> 0 | BC44: =BC18 -> 0 | BD44: =BD18 -> 4 | BE44: =BE18 -> 0 | ... BG44: =BG18 -> 0
A45: VM-PU | AX45: =AX19 -> 2 | AY45: =AY19 -> 0 | AZ45: =AZ19 -> 2 | BA45: =BA19 -> 0 | BB45: =BB19 -> 0 | BC45: =BC19 -> 0 | BD45: =BD19 -> 2 | BE45: =BE19 -> 0 | ... BG45: =BG19 -> 0
A46: total | D46: =SUM(D36:D41) -> 144 | E46: =SUM(E36:E41) -> 3 | F46: =SUM(F36:F41) -> 108 | G46: =SUM(G36:G41) -> 3 | H46: =SUM(H36:H43) -> 204 | I46: =SUM(I36:I43) -> 6 | J46: =SUM(J36:J41) -> 218 | K46: =SUM(K36:K41) -> 5 | L46: =SUM(L36:L41) -> 220 | M46: =SUM(M36:M41) -> 3 | N46: =SUM(N36:N41) -> 220 | O46: =SUM(O36:O41) -> 3 | P46: =SUM(P36:P41) -> 220 | Q46: =SUM(Q36:Q41) -> 3 | ... AW46: =SUM(AW36:AW41) -> 37 | AX46: =SUM(AX36:AX45) -> 192 | AY46: =SUM(AY36:AY45) -> 37 | AZ46: =SUM(AZ36:AZ45) -> 123 | BA46: =SUM(BA36:BA45) -> 0 | BB46: =SUM(BB36:BB45) -> 195 | BC46: =SUM(BC36:BC45) -> 28 | BD46: =SUM(BD36:BD45) -> 194 | BE46: =SUM(BE36:BE45) -> 35 | ... BG46: =SUM(BG36:BG45) -> 35
A48: Servicios
A49: PU - LI | D49: =D5+E5+D12+E12+D23+E23 -> 72 | F49: =F5+G5+F12+G12+F23+G23 -> 54 | H49: =H5+I5+H12+I12+H23+I23 -> 69 | J49: =J5+K5+J12+K12+J23+K23 -> 79 | L49: =L5+M5+L12+M12+L23+M23 -> 79 | N49: =N5+O5+N12+O12+N23+O23 -> 79 | P49: =P5+Q5+P12+Q12+P23+Q23 -> 79 | R49: =R5+S5+R12+S12+R23+S23 -> 67 | T49: =T5+U5+T12+U12+T23+U23 -> 25 | V49: =V5+W5+V12+W12+V23+W23 -> 80 | X49: =X5+Y5+X12+Y12+X23+Y23 -> 79 | Z49: =Z5+AA5+Z12+AA12+Z23+AA23 -> 79 | AB49: =AB5+AC5+AB12+AC12+AB23+AC23 -> 79 | AD49: =AD5+AE5+AD12+AE12+AD23+AE23 -> 79 | AF49: =AF5+AG5+AF12+AG12+AF23+AG23 -> 72 | AH49: =AH5+AI5+AH12+AI12+AH23+AI23 -> 54 | AJ49: =AJ5+AK5+AJ12+AK12+AJ23+AK23 -> 79 | AL49: =AL5+AM5+AL12+AM12+AL23+AM23 -> 79 | AN49: =AN5+AO5+AN12+AO12+AN23+AO23 -> 79 | AP49: =AP5+AQ5+AP12+AQ12+AP23+AQ23 -> 79 | AR49: =AR5+AS5+AR12+AS12+AR23+AS23 -> 79 | AT49: =AT5+AU5+AT12+AU12+AT23+AU23 -> 72 | AV49: =AV5+AW5+AV12+AW12+AV23+AW23 -> 54 | AX49: =AX5+AY5+AX12+AY12+AX23+AY23 -> 79 | AZ49: =AZ5+BA5+AZ12+BA12+AZ23+BA23 -> 44 | BB49: =BB5+BC5+BB12+BC12+BB23+BC23 -> 79 | BD49: =BD5+BE5+BD12+BE12+BD23+BE23 -> 79 | BF49: =BF5+BG5+BF12+BG12+BF23+BG23 -> 79
A50: LI - PU | D50: =D8+E8+D15+E15+D26+E26 -> 75 | F50: =F8+G8+F15+G15+F26+G26 -> 57 | H50: =H8+I8+H15+I15+H26+I26 -> 71 | J50: =J8+K8+J15+K15+J26+K26 -> 78 | L50: =L8+M8+L15+M15+L26+M26 -> 78 | N50: =N8+O8+N15+O15+N26+O26 -> 78 | P50: =P8+Q8+P15+Q15+P26+Q26 -> 78 | R50: =R8+S8+R15+S15+R26+S26 -> 71 | T50: =T8+U8+T15+U15+T26+U26 -> 27 | V50: =V8+W8+V15+W15+V26+W26 -> 78 | X50: =X8+Y8+X15+Y15+X26+Y26 -> 78 | Z50: =Z8+AA8+Z15+AA15+Z26+AA26 -> 78 | AB50: =AB8+AC8+AB15+AC15+AB26+AC26 -> 78 | AD50: =AD8+AE8+AD15+AE15+AD26+AE26 -> 78 | AF50: =AF8+AG8+AF15+AG15+AF26+AG26 -> 75 | AH50: =AH8+AI8+AH15+AI15+AH26+AI26 -> 57 | AJ50: =AJ8+AK8+AJ15+AK15+AJ26+AK26 -> 78 | AL50: =AL8+AM8+AL15+AM15+AL26+AM26 -> 78 | AN50: =AN8+AO8+AN15+AO15+AN26+AO26 -> 78 | AP50: =AP8+AQ8+AP15+AQ15+AP26+AQ26 -> 78 | AR50: =AR8+AS8+AR15+AS15+AR26+AS26 -> 78 | AT50: =AT8+AU8+AT15+AU15+AT26+AU26 -> 75 | AV50: =AV8+AW8+AV15+AW15+AV26+AW26 -> 57 | AX50: =AX8+AY8+AX15+AY15+AX26+AY26 -> 78 | AZ50: =AZ8+BA8+AZ15+BA15+AZ26+BA26 -> 45 | BB50: =BB8+BC8+BB15+BC15+BB26+BC26 -> 78 | BD50: =BD8+BE8+BD15+BE15+BD26+BE26 -> 78 | BF50: =BF8+BG8+BF15+BG15+BF26+BG26 -> 78
...

Sheet Oferta Diaria
A1: Oferta Febrero 2025
C3: 45689 | D3: 45690 | E3: 45691 | F3: 45692 | G3: 45693 | H3: 45694 | I3: 45695 | J3: 45696 | K3: 45697 | L3: 45698 | M3: 45699 | N3: 45700 | O3: 45701 | P3: 45702 | Q3: 45703 | R3: 45704 | S3: 45705 | T3: 45706 | U3: 45707 | V3: 45708 | W3: 45709 | X3: 45710 | Y3: 45711 | Z3: 45712 | AA3: 45713 | AB3: 45714 | AC3: 45715 | AD3: 45716
A4: HÁBIL | B4: km
A5: Servicios PU-LI | B5: 43.13 | C5: ='Data Ocupacion'!D49 -> 72 | D5: ='Data Ocupacion'!F49 -> 54 | E5: ='Data Ocupacion'!H49 -> 69 | F5: ='Data Ocupacion'!J49 -> 79 | G5: ='Data Ocupacion'!L49 -> 79 | H5: ='Data Ocupacion'!N49 -> 79 | I5: ='Data Ocupacion'!P49 -> 79 | J5: ='Data Ocupacion'!R49 -> 67 | K5: ='Data Ocupacion'!T49 -> 25 | L5: ='Data Ocupacion'!V49 -> 80 | M5: ='Data Ocupacion'!X49 -> 79 | N5: ='Data Ocupacion'!Z49 -> 79 | O5: ='Data Ocupacion'!AB49 -> 79 | P5: ='Data Ocupacion'!AD49 -> 79 | Q5: ='Data Ocupacion'!AF49 -> 72 | R5: ='Data Ocupacion'!AH49 -> 54 | S5: ='Data Ocupacion'!AJ49 -> 79 | T5: ='Data Ocupacion'!AL49 -> 79 | U5: ='Data Ocupacion'!AN49 -> 79 | V5: ='Data Ocupacion'!AP49 -> 79 | W5: ='Data Ocupacion'!AR49 -> 79 | X5: ='Data Ocupacion'!AT49 -> 72 | Y5: ='Data Ocupacion'!AV49 -> 54 | Z5: ='Data Ocupacion'!AX49 -> 79 | AA5: ='Data Ocupacion'!AZ49 -> 44 | AB5: ='Data Ocupacion'!BB49 -> 79 | AC5: ='Data Ocupacion'!BD49 -> 79 | AD5: ='Data Ocupacion'!BF49 -> 79
A6: Servicios LI-PU | B6: 43.13 | C6: ='Data Ocupacion'!D50 -> 75 | D6: ='Data Ocupacion'!F50 -> 57 | E6: ='Data Ocupacion'!H50 -> 71 | F6: ='Data Ocupacion'!J50 -> 78 | G6: ='Data Ocupacion'!L50 -> 78 | H6: ='Data Ocupacion'!N50 -> 78 | I6: ='Data Ocupacion'!P50 -> 78 | J6: ='Data Ocupacion'!R50 -> 71 | K6: ='Data Ocupacion'!T50 -> 27 | L6: ='Data Ocupacion'!V50 -> 78 | M6: ='Data Ocupacion'!X50 -> 78 | N6: ='Data Ocupacion'!Z50 -> 78 | O6: ='Data Ocupacion'!AB50 -> 78 | P6: ='Data Ocupacion'!AD50 -> 78 | Q6: ='Data Ocupacion'!AF50 -> 75 | R6: ='Data Ocupacion'!AH50 -> 57 | S6: ='Data Ocupacion'!AJ50 -> 78 | T6: ='Data Ocupacion'!AL50 -> 78 | U6: ='Data Ocupacion'!AN50 -> 78 | V6: ='Data Ocupacion'!AP50 -> 78 | W6: ='Data Ocupacion'!AR50 -> 78 | X6: ='Data Ocupacion'!AT50 -> 75 | Y6: ='Data Ocupacion'!AV50 -> 57 | Z6: ='Data Ocupacion'!AX50 -> 78 | AA6: ='Data Ocupacion'!AZ50 -> 45 | AB6: ='Data Ocupacion'!BB50 -> 78 | AC6: ='Data Ocupacion'!BD50 -> 78 | AD6: ='Data Ocupacion'!BF50 -> 78
A7: Servicios PU-SA | B7: 29.11 | C7: ='Data Ocupacion'!D51 -> 0 | D7: ='Data Ocupacion'!F51 -> 0 | E7: ='Data Ocupacion'!H51 -> 30 | F7: ='Data Ocupacion'!J51 -> 33 | G7: ='Data Ocupacion'!L51 -> 33 | H7: ='Data Ocupacion'!N51 -> 33 | I7: ='Data Ocupacion'!P51 -> 33 | J7: ='Data Ocupacion'!R51 -> 0 | K7: ='Data Ocupacion'!T51 -> 0 | L7: ='Data Ocupacion'!V51 -> 31 | M7: ='Data Ocupacion'!X51 -> 33 | N7: ='Data Ocupacion'!Z51 -> 33 | O7: ='Data Ocupacion'!AB51 -> 33 | P7: ='Data Ocupacion'!AD51 -> 33 | Q7: ='Data Ocupacion'!AF51 -> 0 | R7: ='Data Ocupacion'!AH51 -> 0 | S7: ='Data Ocupacion'!AJ51 -> 33 | T7: ='Data Ocupacion'!AL51 -> 33 | U7: ='Data Ocupacion'!AN51 -> 33 | V7: ='Data Ocupacion'!AP51 -> 33 | W7: ='Data Ocupacion'!AR51 -> 33 | X7: ='Data Ocupacion'!AT51 -> 0 | Y7: ='Data Ocupacion'!AV51 -> 0 | Z7: ='Data Ocupacion'!AX51 -> 33 | AA7: ='Data Ocupacion'!AZ51 -> 13 | AB7: ='Data Ocupacion'!BB51 -> 33 | AC7: ='Data Ocupacion'!BD51 -> 33 | AD7: ='Data Ocupacion'!BF51 -> 33
A8: Servicios SA-PU | B8: 29.11 | C8: ='Data Ocupacion'!D52 -> 0 | D8: ='Data Ocupacion'!F52 -> 0 | E8: ='Data Ocupacion'!H52 -> 29 | F8: ='Data Ocupacion'!J52 -> 32 | G8: ='Data Ocupacion'!L52 -> 32 | H8: ='Data Ocupacion'!N52 -> 32 | I8: ='Data Ocupacion'!P52 -> 32 | J8: ='Data Ocupacion'!R52 -> 0 | K8: ='Data Ocupacion'!T52 -> 0 | L8: ='Data Ocupacion'!V52 -> 32 | M8: ='Data Ocupacion'!X52 -> 32 | N8: ='Data Ocupacion'!Z52 -> 32 | O8: ='Data Ocupacion'!AB52 -> 32 | P8: ='Data Ocupacion'!AD52 -> 32 | Q8: ='Data Ocupacion'!AF52 -> 0 | R8: ='Data Ocupacion'!AH52 -> 0 | S8: ='Data Ocupacion'!AJ52 -> 32 | T8: ='Data Ocupacion'!AL52 -> 32 | U8: ='Data Ocupacion'!AN52 -> 32 | V8: ='Data Ocupacion'!AP52 -> 32 | W8: ='Data Ocupacion'!AR52 -> 32 | X8: ='Data Ocupacion'!AT52 -> 0 | Y8: ='Data Ocupacion'!AV52 -> 0 | Z8: ='Data Ocupacion'!AX52 -> 32 | AA8: ='Data Ocupacion'!AZ52 -> 14 | AB8: ='Data Ocupacion'!BB52 -> 32 | AC8: ='Data Ocupacion'!BD52 -> 32 | AD8: ='Data Ocupacion'!BF52 -> 32
A9: Servicios PU-EB | B9: 25.4 | C9: ='Data Ocupacion'!D53 -> 0 | D9: ='Data Ocupacion'!F53 -> 0 | E9: ='Data Ocupacion'!H53 -> 0 | F9: ='Data Ocupacion'!J53 -> 0 | G9: ='Data Ocupacion'!L53 -> 0 | H9: ='Data Ocupacion'!N53 -> 0 | I9: ='Data Ocupacion'!P53 -> 0 | J9: ='Data Ocupacion'!R53 -> 0 | K9: ='Data Ocupacion'!T53 -> 0 | L9: ='Data Ocupacion'!V53 -> 0 | M9: ='Data Ocupacion'!X53 -> 0 | N9: ='Data Ocupacion'!Z53 -> 0 | O9: ='Data Ocupacion'!AB53 -> 0 | P9: ='Data Ocupacion'!AD53 -> 0 | Q9: ='Data Ocupacion'!AF53 -> 0 | R9: ='Data Ocupacion'!AH53 -> 0 | S9: ='Data Ocupacion'!AJ53 -> 0 | T9: ='Data Ocupacion'!AL53 -> 0 | U9: ='Data Ocupacion'!AN53 -> 0 | V9: ='Data Ocupacion'!AP53 -> 0 | W9: ='Data Ocupacion'!AR53 -> 0 | X9: ='Data Ocupacion'!AT53 -> 0 | Y9: ='Data Ocupacion'!AV53 -> 0 | Z9: ='Data Ocupacion'!AX53 -> 0 | AA9: ='Data Ocupacion'!AZ53 -> 0 | AB9: ='Data Ocupacion'!BB53 -> 0 | AC9: ='Data Ocupacion'!BD53 -> 0 | AD9: ='Data Ocupacion'!BF53 -> 0
A10: Servicios EB-PU | B10: 25.4 | C10: ='Data Ocupacion'!D54 -> 0 | D10: ='Data Ocupacion'!F54 -> 0 | E10: ='Data Ocupacion'!H54 -> 1 | F10: ='Data Ocupacion'!J54 -> 1 | G10: ='Data Ocupacion'!L54 -> 1 | H10: ='Data Ocupacion'!N54 -> 1 | I10: ='Data Ocupacion'!P54 -> 1 | J10: ='Data Ocupacion'!R54 -> 0 | K10: ='Data Ocupacion'!T54 -> 0 | L10: ='Data Ocupacion'!V54 -> 1 | M10: ='Data Ocupacion'!X54 -> 1 | N10: ='Data Ocupacion'!Z54 -> 1 | O10: ='Data Ocupacion'!AB54 -> 1 | P10: ='Data Ocupacion'!AD54 -> 1 | Q10: ='Data Ocupacion'!AF54 -> 0 | R10: ='Data Ocupacion'!AH54 -> 0 | S10: ='Data Ocupacion'!AJ54 -> 1 | T10: ='Data Ocupacion'!AL54 -> 1 | U10: ='Data Ocupacion'!AN54 -> 1 | V10: ='Data Ocupacion'!AP54 -> 1 | W10: ='Data Ocupacion'!AR54 -> 1 | X10: ='Data Ocupacion'!AT54 -> 0 | Y10: ='Data Ocupacion'!AV54 -> 0 | Z10: ='Data Ocupacion'!AX54 -> 1 | AA10: ='Data Ocupacion'!AZ54 -> 1 | AB10: ='Data Ocupacion'!BB54 -> 1 | AC10: ='Data Ocupacion'!BD54 -> 1 | AD10: ='Data Ocupacion'!BF54 -> 1
A11: Servicios PU-ES | B11: 11.71 | E11: 6
A12: Servicios ES-PU | B12: 11.71 | E12: 4
A13: Servicios VM-LI | B13: 34.83 | Z13: 4 | AA13: 4 | AC13: 4 | AD13: 4
A14: Servicios VM-PU | B14: 8.3 | Z14: 2 | AA14: 2 | AC14: 2 | AD14: 2
A16: Trenes PU-LI | B16: 43.13 | C16: ='Data Ocupacion'!D61 -> 75 | D16: ='Data Ocupacion'!F61 -> 57 | E16: ='Data Ocupacion'!H61 -> 72 | F16: ='Data Ocupacion'!J61 -> 81 | G16: ='Data Ocupacion'!L61 -> 80 | H16: ='Data Ocupacion'!N61 -> 80 | I16: ='Data Ocupacion'!P61 -> 80 | J16: ='Data Ocupacion'!R61 -> 73 | K16: ='Data Ocupacion'!T61 -> 50 | L16: ='Data Ocupacion'!V61 -> 81 | M16: ='Data Ocupacion'!X61 -> 80 | N16: ='Data Ocupacion'!Z61 -> 80 | O16: ='Data Ocupacion'!AB61 -> 80 | P16: ='Data Ocupacion'!AD61 -> 80 | Q16: ='Data Ocupacion'!AF61 -> 75 | R16: ='Data Ocupacion'!AH61 -> 57 | S16: ='Data Ocupacion'!AJ61 -> 80 | T16: ='Data Ocupacion'!AL61 -> 80 | U16: ='Data Ocupacion'!AN61 -> 80 | V16: ='Data Ocupacion'!AP61 -> 80 | W16: ='Data Ocupacion'!AR61 -> 80 | X16: ='Data Ocupacion'!AT61 -> 75 | Y16: ='Data Ocupacion'!AV61 -> 76 | Z16: ='Data Ocupacion'!AX61 -> 97 | AA16: ='Data Ocupacion'!AZ61 -> 44 | AB16: ='Data Ocupacion'!BB61 -> 93 | AC16: ='Data Ocupacion'!BD61 -> 96 | AD16: ='Data Ocupacion'!BF61 -> 96
A17: Trenes LI-PU | B17: 43.13 | C17: ='Data Ocupacion'!D62 -> 75 | D17: ='Data Ocupacion'!F62 -> 57 | E17: ='Data Ocupacion'!H62 -> 74 | F17: ='Data Ocupacion'!J62 -> 81 | G17: ='Data Ocupacion'!L62 -> 80 | H17: ='Data Ocupacion'!N62 -> 80 | I17: ='Data Ocupacion'!P62 -> 80 | J17: ='Data Ocupacion'!R62 -> 73 | K17: ='Data Ocupacion'!T62 -> 52 | L17: ='Data Ocupacion'!V62 -> 80 | M17: ='Data Ocupacion'!X62 -> 80 | N17: ='Data Ocupacion'!Z62 -> 80 | O17: ='Data Ocupacion'!AB62 -> 80 | P17: ='Data Ocupacion'!AD62 -> 80 | Q17: ='Data Ocupacion'!AF62 -> 75 | R17: ='Data Ocupacion'!AH62 -> 57 | S17: ='Data Ocupacion'!AJ62 -> 80 | T17: ='Data Ocupacion'!AL62 -> 80 | U17: ='Data Ocupacion'!AN62 -> 80 | V17: ='Data Ocupacion'!AP62 -> 80 | W17: ='Data Ocupacion'!AR62 -> 80 | X17: ='Data Ocupacion'!AT62 -> 75 | Y17: ='Data Ocupacion'!AV62 -> 72 | Z17: ='Data Ocupacion'!AX62 -> 97 | AA17: ='Data Ocupacion'!AZ62 -> 45 | AB17: ='Data Ocupacion'!BB62 -> 92 | AC17: ='Data Ocupacion'!BD62 -> 96 | AD17: ='Data Ocupacion'!BF62 -> 96
A18: Trenes PU-SA | B18: 29.11 | C18: ='Data Ocupacion'!D63 -> 0 | D18: ='Data Ocupacion'!F63 -> 0 | E18: ='Data Ocupacion'!H63 -> 30 | F18: ='Data Ocupacion'!J63 -> 33 | G18: ='Data Ocupacion'!L63 -> 33 | H18: ='Data Ocupacion'!N63 -> 33 | I18: ='Data Ocupacion'!P63 -> 33 | J18: ='Data Ocupacion'!R63 -> 0 | K18: ='Data Ocupacion'!T63 -> 0 | L18: ='Data Ocupacion'!V63 -> 31 | M18: ='Data Ocupacion'!X63 -> 33 | N18: ='Data Ocupacion'!Z63 -> 33 | O18: ='Data Ocupacion'!AB63 -> 33 | P18: ='Data Ocupacion'!AD63 -> 33 | Q18: ='Data Ocupacion'!AF63 -> 0 | R18: ='Data Ocupacion'!AH63 -> 0 | S18: ='Data Ocupacion'!AJ63 -> 33 | T18: ='Data Ocupacion'!AL63 -> 33 | U18: ='Data Ocupacion'!AN63 -> 33 | V18: ='Data Ocupacion'!AP63 -> 33 | W18: ='Data Ocupacion'!AR63 -> 33 | X18: ='Data Ocupacion'!AT63 -> 0 | Y18: ='Data Ocupacion'!AV63 -> 0 | Z18: ='Data Ocupacion'!AX63 -> 33 | AA18: ='Data Ocupacion'!AZ63 -> 13 | AB18: ='Data Ocupacion'!BB63 -> 33 | AC18: ='Data Ocupacion'!BD63 -> 33 | AD18: ='Data Ocupacion'!BF63 -> 33
A19: Trenes SA-PU | B19: 29.11 | C19: ='Data Ocupacion'!D64 -> 0 | D19: ='Data Ocupacion'!F64 -> 0 | E19: ='Data Ocupacion'!H64 -> 29 | F19: ='Data Ocupacion'!J64 -> 32 | G19: ='Data Ocupacion'!L64 -> 32 | H19: ='Data Ocupacion'!N64 -> 32 | I19: ='Data Ocupacion'!P64 -> 32 | J19: ='Data Ocupacion'!R64 -> 0 | K19: ='Data Ocupacion'!T64 -> 0 | L19: ='Data Ocupacion'!V64 -> 32 | M19: ='Data Ocupacion'!X64 -> 32 | N19: ='Data Ocupacion'!Z64 -> 32 | O19: ='Data Ocupacion'!AB64 -> 32 | P19: ='Data Ocupacion'!AD64 -> 32 | Q19: ='Data Ocupacion'!AF64 -> 0 | R19: ='Data Ocupacion'!AH64 -> 0 | S19: ='Data Ocupacion'!AJ64 -> 32 | T19: ='Data Ocupacion'!AL64 -> 32 | U19: ='Data Ocupacion'!AN64 -> 32 | V19: ='Data Ocupacion'!AP64 -> 32 | W19: ='Data Ocupacion'!AR64 -> 32 | X19: ='Data Ocupacion'!AT64 -> 0 | Y19: ='Data Ocupacion'!AV64 -> 0 | Z19: ='Data Ocupacion'!AX64 -> 32 | AA19: ='Data Ocupacion'!AZ64 -> 14 | AB19: ='Data Ocupacion'!BB64 -> 32 | AC19: ='Data Ocupacion'!BD64 -> 32 | AD19: ='Data Ocupacion'!BF64 -> 32
A20: Trenes EB-PU | B20: 25.4 | C20: ='Data Ocupacion'!D66 -> 0 | D20: ='Data Ocupacion'!F66 -> 0 | E20: ='Data Ocupacion'!H66 -> 1 | F20: ='Data Ocupacion'!J66 -> 1 | G20: ='Data Ocupacion'!L66 -> 1 | H20: ='Data Ocupacion'!N66 -> 1 | I20: ='Data Ocupacion'!P66 -> 1 | J20: ='Data Ocupacion'!R66 -> 0 | K20: ='Data Ocupacion'!T66 -> 0 | L20: ='Data Ocupacion'!V66 -> 1 | M20: ='Data Ocupacion'!X66 -> 1 | N20: ='Data Ocupacion'!Z66 -> 1 | O20: ='Data Ocupacion'!AB66 -> 1 | P20: ='Data Ocupacion'!AD66 -> 1 | Q20: ='Data Ocupacion'!AF66 -> 0 | R20: ='Data Ocupacion'!AH66 -> 0 | S20: ='Data Ocupacion'!AJ66 -> 1 | T20: ='Data Ocupacion'!AL66 -> 1 | U20: ='Data Ocupacion'!AN66 -> 1 | V20: ='Data Ocupacion'!AP66 -> 1 | W20: ='Data Ocupacion'!AR66 -> 1 | X20: ='Data Ocupacion'!AT66 -> 0 | Y20: ='Data Ocupacion'!AV66 -> 0 | Z20: ='Data Ocupacion'!AX66 -> 1 | AA20: ='Data Ocupacion'!AZ66 -> 1 | AB20: ='Data Ocupacion'!BB66 -> 1 | AC20: ='Data Ocupacion'!BD66 -> 1 | AD20: ='Data Ocupacion'!BF66 -> 1
A21: Trenes PU-EB | B21: 25.4 | C21: 0 | D21: 0 | E21: 0 | F21: 0 | G21: 0 | H21: 0 | I21: 0 | J21: 0 | K21: 0 | L21: 0 | M21: 0 | N21: 0 | O21: 0 | P21: 0 | Q21: 0 | R21: 0 | S21: 0 | T21: 0 | U21: 0 | V21: 0 | W21: 0 | X21: 0 | Y21: 0 | Z21: 0 | AA21: 0 | AB21: 0 | AC21: 0 | AD21: 0
A22: Trenes PU-ES | B22: 11.71 | E22: 6
A23: Trenes ES-PU | B23: 11.71 | E23: 4
A24: Trenes VM-LI | B24: 34.83 | Z24: 4 | AA24: 4 | AC24: 4 | AD24: 4
A25: Trenes VM-PU | B25: 8.3 | Z25: 2 | AA25: 2 | AC25: 2 | AD25: 2
A27: Corte EB (600) | B27: -17.73 | C27: ='KM-Servicio'!Q5 -> 0 | D27: ='KM-Servicio'!Q12 -> 0 | E27: ='KM-Servicio'!Q19 -> 0 | F27: ='KM-Servicio'!Q28 -> 0 | G27: ='KM-Servicio'!Q35 -> 0 | H27: ='KM-Servicio'!Q42 -> 0 | I27: ='KM-Servicio'!Q49 -> 0 | J27: ='KM-Servicio'!Q56 -> 0 | K27: ='KM-Servicio'!Q63 -> 0 | L27: ='KM-Servicio'!Q70 -> 0 | M27: ='KM-Servicio'!Q77 -> 0 | N27: ='KM-Servicio'!Q84 -> 0 | O27: ='KM-Servicio'!Q91 -> 0 | P27: ='KM-Servicio'!Q98 -> 0 | Q27: ='KM-Servicio'!Q105 -> 0 | R27: ='KM-Servicio'!Q112 -> 0 | S27: ='KM-Servicio'!Q119 -> 0 | T27: ='KM-Servicio'!Q126 -> 0 | U27: ='KM-Servicio'!Q133 -> 0 | V27: ='KM-Servicio'!Q140 -> 0 | W27: ='KM-Servicio'!Q147 -> 0 | X27: ='KM-Servicio'!Q154 -> 0 | Y27: ='KM-Servicio'!Q161 -> 0 | Z27: ='KM-Servicio'!Q168 -> 0 | AA27: ='KM-Servicio'!Q177 -> 0 | AB27: ='KM-Servicio'!Q186 -> 0 | AC27: ='KM-Servicio'!Q193 -> 0 | AD27: ='KM-Servicio'!Q202 -> 0
A28: Acople EB (600) | B28: -17.73 | C28: ='KM-Servicio'!T6 -> 0 | D28: ='KM-Servicio'!T13 -> 0 | E28: ='KM-Servicio'!T20 -> 0 | F28: ='KM-Servicio'!T29 -> 0 | G28: ='KM-Servicio'!T36 -> 0 | H28: ='KM-Servicio'!T43 -> 0 | I28: ='KM-Servicio'!T50 -> 0 | J28: ='KM-Servicio'!T57 -> 0 | K28: ='KM-Servicio'!T64 -> 0 | L28: ='KM-Servicio'!T71 -> 0 | M28: ='KM-Servicio'!T78 -> 0 | N28: ='KM-Servicio'!T85 -> 0 | O28: ='KM-Servicio'!T92 -> 0 | P28: ='KM-Servicio'!T99 -> 0 | Q28: ='KM-Servicio'!T106 -> 0 | R28: ='KM-Servicio'!T113 -> 0 | S28: ='KM-Servicio'!T120 -> 0 | T28: ='KM-Servicio'!T127 -> 0 | U28: ='KM-Servicio'!T134 -> 0 | V28: ='KM-Servicio'!T141 -> 0 | W28: ='KM-Servicio'!T148 -> 0 | X28: ='KM-Servicio'!T155 -> 0 | Y28: ='KM-Servicio'!T162 -> 0 | Z28: ='KM-Servicio'!T169 -> 0 | AA28: ='KM-Servicio'!T176 -> 0 | AB28: ='KM-Servicio'!T187 -> 1 | AC28: ='KM-Servicio'!T194 -> 1 | AD28: ='KM-Servicio'!T203 -> 1
A29: Acople/Corte SA (600) | B29: -14.02 | C29: ='KM-Servicio'!U6 -> 0 | D29: ='KM-Servicio'!U13 -> 0 | E29: ='KM-Servicio'!U20 -> 0 | F29: ='KM-Servicio'!U29 -> 0 | G29: ='KM-Servicio'!U36 -> 0 | H29: ='KM-Servicio'!U43 -> 0 | I29: ='KM-Servicio'!U50 -> 0 | J29: ='KM-Servicio'!U57 -> 0 | K29: ='KM-Servicio'!U64 -> 0 | L29: ='KM-Servicio'!U71 -> 0 | M29: ='KM-Servicio'!U78 -> 0 | N29: ='KM-Servicio'!U85 -> 0 | O29: ='KM-Servicio'!U92 -> 0 | P29: ='KM-Servicio'!U99 -> 0 | Q29: ='KM-Servicio'!U106 -> 0 | R29: ='KM-Servicio'!U113 -> 0 | S29: ='KM-Servicio'!U120 -> 0 | T29: ='KM-Servicio'!U127 -> 0 | U29: ='KM-Servicio'!U134 -> 0 | V29: ='KM-Servicio'!U141 -> 0 | W29: ='KM-Servicio'!U148 -> 0 | X29: ='KM-Servicio'!U155 -> 0 | Y29: ='KM-Servicio'!U162 -> 0 | Z29: ='KM-Servicio'!U169 -> 0 | AA29: ='KM-Servicio'!U178 -> 0 | AB29: ='KM-Servicio'!U187 -> 0 | AC29: ='KM-Servicio'!U194 -> 0 | AD29: ='KM-Servicio'!U203 -> 0
A30: Corte EB (400) | B30: -3.71 | E30: ='KM-Servicio'!Q21 -> 0 | G30: ='KM-Servicio'!Q37 -> 0 | N30: ='KM-Servicio'!Q86 -> 0
A31: Acople EB (600) vía 1 | B31: -25.4 | Y31: 4 | AA31: 4 | AB31: 3 | AC31: 4 | AD31: 3
A33: Servicios | B33: =SUM(C33:AD33) -> 5328 | C33: =SUM(C5:C10) -> 147 | D33: =SUM(D5:D10) -> 111 | E33: =SUM(E5:E12) -> 210 | F33: =SUM(F5:F10) -> 223 | G33: =SUM(G5:G10) -> 223 | H33: =SUM(H5:H10) -> 223 | I33: =SUM(I5:I10) -> 223 | J33: =SUM(J5:J10) -> 138 | K33: =SUM(K5:K10) -> 52 | L33: =SUM(L5:L10) -> 222 | M33: =SUM(M5:M10) -> 223 | ... Y33: =SUM(Y5:Y10) -> 111 | Z33: =SUM(Z5:Z14) -> 229 | AA33: =SUM(AA5:AA14) -> 123 | AB33: =SUM(AB5:AB14) -> 223 | AC33: =SUM(AC5:AC14) -> 229 | AD33: =SUM(AD5:AD14) -> 229
A34: Trenes | B34: =SUM(C34:AD34) -> 5623 | C34: =SUM(C16:C21) -> 150 | D34: =SUM(D16:D21) -> 114 | E34: =SUM(E16:E23) -> 216 | F34: =SUM(F16:F21) -> 228 | G34: =SUM(G16:G21) -> 226 | H34: =SUM(H16:H21) -> 226 | I34: =SUM(I16:I21) -> 226 | J34: =SUM(J16:J21) -> 146 | K34: =SUM(K16:K21) -> 102 | L34: =SUM(L16:L21) -> 225 | M34: =SUM(M16:M21) -> 226 | ... Y34: =SUM(Y16:Y21) -> 148 | Z34: =SUM(Z16:Z25) -> 266 | AA34: =SUM(AA16:AA25) -> 123 | AB34: =SUM(AB16:AB25) -> 251 | AC34: =SUM(AC16:AC25) -> 264 | AD34: =SUM(AD16:AD25) -> 264
A35: Trenes KM | B35: =SUM(C35:AD35) -> 223348.28 | C35: =(C16*$B$16+C17*$B$17+C18*$B$18+C19*$B$19+C21*$B$21+C28*$B$28+C20*$B$20+C27*$B$27+C29*$B$29+C30*$B$30) -> 6469.5 | D35: =(D16*$B$16+D17*$B$17+D18*$B$18+D19*$B$19+D21*$B$21+D28*$B$28+D20*$B$20+D27*$B$27+D29*$B$29+D30*$B$30) -> 4916.82 | E35: =(E16*$B$16+E17*$B$17+E18*$B$18+E19*$B$19+E21*$B$21+E28*$B$28+E20*$B$20+E27*$B$27+E29*$B$29+E30*$B$30+E22*B22+E23*B23) -> 8156.97 | F35: =(F16*$B$16+F17*$B$17+F18*$B$18+F19*$B$19+F21*$B$21+F28*$B$28+F20*$B$20+F27*$B$27+F29*$B$29+F30*$B$30) -> 8904.61 | G35: =(G16*$B$16+G17*$B$17+G18*$B$18+G19*$B$19+G21*$B$21+G28*$B$28+G20*$B$20+G27*$B$27+G29*$B$29+G30*$B$30) -> 8818.35 | H35: =(H16*$B$16+H17*$B$17+H18*$B$18+H19*$B$19+H21*$B$21+H28*$B$28+H20*$B$20+H27*$B$27+H29*$B$29+H30*$B$30) -> 8818.35 | I35: =(I16*$B$16+I17*$B$17+I18*$B$18+I19*$B$19+I21*$B$21+I28*$B$28+I20*$B$20+I27*$B$27+I29*$B$29+I30*$B$30) -> 8818.35 | J35: =(J16*$B$16+J17*$B$17+J18*$B$18+J19*$B$19+J21*$B$21+J28*$B$28+J20*$B$20+J27*$B$27+J29*$B$29+J30*$B$30) -> 6296.98 | K35: =(K16*$B$16+K17*$B$17+K18*$B$18+K19*$B$19+K21*$B$21+K28*$B$28+K20*$B$20+K27*$B$27+K29*$B$29+K30*$B$30) -> 4399.26 | L35: =(L16*$B$16+L17*$B$17+L18*$B$18+L19*$B$19+L21*$B$21+L28*$B$28+L20*$B$20+L27*$B$27+L29*$B$29+L30*$B$30) -> 8803.26 | M35: =(M16*$B$16+M17*$B$17+M18*$B$18+M19*$B$19+M21*$B$21+M28*$B$28+M20*$B$20+M27*$B$27+M29*$B$29+M30*$B$30) -> 8818.35 | ... X35: =(X16*$B$16+X17*$B$17+X18*$B$18+X19*$B$19+X21*$B$21+X28*$B$28+X20*$B$20+X27*$B$27+X29*$B$29+X30*$B$30) -> 6469.5 | Y35: =(Y16*$B$16+Y17*$B$17+Y18*$B$18+Y19*$B$19+Y21*$B$21+Y28*$B$28+Y20*$B$20+Y27*$B$27+Y29*$B$29+Y30*$B$30+Y31*$B$31) -> 6281.64 | Z35: =(Z16*$B$16+Z17*$B$17+Z18*$B$18+Z19*$B$19+Z21*$B$21+Z28*$B$28+Z20*$B$20+Z27*$B$27+Z29*$B$29+Z30*$B$30+Z24*$B$24+Z25*$B$25) -> 10440.69 | AA35: =(AA16*$B$16+AA17*$B$17+AA18*$B$18+AA19*$B$19+AA21*$B$21+AA28*$B$28+AA20*$B$20+AA27*$B$27+AA29*$B$29+AA31*$B$31+AA24*$B$24+AA25*$B$25) -> 4704.26 | AB35: =(AB16*$B$16+AB17*$B$17+AB18*$B$18+AB19*$B$19+AB21*$B$21+AB28*$B$28+AB20*$B$20+AB27*$B$27+AB29*$B$29+AB31*$B$31+AB24*$B$24+AB25*$B$25) -> 9802.67 | AC35: =(AC16*$B$16+AC17*$B$17+AC18*$B$18+AC19*$B$19+AC21*$B$21+AC28*$B$28+AC20*$B$20+AC27*$B$27+AC29*$B$29+AC31*$B$31+AC24*$B$24+AC25*$B$25) -> 10235.1 | AD35: =(AD16*$B$16+AD17*$B$17+AD18*$B$18+AD19*$B$19+AD21*$B$21+AD28*$B$28+AD20*$B$20+AD27*$B$27+AD29*$B$29+AD31*$B$31+AD24*$B$24+AD25*$B$25) -> 10260.5
