Workbook

Sheet Odometro-Kilometraje
A1: Control Contador Kilometraje de Trenes
B2: 45292 | C2: 45293 | D2: 45294 | E2: 45295 | F2: 45296 | G2: 45297 | H2: 45298 | I2: 45299 | J2: 45300 | K2: 45301 | L2: 45302 | M2: 45303 | N2: 45304 | O2: 45305 | P2: 45306 | Q2: 45307 | R2: 45308 | S2: 45309 | T2: 45310 | U2: 45311 | V2: 45312 | W2: 45313 | X2: 45314 | Y2: 45315 | Z2: 45316 | AA2: 45317 | AB2: 45318 | AC2: 45319 | AD2: 45320 | AE2: 45321 | AF2: 45322
B3: Contador | C3: Contador | D3: Contador | E3: Contador | F3: Contador | G3: Contador | H3: Contador | I3: Contador | J3: Contador | K3: Contador | L3: Contador | M3: Contador | N3: Contador | O3: Contador | P3: Contador | Q3: Contador | R3: Contador | S3: Contador | T3: Contador | U3: Contador | V3: Contador | W3: Contador | X3: Contador | Y3: Contador | Z3: Contador | AA3: Contador | AB3: Contador | AC3: Contador | AD3: Contador | AE3: Contador | AF3: Contador
A4: Tren | B4: Odómetro | C4: Odómetro | D4: Odómetro | E4: Odómetro | F4: Odómetro | G4: Odómetro | H4: Odómetro | I4: Odómetro | J4: Odómetro | K4: Odómetro | L4: Odómetro | M4: Odómetro | N4: Odómetro | O4: Odómetro | P4: Odómetro | Q4: Odómetro | R4: Odómetro | S4: Odómetro | T4: Odómetro | U4: Odómetro | V4: Odómetro | W4: Odómetro | X4: Odómetro | Y4: Odómetro | Z4: Odómetro | AA4: Odómetro | AB4: Odómetro | AC4: Odómetro | AD4: Odómetro | AE4: Odómetro | AF4: Odómetro
A5: M01 | B5: 1861436 | C5: 1861716 | D5: 1862171 | E5: 1862279 | F5: 1862472 | G5: 1862472 | H5: 1862472 | I5: 1863008 | J5: 1863483 | K5: 1863957 | L5: 1864322 | M5: 1864738 | N5: 1865256 | O5: 1865601 | P5: 1865907 | Q5: 1866055 | R5: 1866599 | S5: 1867073 | T5: 1867375 | U5: 1867635 | V5: 1868071 | W5: 1868219 | X5: 1868719 | Y5: 1868982 | Z5: 1869415 | AA5: 1869590 | AB5: 1869981 | AC5: 1870024 | AD5: 1870585 | AE5: 1870993 | AF5: 1871395
A6: M02 | B6: 1843658 | C6: 1843852 | D6: 1844371 | E6: 1844825 | F6: 1844845 | G6: 1844845 | H6: 1844890 | I6: 1845150 | J6: 1845604 | K6: 1845903 | L6: 1846288 | M6: 1846832 | N6: 1846875 | O6: 1847224 | P6: 1847330 | Q6: 1847456 | R6: 1847789 | S6: 1848244 | T6: 1848610 | U6: 1849044 | V6: 1849046 | W6: 1849309 | X6: 1849828 | Y6: 1850260 | Z6: 1850779 | AA6: 1851058 | AB6: 1851058 | AC6: 1851058 | AD6: 1851425 | AE6: 1851723 | AF6: 1852241
A7: M03 | B7: 1917925 | C7: 1918273 | D7: 1918380 | E7: 1918730 | F7: 1918973 | G7: 1918973 | H7: 1918973 | I7: 1918973 | J7: 1918973 | K7: 1918973 | L7: 1919493 | M7: 1919945 | N7: 1919945 | O7: 1919945 | P7: 1920398 | Q7: 1920875 | R7: 1921349 | S7: 1921697 | T7: 1922132 | U7: 1922611 | V7: 1922654 | W7: 1923090 | X7: 1923458 | Y7: 1923459 | Z7: 1923911 | AA7: 1924199 | AB7: 1924304 | AC7: 1924497 | AD7: 1924864 | AE7: 1925428 | AF7: 1925826
A8: M04 | B8: 1921935 | C8: 1922256 | D8: 1922451 | E8: 1922969 | F8: 1923053 | G8: 1923107 | H8: 1923282 | I8: 1923732 | J8: 1923856 | K8: 1924221 | L8: 1924613 | M8: 1925091 | N8: 1925611 | O8: 1925873 | P8: 1926047 | Q8: 1926525 | R8: 1926915 | S8: 1927194 | T8: 1927627 | U8: 1927627 | V8: 1927627 | W8: 1927629 | X8: 1927822 | Y8: 1928174 | Z8: 1928436 | AA8: 1928828 | AB8: 1929130 | AC8: 1929434 | AD8: 1929912 | AE8: 1930362 | AF8: 1930680
A9: M05 | B9: 1817897 | C9: 1818367 | D9: 1818493 | E9: 1818493 | F9: 1818600 | G9: 1818600 | H9: 1818600 | I9: 1818968 | J9: 1819405 | K9: 1819602 | L9: 1819900 | M9: 1820178 | N9: 1820198 | O9: 1820198 | P9: 1820409 | Q9: 1820842 | R9: 1821083 | S9: 1821515 | T9: 1821751 | U9: 1821751 | V9: 1821751 | W9: 1821875 | X9: 1822069 | Y9: 1822371 | Z9: 1822846 | AA9: 1823259 | AB9: 1823563 | AC9: 1823910 | AD9: 1824256 | AE9: 1824519 | AF9: 1824970
A10: M06 | B10: 1935072 | C10: 1935552 | D10: 1935772 | E10: 1936055 | F10: 1936441 | G10: 1936441 | H10: 1936441 | I10: 1936897 | J10: 1937250 | K10: 1937817 | L10: 1938296 | M10: 1938480 | N10: 1938832 | O10: 1938834 | P10: 1939290 | Q10: 1939834 | R10: 1940292 | S10: 1940489 | T10: 1941013 | U10: 1941275 | V10: 1941279 | W10: 1941581 | X10: 1941584 | Y10: 1942023 | Z10: 1942413 | AA10: 1942806 | AB10: 1943111 | AC10: 1943374 | AD10: 1943745 | AE10: 1943783 | AF10: 1944104
A11: M07 | B11: 1958327 | C11: 1958765 | D11: 1959114 | E11: 1959310 | F11: 1959678 | G11: 1959853 | H11: 1959855 | I11: 1960077 | J11: 1960553 | K11: 1961031 | L11: 1961507 | M11: 1962031 | N11: 1962509 | O11: 1962942 | P11: 1963506 | Q11: 1963894 | R11: 1964346 | S11: 1964764 | T11: 1965200 | U11: 1965460 | V11: 1965939 | W11: 1966330 | X11: 1966698 | Y11: 1966937 | Z11: 1967328 | AA11: 1967437 | AB11: 1967437 | AC11: 1967438 | AD11: 1967631 | AE11: 1968107 | AF11: 1968456
A12: M08 | B12: 1869219 | C12: 1869723 | D12: 1870221 | E12: 1870698 | F12: 1871219 | G12: 1871739 | H12: 1872173 | I12: 1872690 | J12: 1872795 | K12: 1873180 | L12: 1873479 | M12: 1873974 | N12: 1874195 | O12: 1874628 | P12: 1875078 | Q12: 1875452 | R12: 1875927 | S12: 1876378 | T12: 1876727 | U12: 1876727 | V12: 1876727 | W12: 1877007 | X12: 1877311 | Y12: 1877807 | Z12: 1877844 | AA12: 1878241 | AB12: 1878545 | AC12: 1878593 | AD12: 1879068 | AE12: 1879174 | AF12: 1879756
A13: M09 | B13: 1849199 | C13: 1849628 | D13: 1850192 | E13: 1850710 | F13: 1851232 | G13: 1851665 | H13: 1851925 | I13: 1852380 | J13: 1852595 | K13: 1853029 | L13: 1853359 | M13: 1853810 | N13: 1853810 | O13: 1853810 | P13: 1853986 | Q13: 1854009 | R13: 1854404 | S13: 1854726 | T13: 1854726 | U13: 1854794 | V13: 1854814 | W13: 1855010 | X13: 1855119 | Y13: 1855614 | Z13: 1856092 | AA13: 1856380 | AB13: 1856380 | AC13: 1856573 | AD13: 1857094 | AE13: 1857546 | AF13: 1858066
A14: M10 | B14: 1935240 | C14: 1935262 | D14: 1935457 | E14: 1935566 | F14: 1936002 | G14: 1936521 | H14: 1936953 | I14: 1937514 | J14: 1937989 | K14: 1938205 | L14: 1938356 | M14: 1938638 | N14: 1939113 | O14: 1939150 | P14: 1939674 | Q14: 1940192 | R14: 1940713 | S14: 1941106 | T14: 1941237 | U14: 1941237 | V14: 1941259 | W14: 1941434 | X14: 1941630 | Y14: 1941739 | Z14: 1942001 | AA14: 1942107 | AB14: 1942280 | AC14: 1942579 | AD14: 1943139 | AE14: 1943633 | AF14: 1943845
A15: M11 | B15: 1942359 | C15: 1942921 | D15: 1943482 | E15: 1943914 | F15: 1944435 | G15: 1944910 | H15: 1945347 | I15: 1945498 | J15: 1945519 | K15: 1946038 | L15: 1946556 | M15: 1947075 | N15: 1947507 | O15: 1947637 | P15: 1948112 | Q15: 1948603 | R15: 1948807 | S15: 1949326 | T15: 1949758 | U15: 1950277 | V15: 1950712 | W15: 1950972 | X15: 1951422 | Y15: 1951665 | Z15: 1952012 | AA15: 1952175 | AB15: 1952175 | AC15: 1952175 | AD15: 1952302 | AE15: 1952687 | AF15: 1952882
A16: M12 | B16: 1790013 | C16: 1790534 | D16: 1791008 | E16: 1791568 | F16: 1791655 | G16: 1791655 | H16: 1791655 | I16: 1791655 | J16: 1791676 | K16: 1791677 | L16: 1791677 | M16: 1791686 | N16: 1791686 | O16: 1791686 | P16: 1791877 | Q16: 1792306 | R16: 1792825 | S16: 1793342 | T16: 1793793 | U16: 1793793 | V16: 1793793 | W16: 1793916 | X16: 1794043 | Y16: 1794493 | Z16: 1794772 | AA16: 1795144 | AB16: 1795265 | AC16: 1795250 | AD16: 1795251 | AE16: 1795463 | AF16: 1795588
... A39: XM35 | B39: 554069 | C39: 554605 | D39: 554626 | E39: 554973 | F39: 555425 | G39: 555425 | H39: 555425 | I39: 555516 | J39: 555932 | K39: 556364 | L39: 556796 | M39: 557232 | N39: 557232 | O39: 557232 | P39: 557664 | Q39: 558013 | R39: 558119 | S39: 558120 | T39: 558503 | U39: 558503 | V39: 558503 | W39: 558765 | X39: 559180 | Y39: 559377 | Z39: 559378 | AA39: 559534 | AB39: 559534 | AC39: 559880 | AD39: 559969 | AE39: 560075 | AF39: 560409
A41: Kilometraje Diario Recorrido
B42: 45292 | C42: 45293 | D42: 45294 | E42: 45295 | F42: 45296 | G42: 45297 | H42: 45298 | I42: 45299 | J42: 45300 | K42: 45301 | L42: 45302 | M42: 45303 | N42: 45304 | O42: 45305 | P42: 45306 | Q42: 45307 | R42: 45308 | S42: 45309 | T42: 45310 | U42: 45311 | V42: 45312 | W42: 45313 | X42: 45314 | Y42: 45315 | Z42: 45316 | AA42: 45317 | AB42: 45318 | AC42: 45319 | AD42: 45320 | AE42: 45321 | AF42: 45322
B43: Kilometraje | C43: Kilometraje | D43: Kilometraje | E43: Kilometraje | F43: Kilometraje | G43: Kilometraje | H43: Kilometraje | I43: Kilometraje | J43: Kilometraje | K43: Kilometraje | L43: Kilometraje | M43: Kilometraje | N43: Kilometraje | O43: Kilometraje | P43: Kilometraje | Q43: Kilometraje | R43: Kilometraje | S43: Kilometraje | T43: Kilometraje | U43: Kilometraje | V43: Kilometraje | W43: Kilometraje | X43: Kilometraje | Y43: Kilometraje | Z43: Kilometraje | AA43: Kilometraje | AB43: Kilometraje | AC43: Kilometraje | AD43: Kilometraje | AE43: Kilometraje | AF43: Kilometraje
A44: Tren | B44: Diario | C44: Diario | D44: Diario | E44: Diario | F44: Diario | G44: Diario | H44: Diario | I44: Diario | J44: Diario | K44: Diario | L44: Diario | M44: Diario | N44: Diario | O44: Diario | P44: Diario | Q44: Diario | R44: Diario | S44: Diario | T44: Diario | U44: Diario | V44: Diario | W44: Diario | X44: Diario | Y44: Diario | Z44: Diario | AA44: Diario | AB44: Diario | AC44: Diario | AD44: Diario | AE44: Diario | AF44: Diario
A45: M01 | B45: 0 | C45: =C5-B5 -> 280 | D45: =D5-C5 -> 455 | E45: =E5-D5 -> 108 | F45: =F5-E5 -> 193 | G45: =G5-F5 -> 0 | H45: =H5-G5 -> 0 | I45: =I5-H5 -> 536 | J45: =J5-I5 -> 475 | ... AF45: =AF5-AE5 -> 402
A46: M02 | B46: 0 | C46: =C6-B6 -> 194 | D46: =D6-C6 -> 519 | E46: =E6-D6 -> 454 | F46: =F6-E6 -> 20 | G46: =G6-F6 -> 0 | H46: =H6-G6 -> 45 | I46: =I6-H6 -> 260 | J46: =J6-I6 -> 454 | ... AF46: =AF6-AE6 -> 518
A47: M03 | B47: 0 | C47: =C7-B7 -> 348 | D47: =D7-C7 -> 107 | E47: =E7-D7 -> 350 | F47: =F7-E7 -> 243 | G47: =G7-F7 -> 0 | H47: =H7-G7 -> 0 | I47: =I7-H7 -> 0 | J47: =J7-I7 -> 0 | ... AF47: =AF7-AE7 -> 398
A48: M04 | B48: 462 | C48: =C8-B8 -> 321 | D48: =D8-C8 -> 195 | E48: =E8-D8 -> 518 | F48: =F8-E8 -> 84 | G48: =G8-F8 -> 54 | H48: =H8-G8 -> 175 | I48: =I8-H8 -> 450 | J48: =J8-I8 -> 124 | ... AF48: =AF8-AE8 -> 318
A49: M05 | B49: 365 | C49: =C9-B9 -> 470 | D49: =D9-C9 -> 126 | E49: =E9-D9 -> 0 | F49: =F9-E9 -> 107 | G49: =G9-F9 -> 0 | H49: =H9-G9 -> 0 | I49: =I9-H9 -> 368 | J49: =J9-I9 -> 437 | ... AF49: =AF9-AE9 -> 451
A50: M06 | B50: 1 | C50: =C10-B10 -> 480 | D50: =D10-C10 -> 220 | E50: =E10-D10 -> 283 | F50: =F10-E10 -> 386 | G50: =G10-F10 -> 0 | H50: =H10-G10 -> 0 | I50: =I10-H10 -> 456 | J50: =J10-I10 -> 353 | ... AF50: =AF10-AE10 -> 321
A51: M07 | B51: 90 | C51: =C11-B11 -> 438 | D51: =D11-C11 -> 349 | E51: =E11-D11 -> 196 | F51: =F11-E11 -> 368 | G51: =G11-F11 -> 175 | H51: =H11-G11 -> 2 | I51: =I11-H11 -> 222 | J51: =J11-I11 -> 476 | ... AF51: =AF11-AE11 -> 349
A52: M08 | B52: 0 | C52: =C12-B12 -> 504 | D52: =D12-C12 -> 498 | E52: =E12-D12 -> 477 | F52: =F12-E12 -> 521 | G52: =G12-F12 -> 520 | H52: =H12-G12 -> 434 | I52: =I12-H12 -> 517 | J52: =J12-I12 -> 105 | ... AF52: =AF12-AE12 -> 582
A53: M09 | B53: 434 | C53: =C13-B13 -> 429 | D53: =D13-C13 -> 564 | E53: =E13-D13 -> 518 | F53: =F13-E13 -> 522 | G53: =G13-F13 -> 433 | H53: =H13-G13 -> 260 | I53: =I13-H13 -> 455 | J53: =J13-I13 -> 215 | ... AF53: =AF13-AE13 -> 520
A54: M10 | B54: 0 | C54: =C14-B14 -> 22 | D54: =D14-C14 -> 195 | E54: =E14-D14 -> 109 | F54: =F14-E14 -> 436 | G54: =G14-F14 -> 519 | H54: =H14-G14 -> 432 | I54: =I14-H14 -> 561 | J54: =J14-I14 -> 475 | ... AF54: =AF14-AE14 -> 212
A55: M11 | B55: 41 | C55: =C15-B15 -> 562 | D55: =D15-C15 -> 561 | E55: =E15-D15 -> 432 | F55: =F15-E15 -> 521 | G55: =G15-F15 -> 475 | H55: =H15-G15 -> 437 | I55: =I15-H15 -> 151 | J55: =J15-I15 -> 21 | ... AF55: =AF15-AE15 -> 195
A56: M12 | B56: 57 | C56: =C16-B16 -> 521 | D56: =D16-C16 -> 474 | E56: =E16-D16 -> 560 | F56: =F16-E16 -> 87 | G56: =G16-F16 -> 0 | H56: =H16-G16 -> 0 | I56: =I16-H16 -> 0 | J56: =J16-I16 -> 21 | ... AF56: =AF16-AE16 -> 125
... A79: XM35 | B79: 432 | C79: =C39-B39 -> 536 | D79: =D39-C39 -> 21 | E79: =E39-D39 -> 347 | F79: =F39-E39 -> 452 | G79: =G39-F39 -> 0 | H79: =H39-G39 -> 0 | I79: =I39-H39 -> 91 | J79: =J39-I39 -> 416 | ... AF79: =AF39-AE39 -> 334
A81: Kilometraje Diario | B81: =SUM(B45:B79) -> 5487 | C81: =SUM(C45:C79) -> 13622 | D81: =SUM(D45:D79) -> 12824 | E81: =SUM(E45:E79) -> 12902 | F81: =SUM(F45:F79) -> 12947 | G81: =SUM(G45:G79) -> 6373 | H81: =SUM(H45:H79) -> 4982 | I81: =SUM(I45:I79) -> 12276 | ... AF81: =SUM(AF45:AF79) -> 12043

Sheet KM-Servicio
G1: SA-MI | H1: 21.7 | I1: EB-PU | J1: 25.4 | K1: PU-SA | L1: 29.11 | M1: QU-LI / LI-QU | N1: 21.7 | O1: VM-PU | P1: 8.3 | Q1: VM-LI | R1: 34.83
B2: CANTIDAD DE SERVICIOS | D2: CANTIDAD DE SERVICIOS | G2: PU-PE | H2: 30.4 | I2: PO-SA | J2: 25.4 | K2: PU-LI | L2: 43.13 | M2: MI-LI / LI-MI | N2: 35.73 | O2: HO-LI/LI-HO | P2: 33.97 | Q2: PU-MI | R2: 7.4
B3: PROGRAMADOS | D3: REALIZADOS | F3: Origen-Destino | G3: Total Trenes | H3: Total Servicios | I3: Kms.xTrenes | J3: Kmsxservicios. | K3: Asientos x Kms. | L3: Disp x Km. | M3: Total Odómetro | N3: % Uso Trenes | P3: Cortes | S3: Acoples | V3: KmTren R
B4: Simples | C4: Dobles | D4: Simples | E4: Dobles | P4: EB | Q4: SA | R4: PE | S4: EB | T4: SA | U4: PE
A5: 45292 | B5: 51 | C5: 3 | D5: ='Data Ocupacion'!D33 -> 51 | E5: 3 | F5: PU-LI | G5: =D5+E5*2 -> 57 | H5: =D5+E5 -> 54 | I5: =G5*L$2 -> 2458.41 | J5: =H5*L$2 -> 2329.02 | K5: =I5*104 -> 255674.64 | L5: =H5*104 -> 5616 | V5: =I5-(P5*($L$2-$J$1)+(Q5*($L$2-$L$1))+ (R5*($L$2-$H$2))) -> 2458.41
B6: 0 | C6: 1 | D6: 0 | E6: 1 | F6: MI-LI | G6: =D6+E6*2 -> 2 | H6: =D6+E6 -> 1 | I6: =G6*N$2 -> 71.46 | J6: =H6*N$2 -> 35.73 | K6: =I6*104 -> 7431.84 | L6: =H6*104 -> 104 | V6: =I6-(P6*($L$2-$J$1)+(Q6*($L$2-$L$1))+ (R6*($L$2-$H$2))) -> 71.46
A7: TREN ESPECIAL DOBLE (MI-LI) AÑO NUEVO MADRUGADA | B7: 55 | C7: 2 | D7: ='Data Ocupacion'!D34 -> 55 | E7: ='Data Ocupacion'!E34 -> 2 | F7: LI-PU | G7: =D7+E7*2 -> 59 | H7: =D7+E7 -> 57 | I7: =G7*L$2 -> 2544.67 | J7: =H7*L$2 -> 2458.41 | K7: =I7*104 -> 264645.68 | L7: =H7*104 -> 5928 | V7: =I7-(S7*($L$2-$J$1)+(T7*($L$2-$L$1))) -> 2544.67
B8: 0 | C8: 0 | D8: ='Data Ocupacion'!D35 -> 0 | E8: ='Data Ocupacion'!E35 -> 0 | F8: PU-SA | G8: =D8+E8*2 -> 0 | H8: =D8+E8 -> 0 | I8: =G8*L$1 -> 0 | J8: =H8*L$1 -> 0 | K8: =I8*104 -> 0 | L8: =H8*104 -> 0 | V8: =I8-(P8*($L$1-$J$1)) -> 0
B9: 0 | C9: 0 | D9: ='Data Ocupacion'!D36 -> 0 | E9: ='Data Ocupacion'!E36 -> 0 | F9: SA-PU | G9: =D9+E9*2 -> 0 | H9: =D9+E9 -> 0 | I9: =G9*L$1 -> 0 | J9: =H9*L$1 -> 0 | K9: =I9*104 -> 0 | L9: =H9*104 -> 0 | V9: =I9 -> 0
B10: 0 | C10: 0 | D10: ='Data Ocupacion'!D37 -> 0 | E10: ='Data Ocupacion'!E37 -> 0 | F10: PU-EB | G10: =D10+E10*2 -> 0 | H10: =D10+E10 -> 0 | I10: =G10*J$1 -> 0 | J10: =H10*J$1 -> 0 | K10: =I10*104 -> 0 | L10: =H10*104 -> 0 | V10: =I10 -> 0
B11: 0 | C11: 0 | D11: ='Data Ocupacion'!D38 -> 0 | E11: ='Data Ocupacion'!E38 -> 0 | F11: EB-PU | G11: =D11+E11*2 -> 0 | H11: =D11+E11 -> 0 | I11: =G11*J$1 -> 0 | J11: =H11*J$1 -> 0 | K11: =I11*104 -> 0 | L11: =H11*104 -> 0 | V11: =I11 -> 0
B12: =SUM(B5:B11) -> 106 | C12: =SUM(C5:C11) -> 6 | D12: =SUM(D5:D11) -> 106 | E12: =SUM(E5:E11) -> 6 | G12: =SUM(G5:G11) -> 118 | H12: =SUM(H5:H11) -> 112 | I12: =SUM(I5:I11) -> 5074.54 | J12: =SUM(J5:J11) -> 4823.16 | K12: =SUM(K5:K11) -> 527752.16 | L12: =SUM(L5:L11) -> 11648 | M12: ='Odometro-Kilometraje'!B81 -> 5487 | N12: =(V12/M12)*100 -> 92.48296 | V12: =SUM(V5:V11) -> 5074.54
A13: =A5+1 -> 45293 | B13: 12 | C13: 70 | D13: ='Data Ocupacion'!F33 -> 12 | E13: ='Data Ocupacion'!G33 -> 70 | F13: PU-LI | G13: =D13+E13*2 -> 152 | H13: =D13+E13 -> 82 | I13: =G13*L$2 -> 6555.76 | J13: =H13*L$2 -> 3536.66 | K13: =I13*104 -> 681799.04 | L13: =H13*104 -> 8528 | V13: =I13-(P13*($L$2-$J$1)+(Q13*($L$2-$L$1))+ (R13*($L$2-$H$2))+ (S13*($L$2-$J$1))) -> 6555.76
B14: 13 | C14: 68 | D14: ='Data Ocupacion'!F34 -> 12 | E14: ='Data Ocupacion'!G34 -> 69 | F14: LI-PU | G14: =D14+E14*2 -> 150 | H14: =D14+E14 -> 81 | I14: =G14*L$2 -> 6469.5 | J14: =H14*L$2 -> 3493.53 | K14: =I14*104 -> 672828 | L14: =H14*104 -> 8424 | S14: 1 | V14: =I14-(S14*($L$2-$J$1)+(T14*($L$2-$L$1))) -> 6451.77
B15: 0 | C15: 0 | D15: ='Data Ocupacion'!F35 -> 0 | E15: ='Data Ocupacion'!G35 -> 0 | F15: PU-SA | G15: =D15+E15*2 -> 0 | H15: =D15+E15 -> 0 | I15: =G15*L$1 -> 0 | J15: =H15*L$1 -> 0 | K15: =I15*104 -> 0 | L15: =H15*104 -> 0 | V15: =I15-(P15*($L$1-$J$1)) -> 0
B16: 0 | C16: 0 | D16: ='Data Ocupacion'!F36 -> 0 | E16: ='Data Ocupacion'!G36 -> 0 | F16: SA-PU | G16: =D16+E16*2 -> 0 | H16: =D16+E16 -> 0 | I16: =G16*L$1 -> 0 | J16: =H16*L$1 -> 0 | K16: =I16*104 -> 0 | L16: =H16*104 -> 0 | V16: =I16 -> 0
B17: 0 | C17: 0 | D17: ='Data Ocupacion'!F37 -> 0 | E17: ='Data Ocupacion'!G37 -> 0 | F17: PU-EB | G17: =D17+E17*2 -> 0 | H17: =D17+E17 -> 0 | I17: =G17*J$1 -> 0 | J17: =H17*J$1 -> 0 | K17: =I17*104 -> 0 | L17: =H17*104 -> 0 | V17: =I17 -> 0
B18: 0 | C18: 1 | D18: ='Data Ocupacion'!F38 -> 0 | E18: ='Data Ocupacion'!G38 -> 1 | F18: EB-PU | G18: =D18+E18*2 -> 2 | H18: =D18+E18 -> 1 | I18: =G18*J$1 -> 50.8 | J18: =H18*J$1 -> 25.4 | K18: =I18*104 -> 5283.2 | L18: =H18*104 -> 104 | V18: =I18 -> 50.8
B19: =SUM(B13:B18) -> 25 | C19: =SUM(C13:C18) -> 139 | D19: =SUM(D13:D18) -> 24 | E19: =SUM(E13:E18) -> 140 | G19: =SUM(G13:G18) -> 304 | H19: =SUM(H13:H18) -> 164 | I19: =SUM(I13:I18) -> 13076.06 | J19: =SUM(J13:J18) -> 7055.59 | K19: =SUM(K13:K18) -> 1359910.2 | L19: =SUM(L13:L18) -> 17056 | M19: ='Odometro-Kilometraje'!C81 -> 13622 | N19: =(V19/M19)*100 -> 95.862061 | V19: =SUM(V13:V18) -> 13058.33
A20: =A13+1 -> 45294 | B20: 21 | C20: 61 | D20: ='Data Ocupacion'!H33 -> 22 | E20: ='Data Ocupacion'!I33 -> 60 | F20: PU-LI | G20: =D20+E20*2 -> 142 | H20: =D20+E20 -> 82 | I20: =G20*L$2 -> 6124.46 | J20: =H20*L$2 -> 3536.66 | K20: =I20*104 -> 636943.84 | L20: =H20*104 -> 8528 | V20: =I20-(P20*($L$2-$J$1)+(Q20*($L$2-$L$1))+ (R20*($L$2-$H$2))) -> 6124.46
A21: Cambio distribucion simple por doble 10:30 a 11:30 | B21: 22 | C21: 59 | D21: ='Data Ocupacion'!H34 -> 21 | E21: ='Data Ocupacion'!I34 -> 60 | F21: LI-PU | G21: =D21+E21*2 -> 141 | H21: =D21+E21 -> 81 | I21: =G21*L$2 -> 6081.33 | J21: =H21*L$2 -> 3493.53 | K21: =I21*104 -> 632458.32 | L21: =H21*104 -> 8424 | S21: 6 | V21: =I21-(S21*($L$2-$J$1)+(T21*($L$2-$L$1))) -> 5974.95
B22: 0 | C22: 0 | D22: ='Data Ocupacion'!H35 -> 0 | E22: ='Data Ocupacion'!I35 -> 0 | F22: PU-SA | G22: =D22+E22*2 -> 0 | H22: =D22+E22 -> 0 | I22: =G22*L$1 -> 0 | J22: =H22*L$1 -> 0 | K22: =I22*104 -> 0 | L22: =H22*104 -> 0 | V22: =I22-(P22*($L$1-$J$1)) -> 0
B23: 0 | C23: 0 | D23: ='Data Ocupacion'!H36 -> 0 | E23: ='Data Ocupacion'!I36 -> 0 | F23: SA-PU | G23: =D23+E23*2 -> 0 | H23: =D23+E23 -> 0 | I23: =G23*L$1 -> 0 | J23: =H23*L$1 -> 0 | K23: =I23*104 -> 0 | L23: =H23*104 -> 0 | V23: =I23 -> 0
B24: 0 | C24: 0 | D24: ='Data Ocupacion'!H37 -> 0 | E24: ='Data Ocupacion'!I37 -> 0 | F24: PU-EB | G24: =D24+E24*2 -> 0 | H24: =D24+E24 -> 0 | I24: =G24*J$1 -> 0 | J24: =H24*J$1 -> 0 | K24: =I24*104 -> 0 | L24: =H24*104 -> 0 | V24: =I24 -> 0
B25: 0 | C25: 1 | D25: ='Data Ocupacion'!H38 -> 0 | E25: ='Data Ocupacion'!I38 -> 1 | F25: EB-PU | G25: =D25+E25*2 -> 2 | H25: =D25+E25 -> 1 | I25: =G25*J$1 -> 50.8 | J25: =H25*J$1 -> 25.4 | K25: =I25*104 -> 5283.2 | L25: =H25*104 -> 104 | V25: =I25 -> 50.8
B26: =SUM(B20:B25) -> 43 | C26: =SUM(C20:C25) -> 121 | D26: =SUM(D20:D25) -> 43 | E26: =SUM(E20:E25) -> 121 | G26: =SUM(G20:G25) -> 285 | H26: =SUM(H20:H25) -> 164 | I26: =SUM(I20:I25) -> 12256.59 | J26: =SUM(J20:J25) -> 7055.59 | K26: =SUM(K20:K25) -> 1274685.4 | L26: =SUM(L20:L25) -> 17056 | M26: ='Odometro-Kilometraje'!D81 -> 12824 | N26: =(V26/M26)*100 -> 94.745867 | V26: =SUM(V20:V25) -> 12150.21
A27: =A20+1 -> 45295 | B27: 21 | C27: 61 | D27: ='Data Ocupacion'!J33 -> 18 | E27: ='Data Ocupacion'!K33 -> 64 | F27: PU-LI | G27: =D27+E27*2 -> 146 | H27: =D27+E27 -> 82 | I27: =G27*L$2 -> 6296.98 | J27: =H27*L$2 -> 3536.66 | K27: =I27*104 -> 654885.92 | L27: =H27*104 -> 8528 | V27: =I27-(P27*($L$2-$J$1)+(Q27*($L$2-$L$1))+ (R27*($L$2-$H$2))) -> 6296.98
B28: 22 | C28: 59 | D28: ='Data Ocupacion'!J34 -> 18 | E28: ='Data Ocupacion'!K34 -> 63 | F28: LI-PU | G28: =D28+E28*2 -> 144 | H28: =D28+E28 -> 81 | I28: =G28*L$2 -> 6210.72 | J28: =H28*L$2 -> 3493.53 | K28: =I28*104 -> 645914.88 | L28: =H28*104 -> 8424 | S28: 12 | V28: =I28-(S28*($L$2-$J$1)+(T28*($L$2-$L$1))+(U28*($L$2-$H$2))) -> 5997.96
B29: 0 | C29: 0 | D29: ='Data Ocupacion'!J35 -> 0 | E29: ='Data Ocupacion'!K35 -> 0 | F29: PU-SA | G29: =D29+E29*2 -> 0 | H29: =D29+E29 -> 0 | I29: =G29*L$1 -> 0 | J29: =H29*L$1 -> 0 | K29: =I29*104 -> 0 | L29: =H29*104 -> 0 | V29: =I29-(P29*($L$1-$J$1)) -> 0
B30: 0 | C30: 0 | D30: ='Data Ocupacion'!J36 -> 0 | E30: ='Data Ocupacion'!K36 -> 0 | F30: SA-PU | G30: =D30+E30*2 -> 0 | H30: =D30+E30 -> 0 | I30: =G30*L$1 -> 0 | J30: =H30*L$1 -> 0 | K30: =I30*104 -> 0 | L30: =H30*104 -> 0 | V30: =I30 -> 0
B31: 0 | C31: 0 | D31: ='Data Ocupacion'!J37 -> 0 | E31: ='Data Ocupacion'!K37 -> 0 | F31: PU-EB | G31: =D31+E31*2 -> 0 | H31: =D31+E31 -> 0 | I31: =G31*J$1 -> 0 | J31: =H31*J$1 -> 0 | K31: =I31*104 -> 0 | L31: =H31*104 -> 0 | V31: =I31 -> 0
B32: 0 | C32: 1 | D32: ='Data Ocupacion'!J38 -> 0 | E32: ='Data Ocupacion'!K38 -> 1 | F32: EB-PU | G32: =D32+E32*2 -> 2 | H32: =D32+E32 -> 1 | I32: =G32*J$1 -> 50.8 | J32: =H32*J$1 -> 25.4 | K32: =I32*104 -> 5283.2 | L32: =H32*104 -> 104 | V32: =I32 -> 50.8
B33: =SUM(B27:B32) -> 43 | C33: =SUM(C27:C32) -> 121 | D33: =SUM(D27:D32) -> 36 | E33: =SUM(E27:E32) -> 128 | G33: =SUM(G27:G32) -> 292 | H33: =SUM(H27:H32) -> 164 | I33: =SUM(I27:I32) -> 12558.5 | J33: =SUM(J27:J32) -> 7055.59 | K33: =SUM(K27:K32) -> 1306084 | L33: =SUM(L27:L32) -> 17056 | M33: ='Odometro-Kilometraje'!E81 -> 12902 | N33: =(V33/M33)*100 -> 95.688575 | V33: =SUM(V27:V32) -> 12345.74
A34: =A27+1 -> 45296 | B34: 21 | C34: 61 | D34: ='Data Ocupacion'!L33 -> 18 | E34: ='Data Ocupacion'!M33 -> 64 | F34: PU-LI | G34: =D34+E34*2 -> 146 | H34: =D34+E34 -> 82 | I34: =G34*L$2 -> 6296.98 | J34: =H34*L$2 -> 3536.66 | K34: =I34*104 -> 654885.92 | L34: =H34*104 -> 8528 | V34: =I34-(P34*($L$2-$J$1)+(Q34*($L$2-$L$1))+ (R34*($L$2-$H$2))) -> 6296.98
B35: 22 | C35: 59 | D35: ='Data Ocupacion'!L34 -> 18 | E35: ='Data Ocupacion'!M34 -> 63 | F35: LI-PU | G35: =D35+E35*2 -> 144 | H35: =D35+E35 -> 81 | I35: =G35*L$2 -> 6210.72 | J35: =H35*L$2 -> 3493.53 | K35: =I35*104 -> 645914.88 | L35: =H35*104 -> 8424 | S35: 5 | V35: =I35-(S35*($L$2-$J$1)+(T35*($L$2-$L$1))) -> 6122.07
B36: 0 | C36: 0 | D36: ='Data Ocupacion'!L35 -> 0 | E36: ='Data Ocupacion'!M35 -> 0 | F36: PU-SA | G36: =D36+E36*2 -> 0 | H36: =D36+E36 -> 0 | I36: =G36*L$1 -> 0 | J36: =H36*L$1 -> 0 | K36: =I36*104 -> 0 | L36: =H36*104 -> 0 | V36: =I36-(P36*($L$1-$J$1)) -> 0
B37: 0 | C37: 0 | D37: ='Data Ocupacion'!L36 -> 0 | E37: ='Data Ocupacion'!M36 -> 0 | F37: SA-PU | G37: =D37+E37*2 -> 0 | H37: =D37+E37 -> 0 | I37: =G37*L$1 -> 0 | J37: =H37*L$1 -> 0 | K37: =I37*104 -> 0 | L37: =H37*104 -> 0 | V37: =I37 -> 0
B38: 0 | C38: 0 | D38: ='Data Ocupacion'!L37 -> 0 | E38: ='Data Ocupacion'!M37 -> 0 | F38: PU-EB | G38: =D38+E38*2 -> 0 | H38: =D38+E38 -> 0 | I38: =G38*J$1 -> 0 | J38: =H38*J$1 -> 0 | K38: =I38*104 -> 0 | L38: =H38*104 -> 0 | V38: =I38 -> 0
B39: 0 | C39: 1 | D39: ='Data Ocupacion'!L38 -> 0 | E39: ='Data Ocupacion'!M38 -> 1 | F39: EB-PU | G39: =D39+E39*2 -> 2 | H39: =D39+E39 -> 1 | I39: =G39*J$1 -> 50.8 | J39: =H39*J$1 -> 25.4 | K39: =I39*104 -> 5283.2 | L39: =H39*104 -> 104 | V39: =I39 -> 50.8
B40: =SUM(B34:B39) -> 43 | C40: =SUM(C34:C39) -> 121 | D40: =SUM(D34:D39) -> 36 | E40: =SUM(E34:E39) -> 128 | G40: =SUM(G34:G39) -> 292 | H40: =SUM(H34:H39) -> 164 | I40: =SUM(I34:I39) -> 12558.5 | J40: =SUM(J34:J39) -> 7055.59 | K40: =SUM(K34:K39) -> 1306084 | L40: =SUM(L34:L39) -> 17056 | M40: ='Odometro-Kilometraje'!F81 -> 12947 | N40: =(V40/M40)*100 -> 96.31459 | V40: =SUM(V34:V39) -> 12469.85
...

Sheet Oferta Diaria
A1: Oferta Enero 2024
C3: 45292 | D3: 45293 | E3: 45294 | F3: 45295 | G3: 45296 | H3: 45297 | I3: 45298 | J3: 45299 | K3: 45300 | L3: 45301 | M3: 45302 | N3: 45303 | O3: 45304 | P3: 45305 | Q3: 45306 | R3: 45307 | S3: 45308 | T3: 45309 | U3: 45310 | V3: 45311 | W3: 45312 | X3: 45313 | Y3: 45314 | Z3: 45315 | AA3: 45316 | AB3: 45317 | AC3: 45318 | AD3: 45319 | AE3: 45320 | AF3: 45321 | AG3: 45322
A4: HÁBIL | B4: km
A5: Servicios PU-LI | B5: 43.13 | C5: ='Data Ocupacion'!D44 -> 54 | D5: ='Data Ocupacion'!F44 -> 82 | E5: ='Data Ocupacion'!H44 -> 82 | F5: ='Data Ocupacion'!J44 -> 82 | G5: ='Data Ocupacion'!L44 -> 82 | H5: ='Data Ocupacion'!N44 -> 70 | I5: ='Data Ocupacion'!P44 -> 54 | J5: ='Data Ocupacion'!R44 -> 81 | K5: ='Data Ocupacion'!T44 -> 82 | L5: ='Data Ocupacion'!V44 -> 82 | M5: ='Data Ocupacion'!X44 -> 82 | N5: ='Data Ocupacion'!Z44 -> 82 | O5: ='Data Ocupacion'!AB44 -> 70 | P5: ='Data Ocupacion'!AD44 -> 54 | Q5: ='Data Ocupacion'!AF44 -> 82 | R5: ='Data Ocupacion'!AH44 -> 82 | S5: ='Data Ocupacion'!AJ44 -> 82 | T5: ='Data Ocupacion'!AL44 -> 82 | U5: ='Data Ocupacion'!AN44 -> 82 | V5: ='Data Ocupacion'!AP44 -> 71 | W5: ='Data Ocupacion'!AR44 -> 54 | X5: ='Data Ocupacion'!AT44 -> 82 | Y5: ='Data Ocupacion'!AV44 -> 82 | Z5: ='Data Ocupacion'!AX44 -> 82 | AA5: ='Data Ocupacion'!AZ44 -> 82 | AB5: ='Data Ocupacion'!BB44 -> 44 | AC5: ='Data Ocupacion'!BD44 -> 32 | AD5: ='Data Ocupacion'!BF44 -> 28 | AE5: ='Data Ocupacion'!BH44 -> 82 | AF5: ='Data Ocupacion'!BJ44 -> 82 | AG5: ='Data Ocupacion'!BL44 -> 95
A6: Servicios LI-PU | B6: 43.13 | C6: ='Data Ocupacion'!D45 -> 57 | D6: ='Data Ocupacion'!F45 -> 81 | E6: ='Data Ocupacion'!H45 -> 81 | F6: ='Data Ocupacion'!J45 -> 81 | G6: ='Data Ocupacion'!L45 -> 81 | H6: ='Data Ocupacion'!N45 -> 73 | I6: ='Data Ocupacion'!P45 -> 57 | J6: ='Data Ocupacion'!R45 -> 81 | K6: ='Data Ocupacion'!T45 -> 81 | L6: ='Data Ocupacion'!V45 -> 81 | M6: ='Data Ocupacion'!X45 -> 81 | N6: ='Data Ocupacion'!Z45 -> 81 | O6: ='Data Ocupacion'!AB45 -> 73 | P6: ='Data Ocupacion'!AD45 -> 57 | Q6: ='Data Ocupacion'!AF45 -> 81 | R6: ='Data Ocupacion'!AH45 -> 81 | S6: ='Data Ocupacion'!AJ45 -> 81 | T6: ='Data Ocupacion'!AL45 -> 81 | U6: ='Data Ocupacion'!AN45 -> 81 | V6: ='Data Ocupacion'!AP45 -> 74 | W6: ='Data Ocupacion'!AR45 -> 57 | X6: ='Data Ocupacion'!AT45 -> 81 | Y6: ='Data Ocupacion'!AV45 -> 81 | Z6: ='Data Ocupacion'!AX45 -> 81 | AA6: ='Data Ocupacion'!AZ45 -> 81 | AB6: ='Data Ocupacion'!BB45 -> 41 | AC6: ='Data Ocupacion'!BD45 -> 33 | AD6: ='Data Ocupacion'!BF45 -> 29 | AE6: ='Data Ocupacion'!BH45 -> 81 | AF6: ='Data Ocupacion'!BJ45 -> 81 | AG6: ='Data Ocupacion'!BL45 -> 95
A7: Servicios PU-SA | B7: 29.11 | C7: ='Data Ocupacion'!D46 -> 0 | D7: ='Data Ocupacion'!F46 -> 0 | E7: ='Data Ocupacion'!H46 -> 0 | F7: ='Data Ocupacion'!J46 -> 0 | G7: ='Data Ocupacion'!L46 -> 0 | H7: ='Data Ocupacion'!N46 -> 0 | I7: ='Data Ocupacion'!P46 -> 0 | J7: ='Data Ocupacion'!R46 -> 0 | K7: ='Data Ocupacion'!T46 -> 0 | L7: ='Data Ocupacion'!V46 -> 0 | M7: ='Data Ocupacion'!X46 -> 0 | N7: ='Data Ocupacion'!Z46 -> 0 | O7: ='Data Ocupacion'!AB46 -> 0 | P7: ='Data Ocupacion'!AD46 -> 0 | Q7: ='Data Ocupacion'!AF46 -> 0 | R7: ='Data Ocupacion'!AH46 -> 0 | S7: ='Data Ocupacion'!AJ46 -> 0 | T7: ='Data Ocupacion'!AL46 -> 0 | U7: ='Data Ocupacion'!AN46 -> 0 | V7: ='Data Ocupacion'!AP46 -> 0 | W7: ='Data Ocupacion'!AR46 -> 0 | X7: ='Data Ocupacion'!AT46 -> 0 | Y7: ='Data Ocupacion'!AV46 -> 0 | Z7: ='Data Ocupacion'!AX46 -> 0 | AA7: ='Data Ocupacion'!AZ46 -> 0 | AB7: ='Data Ocupacion'!BB46 -> 0 | AC7: ='Data Ocupacion'!BD46 -> 0 | AD7: ='Data Ocupacion'!BF46 -> 0 | AE7: ='Data Ocupacion'!BH46 -> 0 | AF7: ='Data Ocupacion'!BJ46 -> 0 | AG7: ='Data Ocupacion'!BL46 -> 0
A8: Servicios SA-PU | B8: 29.11 | C8: ='Data Ocupacion'!D47 -> 0 | D8: ='Data Ocupacion'!F47 -> 0 | E8: ='Data Ocupacion'!H47 -> 0 | F8: ='Data Ocupacion'!J47 -> 0 | G8: ='Data Ocupacion'!L47 -> 0 | H8: ='Data Ocupacion'!N47 -> 0 | I8: ='Data Ocupacion'!P47 -> 0 | J8: ='Data Ocupacion'!R47 -> 0 | K8: ='Data Ocupacion'!T47 -> 0 | L8: ='Data Ocupacion'!V47 -> 0 | M8: ='Data Ocupacion'!X47 -> 0 | N8: ='Data Ocupacion'!Z47 -> 0 | O8: ='Data Ocupacion'!AB47 -> 0 | P8: ='Data Ocupacion'!AD47 -> 0 | Q8: ='Data Ocupacion'!AF47 -> 0 | R8: ='Data Ocupacion'!AH47 -> 0 | S8: ='Data Ocupacion'!AJ47 -> 0 | T8: ='Data Ocupacion'!AL47 -> 0 | U8: ='Data Ocupacion'!AN47 -> 0 | V8: ='Data Ocupacion'!AP47 -> 0 | W8: ='Data Ocupacion'!AR47 -> 0 | X8: ='Data Ocupacion'!AT47 -> 0 | Y8: ='Data Ocupacion'!AV47 -> 0 | Z8: ='Data Ocupacion'!AX47 -> 0 | AA8: ='Data Ocupacion'!AZ47 -> 0 | AB8: ='Data Ocupacion'!BB47 -> 0 | AC8: ='Data Ocupacion'!BD47 -> 0 | AD8: ='Data Ocupacion'!BF47 -> 0 | AE8: ='Data Ocupacion'!BH47 -> 0 | AF8: ='Data Ocupacion'!BJ47 -> 0 | AG8: ='Data Ocupacion'!BL47 -> 0
A9: Servicios PU-EB | B9: 25.4 | C9: ='Data Ocupacion'!D48 -> 0 | D9: ='Data Ocupacion'!F48 -> 0 | E9: ='Data Ocupacion'!H48 -> 0 | F9: ='Data Ocupacion'!J48 -> 0 | G9: ='Data Ocupacion'!L48 -> 0 | H9: ='Data Ocupacion'!N48 -> 0 | I9: ='Data Ocupacion'!P48 -> 0 | J9: ='Data Ocupacion'!R48 -> 0 | K9: ='Data Ocupacion'!T48 -> 0 | L9: ='Data Ocupacion'!V48 -> 0 | M9: ='Data Ocupacion'!X48 -> 0 | N9: ='Data Ocupacion'!Z48 -> 0 | O9: ='Data Ocupacion'!AB48 -> 0 | P9: ='Data Ocupacion'!AD48 -> 0 | Q9: ='Data Ocupacion'!AF48 -> 0 | R9: ='Data Ocupacion'!AH48 -> 0 | S9: ='Data Ocupacion'!AJ48 -> 0 | T9: ='Data Ocupacion'!AL48 -> 0 | U9: ='Data Ocupacion'!AN48 -> 0 | V9: ='Data Ocupacion'!AP48 -> 0 | W9: ='Data Ocupacion'!AR48 -> 0 | X9: ='Data Ocupacion'!AT48 -> 0 | Y9: ='Data Ocupacion'!AV48 -> 0 | Z9: ='Data Ocupacion'!AX48 -> 0 | AA9: ='Data Ocupacion'!AZ48 -> 0 | AB9: ='Data Ocupacion'!BB48 -> 0 | AC9: ='Data Ocupacion'!BD48 -> 0 | AD9: ='Data Ocupacion'!BF48 -> 0 | AE9: ='Data Ocupacion'!BH48 -> 0 | AF9: ='Data Ocupacion'!BJ48 -> 0 | AG9: ='Data Ocupacion'!BL48 -> 0
A10: Servicios EB-PU | B10: 25.4 | C10: ='Data Ocupacion'!D49 -> 0 | D10: ='Data Ocupacion'!F49 -> 1 | E10: ='Data Ocupacion'!H49 -> 1 | F10: ='Data Ocupacion'!J49 -> 1 | G10: ='Data Ocupacion'!L49 -> 1 | H10: ='Data Ocupacion'!N49 -> 0 | I10: ='Data Ocupacion'!P49 -> 0 | J10: ='Data Ocupacion'!R49 -> 1 | K10: ='Data Ocupacion'!T49 -> 1 | L10: ='Data Ocupacion'!V49 -> 1 | M10: ='Data Ocupacion'!X49 -> 1 | N10: ='Data Ocupacion'!Z49 -> 1 | O10: ='Data Ocupacion'!AB49 -> 0 | P10: ='Data Ocupacion'!AD49 -> 0 | Q10: ='Data Ocupacion'!AF49 -> 2 | R10: ='Data Ocupacion'!AH49 -> 1 | S10: ='Data Ocupacion'!AJ49 -> 1 | T10: ='Data Ocupacion'!AL49 -> 1 | U10: ='Data Ocupacion'!AN49 -> 1 | V10: ='Data Ocupacion'!AP49 -> 0 | W10: ='Data Ocupacion'!AR49 -> 0 | X10: ='Data Ocupacion'!AT49 -> 1 | Y10: ='Data Ocupacion'!AV49 -> 1 | Z10: ='Data Ocupacion'!AX49 -> 1 | AA10: ='Data Ocupacion'!AZ49 -> 1 | AB10: ='Data Ocupacion'!BB49 -> 1 | AC10: ='Data Ocupacion'!BD49 -> 0 | AD10: ='Data Ocupacion'!BF49 -> 0 | AE10: ='Data Ocupacion'!BH49 -> 1 | AF10: ='Data Ocupacion'!BJ49 -> 1 | AG10: ='Data Ocupacion'!BL49 -> 1
A11: Servicios MI-LI | B11: 35.73 | C11: 1
A12: Servicios LI-MI | B12: 35.73
A14: Trenes PU-LI | B14: 43.13 | C14: ='Data Ocupacion'!D54 -> 57 | D14: ='Data Ocupacion'!F54 -> 152 | E14: ='Data Ocupacion'!H54 -> 142 | F14: ='Data Ocupacion'!J54 -> 146 | G14: ='Data Ocupacion'!L54 -> 146 | H14: ='Data Ocupacion'!N54 -> 73 | I14: ='Data Ocupacion'!P54 -> 57 | J14: ='Data Ocupacion'!R54 -> 142 | K14: ='Data Ocupacion'!T54 -> 136 | L14: ='Data Ocupacion'!V54 -> 136 | M14: ='Data Ocupacion'!X54 -> 136 | N14: ='Data Ocupacion'!Z54 -> 136 | O14: ='Data Ocupacion'!AB54 -> 74 | P14: ='Data Ocupacion'!AD54 -> 57 | Q14: ='Data Ocupacion'!AF54 -> 128 | R14: ='Data Ocupacion'!AH54 -> 126 | S14: ='Data Ocupacion'!AJ54 -> 127 | T14: ='Data Ocupacion'!AL54 -> 127 | U14: ='Data Ocupacion'!AN54 -> 128 | V14: ='Data Ocupacion'!AP54 -> 74 | W14: ='Data Ocupacion'!AR54 -> 57 | X14: ='Data Ocupacion'!AT54 -> 119 | Y14: ='Data Ocupacion'!AV54 -> 119 | Z14: ='Data Ocupacion'!AX54 -> 120 | AA14: ='Data Ocupacion'!AZ54 -> 119 | AB14: ='Data Ocupacion'!BB54 -> 83 | AC14: ='Data Ocupacion'!BD54 -> 64 | AD14: ='Data Ocupacion'!BF54 -> 56 | AE14: ='Data Ocupacion'!BH54 -> 119 | AF14: ='Data Ocupacion'!BJ54 -> 118 | AG14: ='Data Ocupacion'!BL54 -> 137
A15: Trenes LI-PU | B15: 43.13 | C15: ='Data Ocupacion'!D55 -> 59 | D15: ='Data Ocupacion'!F55 -> 150 | E15: ='Data Ocupacion'!H55 -> 141 | F15: ='Data Ocupacion'!J55 -> 144 | G15: ='Data Ocupacion'!L55 -> 144 | H15: ='Data Ocupacion'!N55 -> 73 | I15: ='Data Ocupacion'!P55 -> 57 | J15: ='Data Ocupacion'!R55 -> 136 | K15: ='Data Ocupacion'!T55 -> 133 | L15: ='Data Ocupacion'!V55 -> 133 | M15: ='Data Ocupacion'!X55 -> 134 | N15: ='Data Ocupacion'!Z55 -> 134 | O15: ='Data Ocupacion'!AB55 -> 74 | P15: ='Data Ocupacion'!AD55 -> 57 | Q15: ='Data Ocupacion'!AF55 -> 125 | R15: ='Data Ocupacion'!AH55 -> 124 | S15: ='Data Ocupacion'!AJ55 -> 125 | T15: ='Data Ocupacion'!AL55 -> 124 | U15: ='Data Ocupacion'!AN55 -> 124 | V15: ='Data Ocupacion'!AP55 -> 74 | W15: ='Data Ocupacion'!AR55 -> 57 | X15: ='Data Ocupacion'!AT55 -> 117 | Y15: ='Data Ocupacion'!AV55 -> 117 | Z15: ='Data Ocupacion'!AX55 -> 117 | AA15: ='Data Ocupacion'!AZ55 -> 117 | AB15: ='Data Ocupacion'!BB55 -> 80 | AC15: ='Data Ocupacion'!BD55 -> 64 | AD15: ='Data Ocupacion'!BF55 -> 58 | AE15: ='Data Ocupacion'!BH55 -> 116 | AF15: ='Data Ocupacion'!BJ55 -> 116 | AG15: ='Data Ocupacion'!BL55 -> 130
A16: Trenes PU-SA | B16: 29.11 | C16: ='Data Ocupacion'!D56 -> 0 | D16: ='Data Ocupacion'!F56 -> 0 | E16: ='Data Ocupacion'!H56 -> 0 | F16: ='Data Ocupacion'!J56 -> 0 | G16: ='Data Ocupacion'!L56 -> 0 | H16: ='Data Ocupacion'!N56 -> 0 | I16: ='Data Ocupacion'!P56 -> 0 | J16: ='Data Ocupacion'!R56 -> 0 | K16: ='Data Ocupacion'!T56 -> 0 | L16: ='Data Ocupacion'!V56 -> 0 | M16: ='Data Ocupacion'!X56 -> 0 | N16: ='Data Ocupacion'!Z56 -> 0 | O16: ='Data Ocupacion'!AB56 -> 0 | P16: ='Data Ocupacion'!AD56 -> 0 | Q16: ='Data Ocupacion'!AF56 -> 0 | R16: ='Data Ocupacion'!AH56 -> 0 | S16: ='Data Ocupacion'!AJ56 -> 0 | T16: ='Data Ocupacion'!AL56 -> 0 | U16: ='Data Ocupacion'!AN56 -> 0 | V16: ='Data Ocupacion'!AP56 -> 0 | W16: ='Data Ocupacion'!AR56 -> 0 | X16: ='Data Ocupacion'!AT56 -> 0 | Y16: ='Data Ocupacion'!AV56 -> 0 | Z16: ='Data Ocupacion'!AX56 -> 0 | AA16: ='Data Ocupacion'!AZ56 -> 0 | AB16: ='Data Ocupacion'!BB56 -> 0 | AC16: ='Data Ocupacion'!BD56 -> 0 | AD16: ='Data Ocupacion'!BF56 -> 0 | AE16: ='Data Ocupacion'!BH56 -> 0 | AF16: ='Data Ocupacion'!BJ56 -> 0 | AG16: ='Data Ocupacion'!BL56 -> 0
A17: Trenes SA-PU | B17: 29.11 | C17: ='Data Ocupacion'!D57 -> 0 | D17: ='Data Ocupacion'!F57 -> 0 | E17: ='Data Ocupacion'!H57 -> 0 | F17: ='Data Ocupacion'!J57 -> 0 | G17: ='Data Ocupacion'!L57 -> 0 | H17: ='Data Ocupacion'!N57 -> 0 | I17: ='Data Ocupacion'!P57 -> 0 | J17: ='Data Ocupacion'!R57 -> 0 | K17: ='Data Ocupacion'!T57 -> 0 | L17: ='Data Ocupacion'!V57 -> 0 | M17: ='Data Ocupacion'!X57 -> 0 | N17: ='Data Ocupacion'!Z57 -> 0 | O17: ='Data Ocupacion'!AB57 -> 0 | P17: ='Data Ocupacion'!AD57 -> 0 | Q17: ='Data Ocupacion'!AF57 -> 0 | R17: ='Data Ocupacion'!AH57 -> 0 | S17: ='Data Ocupacion'!AJ57 -> 0 | T17: ='Data Ocupacion'!AL57 -> 0 | U17: ='Data Ocupacion'!AN57 -> 0 | V17: ='Data Ocupacion'!AP57 -> 0 | W17: ='Data Ocupacion'!AR57 -> 0 | X17: ='Data Ocupacion'!AT57 -> 0 | Y17: ='Data Ocupacion'!AV57 -> 0 | Z17: ='Data Ocupacion'!AX57 -> 0 | AA17: ='Data Ocupacion'!AZ57 -> 0 | AB17: ='Data Ocupacion'!BB57 -> 0 | AC17: ='Data Ocupacion'!BD57 -> 0 | AD17: ='Data Ocupacion'!BF57 -> 0 | AE17: ='Data Ocupacion'!BH57 -> 0 | AF17: ='Data Ocupacion'!BJ57 -> 0 | AG17: ='Data Ocupacion'!BL57 -> 0
A18: Trenes EB-PU | B18: 25.4 | C18: ='Data Ocupacion'!D59 -> 0 | D18: ='Data Ocupacion'!F59 -> 2 | E18: ='Data Ocupacion'!H59 -> 2 | F18: ='Data Ocupacion'!J59 -> 2 | G18: ='Data Ocupacion'!L59 -> 2 | H18: ='Data Ocupacion'!N59 -> 0 | I18: ='Data Ocupacion'!P59 -> 0 | J18: ='Data Ocupacion'!R59 -> 2 | K18: ='Data Ocupacion'!T59 -> 2 | L18: ='Data Ocupacion'!V59 -> 2 | M18: ='Data Ocupacion'!X59 -> 2 | N18: ='Data Ocupacion'!Z59 -> 2 | O18: ='Data Ocupacion'!AB59 -> 0 | P18: ='Data Ocupacion'!AD59 -> 0 | Q18: ='Data Ocupacion'!AF59 -> 3 | R18: ='Data Ocupacion'!AH59 -> 2 | S18: ='Data Ocupacion'!AJ59 -> 2 | T18: ='Data Ocupacion'!AL59 -> 2 | U18: ='Data Ocupacion'!AN59 -> 2 | V18: ='Data Ocupacion'!AP59 -> 0 | W18: ='Data Ocupacion'!AR59 -> 0 | X18: ='Data Ocupacion'!AT59 -> 2 | Y18: ='Data Ocupacion'!AV59 -> 2 | Z18: ='Data Ocupacion'!AX59 -> 2 | AA18: ='Data Ocupacion'!AZ59 -> 2 | AB18: ='Data Ocupacion'!BB59 -> 2 | AC18: ='Data Ocupacion'!BD59 -> 0 | AD18: ='Data Ocupacion'!BF59 -> 0 | AE18: ='Data Ocupacion'!BH59 -> 2 | AF18: ='Data Ocupacion'!BJ59 -> 2 | AG18: ='Data Ocupacion'!BL59 -> 2
A19: Trenes PU-EB | B19: 25.4 | C19: 0 | D19: 0 | E19: 0 | F19: 0 | G19: 0 | H19: 0 | I19: 0 | J19: 0 | K19: 0 | L19: 0 | M19: 0 | N19: 0 | O19: 0 | P19: 0 | Q19: 0 | R19: 0 | S19: 0 | T19: 0 | U19: 0 | V19: 0 | W19: 0 | X19: 0 | Y19: 0 | Z19: 0 | AA19: 0 | AB19: 0 | AC19: 0 | AD19: 0 | AE19: 0 | AF19: 0 | AG19: 0
A20: Trenes MI-LI | B20: 35.73 | C20: 2
A21: Trenes LI-MI | B21: 35.73
A22: Corte EB (600) | B22: -17.73 | C22: ='KM-Servicio'!P5 -> 0 | D22: ='KM-Servicio'!P13 -> 0 | E22: ='KM-Servicio'!P20 -> 0 | F22: ='KM-Servicio'!P27 -> 0 | G22: ='KM-Servicio'!P34 -> 0 | H22: ='KM-Servicio'!P41 -> 0 | I22: ='KM-Servicio'!P48 -> 0 | J22: 0 | K22: ='KM-Servicio'!P62 -> 0 | L22: ='KM-Servicio'!P69 -> 0 | M22: ='KM-Servicio'!P76 -> 0 | N22: ='KM-Servicio'!P83 -> 0 | O22: ='KM-Servicio'!P90 -> 0 | P22: ='KM-Servicio'!P97 -> 0 | Q22: ='KM-Servicio'!P104 -> 4 | R22: ='KM-Servicio'!P111 -> 0 | S22: ='KM-Servicio'!P118 -> 0 | T22: ='KM-Servicio'!P125 -> 0 | U22: ='KM-Servicio'!P132 -> 0 | V22: ='KM-Servicio'!P139 -> 0 | W22: ='KM-Servicio'!P146 -> 0 | X22: ='KM-Servicio'!P153 -> 0 | Y22: ='KM-Servicio'!P160 -> 0 | Z22: ='KM-Servicio'!P167 -> 0 | AA22: ='KM-Servicio'!P174 -> 0 | AB22: ='KM-Servicio'!P181 -> 0 | AC22: ='KM-Servicio'!P188 -> 0 | AD22: ='KM-Servicio'!P195 -> 0 | AE22: ='KM-Servicio'!P202 -> 0 | AF22: ='KM-Servicio'!P209 -> 0 | AG22: ='KM-Servicio'!P217 -> 0
A23: Acople EB (600) | B23: -17.73 | C23: ='KM-Servicio'!S7 -> 0 | D23: ='KM-Servicio'!S14 -> 1 | E23: ='KM-Servicio'!S21 -> 6 | F23: ='KM-Servicio'!S28 -> 12 | G23: ='KM-Servicio'!S35 -> 5 | H23: ='KM-Servicio'!S42 -> 0 | I23: ='KM-Servicio'!S49 -> 0 | J23: ='KM-Servicio'!S56 -> 3 | K23: ='KM-Servicio'!S63 -> 6 | L23: ='KM-Servicio'!S70 -> 5 | M23: ='KM-Servicio'!S77 -> 4 | N23: ='KM-Servicio'!S84 -> 4 | O23: ='KM-Servicio'!S91 -> 0 | P23: ='KM-Servicio'!S98 -> 0 | Q23: ='KM-Servicio'!S105 -> 1 | R23: ='KM-Servicio'!S112 -> 1 | S23: ='KM-Servicio'!S119 -> 4 | T23: ='KM-Servicio'!S126 -> 3 | U23: ='KM-Servicio'!S133 -> 1 | V23: ='KM-Servicio'!S140 -> 0 | W23: ='KM-Servicio'!S147 -> 0 | X23: ='KM-Servicio'!S154 -> 1 | Y23: ='KM-Servicio'!S161 -> 1 | Z23: ='KM-Servicio'!S168 -> 1 | AA23: ='KM-Servicio'!S175 -> 1 | AB23: ='KM-Servicio'!S182 -> 1 | AC23: ='KM-Servicio'!S189 -> 0 | AD23: ='KM-Servicio'!S196 -> 0 | AE23: ='KM-Servicio'!S203 -> 2 | AF23: ='KM-Servicio'!S210 -> 1 | AG23: ='KM-Servicio'!S217 -> 0
A24: Acople/Corte SA (600) | B24: -14.02 | C24: ='KM-Servicio'!T7 -> 0 | D24: ='KM-Servicio'!T14 -> 0 | E24: ='KM-Servicio'!T21 -> 0 | F24: ='KM-Servicio'!T28 -> 0 | G24: ='KM-Servicio'!T35 -> 0 | H24: ='KM-Servicio'!T42 -> 0 | I24: ='KM-Servicio'!T49 -> 0 | J24: ='KM-Servicio'!T56 -> 0 | K24: ='KM-Servicio'!T63 -> 0 | L24: ='KM-Servicio'!T70 -> 0 | M24: ='KM-Servicio'!T77 -> 0 | N24: ='KM-Servicio'!T84 -> 0 | O24: ='KM-Servicio'!T91 -> 0 | P24: ='KM-Servicio'!T98 -> 0 | Q24: ='KM-Servicio'!T105 -> 0 | R24: ='KM-Servicio'!T112 -> 0 | S24: ='KM-Servicio'!T119 -> 0 | T24: ='KM-Servicio'!T126 -> 0 | U24: ='KM-Servicio'!T133 -> 0 | V24: ='KM-Servicio'!T140 -> 0 | W24: ='KM-Servicio'!T147 -> 0 | X24: ='KM-Servicio'!T154 -> 0 | Y24: ='KM-Servicio'!T161 -> 0 | Z24: ='KM-Servicio'!T168 -> 0 | AA24: ='KM-Servicio'!T175 -> 0 | AB24: ='KM-Servicio'!T182 -> 0 | AC24: ='KM-Servicio'!T189 -> 0 | AD24: ='KM-Servicio'!T196 -> 0 | AE24: ='KM-Servicio'!T203 -> 0 | AF24: ='KM-Servicio'!T210 -> 0 | AG24: ='KM-Servicio'!T217 -> 0
A25: Corte EB (400) | B25: -3.71 | E25: ='KM-Servicio'!P22 -> 0 | G25: ='KM-Servicio'!P36 -> 0 | N25: ='KM-Servicio'!P85 -> 0
A26: Acople EB (600) vía 1 | B26: -25.4 | J26: 4 | O26: ='KM-Servicio'!R90 -> 0 | U26: ='KM-Servicio'!S167 -> 1 | Z26: 1 | AG26: ='KM-Servicio'!S216 -> 5
A28: Servicios | B28: =SUM(C28:AG28) -> 4555 | C28: =SUM(C5:C11) -> 112 | D28: =SUM(D5:D10) -> 164 | E28: =SUM(E5:E10) -> 164 | F28: =SUM(F5:F10) -> 164 | G28: =SUM(G5:G10) -> 164 | H28: =SUM(H5:H10) -> 143 | I28: =SUM(I5:I10) -> 111 | J28: =SUM(J5:J10) -> 163 | K28: =SUM(K5:K12) -> 164 | L28: =SUM(L5:L10) -> 164 | M28: =SUM(M5:M10) -> 164 | N28: =SUM(N5:N10) -> 164 | O28: =SUM(O5:O10) -> 143 | P28: =SUM(P5:P10) -> 111 | Q28: =SUM(Q5:Q10) -> 165 | R28: =SUM(R5:R10) -> 164 | S28: =SUM(S5:S10) -> 164 | ... AG28: =SUM(AG5:AG10) -> 191
A29: Trenes | B29: =SUM(C29:AG29) -> 6812 | C29: =SUM(C14:C20) -> 118 | D29: =SUM(D14:D19) -> 304 | E29: =SUM(E14:E19) -> 285 | F29: =SUM(F14:F19) -> 292 | G29: =SUM(G14:G19) -> 292 | H29: =SUM(H14:H19) -> 146 | I29: =SUM(I14:I19) -> 114 | J29: =SUM(J14:J19) -> 280 | K29: =SUM(K14:K21) -> 271 | L29: =SUM(L14:L19) -> 271 | M29: =SUM(M14:M19) -> 272 | N29: =SUM(N14:N19) -> 272 | O29: =SUM(O14:O19) -> 148 | P29: =SUM(P14:P19) -> 114 | Q29: =SUM(Q14:Q19) -> 256 | R29: =SUM(R14:R19) -> 252 | S29: =SUM(S14:S19) -> 254 | ... AG29: =SUM(AG14:AG19) -> 269
A30: Trenes KM | B30: =SUM(C30:AG30) -> 291260.47 | C30: =(C14*$B$14+C15*$B$15+C16*$B$16+C17*$B$17+C19*$B$19+C23*$B$23+C18*$B$18+C22*$B$22+C24*B24+C20*B20) -> 5074.54 | D30: =(D14*$B$14+D15*$B$15+D16*$B$16+D17*$B$17+D19*$B$19+D23*$B$23+D18*$B$18+D22*$B$22+D24*B24) -> 13058.33 | E30: =(E14*$B$14+E15*$B$15+E16*$B$16+E17*$B$17+E19*$B$19+E23*$B$23+E18*$B$18+E22*$B$22+E24*B24+E25*B25) -> 12150.21 | F30: =(F14*$B$14+F15*$B$15+F16*$B$16+F17*$B$17+F19*$B$19+F23*$B$23+F18*$B$18+F22*$B$22+F26*B26) -> 12345.74 | G30: =(G14*$B$14+G15*$B$15+G16*$B$16+G17*$B$17+G19*$B$19+G23*$B$23+G18*$B$18+G22*$B$22+G24*B24+G25*B25) -> 12469.85 | H30: =(H14*$B$14+H15*$B$15+H16*$B$16+H17*$B$17+H19*$B$19+H23*$B$23+H18*$B$18+H22*$B$22) -> 6296.98 | I30: =(I14*$B$14+I15*$B$15+I16*$B$16+I17*$B$17+I19*$B$19+I23*$B$23+I18*$B$18+I22*$B$22) -> 4916.82 | J30: =(J14*$B$14+J15*$B$15+J16*$B$16+J17*$B$17+J19*$B$19+J23*$B$23+J18*$B$18+J22*$B$22+J26*B26) -> 11886.15 | K30: =(K14*$B$14+K15*$B$15+K16*$B$16+K17*$B$17+K19*$B$19+K23*$B$23+K18*$B$18+K22*$B$22+K24*B24+K20*B20+K21*B21) -> 11546.39 | L30: =(L14*$B$14+L15*$B$15+L16*$B$16+L17*$B$17+L19*$B$19+L23*$B$23+L18*$B$18+L22*$B$22+L24*B24) -> 11564.12 | M30: =(M14*$B$14+M15*$B$15+M16*$B$16+M17*$B$17+M19*$B$19+M23*$B$23+M18*$B$18+M22*$B$22) -> 11624.98 | N30: =(N14*$B$14+N15*$B$15+N16*$B$16+N17*$B$17+N19*$B$19+N23*$B$23+N18*$B$18+N22*$B$22+N24*B24+N25*B25) -> 11624.98 | O30: =(O14*$B$14+O15*$B$15+O16*$B$16+O17*$B$17+O19*$B$19+O23*$B$23+O18*$B$18+O22*$B$22+O26*B26) -> 6383.24 | P30: =(P14*$B$14+P15*$B$15+P16*$B$16+P17*$B$17+P19*$B$19+P23*$B$23+P18*$B$18+P22*$B$22+P24*B24) -> 4916.82 | Q30: =(Q14*$B$14+Q15*$B$15+Q16*$B$16+Q17*$B$17+Q19*$B$19+Q23*$B$23+Q18*$B$18+Q22*$B$22+Q24*B24) -> 10899.44 | R30: =(R14*$B$14+R15*$B$15+R16*$B$16+R17*$B$17+R19*$B$19+R23*$B$23+R18*$B$18+R22*$B$22) -> 10815.57 | S30: =(S14*$B$14+S15*$B$15+S16*$B$16+S17*$B$17+S19*$B$19+S23*$B$23+S18*$B$18+S22*$B$22) -> 10848.64 | T30: =(T14*$B$14+T15*$B$15+T16*$B$16+T17*$B$17+T19*$B$19+T23*$B$23+T18*$B$18+T22*$B$22+T24*B24) -> 10823.24 | U30: =(U14*$B$14+U15*$B$15+U16*$B$16+U17*$B$17+U19*$B$19+U23*$B$23+U18*$B$18+U22*$B$22+U24*B24+U26*B26) -> 10876.43 | V30: =(V14*$B$14+V15*$B$15+V16*$B$16+V17*$B$17+V19*$B$19+V23*$B$23+V18*$B$18+V22*$B$22+V24*B24) -> 6383.24 | W30: =(W14*$B$14+W15*$B$15+W16*$B$16+W17*$B$17+W19*$B$19+W23*$B$23+W18*$B$18+W22*$B$22+W24*B24) -> 4916.82 | X30: =(X14*$B$14+X15*$B$15+X16*$B$16+X17*$B$17+X19*$B$19+X23*$B$23+X18*$B$18+X22*$B$22+X24*B24) -> 10211.75 | Y30: =(Y14*$B$14+Y15*$B$15+Y16*$B$16+Y17*$B$17+Y19*$B$19+Y23*$B$23+Y18*$B$18+Y22*$B$22+Y24*$B$24) -> 10211.75 | Z30: =(Z14*$B$14+Z15*$B$15+Z16*$B$16+Z17*$B$17+Z19*$B$19+Z23*$B$23+Z18*$B$18+Z22*$B$22+Z24*$B$24+Z26*B26) -> 10229.48 | AA30: =(AA14*$B$14+AA15*$B$15+AA16*$B$16+AA17*$B$17+AA19*$B$19+AA23*$B$23+AA18*$B$18+AA22*$B$22) -> 10211.75 | AB30: =(AB14*$B$14+AB15*$B$15+AB16*$B$16+AB17*$B$17+AB19*$B$19+AB23*$B$23+AB18*$B$18+AB22*$B$22+AB24*B24)-243.4 -> 6819.86 | AC30: =(AC14*$B$14+AC15*$B$15+AC16*$B$16+AC17*$B$17+AC19*$B$19+AC23*$B$23+AC18*$B$18+AC22*$B$22+AC24*B24) -> 5520.64 | AD30: =(AD14*$B$14+AD15*$B$15+AD16*$B$16+AD17*$B$17+AD19*$B$19+AD23*$B$23+AD18*$B$18+AD22*$B$22+AD24*B24) -> 4916.82 | AE30: =(AE14*$B$14+AE15*$B$15+AE16*$B$16+AE17*$B$17+AE19*$B$19+AE23*$B$23+AE18*$B$18+AE22*$B$22+AE24*B24) -> 10150.89 | AF30: =(AF14*$B$14+AF15*$B$15+AF16*$B$16+AF17*$B$17+AF19*$B$19+AF23*$B$23+AF18*$B$18+AF22*$B$22+AF24*B24) -> 10125.49 | AG30: =(AG14*$B$14+AG15*$B$15+AG16*$B$16+AG17*$B$17+AG19*$B$19+AG23*$B$23+AG18*$B$18+AG22*$B$22+AG24*B24+AG26*B26) -> 11439.51
A31: Servicios KM | B31: =SUM(C31:AG31) -> 196041.96 | C31: =$B$5*C5+$B$6*C6+$B$7*C7+$B$8*C8+$B$10*C10+$B$9*C9+C11*B11 -> 4823.16 | D31: =$B$5*D5+$B$6*D6+$B$7*D7+$B$8*D8+$B$10*D10+$B$9*D9 -> 7055.59 | E31: =$B$5*E5+$B$6*E6+$B$7*E7+$B$8*E8+$B$10*E10+$B$9*E9 -> 7055.59 | F31: =$B$5*F5+$B$6*F6+$B$7*F7+$B$8*F8+$B$10*F10+$B$9*F9 -> 7055.59 | G31: =$B$5*G5+$B$6*G6+$B$7*G7+$B$8*G8+$B$10*G10+$B$9*G9 -> 7055.59 | H31: =$B$5*H5+$B$6*H6+$B$7*H7+$B$8*H8+$B$10*H10+$B$9*H9 -> 6167.59 | I31: =$B$5*I5+$B$6*I6+$B$7*I7+$B$8*I8+$B$10*I10+$B$9*I9 -> 4787.43 | J31: =$B$5*J5+$B$6*J6+$B$7*J7+$B$8*J8+$B$10*J10+$B$9*J9 -> 7012.46 | K31: =$B$5*K5+$B$6*K6+$B$7*K7+$B$8*K8+$B$10*K10+$B$9*K9 -> 7055.59 | ... AG31: =$B$5*AG5+$B$6*AG6+$B$7*AG7+$B$8*AG8+$B$10*AG10+$B$9*AG9 -> 8220.1
A32: Asientos KM | B32: =SUM(C32:AG32) -> 30291089 | C32: =C30*104 -> 527752.16 | D32: =D30*104 -> 1358066.3 | E32: =E30*104 -> 1263621.8 | F32: =F30*104 -> 1283957 | G32: =G30*104 -> 1296864.4 | H32: =H30*104 -> 654885.92 | I32: =I30*104 -> 511349.28 | J32: =J30*104 -> 1236159.6 | ... AG32: =AG30*104 -> 1189709
A33: Coches KM | B33: =SUM(C33:AG33) -> 582520.94 | C33: =C30*2 -> 10149.08 | D33: =D30*2 -> 26116.66 | E33: =E30*2 -> 24300.42 | F33: =F30*2 -> 24691.48 | G33: =G30*2 -> 24939.7 | H33: =H30*2 -> 12593.96 | I33: =I30*2 -> 9833.64 | J33: =J30*2 -> 23772.3 | ... AG33: =AG30*2 -> 22879.02
A34: Capacidad Total | B34: =SUM(C34:AG34) -> 2465944 | C34: =+C29*362 -> 42716 | D34: =+D29*362 -> 110048 | E34: =+E29*362 -> 103170 | F34: =+F29*362 -> 105704 | G34: =+G29*362 -> 105704 | H34: =+H29*362 -> 52852 | I34: =+I29*362 -> 41268 | J34: =+J29*362 -> 101360 | ... AG34: =+AG29*362 -> 97378
A35: Ton Km Brutas | B35: =SUM(C35:AG35) -> 23096955 | C35: =C30*79.3 -> 402411.02 | D35: =D30*79.3 -> 1035525.6 | E35: =E30*79.3 -> 963511.65 | F35: =F30*79.3 -> 979017.18 | G35: =G30*79.3 -> 988859.1 | H35: =H30*79.3 -> 499350.51 | I35: =I30*79.3 -> 389903.83 | J35: =J30*79.3 -> 942571.69 | ... AG35: =AG30*79.3 -> 907153.14

Sheet Data Ocupacion
D1: 45292 | F1: 45293 | H1: 45294 | J1: 45295 | L1: 45296 | N1: 45297 | P1: 45298 | R1: 45299 | T1: 45300 | V1: 45301 | X1: 45302 | Z1: 45303 | AB1: 45304 | AD1: 45305 | AF1: 45306 | AH1: 45307 | AJ1: 45308 | AL1: 45309 | AN1: 45310 | AP1: 45311 | AR1: 45312 | AT1: 45313 | AV1: 45314 | AX1: 45315 | AZ1: 45316 | BB1: 45317 | BD1: 45318 | BF1: 45319 | BH1: 45320 | BJ1: 45321 | BL1: 45322
D2: S | E2: M | F2: S | G2: M | H2: S | I2: M | J2: S | K2: M | L2: S | M2: M | N2: S | O2: M | P2: S | Q2: M | R2: S | S2: M | T2: S | U2: M | V2: S | W2: M | X2: S | Y2: M | Z2: S | AA2: M | AB2: S | AC2: M | AD2: S | AE2: M | AF2: S | AG2: M | AH2: S | AI2: M | AJ2: S | AK2: M | AL2: S | AM2: M | AN2: S | AO2: M | AP2: S | AQ2: M | AR2: S | AS2: M | AT2: S | AU2: M | AV2: S | AW2: M | AX2: S | AY2: M | AZ2: S | BA2: M | BB2: S | BC2: M | BD2: S | BE2: M | BF2: S | BG2: M | BH2: S | BI2: M | BJ2: S | BK2: M | BL2: S | BM2: M
A3: Servicios PU-SA | D3: 0 | E3: 0 | F3: 0 | G3: 0 | H3: 0 | I3: 0 | J3: 0 | K3: 0 | L3: 0 | M3: 0 | N3: 0 | O3: 0 | P3: 0 | Q3: 0 | R3: 0 | S3: 0 | T3: 0 | U3: 0 | V3: 0 | W3: 0 | X3: 0 | Y3: 0 | Z3: 0 | AA3: 0 | AB3: 0 | AC3: 0 | AD3: 0 | AE3: 0 | AF3: 0 | AG3: 0 | AH3: 0 | AI3: 0 | AJ3: 0 | AK3: 0 | AL3: 0 | AM3: 0 | AN3: 0 | AO3: 0 | AP3: 0 | AQ3: 0 | AR3: 0 | AS3: 0 | AT3: 0 | AU3: 0 | AV3: 0 | AW3: 0 | AX3: 0 | AY3: 0 | AZ3: 0 | BA3: 0 | BB3: 0 | BC3: 0 | BD3: 0 | BE3: 0 | BF3: 0 | BG3: 0 | BH3: 0 | BI3: 0 | BJ3: 0 | BK3: 0 | BL3: 0 | BM3: 0
A4: Servicios PU-EB | D4: 0 | E4: 0 | F4: 0 | G4: 0 | H4: 0 | I4: 0 | J4: 0 | K4: 0 | L4: 0 | M4: 0 | N4: 0 | O4: 0 | P4: 0 | Q4: 0 | R4: 0 | S4: 0 | T4: 0 | U4: 0 | V4: 0 | W4: 0 | X4: 0 | Y4: 0 | Z4: 0 | AA4: 0 | AB4: 0 | AC4: 0 | AD4: 0 | AE4: 0 | AF4: 0 | AG4: 0 | AH4: 0 | AI4: 0 | AJ4: 0 | AK4: 0 | AL4: 0 | AM4: 0 | AN4: 0 | AO4: 0 | AP4: 0 | AQ4: 0 | AR4: 0 | AS4: 0 | AT4: 0 | AU4: 0 | AV4: 0 | AW4: 0 | AX4: 0 | AY4: 0 | AZ4: 0 | BA4: 0 | BB4: 0 | BC4: 0 | BD4: 0 | BE4: 0 | BF4: 0 | BG4: 0 | BH4: 0 | BI4: 0 | BJ4: 0 | BK4: 0 | BL4: 0 | BM4: 0
A5: Servicios PU-LI | D5: 0 | E5: 0 | F5: 0 | G5: 11 | H5: 0 | I5: 11 | J5: 0 | K5: 11 | L5: 0 | M5: 11 | N5: 0 | O5: 0 | P5: 0 | Q5: 0 | R5: 0 | S5: 11 | T5: 0 | U5: 11 | V5: 0 | W5: 11 | X5: 0 | Y5: 11 | Z5: 0 | AA5: 11 | AB5: 0 | AC5: 0 | AD5: 0 | AE5: 0 | AF5: 0 | AG5: 11 | AH5: 0 | AI5: 11 | AJ5: 0 | AK5: 11 | AL5: 0 | AM5: 11 | AN5: 0 | AO5: 11 | AP5: 0 | AQ5: 0 | AR5: 0 | AS5: 0 | AT5: 0 | AU5: 11 | AV5: 0 | AW5: 11 | AX5: 0 | AY5: 11 | AZ5: 0 | BA5: 11 | BB5: 0 | BC5: 6 | BD5: 0 | BE5: 0 | BF5: 0 | BG5: 0 | BH5: 0 | BI5: 11 | BJ5: 0 | BK5: 11 | BL5: 2 | BM5: 13
A6: Servicios SA-PU | D6: 0 | E6: 0 | F6: 0 | G6: 0 | H6: 0 | I6: 0 | J6: 0 | K6: 0 | L6: 0 | M6: 0 | N6: 0 | O6: 0 | P6: 0 | Q6: 0 | R6: 0 | S6: 0 | T6: 0 | U6: 0 | V6: 0 | W6: 0 | X6: 0 | Y6: 0 | Z6: 0 | AA6: 0 | AB6: 0 | AC6: 0 | AD6: 0 | AE6: 0 | AF6: 0 | AG6: 0 | AH6: 0 | AI6: 0 | AJ6: 0 | AK6: 0 | AL6: 0 | AM6: 0 | AN6: 0 | AO6: 0 | AP6: 0 | AQ6: 0 | AR6: 0 | AS6: 0 | AT6: 0 | AU6: 0 | AV6: 0 | AW6: 0 | AX6: 0 | AY6: 0 | AZ6: 0 | BA6: 0 | BB6: 0 | BC6: 0 | BD6: 0 | BE6: 0 | BF6: 0 | BG6: 0 | BH6: 0 | BI6: 0 | BJ6: 0 | BK6: 0 | BL6: 0 | BM6: 0
A7: Servicios EB-PU | D7: 0 | E7: 0 | F7: 0 | G7: 0 | H7: 0 | I7: 0 | J7: 0 | K7: 0 | L7: 0 | M7: 0 | N7: 0 | O7: 0 | P7: 0 | Q7: 0 | R7: 0 | S7: 0 | T7: 0 | U7: 0 | V7: 0 | W7: 0 | X7: 0 | Y7: 0 | Z7: 0 | AA7: 0 | AB7: 0 | AC7: 0 | AD7: 0 | AE7: 0 | AF7: 0 | AG7: 0 | AH7: 0 | AI7: 0 | AJ7: 0 | AK7: 0 | AL7: 0 | AM7: 0 | AN7: 0 | AO7: 0 | AP7: 0 | AQ7: 0 | AR7: 0 | AS7: 0 | AT7: 0 | AU7: 0 | AV7: 0 | AW7: 0 | AX7: 0 | AY7: 0 | AZ7: 0 | BA7: 0 | BB7: 0 | BC7: 0 | BD7: 0 | BE7: 0 | BF7: 0 | BG7: 0 | BH7: 0 | BI7: 0 | BJ7: 0 | BK7: 0 | BL7: 0 | BM7: 0
A8: Servicios LI-PU | D8: 0 | E8: 0 | F8: 0 | G8: 11 | H8: 0 | I8: 11 | J8: 0 | K8: 11 | L8: 0 | M8: 11 | N8: 0 | O8: 0 | P8: 0 | Q8: 0 | R8: 0 | S8: 11 | T8: 0 | U8: 11 | V8: 0 | W8: 11 | X8: 0 | Y8: 11 | Z8: 0 | AA8: 11 | AB8: 0 | AC8: 0 | AD8: 0 | AE8: 0 | AF8: 1 | AG8: 10 | AH8: 1 | AI8: 10 | AJ8: 1 | AK8: 10 | AL8: 1 | AM8: 10 | AN8: 1 | AO8: 10 | AP8: 0 | AQ8: 0 | AR8: 0 | AS8: 0 | AT8: 3 | AU8: 8 | AV8: 3 | AW8: 8 | AX8: 3 | AY8: 8 | AZ8: 3 | BA8: 8 | BB8: 0 | BC8: 5 | BD8: 0 | BE8: 0 | BF8: 0 | BG8: 0 | BH8: 3 | BI8: 8 | BJ8: 3 | BK8: 8 | BL8: 10 | BM8: 4
A10: Servicios PU-SA | D10: 0 | E10: 0 | F10: 0 | G10: 0 | H10: 0 | I10: 0 | J10: 0 | K10: 0 | L10: 0 | M10: 0 | N10: 0 | O10: 0 | P10: 0 | Q10: 0 | R10: 0 | S10: 0 | T10: 0 | U10: 0 | V10: 0 | W10: 0 | X10: 0 | Y10: 0 | Z10: 0 | AA10: 0 | AB10: 0 | AC10: 0 | AD10: 0 | AE10: 0 | AF10: 0 | AG10: 0 | AH10: 0 | AI10: 0 | AJ10: 0 | AK10: 0 | AL10: 0 | AM10: 0 | AN10: 0 | AO10: 0 | AP10: 0 | AQ10: 0 | AR10: 0 | AS10: 0 | AT10: 0 | AU10: 0 | AV10: 0 | AW10: 0 | AX10: 0 | AY10: 0 | AZ10: 0 | BA10: 0 | BB10: 0 | BC10: 0 | BD10: 0 | BE10: 0 | BF10: 0 | BG10: 0 | BH10: 0 | BI10: 0 | BJ10: 0 | BK10: 0 | BL10: 0 | BM10: 0
A11: Servicios PU-EB | D11: 0 | E11: 0 | F11: 0 | G11: 0 | H11: 0 | I11: 0 | J11: 0 | K11: 0 | L11: 0 | M11: 0 | N11: 0 | O11: 0 | P11: 0 | Q11: 0 | R11: 0 | S11: 0 | T11: 0 | U11: 0 | V11: 0 | W11: 0 | X11: 0 | Y11: 0 | Z11: 0 | AA11: 0 | AB11: 0 | AC11: 0 | AD11: 0 | AE11: 0 | AF11: 0 | AG11: 0 | AH11: 0 | AI11: 0 | AJ11: 0 | AK11: 0 | AL11: 0 | AM11: 0 | AN11: 0 | AO11: 0 | AP11: 0 | AQ11: 0 | AR11: 0 | AS11: 0 | AT11: 0 | AU11: 0 | AV11: 0 | AW11: 0 | AX11: 0 | AY11: 0 | AZ11: 0 | BA11: 0 | BB11: 0 | BC11: 0 | BD11: 0 | BE11: 0 | BF11: 0 | BG11: 0 | BH11: 0 | BI11: 0 | BJ11: 0 | BK11: 0 | BL11: 0 | BM11: 0
A12: Servicios PU-LI | D12: 51 | E12: 3 | F12: 12 | G12: 50 | H12: 22 | I12: 40 | J12: 18 | K12: 44 | L12: 18 | M12: 44 | N12: 67 | O12: 3 | P12: 51 | Q12: 3 | R12: 20 | S12: 42 | T12: 28 | U12: 34 | V12: 28 | W12: 34 | X12: 28 | Y12: 34 | Z12: 28 | AA12: 34 | AB12: 66 | AC12: 4 | AD12: 51 | AE12: 3 | AF12: 36 | AG12: 26 | AH12: 38 | AI12: 24 | AJ12: 37 | AK12: 25 | AL12: 37 | AM12: 25 | AN12: 36 | AO12: 26 | AP12: 68 | AQ12: 3 | AR12: 51 | AS12: 3 | AT12: 45 | AU12: 17 | AV12: 45 | AW12: 17 | AX12: 44 | AY12: 18 | AZ12: 45 | BA12: 17 | BB12: 5 | BC12: 30 | BD12: 0 | BE12: 32 | BF12: 0 | BG12: 28 | BH12: 45 | BI12: 17 | BJ12: 46 | BK12: 16 | BL12: 48 | BM12: 20
A13: Servicios SA-PU | D13: 0 | E13: 0 | F13: 0 | G13: 0 | H13: 0 | I13: 0 | J13: 0 | K13: 0 | L13: 0 | M13: 0 | N13: 0 | O13: 0 | P13: 0 | Q13: 0 | R13: 0 | S13: 0 | T13: 0 | U13: 0 | V13: 0 | W13: 0 | X13: 0 | Y13: 0 | Z13: 0 | AA13: 0 | AB13: 0 | AC13: 0 | AD13: 0 | AE13: 0 | AF13: 0 | AG13: 0 | AH13: 0 | AI13: 0 | AJ13: 0 | AK13: 0 | AL13: 0 | AM13: 0 | AN13: 0 | AO13: 0 | AP13: 0 | AQ13: 0 | AR13: 0 | AS13: 0 | AT13: 0 | AU13: 0 | AV13: 0 | AW13: 0 | AX13: 0 | AY13: 0 | AZ13: 0 | BA13: 0 | BB13: 0 | BC13: 0 | BD13: 0 | BE13: 0 | BF13: 0 | BG13: 0 | BH13: 0 | BI13: 0 | BJ13: 0 | BK13: 0 | BL13: 0 | BM13: 0
A14: Servicios EB-PU | D14: 0 | E14: 0 | F14: 0 | G14: 1 | H14: 0 | I14: 1 | J14: 0 | K14: 1 | L14: 0 | M14: 1 | N14: 0 | O14: 0 | P14: 0 | Q14: 0 | R14: 0 | S14: 1 | T14: 0 | U14: 1 | V14: 0 | W14: 1 | X14: 0 | Y14: 1 | Z14: 0 | AA14: 1 | AB14: 0 | AC14: 0 | AD14: 0 | AE14: 0 | AF14: 1 | AG14: 1 | AH14: 0 | AI14: 1 | AJ14: 0 | AK14: 1 | AL14: 0 | AM14: 1 | AN14: 0 | AO14: 1 | AP14: 0 | AQ14: 0 | AR14: 0 | AS14: 0 | AT14: 0 | AU14: 1 | AV14: 0 | AW14: 1 | AX14: 0 | AY14: 1 | AZ14: 0 | BA14: 1 | BB14: 0 | BC14: 1 | BD14: 0 | BE14: 0 | BF14: 0 | BG14: 0 | BH14: 0 | BI14: 1 | BJ14: 0 | BK14: 1 | BL14: 0 | BM14: 1
A15: Servicios LI-PU | D15: 55 | E15: 2 | F15: 12 | G15: 51 | H15: 21 | I15: 42 | J15: 18 | K15: 45 | L15: 18 | M15: 45 | N15: 73 | O15: 0 | P15: 57 | Q15: 0 | R15: 24 | S15: 39 | T15: 26 | U15: 37 | V15: 25 | W15: 38 | X15: 24 | Y15: 39 | Z15: 24 | AA15: 39 | AB15: 72 | AC15: 1 | AD15: 57 | AE15: 0 | AF15: 32 | AG15: 31 | AH15: 33 | AI15: 30 | AJ15: 32 | AK15: 31 | AL15: 33 | AM15: 30 | AN15: 33 | AO15: 30 | AP15: 74 | AQ15: 0 | AR15: 57 | AS15: 0 | AT15: 38 | AU15: 25 | AV15: 38 | AW15: 25 | AX15: 38 | AY15: 25 | AZ15: 38 | BA15: 25 | BB15: 2 | BC15: 31 | BD15: 2 | BE15: 31 | BF15: 0 | BG15: 29 | BH15: 39 | BI15: 24 | BJ15: 39 | BK15: 24 | BL15: 43 | BM15: 28
A16: Servicios MI-LI | D16: 0 | E16: 1
A18: Servicios PU-SA | D18: 0 | E18: 0 | F18: 0 | G18: 0 | H18: 0 | I18: 0 | J18: 0 | K18: 0 | L18: 0 | M18: 0 | N18: 0 | O18: 0 | P18: 0 | Q18: 0 | R18: 0 | S18: 0 | T18: 0 | U18: 0 | V18: 0 | W18: 0 | X18: 0 | Y18: 0 | Z18: 0 | AA18: 0 | AB18: 0 | AC18: 0 | AD18: 0 | AE18: 0 | AF18: 0 | AG18: 0 | AH18: 0 | AI18: 0 | AJ18: 0 | AK18: 0 | AL18: 0 | AM18: 0 | AN18: 0 | AO18: 0 | AP18: 0 | AQ18: 0 | AR18: 0 | AS18: 0 | AT18: 0 | AU18: 0 | AV18: 0 | AW18: 0 | AX18: 0 | AY18: 0 | AZ18: 0 | BA18: 0 | BB18: 0 | BC18: 0 | BD18: 0 | BE18: 0 | BF18: 0 | BG18: 0 | BH18: 0 | BI18: 0 | BJ18: 0 | BK18: 0 | BL18: 0 | BM18: 0
A19: Servicios PU-EB | D19: 0 | E19: 0 | F19: 0 | G19: 0 | H19: 0 | I19: 0 | J19: 0 | K19: 0 | L19: 0 | M19: 0 | N19: 0 | O19: 0 | P19: 0 | Q19: 0 | R19: 0 | S19: 0 | T19: 0 | U19: 0 | V19: 0 | W19: 0 | X19: 0 | Y19: 0 | Z19: 0 | AA19: 0 | AB19: 0 | AC19: 0 | AD19: 0 | AE19: 0 | AF19: 0 | AG19: 0 | AH19: 0 | AI19: 0 | AJ19: 0 | AK19: 0 | AL19: 0 | AM19: 0 | AN19: 0 | AO19: 0 | AP19: 0 | AQ19: 0 | AR19: 0 | AS19: 0 | AT19: 0 | AU19: 0 | AV19: 0 | AW19: 0 | AX19: 0 | AY19: 0 | AZ19: 0 | BA19: 0 | BB19: 0 | BC19: 0 | BD19: 0 | BE19: 0 | BF19: 0 | BG19: 0 | BH19: 0 | BI19: 0 | BJ19: 0 | BK19: 0 | BL19: 0 | BM19: 0
A20: Servicios PU-LI | D20: 0 | E20: 0 | F20: 0 | G20: 9 | H20: 0 | I20: 9 | J20: 0 | K20: 9 | L20: 0 | M20: 9 | N20: 0 | O20: 0 | P20: 0 | Q20: 0 | R20: 0 | S20: 8 | T20: 0 | U20: 9 | V20: 0 | W20: 9 | X20: 0 | Y20: 9 | Z20: 0 | AA20: 9 | AB20: 0 | AC20: 0 | AD20: 0 | AE20: 0 | AF20: 0 | AG20: 9 | AH20: 0 | AI20: 9 | AJ20: 0 | AK20: 9 | AL20: 0 | AM20: 9 | AN20: 0 | AO20: 9 | AP20: 0 | AQ20: 0 | AR20: 0 | AS20: 0 | AT20: 0 | AU20: 9 | AV20: 0 | AW20: 9 | AX20: 0 | AY20: 9 | AZ20: 0 | BA20: 9 | BB20: 0 | BC20: 3 | BD20: 0 | BE20: 0 | BF20: 0 | BG20: 0 | BH20: 0 | BI20: 9 | BJ20: 0 | BK20: 9 | BL20: 3 | BM20: 9
A21: Servicios SA-PU | D21: 0 | E21: 0 | F21: 0 | G21: 0 | H21: 0 | I21: 0 | J21: 0 | K21: 0 | L21: 0 | M21: 0 | N21: 0 | O21: 0 | P21: 0 | Q21: 0 | R21: 0 | S21: 0 | T21: 0 | U21: 0 | V21: 0 | W21: 0 | X21: 0 | Y21: 0 | Z21: 0 | AA21: 0 | AB21: 0 | AC21: 0 | AD21: 0 | AE21: 0 | AF21: 0 | AG21: 0 | AH21: 0 | AI21: 0 | AJ21: 0 | AK21: 0 | AL21: 0 | AM21: 0 | AN21: 0 | AO21: 0 | AP21: 0 | AQ21: 0 | AR21: 0 | AS21: 0 | AT21: 0 | AU21: 0 | AV21: 0 | AW21: 0 | AX21: 0 | AY21: 0 | AZ21: 0 | BA21: 0 | BB21: 0 | BC21: 0 | BD21: 0 | BE21: 0 | BF21: 0 | BG21: 0 | BH21: 0 | BI21: 0 | BJ21: 0 | BK21: 0 | BL21: 0 | BM21: 0
A22: Servicios EB-PU | D22: 0 | E22: 0 | F22: 0 | G22: 0 | H22: 0 | I22: 0 | J22: 0 | K22: 0 | L22: 0 | M22: 0 | N22: 0 | O22: 0 | P22: 0 | Q22: 0 | R22: 0 | S22: 0 | T22: 0 | U22: 0 | V22: 0 | W22: 0 | X22: 0 | Y22: 0 | Z22: 0 | AA22: 0 | AB22: 0 | AC22: 0 | AD22: 0 | AE22: 0 | AF22: 0 | AG22: 0 | AH22: 0 | AI22: 0 | AJ22: 0 | AK22: 0 | AL22: 0 | AM22: 0 | AN22: 0 | AO22: 0 | AP22: 0 | AQ22: 0 | AR22: 0 | AS22: 0 | AT22: 0 | AU22: 0 | AV22: 0 | AW22: 0 | AX22: 0 | AY22: 0 | AZ22: 0 | BA22: 0 | BB22: 0 | BC22: 0 | BD22: 0 | BE22: 0 | BF22: 0 | BG22: 0 | BH22: 0 | BI22: 0 | BJ22: 0 | BK22: 0 | BL22: 0 | BM22: 0
A23: Servicios LI-PU | D23: 0 | E23: 0 | F23: 0 | G23: 7 | H23: 0 | I23: 7 | J23: 0 | K23: 7 | L23: 0 | M23: 7 | N23: 0 | O23: 0 | P23: 0 | Q23: 0 | R23: 2 | S23: 5 | T23: 3 | U23: 4 | V23: 4 | W23: 3 | X23: 4 | Y23: 3 | Z23: 4 | AA23: 3 | AB23: 0 | AC23: 0 | AD23: 0 | AE23: 0 | AF23: 4 | AG23: 3 | AH23: 4 | AI23: 3 | AJ23: 4 | AK23: 3 | AL23: 4 | AM23: 3 | AN23: 4 | AO23: 3 | AP23: 0 | AQ23: 0 | AR23: 0 | AS23: 0 | AT23: 4 | AU23: 3 | AV23: 4 | AW23: 3 | AX23: 4 | AY23: 3 | AZ23: 4 | BA23: 3 | BB23: 0 | BC23: 3 | BD23: 0 | BE23: 0 | BF23: 0 | BG23: 0 | BH23: 4 | BI23: 3 | BJ23: 4 | BK23: 3 | BL23: 7 | BM23: 3
D26: =SUM(D3:D23) -> 106 | E26: =SUM(E3:E23) -> 6 | F26: =SUM(F3:F23) -> 24 | G26: =SUM(G3:G23) -> 140 | H26: =SUM(H3:H23) -> 43 | I26: =SUM(I3:I23) -> 121 | J26: =SUM(J3:J23) -> 36 | K26: =SUM(K3:K23) -> 128 | ... BM26: =SUM(BM3:BM23) -> 78
A32: Km Servicio
A33: PU - LI | D33: =D5+D12+D20 -> 51 | E33: =E5+E12+E20 -> 3 | F33: =F5+F12+F20 -> 12 | G33: =G5+G12+G20 -> 70 | H33: =H5+H12+H20 -> 22 | I33: =I5+I12+I20 -> 60 | J33: =J5+J12+J20 -> 18 | K33: =K5+K12+K20 -> 64 | ... BM33: =BM5+BM12+BM20 -> 42
A34: LI - PU | D34: =D8+D15+D23 -> 55 | E34: =E8+E15+E23 -> 2 | F34: =F8+F15+F23 -> 12 | G34: =G8+G15+G23 -> 69 | H34: =H8+H15+H23 -> 21 | I34: =I8+I15+I23 -> 60 | J34: =J8+J15+J23 -> 18 | K34: =K8+K15+K23 -> 63 | ... BM34: =BM8+BM15+BM23 -> 35
A35: PU - SA | D35: =D3+D10+D18 -> 0 | E35: =E3+E10+E18 -> 0 | F35: =F3+F10+F18 -> 0 | G35: =G3+G10+G18 -> 0 | H35: =H3+H10+H18 -> 0 | I35: =I3+I10+I18 -> 0 | J35: =J3+J10+J18 -> 0 | K35: =K3+K10+K18 -> 0 | ... BM35: =BM3+BM10+BM18 -> 0
A36: SA - PU | D36: =D6+D13+D21 -> 0 | E36: =E6+E13+E21 -> 0 | F36: =F6+F13+F21 -> 0 | G36: =G6+G13+G21 -> 0 | H36: =H6+H13+H21 -> 0 | I36: =I6+I13+I21 -> 0 | J36: =J6+J13+J21 -> 0 | K36: =K6+K13+K21 -> 0 | ... BD36: =BD6+BD13+BD21 -> 0 | BE36: =BE4+BE11+BE19 -> 0 | BF36: =BF6+BF13+BF21 -> 0 | BG36: =BG6+BG13+BG21 -> 0 | BH36: =BH6+BH13+BH21 -> 0 | BI36: =BI6+BI13+BI21 -> 0 | BJ36: =BJ6+BJ13+BJ21 -> 0 | BK36: =BK6+BK13+BK21 -> 0 | BL36: =BL6+BL13+BL21 -> 0 | BM36: =BM6+BM13+BM21 -> 0
