Workbook

Sheet Odometro-Kilometraje
A1: Control Contador Kilometraje de Trenes
B2: 45627 | C2: 45628 | D2: 45629 | E2: 45630 | F2: 45631 | G2: 45632 | H2: 45633 | I2: 45634 | J2: 45635 | K2: 45636 | L2: 45637 | M2: 45638 | N2: 45639 | O2: 45640 | P2: 45641 | Q2: 45642 | R2: 45643 | S2: 45644 | T2: 45645 | U2: 45646 | V2: 45647 | W2: 45648 | X2: 45649 | Y2: 45650 | Z2: 45651 | AA2: 45652 | AB2: 45653 | AC2: 45654 | AD2: 45655 | AE2: 45656 | AF2: 45657
B3: Contador | C3: Contador | D3: Contador | E3: Contador | F3: Contador | G3: Contador | H3: Contador | I3: Contador | J3: Contador | K3: Contador | L3: Contador | M3: Contador | N3: Contador | O3: Contador | P3: Contador | Q3: Contador | R3: Contador | S3: Contador | T3: Contador | U3: Contador | V3: Contador | W3: Contador | X3: Contador | Y3: Contador | Z3: Contador | AA3: Contador | AB3: Contador | AC3: Contador | AD3: Contador | AE3: Contador | AF3: Contador
A4: Tren | B4: Odómetro | C4: Odómetro | D4: Odómetro | E4: Odómetro | F4: Odómetro | G4: Odómetro | H4: Odómetro | I4: Odómetro | J4: Odómetro | K4: Odómetro | L4: Odómetro | M4: Odómetro | N4: Odómetro | O4: Odómetro | P4: Odómetro | Q4: Odómetro | R4: Odómetro | S4: Odómetro | T4: Odómetro | U4: Odómetro | V4: Odómetro | W4: Odómetro | X4: Odómetro | Y4: Odómetro | Z4: Odómetro | AA4: Odómetro | AB4: Odómetro | AC4: Odómetro | AD4: Odómetro | AE4: Odómetro | AF4: Odómetro
A5: M01 | B5: 1960665 | C5: 1961015 | D5: 1961578 | E5: 1962139 | F5: 1962531 | G5: 1963135 | H5: 1963178 | I5: 1963656 | J5: 1964098 | K5: 1964581 | L5: 1964847 | M5: 1965084 | N5: 1965279 | O5: 1965279 | P5: 1965279 | Q5: 1965447 | R5: 1965738 | S5: 1965933 | T5: 1966127 | U5: 1966714 | V5: 1967146 | W5: 1967149 | X5: 1967584 | Y5: 1968103 | Z5: 1968535 | AA5: 1969012 | AB5: 1969530 | AC5: 1969851 | AD5: 1969851 | AE5: 1970042 | AF5: 1970294
A6: M02 | B6: 1946264 | C6: 1946825 | D6: 1947188 | E6: 1947663 | F6: 1948113 | G6: 1948365 | H6: 1948884 | I6: 1949317 | J6: 1949834 | K6: 1950105 | L6: 1950589 | M6: 1950878 | N6: 1951081 | O6: 1951316 | P6: 1951752 | Q6: 1952229 | R6: 1952791 | S6: 1953394 | T6: 1953914 | U6: 1954475 | V6: 1954992 | W6: 1955426 | X6: 1955878 | Y6: 1956141 | Z6: 1956141 | AA6: 1956500 | AB6: 1956842 | AC6: 1957316 | AD6: 1957793 | AE6: 1958244 | AF6: 1958496
A7: M03 | B7: 2016578 | C7: 2016867 | D7: 2017061 | E7: 2017312 | F7: 2017729 | G7: 2017920 | H7: 2017920 | I7: 2017920 | J7: 2018389 | K7: 2018992 | L7: 2019496 | M7: 2019686 | N7: 2019888 | O7: 2020270 | P7: 2020270 | Q7: 2020584 | R7: 2021144 | S7: 2021470 | T7: 2021810 | U7: 2022259 | V7: 2022259 | W7: 2022259 | X7: 2022455 | Y7: 2022613 | Z7: 2023048 | AA7: 2023608 | AB7: 2023998 | AC7: 2023998 | AD7: 2023999 | AE7: 2024449 | AF7: 2024548
A8: M04 | B8: 2020625 | C8: 2020988 | D8: 2021154 | E8: 2021604 | F8: 2021994 | G8: 2022229 | H8: 2022708 | I8: 2022751 | J8: 2023356 | K8: 2023808 | L8: 2024061 | M8: 2024351 | N8: 2024604 | O8: 2025123 | P8: 2025382 | Q8: 2025901 | R8: 2026240 | S8: 2026581 | T8: 2027068 | U8: 2027630 | V8: 2028106 | W8: 2028538 | X8: 2029058 | Y8: 2029578 | Z8: 2030011 | AA8: 2030282 | AB8: 2030535 | AC8: 2031055 | AD8: 2031078 | AE8: 2031286 | AF8: 2031809
A9: M05 | B9: 1923435 | C9: 1923433 | D9: 1923953 | E9: 1924276 | F9: 1924746 | G9: 1925307 | H9: 1925827 | I9: 1926261 | J9: 1926586 | K9: 1926840 | L9: 1927401 | M9: 1927977 | N9: 1928428 | O9: 1928639 | P9: 1928639 | Q9: 1928892 | R9: 1929498 | S9: 1929922 | T9: 1930116 | U9: 1930376 | V9: 1930854 | W9: 1931287 | X9: 1931593 | Y9: 1932198 | Z9: 1932674 | AA9: 1933235 | AB9: 1933525 | AC9: 1933525 | AD9: 1933525 | AE9: 1933949 | AF9: 1934553
A10: M06 | B10: 2035743 | C10: 2035743 | D10: 2036271 | E10: 2036623 | F10: 2037148 | G10: 2037673 | H10: 2038198 | I10: 2038635 | J10: 2038916 | K10: 2039171 | L10: 2039458 | M10: 2039653 | N10: 2039992 | O10: 2040084 | P10: 2040086 | Q10: 2040450 | R10: 2040639 | S10: 2040833 | T10: 2041359 | U10: 2041922 | V10: 2042439 | W10: 2042443 | X10: 2042708 | Y10: 2043045 | Z10: 2043045 | AA10: 2043384 | AB10: 2043883 | AC10: 2044357 | AD10: 2044401 | AE10: 2044989 | AF10: 2045515
A11: M07 | B11: 2062099 | C11: 2062508 | D11: 2062703 | E11: 2063192 | F11: 2063688 | G11: 2064251 | H11: 2064728 | I11: 2065162 | J11: 2065700 | K11: 2066058 | L11: 2066512 | M11: 2066644 | N11: 2066932 | O11: 2067144 | P11: 2067380 | Q11: 2067860 | R11: 2068382 | S11: 2068904 | T11: 2069195 | U11: 2069682 | V11: 2069769 | W11: 2069773 | X11: 2070293 | Y11: 2070727 | Z11: 2070727 | AA11: 2071179 | AB11: 2071374 | AC11: 2071374 | AD11: 2071374 | AE11: 2071894 | AF11: 2072556
A12: M08 | B12: 1969965 | C12: 1970536 | D12: 1971054 | E12: 1971344 | F12: 1971930 | G12: 1972365 | H12: 1972365 | I12: 1972367 | J12: 1972718 | K12: 1973067 | L12: 1973628 | M12: 1974231 | N12: 1974748 | O12: 1975241 | P12: 1975432 | Q12: 1975885 | R12: 1976139 | S12: 1976699 | T12: 1977191 | U12: 1977386 | V12: 1977386 | W12: 1977386 | X12: 1977811 | Y12: 1978297 | Z12: 1978297 | AA12: 1978765 | AB12: 1979029 | AC12: 1979029 | AD12: 1979029 | AE12: 1979515 | AF12: 1980120
A13: M09 | B13: 1952184 | C13: 1952381 | D13: 1952637 | E13: 1953164 | F13: 1953732 | G13: 1954233 | H13: 1954233 | I13: 1954233 | J13: 1954439 | K13: 1954836 | L13: 1955405 | M13: 1955975 | N13: 1956222 | O13: 1956505 | P13: 1956943 | Q13: 1957468 | R13: 1958081 | S13: 1958694 | T13: 1959228 | U13: 1959800 | V13: 1960282 | W13: 1960326 | X13: 1960781 | Y13: 1960865 | Z13: 1960865 | AA13: 1961322 | AB13: 1961520 | AC13: 1961520 | AD13: 1961520 | AE13: 1962065 | AF13: 1962677
A14: M10 | B14: 2028177 | C14: 2028565 | D14: 2029168 | E14: 2029688 | F14: 2029991 | G14: 2030466 | H14: 2030941 | I14: 2031329 | J14: 2031702 | K14: 2032219 | L14: 2032676 | M14: 2032927 | N14: 2033344 | O14: 2033344 | P14: 2033344 | Q14: 2033539 | R14: 2033791 | S14: 2034260 | T14: 2034606 | U14: 2035123 | V14: 2035597 | W14: 2035641 | X14: 2036090 | Y14: 2036360 | Z14: 2036360 | AA14: 2036728 | AB14: 2037180 | AC14: 2037180 | AD14: 2037180 | AE14: 2037371 | AF14: 2037972
A15: M11 | B15: 2044698 | C15: 2044892 | D15: 2045144 | E15: 2045338 | F15: 2045591 | G15: 2045749 | H15: 2045749 | I15: 2045751 | J15: 2046179 | K15: 2046431 | L15: 2046806 | M15: 2047328 | N15: 2047935 | O15: 2048411 | P15: 2048845 | Q15: 2049341 | R15: 2049537 | S15: 2049798 | T15: 2050364 | U15: 2050843 | V15: 2050843 | W15: 2050843 | X15: 2051364 | Y15: 2051730 | Z15: 2051730 | AA15: 2052124 | AB15: 2052688 | AC15: 2053166 | AD15: 2053602 | AE15: 2054102 | AF15: 2054765
A16: M12 | B16: 1882981 | C16: 1883185 | D16: 1883437 | E16: 1883923 | F16: 1884373 | G16: 1884567 | H16: 1884567 | I16: 1884567 | J16: 1885095 | K16: 1885655 | L16: 1886019 | M16: 1886300 | N16: 1886904 | O16: 1887379 | P16: 1887613 | Q16: 1887875 | R16: 1888229 | S16: 1888533 | T16: 1888803 | U16: 1889056 | V16: 1889574 | W16: 1890005 | X16: 1890540 | Y16: 1891015 | Z16: 1891446 | AA16: 1892010 | AB16: 1892614 | AC16: 1892657 | AD16: 1893134 | AE16: 1893379 | AF16: 1893804
... A39: XM35 | B39: 625599 | C39: 625793 | D39: 626107 | E39: 626348 | F39: 626832 | G39: 627181 | H39: 627183 | I39: 627185 | J39: 627277 | K39: 627453 | L39: 627725 | M39: 627918 | N39: 628253 | O39: 628253 | P39: 628253 | Q39: 628421 | R39: 628683 | S39: 629118 | T39: 629550 | U39: 629914 | V39: 629914 | W39: 629934 | X39: 630136 | Y39: 630638 | Z39: 630682 | AA39: 631033 | AB39: 631484 | AC39: 631484 | AD39: 631484 | AE39: 631784 | AF39: 632352
A41: Kilometraje Diario Recorrido
B42: 45627 | C42: 45628 | D42: 45629 | E42: 45630 | F42: 45631 | G42: 45632 | H42: 45633 | I42: 45634 | J42: 45635 | K42: 45636 | L42: 45637 | M42: 45638 | N42: 45639 | O42: 45640 | P42: 45641 | Q42: 45642 | R42: 45643 | S42: 45644 | T42: 45645 | U42: 45646 | V42: 45647 | W42: 45648 | X42: 45649 | Y42: 45650 | Z42: 45651 | AA42: 45652 | AB42: 45653 | AC42: 45654 | AD42: 45655 | AE42: 45656 | AF42: 45657
B43: Kilometraje | C43: Kilometraje | D43: Kilometraje | E43: Kilometraje | F43: Kilometraje | G43: Kilometraje | H43: Kilometraje | I43: Kilometraje | J43: Kilometraje | K43: Kilometraje | L43: Kilometraje | M43: Kilometraje | N43: Kilometraje | O43: Kilometraje | P43: Kilometraje | Q43: Kilometraje | R43: Kilometraje | S43: Kilometraje | T43: Kilometraje | U43: Kilometraje | V43: Kilometraje | W43: Kilometraje | X43: Kilometraje | Y43: Kilometraje | Z43: Kilometraje | AA43: Kilometraje | AB43: Kilometraje | AC43: Kilometraje | AD43: Kilometraje | AE43: Kilometraje | AF43: Kilometraje
A44: Tren | B44: Diario | C44: Diario | D44: Diario | E44: Diario | F44: Diario | G44: Diario | H44: Diario | I44: Diario | J44: Diario | K44: Diario | L44: Diario | M44: Diario | N44: Diario | O44: Diario | P44: Diario | Q44: Diario | R44: Diario | S44: Diario | T44: Diario | U44: Diario | V44: Diario | W44: Diario | X44: Diario | Y44: Diario | Z44: Diario | AA44: Diario | AB44: Diario | AC44: Diario | AD44: Diario | AE44: Diario | AF44: Diario
A45: M01 | B45: 434 | C45: =C5-B5 -> 350 | D45: =D5-C5 -> 563 | E45: =E5-D5 -> 561 | F45: =F5-E5 -> 392 | G45: =G5-F5 -> 604 | H45: =H5-G5 -> 43 | I45: =I5-H5 -> 478 | J45: =J5-I5 -> 442 | ... AF45: =AF5-AE5 -> 252
A46: M02 | B46: 217 | C46: =C6-B6 -> 561 | D46: =D6-C6 -> 363 | E46: =E6-D6 -> 475 | F46: =F6-E6 -> 450 | G46: =G6-F6 -> 252 | H46: =H6-G6 -> 519 | I46: =I6-H6 -> 433 | J46: =J6-I6 -> 517 | ... AF46: =AF6-AE6 -> 252
A47: M03 | B47: 2 | C47: =C7-B7 -> 289 | D47: =D7-C7 -> 194 | E47: =E7-D7 -> 251 | F47: =F7-E7 -> 417 | G47: =G7-F7 -> 191 | H47: =H7-G7 -> 0 | I47: =I7-H7 -> 0 | J47: =J7-I7 -> 469 | ... AF47: =AF7-AE7 -> 99
A48: M04 | B48: 434 | C48: =C8-B8 -> 363 | D48: =D8-C8 -> 166 | E48: =E8-D8 -> 450 | F48: =F8-E8 -> 390 | G48: =G8-F8 -> 235 | H48: =H8-G8 -> 479 | I48: =I8-H8 -> 43 | J48: =J8-I8 -> 605 | ... AF48: =AF8-AE8 -> 523
A49: M05 | B49: 0 | C49: =C9-B9 -> -2 | D49: =D9-C9 -> 520 | E49: =E9-D9 -> 323 | F49: =F9-E9 -> 470 | G49: =G9-F9 -> 561 | H49: =H9-G9 -> 520 | I49: =I9-H9 -> 434 | J49: =J9-I9 -> 325 | ... AF49: =AF9-AE9 -> 604
A50: M06 | B50: 0 | C50: =C10-B10 -> 0 | D50: =D10-C10 -> 528 | E50: =E10-D10 -> 352 | F50: =F10-E10 -> 525 | G50: =G10-F10 -> 525 | H50: =H10-G10 -> 525 | I50: =I10-H10 -> 437 | J50: =J10-I10 -> 281 | ... AF50: =AF10-AE10 -> 526
A51: M07 | B51: 220 | C51: =C11-B11 -> 409 | D51: =D11-C11 -> 195 | E51: =E11-D11 -> 489 | F51: =F11-E11 -> 496 | G51: =G11-F11 -> 563 | H51: =H11-G11 -> 477 | I51: =I11-H11 -> 434 | J51: =J11-I11 -> 538 | ... AF51: =AF11-AE11 -> 662
A52: M08 | B52: 0 | C52: =C12-B12 -> 571 | D52: =D12-C12 -> 518 | E52: =E12-D12 -> 290 | F52: =F12-E12 -> 586 | G52: =G12-F12 -> 435 | H52: =H12-G12 -> 0 | I52: =I12-H12 -> 2 | J52: =J12-I12 -> 351 | ... AF52: =AF12-AE12 -> 605
A53: M09 | B53: 0 | C53: =C13-B13 -> 197 | D53: =D13-C13 -> 256 | E53: =E13-D13 -> 527 | F53: =F13-E13 -> 568 | G53: =G13-F13 -> 501 | H53: =H13-G13 -> 0 | I53: =I13-H13 -> 0 | J53: =J13-I13 -> 206 | ... AF53: =AF13-AE13 -> 612
A54: M10 | B54: 477 | C54: =C14-B14 -> 388 | D54: =D14-C14 -> 603 | E54: =E14-D14 -> 520 | F54: =F14-E14 -> 303 | G54: =G14-F14 -> 475 | H54: =H14-G14 -> 475 | I54: =I14-H14 -> 388 | J54: =J14-I14 -> 373 | ... AF54: =AF14-AE14 -> 601
A55: M11 | B55: 246 | C55: =C15-B15 -> 194 | D55: =D15-C15 -> 252 | E55: =E15-D15 -> 194 | F55: =F15-E15 -> 253 | G55: =G15-F15 -> 158 | H55: =H15-G15 -> 0 | I55: =I15-H15 -> 2 | J55: =J15-I15 -> 428 | ... AF55: =AF15-AE15 -> 663
A56: M12 | B56: 0 | C56: =C16-B16 -> 204 | D56: =D16-C16 -> 252 | E56: =E16-D16 -> 486 | F56: =F16-E16 -> 450 | G56: =G16-F16 -> 194 | H56: =H16-G16 -> 0 | I56: =I16-H16 -> 0 | J56: =J16-I16 -> 528 | ... AF56: =AF16-AE16 -> 425
... A79: XM35 | B79: 0 | C79: =C39-B39 -> 194 | D79: =D39-C39 -> 314 | E79: =E39-D39 -> 241 | F79: =F39-E39 -> 484 | G79: =G39-F39 -> 349 | H79: =H39-G39 -> 2 | I79: =I39-H39 -> 2 | J79: =J39-I39 -> 92 | ... AF79: =AF39-AE39 -> 568
A81: Kilometraje Diario | B81: =SUM(B45:B79) -> 4759 | C81: =SUM(C45:C79) -> 12498 | D81: =SUM(D45:D79) -> 12507 | E81: =SUM(E45:E79) -> 12754 | F81: =SUM(F45:F79) -> 12495 | G81: =SUM(G45:G79) -> 12453 | H81: =SUM(H45:H79) -> 6541 | I81: =SUM(I45:I79) -> 5155 | ... AF81: =SUM(AF45:AF79) -> 13961

Sheet KM-Servicio
F1: LI-BA | G1: SA-MI | H1: 21.7 | I1: EB-PU | J1: 25.4 | K1: PU-SA | L1: 29.11 | M1: QU-LI / LI-QU | N1: 21.7 | O1: VM-PU | P1: 8.3 | Q1: VM-LI | R1: 34.83 | S1: PU-ES | T1: 11.7 | U1: PU-QU
B2: CANTIDAD DE SERVICIOS | D2: CANTIDAD DE SERVICIOS | F2: 39.4 | G2: PU-PE | H2: 30.4 | I2: PO-SA | J2: 25.4 | K2: PU-LI | L2: 43.13 | M2: MI-LI / LI-MI | N2: 35.73 | O2: HO-LI/LI-HO | P2: 33.97 | Q2: PU-MI | R2: 7.4 | S2: PE-LI | T2: 12.73 | U2: 21.4
B3: PROGRAMADOS | D3: REALIZADOS | F3: Origen-Destino | G3: Total Trenes | H3: Total Servicios | I3: Kms.xTrenes | J3: Kmsxservicios. | K3: Asientos x Kms. | L3: Disp x Km. | M3: Total Odómetro | N3: % Uso Trenes | P3: Cortes | S3: Acoples | U3: KmTren R
B4: Simples | C4: Dobles | D4: Simples | E4: Dobles | P4: EB | Q4: SA | R4: PE | S4: EB | T4: SA
A5: 45627 | B5: 33 | C5: 14 | D5: ='Data Ocupacion'!D34 -> 23 | E5: ='Data Ocupacion'!E34 -> 16 | F5: PU-LI | G5: =D5+E5*2 -> 55 | H5: =D5+E5 -> 39 | I5: =G5*L$2 -> 2372.15 | J5: =H5*L$2 -> 1682.07 | K5: =I5*104 -> 246703.6 | L5: =H5*104 -> 4056 | U5: =I5-((P5*($L$2-$J$1)))-(S5*($J$1)) -> 2372.15
A6: PLANILLA NUEVA 1 DICIEMBRE DOMINGO | B6: 36 | C6: 11 | D6: ='Data Ocupacion'!D35 -> 25 | E6: ='Data Ocupacion'!E35 -> 15 | F6: LI-PU | G6: =D6+E6*2 -> 55 | H6: =D6+E6 -> 40 | I6: =G6*L$2 -> 2372.15 | J6: =H6*L$2 -> 1725.2 | K6: =I6*104 -> 246703.6 | L6: =H6*104 -> 4160 | U6: =I6-(S6*($L$2-$J$1)+(T6*($L$2-$L$1))) -> 2372.15
B7: 0 | C7: 0 | D7: ='Data Ocupacion'!D36 -> 0 | E7: ='Data Ocupacion'!E36 -> 0 | F7: PU-SA | G7: =D7+E7*2 -> 0 | H7: =D7+E7 -> 0 | I7: =G7*L$1 -> 0 | J7: =H7*L$1 -> 0 | K7: =I7*104 -> 0 | L7: =H7*104 -> 0 | U7: =I7-(P7*($L$1-$J$1)) -> 0
B8: 0 | C8: 0 | D8: ='Data Ocupacion'!D37 -> 0 | E8: ='Data Ocupacion'!E37 -> 0 | F8: SA-PU | G8: =D8+E8*2 -> 0 | H8: =D8+E8 -> 0 | I8: =G8*L$1 -> 0 | J8: =H8*L$1 -> 0 | K8: =I8*104 -> 0 | L8: =H8*104 -> 0 | U8: =I8 -> 0
B9: 0 | C9: 0 | D9: ='Data Ocupacion'!D38 -> 0 | E9: ='Data Ocupacion'!E38 -> 0 | F9: PU-EB | G9: =D9+E9*2 -> 0 | H9: =D9+E9 -> 0 | I9: =G9*J$1 -> 0 | J9: =H9*J$1 -> 0 | K9: =I9*104 -> 0 | L9: =H9*104 -> 0 | U9: =I9 -> 0
B10: 0 | C10: 0 | D10: ='Data Ocupacion'!D39 -> 0 | E10: ='Data Ocupacion'!E39 -> 0 | F10: EB-PU | G10: =D10+E10*2 -> 0 | H10: =D10+E10 -> 0 | I10: =G10*J$1 -> 0 | J10: =H10*J$1 -> 0 | K10: =I10*104 -> 0 | L10: =H10*104 -> 0 | U10: =I10 -> 0
B11: =SUM(B5:B10) -> 69 | C11: =SUM(C5:C10) -> 25 | D11: =SUM(D5:D10) -> 48 | E11: =SUM(E5:E10) -> 31 | G11: =SUM(G5:G10) -> 110 | H11: =SUM(H5:H10) -> 79 | I11: =SUM(I5:I10) -> 4744.3 | J11: =SUM(J5:J10) -> 3407.27 | K11: =SUM(K5:K10) -> 493407.2 | L11: =SUM(L5:L10) -> 8216 | M11: ='Odometro-Kilometraje'!B81 -> 4759 | N11: =(U11/M11)*100 -> 99.691112 | U11: =SUM(U5:U10) -> 4744.3
A12: =A5+1 -> 45628 | B12: 42 | C12: 37 | D12: ='Data Ocupacion'!F34 -> 41 | E12: ='Data Ocupacion'!G34 -> 38 | F12: PU-LI | G12: =D12+E12*2 -> 117 | H12: =D12+E12 -> 79 | I12: =G12*L$2 -> 5046.21 | J12: =H12*L$2 -> 3407.27 | K12: =I12*104 -> 524805.84 | L12: =H12*104 -> 8216 | P12: 3 | U12: =I12-((P12*($L$2-$J$1)))-(S12*($J$1)) -> 4993.02
B13: 40 | C13: 38 | D13: ='Data Ocupacion'!F35 -> 39 | E13: ='Data Ocupacion'!G35 -> 39 | F13: LI-PU | G13: =D13+E13*2 -> 117 | H13: =D13+E13 -> 78 | I13: =G13*L$2 -> 5046.21 | J13: =H13*L$2 -> 3364.14 | K13: =I13*104 -> 524805.84 | L13: =H13*104 -> 8112 | U13: =I13-(S13*($L$2-$J$1)+(T13*($L$2-$L$1))) -> 5046.21
B14: 29 | C14: 4 | D14: ='Data Ocupacion'!F36 -> 29 | E14: ='Data Ocupacion'!G36 -> 4 | F14: PU-SA | G14: =D14+E14*2 -> 37 | H14: =D14+E14 -> 33 | I14: =G14*L$1 -> 1077.07 | J14: =H14*L$1 -> 960.63 | K14: =I14*104 -> 112015.28 | L14: =H14*104 -> 3432 | U14: =I14-(P14*($L$1-$J$1)) -> 1077.07
B15: 28 | C15: 4 | D15: ='Data Ocupacion'!F37 -> 28 | E15: ='Data Ocupacion'!G37 -> 4 | F15: SA-PU | G15: =D15+E15*2 -> 36 | H15: =D15+E15 -> 32 | I15: =G15*L$1 -> 1047.96 | J15: =H15*L$1 -> 931.52 | K15: =I15*104 -> 108987.84 | L15: =H15*104 -> 3328 | U15: =I15 -> 1047.96
B16: 0 | C16: 0 | D16: ='Data Ocupacion'!F38 -> 0 | E16: ='Data Ocupacion'!G38 -> 0 | F16: PU-EB | G16: =D16+E16*2 -> 0 | H16: =D16+E16 -> 0 | I16: =G16*J$1 -> 0 | J16: =H16*J$1 -> 0 | K16: =I16*104 -> 0 | L16: =H16*104 -> 0 | U16: =I16 -> 0
B17: 1 | C17: 0 | D17: ='Data Ocupacion'!F39 -> 1 | E17: ='Data Ocupacion'!G39 -> 0 | F17: EB-PU | G17: =D17+E17*2 -> 1 | H17: =D17+E17 -> 1 | I17: =G17*J$1 -> 25.4 | J17: =H17*J$1 -> 25.4 | K17: =I17*104 -> 2641.6 | L17: =H17*104 -> 104 | U17: =I17 -> 25.4
B18: =SUM(B12:B17) -> 140 | C18: =SUM(C12:C17) -> 83 | D18: =SUM(D12:D17) -> 138 | E18: =SUM(E12:E17) -> 85 | G18: =SUM(G12:G17) -> 308 | H18: =SUM(H12:H17) -> 223 | I18: =SUM(I12:I17) -> 12242.85 | J18: =SUM(J12:J17) -> 8688.96 | K18: =SUM(K12:K17) -> 1273256.4 | L18: =SUM(L12:L17) -> 23192 | M18: ='Odometro-Kilometraje'!C81 -> 12498 | N18: =(U18/M18)*100 -> 97.532885 | U18: =SUM(U12:U17) -> 12189.66
A19: =A12+1 -> 45629 | B19: 42 | C19: 37 | D19: ='Data Ocupacion'!H34 -> 42 | E19: ='Data Ocupacion'!I34 -> 37 | F19: PU-LI | G19: =D19+E19*2 -> 116 | H19: =D19+E19 -> 79 | I19: =G19*L$2 -> 5003.08 | J19: =H19*L$2 -> 3407.27 | K19: =I19*104 -> 520320.32 | L19: =H19*104 -> 8216 | P19: 4 | U19: =I19-((P19*($L$2-$J$1)))-(S19*($J$1)) -> 4932.16
B20: 40 | C20: 38 | D20: ='Data Ocupacion'!H35 -> 40 | E20: ='Data Ocupacion'!I35 -> 38 | F20: LI-PU | G20: =D20+E20*2 -> 116 | H20: =D20+E20 -> 78 | I20: =G20*L$2 -> 5003.08 | J20: =H20*L$2 -> 3364.14 | K20: =I20*104 -> 520320.32 | L20: =H20*104 -> 8112 | U20: =I20-(S20*($L$2-$J$1)+(T20*($L$2-$L$1))) -> 5003.08
B21: 29 | C21: 4 | D21: ='Data Ocupacion'!H36 -> 29 | E21: ='Data Ocupacion'!I36 -> 4 | F21: PU-SA | G21: =D21+E21*2 -> 37 | H21: =D21+E21 -> 33 | I21: =G21*L$1 -> 1077.07 | J21: =H21*L$1 -> 960.63 | K21: =I21*104 -> 112015.28 | L21: =H21*104 -> 3432 | U21: =I21-(P21*($L$1-$J$1)) -> 1077.07
B22: 28 | C22: 4 | D22: ='Data Ocupacion'!H37 -> 28 | E22: ='Data Ocupacion'!I37 -> 4 | F22: SA-PU | G22: =D22+E22*2 -> 36 | H22: =D22+E22 -> 32 | I22: =G22*L$1 -> 1047.96 | J22: =H22*L$1 -> 931.52 | K22: =I22*104 -> 108987.84 | L22: =H22*104 -> 3328 | U22: =I22 -> 1047.96
B23: 0 | C23: 0 | D23: ='Data Ocupacion'!H38 -> 0 | E23: ='Data Ocupacion'!I38 -> 0 | F23: PU-EB | G23: =D23+E23*2 -> 0 | H23: =D23+E23 -> 0 | I23: =G23*J$1 -> 0 | J23: =H23*J$1 -> 0 | K23: =I23*104 -> 0 | L23: =H23*104 -> 0 | U23: =I23 -> 0
B24: 1 | C24: 0 | D24: ='Data Ocupacion'!H39 -> 1 | E24: ='Data Ocupacion'!I39 -> 0 | F24: EB-PU | G24: =D24+E24*2 -> 1 | H24: =D24+E24 -> 1 | I24: =G24*J$1 -> 25.4 | J24: =H24*J$1 -> 25.4 | K24: =I24*104 -> 2641.6 | L24: =H24*104 -> 104 | U24: =I24 -> 25.4
B25: =SUM(B19:B24) -> 140 | C25: =SUM(C19:C24) -> 83 | D25: =SUM(D19:D24) -> 140 | E25: =SUM(E19:E24) -> 83 | G25: =SUM(G19:G24) -> 306 | H25: =SUM(H19:H24) -> 223 | I25: =SUM(I19:I24) -> 12156.59 | J25: =SUM(J19:J24) -> 8688.96 | K25: =SUM(K19:K24) -> 1264285.4 | L25: =SUM(L19:L24) -> 23192 | M25: ='Odometro-Kilometraje'!D81 -> 12507 | N25: =(U25/M25)*100 -> 96.631247 | U25: =SUM(U19:U24) -> 12085.67
A26: =A19+1 -> 45630 | B26: 42 | C26: 37 | D26: ='Data Ocupacion'!J34 -> 42 | E26: ='Data Ocupacion'!K34 -> 37 | F26: PU-LI | G26: =D26+E26*2 -> 116 | H26: =D26+E26 -> 79 | I26: =G26*L$2 -> 5003.08 | J26: =H26*L$2 -> 3407.27 | K26: =I26*104 -> 520320.32 | L26: =H26*104 -> 8216 | P26: 3 | S26: 2 | U26: =I26-((P26*($L$2-$J$1)))-(S26*($J$1)) -> 4899.09
B27: 40 | C27: 38 | D27: ='Data Ocupacion'!J35 -> 40 | E27: ='Data Ocupacion'!K35 -> 38 | F27: LI-PU | G27: =D27+E27*2 -> 116 | H27: =D27+E27 -> 78 | I27: =G27*L$2 -> 5003.08 | J27: =H27*L$2 -> 3364.14 | K27: =I27*104 -> 520320.32 | L27: =H27*104 -> 8112 | U27: =I27-(S27*($L$2-$J$1)+(T27*($L$2-$L$1))) -> 5003.08
B28: 29 | C28: 4 | D28: ='Data Ocupacion'!J36 -> 29 | E28: ='Data Ocupacion'!K36 -> 4 | F28: PU-SA | G28: =D28+E28*2 -> 37 | H28: =D28+E28 -> 33 | I28: =G28*L$1 -> 1077.07 | J28: =H28*L$1 -> 960.63 | K28: =I28*104 -> 112015.28 | L28: =H28*104 -> 3432 | U28: =I28-(P28*($L$1-$J$1)) -> 1077.07
B29: 28 | C29: 4 | D29: ='Data Ocupacion'!J37 -> 28 | E29: ='Data Ocupacion'!K37 -> 4 | F29: SA-PU | G29: =D29+E29*2 -> 36 | H29: =D29+E29 -> 32 | I29: =G29*L$1 -> 1047.96 | J29: =H29*L$1 -> 931.52 | K29: =I29*104 -> 108987.84 | L29: =H29*104 -> 3328 | U29: =I29 -> 1047.96
B30: 0 | C30: 0 | D30: ='Data Ocupacion'!J38 -> 0 | E30: ='Data Ocupacion'!K38 -> 0 | F30: PU-EB | G30: =D30+E30*2 -> 0 | H30: =D30+E30 -> 0 | I30: =G30*J$1 -> 0 | J30: =H30*J$1 -> 0 | K30: =I30*104 -> 0 | L30: =H30*104 -> 0 | U30: =I30 -> 0
B31: 1 | C31: 0 | D31: ='Data Ocupacion'!J39 -> 1 | E31: ='Data Ocupacion'!K39 -> 0 | F31: EB-PU | G31: =D31+E31*2 -> 1 | H31: =D31+E31 -> 1 | I31: =G31*J$1 -> 25.4 | J31: =H31*J$1 -> 25.4 | K31: =I31*104 -> 2641.6 | L31: =H31*104 -> 104 | U31: =I31 -> 25.4
B32: =SUM(B26:B31) -> 140 | C32: =SUM(C26:C31) -> 83 | D32: =SUM(D26:D31) -> 140 | E32: =SUM(E26:E31) -> 83 | G32: =SUM(G26:G31) -> 306 | H32: =SUM(H26:H31) -> 223 | I32: =SUM(I26:I31) -> 12156.59 | J32: =SUM(J26:J31) -> 8688.96 | K32: =SUM(K26:K31) -> 1264285.4 | L32: =SUM(L26:L31) -> 23192 | M32: ='Odometro-Kilometraje'!E81 -> 12754 | N32: =(U32/M32)*100 -> 94.500549 | U32: =SUM(U26:U31) -> 12052.6
A33: =A26+1 -> 45631 | B33: 42 | C33: 37 | D33: ='Data Ocupacion'!L34 -> 42 | E33: ='Data Ocupacion'!M34 -> 37 | F33: PU-LI | G33: =D33+E33*2 -> 116 | H33: =D33+E33 -> 79 | I33: =G33*L$2 -> 5003.08 | J33: =H33*L$2 -> 3407.27 | K33: =I33*104 -> 520320.32 | L33: =H33*104 -> 8216 | P33: 4 | U33: =I33-((P33*($L$2-$J$1)))-(S33*($J$1)) -> 4932.16
B34: 40 | C34: 38 | D34: ='Data Ocupacion'!L35 -> 40 | E34: ='Data Ocupacion'!M35 -> 38 | F34: LI-PU | G34: =D34+E34*2 -> 116 | H34: =D34+E34 -> 78 | I34: =G34*L$2 -> 5003.08 | J34: =H34*L$2 -> 3364.14 | K34: =I34*104 -> 520320.32 | L34: =H34*104 -> 8112 | S34: 1 | U34: =I34-(S34*($L$2-$J$1)+(T34*($L$2-$L$1))) -> 4985.35
B35: 29 | C35: 4 | D35: ='Data Ocupacion'!L36 -> 29 | E35: ='Data Ocupacion'!M36 -> 4 | F35: PU-SA | G35: =D35+E35*2 -> 37 | H35: =D35+E35 -> 33 | I35: =G35*L$1 -> 1077.07 | J35: =H35*L$1 -> 960.63 | K35: =I35*104 -> 112015.28 | L35: =H35*104 -> 3432 | U35: =I35-(P35*($L$1-$J$1)) -> 1077.07
B36: 28 | C36: 4 | D36: ='Data Ocupacion'!L37 -> 28 | E36: ='Data Ocupacion'!M37 -> 4 | F36: SA-PU | G36: =D36+E36*2 -> 36 | H36: =D36+E36 -> 32 | I36: =G36*L$1 -> 1047.96 | J36: =H36*L$1 -> 931.52 | K36: =I36*104 -> 108987.84 | L36: =H36*104 -> 3328 | U36: =I36 -> 1047.96
B37: 0 | C37: 0 | D37: ='Data Ocupacion'!L38 -> 0 | E37: ='Data Ocupacion'!M38 -> 0 | F37: PU-EB | G37: =D37+E37*2 -> 0 | H37: =D37+E37 -> 0 | I37: =G37*J$1 -> 0 | J37: =H37*J$1 -> 0 | K37: =I37*104 -> 0 | L37: =H37*104 -> 0 | U37: =I37 -> 0
B38: 1 | C38: 0 | D38: ='Data Ocupacion'!L39 -> 1 | E38: ='Data Ocupacion'!M39 -> 0 | F38: EB-PU | G38: =D38+E38*2 -> 1 | H38: =D38+E38 -> 1 | I38: =G38*J$1 -> 25.4 | J38: =H38*J$1 -> 25.4 | K38: =I38*104 -> 2641.6 | L38: =H38*104 -> 104 | U38: =I38 -> 25.4
B39: =SUM(B33:B38) -> 140 | C39: =SUM(C33:C38) -> 83 | D39: =SUM(D33:D38) -> 140 | E39: =SUM(E33:E38) -> 83 | G39: =SUM(G33:G38) -> 306 | H39: =SUM(H33:H38) -> 223 | I39: =SUM(I33:I38) -> 12156.59 | J39: =SUM(J33:J38) -> 8688.96 | K39: =SUM(K33:K38) -> 1264285.4 | L39: =SUM(L33:L38) -> 23192 | M39: ='Odometro-Kilometraje'!F81 -> 12495 | N39: =(U39/M39)*100 -> 96.582153 | U39: =SUM(U33:U38) -> 12067.94
A40: =A33+1 -> 45632 | B40: 42 | C40: 37 | D40: ='Data Ocupacion'!N34 -> 43 | E40: ='Data Ocupacion'!O34 -> 36 | F40: PU-LI | G40: =D40+E40*2 -> 115 | H40: =D40+E40 -> 79 | I40: =G40*L$2 -> 4959.95 | J40: =H40*L$2 -> 3407.27 | K40: =I40*104 -> 515834.8 | L40: =H40*104 -> 8216 | P40: 3 | U40: =I40-((P40*($L$2-$J$1)))-(S40*($J$1)) -> 4906.76
...

Sheet Data Ocupacion
D1: 45627 | F1: 45628 | H1: 45629 | J1: 45630 | L1: 45631 | N1: 45632 | P1: 45633 | R1: 45634 | T1: 45635 | V1: 45636 | X1: 45637 | Z1: 45638 | AB1: 45639 | AD1: 45640 | AF1: 45641 | AH1: 45642 | AJ1: 45643 | AL1: 45644 | AN1: 45645 | AP1: 45646 | AR1: 45647 | AT1: 45648 | AV1: 45649 | AX1: 45650 | AZ1: 45651 | BB1: 45652 | BD1: 45653 | BF1: 45654 | BH1: 45655 | BJ1: 45656 | BL1: 45657
D2: S | E2: M | F2: S | G2: M | H2: S | I2: M | J2: S | K2: M | L2: S | M2: M | N2: S | O2: M | P2: S | Q2: M | R2: S | S2: M | T2: S | U2: M | V2: S | W2: M | X2: S | Y2: M | Z2: S | AA2: M | AB2: S | AC2: M | AD2: S | AE2: M | AF2: S | AG2: M | AH2: S | AI2: M | AJ2: S | AK2: M | AL2: S | AM2: M | AN2: S | AO2: M | AP2: S | AQ2: M | AR2: S | AS2: M | AT2: S | AU2: M | AV2: S | AW2: M | AX2: S | AY2: M | AZ2: S | BA2: M | BB2: S | BC2: M | BD2: S | BE2: M | BF2: S | BG2: M | BH2: S | BI2: M | BJ2: S | BK2: M | BL2: S | BM2: M
A3: Servicios PU-SA | D3: 0 | E3: 0 | F3: 6 | G3: 4 | H3: 6 | I3: 4 | J3: 6 | K3: 4 | L3: 6 | M3: 4 | N3: 6 | O3: 4 | P3: 0 | Q3: 0 | R3: 0 | S3: 0 | T3: 7 | U3: 3 | V3: 6 | W3: 4 | X3: 6 | Y3: 4 | Z3: 7 | AA3: 3 | AB3: 6 | AC3: 4 | AD3: 0 | AE3: 0 | AF3: 0 | AG3: 0 | AH3: 7 | AI3: 3 | AJ3: 6 | AK3: 4 | AL3: 6 | AM3: 4 | AN3: 6 | AO3: 4 | AP3: 6 | AQ3: 4 | AR3: 0 | AS3: 0 | AT3: 0 | AU3: 0 | AV3: 7 | AW3: 3 | AX3: 6 | AY3: 4 | AZ3: 0 | BA3: 0 | BB3: 7 | BC3: 3 | BD3: 6 | BE3: 4 | BF3: 0 | BG3: 0 | BH3: 0 | BI3: 0 | BJ3: 0 | BK3: 2 | BL3: 8 | BM3: 2
A4: Servicios PU-EB | D4: 0 | E4: 0 | F4: 0 | G4: 0 | H4: 0 | I4: 0 | J4: 0 | K4: 0 | L4: 0 | M4: 0 | N4: 0 | O4: 0 | P4: 0 | Q4: 0 | R4: 0 | S4: 0 | T4: 0 | U4: 0 | V4: 0 | W4: 0 | X4: 0 | Y4: 0 | Z4: 0 | AA4: 0 | AB4: 0 | AC4: 0 | AD4: 0 | AE4: 0 | AF4: 0 | AG4: 0 | AH4: 0 | AI4: 0 | AJ4: 0 | AK4: 0 | AL4: 0 | AM4: 0 | AN4: 0 | AO4: 0 | AP4: 0 | AQ4: 0 | AR4: 0 | AS4: 0 | AT4: 0 | AU4: 0 | AV4: 0 | AW4: 0 | AX4: 0 | AY4: 0 | AZ4: 0 | BA4: 0 | BB4: 0 | BC4: 0 | BD4: 0 | BE4: 0 | BF4: 0 | BG4: 0 | BH4: 0 | BI4: 0 | BJ4: 0 | BK4: 0 | BL4: 0 | BM4: 0
A5: Servicios PU-LI | D5: 0 | E5: 0 | F5: 1 | G5: 9 | H5: 1 | I5: 9 | J5: 1 | K5: 9 | L5: 1 | M5: 9 | N5: 1 | O5: 9 | P5: 0 | Q5: 0 | R5: 0 | S5: 0 | T5: 1 | U5: 9 | V5: 1 | W5: 9 | X5: 1 | Y5: 9 | Z5: 1 | AA5: 9 | AB5: 1 | AC5: 9 | AD5: 0 | AE5: 0 | AF5: 0 | AG5: 0 | AH5: 1 | AI5: 9 | AJ5: 1 | AK5: 9 | AL5: 1 | AM5: 9 | AN5: 1 | AO5: 9 | AP5: 2 | AQ5: 8 | AR5: 0 | AS5: 0 | AT5: 0 | AU5: 0 | AV5: 1 | AW5: 9 | AX5: 1 | AY5: 9 | AZ5: 0 | BA5: 0 | BB5: 1 | BC5: 9 | BD5: 1 | BE5: 9 | BF5: 0 | BG5: 0 | BH5: 0 | BI5: 0 | BJ5: 0 | BK5: 9 | BL5: 1 | BM5: 9
A6: Servicios SA-PU | D6: 0 | E6: 0 | F6: 9 | G6: 1 | H6: 9 | I6: 1 | J6: 9 | K6: 1 | L6: 9 | M6: 1 | N6: 9 | O6: 1 | P6: 0 | Q6: 0 | R6: 0 | S6: 0 | T6: 9 | U6: 0 | V6: 9 | W6: 1 | X6: 9 | Y6: 1 | Z6: 10 | AA6: 0 | AB6: 9 | AC6: 1 | AD6: 0 | AE6: 0 | AF6: 0 | AG6: 0 | AH6: 10 | AI6: 0 | AJ6: 9 | AK6: 1 | AL6: 9 | AM6: 1 | AN6: 9 | AO6: 1 | AP6: 9 | AQ6: 1 | AR6: 0 | AS6: 0 | AT6: 0 | AU6: 0 | AV6: 10 | AW6: 0 | AX6: 9 | AY6: 1 | AZ6: 0 | BA6: 0 | BB6: 10 | BC6: 0 | BD6: 9 | BE6: 1 | BF6: 0 | BG6: 0 | BH6: 0 | BI6: 0 | BJ6: 2 | BK6: 2 | BL6: 10 | BM6: 0
A7: Servicios EB-PU | D7: 0 | E7: 0 | F7: 0 | G7: 0 | H7: 0 | I7: 0 | J7: 0 | K7: 0 | L7: 0 | M7: 0 | N7: 0 | O7: 0 | P7: 0 | Q7: 0 | R7: 0 | S7: 0 | T7: 0 | U7: 0 | V7: 0 | W7: 0 | X7: 0 | Y7: 0 | Z7: 0 | AA7: 0 | AB7: 0 | AC7: 0 | AD7: 0 | AE7: 0 | AF7: 0 | AG7: 0 | AH7: 0 | AI7: 0 | AJ7: 0 | AK7: 0 | AL7: 0 | AM7: 0 | AN7: 0 | AO7: 0 | AP7: 0 | AQ7: 0 | AR7: 0 | AS7: 0 | AT7: 0 | AU7: 0 | AV7: 0 | AW7: 0 | AX7: 0 | AY7: 0 | AZ7: 0 | BA7: 0 | BB7: 0 | BC7: 0 | BD7: 0 | BE7: 0 | BF7: 0 | BG7: 0 | BH7: 0 | BI7: 0 | BJ7: 0 | BK7: 0 | BL7: 0 | BM7: 0
A8: Servicios LI-PU | D8: 0 | E8: 0 | F8: 2 | G8: 8 | H8: 3 | I8: 7 | J8: 3 | K8: 7 | L8: 3 | M8: 7 | N8: 3 | O8: 7 | P8: 0 | Q8: 0 | R8: 0 | S8: 0 | T8: 4 | U8: 6 | V8: 4 | W8: 6 | X8: 4 | Y8: 6 | Z8: 4 | AA8: 6 | AB8: 4 | AC8: 6 | AD8: 0 | AE8: 0 | AF8: 0 | AG8: 0 | AH8: 3 | AI8: 7 | AJ8: 4 | AK8: 6 | AL8: 5 | AM8: 5 | AN8: 4 | AO8: 6 | AP8: 5 | AQ8: 5 | AR8: 0 | AS8: 0 | AT8: 0 | AU8: 0 | AV8: 4 | AW8: 6 | AX8: 4 | AY8: 6 | AZ8: 0 | BA8: 0 | BB8: 3 | BC8: 7 | BD8: 4 | BE8: 6 | BF8: 0 | BG8: 0 | BH8: 0 | BI8: 0 | BJ8: 2 | BK8: 7 | BL8: 4 | BM8: 6
A10: Servicios PU-SA | D10: 0 | E10: 0 | F10: 16 | G10: 0 | H10: 16 | I10: 0 | J10: 16 | K10: 0 | L10: 16 | M10: 0 | N10: 16 | O10: 0 | P10: 0 | Q10: 0 | R10: 0 | S10: 0 | T10: 16 | U10: 0 | V10: 16 | W10: 0 | X10: 16 | Y10: 0 | Z10: 16 | AA10: 0 | AB10: 16 | AC10: 0 | AD10: 0 | AE10: 0 | AF10: 0 | AG10: 0 | AH10: 16 | AI10: 0 | AJ10: 16 | AK10: 0 | AL10: 16 | AM10: 0 | AN10: 16 | AO10: 0 | AP10: 15 | AQ10: 0 | AR10: 0 | AS10: 0 | AT10: 0 | AU10: 0 | AV10: 16 | AW10: 0 | AX10: 16 | AY10: 0 | AZ10: 0 | BA10: 0 | BB10: 16 | BC10: 0 | BD10: 16 | BE10: 0 | BF10: 0 | BG10: 0 | BH10: 0 | BI10: 0 | BJ10: 13 | BK10: 0 | BL10: 16 | BM10: 0
A11: Servicios PU-EB | D11: 0 | E11: 0 | F11: 0 | G11: 0 | H11: 0 | I11: 0 | J11: 0 | K11: 0 | L11: 0 | M11: 0 | N11: 0 | O11: 0 | P11: 0 | Q11: 0 | R11: 0 | S11: 0 | T11: 0 | U11: 0 | V11: 0 | W11: 0 | X11: 0 | Y11: 0 | Z11: 0 | AA11: 0 | AB11: 0 | AC11: 0 | AD11: 0 | AE11: 0 | AF11: 0 | AG11: 0 | AH11: 0 | AI11: 0 | AJ11: 0 | AK11: 0 | AL11: 0 | AM11: 0 | AN11: 0 | AO11: 0 | AP11: 0 | AQ11: 0 | AR11: 0 | AS11: 0 | AT11: 0 | AU11: 0 | AV11: 0 | AW11: 0 | AX11: 0 | AY11: 0 | AZ11: 0 | BA11: 0 | BB11: 0 | BC11: 0 | BD11: 0 | BE11: 0 | BF11: 0 | BG11: 0 | BH11: 0 | BI11: 0 | BJ11: 0 | BK11: 0 | BL11: 0 | BM11: 0
A12: Servicios PU-LI | D12: 23 | E12: 16 | F12: 38 | G12: 23 | H12: 39 | I12: 22 | J12: 39 | K12: 22 | L12: 39 | M12: 22 | N12: 40 | O12: 21 | P12: 69 | Q12: 3 | R12: 49 | S12: 5 | T12: 40 | U12: 21 | V12: 40 | W12: 21 | X12: 39 | Y12: 22 | Z12: 40 | AA12: 21 | AB12: 38 | AC12: 23 | AD12: 39 | AE12: 34 | AF12: 23 | AG12: 32 | AH12: 39 | AI12: 22 | AJ12: 39 | AK12: 22 | AL12: 41 | AM12: 20 | AN12: 40 | AO12: 21 | AP12: 40 | AQ12: 21 | AR12: 68 | AS12: 4 | AT12: 51 | AU12: 3 | AV12: 42 | AW12: 19 | AX12: 32 | AY12: 29 | AZ12: 51 | BA12: 3 | BB12: 38 | BC12: 23 | BD12: 40 | BE12: 21 | BF12: 69 | BG12: 3 | BH12: 51 | BI12: 3 | BJ12: 31 | BK12: 22 | BL12: 21 | BM12: 40
A13: Servicios SA-PU | D13: 0 | E13: 0 | F13: 13 | G13: 3 | H13: 13 | I13: 3 | J13: 13 | K13: 3 | L13: 13 | M13: 3 | N13: 13 | O13: 3 | P13: 0 | Q13: 0 | R13: 0 | S13: 0 | T13: 13 | U13: 3 | V13: 13 | W13: 3 | X13: 13 | Y13: 3 | Z13: 13 | AA13: 3 | AB13: 13 | AC13: 3 | AD13: 0 | AE13: 0 | AF13: 0 | AG13: 0 | AH13: 13 | AI13: 3 | AJ13: 13 | AK13: 3 | AL13: 13 | AM13: 3 | AN13: 13 | AO13: 3 | AP13: 13 | AQ13: 3 | AR13: 0 | AS13: 0 | AT13: 0 | AU13: 0 | AV13: 13 | AW13: 3 | AX13: 13 | AY13: 3 | AZ13: 0 | BA13: 0 | BB13: 13 | BC13: 3 | BD13: 13 | BE13: 3 | BF13: 0 | BG13: 0 | BH13: 0 | BI13: 0 | BJ13: 12 | BK13: 0 | BL13: 14 | BM13: 2
A14: Servicios EB-PU | D14: 0 | E14: 0 | F14: 1 | G14: 0 | H14: 1 | I14: 0 | J14: 1 | K14: 0 | L14: 1 | M14: 0 | N14: 1 | O14: 0 | P14: 0 | Q14: 0 | R14: 0 | S14: 0 | T14: 1 | U14: 0 | V14: 1 | W14: 0 | X14: 1 | Y14: 0 | Z14: 1 | AA14: 0 | AB14: 1 | AC14: 0 | AD14: 0 | AE14: 0 | AF14: 0 | AG14: 0 | AH14: 1 | AI14: 0 | AJ14: 1 | AK14: 0 | AL14: 1 | AM14: 0 | AN14: 1 | AO14: 0 | AP14: 1 | AQ14: 0 | AR14: 0 | AS14: 0 | AT14: 0 | AU14: 0 | AV14: 1 | AW14: 0 | AX14: 1 | AY14: 0 | AZ14: 0 | BA14: 0 | BB14: 1 | BC14: 0 | BD14: 1 | BE14: 0 | BF14: 0 | BG14: 0 | BH14: 0 | BI14: 0 | BJ14: 0 | BK14: 0 | BL14: 1 | BM14: 0
A15: Servicios LI-PU | D15: 25 | E15: 15 | F15: 32 | G15: 29 | H15: 32 | I15: 29 | J15: 32 | K15: 29 | L15: 32 | M15: 29 | N15: 33 | O15: 29 | P15: 75 | Q15: 0 | R15: 55 | S15: 2 | T15: 33 | U15: 28 | V15: 32 | W15: 29 | X15: 31 | Y15: 30 | Z15: 32 | AA15: 29 | AB15: 32 | AC15: 29 | AD15: 43 | AE15: 32 | AF15: 30 | AG15: 27 | AH15: 32 | AI15: 29 | AJ15: 31 | AK15: 30 | AL15: 32 | AM15: 29 | AN15: 32 | AO15: 29 | AP15: 32 | AQ15: 29 | AR15: 74 | AS15: 1 | AT15: 57 | AU15: 0 | AV15: 34 | AW15: 27 | AX15: 29 | AY15: 32 | AZ15: 57 | BA15: 0 | BB15: 32 | BC15: 29 | BD15: 32 | BE15: 29 | BF15: 75 | BG15: 0 | BH15: 57 | BI15: 0 | BJ15: 26 | BK15: 27 | BL15: 18 | BM15: 41
A16: Servicios MI-LI | BJ16: 2 | BK16: 1
A17: Servicios LI-MI | BJ17: 2 | BK17: 3
A18: Servicios LI-BA | BM18: 2
A19: Servicios PU-SA | D19: 0 | E19: 0 | F19: 7 | G19: 0 | H19: 7 | I19: 0 | J19: 7 | K19: 0 | L19: 7 | M19: 0 | N19: 7 | O19: 0 | P19: 0 | Q19: 0 | R19: 0 | S19: 0 | T19: 7 | U19: 0 | V19: 7 | W19: 0 | X19: 7 | Y19: 0 | Z19: 7 | AA19: 0 | AB19: 7 | AC19: 0 | AD19: 0 | AE19: 0 | AF19: 0 | AG19: 0 | AH19: 7 | AI19: 0 | AJ19: 7 | AK19: 0 | AL19: 7 | AM19: 0 | AN19: 7 | AO19: 0 | AP19: 7 | AQ19: 0 | AR19: 0 | AS19: 0 | AT19: 0 | AU19: 0 | AV19: 7 | AW19: 0 | AX19: 7 | AY19: 0 | AZ19: 0 | BA19: 0 | BB19: 7 | BC19: 0 | BD19: 7 | BE19: 0 | BF19: 0 | BG19: 0 | BH19: 0 | BI19: 0 | BJ19: 7 | BK19: 0 | BL19: 7 | BM19: 0
A20: Servicios PU-EB | D20: 0 | E20: 0 | F20: 0 | G20: 0 | H20: 0 | I20: 0 | J20: 0 | K20: 0 | L20: 0 | M20: 0 | N20: 0 | O20: 0 | P20: 0 | Q20: 0 | R20: 0 | S20: 0 | T20: 0 | U20: 0 | V20: 0 | W20: 0 | X20: 0 | Y20: 0 | Z20: 0 | AA20: 0 | AB20: 0 | AC20: 0 | AD20: 0 | AE20: 0 | AF20: 0 | AG20: 0 | AH20: 0 | AI20: 0 | AJ20: 0 | AK20: 0 | AL20: 0 | AM20: 0 | AN20: 0 | AO20: 0 | AP20: 0 | AQ20: 0 | AR20: 0 | AS20: 0 | AT20: 0 | AU20: 0 | AV20: 0 | AW20: 0 | AX20: 0 | AY20: 0 | AZ20: 0 | BA20: 0 | BB20: 0 | BC20: 0 | BD20: 0 | BE20: 0 | BF20: 0 | BG20: 0 | BH20: 0 | BI20: 0 | BJ20: 0 | BK20: 0 | BL20: 0 | BM20: 0
A21: Servicios PU-LI | D21: 0 | E21: 0 | F21: 2 | G21: 6 | H21: 2 | I21: 6 | J21: 2 | K21: 6 | L21: 2 | M21: 6 | N21: 2 | O21: 6 | P21: 0 | Q21: 0 | R21: 0 | S21: 0 | T21: 3 | U21: 5 | V21: 2 | W21: 6 | X21: 2 | Y21: 6 | Z21: 2 | AA21: 6 | AB21: 2 | AC21: 6 | AD21: 0 | AE21: 0 | AF21: 0 | AG21: 0 | AH21: 2 | AI21: 6 | AJ21: 2 | AK21: 6 | AL21: 2 | AM21: 6 | AN21: 2 | AO21: 6 | AP21: 2 | AQ21: 6 | AR21: 0 | AS21: 0 | AT21: 0 | AU21: 0 | AV21: 2 | AW21: 6 | AX21: 7 | AY21: 1 | AZ21: 0 | BA21: 0 | BB21: 3 | BC21: 5 | BD21: 2 | BE21: 6 | BF21: 0 | BG21: 0 | BH21: 0 | BI21: 0 | BJ21: 3 | BK21: 5 | BL21: 7 | BM21: 1
A22: Servicios SA-PU | D22: 0 | E22: 0 | F22: 6 | G22: 0 | H22: 6 | I22: 0 | J22: 6 | K22: 0 | L22: 6 | M22: 0 | N22: 6 | O22: 0 | P22: 0 | Q22: 0 | R22: 0 | S22: 0 | T22: 6 | U22: 0 | V22: 6 | W22: 0 | X22: 6 | Y22: 0 | Z22: 6 | AA22: 0 | AB22: 6 | AC22: 0 | AD22: 0 | AE22: 0 | AF22: 0 | AG22: 0 | AH22: 6 | AI22: 0 | AJ22: 6 | AK22: 0 | AL22: 6 | AM22: 0 | AN22: 6 | AO22: 0 | AP22: 6 | AQ22: 0 | AR22: 0 | AS22: 0 | AT22: 0 | AU22: 0 | AV22: 6 | AW22: 0 | AX22: 6 | AY22: 0 | AZ22: 0 | BA22: 0 | BB22: 6 | BC22: 0 | BD22: 6 | BE22: 0 | BF22: 0 | BG22: 0 | BH22: 0 | BI22: 0 | BJ22: 6 | BK22: 0 | BL22: 6 | BM22: 0
A23: Servicios EB-PU | D23: 0 | E23: 0 | F23: 0 | G23: 0 | H23: 0 | I23: 0 | J23: 0 | K23: 0 | L23: 0 | M23: 0 | N23: 0 | O23: 0 | P23: 0 | Q23: 0 | R23: 0 | S23: 0 | T23: 0 | U23: 0 | V23: 0 | W23: 0 | X23: 0 | Y23: 0 | Z23: 0 | AA23: 0 | AB23: 0 | AC23: 0 | AD23: 0 | AE23: 0 | AF23: 0 | AG23: 0 | AH23: 0 | AI23: 0 | AJ23: 0 | AK23: 0 | AL23: 0 | AM23: 0 | AN23: 0 | AO23: 0 | AP23: 0 | AQ23: 0 | AR23: 0 | AS23: 0 | AT23: 0 | AU23: 0 | AV23: 0 | AW23: 0 | AX23: 0 | AY23: 0 | AZ23: 0 | BA23: 0 | BB23: 0 | BC23: 0 | BD23: 0 | BE23: 0 | BF23: 0 | BG23: 0 | BH23: 0 | BI23: 0 | BJ23: 0 | BK23: 0 | BL23: 0 | BM23: 0
A24: Servicios LI-PU | D24: 0 | E24: 0 | F24: 5 | G24: 2 | H24: 5 | I24: 2 | J24: 5 | K24: 2 | L24: 5 | M24: 2 | N24: 5 | O24: 2 | P24: 0 | Q24: 0 | R24: 0 | S24: 0 | T24: 5 | U24: 2 | V24: 5 | W24: 2 | X24: 5 | Y24: 2 | Z24: 5 | AA24: 2 | AB24: 5 | AC24: 2 | AD24: 0 | AE24: 0 | AF24: 0 | AG24: 0 | AH24: 5 | AI24: 2 | AJ24: 5 | AK24: 2 | AL24: 5 | AM24: 2 | AN24: 5 | AO24: 2 | AP24: 5 | AQ24: 2 | AR24: 0 | AS24: 0 | AT24: 0 | AU24: 0 | AV24: 5 | AW24: 2 | AX24: 5 | AY24: 2 | AZ24: 0 | BA24: 0 | BB24: 5 | BC24: 2 | BD24: 5 | BE24: 2 | BF24: 0 | BG24: 0 | BH24: 0 | BI24: 0 | BJ24: 5 | BK24: 2 | BL24: 3 | BM24: 4
D27: =SUM(D3:D24) -> 48 | E27: =SUM(E3:E24) -> 31 | F27: =SUM(F3:F24) -> 138 | G27: =SUM(G3:G24) -> 85 | H27: =SUM(H3:H24) -> 140 | I27: =SUM(I3:I24) -> 83 | J27: =SUM(J3:J24) -> 140 | K27: =SUM(K3:K24) -> 83 | ... BM27: =SUM(BM3:BM24) -> 107
A33: Km Servicio
A34: PU - LI | D34: =D5+D12+D21 -> 23 | E34: =E5+E12+E21 -> 16 | F34: =F5+F12+F21 -> 41 | G34: =G5+G12+G21 -> 38 | H34: =H5+H12+H21 -> 42 | I34: =I5+I12+I21 -> 37 | J34: =J5+J12+J21 -> 42 | K34: =K5+K12+K21 -> 37 | ... BM34: =BM5+BM12+BM21 -> 50
A35: LI - PU | D35: =D8+D15+D24 -> 25 | E35: =E8+E15+E24 -> 15 | F35: =F8+F15+F24 -> 39 | G35: =G8+G15+G24 -> 39 | H35: =H8+H15+H24 -> 40 | I35: =I8+I15+I24 -> 38 | J35: =J8+J15+J24 -> 40 | K35: =K8+K15+K24 -> 38 | ... BM35: =BM8+BM15+BM24 -> 51
A36: PU - SA | D36: =D3+D10+D19 -> 0 | E36: =E3+E10+E19 -> 0 | F36: =F3+F10+F19 -> 29 | G36: =G3+G10+G19 -> 4 | H36: =H3+H10+H19 -> 29 | I36: =I3+I10+I19 -> 4 | J36: =J3+J10+J19 -> 29 | K36: =K3+K10+K19 -> 4 | ... BM36: =BM3+BM10+BM19 -> 2
A37: SA - PU | D37: =D6+D13+D22 -> 0 | E37: =E6+E13+E22 -> 0 | F37: =F6+F13+F22 -> 28 | G37: =G6+G13+G22 -> 4 | H37: =H6+H13+H22 -> 28 | I37: =I6+I13+I22 -> 4 | J37: =J6+J13+J22 -> 28 | K37: =K6+K13+K22 -> 4 | ... BM37: =BM6+BM13+BM22 -> 2
A38: PU-EB | D38: =D4+D11+D20 -> 0 | E38: =E4+E11+E20 -> 0 | F38: =F4+F11+F20 -> 0 | G38: =G4+G11+G20 -> 0 | H38: =H4+H11+H20 -> 0 | I38: =I4+I11+I20 -> 0 | J38: =J4+J11+J20 -> 0 | K38: =K4+K11+K20 -> 0 | ... BM38: =BM4+BM11+BM20 -> 0
A39: EB-PU | D39: =D7+D14+D23 -> 0 | E39: =E7+E14+E23 -> 0 | F39: =F7+F14+F23 -> 1 | G39: =G7+G14+G23 -> 0 | H39: =H7+H14+H23 -> 1 | I39: =I7+I14+I23 -> 0 | J39: =J7+J14+J23 -> 1 | K39: =K7+K14+K23 -> 0 | ... BM39: =BM7+BM14+BM23 -> 0
A40: MI-LI | BJ40: =BJ16 -> 2 | BK40: =BK16 -> 1
A41: LI-MI | BJ41: =BJ17 -> 2 | BK41: =BK17 -> 3
A42: LI-BA | BM42: =BM18 -> 2
A43: total | D43: =SUM(D34:D39) -> 48 | E43: =SUM(E34:E39) -> 31 | F43: =SUM(F34:F39) -> 138 | G43: =SUM(G34:G39) -> 85 | H43: =SUM(H34:H39) -> 140 | I43: =SUM(I34:I39) -> 83 | J43: =SUM(J34:J39) -> 140 | K43: =SUM(K34:K39) -> 83 | ... BI43: =SUM(BI34:BI39) -> 3 | BJ43: =SUM(BJ34:BJ41) -> 111 | BK43: =SUM(BK34:BK41) -> 80 | BL43: =SUM(BL34:BL39) -> 116 | BM43: =SUM(BM34:BM42) -> 107
A45: Servicios
A46: PU - LI | D46: =D5+E5+D12+E12+D21+E21 -> 39 | F46: =F5+G5+F12+G12+F21+G21 -> 79 | H46: =H5+I5+H12+I12+H21+I21 -> 79 | J46: =J5+K5+J12+K12+J21+K21 -> 79 | L46: =L5+M5+L12+M12+L21+M21 -> 79 | N46: =N5+O5+N12+O12+N21+O21 -> 79 | P46: =P5+Q5+P12+Q12+P21+Q21 -> 72 | R46: =R5+S5+R12+S12+R21+S21 -> 54 | T46: =T5+U5+T12+U12+T21+U21 -> 79 | V46: =V5+W5+V12+W12+V21+W21 -> 79 | X46: =X5+Y5+X12+Y12+X21+Y21 -> 79 | Z46: =Z5+AA5+Z12+AA12+Z21+AA21 -> 79 | AB46: =AB5+AC5+AB12+AC12+AB21+AC21 -> 79 | AD46: =AD5+AE5+AD12+AE12+AD21+AE21 -> 73 | AF46: =AF5+AG5+AF12+AG12+AF21+AG21 -> 55 | AH46: =AH5+AI5+AH12+AI12+AH21+AI21 -> 79 | AJ46: =AJ5+AK5+AJ12+AK12+AJ21+AK21 -> 79 | AL46: =AL5+AM5+AL12+AM12+AL21+AM21 -> 79 | AN46: =AN5+AO5+AN12+AO12+AN21+AO21 -> 79 | AP46: =AP5+AQ5+AP12+AQ12+AP21+AQ21 -> 79 | AR46: =AR5+AS5+AR12+AS12+AR21+AS21 -> 72 | AT46: =AT5+AU5+AT12+AU12+AT21+AU21 -> 54 | AV46: =AV5+AW5+AV12+AW12+AV21+AW21 -> 79 | AX46: =AX5+AY5+AX12+AY12+AX21+AY21 -> 79 | AZ46: =AZ5+BA5+AZ12+BA12+AZ21+BA21 -> 54 | BB46: =BB5+BC5+BB12+BC12+BB21+BC21 -> 79 | BD46: =BD5+BE5+BD12+BE12+BD21+BE21 -> 79 | BF46: =BF5+BG5+BF12+BG12+BF21+BG21 -> 72 | BH46: =BH5+BI5+BH12+BI12+BH21+BI21 -> 54 | BJ46: =BJ5+BK5+BJ12+BK12+BJ21+BK21 -> 70 | BL46: =BL5+BM5+BL12+BM12+BL21+BM21 -> 79
A47: LI - PU | D47: =D8+E8+D15+E15+D24+E24 -> 40 | F47: =F8+G8+F15+G15+F24+G24 -> 78 | H47: =H8+I8+H15+I15+H24+I24 -> 78 | J47: =J8+K8+J15+K15+J24+K24 -> 78 | L47: =L8+M8+L15+M15+L24+M24 -> 78 | N47: =N8+O8+N15+O15+N24+O24 -> 79 | P47: =P8+Q8+P15+Q15+P24+Q24 -> 75 | R47: =R8+S8+R15+S15+R24+S24 -> 57 | T47: =T8+U8+T15+U15+T24+U24 -> 78 | V47: =V8+W8+V15+W15+V24+W24 -> 78 | X47: =X8+Y8+X15+Y15+X24+Y24 -> 78 | Z47: =Z8+AA8+Z15+AA15+Z24+AA24 -> 78 | AB47: =AB8+AC8+AB15+AC15+AB24+AC24 -> 78 | AD47: =AD8+AE8+AD15+AE15+AD24+AE24 -> 75 | AF47: =AF8+AG8+AF15+AG15+AF24+AG24 -> 57 | AH47: =AH8+AI8+AH15+AI15+AH24+AI24 -> 78 | AJ47: =AJ8+AK8+AJ15+AK15+AJ24+AK24 -> 78 | AL47: =AL8+AM8+AL15+AM15+AL24+AM24 -> 78 | AN47: =AN8+AO8+AN15+AO15+AN24+AO24 -> 78 | AP47: =AP8+AQ8+AP15+AQ15+AP24+AQ24 -> 78 | AR47: =AR8+AS8+AR15+AS15+AR24+AS24 -> 75 | AT47: =AT8+AU8+AT15+AU15+AT24+AU24 -> 57 | AV47: =AV8+AW8+AV15+AW15+AV24+AW24 -> 78 | AX47: =AX8+AY8+AX15+AY15+AX24+AY24 -> 78 | AZ47: =AZ8+BA8+AZ15+BA15+AZ24+BA24 -> 57 | BB47: =BB8+BC8+BB15+BC15+BB24+BC24 -> 78 | BD47: =BD8+BE8+BD15+BE15+BD24+BE24 -> 78 | BF47: =BF8+BG8+BF15+BG15+BF24+BG24 -> 75 | BH47: =BH8+BI8+BH15+BI15+BH24+BI24 -> 57 | BJ47: =BJ8+BK8+BJ15+BK15+BJ24+BK24 -> 69 | BL47: =BL8+BM8+BL15+BM15+BL24+BM24 -> 76
A48: PU - SA | D48: =D3+E3+D10+E10+D19+E19 -> 0 | F48: =F3+G3+F10+G10+F19+G19 -> 33 | H48: =H3+I3+H10+I10+H19+I19 -> 33 | J48: =J3+K3+J10+K10+J19+K19 -> 33 | L48: =L3+M3+L10+M10+L19+M19 -> 33 | N48: =N3+O3+N10+O10+N19+O19 -> 33 | P48: =P3+Q3+P10+Q10+P19+Q19 -> 0 | R48: =R3+S3+R10+S10+R19+S19 -> 0 | T48: =T3+U3+T10+U10+T19+U19 -> 33 | V48: =V3+W3+V10+W10+V19+W19 -> 33 | X48: =X3+Y3+X10+Y10+X19+Y19 -> 33 | Z48: =Z3+AA3+Z10+AA10+Z19+AA19 -> 33 | AB48: =AB3+AC3+AB10+AC10+AB19+AC19 -> 33 | AD48: =AD3+AE3+AD10+AE10+AD19+AE19 -> 0 | AF48: =AF3+AG3+AF10+AG10+AF19+AG19 -> 0 | AH48: =AH3+AI3+AH10+AI10+AH19+AI19 -> 33 | AJ48: =AJ3+AK3+AJ10+AK10+AJ19+AK19 -> 33 | AL48: =AL3+AM3+AL10+AM10+AL19+AM19 -> 33 | AN48: =AN3+AO3+AN10+AO10+AN19+AO19 -> 33 | AP48: =AP3+AQ3+AP10+AQ10+AP19+AQ19 -> 32 | AR48: =AR3+AS3+AR10+AS10+AR19+AS19 -> 0 | AT48: =AT3+AU3+AT10+AU10+AT19+AU19 -> 0 | AV48: =AV3+AW3+AV10+AW10+AV19+AW19 -> 33 | AX48: =AX3+AY3+AX10+AY10+AX19+AY19 -> 33 | AZ48: =AZ3+BA3+AZ10+BA10+AZ19+BA19 -> 0 | BB48: =BB3+BC3+BB10+BC10+BB19+BC19 -> 33 | BD48: =BD3+BE3+BD10+BE10+BD19+BE19 -> 33 | BF48: =BF3+BG3+BF10+BG10+BF19+BG19 -> 0 | BH48: =BH3+BI3+BH10+BI10+BH19+BI19 -> 0 | BJ48: =BJ3+BK3+BJ10+BK10+BJ19+BK19 -> 22 | BL48: =BL3+BM3+BL10+BM10+BL19+BM19 -> 33
A49: SA - PU | D49: =D6+E6+D13+E13+D22+E22 -> 0 | F49: =F6+G6+F13+G13+F22+G22 -> 32 | H49: =H6+I6+H13+I13+H22+I22 -> 32 | J49: =J6+K6+J13+K13+J22+K22 -> 32 | L49: =L6+M6+L13+M13+L22+M22 -> 32 | N49: =N6+O6+N13+O13+N22+O22 -> 32 | P49: =P6+Q6+P13+Q13+P22+Q22 -> 0 | R49: =R6+S6+R13+S13+R22+S22 -> 0 | T49: =T6+U6+T13+U13+T22+U22 -> 31 | V49: =V6+W6+V13+W13+V22+W22 -> 32 | X49: =X6+Y6+X13+Y13+X22+Y22 -> 32 | Z49: =Z6+AA6+Z13+AA13+Z22+AA22 -> 32 | AB49: =AB6+AC6+AB13+AC13+AB22+AC22 -> 32 | AD49: =AD6+AE6+AD13+AE13+AD22+AE22 -> 0 | AF49: =AF6+AG6+AF13+AG13+AF22+AG22 -> 0 | AH49: =AH6+AI6+AH13+AI13+AH22+AI22 -> 32 | AJ49: =AJ6+AK6+AJ13+AK13+AJ22+AK22 -> 32 | AL49: =AL6+AM6+AL13+AM13+AL22+AM22 -> 32 | AN49: =AN6+AO6+AN13+AO13+AN22+AO22 -> 32 | AP49: =AP6+AQ6+AP13+AQ13+AP22+AQ22 -> 32 | AR49: =AR6+AS6+AR13+AS13+AR22+AS22 -> 0 | AT49: =AT6+AU6+AT13+AU13+AT22+AU22 -> 0 | AV49: =AV6+AW6+AV13+AW13+AV22+AW22 -> 32 | AX49: =AX6+AY6+AX13+AY13+AX22+AY22 -> 32 | AZ49: =AZ6+BA6+AZ13+BA13+AZ22+BA22 -> 0 | BB49: =BB6+BC6+BB13+BC13+BB22+BC22 -> 32 | BD49: =BD6+BE6+BD13+BE13+BD22+BE22 -> 32 | BF49: =BF6+BG6+BF13+BG13+BF22+BG22 -> 0 | BH49: =BH6+BI6+BH13+BI13+BH22+BI22 -> 0 | BJ49: =BJ6+BK6+BJ13+BK13+BJ22+BK22 -> 22 | BL49: =BL6+BM6+BL13+BM13+BL22+BM22 -> 32
...

Sheet Oferta Diaria
A1: Oferta Diciembre 2024
C3: 45627 | D3: 45628 | E3: 45629 | F3: 45630 | G3: 45631 | H3: 45632 | I3: 45633 | J3: 45634 | K3: 45635 | L3: 45636 | M3: 45637 | N3: 45638 | O3: 45639 | P3: 45640 | Q3: 45641 | R3: 45642 | S3: 45643 | T3: 45644 | U3: 45645 | V3: 45646 | W3: 45647 | X3: 45648 | Y3: 45649 | Z3: 45650 | AA3: 45651 | AB3: 45652 | AC3: 45653 | AD3: 45654 | AE3: 45655 | AF3: 45656 | AG3: 45657
A4: HÁBIL | B4: km
A5: Servicios PU-LI | B5: 43.13 | C5: ='Data Ocupacion'!D46 -> 39 | D5: ='Data Ocupacion'!F46 -> 79 | E5: ='Data Ocupacion'!H46 -> 79 | F5: ='Data Ocupacion'!J46 -> 79 | G5: ='Data Ocupacion'!L46 -> 79 | H5: ='Data Ocupacion'!N46 -> 79 | I5: ='Data Ocupacion'!P46 -> 72 | J5: ='Data Ocupacion'!R46 -> 54 | K5: ='Data Ocupacion'!T46 -> 79 | L5: ='Data Ocupacion'!V46 -> 79 | M5: ='Data Ocupacion'!X46 -> 79 | N5: ='Data Ocupacion'!Z46 -> 79 | O5: ='Data Ocupacion'!AB46 -> 79 | P5: ='Data Ocupacion'!AD46 -> 73 | Q5: ='Data Ocupacion'!AF46 -> 55 | R5: ='Data Ocupacion'!AH46 -> 79 | S5: ='Data Ocupacion'!AJ46 -> 79 | T5: ='Data Ocupacion'!AL46 -> 79 | U5: ='Data Ocupacion'!AN46 -> 79 | V5: ='Data Ocupacion'!AP46 -> 79 | W5: ='Data Ocupacion'!AR46 -> 72 | X5: ='Data Ocupacion'!AT46 -> 54 | Y5: ='Data Ocupacion'!AV46 -> 79 | Z5: ='Data Ocupacion'!AX46 -> 79 | AA5: ='Data Ocupacion'!AZ46 -> 54 | AB5: ='Data Ocupacion'!BB46 -> 79 | AC5: ='Data Ocupacion'!BD46 -> 79 | AD5: ='Data Ocupacion'!BF46 -> 72 | AE5: ='Data Ocupacion'!BH46 -> 54 | AF5: ='Data Ocupacion'!BJ46 -> 70 | AG5: ='Data Ocupacion'!BL46 -> 79
A6: Servicios LI-PU | B6: 43.13 | C6: ='Data Ocupacion'!D47 -> 40 | D6: ='Data Ocupacion'!F47 -> 78 | E6: ='Data Ocupacion'!H47 -> 78 | F6: ='Data Ocupacion'!J47 -> 78 | G6: ='Data Ocupacion'!L47 -> 78 | H6: ='Data Ocupacion'!N47 -> 79 | I6: ='Data Ocupacion'!P47 -> 75 | J6: ='Data Ocupacion'!R47 -> 57 | K6: ='Data Ocupacion'!T47 -> 78 | L6: ='Data Ocupacion'!V47 -> 78 | M6: ='Data Ocupacion'!X47 -> 78 | N6: ='Data Ocupacion'!Z47 -> 78 | O6: ='Data Ocupacion'!AB47 -> 78 | P6: ='Data Ocupacion'!AD47 -> 75 | Q6: ='Data Ocupacion'!AF47 -> 57 | R6: ='Data Ocupacion'!AH47 -> 78 | S6: ='Data Ocupacion'!AJ47 -> 78 | T6: ='Data Ocupacion'!AL47 -> 78 | U6: ='Data Ocupacion'!AN47 -> 78 | V6: ='Data Ocupacion'!AP47 -> 78 | W6: ='Data Ocupacion'!AR47 -> 75 | X6: ='Data Ocupacion'!AT47 -> 57 | Y6: ='Data Ocupacion'!AV47 -> 78 | Z6: ='Data Ocupacion'!AX47 -> 78 | AA6: ='Data Ocupacion'!AZ47 -> 57 | AB6: ='Data Ocupacion'!BB47 -> 78 | AC6: ='Data Ocupacion'!BD47 -> 78 | AD6: ='Data Ocupacion'!BF47 -> 75 | AE6: ='Data Ocupacion'!BH47 -> 57 | AF6: ='Data Ocupacion'!BJ47 -> 69 | AG6: ='Data Ocupacion'!BL47 -> 76
A7: Servicios PU-SA | B7: 29.11 | C7: ='Data Ocupacion'!D48 -> 0 | D7: ='Data Ocupacion'!F48 -> 33 | E7: ='Data Ocupacion'!H48 -> 33 | F7: ='Data Ocupacion'!J48 -> 33 | G7: ='Data Ocupacion'!L48 -> 33 | H7: ='Data Ocupacion'!N48 -> 33 | I7: ='Data Ocupacion'!P48 -> 0 | J7: ='Data Ocupacion'!R48 -> 0 | K7: ='Data Ocupacion'!T48 -> 33 | L7: ='Data Ocupacion'!V48 -> 33 | M7: ='Data Ocupacion'!X48 -> 33 | N7: ='Data Ocupacion'!Z48 -> 33 | O7: ='Data Ocupacion'!AB48 -> 33 | P7: ='Data Ocupacion'!AD48 -> 0 | Q7: ='Data Ocupacion'!AF48 -> 0 | R7: ='Data Ocupacion'!AH48 -> 33 | S7: ='Data Ocupacion'!AJ48 -> 33 | T7: ='Data Ocupacion'!AL48 -> 33 | U7: ='Data Ocupacion'!AN48 -> 33 | V7: ='Data Ocupacion'!AP48 -> 32 | W7: ='Data Ocupacion'!AR48 -> 0 | X7: ='Data Ocupacion'!AT48 -> 0 | Y7: ='Data Ocupacion'!AV48 -> 33 | Z7: ='Data Ocupacion'!AX48 -> 33 | AA7: ='Data Ocupacion'!AZ48 -> 0 | AB7: ='Data Ocupacion'!BB48 -> 33 | AC7: ='Data Ocupacion'!BD48 -> 33 | AD7: ='Data Ocupacion'!BF48 -> 0 | AE7: ='Data Ocupacion'!BH48 -> 0 | AF7: ='Data Ocupacion'!BJ48 -> 22 | AG7: ='Data Ocupacion'!BL48 -> 33
A8: Servicios SA-PU | B8: 29.11 | C8: ='Data Ocupacion'!D49 -> 0 | D8: ='Data Ocupacion'!F49 -> 32 | E8: ='Data Ocupacion'!H49 -> 32 | F8: ='Data Ocupacion'!J49 -> 32 | G8: ='Data Ocupacion'!L49 -> 32 | H8: ='Data Ocupacion'!N49 -> 32 | I8: ='Data Ocupacion'!P49 -> 0 | J8: ='Data Ocupacion'!R49 -> 0 | K8: ='Data Ocupacion'!T49 -> 31 | L8: ='Data Ocupacion'!V49 -> 32 | M8: ='Data Ocupacion'!X49 -> 32 | N8: ='Data Ocupacion'!Z49 -> 32 | O8: ='Data Ocupacion'!AB49 -> 32 | P8: ='Data Ocupacion'!AD49 -> 0 | Q8: ='Data Ocupacion'!AF49 -> 0 | R8: ='Data Ocupacion'!AH49 -> 32 | S8: ='Data Ocupacion'!AJ49 -> 32 | T8: ='Data Ocupacion'!AL49 -> 32 | U8: ='Data Ocupacion'!AN49 -> 32 | V8: ='Data Ocupacion'!AP49 -> 32 | W8: ='Data Ocupacion'!AR49 -> 0 | X8: ='Data Ocupacion'!AT49 -> 0 | Y8: ='Data Ocupacion'!AV49 -> 32 | Z8: ='Data Ocupacion'!AX49 -> 32 | AA8: ='Data Ocupacion'!AZ49 -> 0 | AB8: ='Data Ocupacion'!BB49 -> 32 | AC8: ='Data Ocupacion'!BD49 -> 32 | AD8: ='Data Ocupacion'!BF49 -> 0 | AE8: ='Data Ocupacion'!BH49 -> 0 | AF8: ='Data Ocupacion'!BJ49 -> 22 | AG8: ='Data Ocupacion'!BL49 -> 32
A9: Servicios PU-EB | B9: 25.4 | C9: ='Data Ocupacion'!D50 -> 0 | D9: ='Data Ocupacion'!F50 -> 0 | E9: ='Data Ocupacion'!H50 -> 0 | F9: ='Data Ocupacion'!J50 -> 0 | G9: ='Data Ocupacion'!L50 -> 0 | H9: ='Data Ocupacion'!N50 -> 0 | I9: ='Data Ocupacion'!P50 -> 0 | J9: ='Data Ocupacion'!R50 -> 0 | K9: ='Data Ocupacion'!T50 -> 0 | L9: ='Data Ocupacion'!V50 -> 0 | M9: ='Data Ocupacion'!X50 -> 0 | N9: ='Data Ocupacion'!Z50 -> 0 | O9: ='Data Ocupacion'!AB50 -> 0 | P9: ='Data Ocupacion'!AD50 -> 0 | Q9: ='Data Ocupacion'!AF50 -> 0 | R9: ='Data Ocupacion'!AH50 -> 0 | S9: ='Data Ocupacion'!AJ50 -> 0 | T9: ='Data Ocupacion'!AL50 -> 0 | U9: ='Data Ocupacion'!AN50 -> 0 | V9: ='Data Ocupacion'!AP50 -> 0 | W9: ='Data Ocupacion'!AR50 -> 0 | X9: ='Data Ocupacion'!AT50 -> 0 | Y9: ='Data Ocupacion'!AV50 -> 0 | Z9: ='Data Ocupacion'!AX50 -> 0 | AA9: ='Data Ocupacion'!AZ50 -> 0 | AB9: ='Data Ocupacion'!BB50 -> 0 | AC9: ='Data Ocupacion'!BD50 -> 0 | AD9: ='Data Ocupacion'!BF50 -> 0 | AE9: ='Data Ocupacion'!BH50 -> 0 | AF9: ='Data Ocupacion'!BJ50 -> 0 | AG9: ='Data Ocupacion'!BL50 -> 0
A10: Servicios EB-PU | B10: 25.4 | C10: ='Data Ocupacion'!D51 -> 0 | D10: ='Data Ocupacion'!F51 -> 1 | E10: ='Data Ocupacion'!H51 -> 1 | F10: ='Data Ocupacion'!J51 -> 1 | G10: ='Data Ocupacion'!L51 -> 1 | H10: ='Data Ocupacion'!N51 -> 1 | I10: ='Data Ocupacion'!P51 -> 0 | J10: ='Data Ocupacion'!R51 -> 0 | K10: ='Data Ocupacion'!T51 -> 1 | L10: ='Data Ocupacion'!V51 -> 1 | M10: ='Data Ocupacion'!X51 -> 1 | N10: ='Data Ocupacion'!Z51 -> 1 | O10: ='Data Ocupacion'!AB51 -> 1 | P10: ='Data Ocupacion'!AD51 -> 0 | Q10: ='Data Ocupacion'!AF51 -> 0 | R10: ='Data Ocupacion'!AH51 -> 1 | S10: ='Data Ocupacion'!AJ51 -> 1 | T10: ='Data Ocupacion'!AL51 -> 1 | U10: ='Data Ocupacion'!AN51 -> 1 | V10: ='Data Ocupacion'!AP51 -> 1 | W10: ='Data Ocupacion'!AR51 -> 0 | X10: ='Data Ocupacion'!AT51 -> 0 | Y10: ='Data Ocupacion'!AV51 -> 1 | Z10: ='Data Ocupacion'!AX51 -> 1 | AA10: ='Data Ocupacion'!AZ51 -> 0 | AB10: ='Data Ocupacion'!BB51 -> 1 | AC10: ='Data Ocupacion'!BD51 -> 1 | AD10: ='Data Ocupacion'!BF51 -> 0 | AE10: ='Data Ocupacion'!BH51 -> 0 | AF10: ='Data Ocupacion'!BJ51 -> 0 | AG10: ='Data Ocupacion'!BL51 -> 1
A11: Servicios MI-LI | B11: 35.73 | AF11: ='Data Ocupacion'!BJ52 -> 3
A12: Servicios LI-MI | B12: 35.73 | AF12: ='Data Ocupacion'!BJ53 -> 5
A13: Servicios LI-BA | B13: 39.4 | AG13: ='Data Ocupacion'!BL54 -> 2
A15: Trenes PU-LI | B15: 43.13 | C15: ='Data Ocupacion'!D56 -> 55 | D15: ='Data Ocupacion'!F56 -> 117 | E15: ='Data Ocupacion'!H56 -> 116 | F15: ='Data Ocupacion'!J56 -> 116 | G15: ='Data Ocupacion'!L56 -> 116 | H15: ='Data Ocupacion'!N56 -> 115 | I15: ='Data Ocupacion'!P56 -> 75 | J15: ='Data Ocupacion'!R56 -> 59 | K15: ='Data Ocupacion'!T56 -> 114 | L15: ='Data Ocupacion'!V56 -> 115 | M15: ='Data Ocupacion'!X56 -> 116 | N15: ='Data Ocupacion'!Z56 -> 115 | O15: ='Data Ocupacion'!AB56 -> 117 | P15: ='Data Ocupacion'!AD56 -> 107 | Q15: ='Data Ocupacion'!AF56 -> 87 | R15: ='Data Ocupacion'!AH56 -> 116 | S15: ='Data Ocupacion'!AJ56 -> 116 | T15: ='Data Ocupacion'!AL56 -> 114 | U15: ='Data Ocupacion'!AN56 -> 115 | V15: ='Data Ocupacion'!AP56 -> 114 | W15: ='Data Ocupacion'!AR56 -> 76 | X15: ='Data Ocupacion'!AT56 -> 57 | Y15: ='Data Ocupacion'!AV56 -> 113 | Z15: ='Data Ocupacion'!AX56 -> 118 | AA15: ='Data Ocupacion'!AZ56 -> 57 | AB15: ='Data Ocupacion'!BB56 -> 116 | AC15: ='Data Ocupacion'!BD56 -> 115 | AD15: ='Data Ocupacion'!BF56 -> 75 | AE15: ='Data Ocupacion'!BH56 -> 57 | AF15: ='Data Ocupacion'!BJ56 -> 106 | AG15: ='Data Ocupacion'!BL56 -> 129
A16: Trenes LI-PU | B16: 43.13 | C16: ='Data Ocupacion'!D57 -> 55 | D16: ='Data Ocupacion'!F57 -> 117 | E16: ='Data Ocupacion'!H57 -> 116 | F16: ='Data Ocupacion'!J57 -> 116 | G16: ='Data Ocupacion'!L57 -> 116 | H16: ='Data Ocupacion'!N57 -> 117 | I16: ='Data Ocupacion'!P57 -> 75 | J16: ='Data Ocupacion'!R57 -> 59 | K16: ='Data Ocupacion'!T57 -> 114 | L16: ='Data Ocupacion'!V57 -> 115 | M16: ='Data Ocupacion'!X57 -> 116 | N16: ='Data Ocupacion'!Z57 -> 115 | O16: ='Data Ocupacion'!AB57 -> 115 | P16: ='Data Ocupacion'!AD57 -> 107 | Q16: ='Data Ocupacion'!AF57 -> 84 | R16: ='Data Ocupacion'!AH57 -> 116 | S16: ='Data Ocupacion'!AJ57 -> 116 | T16: ='Data Ocupacion'!AL57 -> 114 | U16: ='Data Ocupacion'!AN57 -> 115 | V16: ='Data Ocupacion'!AP57 -> 114 | W16: ='Data Ocupacion'!AR57 -> 76 | X16: ='Data Ocupacion'!AT57 -> 57 | Y16: ='Data Ocupacion'!AV57 -> 113 | Z16: ='Data Ocupacion'!AX57 -> 118 | AA16: ='Data Ocupacion'!AZ57 -> 57 | AB16: ='Data Ocupacion'!BB57 -> 116 | AC16: ='Data Ocupacion'!BD57 -> 115 | AD16: ='Data Ocupacion'!BF57 -> 75 | AE16: ='Data Ocupacion'!BH57 -> 57 | AF16: ='Data Ocupacion'!BJ57 -> 105 | AG16: ='Data Ocupacion'!BL57 -> 127
A17: Trenes PU-SA | B17: 29.11 | C17: ='Data Ocupacion'!D58 -> 0 | D17: ='Data Ocupacion'!F58 -> 37 | E17: ='Data Ocupacion'!H58 -> 37 | F17: ='Data Ocupacion'!J58 -> 37 | G17: ='Data Ocupacion'!L58 -> 37 | H17: ='Data Ocupacion'!N58 -> 37 | I17: ='Data Ocupacion'!P58 -> 0 | J17: ='Data Ocupacion'!R58 -> 0 | K17: ='Data Ocupacion'!T58 -> 36 | L17: ='Data Ocupacion'!V58 -> 37 | M17: ='Data Ocupacion'!X58 -> 37 | N17: ='Data Ocupacion'!Z58 -> 36 | O17: ='Data Ocupacion'!AB58 -> 37 | P17: ='Data Ocupacion'!AD58 -> 0 | Q17: ='Data Ocupacion'!AF58 -> 0 | R17: ='Data Ocupacion'!AH58 -> 36 | S17: ='Data Ocupacion'!AJ58 -> 37 | T17: ='Data Ocupacion'!AL58 -> 37 | U17: ='Data Ocupacion'!AN58 -> 37 | V17: ='Data Ocupacion'!AP58 -> 36 | W17: ='Data Ocupacion'!AR58 -> 0 | X17: ='Data Ocupacion'!AT58 -> 0 | Y17: ='Data Ocupacion'!AV58 -> 36 | Z17: ='Data Ocupacion'!AX58 -> 37 | AA17: ='Data Ocupacion'!AZ58 -> 0 | AB17: ='Data Ocupacion'!BB58 -> 36 | AC17: ='Data Ocupacion'!BD58 -> 37 | AD17: ='Data Ocupacion'!BF58 -> 0 | AE17: ='Data Ocupacion'!BH58 -> 0 | AF17: ='Data Ocupacion'!BJ58 -> 24 | AG17: ='Data Ocupacion'!BL58 -> 35
A18: Trenes SA-PU | B18: 29.11 | C18: ='Data Ocupacion'!D59 -> 0 | D18: ='Data Ocupacion'!F59 -> 36 | E18: ='Data Ocupacion'!H59 -> 36 | F18: ='Data Ocupacion'!J59 -> 36 | G18: ='Data Ocupacion'!L59 -> 36 | H18: ='Data Ocupacion'!N59 -> 36 | I18: ='Data Ocupacion'!P59 -> 0 | J18: ='Data Ocupacion'!R59 -> 0 | K18: ='Data Ocupacion'!T59 -> 34 | L18: ='Data Ocupacion'!V59 -> 36 | M18: ='Data Ocupacion'!X59 -> 36 | N18: ='Data Ocupacion'!Z59 -> 35 | O18: ='Data Ocupacion'!AB59 -> 36 | P18: ='Data Ocupacion'!AD59 -> 0 | Q18: ='Data Ocupacion'!AF59 -> 0 | R18: ='Data Ocupacion'!AH59 -> 35 | S18: ='Data Ocupacion'!AJ59 -> 36 | T18: ='Data Ocupacion'!AL59 -> 36 | U18: ='Data Ocupacion'!AN59 -> 36 | V18: ='Data Ocupacion'!AP59 -> 36 | W18: ='Data Ocupacion'!AR59 -> 0 | X18: ='Data Ocupacion'!AT59 -> 0 | Y18: ='Data Ocupacion'!AV59 -> 35 | Z18: ='Data Ocupacion'!AX59 -> 36 | AA18: ='Data Ocupacion'!AZ59 -> 0 | AB18: ='Data Ocupacion'!BB59 -> 35 | AC18: ='Data Ocupacion'!BD59 -> 36 | AD18: ='Data Ocupacion'!BF59 -> 0 | AE18: ='Data Ocupacion'!BH59 -> 0 | AF18: ='Data Ocupacion'!BJ59 -> 24 | AG18: ='Data Ocupacion'!BL59 -> 34
A19: Trenes EB-PU | B19: 25.4 | C19: ='Data Ocupacion'!D61 -> 0 | D19: ='Data Ocupacion'!F61 -> 1 | E19: ='Data Ocupacion'!H61 -> 1 | F19: ='Data Ocupacion'!J61 -> 1 | G19: ='Data Ocupacion'!L61 -> 1 | H19: ='Data Ocupacion'!N61 -> 1 | I19: ='Data Ocupacion'!P61 -> 0 | J19: ='Data Ocupacion'!R61 -> 0 | K19: ='Data Ocupacion'!T61 -> 1 | L19: ='Data Ocupacion'!V61 -> 1 | M19: ='Data Ocupacion'!X61 -> 1 | N19: ='Data Ocupacion'!Z61 -> 1 | O19: ='Data Ocupacion'!AB61 -> 1 | P19: ='Data Ocupacion'!AD61 -> 0 | Q19: ='Data Ocupacion'!AF61 -> 0 | R19: ='Data Ocupacion'!AH61 -> 1 | S19: ='Data Ocupacion'!AJ61 -> 1 | T19: ='Data Ocupacion'!AL61 -> 1 | U19: ='Data Ocupacion'!AN61 -> 1 | V19: ='Data Ocupacion'!AP61 -> 1 | W19: ='Data Ocupacion'!AR61 -> 0 | X19: ='Data Ocupacion'!AT61 -> 0 | Y19: ='Data Ocupacion'!AV61 -> 1 | Z19: ='Data Ocupacion'!AX61 -> 1 | AA19: ='Data Ocupacion'!AZ61 -> 0 | AB19: ='Data Ocupacion'!BB61 -> 1 | AC19: ='Data Ocupacion'!BD61 -> 1 | AD19: ='Data Ocupacion'!BF61 -> 0 | AE19: ='Data Ocupacion'!BH61 -> 0 | AF19: ='Data Ocupacion'!BJ61 -> 0 | AG19: ='Data Ocupacion'!BL61 -> 1
A20: Trenes PU-EB | B20: 25.4 | C20: 0 | D20: 0 | E20: 0 | F20: 0 | G20: 0 | H20: ='Data Ocupacion'!N60 -> 0 | I20: ='Data Ocupacion'!P60 -> 0 | J20: ='Data Ocupacion'!R60 -> 0 | K20: ='Data Ocupacion'!T60 -> 0 | L20: 0 | M20: 0 | N20: 0 | O20: 0 | P20: 0 | Q20: 0 | R20: 0 | S20: 0 | T20: 0 | U20: 0 | V20: 0 | W20: 0 | X20: 0 | Y20: 0 | Z20: 0 | AA20: 0 | AB20: 0 | AC20: 0 | AD20: 0 | AE20: 0 | AF20: 0 | AG20: 0
A21: Trenes MI-LI | B21: 35.73 | AF21: ='Data Ocupacion'!BJ62 -> 4
A22: Trenes LI-MI | B22: 35.73 | AF22: ='Data Ocupacion'!BJ63 -> 8
A23: Trenes LI-BA | B23: 39.4 | AG23: ='Data Ocupacion'!BL64 -> 4
A25: Corte EB (600) | B25: -17.73 | C25: ='KM-Servicio'!P5 -> 0 | D25: ='KM-Servicio'!P12 -> 3 | E25: ='KM-Servicio'!P19 -> 4 | F25: ='KM-Servicio'!P26 -> 3 | G25: ='KM-Servicio'!P33 -> 4 | H25: ='KM-Servicio'!P40 -> 3 | I25: ='KM-Servicio'!P47 -> 0 | J25: ='KM-Servicio'!P54 -> 0 | K25: ='KM-Servicio'!P61 -> 1 | L25: ='KM-Servicio'!P68 -> 2 | M25: ='KM-Servicio'!P75 -> 3 | N25: ='KM-Servicio'!P82 -> 3 | O25: ='KM-Servicio'!P89 -> 3 | P25: ='KM-Servicio'!P96 -> 0 | Q25: ='KM-Servicio'!P103 -> 0 | R25: ='KM-Servicio'!P110 -> 3 | S25: ='KM-Servicio'!P117 -> 4 | T25: ='KM-Servicio'!P124 -> 0 | U25: ='KM-Servicio'!P131 -> 4 | V25: ='KM-Servicio'!P138 -> 3 | W25: ='KM-Servicio'!P145 -> 0 | X25: ='KM-Servicio'!P152 -> 0 | Y25: ='KM-Servicio'!P159 -> 2 | Z25: ='KM-Servicio'!P166 -> 2 | AA25: ='KM-Servicio'!P173 -> 0 | AB25: ='KM-Servicio'!P180 -> 4 | AC25: ='KM-Servicio'!P187 -> 4 | AD25: ='KM-Servicio'!P194 -> 0 | AE25: ='KM-Servicio'!P201 -> 0 | AF25: ='KM-Servicio'!P208 -> 3 | AG25: ='KM-Servicio'!P217 -> 3
A26: Acople EB (600) | B26: -17.73 | C26: ='KM-Servicio'!S6 -> 0 | D26: ='KM-Servicio'!S13 -> 0 | E26: ='KM-Servicio'!S20 -> 0 | F26: ='KM-Servicio'!S27 -> 0 | G26: ='KM-Servicio'!S34 -> 1 | H26: ='KM-Servicio'!S41 -> 0 | I26: ='KM-Servicio'!S48 -> 0 | J26: ='KM-Servicio'!S55 -> 0 | K26: ='KM-Servicio'!S62 -> 0 | L26: ='KM-Servicio'!S69 -> 1 | M26: ='KM-Servicio'!S76 -> 3 | N26: ='KM-Servicio'!S83 -> 0 | O26: ='KM-Servicio'!S90 -> 0 | P26: ='KM-Servicio'!S97 -> 0 | Q26: ='KM-Servicio'!S104 -> 0 | R26: ='KM-Servicio'!S111 -> 0 | S26: ='KM-Servicio'!S118 -> 1 | T26: ='KM-Servicio'!S125 -> 0 | U26: ='KM-Servicio'!S132 -> 0 | V26: ='KM-Servicio'!S139 -> 0 | W26: ='KM-Servicio'!S146 -> 0 | X26: ='KM-Servicio'!S153 -> 0 | Y26: ='KM-Servicio'!S160 -> 0 | Z26: ='KM-Servicio'!S167 -> 5 | AA26: ='KM-Servicio'!S174 -> 0 | AB26: ='KM-Servicio'!S181 -> 1 | AC26: ='KM-Servicio'!S188 -> 1 | AD26: ='KM-Servicio'!S195 -> 0 | AE26: ='KM-Servicio'!S202 -> 0 | AF26: ='KM-Servicio'!S209 -> 0 | AG26: ='KM-Servicio'!S218 -> 3
A27: Acople/Corte SA (600) | B27: -14.02 | C27: ='KM-Servicio'!T6 -> 0 | D27: ='KM-Servicio'!T13 -> 0 | E27: ='KM-Servicio'!T20 -> 0 | F27: ='KM-Servicio'!T27 -> 0 | G27: ='KM-Servicio'!T34 -> 0 | H27: ='KM-Servicio'!T40 -> 0 | I27: ='KM-Servicio'!T48 -> 0 | J27: ='KM-Servicio'!T55 -> 0 | K27: ='KM-Servicio'!T62 -> 0 | L27: ='KM-Servicio'!T69 -> 0 | M27: ='KM-Servicio'!T76 -> 0 | N27: ='KM-Servicio'!T83 -> 0 | O27: ='KM-Servicio'!T90 -> 0 | P27: ='KM-Servicio'!T97 -> 0 | Q27: ='KM-Servicio'!T104 -> 0 | R27: ='KM-Servicio'!T111 -> 0 | S27: ='KM-Servicio'!T118 -> 0 | T27: ='KM-Servicio'!T125 -> 0 | U27: ='KM-Servicio'!T132 -> 0 | V27: ='KM-Servicio'!T139 -> 0 | W27: ='KM-Servicio'!T146 -> 0 | X27: ='KM-Servicio'!T153 -> 0 | Y27: ='KM-Servicio'!T160 -> 0 | Z27: ='KM-Servicio'!T167 -> 0 | AA27: ='KM-Servicio'!T174 -> 0 | AB27: ='KM-Servicio'!T181 -> 0 | AC27: ='KM-Servicio'!T188 -> 0 | AD27: ='KM-Servicio'!T195 -> 0 | AE27: ='KM-Servicio'!T202 -> 0 | AF27: ='KM-Servicio'!T209 -> 0 | AG27: ='KM-Servicio'!T216 -> 0
A28: Corte EB (400) | B28: -3.71
A29: Acople EB (600) vía 1 | B29: -25.4 | F29: 2 | J29: 1 | O29: 2 | P29: 7 | Q29: 3 | AC29: 1 | AF29: 1
A30: Corte PE (600) vía 1 | B30: -12.73
A31: Corte PE (600) | B31: -12.73
A32: Corte EB (600) vía 2 | B32: -25.4
