Workbook

Sheet Odometro-Kilometraje
A1: Control Contador Kilometraje de Trenes
B2: 45809 | C2: 45810 | D2: 45811 | E2: 45812 | F2: 45813 | G2: 45814 | H2: 45815 | I2: 45816 | J2: 45817 | K2: 45818 | L2: 45819 | M2: 45820 | N2: 45821 | O2: 45822 | P2: 45823 | Q2: 45824 | R2: 45825 | S2: 45826 | T2: 45827 | U2: 45828 | V2: 45829 | W2: 45830 | X2: 45831 | Y2: 45832 | Z2: 45833 | AA2: 45834 | AB2: 45835 | AC2: 45836 | AD2: 45837 | AE2: 45838
B3: Contador | C3: Contador | D3: Contador | E3: Contador | F3: Contador | G3: Contador | H3: Contador | I3: Contador | J3: Contador | K3: Contador | L3: Contador | M3: Contador | N3: Contador | O3: Contador | P3: Contador | Q3: Contador | R3: Contador | S3: Contador | T3: Contador | U3: Contador | V3: Contador | W3: Contador | X3: Contador | Y3: Contador | Z3: Contador | AA3: Contador | AB3: Contador | AC3: Contador | AD3: Contador | AE3: Contador
A4: Tren | B4: Odómetro | C4: Odómetro | D4: Odómetro | E4: Odómetro | F4: Odómetro | G4: Odómetro | H4: Odómetro | I4: Odómetro | J4: Odómetro | K4: Odómetro | L4: Odómetro | M4: Odómetro | N4: Odómetro | O4: Odómetro | P4: Odómetro | Q4: Odómetro | R4: Odómetro | S4: Odómetro | T4: Odómetro | U4: Odómetro | V4: Odómetro | W4: Odómetro | X4: Odómetro | Y4: Odómetro | Z4: Odómetro | AA4: Odómetro | AB4: Odómetro | AC4: Odómetro | AD4: Odómetro | AE4: Odómetro
A5: M01 | B5: 2011346 | C5: 2011845 | D5: 2012295 | E5: 2012375 | F5: 2012483 | G5: 2012668 | H5: 2012668 | I5: 2012668 | J5: 2012927 | K5: 2013240 | L5: 2013757 | M5: 2014273 | N5: 2014833 | O5: 2014877 | P5: 2015396 | Q5: 2015420 | R5: 2015681 | S5: 2016157 | T5: 2016428 | U5: 2016906 | V5: 2017466 | W5: 2017509 | X5: 2018083 | Y5: 2018514 | Z5: 2018965 | AA5: 2019219 | AB5: 2019468 | AC5: 2019468 | AD5: 2019468 | AE5: 2019660
A6: M02 | B6: 1984952 | C6: 1984973 | D6: 1985277 | E6: 1985528 | F6: 1985842 | G6: 1986403 | H6: 1986474 | I6: 1986478 | J6: 1986749 | K6: 1987225 | L6: 1987743 | M6: 1987981 | N6: 1988181 | O6: 1988181 | P6: 1988182 | Q6: 1988350 | R6: 1988808 | S6: 1989361 | T6: 1989924 | U6: 1990400 | V6: 1990961 | W6: 1991135 | X6: 1991366 | Y6: 1991616 | Z6: 1991866 | AA6: 1992128 | AB6: 1992717 | AC6: 1993237 | AD6: 1993329 | AE6: 1993592
A7: M03 | B7: 2072114 | C7: 2072559 | D7: 2072996 | E7: 2073559 | F7: 2074036 | G7: 2074238 | H7: 2074238 | I7: 2074238 | J7: 2074490 | K7: 2074888 | L7: 2075321 | M7: 2075428 | N7: 2075735 | O7: 2076255 | P7: 2076774 | Q7: 2076952 | R7: 2077558 | S7: 2077991 | T7: 2078313 | U7: 2078399 | V7: 2078917 | W7: 2079008 | X7: 2079329 | Y7: 2079848 | Z7: 2080411 | AA7: 2080680 | AB7: 2081130 | AC7: 2081281 | AD7: 2081842 | AE7: 2082276
A8: M04 | B8: 2073476 | C8: 2073912 | D8: 2074261 | E8: 2074697 | F8: 2075300 | G8: 2075753 | H8: 2075753 | I8: 2075772 | J8: 2075864 | K8: 2075973 | L8: 2076167 | M8: 2076482 | N8: 2076717 | O8: 2076717 | P8: 2076717 | Q8: 2076998 | R8: 2077452 | S8: 2077717 | T8: 2077947 | U8: 2077947 | V8: 2077947 | W8: 2077947 | X8: 2078138 | Y8: 2078329 | Z8: 2078561 | AA8: 2078834 | AB8: 2079105 | AC8: 2079105 | AD8: 2079105 | AE8: 2079356
A9: M05 | B9: 1980831 | C9: 1981434 | D9: 1982038 | E9: 1982487 | F9: 1982631 | G9: 1983031 | H9: 1983551 | I9: 1983982 | J9: 1984413 | K9: 1984932 | L9: 1985233 | M9: 1985714 | N9: 1985909 | O9: 1985909 | P9: 1985909 | Q9: 1985911 | R9: 1986162 | S9: 1986353 | T9: 1986665 | U9: 1986665 | V9: 1987184 | W9: 1987660 | X9: 1987959 | Y9: 1988491 | Z9: 1988983 | AA9: 1989236 | AB9: 1989378 | AC9: 1989378 | AD9: 1989556 | AE9: 1990116
A10: M06 | B10: 2094412 | C10: 2094696 | D10: 2094759 | E10: 2094840 | F10: 2095271 | G10: 2095637 | H10: 2095637 | I10: 2095637 | J10: 2095942 | K10: 2096505 | L10: 2096980 | M10: 2097219 | N10: 2097411 | O10: 2097411 | P10: 2097411 | Q10: 2097868 | R10: 2098342 | S10: 2098611 | T10: 2099137 | U10: 2099181 | V10: 2099698 | W10: 2100129 | X10: 2100304 | Y10: 2100754 | Z10: 2101068 | AA10: 2101432 | AB10: 2101907 | AC10: 2102426 | AD10: 2102857 | AE10: 2103050
A11: M07 | B11: 2122227 | C11: 2122836 | D11: 2122946 | E11: 2123195 | F11: 2123449 | G11: 2123702 | H11: 2123702 | I11: 2123702 | J11: 2123956 | K11: 2124090 | L11: 2124543 | M11: 2124737 | N11: 2125172 | O11: 2125736 | P11: 2125781 | Q11: 2126046 | R11: 2126568 | S11: 2126711 | T11: 2127085 | U11: 2127085 | V11: 2127085 | W11: 2127085 | X11: 2127304 | Y11: 2127911 | Z11: 2128358 | AA11: 2128966 | AB11: 2129576 | AC11: 2130184 | AD11: 2130445 | AE11: 2130816
A12: M08 | B12: 2025763 | C12: 2026111 | D12: 2026673 | E12: 2027234 | F12: 2027463 | G12: 2027810 | H12: 2028371 | I12: 2028415 | J12: 2029019 | K12: 2029472 | L12: 2029676 | M12: 2029678 | N12: 2029871 | O12: 2030433 | P12: 2030476 | Q12: 2030840 | R12: 2031008 | S12: 2031374 | T12: 2031706 | U12: 2032182 | V12: 2032702 | W12: 2033180 | X12: 2033589 | Y12: 2033841 | Z12: 2034093 | AA12: 2034355 | AB12: 2034916 | AC12: 2035425 | AD12: 2035953 | AE12: 2036517
A13: M09 | B13: 2008561 | C13: 2008740 | D13: 2008917 | E13: 2009009 | F13: 2009529 | G13: 2010048 | H13: 2010565 | I13: 2010823 | J13: 2011137 | K13: 2011657 | L13: 2012174 | M13: 2012177 | N13: 2012357 | O13: 2012875 | P13: 2013134 | Q13: 2013565 | R13: 2014085 | S13: 2014518 | T13: 2014831 | U13: 2015305 | V13: 2015348 | W13: 2015824 | X13: 2016317 | Y13: 2016802 | Z13: 2017321 | AA13: 2017719 | AB13: 2017981 | AC13: 2018541 | AD13: 2019058 | AE13: 2019620
A14: M10 | B14: 2085187 | C14: 2085553 | D14: 2085811 | E14: 2086184 | F14: 2086658 | G14: 2087178 | H14: 2087695 | I14: 2088169 | J14: 2088729 | K14: 2089084 | L14: 2089132 | M14: 2089653 | N14: 2090213 | O14: 2090257 | P14: 2090257 | Q14: 2090690 | R14: 2091002 | S14: 2091605 | T14: 2091984 | U14: 2091984 | V14: 2091984 | W14: 2091986 | X14: 2092352 | Y14: 2092485 | Z14: 2092832 | AA14: 2093265 | AB14: 2093715 | AC14: 2093715 | AD14: 2093715 | AE14: 2093858
A15: M11 | B15: 2102070 | C15: 2102134 | D15: 2102387 | E15: 2102638 | F15: 2102954 | G15: 2103407 | H15: 2103407 | I15: 2103407 | J15: 2103599 | K15: 2103811 | L15: 2104064 | M15: 2104315 | N15: 2104906 | O15: 2105429 | P15: 2105907 | Q15: 2106298 | R15: 2106500 | S15: 2106711 | T15: 2107275 | U15: 2107752 | V15: 2108230 | W15: 2108752 | X15: 2109273 | Y15: 2109484 | Z15: 2110006 | AA15: 2110487 | AB15: 2110982 | AC15: 2110982 | AD15: 2110982 | AE15: 2111046
A16: M12 | B16: 1947213 | C16: 1947817 | D16: 1948173 | E16: 1948780 | F16: 1949042 | G16: 1949295 | H16: 1949857 | I16: 1950205 | J16: 1950767 | K16: 1951250 | L16: 1951477 | M16: 1952039 | N16: 1952601 | O16: 1953121 | P16: 1953597 | Q16: 1953920 | R16: 1954019 | S16: 1954020 | T16: 1954118 | U16: 1954118 | V16: 1954118 | W16: 1954118 | X16: 1954261 | Y16: 1954574 | Z16: 1954833 | AA16: 1955218 | AB16: 1955610 | AC16: 1956043 | AD16: 1956044 | AE16: 1956306
... A39: XM35 | B39: 666061 | C39: 666493 | D39: 666695 | E39: 666944 | F39: 667136 | G39: 667327 | H39: 667327 | I39: 667327 | J39: 667391 | K39: 667582 | L39: 667662 | M39: 668226 | N39: 668507 | O39: 668507 | P39: 668507 | Q39: 668570 | R39: 669070 | S39: 669592 | T39: 669683 | U39: 669683 | V39: 669683 | W39: 669683 | X39: 669968 | Y39: 670314 | Z39: 670662 | AA39: 670864 | AB39: 671055 | AC39: 671055 | AD39: 671055 | AE39: 671303
A41: Kilometraje Diario Recorrido
B42: 45809 | C42: 45810 | D42: 45811 | E42: 45812 | F42: 45813 | G42: 45814 | H42: 45815 | I42: 45816 | J42: 45817 | K42: 45818 | L42: 45819 | M42: 45820 | N42: 45821 | O42: 45822 | P42: 45823 | Q42: 45824 | R42: 45825 | S42: 45826 | T42: 45827 | U42: 45828 | V42: 45829 | W42: 45830 | X42: 45831 | Y42: 45832 | Z42: 45833 | AA42: 45834 | AB42: 45835 | AC42: 45836 | AD42: 45837 | AE42: 45838
B43: Kilometraje | C43: Kilometraje | D43: Kilometraje | E43: Kilometraje | F43: Kilometraje | G43: Kilometraje | H43: Kilometraje | I43: Kilometraje | J43: Kilometraje | K43: Kilometraje | L43: Kilometraje | M43: Kilometraje | N43: Kilometraje | O43: Kilometraje | P43: Kilometraje | Q43: Kilometraje | R43: Kilometraje | S43: Kilometraje | T43: Kilometraje | U43: Kilometraje | V43: Kilometraje | W43: Kilometraje | X43: Kilometraje | Y43: Kilometraje | Z43: Kilometraje | AA43: Kilometraje | AB43: Kilometraje | AC43: Kilometraje | AD43: Kilometraje | AE43: Kilometraje
A44: Tren | B44: Diario | C44: Diario | D44: Diario | E44: Diario | F44: Diario | G44: Diario | H44: Diario | I44: Diario | J44: Diario | K44: Diario | L44: Diario | M44: Diario | N44: Diario | O44: Diario | P44: Diario | Q44: Diario | R44: Diario | S44: Diario | T44: Diario | U44: Diario | V44: Diario | W44: Diario | X44: Diario | Y44: Diario | Z44: Diario | AA44: Diario | AB44: Diario | AC44: Diario | AD44: Diario | AE44: Diario
A45: M01 | B45: 0 | C45: =C5-B5 -> 499 | D45: =D5-C5 -> 450 | E45: =E5-D5 -> 80 | F45: =F5-E5 -> 108 | G45: =G5-F5 -> 185 | H45: =H5-G5 -> 0 | I45: =I5-H5 -> 0 | J45: =J5-I5 -> 259 | ... AE45: =AE5-AD5 -> 192
A46: M02 | B46: 0 | C46: =C6-B6 -> 21 | D46: =D6-C6 -> 304 | E46: =E6-D6 -> 251 | F46: =F6-E6 -> 314 | G46: =G6-F6 -> 561 | H46: =H6-G6 -> 71 | I46: =I6-H6 -> 4 | J46: =J6-I6 -> 271 | ... AE46: =AE6-AD6 -> 263
A47: M03 | B47: 478 | C47: =C7-B7 -> 445 | D47: =D7-C7 -> 437 | E47: =E7-D7 -> 563 | F47: =F7-E7 -> 477 | G47: =G7-F7 -> 202 | H47: =H7-G7 -> 0 | I47: =I7-H7 -> 0 | J47: =J7-I7 -> 252 | ... AE47: =AE7-AD7 -> 434
A48: M04 | B48: 433 | C48: =C8-B8 -> 436 | D48: =D8-C8 -> 349 | E48: =E8-D8 -> 436 | F48: =F8-E8 -> 603 | G48: =G8-F8 -> 453 | H48: =H8-G8 -> 0 | I48: =I8-H8 -> 19 | J48: =J8-I8 -> 92 | ... AE48: =AE8-AD8 -> 251
A49: M05 | B49: 43 | C49: =C9-B9 -> 603 | D49: =D9-C9 -> 604 | E49: =E9-D9 -> 449 | F49: =F9-E9 -> 144 | G49: =G9-F9 -> 400 | H49: =H9-G9 -> 520 | I49: =I9-H9 -> 431 | J49: =J9-I9 -> 431 | ... AE49: =AE9-AD9 -> 560
A50: M06 | B50: 518 | C50: =C10-B10 -> 284 | D50: =D10-C10 -> 63 | E50: =E10-D10 -> 81 | F50: =F10-E10 -> 431 | G50: =G10-F10 -> 366 | H50: =H10-G10 -> 0 | I50: =I10-H10 -> 0 | J50: =J10-I10 -> 305 | ... AE50: =AE10-AD10 -> 193
A51: M07 | B51: 521 | C51: =C11-B11 -> 609 | D51: =D11-C11 -> 110 | E51: =E11-D11 -> 249 | F51: =F11-E11 -> 254 | G51: =G11-F11 -> 253 | H51: =H11-G11 -> 0 | I51: =I11-H11 -> 0 | J51: =J11-I11 -> 254 | ... AE51: =AE11-AD11 -> 371
A52: M08 | B52: 433 | C52: =C12-B12 -> 348 | D52: =D12-C12 -> 562 | E52: =E12-D12 -> 561 | F52: =F12-E12 -> 229 | G52: =G12-F12 -> 347 | H52: =H12-G12 -> 561 | I52: =I12-H12 -> 44 | J52: =J12-I12 -> 604 | ... AE52: =AE12-AD12 -> 564
A53: M09 | B53: 177 | C53: =C13-B13 -> 179 | D53: =D13-C13 -> 177 | E53: =E13-D13 -> 92 | F53: =F13-E13 -> 520 | G53: =G13-F13 -> 519 | H53: =H13-G13 -> 517 | I53: =I13-H13 -> 258 | J53: =J13-I13 -> 314 | ... AE53: =AE13-AD13 -> 562
A54: M10 | B54: 0 | C54: =C14-B14 -> 366 | D54: =D14-C14 -> 258 | E54: =E14-D14 -> 373 | F54: =F14-E14 -> 474 | G54: =G14-F14 -> 520 | H54: =H14-G14 -> 517 | I54: =I14-H14 -> 474 | J54: =J14-I14 -> 560 | ... AE54: =AE14-AD14 -> 143
A55: M11 | B55: 0 | C55: =C15-B15 -> 64 | D55: =D15-C15 -> 253 | E55: =E15-D15 -> 251 | F55: =F15-E15 -> 316 | G55: =G15-F15 -> 453 | H55: =H15-G15 -> 0 | I55: =I15-H15 -> 0 | J55: =J15-I15 -> 192 | ... AE55: =AE15-AD15 -> 64
A56: M12 | B56: 432 | C56: =C16-B16 -> 604 | D56: =D16-C16 -> 356 | E56: =E16-D16 -> 607 | F56: =F16-E16 -> 262 | G56: =G16-F16 -> 253 | H56: =H16-G16 -> 562 | I56: =I16-H16 -> 348 | J56: =J16-I16 -> 562 | ... AE56: =AE16-AD16 -> 262
... A79: XM35 | B79: 0 | C79: =C39-B39 -> 432 | D79: =D39-C39 -> 202 | E79: =E39-D39 -> 249 | F79: =F39-E39 -> 192 | G79: =G39-F39 -> 191 | H79: =H39-G39 -> 0 | I79: =I39-H39 -> 0 | J79: =J39-I39 -> 64 | ... AE79: =AE39-AD39 -> 248
A81: Kilometraje Diario | B81: =SUM(B45:B79) -> 5149 | C81: =SUM(C45:C79) -> 11955 | D81: =SUM(D45:D79) -> 12127 | E81: =SUM(E45:E79) -> 11994 | F81: =SUM(F45:F79) -> 11903 | G81: =SUM(G45:G79) -> 12074 | H81: =SUM(H45:H79) -> 6589 | I81: =SUM(I45:I79) -> 4964 | ... AE81: =SUM(AE45:AE79) -> 11444

Sheet KM-Servicio
E1: SA-QU/QU-SA | F1: 7.68 | H1: SA-MI | I1: 21.7 | J1: EB-PU | K1: 25.4 | L1: PU-SA | M1: 29.11 | N1: QU-LI / LI-QU | O1: 21.7 | P1: VM-PU | Q1: 8.3 | R1: VM-LI | S1: 34.83 | T1: LI-PO | U1: 39.19 | W1: PU-ES/ES-PU | X1: 11.71 | Y1: PU-RE | Z1: 6 | AA1: PU-BA | AB1: 2.2
B2: CANTIDAD DE SERVICIOS | D2: CANTIDAD DE SERVICIOS | F2: EB-LI | G2: =M2-K1 -> 17.73 | H2: PU-PE | I2: 30.4 | J2: PO-SA | K2: 25.4 | L2: PU-LI | M2: 43.13 | N2: MI-LI / LI-MI | O2: 35.73 | P2: HO-LI/LI-HO | Q2: 33.97 | R2: PU-MI | S2: 7.4 | T2: LI-PE | U2: 12.72 | W2: MI-SA | X2: 21.7 | Y2: PU-PO | Z2: 3.9
B3: PROGRAMADOS | D3: REALIZADOS | F3: Origen-Destino | G3: Total Trenes | H3: Total Trenes P | I3: Total Servicios | J3: Kms.xTrenes | K3: Kmsxservicios. | L3: Asientos x Kms. | M3: Disp x Km. | N3: Total Odómetro | O3: % Uso Trenes | Q3: Cortes | T3: Acoples | W3: KmTren R | X3: KmTren P
B4: Simples | C4: Dobles | D4: Simples | E4: Dobles | Q4: EB | R4: SA | S4: PE | T4: EB | U4: SA | V4: PE
A5: 45809 | B5: 53 | C5: 3 | D5: ='Data Ocupacion'!D37 -> 53 | E5: ='Data Ocupacion'!E37 -> 3 | F5: PU-LI | G5: =D5+E5*2 -> 59 | H5: =B5+C5*2 -> 59 | I5: =D5+E5 -> 56 | J5: =G5*M$2 -> 2544.67 | K5: =I5*M$2 -> 2415.28 | L5: =J5*104 -> 264645.68 | M5: =I5*104 -> 5824 | W5: =J5-(Q5*($M$2-$K$1))-(R5*($M$2-$M$1))- (S5*($M$2-$I$2))+ (T5*($G$2)) -> 2544.67 | X5: =H5*$M$2 -> 2544.67
A6: PLANILLA NUEVA DOMINGO CUENTA PUBLICA PRESIDENTE | B6: 59 | C6: 0 | D6: ='Data Ocupacion'!D38 -> 59 | E6: ='Data Ocupacion'!E38 -> 0 | F6: LI-PU | G6: =D6+E6*2 -> 59 | H6: =B6+C6*2 -> 59 | I6: =D6+E6 -> 59 | J6: =G6*M$2 -> 2544.67 | K6: =I6*M$2 -> 2544.67 | L6: =J6*104 -> 264645.68 | M6: =I6*104 -> 6136 | W6: =J6-(T6*($M$2-$K$1)+(U6*($M$2-$M$1))) -> 2544.67 | X6: =H6*$M$2 -> 2544.67
B7: 0 | C7: 0 | D7: ='Data Ocupacion'!D39 -> 0 | E7: ='Data Ocupacion'!E39 -> 0 | F7: PU-SA | G7: =D7+E7*2 -> 0 | H7: =B7+C7*2 -> 0 | I7: =D7+E7 -> 0 | J7: =G7*M$1 -> 0 | K7: =I7*M$1 -> 0 | L7: =J7*104 -> 0 | M7: =I7*104 -> 0 | W7: =J7-(Q7*($M$1-$K$1)) -> 0 | X7: =H7*$M$1 -> 0
B8: 0 | C8: 0 | D8: ='Data Ocupacion'!D40 -> 0 | E8: ='Data Ocupacion'!E40 -> 0 | F8: SA-PU | G8: =D8+E8*2 -> 0 | H8: =B8+C8*2 -> 0 | I8: =D8+E8 -> 0 | J8: =G8*M$1 -> 0 | K8: =I8*M$1 -> 0 | L8: =J8*104 -> 0 | M8: =I8*104 -> 0 | W8: =J8 -> 0 | X8: =H8*$M$1 -> 0
B9: 0 | C9: 0 | D9: ='Data Ocupacion'!D41 -> 0 | E9: ='Data Ocupacion'!E41 -> 0 | F9: PU-EB | G9: =D9+E9*2 -> 0 | H9: =B9+C9*2 -> 0 | I9: =D9+E9 -> 0 | J9: =G9*K$1 -> 0 | K9: =I9*K$1 -> 0 | L9: =J9*104 -> 0 | M9: =I9*104 -> 0 | W9: =J9 -> 0 | X9: =H9*$K$1 -> 0
B10: 0 | C10: 0 | D10: ='Data Ocupacion'!D42 -> 0 | E10: ='Data Ocupacion'!E42 -> 0 | F10: EB-PU | G10: =D10+E10*2 -> 0 | H10: =B10+C10*2 -> 0 | I10: =D10+E10 -> 0 | J10: =G10*K$1 -> 0 | K10: =I10*K$1 -> 0 | L10: =J10*104 -> 0 | M10: =I10*104 -> 0 | W10: =J10 -> 0 | X10: =H10*$K$1 -> 0
B11: =SUM(B5:B10) -> 112 | C11: =SUM(C5:C10) -> 3 | D11: =SUM(D5:D10) -> 112 | E11: =SUM(E5:E10) -> 3 | G11: =SUM(G5:G10) -> 118 | H11: =SUM(H5:H10) -> 118 | I11: =SUM(I5:I10) -> 115 | J11: =SUM(J5:J10) -> 5089.34 | K11: =SUM(K5:K10) -> 4959.95 | L11: =SUM(L5:L10) -> 529291.36 | M11: =SUM(M5:M10) -> 11960 | N11: ='Odometro-Kilometraje'!B81 -> 5149 | O11: =(W11/N11)*100 -> 98.841328 | W11: =SUM(W5:W10) -> 5089.34 | X11: =SUM(X5:X10) -> 5089.34
A12: =A5+1 -> 45810 | B12: 47 | C12: 32 | D12: ='Data Ocupacion'!F37 -> 47 | E12: ='Data Ocupacion'!G37 -> 32 | F12: PU-LI | G12: =D12+E12*2 -> 111 | H12: =B12+C12*2 -> 111 | I12: =D12+E12 -> 79 | J12: =G12*M$2 -> 4787.43 | K12: =I12*M$2 -> 3407.27 | L12: =J12*104 -> 497892.72 | M12: =I12*104 -> 8216 | Q12: 3 | W12: =J12-(Q12*($M$2-$K$1))-(R12*($M$2-$M$1))- (S12*($M$2-$I$2))+ (T12*($G$2)) -> 4734.24 | X12: =H12*$M$2 -> 4787.43
B13: 45 | C13: 33 | D13: ='Data Ocupacion'!F38 -> 45 | E13: ='Data Ocupacion'!G38 -> 33 | F13: LI-PU | G13: =D13+E13*2 -> 111 | H13: =B13+C13*2 -> 111 | I13: =D13+E13 -> 78 | J13: =G13*M$2 -> 4787.43 | K13: =I13*M$2 -> 3364.14 | L13: =J13*104 -> 497892.72 | M13: =I13*104 -> 8112 | T13: 4 | W13: =J13-(T13*($M$2-$K$1)+(U13*($M$2-$M$1))) -> 4716.51 | X13: =H13*$M$2 -> 4787.43
B14: 29 | C14: 4 | D14: ='Data Ocupacion'!F39 -> 29 | E14: ='Data Ocupacion'!G39 -> 4 | F14: PU-SA | G14: =D14+E14*2 -> 37 | H14: =B14+C14*2 -> 37 | I14: =D14+E14 -> 33 | J14: =G14*M$1 -> 1077.07 | K14: =I14*M$1 -> 960.63 | L14: =J14*104 -> 112015.28 | M14: =I14*104 -> 3432 | W14: =J14-(Q14*($M$1-$K$1)) -> 1077.07 | X14: =H14*$M$1 -> 1077.07
B15: 28 | C15: 4 | D15: ='Data Ocupacion'!F40 -> 28 | E15: ='Data Ocupacion'!G40 -> 4 | F15: SA-PU | G15: =D15+E15*2 -> 36 | H15: =B15+C15*2 -> 36 | I15: =D15+E15 -> 32 | J15: =G15*M$1 -> 1047.96 | K15: =I15*M$1 -> 931.52 | L15: =J15*104 -> 108987.84 | M15: =I15*104 -> 3328 | W15: =J15 -> 1047.96 | X15: =H15*$M$1 -> 1047.96
B16: 0 | C16: 0 | D16: ='Data Ocupacion'!F41 -> 0 | E16: ='Data Ocupacion'!G41 -> 0 | F16: PU-EB | G16: =D16+E16*2 -> 0 | H16: =B16+C16*2 -> 0 | I16: =D16+E16 -> 0 | J16: =G16*K$1 -> 0 | K16: =I16*K$1 -> 0 | L16: =J16*104 -> 0 | M16: =I16*104 -> 0 | W16: =J16 -> 0 | X16: =H16*$K$1 -> 0
B17: 1 | C17: 0 | D17: ='Data Ocupacion'!F42 -> 1 | E17: ='Data Ocupacion'!G42 -> 0 | F17: EB-PU | G17: =D17+E17*2 -> 1 | H17: =B17+C17*2 -> 1 | I17: =D17+E17 -> 1 | J17: =G17*K$1 -> 25.4 | K17: =I17*K$1 -> 25.4 | L17: =J17*104 -> 2641.6 | M17: =I17*104 -> 104 | W17: =J17 -> 25.4 | X17: =H17*$K$1 -> 25.4
B18: =SUM(B12:B17) -> 150 | C18: =SUM(C12:C17) -> 73 | D18: =SUM(D12:D17) -> 150 | E18: =SUM(E12:E17) -> 73 | G18: =SUM(G12:G17) -> 296 | H18: =SUM(H12:H17) -> 296 | I18: =SUM(I12:I17) -> 223 | J18: =SUM(J12:J17) -> 11725.29 | K18: =SUM(K12:K17) -> 8688.96 | L18: =SUM(L12:L17) -> 1219430.2 | M18: =SUM(M12:M17) -> 23192 | N18: ='Odometro-Kilometraje'!C81 -> 11955 | O18: =(W18/N18)*100 -> 97.040402 | W18: =SUM(W12:W17) -> 11601.18 | X18: =SUM(X12:X17) -> 11725.29
A19: =A12+1 -> 45811 | B19: 47 | C19: 32 | D19: ='Data Ocupacion'!H37 -> 46 | E19: ='Data Ocupacion'!I37 -> 33 | F19: PU-LI | G19: =D19+E19*2 -> 112 | H19: =B19+C19*2 -> 111 | I19: =D19+E19 -> 79 | J19: =G19*M$2 -> 4830.56 | K19: =I19*M$2 -> 3407.27 | L19: =J19*104 -> 502378.24 | M19: =I19*104 -> 8216 | Q19: 4 | W19: =J19-(Q19*($M$2-$K$1))-(R19*($M$2-$M$1))- (S19*($M$2-$I$2))+ (T19*($G$2)) -> 4759.64 | X19: =H19*$M$2 -> 4787.43
B20: 45 | C20: 33 | D20: ='Data Ocupacion'!H38 -> 44 | E20: ='Data Ocupacion'!I38 -> 34 | F20: LI-PU | G20: =D20+E20*2 -> 112 | H20: =B20+C20*2 -> 111 | I20: =D20+E20 -> 78 | J20: =G20*M$2 -> 4830.56 | K20: =I20*M$2 -> 3364.14 | L20: =J20*104 -> 502378.24 | M20: =I20*104 -> 8112 | T20: 2 | W20: =J20-(T20*($M$2-$K$1)+(U20*($M$2-$M$1))) -> 4795.1 | X20: =H20*$M$2 -> 4787.43
B21: 29 | C21: 4 | D21: ='Data Ocupacion'!H39 -> 29 | E21: ='Data Ocupacion'!I39 -> 4 | F21: PU-SA | G21: =D21+E21*2 -> 37 | H21: =B21+C21*2 -> 37 | I21: =D21+E21 -> 33 | J21: =G21*M$1 -> 1077.07 | K21: =I21*M$1 -> 960.63 | L21: =J21*104 -> 112015.28 | M21: =I21*104 -> 3432 | W21: =J21-(Q21*($M$1-$K$1)) -> 1077.07 | X21: =H21*$M$1 -> 1077.07
B22: 28 | C22: 4 | D22: ='Data Ocupacion'!H40 -> 28 | E22: ='Data Ocupacion'!I40 -> 4 | F22: SA-PU | G22: =D22+E22*2 -> 36 | H22: =B22+C22*2 -> 36 | I22: =D22+E22 -> 32 | J22: =G22*M$1 -> 1047.96 | K22: =I22*M$1 -> 931.52 | L22: =J22*104 -> 108987.84 | M22: =I22*104 -> 3328 | W22: =J22 -> 1047.96 | X22: =H22*$M$1 -> 1047.96
B23: 0 | C23: 0 | D23: ='Data Ocupacion'!H41 -> 0 | E23: ='Data Ocupacion'!I41 -> 0 | F23: PU-EB | G23: =D23+E23*2 -> 0 | H23: =B23+C23*2 -> 0 | I23: =D23+E23 -> 0 | J23: =G23*K$1 -> 0 | K23: =I23*K$1 -> 0 | L23: =J23*104 -> 0 | M23: =I23*104 -> 0 | W23: =J23 -> 0 | X23: =H23*$K$1 -> 0
B24: 1 | C24: 0 | D24: ='Data Ocupacion'!H42 -> 1 | E24: ='Data Ocupacion'!I42 -> 0 | F24: EB-PU | G24: =D24+E24*2 -> 1 | H24: =B24+C24*2 -> 1 | I24: =D24+E24 -> 1 | J24: =G24*K$1 -> 25.4 | K24: =I24*K$1 -> 25.4 | L24: =J24*104 -> 2641.6 | M24: =I24*104 -> 104 | W24: =J24 -> 25.4 | X24: =H24*$K$1 -> 25.4
B25: =SUM(B19:B24) -> 150 | C25: =SUM(C19:C24) -> 73 | D25: =SUM(D19:D24) -> 148 | E25: =SUM(E19:E24) -> 75 | G25: =SUM(G19:G24) -> 298 | H25: =SUM(H19:H24) -> 296 | I25: =SUM(I19:I24) -> 223 | J25: =SUM(J19:J24) -> 11811.55 | K25: =SUM(K19:K24) -> 8688.96 | L25: =SUM(L19:L24) -> 1228401.2 | M25: =SUM(M19:M24) -> 23192 | N25: ='Odometro-Kilometraje'!D81 -> 12127 | O25: =(W25/N25)*100 -> 96.521563 | W25: =SUM(W19:W24) -> 11705.17 | X25: =SUM(X19:X24) -> 11725.29
A26: =A19+1 -> 45812 | B26: 47 | C26: 32 | D26: ='Data Ocupacion'!J37 -> 47 | E26: ='Data Ocupacion'!K37 -> 32 | F26: PU-LI | G26: =D26+E26*2 -> 111 | H26: =B26+C26*2 -> 111 | I26: =D26+E26 -> 79 | J26: =G26*M$2 -> 4787.43 | K26: =I26*M$2 -> 3407.27 | L26: =J26*104 -> 497892.72 | M26: =I26*104 -> 8216 | Q26: 3 | W26: =J26-(Q26*($M$2-$K$1))-(R26*($M$2-$M$1))- (S26*($M$2-$I$2))+ (T26*($G$2)) -> 4734.24 | X26: =H26*$M$2 -> 4787.43
B27: 45 | C27: 33 | D27: ='Data Ocupacion'!J38 -> 45 | E27: ='Data Ocupacion'!K38 -> 33 | F27: LI-PU | G27: =D27+E27*2 -> 111 | H27: =B27+C27*2 -> 111 | I27: =D27+E27 -> 78 | J27: =G27*M$2 -> 4787.43 | K27: =I27*M$2 -> 3364.14 | L27: =J27*104 -> 497892.72 | M27: =I27*104 -> 8112 | T27: 4 | W27: =J27-(T27*($M$2-$K$1)+(U27*($M$2-$M$1))+(V27*($M$2-$I$2))) -> 4716.51 | X27: =H27*$M$2 -> 4787.43
B28: 29 | C28: 4 | D28: ='Data Ocupacion'!J39 -> 29 | E28: ='Data Ocupacion'!K39 -> 4 | F28: PU-SA | G28: =D28+E28*2 -> 37 | H28: =B28+C28*2 -> 37 | I28: =D28+E28 -> 33 | J28: =G28*M$1 -> 1077.07 | K28: =I28*M$1 -> 960.63 | L28: =J28*104 -> 112015.28 | M28: =I28*104 -> 3432 | W28: =J28-(Q28*($M$1-$K$1)) -> 1077.07 | X28: =H28*$M$1 -> 1077.07
B29: 28 | C29: 4 | D29: ='Data Ocupacion'!J40 -> 28 | E29: ='Data Ocupacion'!K40 -> 4 | F29: SA-PU | G29: =D29+E29*2 -> 36 | H29: =B29+C29*2 -> 36 | I29: =D29+E29 -> 32 | J29: =G29*M$1 -> 1047.96 | K29: =I29*M$1 -> 931.52 | L29: =J29*104 -> 108987.84 | M29: =I29*104 -> 3328 | W29: =J29 -> 1047.96 | X29: =H29*$M$1 -> 1047.96
B30: 0 | C30: 0 | D30: ='Data Ocupacion'!J41 -> 0 | E30: ='Data Ocupacion'!K41 -> 0 | F30: PU-EB | G30: =D30+E30*2 -> 0 | H30: =B30+C30*2 -> 0 | I30: =D30+E30 -> 0 | J30: =G30*K$1 -> 0 | K30: =I30*K$1 -> 0 | L30: =J30*104 -> 0 | M30: =I30*104 -> 0 | W30: =J30 -> 0 | X30: =H30*$K$1 -> 0
B31: 1 | C31: 0 | D31: ='Data Ocupacion'!J42 -> 1 | E31: ='Data Ocupacion'!K42 -> 0 | F31: EB-PU | G31: =D31+E31*2 -> 1 | H31: =B31+C31*2 -> 1 | I31: =D31+E31 -> 1 | J31: =G31*K$1 -> 25.4 | K31: =I31*K$1 -> 25.4 | L31: =J31*104 -> 2641.6 | M31: =I31*104 -> 104 | W31: =J31 -> 25.4 | X31: =H31*$K$1 -> 25.4
B32: =SUM(B26:B31) -> 150 | C32: =SUM(C26:C31) -> 73 | D32: =SUM(D26:D31) -> 150 | E32: =SUM(E26:E31) -> 73 | G32: =SUM(G26:G31) -> 296 | H32: =SUM(H26:H31) -> 296 | I32: =SUM(I26:I31) -> 223 | J32: =SUM(J26:J31) -> 11725.29 | K32: =SUM(K26:K31) -> 8688.96 | L32: =SUM(L26:L31) -> 1219430.2 | M32: =SUM(M26:M31) -> 23192 | N32: ='Odometro-Kilometraje'!E81 -> 11994 | O32: =(W32/N32)*100 -> 96.724862 | W32: =SUM(W26:W31) -> 11601.18 | X32: =SUM(X26:X31) -> 11725.29
A33: =A26+1 -> 45813 | B33: 47 | C33: 32 | D33: ='Data Ocupacion'!L37 -> 46 | E33: ='Data Ocupacion'!M37 -> 33 | F33: PU-LI | G33: =D33+E33*2 -> 112 | H33: =B33+C33*2 -> 111 | I33: =D33+E33 -> 79 | J33: =G33*M$2 -> 4830.56 | K33: =I33*M$2 -> 3407.27 | L33: =J33*104 -> 502378.24 | M33: =I33*104 -> 8216 | Q33: 5 | W33: =J33-(Q33*($M$2-$K$1))-(R33*($M$2-$M$1))- (S33*($M$2-$I$2))+ (T33*($G$2)) -> 4741.91 | X33: =H33*$M$2 -> 4787.43
B34: 45 | C34: 33 | D34: ='Data Ocupacion'!L38 -> 45 | E34: ='Data Ocupacion'!M38 -> 33 | F34: LI-PU | G34: =D34+E34*2 -> 111 | H34: =B34+C34*2 -> 111 | I34: =D34+E34 -> 78 | J34: =G34*M$2 -> 4787.43 | K34: =I34*M$2 -> 3364.14 | L34: =J34*104 -> 497892.72 | M34: =I34*104 -> 8112 | T34: 7 | W34: =J34-(T34*($M$2-$K$1)+(U34*($M$2-$M$1))) -> 4663.32 | X34: =H34*$M$2 -> 4787.43
B35: 29 | C35: 4 | D35: ='Data Ocupacion'!L39 -> 29 | E35: ='Data Ocupacion'!M39 -> 4 | F35: PU-SA | G35: =D35+E35*2 -> 37 | H35: =B35+C35*2 -> 37 | I35: =D35+E35 -> 33 | J35: =G35*M$1 -> 1077.07 | K35: =I35*M$1 -> 960.63 | L35: =J35*104 -> 112015.28 | M35: =I35*104 -> 3432 | W35: =J35-(Q35*($M$1-$K$1)) -> 1077.07 | X35: =H35*$M$1 -> 1077.07
B36: 28 | C36: 4 | D36: ='Data Ocupacion'!L40 -> 27 | E36: ='Data Ocupacion'!M40 -> 5 | F36: SA-PU | G36: =D36+E36*2 -> 37 | H36: =B36+C36*2 -> 36 | I36: =D36+E36 -> 32 | J36: =G36*M$1 -> 1077.07 | K36: =I36*M$1 -> 931.52 | L36: =J36*104 -> 112015.28 | M36: =I36*104 -> 3328 | W36: =J36 -> 1077.07 | X36: =H36*$M$1 -> 1047.96
B37: 0 | C37: 0 | D37: ='Data Ocupacion'!L41 -> 0 | E37: ='Data Ocupacion'!M41 -> 0 | F37: PU-EB | G37: =D37+E37*2 -> 0 | H37: =B37+C37*2 -> 0 | I37: =D37+E37 -> 0 | J37: =G37*K$1 -> 0 | K37: =I37*K$1 -> 0 | L37: =J37*104 -> 0 | M37: =I37*104 -> 0 | W37: =J37 -> 0 | X37: =H37*$K$1 -> 0
B38: 1 | C38: 0 | D38: ='Data Ocupacion'!L42 -> 1 | E38: ='Data Ocupacion'!M42 -> 0 | F38: EB-PU | G38: =D38+E38*2 -> 1 | H38: =B38+C38*2 -> 1 | I38: =D38+E38 -> 1 | J38: =G38*K$1 -> 25.4 | K38: =I38*K$1 -> 25.4 | L38: =J38*104 -> 2641.6 | M38: =I38*104 -> 104 | W38: =J38 -> 25.4 | X38: =H38*$K$1 -> 25.4
B39: =SUM(B33:B38) -> 150 | C39: =SUM(C33:C38) -> 73 | D39: =SUM(D33:D38) -> 148 | E39: =SUM(E33:E38) -> 75 | G39: =SUM(G33:G38) -> 298 | H39: =SUM(H33:H38) -> 296 | I39: =SUM(I33:I38) -> 223 | J39: =SUM(J33:J38) -> 11797.53 | K39: =SUM(K33:K38) -> 8688.96 | L39: =SUM(L33:L38) -> 1226943.1 | M39: =SUM(M33:M38) -> 23192 | N39: ='Odometro-Kilometraje'!F81 -> 11903 | O39: =(W39/N39)*100 -> 97.326472 | W39: =SUM(W33:W38) -> 11584.77 | X39: =SUM(X33:X38) -> 11725.29
A40: =A33+1 -> 45814 | B40: 47 | C40: 32 | D40: ='Data Ocupacion'!N37 -> 46 | E40: ='Data Ocupacion'!O37 -> 33 | F40: PU-LI | G40: =D40+E40*2 -> 112 | H40: =B40+C40*2 -> 111 | I40: =D40+E40 -> 79 | J40: =G40*M$2 -> 4830.56 | K40: =I40*M$2 -> 3407.27 | L40: =J40*104 -> 502378.24 | M40: =I40*104 -> 8216 | Q40: 4 | S40: 1 | W40: =J40-(Q40*($M$2-$K$1))-(R40*($M$2-$M$1))- (S40*($M$2-$I$2))+ (T40*($G$2)) -> 4746.91 | X40: =H40*$M$2 -> 4787.43
...

Sheet Oferta Diaria
A1: Oferta Junio 2025
C3: 45809 | D3: 45810 | E3: 45811 | F3: 45812 | G3: 45813 | H3: 45814 | I3: 45815 | J3: 45816 | K3: 45817 | L3: 45818 | M3: 45819 | N3: 45820 | O3: 45821 | P3: 45822 | Q3: 45823 | R3: 45824 | S3: 45825 | T3: 45826 | U3: 45827 | V3: 45828 | W3: 45829 | X3: 45830 | Y3: 45831 | Z3: 45832 | AA3: 45833 | AB3: 45834 | AC3: 45835 | AD3: 45836 | AE3: 45837 | AF3: 45838
A4: HÁBIL | B4: km
A5: Servicios PU-LI | B5: 43.13 | C5: ='Data Ocupacion'!D51 -> 56 | D5: ='Data Ocupacion'!F51 -> 79 | E5: ='Data Ocupacion'!H51 -> 79 | F5: ='Data Ocupacion'!J51 -> 79 | G5: ='Data Ocupacion'!L51 -> 79 | H5: ='Data Ocupacion'!N51 -> 79 | I5: ='Data Ocupacion'!P51 -> 72 | J5: ='Data Ocupacion'!R51 -> 54 | K5: ='Data Ocupacion'!T51 -> 79 | L5: ='Data Ocupacion'!V51 -> 79 | M5: ='Data Ocupacion'!X51 -> 79 | N5: ='Data Ocupacion'!Z51 -> 79 | O5: ='Data Ocupacion'!AB51 -> 79 | P5: ='Data Ocupacion'!AD51 -> 72 | Q5: ='Data Ocupacion'!AF51 -> 54 | R5: ='Data Ocupacion'!AH51 -> 50 | S5: ='Data Ocupacion'!AJ51 -> 79 | T5: ='Data Ocupacion'!AL51 -> 79 | U5: ='Data Ocupacion'!AN51 -> 79 | V5: ='Data Ocupacion'!AP51 -> 54 | W5: ='Data Ocupacion'!AR51 -> 72 | X5: ='Data Ocupacion'!AT51 -> 54 | Y5: ='Data Ocupacion'!AV51 -> 62 | Z5: ='Data Ocupacion'!AX51 -> 79 | AA5: ='Data Ocupacion'!AZ51 -> 79 | AB5: ='Data Ocupacion'!BB51 -> 79 | AC5: ='Data Ocupacion'!BD51 -> 79 | AD5: ='Data Ocupacion'!BF51 -> 72 | AE5: ='Data Ocupacion'!BH51 -> 61 | AF5: ='Data Ocupacion'!BJ51 -> 79
A6: Servicios LI-PU | B6: 43.13 | C6: ='Data Ocupacion'!D52 -> 59 | D6: ='Data Ocupacion'!F52 -> 78 | E6: ='Data Ocupacion'!H52 -> 78 | F6: ='Data Ocupacion'!J52 -> 78 | G6: ='Data Ocupacion'!L52 -> 78 | H6: ='Data Ocupacion'!N52 -> 78 | I6: ='Data Ocupacion'!P52 -> 75 | J6: ='Data Ocupacion'!R52 -> 57 | K6: ='Data Ocupacion'!T52 -> 78 | L6: ='Data Ocupacion'!V52 -> 78 | M6: ='Data Ocupacion'!X52 -> 78 | N6: ='Data Ocupacion'!Z52 -> 78 | O6: ='Data Ocupacion'!AB52 -> 78 | P6: ='Data Ocupacion'!AD52 -> 75 | Q6: ='Data Ocupacion'!AF52 -> 57 | R6: ='Data Ocupacion'!AH52 -> 49 | S6: ='Data Ocupacion'!AJ52 -> 78 | T6: ='Data Ocupacion'!AL52 -> 78 | U6: ='Data Ocupacion'!AN52 -> 78 | V6: ='Data Ocupacion'!AP52 -> 57 | W6: ='Data Ocupacion'!AR52 -> 75 | X6: ='Data Ocupacion'!AT52 -> 57 | Y6: ='Data Ocupacion'!AV52 -> 61 | Z6: ='Data Ocupacion'!AX52 -> 78 | AA6: ='Data Ocupacion'!AZ52 -> 78 | AB6: ='Data Ocupacion'!BB52 -> 78 | AC6: ='Data Ocupacion'!BD52 -> 78 | AD6: ='Data Ocupacion'!BF52 -> 75 | AE6: ='Data Ocupacion'!BH52 -> 61 | AF6: ='Data Ocupacion'!BJ52 -> 78
A7: Servicios PU-SA | B7: 29.11 | C7: ='Data Ocupacion'!D53 -> 0 | D7: ='Data Ocupacion'!F53 -> 33 | E7: ='Data Ocupacion'!H53 -> 33 | F7: ='Data Ocupacion'!J53 -> 33 | G7: ='Data Ocupacion'!L53 -> 33 | H7: ='Data Ocupacion'!N53 -> 33 | I7: ='Data Ocupacion'!P53 -> 0 | J7: ='Data Ocupacion'!R53 -> 0 | K7: ='Data Ocupacion'!T53 -> 33 | L7: ='Data Ocupacion'!V53 -> 33 | M7: ='Data Ocupacion'!X53 -> 33 | N7: ='Data Ocupacion'!Z53 -> 33 | O7: ='Data Ocupacion'!AB53 -> 33 | P7: ='Data Ocupacion'!AD53 -> 0 | Q7: ='Data Ocupacion'!AF53 -> 0 | R7: ='Data Ocupacion'!AH53 -> 5 | S7: ='Data Ocupacion'!AJ53 -> 33 | T7: ='Data Ocupacion'!AL53 -> 33 | U7: ='Data Ocupacion'!AN53 -> 33 | V7: ='Data Ocupacion'!AP53 -> 0 | W7: ='Data Ocupacion'!AR53 -> 0 | X7: ='Data Ocupacion'!AT53 -> 0 | Y7: ='Data Ocupacion'!AV53 -> 26 | Z7: ='Data Ocupacion'!AX53 -> 33 | AA7: ='Data Ocupacion'!AZ53 -> 33 | AB7: ='Data Ocupacion'!BB53 -> 33 | AC7: ='Data Ocupacion'!BD53 -> 33 | AD7: ='Data Ocupacion'!BF53 -> 0 | AE7: ='Data Ocupacion'!BH53 -> 0 | AF7: ='Data Ocupacion'!BJ53 -> 33
A8: Servicios SA-PU | B8: 29.11 | C8: ='Data Ocupacion'!D54 -> 0 | D8: ='Data Ocupacion'!F54 -> 32 | E8: ='Data Ocupacion'!H54 -> 32 | F8: ='Data Ocupacion'!J54 -> 32 | G8: ='Data Ocupacion'!L54 -> 32 | H8: ='Data Ocupacion'!N54 -> 32 | I8: ='Data Ocupacion'!P54 -> 0 | J8: ='Data Ocupacion'!R54 -> 0 | K8: ='Data Ocupacion'!T54 -> 32 | L8: ='Data Ocupacion'!V54 -> 32 | M8: ='Data Ocupacion'!X54 -> 32 | N8: ='Data Ocupacion'!Z54 -> 32 | O8: ='Data Ocupacion'!AB54 -> 32 | P8: ='Data Ocupacion'!AD54 -> 0 | Q8: ='Data Ocupacion'!AF54 -> 0 | R8: ='Data Ocupacion'!AH54 -> 6 | S8: ='Data Ocupacion'!AJ54 -> 32 | T8: ='Data Ocupacion'!AL54 -> 32 | U8: ='Data Ocupacion'!AN54 -> 32 | V8: ='Data Ocupacion'!AP54 -> 0 | W8: ='Data Ocupacion'!AR54 -> 0 | X8: ='Data Ocupacion'!AT54 -> 0 | Y8: ='Data Ocupacion'!AV54 -> 30 | Z8: ='Data Ocupacion'!AX54 -> 32 | AA8: ='Data Ocupacion'!AZ54 -> 32 | AB8: ='Data Ocupacion'!BB54 -> 32 | AC8: ='Data Ocupacion'!BD54 -> 32 | AD8: ='Data Ocupacion'!BF54 -> 0 | AE8: ='Data Ocupacion'!BH54 -> 0 | AF8: ='Data Ocupacion'!BJ54 -> 32
A9: Servicios PU-EB | B9: 25.4 | C9: ='Data Ocupacion'!D55 -> 0 | D9: ='Data Ocupacion'!F55 -> 0 | E9: ='Data Ocupacion'!H55 -> 0 | F9: ='Data Ocupacion'!J55 -> 0 | G9: ='Data Ocupacion'!L55 -> 0 | H9: ='Data Ocupacion'!N55 -> 0 | I9: ='Data Ocupacion'!P55 -> 0 | J9: ='Data Ocupacion'!R55 -> 0 | K9: ='Data Ocupacion'!T55 -> 0 | L9: ='Data Ocupacion'!V55 -> 0 | M9: ='Data Ocupacion'!X55 -> 0 | N9: ='Data Ocupacion'!Z55 -> 0 | O9: ='Data Ocupacion'!AB55 -> 0 | P9: ='Data Ocupacion'!AD55 -> 0 | Q9: ='Data Ocupacion'!AF55 -> 0 | R9: ='Data Ocupacion'!AH55 -> 0 | S9: ='Data Ocupacion'!AJ55 -> 0 | T9: ='Data Ocupacion'!AL55 -> 0 | U9: ='Data Ocupacion'!AN55 -> 0 | V9: ='Data Ocupacion'!AP55 -> 0 | W9: ='Data Ocupacion'!AR55 -> 0 | X9: ='Data Ocupacion'!AT55 -> 0 | Y9: ='Data Ocupacion'!AV55 -> 0 | Z9: ='Data Ocupacion'!AX55 -> 0 | AA9: ='Data Ocupacion'!AZ55 -> 0 | AB9: ='Data Ocupacion'!BB55 -> 0 | AC9: ='Data Ocupacion'!BD55 -> 0 | AD9: ='Data Ocupacion'!BF55 -> 0 | AE9: ='Data Ocupacion'!BH55 -> 0 | AF9: ='Data Ocupacion'!BJ55 -> 0
A10: Servicios EB-PU | B10: 25.4 | C10: ='Data Ocupacion'!D56 -> 0 | D10: ='Data Ocupacion'!F56 -> 1 | E10: ='Data Ocupacion'!H56 -> 1 | F10: ='Data Ocupacion'!J56 -> 1 | G10: ='Data Ocupacion'!L56 -> 1 | H10: ='Data Ocupacion'!N56 -> 1 | I10: ='Data Ocupacion'!P56 -> 0 | J10: ='Data Ocupacion'!R56 -> 0 | K10: ='Data Ocupacion'!T56 -> 1 | L10: ='Data Ocupacion'!V56 -> 1 | M10: ='Data Ocupacion'!X56 -> 1 | N10: ='Data Ocupacion'!Z56 -> 1 | O10: ='Data Ocupacion'!AB56 -> 1 | P10: ='Data Ocupacion'!AD56 -> 0 | Q10: ='Data Ocupacion'!AF56 -> 0 | R10: ='Data Ocupacion'!AH56 -> 0 | S10: ='Data Ocupacion'!AJ56 -> 1 | T10: ='Data Ocupacion'!AL56 -> 1 | U10: ='Data Ocupacion'!AN56 -> 1 | V10: ='Data Ocupacion'!AP56 -> 0 | W10: ='Data Ocupacion'!AR56 -> 0 | X10: ='Data Ocupacion'!AT56 -> 0 | Y10: ='Data Ocupacion'!AV56 -> 1 | Z10: ='Data Ocupacion'!AX56 -> 1 | AA10: ='Data Ocupacion'!AZ56 -> 1 | AB10: ='Data Ocupacion'!BB56 -> 1 | AC10: ='Data Ocupacion'!BD56 -> 1 | AD10: ='Data Ocupacion'!BF56 -> 0 | AE10: ='Data Ocupacion'!BH56 -> 0 | AF10: ='Data Ocupacion'!BJ56 -> 1
A11: Servicios MI-LI | B11: 35.73 | Y11: ='Data Ocupacion'!AV57 -> 12
A12: Servicios LI-MI | B12: 35.73 | Y12: ='Data Ocupacion'!AV58 -> 15
A13: Servicios PU-RE | B13: 6 | Y13: ='Data Ocupacion'!AV59 -> 4
A14: Servicios MI-SA | B14: 21.7 | Y14: ='Data Ocupacion'!AV60 -> 1
A15: Servicios SA-MI | B15: 21.7 | Y15: ='Data Ocupacion'!AV61 -> 1
A17: Trenes PU-LI | B17: 43.13 | C17: ='Data Ocupacion'!D63 -> 59 | D17: ='Data Ocupacion'!F63 -> 111 | E17: ='Data Ocupacion'!H63 -> 112 | F17: ='Data Ocupacion'!J63 -> 111 | G17: ='Data Ocupacion'!L63 -> 112 | H17: ='Data Ocupacion'!N63 -> 112 | I17: ='Data Ocupacion'!P63 -> 75 | J17: ='Data Ocupacion'!R63 -> 57 | K17: ='Data Ocupacion'!T63 -> 111 | L17: ='Data Ocupacion'!V63 -> 111 | M17: ='Data Ocupacion'!X63 -> 112 | N17: ='Data Ocupacion'!Z63 -> 110 | O17: ='Data Ocupacion'!AB63 -> 111 | P17: ='Data Ocupacion'!AD63 -> 75 | Q17: ='Data Ocupacion'!AF63 -> 56 | R17: ='Data Ocupacion'!AH63 -> 82 | S17: ='Data Ocupacion'!AJ63 -> 111 | T17: ='Data Ocupacion'!AL63 -> 111 | U17: ='Data Ocupacion'!AN63 -> 111 | V17: ='Data Ocupacion'!AP63 -> 57 | W17: ='Data Ocupacion'!AR63 -> 75 | X17: ='Data Ocupacion'!AT63 -> 57 | Y17: ='Data Ocupacion'!AV63 -> 90 | Z17: ='Data Ocupacion'!AX63 -> 111 | AA17: ='Data Ocupacion'!AZ63 -> 110 | AB17: ='Data Ocupacion'!BB63 -> 112 | AC17: ='Data Ocupacion'!BD63 -> 111 | AD17: ='Data Ocupacion'!BF63 -> 75 | AE17: ='Data Ocupacion'!BH63 -> 72 | AF17: ='Data Ocupacion'!BJ63 -> 104
A18: Trenes LI-PU | B18: 43.13 | C18: ='Data Ocupacion'!D64 -> 59 | D18: ='Data Ocupacion'!F64 -> 111 | E18: ='Data Ocupacion'!H64 -> 112 | F18: ='Data Ocupacion'!J64 -> 111 | G18: ='Data Ocupacion'!L64 -> 111 | H18: ='Data Ocupacion'!N64 -> 112 | I18: ='Data Ocupacion'!P64 -> 75 | J18: ='Data Ocupacion'!R64 -> 57 | K18: ='Data Ocupacion'!T64 -> 112 | L18: ='Data Ocupacion'!V64 -> 111 | M18: ='Data Ocupacion'!X64 -> 112 | N18: ='Data Ocupacion'!Z64 -> 110 | O18: ='Data Ocupacion'!AB64 -> 111 | P18: ='Data Ocupacion'!AD64 -> 75 | Q18: ='Data Ocupacion'!AF64 -> 57 | R18: ='Data Ocupacion'!AH64 -> 78 | S18: ='Data Ocupacion'!AJ64 -> 111 | T18: ='Data Ocupacion'!AL64 -> 111 | U18: ='Data Ocupacion'!AN64 -> 111 | V18: ='Data Ocupacion'!AP64 -> 57 | W18: ='Data Ocupacion'!AR64 -> 75 | X18: ='Data Ocupacion'!AT64 -> 57 | Y18: ='Data Ocupacion'!AV64 -> 91 | Z18: ='Data Ocupacion'!AX64 -> 111 | AA18: ='Data Ocupacion'!AZ64 -> 110 | AB18: ='Data Ocupacion'!BB64 -> 112 | AC18: ='Data Ocupacion'!BD64 -> 111 | AD18: ='Data Ocupacion'!BF64 -> 75 | AE18: ='Data Ocupacion'!BH64 -> 72 | AF18: ='Data Ocupacion'!BJ64 -> 104
A19: Trenes PU-SA | B19: 29.11 | C19: ='Data Ocupacion'!D65 -> 0 | D19: ='Data Ocupacion'!F65 -> 37 | E19: ='Data Ocupacion'!H65 -> 37 | F19: ='Data Ocupacion'!J65 -> 37 | G19: ='Data Ocupacion'!L65 -> 37 | H19: ='Data Ocupacion'!N65 -> 37 | I19: ='Data Ocupacion'!P65 -> 0 | J19: ='Data Ocupacion'!R65 -> 0 | K19: ='Data Ocupacion'!T65 -> 38 | L19: ='Data Ocupacion'!V65 -> 38 | M19: ='Data Ocupacion'!X65 -> 37 | N19: ='Data Ocupacion'!Z65 -> 35 | O19: ='Data Ocupacion'!AB65 -> 37 | P19: ='Data Ocupacion'!AD65 -> 0 | Q19: ='Data Ocupacion'!AF65 -> 0 | R19: ='Data Ocupacion'!AH65 -> 5 | S19: ='Data Ocupacion'!AJ65 -> 37 | T19: ='Data Ocupacion'!AL65 -> 37 | U19: ='Data Ocupacion'!AN65 -> 38 | V19: ='Data Ocupacion'!AP65 -> 0 | W19: ='Data Ocupacion'!AR65 -> 0 | X19: ='Data Ocupacion'!AT65 -> 0 | Y19: ='Data Ocupacion'!AV65 -> 30 | Z19: ='Data Ocupacion'!AX65 -> 37 | AA19: ='Data Ocupacion'!AZ65 -> 37 | AB19: ='Data Ocupacion'!BB65 -> 37 | AC19: ='Data Ocupacion'!BD65 -> 37 | AD19: ='Data Ocupacion'!BF65 -> 0 | AE19: ='Data Ocupacion'!BH65 -> 0 | AF19: ='Data Ocupacion'!BJ65 -> 36
A20: Trenes SA-PU | B20: 29.11 | C20: ='Data Ocupacion'!D66 -> 0 | D20: ='Data Ocupacion'!F66 -> 36 | E20: ='Data Ocupacion'!H66 -> 36 | F20: ='Data Ocupacion'!J66 -> 36 | G20: ='Data Ocupacion'!L66 -> 37 | H20: ='Data Ocupacion'!N66 -> 36 | I20: ='Data Ocupacion'!P66 -> 0 | J20: ='Data Ocupacion'!R66 -> 0 | K20: ='Data Ocupacion'!T66 -> 37 | L20: ='Data Ocupacion'!V66 -> 38 | M20: ='Data Ocupacion'!X66 -> 36 | N20: ='Data Ocupacion'!Z66 -> 34 | O20: ='Data Ocupacion'!AB66 -> 36 | P20: ='Data Ocupacion'!AD66 -> 0 | Q20: ='Data Ocupacion'!AF66 -> 0 | R20: ='Data Ocupacion'!AH66 -> 6 | S20: ='Data Ocupacion'!AJ66 -> 36 | T20: ='Data Ocupacion'!AL66 -> 36 | U20: ='Data Ocupacion'!AN66 -> 37 | V20: ='Data Ocupacion'!AP66 -> 0 | W20: ='Data Ocupacion'!AR66 -> 0 | X20: ='Data Ocupacion'!AT66 -> 0 | Y20: ='Data Ocupacion'!AV66 -> 34 | Z20: ='Data Ocupacion'!AX66 -> 36 | AA20: ='Data Ocupacion'!AZ66 -> 36 | AB20: ='Data Ocupacion'!BB66 -> 36 | AC20: ='Data Ocupacion'!BD66 -> 36 | AD20: ='Data Ocupacion'!BF66 -> 0 | AE20: ='Data Ocupacion'!BH66 -> 0 | AF20: ='Data Ocupacion'!BJ66 -> 35
A21: Trenes EB-PU | B21: 25.4 | C21: ='Data Ocupacion'!D68 -> 0 | D21: ='Data Ocupacion'!F68 -> 1 | E21: ='Data Ocupacion'!H68 -> 1 | F21: ='Data Ocupacion'!J68 -> 1 | G21: ='Data Ocupacion'!L68 -> 1 | H21: ='Data Ocupacion'!N68 -> 1 | I21: ='Data Ocupacion'!P68 -> 0 | J21: ='Data Ocupacion'!R68 -> 0 | K21: ='Data Ocupacion'!T68 -> 1 | L21: ='Data Ocupacion'!V68 -> 1 | M21: ='Data Ocupacion'!X68 -> 1 | N21: ='Data Ocupacion'!Z68 -> 1 | O21: ='Data Ocupacion'!AB68 -> 1 | P21: ='Data Ocupacion'!AD68 -> 0 | Q21: ='Data Ocupacion'!AF68 -> 0 | R21: ='Data Ocupacion'!AH68 -> 0 | S21: ='Data Ocupacion'!AJ68 -> 1 | T21: ='Data Ocupacion'!AL68 -> 1 | U21: ='Data Ocupacion'!AN68 -> 1 | V21: ='Data Ocupacion'!AP68 -> 0 | W21: ='Data Ocupacion'!AR68 -> 0 | X21: ='Data Ocupacion'!AT68 -> 0 | Y21: ='Data Ocupacion'!AV68 -> 1 | Z21: ='Data Ocupacion'!AX68 -> 1 | AA21: ='Data Ocupacion'!AZ68 -> 1 | AB21: ='Data Ocupacion'!BB68 -> 1 | AC21: ='Data Ocupacion'!BD68 -> 1 | AD21: ='Data Ocupacion'!BF68 -> 0 | AE21: ='Data Ocupacion'!BH68 -> 0 | AF21: ='Data Ocupacion'!BJ68 -> 1
A22: Trenes PU-EB | B22: 25.4 | C22: 0 | D22: 0 | E22: 0 | F22: 0 | G22: 0 | H22: 0 | I22: 0 | K22: 0 | L22: 0 | M22: 0 | N22: 0 | O22: 0 | P22: 0 | Q22: 0 | R22: 0 | S22: 0 | T22: 0 | U22: 0 | V22: 0 | W22: 0 | X22: 0 | Y22: 0 | Z22: 0 | AA22: 0 | AB22: 0 | AC22: 0 | AD22: 0 | AE22: 0 | AF22: 0
A23: Trenes MI-LI | B23: 35.73 | Y23: ='Data Ocupacion'!AV69 -> 14
A24: Trenes LI-MI | B24: 35.73 | Y24: ='Data Ocupacion'!AV70 -> 17
A25: Trenes PU-RE | B25: 6 | Y25: ='Data Ocupacion'!AV71 -> 6
A26: Trenes MI-SA | B26: 21.7 | Y26: ='Data Ocupacion'!AV72 -> 1
A27: Trenes SA-MI | B27: 21.7 | Y27: ='Data Ocupacion'!AV73 -> 1
A29: Corte EB (600) | B29: -17.73 | C29: ='KM-Servicio'!Q5 -> 0 | D29: ='KM-Servicio'!Q12 -> 3 | E29: ='KM-Servicio'!Q19 -> 4 | F29: ='KM-Servicio'!Q26 -> 3 | G29: ='KM-Servicio'!Q33 -> 5 | H29: ='KM-Servicio'!Q40 -> 4 | I29: ='KM-Servicio'!Q47 -> 0 | J29: ='KM-Servicio'!Q54 -> 0 | K29: ='KM-Servicio'!Q61 -> 4 | L29: ='KM-Servicio'!Q68 -> 3 | M29: ='KM-Servicio'!Q75 -> 3 | N29: ='KM-Servicio'!Q82 -> 0 | O29: ='KM-Servicio'!Q89 -> 1 | P29: ='KM-Servicio'!Q96 -> 0 | Q29: ='KM-Servicio'!Q103 -> 0 | R29: ='KM-Servicio'!Q110 -> 0 | S29: ='KM-Servicio'!Q117 -> 5 | T29: ='KM-Servicio'!Q124 -> 5 | U29: ='KM-Servicio'!Q131 -> 6 | V29: ='KM-Servicio'!Q138 -> 0 | W29: ='KM-Servicio'!Q145 -> 0 | X29: ='KM-Servicio'!Q152 -> 0 | Y29: ='KM-Servicio'!Q159 -> 4 | Z29: ='KM-Servicio'!Q171 -> 5 | AA29: ='KM-Servicio'!Q178 -> 5 | AB29: ='KM-Servicio'!Q185 -> 4 | AC29: ='KM-Servicio'!Q192 -> 3 | AD29: ='KM-Servicio'!Q199 -> 0 | AE29: ='KM-Servicio'!Q206 -> 0 | AF29: ='KM-Servicio'!Q213 -> 3
A30: Acople EB (600) | B30: -17.73 | C30: ='KM-Servicio'!T6 -> 0 | D30: ='KM-Servicio'!T13 -> 4 | E30: ='KM-Servicio'!T20 -> 2 | F30: ='KM-Servicio'!T27 -> 4 | G30: ='KM-Servicio'!T34 -> 7 | H30: ='KM-Servicio'!T41 -> 3 | I30: ='KM-Servicio'!T48 -> 0 | J30: ='KM-Servicio'!T55 -> 0 | K30: ='KM-Servicio'!T62 -> 6 | L30: ='KM-Servicio'!T69 -> 6 | M30: ='KM-Servicio'!T76 -> 5 | N30: ='KM-Servicio'!T83 -> 2 | O30: ='KM-Servicio'!T90 -> 3 | P30: ='KM-Servicio'!T97 -> 0 | Q30: ='KM-Servicio'!T104 -> 0 | R30: ='KM-Servicio'!T111 -> 0 | S30: ='KM-Servicio'!T118 -> 6 | T30: ='KM-Servicio'!T125 -> 6 | U30: ='KM-Servicio'!T132 -> 6 | V30: ='KM-Servicio'!T139 -> 0 | W30: ='KM-Servicio'!T146 -> 0 | X30: ='KM-Servicio'!T153 -> 0 | Y30: ='KM-Servicio'!T160 -> 4 | Z30: ='KM-Servicio'!T172 -> 6 | AA30: ='KM-Servicio'!T179 -> 4 | AB30: ='KM-Servicio'!T186 -> 4 | AC30: ='KM-Servicio'!T193 -> 5 | AD30: ='KM-Servicio'!T200 -> 0 | AE30: ='KM-Servicio'!T207 -> 0 | AF30: ='KM-Servicio'!T214 -> 5
A31: Acople/Corte SA (600) | B31: -14.02 | C31: ='KM-Servicio'!U6 -> 0 | D31: ='KM-Servicio'!U13 -> 0 | E31: ='KM-Servicio'!U20 -> 0 | F31: ='KM-Servicio'!U27 -> 0 | G31: ='KM-Servicio'!U34 -> 0 | H31: ='KM-Servicio'!U41 -> 0 | I31: ='KM-Servicio'!U48 -> 0 | J31: ='KM-Servicio'!U55 -> 0 | K31: ='KM-Servicio'!U62 -> 0 | L31: ='KM-Servicio'!U69 -> 0 | M31: ='KM-Servicio'!U76 -> 0 | N31: ='KM-Servicio'!U83 -> 0 | O31: ='KM-Servicio'!U90 -> 0 | P31: ='KM-Servicio'!U97 -> 0 | Q31: ='KM-Servicio'!U104 -> 0 | R31: ='KM-Servicio'!U111 -> 0 | S31: ='KM-Servicio'!U118 -> 0 | T31: ='KM-Servicio'!U125 -> 0 | U31: ='KM-Servicio'!U132 -> 0 | V31: ='KM-Servicio'!U139 -> 0 | W31: ='KM-Servicio'!U146 -> 0 | X31: ='KM-Servicio'!U153 -> 0 | Y31: ='KM-Servicio'!U160 -> 0 | Z31: ='KM-Servicio'!U172 -> 0 | AA31: ='KM-Servicio'!U179 -> 2 | AB31: ='KM-Servicio'!U186 -> 0 | AC31: ='KM-Servicio'!U193 -> 0 | AD31: ='KM-Servicio'!U200 -> 0 | AE31: ='KM-Servicio'!U207 -> 0 | AF31: ='KM-Servicio'!U214 -> 0
A32: Corte EB (400) | B32: -3.71 | E32: ='KM-Servicio'!Q21 -> 0 | G32: ='KM-Servicio'!Q35 -> 0 | N32: ='KM-Servicio'!Q84 -> 0
A33: Acople EB (600) vía 1 | B33: 17.73
A34: Acople PE (600) via 2 | B34: -12.73 | H34: 1
A36: Servicios | B36: =SUM(C36:AF36) -> 5606 | C36: =SUM(C5:C10) -> 115 | D36: =SUM(D5:D10) -> 223 | E36: =SUM(E5:E10) -> 223 | F36: =SUM(F5:F10) -> 223 | G36: =SUM(G5:G10) -> 223 | H36: =SUM(H5:H10) -> 223 | I36: =SUM(I5:I10) -> 147 | J36: =SUM(J5:J10) -> 111 | ... X36: =SUM(X5:X10) -> 111 | Y36: =SUM(Y5:Y15) -> 213 | Z36: =SUM(Z5:Z10) -> 223 | AA36: =SUM(AA5:AA10) -> 223 | AB36: =SUM(AB5:AB10) -> 223 | AC36: =SUM(AC5:AC10) -> 223 | AD36: =SUM(AD5:AD10) -> 147 | AE36: =SUM(AE5:AE10) -> 122 | AF36: =SUM(AF5:AF10) -> 223
A37: Trenes | B37: =SUM(C37:AF37) -> 7095 | C37: =SUM(C17:C22) -> 118 | D37: =SUM(D17:D22) -> 296 | E37: =SUM(E17:E22) -> 298 | F37: =SUM(F17:F22) -> 296 | G37: =SUM(G17:G22) -> 298 | H37: =SUM(H17:H22) -> 298 | I37: =SUM(I17:I22) -> 150 | J37: =SUM(J17:J22) -> 114 | ... X37: =SUM(X17:X22) -> 114 | Y37: =SUM(Y17:Y27) -> 285 | Z37: =SUM(Z17:Z22) -> 296 | AA37: =SUM(AA17:AA22) -> 294 | AB37: =SUM(AB17:AB22) -> 298 | AC37: =SUM(AC17:AC22) -> 296 | AD37: =SUM(AD17:AD22) -> 150 | AE37: =SUM(AE17:AE22) -> 144 | AF37: =SUM(AF17:AF22) -> 280
A38: Trenes KM | B38: =SUM(C38:AF38) -> 282831.51 | C38: =(C17*$B$17+C18*$B$18+C19*$B$19+C20*$B$20+C22*$B$22+C30*$B$30+C21*$B$21+C29*$B$29+C31*$B$31+C32*$B$32+C33*B33) -> 5089.34 | D38: =(D17*$B$17+D18*$B$18+D19*$B$19+D20*$B$20+D22*$B$22+D30*$B$30+D21*$B$21+D29*$B$29+D31*$B$31+D32*$B$32+D33*B33) -> 11601.18 | E38: =(E17*$B$17+E18*$B$18+E19*$B$19+E20*$B$20+E22*$B$22+E30*$B$30+E21*$B$21+E29*$B$29+E31*$B$31+E32*$B$32+E33*B33) -> 11705.17 | F38: =(F17*$B$17+F18*$B$18+F19*$B$19+F20*$B$20+F22*$B$22+F30*$B$30+F21*$B$21+F29*$B$29+F31*$B$31+F32*$B$32+F33*B33) -> 11601.18 | G38: =(G17*$B$17+G18*$B$18+G19*$B$19+G20*$B$20+G22*$B$22+G30*$B$30+G21*$B$21+G29*$B$29+G31*$B$31+G32*$B$32+G33*B33) -> 11584.77 | H38: =(H17*$B$17+H18*$B$18+H19*$B$19+H20*$B$20+H22*$B$22+H30*$B$30+H21*$B$21+H29*$B$29+H31*$B$31+H32*$B$32+H33*B33+H34*B34) -> 11674.71 | I38: =(I17*$B$17+I18*$B$18+I19*$B$19+I20*$B$20+I22*$B$22+I30*$B$30+I21*$B$21+I29*$B$29+I31*$B$31+I32*$B$32+I33*B33) -> 6469.5 | J38: =(J17*$B$17+J18*$B$18+J19*$B$19+J20*$B$20+J22*$B$22+J30*$B$30+J21*$B$21+J29*$B$29+J31*$B$31+J32*$B$32+J33*B33) -> 4916.82 | K38: =(K17*$B$17+K18*$B$18+K19*$B$19+K20*$B$20+K22*$B$22+K30*$B$30+K21*$B$21+K29*$B$29+K31*$B$31+K32*$B$32+K33*B33) -> 11649.34 | L38: =(L17*$B$17+L18*$B$18+L19*$B$19+L20*$B$20+L22*$B$22+L30*$B$30+L21*$B$21+L29*$B$29+L31*$B$31+L32*$B$32+L33*B33) -> 11653.05 | M38: =(M17*$B$17+M18*$B$18+M19*$B$19+M20*$B$20+M22*$B$22+M30*$B$30+M21*$B$21+M29*$B$29+M31*$B$31+M32*$B$32+M33*B33) -> 11669.71 | N38: =(N17*$B$17+N18*$B$18+N19*$B$19+N20*$B$20+N22*$B$22+N30*$B$30+N21*$B$21+N29*$B$29+N31*$B$31+N32*$B$32+N33*B33) -> 11487.13 | O38: =(O17*$B$17+O18*$B$18+O19*$B$19+O20*$B$20+O22*$B$22+O30*$B$30+O21*$B$21+O29*$B$29+O31*$B$31+O32*$B$32+O33*B33) -> 11654.37 | P38: =(P17*$B$17+P18*$B$18+P19*$B$19+P20*$B$20+P22*$B$22+P30*$B$30+P21*$B$21+P29*$B$29+P31*$B$31+P32*$B$32+P33*B33) -> 6469.5 | Q38: =(Q17*$B$17+Q18*$B$18+Q19*$B$19+Q20*$B$20+Q22*$B$22+Q30*$B$30+Q21*$B$21+Q29*$B$29+Q31*$B$31+Q32*$B$32) -> 4873.69 | R38: =(R17*$B$17+R18*$B$18+R19*$B$19+R20*$B$20+R22*$B$22+R30*$B$30+R21*$B$21+R29*$B$29+R31*$B$31+R33*$B$33) -> 7221.01 | S38: =(S17*$B$17+S18*$B$18+S19*$B$19+S20*$B$20+S22*$B$22+S30*$B$30+S21*$B$21+S29*$B$29+S31*$B$31+S32*$B$32) -> 11530.26 | T38: =(T17*$B$17+T18*$B$18+T19*$B$19+T20*$B$20+T22*$B$22+T30*$B$30+T21*$B$21+T29*$B$29+T31*$B$31+T32*$B$32) -> 11530.26 | U38: =(U17*$B$17+U18*$B$18+U19*$B$19+U20*$B$20+U22*$B$22+U30*$B$30+U21*$B$21+U29*$B$29+U31*$B$31+U32*$B$32+U33*B33) -> 11570.75 | V38: =(V17*$B$17+V18*$B$18+V19*$B$19+V20*$B$20+V22*$B$22+V30*$B$30+V21*$B$21+V29*$B$29+V31*$B$31+V32*$B$32+V33*B33) -> 4916.82 | W38: =(W17*$B$17+W18*$B$18+W19*$B$19+W20*$B$20+W22*$B$22+W30*$B$30+W21*$B$21+W29*$B$29+W31*$B$31+W33*$B$33) -> 6469.5 | X38: =(X17*$B$17+X18*$B$18+X19*$B$19+X20*$B$20+X22*$B$22+X30*$B$30+X21*$B$21+X29*$B$29+X31*$B$31+X33*$B$33) -> 4916.82 | Y38: =(Y17*$B$17+Y18*$B$18+Y19*$B$19+Y20*$B$20+Y22*$B$22+Y30*$B$30+Y21*$B$21+Y29*$B$29+Y31*$B$31+Y33*$B$33+Y23*B23+Y24*B24+Y25*B25+Y26*B26+Y27*B27) -> 10740.16 | Z38: =(Z17*$B$17+Z18*$B$18+Z19*$B$19+Z20*$B$20+Z22*$B$22+Z30*$B$30+Z21*$B$21+Z29*$B$29+Z31*$B$31+Z33*$B$33) -> 11530.26 | AA38: =(AA17*$B$17+AA18*$B$18+AA19*$B$19+AA20*$B$20+AA22*$B$22+AA30*$B$30+AA21*$B$21+AA29*$B$29+AA31*$B$31+AA33*$B$33) -> 11451.42 | AB38: =(AB17*$B$17+AB18*$B$18+AB19*$B$19+AB20*$B$20+AB22*$B$22+AB30*$B$30+AB21*$B$21+AB29*$B$29+AB31*$B$31+AB33*$B$33) -> 11669.71 | AC38: =(AC17*$B$17+AC18*$B$18+AC19*$B$19+AC20*$B$20+AC22*$B$22+AC30*$B$30+AC21*$B$21+AC29*$B$29+AC31*$B$31+AC32*$B$32+AC33*B33) -> 11583.45 | AD38: =(AD17*$B$17+AD18*$B$18+AD19*$B$19+AD20*$B$20+AD22*$B$22+AD30*$B$30+AD21*$B$21+AD29*$B$29+AD31*$B$31+AD32*$B$32+AD33*B33) -> 6469.5 | AE38: =(AE17*$B$17+AE18*$B$18+AE19*$B$19+AE20*$B$20+AE22*$B$22+AE30*$B$30+AE21*$B$21+AE29*$B$29+AE31*$B$31+AE33*$B$33) -> 6210.72 | AF38: =(AF17*$B$17+AF18*$B$18+AF19*$B$19+AF20*$B$20+AF22*$B$22+AF30*$B$30+AF21*$B$21+AF29*$B$29+AF31*$B$31+AF32*$B$32) -> 10921.41
A39: Servicios KM | B39: =SUM(C39:AF39) -> 223715.99 | C39: =$B$5*C5+$B$6*C6+$B$7*C7+$B$8*C8+$B$10*C10+$B$9*C9 -> 4959.95 | D39: =$B$5*D5+$B$6*D6+$B$7*D7+$B$8*D8+$B$10*D10+$B$9*D9 -> 8688.96 | E39: =$B$5*E5+$B$6*E6+$B$7*E7+$B$8*E8+$B$10*E10+$B$9*E9 -> 8688.96 | F39: =$B$5*F5+$B$6*F6+$B$7*F7+$B$8*F8+$B$10*F10+$B$9*F9 -> 8688.96 | G39: =$B$5*G5+$B$6*G6+$B$7*G7+$B$8*G8+$B$10*G10+$B$9*G9 -> 8688.96 | H39: =$B$5*H5+$B$6*H6+$B$7*H7+$B$8*H8+$B$10*H10+$B$9*H9 -> 8688.96 | I39: =$B$5*I5+$B$6*I6+$B$7*I7+$B$8*I8+$B$10*I10+$B$9*I9 -> 6340.11 | J39: =$B$5*J5+$B$6*J6+$B$7*J7+$B$8*J8+$B$10*J10+$B$9*J9 -> 4787.43 | ... X39: =$B$5*X5+$B$6*X6+$B$7*X7+$B$8*X8+$B$10*X10+$B$9*X9 -> 4787.43 | Y39: =$B$5*Y5+$B$6*Y6+$B$7*Y7+$B$8*Y8+$B$10*Y10+$B$9*Y9+Y11*B11+Y12*B12+Y13*B13+Y14*B14+Y15*B15 -> 7992.66 | Z39: =$B$5*Z5+$B$6*Z6+$B$7*Z7+$B$8*Z8+$B$10*Z10+$B$9*Z9 -> 8688.96 | AA39: =$B$5*AA5+$B$6*AA6+$B$7*AA7+$B$8*AA8+$B$10*AA10+$B$9*AA9 -> 8688.96 | AB39: =$B$5*AB5+$B$6*AB6+$B$7*AB7+$B$8*AB8+$B$10*AB10+$B$9*AB9 -> 8688.96 | AC39: =$B$5*AC5+$B$6*AC6+$B$7*AC7+$B$8*AC8+$B$10*AC10+$B$9*AC9 -> 8688.96 | AD39: =$B$5*AD5+$B$6*AD6+$B$7*AD7+$B$8*AD8+$B$10*AD10+$B$9*AD9 -> 6340.11 | AE39: =$B$5*AE5+$B$6*AE6+$B$7*AE7+$B$8*AE8+$B$10*AE10+$B$9*AE9 -> 5261.86 | AF39: =$B$5*AF5+$B$6*AF6+$B$7*AF7+$B$8*AF8+$B$10*AF10+$B$9*AF9 -> 8688.96
A40: Asientos KM | B40: =SUM(C40:AF40) -> 29414477 | C40: =C38*104 -> 529291.36 | D40: =D38*104 -> 1206522.7 | E40: =E38*104 -> 1217337.7 | F40: =F38*104 -> 1206522.7 | G40: =G38*104 -> 1204816.1 | H40: =H38*104 -> 1214169.8 | I40: =I38*104 -> 672828 | J40: =J38*104 -> 511349.28 | ... AF40: =AF38*104 -> 1135826.6
A41: Coches KM | B41: =SUM(C41:AF41) -> 565663.02 | C41: =C38*2 -> 10178.68 | D41: =D38*2 -> 23202.36 | E41: =E38*2 -> 23410.34 | F41: =F38*2 -> 23202.36 | G41: =G38*2 -> 23169.54 | H41: =H38*2 -> 23349.42 | I41: =I38*2 -> 12939 | J41: =J38*2 -> 9833.64 | ... AF41: =AF38*2 -> 21842.82
A42: Capacidad Total | B42: =SUM(C42:AF42) -> 2568390 | C42: =+C37*362 -> 42716 | D42: =+D37*362 -> 107152 | E42: =+E37*362 -> 107876 | F42: =+F37*362 -> 107152 | G42: =+G37*362 -> 107876 | H42: =+H37*362 -> 107876 | I42: =+I37*362 -> 54300 | J42: =+J37*362 -> 41268 | ... AF42: =+AF37*362 -> 101360
A43: Ton Km Brutas | B43: =SUM(C43:AF43) -> 22428539 | C43: =C38*79.3 -> 403584.66 | D43: =D38*79.3 -> 919973.57 | E43: =E38*79.3 -> 928219.98 | F43: =F38*79.3 -> 919973.57 | G43: =G38*79.3 -> 918672.26 | H43: =H38*79.3 -> 925804.5 | I43: =I38*79.3 -> 513031.35 | J43: =J38*79.3 -> 389903.83 | ... AF43: =AF38*79.3 -> 866067.81

Sheet Data Ocupacion
D1: 45809 | F1: 45810 | H1: 45811 | J1: 45812 | L1: 45813 | N1: 45814 | P1: 45815 | R1: 45816 | T1: 45817 | V1: 45818 | X1: 45819 | Z1: 45820 | AB1: 45821 | AD1: 45822 | AF1: 45823 | AH1: 45824 | AJ1: 45825 | AL1: 45826 | AN1: 45827 | AP1: 45828 | AR1: 45829 | AT1: 45830 | AV1: 45831 | AX1: 45832 | AZ1: 45833 | BB1: 45834 | BD1: 45835 | BF1: 45836 | BH1: 45837 | BJ1: 45838
D2: S | E2: M | F2: S | G2: M | H2: S | I2: M | J2: S | K2: M | L2: S | M2: M | N2: S | O2: M | P2: S | Q2: M | R2: S | S2: M | T2: S | U2: M | V2: S | W2: M | X2: S | Y2: M | Z2: S | AA2: M | AB2: S | AC2: M | AD2: S | AE2: M | AF2: S | AG2: M | AH2: S | AI2: M | AJ2: S | AK2: M | AL2: S | AM2: M | AN2: S | AO2: M | AP2: S | AQ2: M | AR2: S | AS2: M | AT2: S | AU2: M | AV2: S | AW2: M | AX2: S | AY2: M | AZ2: S | BA2: M | BB2: S | BC2: M | BD2: S | BE2: M | BF2: S | BG2: M | BH2: S | BI2: M | BJ2: S | BK2: M
A3: Servicios PU-SA | D3: 0 | E3: 0 | F3: 7 | G3: 3 | H3: 7 | I3: 3 | J3: 7 | K3: 3 | L3: 7 | M3: 3 | N3: 7 | O3: 3 | P3: 0 | Q3: 0 | R3: 0 | S3: 0 | T3: 6 | U3: 4 | V3: 6 | W3: 4 | X3: 7 | Y3: 3 | Z3: 9 | AA3: 1 | AB3: 7 | AC3: 3 | AD3: 0 | AE3: 0 | AF3: 0 | AG3: 0 | AH3: 0 | AI3: 0 | AJ3: 7 | AK3: 3 | AL3: 7 | AM3: 3 | AN3: 6 | AO3: 4 | AP3: 0 | AQ3: 0 | AR3: 0 | AS3: 0 | AT3: 0 | AU3: 0 | AV3: 7 | AW3: 3 | AX3: 7 | AY3: 3 | AZ3: 7 | BA3: 3 | BB3: 7 | BC3: 3 | BD3: 7 | BE3: 3 | BF3: 0 | BG3: 0 | BH3: 0 | BI3: 0 | BJ3: 7 | BK3: 3
A4: Servicios PU-EB | D4: 0 | E4: 0 | F4: 0 | G4: 0 | H4: 0 | I4: 0 | J4: 0 | K4: 0 | L4: 0 | M4: 0 | N4: 0 | O4: 0 | P4: 0 | Q4: 0 | R4: 0 | S4: 0 | T4: 0 | U4: 0 | V4: 0 | W4: 0 | X4: 0 | Y4: 0 | Z4: 0 | AA4: 0 | AB4: 0 | AC4: 0 | AD4: 0 | AE4: 0 | AF4: 0 | AG4: 0 | AH4: 0 | AI4: 0 | AJ4: 0 | AK4: 0 | AL4: 0 | AM4: 0 | AN4: 0 | AO4: 0 | AP4: 0 | AQ4: 0 | AR4: 0 | AS4: 0 | AT4: 0 | AU4: 0 | AV4: 0 | AW4: 0 | AX4: 0 | AY4: 0 | AZ4: 0 | BA4: 0 | BB4: 0 | BC4: 0 | BD4: 0 | BE4: 0 | BF4: 0 | BG4: 0 | BH4: 0 | BI4: 0 | BJ4: 0 | BK4: 0
A5: Servicios PU-LI | D5: 0 | E5: 0 | F5: 1 | G5: 9 | H5: 1 | I5: 9 | J5: 1 | K5: 9 | L5: 1 | M5: 9 | N5: 0 | O5: 10 | P5: 0 | Q5: 0 | R5: 0 | S5: 0 | T5: 1 | U5: 9 | V5: 1 | W5: 9 | X5: 0 | Y5: 10 | Z5: 2 | AA5: 8 | AB5: 1 | AC5: 9 | AD5: 0 | AE5: 0 | AF5: 0 | AG5: 0 | AH5: 0 | AI5: 9 | AJ5: 1 | AK5: 9 | AL5: 1 | AM5: 9 | AN5: 1 | AO5: 9 | AP5: 2 | AQ5: 1 | AR5: 0 | AS5: 0 | AT5: 0 | AU5: 0 | AV5: 0 | AW5: 10 | AX5: 1 | AY5: 9 | AZ5: 2 | BA5: 8 | BB5: 0 | BC5: 10 | BD5: 1 | BE5: 9 | BF5: 0 | BG5: 0 | BH5: 0 | BI5: 0 | BJ5: 1 | BK5: 9
A6: Servicios SA-PU | D6: 0 | E6: 0 | F6: 9 | G6: 1 | H6: 9 | I6: 1 | J6: 9 | K6: 1 | L6: 8 | M6: 2 | N6: 9 | O6: 1 | P6: 0 | Q6: 0 | R6: 0 | S6: 0 | T6: 8 | U6: 2 | V6: 7 | W6: 3 | X6: 9 | Y6: 1 | Z6: 9 | AA6: 1 | AB6: 9 | AC6: 1 | AD6: 0 | AE6: 0 | AF6: 0 | AG6: 0 | AH6: 0 | AI6: 0 | AJ6: 9 | AK6: 1 | AL6: 9 | AM6: 1 | AN6: 8 | AO6: 2 | AP6: 0 | AQ6: 0 | AR6: 0 | AS6: 0 | AT6: 0 | AU6: 0 | AV6: 9 | AW6: 1 | AX6: 9 | AY6: 1 | AZ6: 9 | BA6: 1 | BB6: 9 | BC6: 1 | BD6: 9 | BE6: 1 | BF6: 0 | BG6: 0 | BH6: 0 | BI6: 0 | BJ6: 10 | BK6: 0
A7: Servicios EB-PU | D7: 0 | E7: 0 | F7: 0 | G7: 0 | H7: 0 | I7: 0 | J7: 0 | K7: 0 | L7: 0 | M7: 0 | N7: 0 | O7: 0 | P7: 0 | Q7: 0 | R7: 0 | S7: 0 | T7: 0 | U7: 0 | V7: 0 | W7: 0 | X7: 0 | Y7: 0 | Z7: 0 | AA7: 0 | AB7: 0 | AC7: 0 | AD7: 0 | AE7: 0 | AF7: 0 | AG7: 0 | AH7: 0 | AI7: 0 | AJ7: 0 | AK7: 0 | AL7: 0 | AM7: 0 | AN7: 0 | AO7: 0 | AP7: 0 | AQ7: 0 | AR7: 0 | AS7: 0 | AT7: 0 | AU7: 0 | AV7: 0 | AW7: 0 | AX7: 0 | AY7: 0 | AZ7: 0 | BA7: 0 | BB7: 0 | BC7: 0 | BD7: 0 | BE7: 0 | BF7: 0 | BG7: 0 | BH7: 0 | BI7: 0 | BJ7: 0 | BK7: 0
A8: Servicios LI-PU | D8: 0 | E8: 0 | F8: 4 | G8: 6 | H8: 4 | I8: 6 | J8: 4 | K8: 6 | L8: 4 | M8: 6 | N8: 3 | O8: 7 | P8: 0 | Q8: 0 | R8: 0 | S8: 0 | T8: 3 | U8: 7 | V8: 4 | W8: 6 | X8: 3 | Y8: 7 | Z8: 5 | AA8: 5 | AB8: 4 | AC8: 6 | AD8: 0 | AE8: 0 | AF8: 0 | AG8: 0 | AH8: 0 | AI8: 8 | AJ8: 4 | AK8: 6 | AL8: 4 | AM8: 6 | AN8: 4 | AO8: 6 | AP8: 6 | AQ8: 0 | AR8: 0 | AS8: 0 | AT8: 0 | AU8: 0 | AV8: 4 | AW8: 6 | AX8: 4 | AY8: 6 | AZ8: 5 | BA8: 5 | BB8: 3 | BC8: 7 | BD8: 4 | BE8: 6 | BF8: 0 | BG8: 0 | BH8: 0 | BI8: 0 | BJ8: 6 | BK8: 4
A10: Servicios PU-SA | D10: 0 | E10: 0 | F10: 15 | G10: 1 | H10: 15 | I10: 1 | J10: 15 | K10: 1 | L10: 15 | M10: 1 | N10: 15 | O10: 1 | P10: 0 | Q10: 0 | R10: 0 | S10: 0 | T10: 15 | U10: 1 | V10: 15 | W10: 1 | X10: 15 | Y10: 1 | Z10: 15 | AA10: 1 | AB10: 15 | AC10: 1 | AD10: 0 | AE10: 0 | AF10: 0 | AG10: 0 | AH10: 1 | AI10: 0 | AJ10: 15 | AK10: 1 | AL10: 15 | AM10: 1 | AN10: 15 | AO10: 1 | AP10: 0 | AQ10: 0 | AR10: 0 | AS10: 0 | AT10: 0 | AU10: 0 | AV10: 9 | AW10: 1 | AX10: 15 | AY10: 1 | AZ10: 15 | BA10: 1 | BB10: 15 | BC10: 1 | BD10: 15 | BE10: 1 | BF10: 0 | BG10: 0 | BH10: 0 | BI10: 0 | BJ10: 16 | BK10: 0
A11: Servicios PU-EB | D11: 0 | E11: 0 | F11: 0 | G11: 0 | H11: 0 | I11: 0 | J11: 0 | K11: 0 | L11: 0 | M11: 0 | N11: 0 | O11: 0 | P11: 0 | Q11: 0 | R11: 0 | S11: 0 | T11: 0 | U11: 0 | V11: 0 | W11: 0 | X11: 0 | Y11: 0 | Z11: 0 | AA11: 0 | AB11: 0 | AC11: 0 | AD11: 0 | AE11: 0 | AF11: 0 | AG11: 0 | AH11: 0 | AI11: 0 | AJ11: 0 | AK11: 0 | AL11: 0 | AM11: 0 | AN11: 0 | AO11: 0 | AP11: 0 | AQ11: 0 | AR11: 0 | AS11: 0 | AT11: 0 | AU11: 0 | AV11: 0 | AW11: 0 | AX11: 0 | AY11: 0 | AZ11: 0 | BA11: 0 | BB11: 0 | BC11: 0 | BD11: 0 | BE11: 0 | BF11: 0 | BG11: 0 | BH11: 0 | BI11: 0 | BJ11: 0 | BK11: 0
A12: Servicios PU-LI | D12: 53 | E12: 3 | F12: 44 | G12: 17 | H12: 43 | I12: 18 | J12: 44 | K12: 17 | L12: 43 | M12: 18 | N12: 44 | O12: 17 | P12: 69 | Q12: 3 | R12: 51 | S12: 3 | T12: 44 | U12: 17 | V12: 44 | W12: 17 | X12: 44 | Y12: 17 | Z12: 44 | AA12: 17 | AB12: 44 | AC12: 17 | AD12: 69 | AE12: 3 | AF12: 52 | AG12: 2 | AH12: 13 | AI12: 18 | AJ12: 44 | AK12: 17 | AL12: 44 | AM12: 17 | AN12: 44 | AO12: 17 | AP12: 43 | AQ12: 2 | AR12: 69 | AS12: 3 | AT12: 51 | AU12: 3 | AV12: 32 | AW12: 12 | AX12: 44 | AY12: 17 | AZ12: 44 | BA12: 17 | BB12: 44 | BC12: 17 | BD12: 44 | BE12: 17 | BF12: 69 | BG12: 3 | BH12: 50 | BI12: 11 | BJ12: 48 | BK12: 13
A13: Servicios SA-PU | D13: 0 | E13: 0 | F13: 13 | G13: 3 | H13: 13 | I13: 3 | J13: 13 | K13: 3 | L13: 13 | M13: 3 | N13: 13 | O13: 3 | P13: 0 | Q13: 0 | R13: 0 | S13: 0 | T13: 13 | U13: 3 | V13: 13 | W13: 3 | X13: 13 | Y13: 3 | Z13: 15 | AA13: 1 | AB13: 13 | AC13: 3 | AD13: 0 | AE13: 0 | AF13: 0 | AG13: 0 | AH13: 3 | AI13: 0 | AJ13: 13 | AK13: 3 | AL13: 13 | AM13: 3 | AN13: 13 | AO13: 3 | AP13: 0 | AQ13: 0 | AR13: 0 | AS13: 0 | AT13: 0 | AU13: 0 | AV13: 12 | AW13: 3 | AX13: 13 | AY13: 3 | AZ13: 13 | BA13: 3 | BB13: 13 | BC13: 3 | BD13: 13 | BE13: 3 | BF13: 0 | BG13: 0 | BH13: 0 | BI13: 0 | BJ13: 13 | BK13: 3
A14: Servicios EB-PU | D14: 0 | E14: 0 | F14: 1 | G14: 0 | H14: 1 | I14: 0 | J14: 1 | K14: 0 | L14: 1 | M14: 0 | N14: 1 | O14: 0 | P14: 0 | Q14: 0 | R14: 0 | S14: 0 | T14: 1 | U14: 0 | V14: 1 | W14: 0 | X14: 1 | Y14: 0 | Z14: 1 | AA14: 0 | AB14: 1 | AC14: 0 | AD14: 0 | AE14: 0 | AF14: 0 | AG14: 0 | AH14: 0 | AI14: 0 | AJ14: 1 | AK14: 0 | AL14: 1 | AM14: 0 | AN14: 1 | AO14: 0 | AP14: 0 | AQ14: 0 | AR14: 0 | AS14: 0 | AT14: 0 | AU14: 0 | AV14: 1 | AW14: 0 | AX14: 1 | AY14: 0 | AZ14: 1 | BA14: 0 | BB14: 1 | BC14: 0 | BD14: 1 | BE14: 0 | BF14: 0 | BG14: 0 | BH14: 0 | BI14: 0 | BJ14: 1 | BK14: 0
A15: Servicios LI-PU | D15: 59 | E15: 0 | F15: 36 | G15: 25 | H15: 35 | I15: 26 | J15: 36 | K15: 25 | L15: 36 | M15: 25 | N15: 36 | O15: 25 | P15: 75 | Q15: 0 | R15: 57 | S15: 0 | T15: 36 | U15: 25 | V15: 36 | W15: 25 | X15: 36 | Y15: 25 | Z15: 36 | AA15: 25 | AB15: 36 | AC15: 25 | AD15: 75 | AE15: 0 | AF15: 57 | AG15: 0 | AH15: 15 | AI15: 20 | AJ15: 36 | AK15: 25 | AL15: 36 | AM15: 25 | AN15: 36 | AO15: 25 | AP15: 45 | AQ15: 0 | AR15: 75 | AS15: 0 | AT15: 57 | AU15: 0 | AV15: 22 | AW15: 23 | AX15: 36 | AY15: 25 | AZ15: 36 | BA15: 25 | BB15: 36 | BC15: 25 | BD15: 36 | BE15: 25 | BF15: 75 | BG15: 0 | BH15: 50 | BI15: 11 | BJ15: 41 | BK15: 20
A16: Servicios MI-LI | AV16: 10 | AW16: 2
A17: Servicios LI-MI | AV17: 13 | AW17: 2
A18: Servicios PU-RE | AV18: 2 | AW18: 2
A19: Servicios MI-SA | AV19: 1 | AW19: 0
A20: Servicios SA-MI | AV20: 1 | AW20: 0
A22: Servicios PU-SA | D22: 0 | E22: 0 | F22: 7 | G22: 0 | H22: 7 | I22: 0 | J22: 7 | K22: 0 | L22: 7 | M22: 0 | N22: 7 | O22: 0 | P22: 0 | Q22: 0 | R22: 0 | S22: 0 | T22: 7 | U22: 0 | V22: 7 | W22: 0 | X22: 7 | Y22: 0 | Z22: 7 | AA22: 0 | AB22: 7 | AC22: 0 | AD22: 0 | AE22: 0 | AF22: 0 | AG22: 0 | AH22: 4 | AI22: 0 | AJ22: 7 | AK22: 0 | AL22: 7 | AM22: 0 | AN22: 7 | AO22: 0 | AP22: 0 | AQ22: 0 | AR22: 0 | AS22: 0 | AT22: 0 | AU22: 0 | AV22: 6 | AW22: 0 | AX22: 7 | AY22: 0 | AZ22: 7 | BA22: 0 | BB22: 7 | BC22: 0 | BD22: 7 | BE22: 0 | BF22: 0 | BG22: 0 | BH22: 0 | BI22: 0 | BJ22: 7 | BK22: 0
A23: Servicios PU-EB | D23: 0 | E23: 0 | F23: 0 | G23: 0 | H23: 0 | I23: 0 | J23: 0 | K23: 0 | L23: 0 | M23: 0 | N23: 0 | O23: 0 | P23: 0 | Q23: 0 | R23: 0 | S23: 0 | T23: 0 | U23: 0 | V23: 0 | W23: 0 | X23: 0 | Y23: 0 | Z23: 0 | AA23: 0 | AB23: 0 | AC23: 0 | AD23: 0 | AE23: 0 | AF23: 0 | AG23: 0 | AH23: 0 | AI23: 0 | AJ23: 0 | AK23: 0 | AL23: 0 | AM23: 0 | AN23: 0 | AO23: 0 | AP23: 0 | AQ23: 0 | AR23: 0 | AS23: 0 | AT23: 0 | AU23: 0 | AV23: 0 | AW23: 0 | AX23: 0 | AY23: 0 | AZ23: 0 | BA23: 0 | BB23: 0 | BC23: 0 | BD23: 0 | BE23: 0 | BF23: 0 | BG23: 0 | BH23: 0 | BI23: 0 | BJ23: 0 | BK23: 0
A24: Servicios PU-LI | D24: 0 | E24: 0 | F24: 2 | G24: 6 | H24: 2 | I24: 6 | J24: 2 | K24: 6 | L24: 2 | M24: 6 | N24: 2 | O24: 6 | P24: 0 | Q24: 0 | R24: 0 | S24: 0 | T24: 2 | U24: 6 | V24: 2 | W24: 6 | X24: 2 | Y24: 6 | Z24: 2 | AA24: 6 | AB24: 2 | AC24: 6 | AD24: 0 | AE24: 0 | AF24: 0 | AG24: 0 | AH24: 5 | AI24: 5 | AJ24: 2 | AK24: 6 | AL24: 2 | AM24: 6 | AN24: 2 | AO24: 6 | AP24: 6 | AQ24: 0 | AR24: 0 | AS24: 0 | AT24: 0 | AU24: 0 | AV24: 2 | AW24: 6 | AX24: 2 | AY24: 6 | AZ24: 2 | BA24: 6 | BB24: 2 | BC24: 6 | BD24: 2 | BE24: 6 | BF24: 0 | BG24: 0 | BH24: 0 | BI24: 0 | BJ24: 5 | BK24: 3
