Workbook

Sheet Odometro-Kilometraje
A1: Control Contador Kilometraje de Trenes
B2: 45778 | C2: 45779 | D2: 45780 | E2: 45781 | F2: 45782 | G2: 45783 | H2: 45784 | I2: 45785 | J2: 45786 | K2: 45787 | L2: 45788 | M2: 45789 | N2: 45790 | O2: 45791 | P2: 45792 | Q2: 45793 | R2: 45794 | S2: 45795 | T2: 45796 | U2: 45797 | V2: 45798 | W2: 45799 | X2: 45800 | Y2: 45801 | Z2: 45802 | AA2: 45803 | AB2: 45804 | AC2: 45805 | AD2: 45806 | AE2: 45807 | AF2: 45808
B3: Contador | C3: Contador | D3: Contador | E3: Contador | F3: Contador | G3: Contador | H3: Contador | I3: Contador | J3: Contador | K3: Contador | L3: Contador | M3: Contador | N3: Contador | O3: Contador | P3: Contador | Q3: Contador | R3: Contador | S3: Contador | T3: Contador | U3: Contador | V3: Contador | W3: Contador | X3: Contador | Y3: Contador | Z3: Contador | AA3: Contador | AB3: Contador | AC3: Contador | AD3: Contador | AE3: Contador | AF3: Contador
A4: Tren | B4: Odómetro | C4: Odómetro | D4: Odómetro | E4: Odómetro | F4: Odómetro | G4: Odómetro | H4: Odómetro | I4: Odómetro | J4: Odómetro | K4: Odómetro | L4: Odómetro | M4: Odómetro | N4: Odómetro | O4: Odómetro | P4: Odómetro | Q4: Odómetro | R4: Odómetro | S4: Odómetro | T4: Odómetro | U4: Odómetro | V4: Odómetro | W4: Odómetro | X4: Odómetro | Y4: Odómetro | Z4: Odómetro | AA4: Odómetro | AB4: Odómetro | AC4: Odómetro | AD4: Odómetro | AE4: Odómetro | AF4: Odómetro
A5: M01 | B5: 2003943 | C5: 2004180 | D5: 2004180 | E5: 2004180 | F5: 2004374 | G5: 2004626 | H5: 2004803 | I5: 2005264 | J5: 2005742 | K5: 2005785 | L5: 2006259 | M5: 2006391 | N5: 2006392 | O5: 2006824 | P5: 2007384 | Q5: 2007622 | R5: 2007622 | S5: 2007622 | T5: 2007929 | U5: 2008403 | V5: 2008403 | W5: 2008963 | X5: 2009307 | Y5: 2009350 | Z5: 2009868 | AA5: 2010071 | AB5: 2010323 | AC5: 2010832 | AD5: 2011095 | AE5: 2011346 | AF5: 2011346
A6: M02 | B6: 1984952 | C6: 1984952 | D6: 1984952 | E6: 1984952 | F6: 1984952 | G6: 1984952 | H6: 1984952 | I6: 1984952 | J6: 1984952 | K6: 1984952 | L6: 1984952 | M6: 1984952 | N6: 1984952 | O6: 1984952 | P6: 1984952 | Q6: 1984952 | R6: 1984952 | S6: 1984952 | T6: 1984952 | U6: 1984952 | V6: 1984952 | W6: 1984952 | X6: 1984952 | Y6: 1984952 | Z6: 1984952 | AA6: 1984952 | AB6: 1984952 | AC6: 1984952 | AD6: 1984952 | AE6: 1984952 | AF6: 1984952
A7: M03 | B7: 2062023 | C7: 2062330 | D7: 2062849 | E7: 2062893 | F7: 2063329 | G7: 2063762 | H7: 2064286 | I7: 2064724 | J7: 2065177 | K7: 2065177 | L7: 2065177 | M7: 2065371 | N7: 2065771 | O7: 2066204 | P7: 2066510 | Q7: 2067071 | R7: 2067632 | S7: 2068107 | T7: 2068455 | U7: 2068722 | V7: 2068749 | W7: 2069270 | X7: 2069357 | Y7: 2069357 | Z7: 2069357 | AA7: 2069810 | AB7: 2070072 | AC7: 2070506 | AD7: 2070598 | AE7: 2071118 | AF7: 2071636
A8: M04 | B8: 2062213 | C8: 2062706 | D8: 2062706 | E8: 2062706 | F8: 2063226 | G8: 2063638 | H8: 2063899 | I8: 2064069 | J8: 2064372 | K8: 2064763 | L8: 2065283 | M8: 2065735 | N8: 2066076 | O8: 2066597 | P8: 2066770 | Q8: 2067292 | R8: 2067853 | S8: 2068247 | T8: 2068810 | U8: 2069372 | V8: 2069850 | W8: 2070156 | X8: 2070357 | Y8: 2070357 | Z8: 2070357 | AA8: 2070549 | AB8: 2071137 | AC8: 2071398 | AD8: 2072003 | AE8: 2072525 | AF8: 2073043
A9: M05 | B9: 1970913 | C9: 1971172 | D9: 1971172 | E9: 1971172 | F9: 1971341 | G9: 1971861 | H9: 1972295 | I9: 1972729 | J9: 1973117 | K9: 1973636 | L9: 1973679 | M9: 1974043 | N9: 1974536 | O9: 1974789 | P9: 1975349 | Q9: 1975593 | R9: 1975593 | S9: 1975593 | T9: 1975890 | U9: 1976193 | V9: 1976369 | W9: 1976972 | X9: 1977493 | Y9: 1978012 | Z9: 1978487 | AA9: 1978687 | AB9: 1978880 | AC9: 1979440 | AD9: 1979915 | AE9: 1980227 | AF9: 1980788
A10: M06 | B10: 2084297 | C10: 2084650 | D10: 2084650 | E10: 2084650 | F10: 2084732 | G10: 2085020 | H10: 2085606 | I10: 2085965 | J10: 2086230 | K10: 2086230 | L10: 2086230 | M10: 2086415 | N10: 2086599 | O10: 2086784 | P10: 2086971 | Q10: 2087268 | R10: 2087742 | S10: 2088219 | T10: 2088547 | U10: 2088886 | V10: 2089403 | W10: 2089920 | X10: 2090525 | Y10: 2091043 | Z10: 2091475 | AA10: 2092034 | AB10: 2092426 | AC10: 2092775 | AD10: 2093291 | AE10: 2093851 | AF10: 2093894
A11: M07 | B11: 2112446 | C11: 2112697 | D11: 2112697 | E11: 2112697 | F11: 2113111 | G11: 2113479 | H11: 2113778 | I11: 2114241 | J11: 2114505 | K11: 2115070 | L11: 2115115 | M11: 2115318 | N11: 2115570 | O11: 2115821 | P11: 2116016 | Q11: 2116520 | R11: 2117043 | S11: 2117564 | T11: 2118172 | U11: 2118376 | V11: 2118376 | W11: 2118571 | X11: 2119075 | Y11: 2119600 | Z11: 2119743 | AA11: 2120129 | AB11: 2120563 | AC11: 2120768 | AD11: 2120868 | AE11: 2121182 | AF11: 2121706
A12: M08 | B12: 2015839 | C12: 2015929 | D12: 2016449 | E12: 2016452 | F12: 2016889 | G12: 2017322 | H12: 2017671 | I12: 2017976 | J12: 2018473 | K12: 2018473 | L12: 2018493 | M12: 2018943 | N12: 2019136 | O12: 2019388 | P12: 2019699 | Q12: 2019958 | R12: 2019958 | S12: 2019958 | T12: 2020211 | U12: 2020472 | V12: 2020472 | W12: 2020724 | X12: 2021295 | Y12: 2021857 | Z12: 2022333 | AA12: 2022896 | AB12: 2023373 | AC12: 2023977 | AD12: 2024495 | AE12: 2024808 | AF12: 2025330
A13: M09 | B13: 1998486 | C13: 1999055 | D13: 1999583 | E13: 2000066 | F13: 2000308 | G13: 2000564 | H13: 2000793 | I13: 2000793 | J13: 2001255 | K13: 2001255 | L13: 2001255 | M13: 2001452 | N13: 2001712 | O13: 2002201 | P13: 2002637 | Q13: 2002944 | R13: 2002944 | S13: 2002944 | T13: 2003299 | U13: 2003868 | V13: 2004175 | W13: 2004499 | X13: 2004768 | Y13: 2005299 | Z13: 2005782 | AA13: 2006006 | AB13: 2006272 | AC13: 2006799 | AD13: 2007241 | AE13: 2007856 | AF13: 2008384
A14: M10 | B14: 2074160 | C14: 2074675 | D14: 2075192 | E14: 2075709 | F14: 2076313 | G14: 2076704 | H14: 2077222 | I14: 2077577 | J14: 2077731 | K14: 2077731 | L14: 2077734 | M14: 2078252 | N14: 2078812 | O14: 2079329 | P14: 2079888 | Q14: 2080407 | R14: 2080407 | S14: 2080407 | T14: 2080669 | U14: 2081100 | V14: 2081100 | W14: 2081660 | X14: 2082220 | Y14: 2082737 | Z14: 2083254 | AA14: 2083686 | AB14: 2084291 | AC14: 2084638 | AD14: 2085088 | AE14: 2085187 | AF14: 2085187
A15: M11 | B15: 2093579 | C15: 2094110 | D15: 2094153 | E15: 2094153 | F15: 2094674 | G15: 2095197 | H15: 2095634 | I15: 2095791 | J15: 2096244 | K15: 2096765 | L15: 2096767 | M15: 2097074 | N15: 2097405 | O15: 2097658 | P15: 2097908 | Q15: 2098161 | R15: 2098161 | S15: 2098161 | T15: 2098684 | U15: 2098992 | V15: 2099470 | W15: 2099906 | X15: 2100362 | Y15: 2100362 | Z15: 2100362 | AA15: 2100636 | AB15: 2100841 | AC15: 2101096 | AD15: 2101619 | AE15: 2102070 | AF15: 2102070
A16: M12 | B16: 1935976 | C16: 1936583 | D16: 1937103 | E16: 1937535 | F16: 1937730 | G16: 1937899 | H16: 1938462 | I16: 1938967 | J16: 1939573 | K16: 1940135 | L16: 1940178 | M16: 1940569 | N16: 1941081 | O16: 1941532 | P16: 1941720 | Q16: 1941888 | R16: 1941890 | S16: 1942368 | T16: 1942930 | U16: 1943491 | V16: 1943535 | W16: 1943750 | X16: 1944183 | Y16: 1944183 | Z16: 1944185 | AA16: 1944706 | AB16: 1945158 | AC16: 1945351 | AD16: 1945658 | AE16: 1946219 | AF16: 1946781
... A39: XM35 | B39: 658235 | C39: 658401 | D39: 658401 | E39: 658401 | F39: 658603 | G39: 658855 | H39: 659106 | I39: 659460 | J39: 659976 | K39: 660496 | L39: 660971 | M39: 661362 | N39: 661941 | O39: 662376 | P39: 662809 | Q39: 663157 | R39: 663675 | S39: 663782 | T39: 664033 | U39: 664285 | V39: 664285 | W39: 664548 | X39: 664741 | Y39: 664741 | Z39: 664741 | AA39: 664993 | AB39: 665196 | AC39: 665364 | AD39: 665713 | AE39: 666061 | AF39: 666061
A41: Kilometraje Diario Recorrido
B42: 45778 | C42: 45779 | D42: 45780 | E42: 45781 | F42: 45782 | G42: 45783 | H42: 45784 | I42: 45785 | J42: 45786 | K42: 45787 | L42: 45788 | M42: 45789 | N42: 45790 | O42: 45791 | P42: 45792 | Q42: 45793 | R42: 45794 | S42: 45795 | T42: 45796 | U42: 45797 | V42: 45798 | W42: 45799 | X42: 45800 | Y42: 45801 | Z42: 45802 | AA42: 45803 | AB42: 45804 | AC42: 45805 | AD42: 45806 | AE42: 45807 | AF42: 45808
B43: Kilometraje | C43: Kilometraje | D43: Kilometraje | E43: Kilometraje | F43: Kilometraje | G43: Kilometraje | H43: Kilometraje | I43: Kilometraje | J43: Kilometraje | K43: Kilometraje | L43: Kilometraje | M43: Kilometraje | N43: Kilometraje | O43: Kilometraje | P43: Kilometraje | Q43: Kilometraje | R43: Kilometraje | S43: Kilometraje | T43: Kilometraje | U43: Kilometraje | V43: Kilometraje | W43: Kilometraje | X43: Kilometraje | Y43: Kilometraje | Z43: Kilometraje | AA43: Kilometraje | AB43: Kilometraje | AC43: Kilometraje | AD43: Kilometraje | AE43: Kilometraje | AF43: Kilometraje
A44: Tren | B44: Diario | C44: Diario | D44: Diario | E44: Diario | F44: Diario | G44: Diario | H44: Diario | I44: Diario | J44: Diario | K44: Diario | L44: Diario | M44: Diario | N44: Diario | O44: Diario | P44: Diario | Q44: Diario | R44: Diario | S44: Diario | T44: Diario | U44: Diario | V44: Diario | W44: Diario | X44: Diario | Y44: Diario | Z44: Diario | AA44: Diario | AB44: Diario | AC44: Diario | AD44: Diario | AE44: Diario | AF44: Diario
A45: M01 | B45: 473 | C45: =C5-B5 -> 237 | D45: =D5-C5 -> 0 | E45: =E5-D5 -> 0 | F45: =F5-E5 -> 194 | G45: =G5-F5 -> 252 | H45: =H5-G5 -> 177 | I45: =I5-H5 -> 461 | J45: =J5-I5 -> 478 | ... AF45: =AF5-AE5 -> 0
A46: M02 | B46: 0 | C46: =C6-B6 -> 0 | D46: =D6-C6 -> 0 | E46: =E6-D6 -> 0 | F46: =F6-E6 -> 0 | G46: =G6-F6 -> 0 | H46: =H6-G6 -> 0 | I46: =I6-H6 -> 0 | J46: =J6-I6 -> 0 | ... AF46: =AF6-AE6 -> 0
A47: M03 | B47: 0 | C47: =C7-B7 -> 307 | D47: =D7-C7 -> 519 | E47: =E7-D7 -> 44 | F47: =F7-E7 -> 436 | G47: =G7-F7 -> 433 | H47: =H7-G7 -> 524 | I47: =I7-H7 -> 438 | J47: =J7-I7 -> 453 | ... AF47: =AF7-AE7 -> 518
A48: M04 | B48: 476 | C48: =C8-B8 -> 493 | D48: =D8-C8 -> 0 | E48: =E8-D8 -> 0 | F48: =F8-E8 -> 520 | G48: =G8-F8 -> 412 | H48: =H8-G8 -> 261 | I48: =I8-H8 -> 170 | J48: =J8-I8 -> 303 | ... AF48: =AF8-AE8 -> 518
A49: M05 | B49: 520 | C49: =C9-B9 -> 259 | D49: =D9-C9 -> 0 | E49: =E9-D9 -> 0 | F49: =F9-E9 -> 169 | G49: =G9-F9 -> 520 | H49: =H9-G9 -> 434 | I49: =I9-H9 -> 434 | J49: =J9-I9 -> 388 | ... AF49: =AF9-AE9 -> 561
A50: M06 | B50: 0 | C50: =C10-B10 -> 353 | D50: =D10-C10 -> 0 | E50: =E10-D10 -> 0 | F50: =F10-E10 -> 82 | G50: =G10-F10 -> 288 | H50: =H10-G10 -> 586 | I50: =I10-H10 -> 359 | J50: =J10-I10 -> 265 | ... AF50: =AF10-AE10 -> 43
A51: M07 | B51: 0 | C51: =C11-B11 -> 251 | D51: =D11-C11 -> 0 | E51: =E11-D11 -> 0 | F51: =F11-E11 -> 414 | G51: =G11-F11 -> 368 | H51: =H11-G11 -> 299 | I51: =I11-H11 -> 463 | J51: =J11-I11 -> 264 | ... AF51: =AF11-AE11 -> 524
A52: M08 | B52: 432 | C52: =C12-B12 -> 90 | D52: =D12-C12 -> 520 | E52: =E12-D12 -> 3 | F52: =F12-E12 -> 437 | G52: =G12-F12 -> 433 | H52: =H12-G12 -> 349 | I52: =I12-H12 -> 305 | J52: =J12-I12 -> 497 | ... AF52: =AF12-AE12 -> 522
A53: M09 | B53: 482 | C53: =C13-B13 -> 569 | D53: =D13-C13 -> 528 | E53: =E13-D13 -> 483 | F53: =F13-E13 -> 242 | G53: =G13-F13 -> 256 | H53: =H13-G13 -> 229 | I53: =I13-H13 -> 0 | J53: =J13-I13 -> 462 | ... AF53: =AF13-AE13 -> 528
A54: M10 | B54: 1 | C54: =C14-B14 -> 515 | D54: =D14-C14 -> 517 | E54: =E14-D14 -> 517 | F54: =F14-E14 -> 604 | G54: =G14-F14 -> 391 | H54: =H14-G14 -> 518 | I54: =I14-H14 -> 355 | J54: =J14-I14 -> 154 | ... AF54: =AF14-AE14 -> 0
A55: M11 | B55: 0 | C55: =C15-B15 -> 531 | D55: =D15-C15 -> 43 | E55: =E15-D15 -> 0 | F55: =F15-E15 -> 521 | G55: =G15-F15 -> 523 | H55: =H15-G15 -> 437 | I55: =I15-H15 -> 157 | J55: =J15-I15 -> 453 | ... AF55: =AF15-AE15 -> 0
A56: M12 | B56: 45 | C56: =C16-B16 -> 607 | D56: =D16-C16 -> 520 | E56: =E16-D16 -> 432 | F56: =F16-E16 -> 195 | G56: =G16-F16 -> 169 | H56: =H16-G16 -> 563 | I56: =I16-H16 -> 505 | J56: =J16-I16 -> 606 | ... AF56: =AF16-AE16 -> 562
... A79: XM35 | B79: 0 | C79: =C39-B39 -> 166 | D79: =D39-C39 -> 0 | E79: =E39-D39 -> 0 | F79: =F39-E39 -> 202 | G79: =G39-F39 -> 252 | H79: =H39-G39 -> 251 | I79: =I39-H39 -> 354 | J79: =J39-I39 -> 516 | ... AF79: =AF39-AE39 -> 0
A81: Kilometraje Diario | B81: =SUM(B45:B79) -> 4943 | C81: =SUM(C45:C79) -> 12128 | D81: =SUM(D45:D79) -> 6489 | E81: =SUM(E45:E79) -> 4955 | F81: =SUM(F45:F79) -> 12105 | G81: =SUM(G45:G79) -> 12087 | H81: =SUM(H45:H79) -> 12123 | I81: =SUM(I45:I79) -> 10264 | ... AF81: =SUM(AF45:AF79) -> 6584
O86: XT-1 | P86: 2011095 | Q86: 2011346 | R86: 251 | S86: 7.64 | T86: 232.88 | U86: 10.48
O87: XT-2 | P87: 1984952 | Q87: 1984952 | R87: 0 | S87: 0 | T87: 0 | U87: 0
O88: XT-3 | P88: 2070598 | Q88: 2071118 | R88: 520 | S88: 0 | T88: 474.43 | U88: 45.57
O89: XT-4 | P89: 2072003 | Q89: 2072525 | R89: 522 | S89: 0 | T89: 560.69 | U89: -38.69
O90: XT-5 | P90: 1979915 | Q90: 1980227 | R90: 312 | S90: 0 | T90: 345.04 | U90: -33.04
...

Sheet KM-Servicio
E1: SA-QU/QU-SA | F1: 7.68 | H1: SA-MI | I1: 21.7 | J1: EB-PU | K1: 25.4 | L1: PU-SA | M1: 29.11 | N1: QU-LI / LI-QU | O1: 21.7 | P1: VM-PU | Q1: 8.3 | R1: VM-LI | S1: 34.83 | T1: LI-PO | U1: 39.19 | W1: PU-ES/ES-PU | X1: 11.71
B2: CANTIDAD DE SERVICIOS | D2: CANTIDAD DE SERVICIOS | F2: EB-LI | G2: =M2-K1 -> 17.73 | H2: PU-PE | I2: 30.4 | J2: PO-SA | K2: 25.4 | L2: PU-LI | M2: 43.13 | N2: MI-LI / LI-MI | O2: 35.73 | P2: HO-LI/LI-HO | Q2: 33.97 | R2: PU-MI | S2: 7.4 | T2: LI-PE | U2: 12.72 | W2: MI-SA | X2: 21.7
B3: PROGRAMADOS | D3: REALIZADOS | F3: Origen-Destino | G3: Total Trenes | H3: Total Trenes P | I3: Total Servicios | J3: Kms.xTrenes | K3: Kmsxservicios. | L3: Asientos x Kms. | M3: Disp x Km. | N3: Total Odómetro | O3: % Uso Trenes | Q3: Cortes | T3: Acoples | W3: KmTren R | X3: KmTren P
B4: Simples | C4: Dobles | D4: Simples | E4: Dobles | Q4: EB | R4: SA | S4: PE | T4: EB | U4: SA | V4: PE
A5: 45778 | B5: 51 | C5: 3 | D5: ='Data Ocupacion'!D41 -> 51 | E5: ='Data Ocupacion'!E41 -> 3 | F5: PU-LI | G5: =D5+E5*2 -> 57 | H5: =B5+C5*2 -> 57 | I5: =D5+E5 -> 54 | J5: =G5*M$2 -> 2458.41 | K5: =I5*M$2 -> 2329.02 | L5: =J5*104 -> 255674.64 | M5: =I5*104 -> 5616 | W5: =J5-(Q5*($M$2-$K$1))-(R5*($M$2-$M$1))- (S5*($M$2-$I$2))+ (T5*($G$2)) -> 2458.41 | X5: =H5*$M$2 -> 2458.41
B6: 57 | C6: 0 | D6: ='Data Ocupacion'!D42 -> 57 | E6: ='Data Ocupacion'!E42 -> 0 | F6: LI-PU | G6: =D6+E6*2 -> 57 | H6: =B6+C6*2 -> 57 | I6: =D6+E6 -> 57 | J6: =G6*M$2 -> 2458.41 | K6: =I6*M$2 -> 2458.41 | L6: =J6*104 -> 255674.64 | M6: =I6*104 -> 5928 | W6: =J6-(T6*($M$2-$K$1)+(U6*($M$2-$M$1))) -> 2458.41 | X6: =H6*$M$2 -> 2458.41
B7: 0 | C7: 0 | D7: ='Data Ocupacion'!D43 -> 0 | E7: ='Data Ocupacion'!E43 -> 0 | F7: PU-SA | G7: =D7+E7*2 -> 0 | H7: =B7+C7*2 -> 0 | I7: =D7+E7 -> 0 | J7: =G7*M$1 -> 0 | K7: =I7*M$1 -> 0 | L7: =J7*104 -> 0 | M7: =I7*104 -> 0 | W7: =J7-(Q7*($M$1-$K$1)) -> 0 | X7: =H7*$M$1 -> 0
B8: 0 | C8: 0 | D8: ='Data Ocupacion'!D44 -> 0 | E8: ='Data Ocupacion'!E44 -> 0 | F8: SA-PU | G8: =D8+E8*2 -> 0 | H8: =B8+C8*2 -> 0 | I8: =D8+E8 -> 0 | J8: =G8*M$1 -> 0 | K8: =I8*M$1 -> 0 | L8: =J8*104 -> 0 | M8: =I8*104 -> 0 | W8: =J8 -> 0 | X8: =H8*$M$1 -> 0
B9: 0 | C9: 0 | D9: ='Data Ocupacion'!D45 -> 0 | E9: ='Data Ocupacion'!E45 -> 0 | F9: PU-EB | G9: =D9+E9*2 -> 0 | H9: =B9+C9*2 -> 0 | I9: =D9+E9 -> 0 | J9: =G9*K$1 -> 0 | K9: =I9*K$1 -> 0 | L9: =J9*104 -> 0 | M9: =I9*104 -> 0 | W9: =J9 -> 0 | X9: =H9*$K$1 -> 0
B10: 0 | C10: 0 | D10: ='Data Ocupacion'!D46 -> 0 | E10: ='Data Ocupacion'!E46 -> 0 | F10: EB-PU | G10: =D10+E10*2 -> 0 | H10: =B10+C10*2 -> 0 | I10: =D10+E10 -> 0 | J10: =G10*K$1 -> 0 | K10: =I10*K$1 -> 0 | L10: =J10*104 -> 0 | M10: =I10*104 -> 0 | W10: =J10 -> 0 | X10: =H10*$K$1 -> 0
B11: =SUM(B5:B10) -> 108 | C11: =SUM(C5:C10) -> 3 | D11: =SUM(D5:D10) -> 108 | E11: =SUM(E5:E10) -> 3 | G11: =SUM(G5:G10) -> 114 | H11: =SUM(H5:H10) -> 114 | I11: =SUM(I5:I10) -> 111 | J11: =SUM(J5:J10) -> 4916.82 | K11: =SUM(K5:K10) -> 4787.43 | L11: =SUM(L5:L10) -> 511349.28 | M11: =SUM(M5:M10) -> 11544 | N11: ='Odometro-Kilometraje'!B81 -> 4943 | O11: =(W11/N11)*100 -> 99.470362 | W11: =SUM(W5:W10) -> 4916.82 | X11: =SUM(X5:X10) -> 4916.82
A12: =A5+1 -> 45779 | B12: 47 | C12: 32 | D12: ='Data Ocupacion'!F41 -> 47 | E12: ='Data Ocupacion'!G41 -> 32 | F12: PU-LI | G12: =D12+E12*2 -> 111 | H12: =B12+C12*2 -> 111 | I12: =D12+E12 -> 79 | J12: =G12*M$2 -> 4787.43 | K12: =I12*M$2 -> 3407.27 | L12: =J12*104 -> 497892.72 | M12: =I12*104 -> 8216 | Q12: 4 | T12: 4 | W12: =J12-(Q12*($M$2-$K$1))-(R12*($M$2-$M$1))- (S12*($M$2-$I$2))+ (T12*($G$2)) -> 4787.43 | X12: =H12*$M$2 -> 4787.43
B13: 45 | C13: 33 | D13: ='Data Ocupacion'!F42 -> 45 | E13: ='Data Ocupacion'!G42 -> 33 | F13: LI-PU | G13: =D13+E13*2 -> 111 | H13: =B13+C13*2 -> 111 | I13: =D13+E13 -> 78 | J13: =G13*M$2 -> 4787.43 | K13: =I13*M$2 -> 3364.14 | L13: =J13*104 -> 497892.72 | M13: =I13*104 -> 8112 | W13: =J13-(T13*($M$2-$K$1)+(U13*($M$2-$M$1))) -> 4787.43 | X13: =H13*$M$2 -> 4787.43
B14: 29 | C14: 4 | D14: ='Data Ocupacion'!F43 -> 29 | E14: ='Data Ocupacion'!G43 -> 4 | F14: PU-SA | G14: =D14+E14*2 -> 37 | H14: =B14+C14*2 -> 37 | I14: =D14+E14 -> 33 | J14: =G14*M$1 -> 1077.07 | K14: =I14*M$1 -> 960.63 | L14: =J14*104 -> 112015.28 | M14: =I14*104 -> 3432 | W14: =J14-(Q14*($M$1-$K$1)) -> 1077.07 | X14: =H14*$M$1 -> 1077.07
B15: 28 | C15: 4 | D15: ='Data Ocupacion'!F44 -> 28 | E15: ='Data Ocupacion'!G44 -> 4 | F15: SA-PU | G15: =D15+E15*2 -> 36 | H15: =B15+C15*2 -> 36 | I15: =D15+E15 -> 32 | J15: =G15*M$1 -> 1047.96 | K15: =I15*M$1 -> 931.52 | L15: =J15*104 -> 108987.84 | M15: =I15*104 -> 3328 | W15: =J15 -> 1047.96 | X15: =H15*$M$1 -> 1047.96
B16: 0 | C16: 0 | D16: ='Data Ocupacion'!F45 -> 0 | E16: ='Data Ocupacion'!G45 -> 0 | F16: PU-EB | G16: =D16+E16*2 -> 0 | H16: =B16+C16*2 -> 0 | I16: =D16+E16 -> 0 | J16: =G16*K$1 -> 0 | K16: =I16*K$1 -> 0 | L16: =J16*104 -> 0 | M16: =I16*104 -> 0 | W16: =J16 -> 0 | X16: =H16*$K$1 -> 0
B17: 1 | C17: 0 | D17: ='Data Ocupacion'!F46 -> 1 | E17: ='Data Ocupacion'!G46 -> 0 | F17: EB-PU | G17: =D17+E17*2 -> 1 | H17: =B17+C17*2 -> 1 | I17: =D17+E17 -> 1 | J17: =G17*K$1 -> 25.4 | K17: =I17*K$1 -> 25.4 | L17: =J17*104 -> 2641.6 | M17: =I17*104 -> 104 | W17: =J17 -> 25.4 | X17: =H17*$K$1 -> 25.4
B18: =SUM(B12:B17) -> 150 | C18: =SUM(C12:C17) -> 73 | D18: =SUM(D12:D17) -> 150 | E18: =SUM(E12:E17) -> 73 | G18: =SUM(G12:G17) -> 296 | H18: =SUM(H12:H17) -> 296 | I18: =SUM(I12:I17) -> 223 | J18: =SUM(J12:J17) -> 11725.29 | K18: =SUM(K12:K17) -> 8688.96 | L18: =SUM(L12:L17) -> 1219430.2 | M18: =SUM(M12:M17) -> 23192 | N18: ='Odometro-Kilometraje'!C81 -> 12128 | O18: =(W18/N18)*100 -> 96.679502 | W18: =SUM(W12:W17) -> 11725.29 | X18: =SUM(X12:X17) -> 11725.29
A19: =A12+1 -> 45780 | B19: 69 | C19: 3 | D19: ='Data Ocupacion'!H41 -> 69 | E19: ='Data Ocupacion'!I41 -> 3 | F19: PU-LI | G19: =D19+E19*2 -> 75 | H19: =B19+C19*2 -> 75 | I19: =D19+E19 -> 72 | J19: =G19*M$2 -> 3234.75 | K19: =I19*M$2 -> 3105.36 | L19: =J19*104 -> 336414 | M19: =I19*104 -> 7488 | W19: =J19-(Q19*($M$2-$K$1))-(R19*($M$2-$M$1))- (S19*($M$2-$I$2))+ (T19*($G$2)) -> 3234.75 | X19: =H19*$M$2 -> 3234.75
B20: 75 | C20: 0 | D20: ='Data Ocupacion'!H42 -> 75 | E20: ='Data Ocupacion'!I42 -> 0 | F20: LI-PU | G20: =D20+E20*2 -> 75 | H20: =B20+C20*2 -> 75 | I20: =D20+E20 -> 75 | J20: =G20*M$2 -> 3234.75 | K20: =I20*M$2 -> 3234.75 | L20: =J20*104 -> 336414 | M20: =I20*104 -> 7800 | W20: =J20-(T20*($M$2-$K$1)+(U20*($M$2-$M$1))) -> 3234.75 | X20: =H20*$M$2 -> 3234.75
B21: 0 | C21: 0 | D21: ='Data Ocupacion'!H43 -> 0 | E21: ='Data Ocupacion'!I43 -> 0 | F21: PU-SA | G21: =D21+E21*2 -> 0 | H21: =B21+C21*2 -> 0 | I21: =D21+E21 -> 0 | J21: =G21*M$1 -> 0 | K21: =I21*M$1 -> 0 | L21: =J21*104 -> 0 | M21: =I21*104 -> 0 | W21: =J21-(Q21*($M$1-$K$1)) -> 0 | X21: =H21*$M$1 -> 0
B22: 0 | C22: 0 | D22: ='Data Ocupacion'!H44 -> 0 | E22: ='Data Ocupacion'!I44 -> 0 | F22: SA-PU | G22: =D22+E22*2 -> 0 | H22: =B22+C22*2 -> 0 | I22: =D22+E22 -> 0 | J22: =G22*M$1 -> 0 | K22: =I22*M$1 -> 0 | L22: =J22*104 -> 0 | M22: =I22*104 -> 0 | W22: =J22 -> 0 | X22: =H22*$M$1 -> 0
B23: 0 | C23: 0 | D23: ='Data Ocupacion'!H45 -> 0 | E23: ='Data Ocupacion'!I45 -> 0 | F23: PU-EB | G23: =D23+E23*2 -> 0 | H23: =B23+C23*2 -> 0 | I23: =D23+E23 -> 0 | J23: =G23*K$1 -> 0 | K23: =I23*K$1 -> 0 | L23: =J23*104 -> 0 | M23: =I23*104 -> 0 | W23: =J23 -> 0 | X23: =H23*$K$1 -> 0
B24: 0 | C24: 0 | D24: ='Data Ocupacion'!H46 -> 0 | E24: ='Data Ocupacion'!I46 -> 0 | F24: EB-PU | G24: =D24+E24*2 -> 0 | H24: =B24+C24*2 -> 0 | I24: =D24+E24 -> 0 | J24: =G24*K$1 -> 0 | K24: =I24*K$1 -> 0 | L24: =J24*104 -> 0 | M24: =I24*104 -> 0 | W24: =J24 -> 0 | X24: =H24*$K$1 -> 0
B25: =SUM(B19:B24) -> 144 | C25: =SUM(C19:C24) -> 3 | D25: =SUM(D19:D24) -> 144 | E25: =SUM(E19:E24) -> 3 | G25: =SUM(G19:G24) -> 150 | H25: =SUM(H19:H24) -> 150 | I25: =SUM(I19:I24) -> 147 | J25: =SUM(J19:J24) -> 6469.5 | K25: =SUM(K19:K24) -> 6340.11 | L25: =SUM(L19:L24) -> 672828 | M25: =SUM(M19:M24) -> 15288 | N25: ='Odometro-Kilometraje'!D81 -> 6489 | O25: =(W25/N25)*100 -> 99.699491 | W25: =SUM(W19:W24) -> 6469.5 | X25: =SUM(X19:X24) -> 6469.5
A26: =A19+1 -> 45781 | B26: 51 | C26: 3 | D26: ='Data Ocupacion'!J41 -> 51 | E26: ='Data Ocupacion'!K41 -> 3 | F26: PU-LI | G26: =D26+E26*2 -> 57 | H26: =B26+C26*2 -> 57 | I26: =D26+E26 -> 54 | J26: =G26*M$2 -> 2458.41 | K26: =I26*M$2 -> 2329.02 | L26: =J26*104 -> 255674.64 | M26: =I26*104 -> 5616 | W26: =J26-(Q26*($M$2-$K$1))-(R26*($M$2-$M$1))- (S26*($M$2-$I$2))+ (T26*($G$2)) -> 2458.41 | X26: =H26*$M$2 -> 2458.41
B27: 57 | C27: 0 | D27: ='Data Ocupacion'!J42 -> 57 | E27: ='Data Ocupacion'!K42 -> 0 | F27: LI-PU | G27: =D27+E27*2 -> 57 | H27: =B27+C27*2 -> 57 | I27: =D27+E27 -> 57 | J27: =G27*M$2 -> 2458.41 | K27: =I27*M$2 -> 2458.41 | L27: =J27*104 -> 255674.64 | M27: =I27*104 -> 5928 | W27: =J27-(T27*($M$2-$K$1)+(U27*($M$2-$M$1))+(V27*($M$2-$I$2))) -> 2458.41 | X27: =H27*$M$2 -> 2458.41
B28: 0 | C28: 0 | D28: ='Data Ocupacion'!J43 -> 0 | E28: ='Data Ocupacion'!K43 -> 0 | F28: PU-SA | G28: =D28+E28*2 -> 0 | H28: =B28+C28*2 -> 0 | I28: =D28+E28 -> 0 | J28: =G28*M$1 -> 0 | K28: =I28*M$1 -> 0 | L28: =J28*104 -> 0 | M28: =I28*104 -> 0 | W28: =J28-(Q28*($M$1-$K$1)) -> 0 | X28: =H28*$M$1 -> 0
B29: 0 | C29: 0 | D29: ='Data Ocupacion'!J44 -> 0 | E29: ='Data Ocupacion'!K44 -> 0 | F29: SA-PU | G29: =D29+E29*2 -> 0 | H29: =B29+C29*2 -> 0 | I29: =D29+E29 -> 0 | J29: =G29*M$1 -> 0 | K29: =I29*M$1 -> 0 | L29: =J29*104 -> 0 | M29: =I29*104 -> 0 | W29: =J29 -> 0 | X29: =H29*$M$1 -> 0
B30: 0 | C30: 0 | D30: ='Data Ocupacion'!J45 -> 0 | E30: ='Data Ocupacion'!K45 -> 0 | F30: PU-EB | G30: =D30+E30*2 -> 0 | H30: =B30+C30*2 -> 0 | I30: =D30+E30 -> 0 | J30: =G30*K$1 -> 0 | K30: =I30*K$1 -> 0 | L30: =J30*104 -> 0 | M30: =I30*104 -> 0 | W30: =J30 -> 0 | X30: =H30*$K$1 -> 0
B31: 0 | C31: 0 | D31: ='Data Ocupacion'!J46 -> 0 | E31: ='Data Ocupacion'!K46 -> 0 | F31: EB-PU | G31: =D31+E31*2 -> 0 | H31: =B31+C31*2 -> 0 | I31: =D31+E31 -> 0 | J31: =G31*K$1 -> 0 | K31: =I31*K$1 -> 0 | L31: =J31*104 -> 0 | M31: =I31*104 -> 0 | W31: =J31 -> 0 | X31: =H31*$K$1 -> 0
B32: =SUM(B26:B31) -> 108 | C32: =SUM(C26:C31) -> 3 | D32: =SUM(D26:D31) -> 108 | E32: =SUM(E26:E31) -> 3 | G32: =SUM(G26:G31) -> 114 | H32: =SUM(H26:H31) -> 114 | I32: =SUM(I26:I31) -> 111 | J32: =SUM(J26:J31) -> 4916.82 | K32: =SUM(K26:K31) -> 4787.43 | L32: =SUM(L26:L31) -> 511349.28 | M32: =SUM(M26:M31) -> 11544 | N32: ='Odometro-Kilometraje'!E81 -> 4955 | O32: =(W32/N32)*100 -> 99.229465 | W32: =SUM(W26:W31) -> 4916.82 | X32: =SUM(X26:X31) -> 4916.82
A33: =A26+1 -> 45782 | B33: 47 | C33: 32 | D33: ='Data Ocupacion'!L41 -> 47 | E33: ='Data Ocupacion'!M41 -> 32 | F33: PU-LI | G33: =D33+E33*2 -> 111 | H33: =B33+C33*2 -> 111 | I33: =D33+E33 -> 79 | J33: =G33*M$2 -> 4787.43 | K33: =I33*M$2 -> 3407.27 | L33: =J33*104 -> 497892.72 | M33: =I33*104 -> 8216 | Q33: 2 | T33: 3 | W33: =J33-(Q33*($M$2-$K$1))-(R33*($M$2-$M$1))- (S33*($M$2-$I$2))+ (T33*($G$2)) -> 4805.16 | X33: =H33*$M$2 -> 4787.43
B34: 45 | C34: 33 | D34: ='Data Ocupacion'!L42 -> 45 | E34: ='Data Ocupacion'!M42 -> 33 | F34: LI-PU | G34: =D34+E34*2 -> 111 | H34: =B34+C34*2 -> 111 | I34: =D34+E34 -> 78 | J34: =G34*M$2 -> 4787.43 | K34: =I34*M$2 -> 3364.14 | L34: =J34*104 -> 497892.72 | M34: =I34*104 -> 8112 | W34: =J34-(T34*($M$2-$K$1)+(U34*($M$2-$M$1))) -> 4787.43 | X34: =H34*$M$2 -> 4787.43
B35: 29 | C35: 4 | D35: ='Data Ocupacion'!L43 -> 29 | E35: ='Data Ocupacion'!M43 -> 4 | F35: PU-SA | G35: =D35+E35*2 -> 37 | H35: =B35+C35*2 -> 37 | I35: =D35+E35 -> 33 | J35: =G35*M$1 -> 1077.07 | K35: =I35*M$1 -> 960.63 | L35: =J35*104 -> 112015.28 | M35: =I35*104 -> 3432 | W35: =J35-(Q35*($M$1-$K$1)) -> 1077.07 | X35: =H35*$M$1 -> 1077.07
B36: 28 | C36: 4 | D36: ='Data Ocupacion'!L44 -> 28 | E36: ='Data Ocupacion'!M44 -> 4 | F36: SA-PU | G36: =D36+E36*2 -> 36 | H36: =B36+C36*2 -> 36 | I36: =D36+E36 -> 32 | J36: =G36*M$1 -> 1047.96 | K36: =I36*M$1 -> 931.52 | L36: =J36*104 -> 108987.84 | M36: =I36*104 -> 3328 | W36: =J36 -> 1047.96 | X36: =H36*$M$1 -> 1047.96
B37: 0 | C37: 0 | D37: ='Data Ocupacion'!L45 -> 0 | E37: ='Data Ocupacion'!M45 -> 0 | F37: PU-EB | G37: =D37+E37*2 -> 0 | H37: =B37+C37*2 -> 0 | I37: =D37+E37 -> 0 | J37: =G37*K$1 -> 0 | K37: =I37*K$1 -> 0 | L37: =J37*104 -> 0 | M37: =I37*104 -> 0 | W37: =J37 -> 0 | X37: =H37*$K$1 -> 0
B38: 1 | C38: 0 | D38: ='Data Ocupacion'!L46 -> 1 | E38: ='Data Ocupacion'!M46 -> 0 | F38: EB-PU | G38: =D38+E38*2 -> 1 | H38: =B38+C38*2 -> 1 | I38: =D38+E38 -> 1 | J38: =G38*K$1 -> 25.4 | K38: =I38*K$1 -> 25.4 | L38: =J38*104 -> 2641.6 | M38: =I38*104 -> 104 | W38: =J38 -> 25.4 | X38: =H38*$K$1 -> 25.4
B39: =SUM(B33:B38) -> 150 | C39: =SUM(C33:C38) -> 73 | D39: =SUM(D33:D38) -> 150 | E39: =SUM(E33:E38) -> 73 | G39: =SUM(G33:G38) -> 296 | H39: =SUM(H33:H38) -> 296 | I39: =SUM(I33:I38) -> 223 | J39: =SUM(J33:J38) -> 11725.29 | K39: =SUM(K33:K38) -> 8688.96 | L39: =SUM(L33:L38) -> 1219430.2 | M39: =SUM(M33:M38) -> 23192 | N39: ='Odometro-Kilometraje'!F81 -> 12105 | O39: =(W39/N39)*100 -> 97.009665 | W39: =SUM(W33:W38) -> 11743.02 | X39: =SUM(X33:X38) -> 11725.29
A40: =A33+1 -> 45783 | B40: 47 | C40: 32 | D40: ='Data Ocupacion'!N41 -> 47 | E40: ='Data Ocupacion'!O41 -> 32 | F40: PU-LI | G40: =D40+E40*2 -> 111 | H40: =B40+C40*2 -> 111 | I40: =D40+E40 -> 79 | J40: =G40*M$2 -> 4787.43 | K40: =I40*M$2 -> 3407.27 | L40: =J40*104 -> 497892.72 | M40: =I40*104 -> 8216 | T40: 2 | W40: =J40-(Q40*($M$2-$K$1))-(R40*($M$2-$M$1))- (S40*($M$2-$I$2))+ (T40*($G$2)) -> 4822.89 | X40: =H40*$M$2 -> 4787.43
...

Sheet Data Ocupacion
D1: 45778 | F1: 45779 | H1: 45780 | J1: 45781 | L1: 45782 | N1: 45783 | P1: 45784 | R1: 45785 | T1: 45786 | V1: 45787 | X1: 45788 | Z1: 45789 | AB1: 45790 | AD1: 45791 | AF1: 45792 | AH1: 45793 | AJ1: 45794 | AL1: 45795 | AN1: 45796 | AP1: 45797 | AR1: 45798 | AT1: 45799 | AV1: 45800 | AX1: 45801 | AZ1: 45802 | BB1: 45803 | BD1: 45804 | BF1: 45805 | BH1: 45806 | BJ1: 45807 | BL1: 45808
D2: S | E2: M | F2: S | G2: M | H2: S | I2: M | J2: S | K2: M | L2: S | M2: M | N2: S | O2: M | P2: S | Q2: M | R2: S | S2: M | T2: S | U2: M | V2: S | W2: M | X2: S | Y2: M | Z2: S | AA2: M | AB2: S | AC2: M | AD2: S | AE2: M | AF2: S | AG2: M | AH2: S | AI2: M | AJ2: S | AK2: M | AL2: S | AM2: M | AN2: S | AO2: M | AP2: S | AQ2: M | AR2: S | AS2: M | AT2: S | AU2: M | AV2: S | AW2: M | AX2: S | AY2: M | AZ2: S | BA2: M | BB2: S | BC2: M | BD2: S | BE2: M | BF2: S | BG2: M | BH2: S | BI2: M | BJ2: S | BK2: M | BL2: S | BM2: M
A3: Servicios PU-SA | D3: 0 | E3: 0 | F3: 7 | G3: 3 | H3: 0 | I3: 0 | J3: 0 | K3: 0 | L3: 7 | M3: 3 | N3: 7 | O3: 3 | P3: 7 | Q3: 3 | R3: 2 | S3: 0 | T3: 7 | U3: 3 | V3: 0 | W3: 0 | X3: 0 | Y3: 0 | Z3: 7 | AA3: 3 | AB3: 7 | AC3: 3 | AD3: 7 | AE3: 3 | AF3: 7 | AG3: 3 | AH3: 7 | AI3: 3 | AJ3: 0 | AK3: 0 | AL3: 0 | AM3: 0 | AN3: 7 | AO3: 3 | AP3: 7 | AQ3: 3 | AR3: 0 | AS3: 0 | AT3: 7 | AU3: 3 | AV3: 7 | AW3: 3 | AX3: 0 | AY3: 0 | AZ3: 0 | BA3: 0 | BB3: 7 | BC3: 3 | BD3: 7 | BE3: 3 | BF3: 7 | BG3: 3 | BH3: 7 | BI3: 3 | BJ3: 7 | BK3: 3 | BL3: 0 | BM3: 0
A4: Servicios PU-EB | D4: 0 | E4: 0 | F4: 0 | G4: 0 | H4: 0 | I4: 0 | J4: 0 | K4: 0 | L4: 0 | M4: 0 | N4: 0 | O4: 0 | P4: 0 | Q4: 0 | R4: 0 | S4: 0 | T4: 0 | U4: 0 | V4: 0 | W4: 0 | X4: 0 | Y4: 0 | Z4: 0 | AA4: 0 | AB4: 0 | AC4: 0 | AD4: 0 | AE4: 0 | AF4: 0 | AG4: 0 | AH4: 0 | AI4: 0 | AJ4: 0 | AK4: 0 | AL4: 0 | AM4: 0 | AN4: 0 | AO4: 0 | AP4: 0 | AQ4: 0 | AR4: 0 | AS4: 0 | AT4: 0 | AU4: 0 | AV4: 0 | AW4: 0 | AX4: 0 | AY4: 0 | AZ4: 0 | BA4: 0 | BB4: 0 | BC4: 0 | BD4: 0 | BE4: 0 | BF4: 0 | BG4: 0 | BH4: 0 | BI4: 0 | BJ4: 0 | BK4: 0 | BL4: 0 | BM4: 0
A5: Servicios PU-LI | D5: 0 | E5: 0 | F5: 1 | G5: 9 | H5: 0 | I5: 0 | J5: 0 | K5: 0 | L5: 1 | M5: 9 | N5: 1 | O5: 9 | P5: 1 | Q5: 9 | R5: 5 | S5: 1 | T5: 1 | U5: 9 | V5: 0 | W5: 0 | X5: 0 | Y5: 0 | Z5: 1 | AA5: 9 | AB5: 2 | AC5: 8 | AD5: 1 | AE5: 9 | AF5: 1 | AG5: 9 | AH5: 1 | AI5: 9 | AJ5: 0 | AK5: 0 | AL5: 0 | AM5: 0 | AN5: 1 | AO5: 9 | AP5: 2 | AQ5: 8 | AR5: 0 | AS5: 0 | AT5: 1 | AU5: 9 | AV5: 1 | AW5: 9 | AX5: 0 | AY5: 0 | AZ5: 0 | BA5: 0 | BB5: 1 | BC5: 9 | BD5: 2 | BE5: 8 | BF5: 2 | BG5: 8 | BH5: 1 | BI5: 9 | BJ5: 1 | BK5: 9 | BL5: 0 | BM5: 0
A6: Servicios SA-PU | D6: 0 | E6: 0 | F6: 9 | G6: 1 | H6: 0 | I6: 0 | J6: 0 | K6: 0 | L6: 9 | M6: 1 | N6: 9 | O6: 1 | P6: 9 | Q6: 1 | R6: 1 | S6: 0 | T6: 9 | U6: 1 | V6: 0 | W6: 0 | X6: 0 | Y6: 0 | Z6: 9 | AA6: 1 | AB6: 9 | AC6: 1 | AD6: 9 | AE6: 1 | AF6: 9 | AG6: 1 | AH6: 9 | AI6: 1 | AJ6: 0 | AK6: 0 | AL6: 0 | AM6: 0 | AN6: 9 | AO6: 1 | AP6: 9 | AQ6: 1 | AR6: 0 | AS6: 0 | AT6: 9 | AU6: 1 | AV6: 9 | AW6: 1 | AX6: 0 | AY6: 0 | AZ6: 0 | BA6: 0 | BB6: 9 | BC6: 1 | BD6: 9 | BE6: 1 | BF6: 9 | BG6: 1 | BH6: 10 | BI6: 0 | BJ6: 9 | BK6: 1 | BL6: 0 | BM6: 0
A7: Servicios EB-PU | D7: 0 | E7: 0 | F7: 0 | G7: 0 | H7: 0 | I7: 0 | J7: 0 | K7: 0 | L7: 0 | M7: 0 | N7: 0 | O7: 0 | P7: 0 | Q7: 0 | R7: 0 | S7: 0 | T7: 0 | U7: 0 | V7: 0 | W7: 0 | X7: 0 | Y7: 0 | Z7: 0 | AA7: 0 | AB7: 0 | AC7: 0 | AD7: 0 | AE7: 0 | AF7: 0 | AG7: 0 | AH7: 0 | AI7: 0 | AJ7: 0 | AK7: 0 | AL7: 0 | AM7: 0 | AN7: 0 | AO7: 0 | AP7: 0 | AQ7: 0 | AR7: 0 | AS7: 0 | AT7: 0 | AU7: 0 | AV7: 0 | AW7: 0 | AX7: 0 | AY7: 0 | AZ7: 0 | BA7: 0 | BB7: 0 | BC7: 0 | BD7: 0 | BE7: 0 | BF7: 0 | BG7: 0 | BH7: 0 | BI7: 0 | BJ7: 0 | BK7: 0 | BL7: 0 | BM7: 0
A8: Servicios LI-PU | D8: 0 | E8: 0 | F8: 4 | G8: 6 | H8: 0 | I8: 0 | J8: 0 | K8: 0 | L8: 4 | M8: 6 | N8: 4 | O8: 6 | P8: 4 | Q8: 6 | R8: 4 | S8: 4 | T8: 4 | U8: 6 | V8: 0 | W8: 0 | X8: 0 | Y8: 0 | Z8: 4 | AA8: 6 | AB8: 5 | AC8: 5 | AD8: 4 | AE8: 6 | AF8: 4 | AG8: 6 | AH8: 4 | AI8: 6 | AJ8: 0 | AK8: 0 | AL8: 0 | AM8: 0 | AN8: 4 | AO8: 6 | AP8: 5 | AQ8: 5 | AR8: 0 | AS8: 0 | AT8: 4 | AU8: 6 | AV8: 4 | AW8: 6 | AX8: 0 | AY8: 0 | AZ8: 0 | BA8: 0 | BB8: 4 | BC8: 6 | BD8: 5 | BE8: 5 | BF8: 5 | BG8: 5 | BH8: 4 | BI8: 6 | BJ8: 4 | BK8: 6 | BL8: 0 | BM8: 0
A10: Servicios PU-SA | D10: 0 | E10: 0 | F10: 15 | G10: 1 | H10: 0 | I10: 0 | J10: 0 | K10: 0 | L10: 15 | M10: 1 | N10: 15 | O10: 1 | P10: 15 | Q10: 1 | R10: 12 | S10: 0 | T10: 15 | U10: 1 | V10: 0 | W10: 0 | X10: 0 | Y10: 0 | Z10: 15 | AA10: 1 | AB10: 15 | AC10: 1 | AD10: 15 | AE10: 1 | AF10: 15 | AG10: 1 | AH10: 15 | AI10: 1 | AJ10: 0 | AK10: 0 | AL10: 0 | AM10: 0 | AN10: 15 | AO10: 1 | AP10: 15 | AQ10: 1 | AR10: 0 | AS10: 0 | AT10: 15 | AU10: 1 | AV10: 15 | AW10: 1 | AX10: 0 | AY10: 0 | AZ10: 0 | BA10: 0 | BB10: 15 | BC10: 1 | BD10: 15 | BE10: 1 | BF10: 15 | BG10: 1 | BH10: 16 | BI10: 0 | BJ10: 15 | BK10: 1 | BL10: 0 | BM10: 0
A11: Servicios PU-EB | D11: 0 | E11: 0 | F11: 0 | G11: 0 | H11: 0 | I11: 0 | J11: 0 | K11: 0 | L11: 0 | M11: 0 | N11: 0 | O11: 0 | P11: 0 | Q11: 0 | R11: 0 | S11: 0 | T11: 0 | U11: 0 | V11: 0 | W11: 0 | X11: 0 | Y11: 0 | Z11: 0 | AA11: 0 | AB11: 0 | AC11: 0 | AD11: 0 | AE11: 0 | AF11: 0 | AG11: 0 | AH11: 0 | AI11: 0 | AJ11: 0 | AK11: 0 | AL11: 0 | AM11: 0 | AN11: 0 | AO11: 0 | AP11: 0 | AQ11: 0 | AR11: 0 | AS11: 0 | AT11: 0 | AU11: 0 | AV11: 0 | AW11: 0 | AX11: 0 | AY11: 0 | AZ11: 0 | BA11: 0 | BB11: 0 | BC11: 0 | BD11: 0 | BE11: 0 | BF11: 0 | BG11: 0 | BH11: 0 | BI11: 0 | BJ11: 0 | BK11: 0 | BL11: 0 | BM11: 0
A12: Servicios PU-LI | D12: 51 | E12: 3 | F12: 44 | G12: 17 | H12: 69 | I12: 3 | J12: 51 | K12: 3 | L12: 44 | M12: 17 | N12: 44 | O12: 17 | P12: 44 | Q12: 17 | R12: 23 | S12: 18 | T12: 44 | U12: 17 | V12: 69 | W12: 3 | X12: 51 | Y12: 3 | Z12: 44 | AA12: 17 | AB12: 44 | AC12: 17 | AD12: 44 | AE12: 17 | AF12: 44 | AG12: 17 | AH12: 44 | AI12: 17 | AJ12: 69 | AK12: 3 | AL12: 51 | AM12: 3 | AN12: 39 | AO12: 22 | AP12: 42 | AQ12: 19 | AR12: 49 | AS12: 5 | AT12: 44 | AU12: 17 | AV12: 44 | AW12: 17 | AX12: 69 | AY12: 3 | AZ12: 51 | BA12: 3 | BB12: 44 | BC12: 17 | BD12: 44 | BE12: 17 | BF12: 44 | BG12: 17 | BH12: 44 | BI12: 17 | BJ12: 44 | BK12: 17 | BL12: 69 | BM12: 3
A13: Servicios SA-PU | D13: 0 | E13: 0 | F13: 13 | G13: 3 | H13: 0 | I13: 0 | J13: 0 | K13: 0 | L13: 13 | M13: 3 | N13: 13 | O13: 3 | P13: 13 | Q13: 3 | R13: 12 | S13: 2 | T13: 13 | U13: 3 | V13: 0 | W13: 0 | X13: 0 | Y13: 0 | Z13: 13 | AA13: 3 | AB13: 13 | AC13: 3 | AD13: 13 | AE13: 3 | AF13: 13 | AG13: 3 | AH13: 13 | AI13: 3 | AJ13: 0 | AK13: 0 | AL13: 0 | AM13: 0 | AN13: 13 | AO13: 3 | AP13: 13 | AQ13: 3 | AR13: 0 | AS13: 0 | AT13: 13 | AU13: 3 | AV13: 13 | AW13: 3 | AX13: 0 | AY13: 0 | AZ13: 0 | BA13: 0 | BB13: 13 | BC13: 3 | BD13: 13 | BE13: 3 | BF13: 13 | BG13: 3 | BH13: 13 | BI13: 3 | BJ13: 13 | BK13: 3 | BL13: 0 | BM13: 0
A14: Servicios EB-PU | D14: 0 | E14: 0 | F14: 1 | G14: 0 | H14: 0 | I14: 0 | J14: 0 | K14: 0 | L14: 1 | M14: 0 | N14: 1 | O14: 0 | P14: 1 | Q14: 0 | R14: 1 | S14: 0 | T14: 1 | U14: 0 | V14: 0 | W14: 0 | X14: 0 | Y14: 0 | Z14: 1 | AA14: 0 | AB14: 1 | AC14: 0 | AD14: 1 | AE14: 0 | AF14: 1 | AG14: 0 | AH14: 1 | AI14: 0 | AJ14: 0 | AK14: 0 | AL14: 0 | AM14: 0 | AN14: 1 | AO14: 0 | AP14: 1 | AQ14: 0 | AR14: 0 | AS14: 0 | AT14: 1 | AU14: 0 | AV14: 1 | AW14: 0 | AX14: 0 | AY14: 0 | AZ14: 0 | BA14: 0 | BB14: 1 | BC14: 0 | BD14: 1 | BE14: 0 | BF14: 1 | BG14: 0 | BH14: 1 | BI14: 0 | BJ14: 1 | BK14: 0 | BL14: 0 | BM14: 0
A15: Servicios LI-PU | D15: 57 | E15: 0 | F15: 36 | G15: 25 | H15: 75 | I15: 0 | J15: 57 | K15: 0 | L15: 36 | M15: 25 | N15: 36 | O15: 25 | P15: 36 | Q15: 25 | R15: 19 | S15: 22 | T15: 36 | U15: 25 | V15: 75 | W15: 0 | X15: 57 | Y15: 0 | Z15: 36 | AA15: 25 | AB15: 36 | AC15: 25 | AD15: 36 | AE15: 25 | AF15: 36 | AG15: 25 | AH15: 37 | AI15: 24 | AJ15: 75 | AK15: 0 | AL15: 57 | AM15: 0 | AN15: 36 | AO15: 25 | AP15: 37 | AQ15: 24 | AR15: 55 | AS15: 2 | AT15: 36 | AU15: 25 | AV15: 36 | AW15: 25 | AX15: 75 | AY15: 0 | AZ15: 57 | BA15: 0 | BB15: 38 | BC15: 23 | BD15: 36 | BE15: 25 | BF15: 36 | BG15: 25 | BH15: 36 | BI15: 25 | BJ15: 36 | BK15: 25 | BL15: 75 | BM15: 0
A16: Servicios LI-QU | R16: 1 | S16: 3
A17: Servicios QU-LI | R17: 2 | S17: 1
A18: Servicios LI-MI | R18: 0 | S18: 5
A19: Servicios MI-LI | R19: 3 | S19: 2
A20: Servicios SA-QU | R20: 1 | S20: 1
A21: Servicios PU-CH | R21: 1 | S21: 0
A22: Servicios PU-FR | R22: 1 | S22: 0
A23: Servicios PU-RE | R23: 0 | S23: 1
A24: Servicios LI-CH | R24: 0 | S24: 1
A26: Servicios PU-SA | D26: 0 | E26: 0 | F26: 7 | G26: 0 | H26: 0 | I26: 0 | J26: 0 | K26: 0 | L26: 7 | M26: 0 | N26: 7 | O26: 0 | P26: 7 | Q26: 0 | R26: 7 | S26: 0 | T26: 7 | U26: 0 | V26: 0 | W26: 0 | X26: 0 | Y26: 0 | Z26: 7 | AA26: 0 | AB26: 7 | AC26: 0 | AD26: 7 | AE26: 0 | AF26: 7 | AG26: 0 | AH26: 7 | AI26: 0 | AJ26: 0 | AK26: 0 | AL26: 0 | AM26: 0 | AN26: 7 | AO26: 0 | AP26: 7 | AQ26: 0 | AR26: 0 | AS26: 0 | AT26: 7 | AU26: 0 | AV26: 7 | AW26: 0 | AX26: 0 | AY26: 0 | AZ26: 0 | BA26: 0 | BB26: 7 | BC26: 0 | BD26: 7 | BE26: 0 | BF26: 7 | BG26: 0 | BH26: 7 | BI26: 0 | BJ26: 7 | BK26: 0 | BL26: 0 | BM26: 0
A27: Servicios PU-EB | D27: 0 | E27: 0 | F27: 0 | G27: 0 | H27: 0 | I27: 0 | J27: 0 | K27: 0 | L27: 0 | M27: 0 | N27: 0 | O27: 0 | P27: 0 | Q27: 0 | R27: 0 | S27: 0 | T27: 0 | U27: 0 | V27: 0 | W27: 0 | X27: 0 | Y27: 0 | Z27: 0 | AA27: 0 | AB27: 0 | AC27: 0 | AD27: 0 | AE27: 0 | AF27: 0 | AG27: 0 | AH27: 0 | AI27: 0 | AJ27: 0 | AK27: 0 | AL27: 0 | AM27: 0 | AN27: 0 | AO27: 0 | AP27: 0 | AQ27: 0 | AR27: 0 | AS27: 0 | AT27: 0 | AU27: 0 | AV27: 0 | AW27: 0 | AX27: 0 | AY27: 0 | AZ27: 0 | BA27: 0 | BB27: 0 | BC27: 0 | BD27: 0 | BE27: 0 | BF27: 0 | BG27: 0 | BH27: 0 | BI27: 0 | BJ27: 0 | BK27: 0 | BL27: 0 | BM27: 0
A28: Servicios PU-LI | D28: 0 | E28: 0 | F28: 2 | G28: 6 | H28: 0 | I28: 0 | J28: 0 | K28: 0 | L28: 2 | M28: 6 | N28: 2 | O28: 6 | P28: 2 | Q28: 6 | R28: 3 | S28: 5 | T28: 2 | U28: 6 | V28: 0 | W28: 0 | X28: 0 | Y28: 0 | Z28: 2 | AA28: 6 | AB28: 2 | AC28: 6 | AD28: 2 | AE28: 6 | AF28: 2 | AG28: 6 | AH28: 3 | AI28: 5 | AJ28: 0 | AK28: 0 | AL28: 0 | AM28: 0 | AN28: 2 | AO28: 6 | AP28: 3 | AQ28: 5 | AR28: 0 | AS28: 0 | AT28: 2 | AU28: 6 | AV28: 2 | AW28: 6 | AX28: 0 | AY28: 0 | AZ28: 0 | BA28: 0 | BB28: 4 | BC28: 4 | BD28: 2 | BE28: 6 | BF28: 2 | BG28: 6 | BH28: 2 | BI28: 6 | BJ28: 2 | BK28: 6 | BL28: 0 | BM28: 0
A29: Servicios SA-PU | D29: 0 | E29: 0 | F29: 6 | G29: 0 | H29: 0 | I29: 0 | J29: 0 | K29: 0 | L29: 6 | M29: 0 | N29: 6 | O29: 0 | P29: 6 | Q29: 0 | R29: 6 | S29: 0 | T29: 6 | U29: 0 | V29: 0 | W29: 0 | X29: 0 | Y29: 0 | Z29: 6 | AA29: 0 | AB29: 6 | AC29: 0 | AD29: 6 | AE29: 0 | AF29: 6 | AG29: 0 | AH29: 6 | AI29: 0 | AJ29: 0 | AK29: 0 | AL29: 0 | AM29: 0 | AN29: 6 | AO29: 0 | AP29: 6 | AQ29: 0 | AR29: 0 | AS29: 0 | AT29: 6 | AU29: 0 | AV29: 6 | AW29: 0 | AX29: 0 | AY29: 0 | AZ29: 0 | BA29: 0 | BB29: 6 | BC29: 0 | BD29: 6 | BE29: 0 | BF29: 6 | BG29: 0 | BH29: 6 | BI29: 0 | BJ29: 6 | BK29: 0 | BL29: 0 | BM29: 0
A30: Servicios EB-PU | D30: 0 | E30: 0 | F30: 0 | G30: 0 | H30: 0 | I30: 0 | J30: 0 | K30: 0 | L30: 0 | M30: 0 | N30: 0 | O30: 0 | P30: 0 | Q30: 0 | R30: 0 | S30: 0 | T30: 0 | U30: 0 | V30: 0 | W30: 0 | X30: 0 | Y30: 0 | Z30: 0 | AA30: 0 | AB30: 0 | AC30: 0 | AD30: 0 | AE30: 0 | AF30: 0 | AG30: 0 | AH30: 0 | AI30: 0 | AJ30: 0 | AK30: 0 | AL30: 0 | AM30: 0 | AN30: 0 | AO30: 0 | AP30: 0 | AQ30: 0 | AR30: 0 | AS30: 0 | AT30: 0 | AU30: 0 | AV30: 0 | AW30: 0 | AX30: 0 | AY30: 0 | AZ30: 0 | BA30: 0 | BB30: 0 | BC30: 0 | BD30: 0 | BE30: 0 | BF30: 0 | BG30: 0 | BH30: 0 | BI30: 0 | BJ30: 0 | BK30: 0 | BL30: 0 | BM30: 0
A31: Servicios LI-PU | D31: 0 | E31: 0 | F31: 5 | G31: 2 | H31: 0 | I31: 0 | J31: 0 | K31: 0 | L31: 5 | M31: 2 | N31: 5 | O31: 2 | P31: 5 | Q31: 2 | R31: 5 | S31: 2 | T31: 5 | U31: 2 | V31: 0 | W31: 0 | X31: 0 | Y31: 0 | Z31: 5 | AA31: 2 | AB31: 5 | AC31: 2 | AD31: 5 | AE31: 2 | AF31: 5 | AG31: 2 | AH31: 5 | AI31: 2 | AJ31: 0 | AK31: 0 | AL31: 0 | AM31: 0 | AN31: 5 | AO31: 2 | AP31: 5 | AQ31: 2 | AR31: 0 | AS31: 0 | AT31: 5 | AU31: 2 | AV31: 5 | AW31: 2 | AX31: 0 | AY31: 0 | AZ31: 0 | BA31: 0 | BB31: 5 | BC31: 2 | BD31: 5 | BE31: 2 | BF31: 5 | BG31: 2 | BH31: 5 | BI31: 2 | BJ31: 5 | BK31: 2 | BL31: 0 | BM31: 0
D34: =SUM(D3:D31) -> 108 | E34: =SUM(E3:E31) -> 3 | F34: =SUM(F3:F31) -> 150 | G34: =SUM(G3:G31) -> 73 | H34: =SUM(H3:H31) -> 144 | I34: =SUM(I3:I31) -> 3 | J34: =SUM(J3:J31) -> 108 | K34: =SUM(K3:K31) -> 3 | ... BM34: =SUM(BM3:BM31) -> 3
A40: Km Servicio
A41: PU - LI | D41: =D5+D12+D28 -> 51 | E41: =E5+E12+E28 -> 3 | F41: =F5+F12+F28 -> 47 | G41: =G5+G12+G28 -> 32 | H41: =H5+H12+H28 -> 69 | I41: =I5+I12+I28 -> 3 | J41: =J5+J12+J28 -> 51 | K41: =K5+K12+K28 -> 3 | ... BM41: =BM5+BM12+BM28 -> 3
A42: LI - PU | D42: =D8+D15+D31 -> 57 | E42: =E8+E15+E31 -> 0 | F42: =F8+F15+F31 -> 45 | G42: =G8+G15+G31 -> 33 | H42: =H8+H15+H31 -> 75 | I42: =I8+I15+I31 -> 0 | J42: =J8+J15+J31 -> 57 | K42: =K8+K15+K31 -> 0 | ... BM42: =BM8+BM15+BM31 -> 0
A43: PU - SA | D43: =D3+D10+D26 -> 0 | E43: =E3+E10+E26 -> 0 | F43: =F3+F10+F26 -> 29 | G43: =G3+G10+G26 -> 4 | H43: =H3+H10+H26 -> 0 | I43: =I3+I10+I26 -> 0 | J43: =J3+J10+J26 -> 0 | K43: =K3+K10+K26 -> 0 | ... BM43: =BM3+BM10+BM26 -> 0
A44: SA - PU | D44: =D6+D13+D29 -> 0 | E44: =E6+E13+E29 -> 0 | F44: =F6+F13+F29 -> 28 | G44: =G6+G13+G29 -> 4 | H44: =H6+H13+H29 -> 0 | I44: =I6+I13+I29 -> 0 | J44: =J6+J13+J29 -> 0 | K44: =K6+K13+K29 -> 0 | ... BM44: =BM6+BM13+BM29 -> 0
A45: PU-EB | D45: =D4+D11+D27 -> 0 | E45: =E4+E11+E27 -> 0 | F45: =F4+F11+F27 -> 0 | G45: =G4+G11+G27 -> 0 | H45: =H4+H11+H27 -> 0 | I45: =I4+I11+I27 -> 0 | J45: =J4+J11+J27 -> 0 | K45: =K4+K11+K27 -> 0 | ... BM45: =BM4+BM11+BM27 -> 0
A46: EB-PU | D46: =D7+D14+D30 -> 0 | E46: =E7+E14+E30 -> 0 | F46: =F7+F14+F30 -> 1 | G46: =G7+G14+G30 -> 0 | H46: =H7+H14+H30 -> 0 | I46: =I7+I14+I30 -> 0 | J46: =J7+J14+J30 -> 0 | K46: =K7+K14+K30 -> 0 | ... BM46: =BM7+BM14+BM30 -> 0
A47: LI-QU | R47: =R16 -> 1 | S47: =S16 -> 3
A48: QU-LI | R48: =R17 -> 2 | S48: =S17 -> 1
A49: LI-MI | R49: =R18 -> 0 | S49: =S18 -> 5
...

Sheet Oferta Diaria
A1: Oferta Mayo 2025
C3: 45778 | D3: 45779 | E3: 45780 | F3: 45781 | G3: 45782 | H3: 45783 | I3: 45784 | J3: 45785 | K3: 45786 | L3: 45787 | M3: 45788 | N3: 45789 | O3: 45790 | P3: 45791 | Q3: 45792 | R3: 45793 | S3: 45794 | T3: 45795 | U3: 45796 | V3: 45797 | W3: 45798 | X3: 45799 | Y3: 45800 | Z3: 45801 | AA3: 45802 | AB3: 45803 | AC3: 45804 | AD3: 45805 | AE3: 45806 | AF3: 45807 | AG3: 45808
A4: HÁBIL | B4: km
A5: Servicios PU-LI | B5: 43.13 | C5: ='Data Ocupacion'!D59 -> 54 | D5: ='Data Ocupacion'!F59 -> 79 | E5: ='Data Ocupacion'!H59 -> 72 | F5: ='Data Ocupacion'!J59 -> 54 | G5: ='Data Ocupacion'!L59 -> 79 | H5: ='Data Ocupacion'!N59 -> 79 | I5: ='Data Ocupacion'!P59 -> 79 | J5: ='Data Ocupacion'!R59 -> 55 | K5: ='Data Ocupacion'!T59 -> 79 | L5: ='Data Ocupacion'!V59 -> 72 | M5: ='Data Ocupacion'!X59 -> 54 | N5: ='Data Ocupacion'!Z59 -> 79 | O5: ='Data Ocupacion'!AB59 -> 79 | P5: ='Data Ocupacion'!AD59 -> 79 | Q5: ='Data Ocupacion'!AF59 -> 79 | R5: ='Data Ocupacion'!AH59 -> 79 | S5: ='Data Ocupacion'!AJ59 -> 72 | T5: ='Data Ocupacion'!AL59 -> 54 | U5: ='Data Ocupacion'!AN59 -> 79 | V5: ='Data Ocupacion'!AP59 -> 79 | W5: ='Data Ocupacion'!AR59 -> 54 | X5: ='Data Ocupacion'!AT59 -> 79 | Y5: ='Data Ocupacion'!AV59 -> 79 | Z5: ='Data Ocupacion'!AX59 -> 72 | AA5: ='Data Ocupacion'!AZ59 -> 54 | AB5: ='Data Ocupacion'!BB59 -> 79 | AC5: ='Data Ocupacion'!BD59 -> 79 | AD5: ='Data Ocupacion'!BF59 -> 79 | AE5: ='Data Ocupacion'!BH59 -> 79 | AF5: ='Data Ocupacion'!BJ59 -> 79 | AG5: ='Data Ocupacion'!BL59 -> 72
A6: Servicios LI-PU | B6: 43.13 | C6: ='Data Ocupacion'!D60 -> 57 | D6: ='Data Ocupacion'!F60 -> 78 | E6: ='Data Ocupacion'!H60 -> 75 | F6: ='Data Ocupacion'!J60 -> 57 | G6: ='Data Ocupacion'!L60 -> 78 | H6: ='Data Ocupacion'!N60 -> 78 | I6: ='Data Ocupacion'!P60 -> 78 | J6: ='Data Ocupacion'!R60 -> 56 | K6: ='Data Ocupacion'!T60 -> 78 | L6: ='Data Ocupacion'!V60 -> 75 | M6: ='Data Ocupacion'!X60 -> 57 | N6: ='Data Ocupacion'!Z60 -> 78 | O6: ='Data Ocupacion'!AB60 -> 78 | P6: ='Data Ocupacion'!AD60 -> 78 | Q6: ='Data Ocupacion'!AF60 -> 78 | R6: ='Data Ocupacion'!AH60 -> 78 | S6: ='Data Ocupacion'!AJ60 -> 75 | T6: ='Data Ocupacion'!AL60 -> 57 | U6: ='Data Ocupacion'!AN60 -> 78 | V6: ='Data Ocupacion'!AP60 -> 78 | W6: ='Data Ocupacion'!AR60 -> 57 | X6: ='Data Ocupacion'!AT60 -> 78 | Y6: ='Data Ocupacion'!AV60 -> 78 | Z6: ='Data Ocupacion'!AX60 -> 75 | AA6: ='Data Ocupacion'!AZ60 -> 57 | AB6: ='Data Ocupacion'!BB60 -> 78 | AC6: ='Data Ocupacion'!BD60 -> 78 | AD6: ='Data Ocupacion'!BF60 -> 78 | AE6: ='Data Ocupacion'!BH60 -> 78 | AF6: ='Data Ocupacion'!BJ60 -> 78 | AG6: ='Data Ocupacion'!BL60 -> 75
A7: Servicios PU-SA | B7: 29.11 | C7: ='Data Ocupacion'!D61 -> 0 | D7: ='Data Ocupacion'!F61 -> 33 | E7: ='Data Ocupacion'!H61 -> 0 | F7: ='Data Ocupacion'!J61 -> 0 | G7: ='Data Ocupacion'!L61 -> 33 | H7: ='Data Ocupacion'!N61 -> 33 | I7: ='Data Ocupacion'!P61 -> 33 | J7: ='Data Ocupacion'!R61 -> 21 | K7: ='Data Ocupacion'!T61 -> 33 | L7: ='Data Ocupacion'!V61 -> 0 | M7: ='Data Ocupacion'!X61 -> 0 | N7: ='Data Ocupacion'!Z61 -> 33 | O7: ='Data Ocupacion'!AB61 -> 33 | P7: ='Data Ocupacion'!AD61 -> 33 | Q7: ='Data Ocupacion'!AF61 -> 33 | R7: ='Data Ocupacion'!AH61 -> 33 | S7: ='Data Ocupacion'!AJ61 -> 0 | T7: ='Data Ocupacion'!AL61 -> 0 | U7: ='Data Ocupacion'!AN61 -> 33 | V7: ='Data Ocupacion'!AP61 -> 33 | W7: ='Data Ocupacion'!AR61 -> 0 | X7: ='Data Ocupacion'!AT61 -> 33 | Y7: ='Data Ocupacion'!AV61 -> 33 | Z7: ='Data Ocupacion'!AX61 -> 0 | AA7: ='Data Ocupacion'!AZ61 -> 0 | AB7: ='Data Ocupacion'!BB61 -> 33 | AC7: ='Data Ocupacion'!BD61 -> 33 | AD7: ='Data Ocupacion'!BF61 -> 33 | AE7: ='Data Ocupacion'!BH61 -> 33 | AF7: ='Data Ocupacion'!BJ61 -> 33 | AG7: ='Data Ocupacion'!BL61 -> 0
A8: Servicios SA-PU | B8: 29.11 | C8: ='Data Ocupacion'!D62 -> 0 | D8: ='Data Ocupacion'!F62 -> 32 | E8: ='Data Ocupacion'!H62 -> 0 | F8: ='Data Ocupacion'!J62 -> 0 | G8: ='Data Ocupacion'!L62 -> 32 | H8: ='Data Ocupacion'!N62 -> 32 | I8: ='Data Ocupacion'!P62 -> 32 | J8: ='Data Ocupacion'!R62 -> 21 | K8: ='Data Ocupacion'!T62 -> 32 | L8: ='Data Ocupacion'!V62 -> 0 | M8: ='Data Ocupacion'!X62 -> 0 | N8: ='Data Ocupacion'!Z62 -> 32 | O8: ='Data Ocupacion'!AB62 -> 32 | P8: ='Data Ocupacion'!AD62 -> 32 | Q8: ='Data Ocupacion'!AF62 -> 32 | R8: ='Data Ocupacion'!AH62 -> 32 | S8: ='Data Ocupacion'!AJ62 -> 0 | T8: ='Data Ocupacion'!AL62 -> 0 | U8: ='Data Ocupacion'!AN62 -> 32 | V8: ='Data Ocupacion'!AP62 -> 32 | W8: ='Data Ocupacion'!AR62 -> 0 | X8: ='Data Ocupacion'!AT62 -> 32 | Y8: ='Data Ocupacion'!AV62 -> 32 | Z8: ='Data Ocupacion'!AX62 -> 0 | AA8: ='Data Ocupacion'!AZ62 -> 0 | AB8: ='Data Ocupacion'!BB62 -> 32 | AC8: ='Data Ocupacion'!BD62 -> 32 | AD8: ='Data Ocupacion'!BF62 -> 32 | AE8: ='Data Ocupacion'!BH62 -> 32 | AF8: ='Data Ocupacion'!BJ62 -> 32 | AG8: ='Data Ocupacion'!BL62 -> 0
A9: Servicios PU-EB | B9: 25.4 | C9: ='Data Ocupacion'!D63 -> 0 | D9: ='Data Ocupacion'!F63 -> 0 | E9: ='Data Ocupacion'!H63 -> 0 | F9: ='Data Ocupacion'!J63 -> 0 | G9: ='Data Ocupacion'!L63 -> 0 | H9: ='Data Ocupacion'!N63 -> 0 | I9: ='Data Ocupacion'!P63 -> 0 | J9: ='Data Ocupacion'!R63 -> 0 | K9: ='Data Ocupacion'!T63 -> 0 | L9: ='Data Ocupacion'!V63 -> 0 | M9: ='Data Ocupacion'!X63 -> 0 | N9: ='Data Ocupacion'!Z63 -> 0 | O9: ='Data Ocupacion'!AB63 -> 0 | P9: ='Data Ocupacion'!AD63 -> 0 | Q9: ='Data Ocupacion'!AF63 -> 0 | R9: ='Data Ocupacion'!AH63 -> 0 | S9: ='Data Ocupacion'!AJ63 -> 0 | T9: ='Data Ocupacion'!AL63 -> 0 | U9: ='Data Ocupacion'!AN63 -> 0 | V9: ='Data Ocupacion'!AP63 -> 0 | W9: ='Data Ocupacion'!AR63 -> 0 | X9: ='Data Ocupacion'!AT63 -> 0 | Y9: ='Data Ocupacion'!AV63 -> 0 | Z9: ='Data Ocupacion'!AX63 -> 0 | AA9: ='Data Ocupacion'!AZ63 -> 0 | AB9: ='Data Ocupacion'!BB63 -> 0 | AC9: ='Data Ocupacion'!BD63 -> 0 | AD9: ='Data Ocupacion'!BF63 -> 0 | AE9: ='Data Ocupacion'!BH63 -> 0 | AF9: ='Data Ocupacion'!BJ63 -> 0 | AG9: ='Data Ocupacion'!BL63 -> 0
A10: Servicios EB-PU | B10: 25.4 | C10: ='Data Ocupacion'!D64 -> 0 | D10: ='Data Ocupacion'!F64 -> 1 | E10: ='Data Ocupacion'!H64 -> 0 | F10: ='Data Ocupacion'!J64 -> 0 | G10: ='Data Ocupacion'!L64 -> 1 | H10: ='Data Ocupacion'!N64 -> 1 | I10: ='Data Ocupacion'!P64 -> 1 | J10: ='Data Ocupacion'!R64 -> 1 | K10: ='Data Ocupacion'!T64 -> 1 | L10: ='Data Ocupacion'!V64 -> 0 | M10: ='Data Ocupacion'!X64 -> 0 | N10: ='Data Ocupacion'!Z64 -> 1 | O10: ='Data Ocupacion'!AB64 -> 1 | P10: ='Data Ocupacion'!AD64 -> 1 | Q10: ='Data Ocupacion'!AF64 -> 1 | R10: ='Data Ocupacion'!AH64 -> 1 | S10: ='Data Ocupacion'!AJ64 -> 0 | T10: ='Data Ocupacion'!AL64 -> 0 | U10: ='Data Ocupacion'!AN64 -> 1 | V10: ='Data Ocupacion'!AP64 -> 1 | W10: ='Data Ocupacion'!AR64 -> 0 | X10: ='Data Ocupacion'!AT64 -> 1 | Y10: ='Data Ocupacion'!AV64 -> 1 | Z10: ='Data Ocupacion'!AX64 -> 0 | AA10: ='Data Ocupacion'!AZ64 -> 0 | AB10: ='Data Ocupacion'!BB64 -> 1 | AC10: ='Data Ocupacion'!BD64 -> 1 | AD10: ='Data Ocupacion'!BF64 -> 1 | AE10: ='Data Ocupacion'!BH64 -> 1 | AF10: ='Data Ocupacion'!BJ64 -> 1 | AG10: ='Data Ocupacion'!BL64 -> 0
A11: Servicios PU-ES | B11: 11.71
A12: Servicios LI-QU | B12: 21.7 | J12: ='Data Ocupacion'!R65 -> 4
A13: Servicios QU-LI | B13: 21.7 | J13: ='Data Ocupacion'!R66 -> 3
A14: Servicios LI-MI | B14: 35.73 | J14: ='Data Ocupacion'!R67 -> 5
A15: Servicios MI-LI | B15: 35.73 | J15: ='Data Ocupacion'!R68 -> 5
A16: Servicios SA-QU | B16: 7.68 | J16: ='Data Ocupacion'!R69 -> 2
A17: Servicios PU-CH | B17: 10.17 | J17: ='Data Ocupacion'!R70 -> 1
A18: Servicios PU-FR | B18: 1.42 | J18: ='Data Ocupacion'!R71 -> 1
A19: Servicios PU-RE | B19: 5.99 | J19: ='Data Ocupacion'!R72 -> 1
A20: Servicios LI-CH | B20: 32.96 | J20: ='Data Ocupacion'!R73 -> 1
A22: Trenes PU-LI | B22: 43.13 | C22: ='Data Ocupacion'!D76 -> 57 | D22: ='Data Ocupacion'!F76 -> 111 | E22: ='Data Ocupacion'!H76 -> 75 | F22: ='Data Ocupacion'!J76 -> 57 | G22: ='Data Ocupacion'!L76 -> 111 | H22: ='Data Ocupacion'!N76 -> 111 | I22: ='Data Ocupacion'!P76 -> 111 | J22: ='Data Ocupacion'!R76 -> 79 | K22: ='Data Ocupacion'!T76 -> 111 | L22: ='Data Ocupacion'!V76 -> 75 | M22: ='Data Ocupacion'!X76 -> 57 | N22: ='Data Ocupacion'!Z76 -> 111 | O22: ='Data Ocupacion'!AB76 -> 110 | P22: ='Data Ocupacion'!AD76 -> 111 | Q22: ='Data Ocupacion'!AF76 -> 111 | R22: ='Data Ocupacion'!AH76 -> 110 | S22: ='Data Ocupacion'!AJ76 -> 75 | T22: ='Data Ocupacion'!AL76 -> 57 | U22: ='Data Ocupacion'!AN76 -> 116 | V22: ='Data Ocupacion'!AP76 -> 111 | W22: ='Data Ocupacion'!AR76 -> 59 | X22: ='Data Ocupacion'!AT76 -> 111 | Y22: ='Data Ocupacion'!AV76 -> 111 | Z22: ='Data Ocupacion'!AX76 -> 75 | AA22: ='Data Ocupacion'!AZ76 -> 57 | AB22: ='Data Ocupacion'!BB76 -> 109 | AC22: ='Data Ocupacion'!BD76 -> 110 | AD22: ='Data Ocupacion'!BF76 -> 110 | AE22: ='Data Ocupacion'!BH76 -> 111 | AF22: ='Data Ocupacion'!BJ76 -> 111 | AG22: ='Data Ocupacion'!BL76 -> 75
A23: Trenes LI-PU | B23: 43.13 | C23: ='Data Ocupacion'!D77 -> 57 | D23: ='Data Ocupacion'!F77 -> 111 | E23: ='Data Ocupacion'!H77 -> 75 | F23: ='Data Ocupacion'!J77 -> 57 | G23: ='Data Ocupacion'!L77 -> 111 | H23: ='Data Ocupacion'!N77 -> 111 | I23: ='Data Ocupacion'!P77 -> 111 | J23: ='Data Ocupacion'!R77 -> 84 | K23: ='Data Ocupacion'!T77 -> 111 | L23: ='Data Ocupacion'!V77 -> 75 | M23: ='Data Ocupacion'!X77 -> 57 | N23: ='Data Ocupacion'!Z77 -> 111 | O23: ='Data Ocupacion'!AB77 -> 110 | P23: ='Data Ocupacion'!AD77 -> 111 | Q23: ='Data Ocupacion'!AF77 -> 111 | R23: ='Data Ocupacion'!AH77 -> 110 | S23: ='Data Ocupacion'!AJ77 -> 75 | T23: ='Data Ocupacion'!AL77 -> 57 | U23: ='Data Ocupacion'!AN77 -> 111 | V23: ='Data Ocupacion'!AP77 -> 109 | W23: ='Data Ocupacion'!AR77 -> 59 | X23: ='Data Ocupacion'!AT77 -> 111 | Y23: ='Data Ocupacion'!AV77 -> 111 | Z23: ='Data Ocupacion'!AX77 -> 75 | AA23: ='Data Ocupacion'!AZ77 -> 57 | AB23: ='Data Ocupacion'!BB77 -> 109 | AC23: ='Data Ocupacion'!BD77 -> 110 | AD23: ='Data Ocupacion'!BF77 -> 110 | AE23: ='Data Ocupacion'!BH77 -> 111 | AF23: ='Data Ocupacion'!BJ77 -> 111 | AG23: ='Data Ocupacion'!BL77 -> 75
A24: Trenes PU-SA | B24: 29.11 | C24: ='Data Ocupacion'!D78 -> 0 | D24: ='Data Ocupacion'!F78 -> 37 | E24: ='Data Ocupacion'!H78 -> 0 | F24: ='Data Ocupacion'!J78 -> 0 | G24: ='Data Ocupacion'!L78 -> 37 | H24: ='Data Ocupacion'!N78 -> 37 | I24: ='Data Ocupacion'!P78 -> 37 | J24: ='Data Ocupacion'!R78 -> 21 | K24: ='Data Ocupacion'!T78 -> 37 | L24: ='Data Ocupacion'!V78 -> 0 | M24: ='Data Ocupacion'!X78 -> 0 | N24: ='Data Ocupacion'!Z78 -> 37 | O24: ='Data Ocupacion'!AB78 -> 37 | P24: ='Data Ocupacion'!AD78 -> 37 | Q24: ='Data Ocupacion'!AF78 -> 37 | R24: ='Data Ocupacion'!AH78 -> 37 | S24: ='Data Ocupacion'!AJ78 -> 0 | T24: ='Data Ocupacion'!AL78 -> 0 | U24: ='Data Ocupacion'!AN78 -> 37 | V24: ='Data Ocupacion'!AP78 -> 37 | W24: ='Data Ocupacion'!AR78 -> 0 | X24: ='Data Ocupacion'!AT78 -> 37 | Y24: ='Data Ocupacion'!AV78 -> 37 | Z24: ='Data Ocupacion'!AX78 -> 0 | AA24: ='Data Ocupacion'!AZ78 -> 0 | AB24: ='Data Ocupacion'!BB78 -> 37 | AC24: ='Data Ocupacion'!BD78 -> 37 | AD24: ='Data Ocupacion'!BF78 -> 37 | AE24: ='Data Ocupacion'!BH78 -> 36 | AF24: ='Data Ocupacion'!BJ78 -> 37 | AG24: ='Data Ocupacion'!BL78 -> 0
A25: Trenes SA-PU | B25: 29.11 | C25: ='Data Ocupacion'!D79 -> 0 | D25: ='Data Ocupacion'!F79 -> 36 | E25: ='Data Ocupacion'!H79 -> 0 | F25: ='Data Ocupacion'!J79 -> 0 | G25: ='Data Ocupacion'!L79 -> 36 | H25: ='Data Ocupacion'!N79 -> 36 | I25: ='Data Ocupacion'!P79 -> 36 | J25: ='Data Ocupacion'!R79 -> 23 | K25: ='Data Ocupacion'!T79 -> 36 | L25: ='Data Ocupacion'!V79 -> 0 | M25: ='Data Ocupacion'!X79 -> 0 | N25: ='Data Ocupacion'!Z79 -> 36 | O25: ='Data Ocupacion'!AB79 -> 36 | P25: ='Data Ocupacion'!AD79 -> 36 | Q25: ='Data Ocupacion'!AF79 -> 36 | R25: ='Data Ocupacion'!AH79 -> 36 | S25: ='Data Ocupacion'!AJ79 -> 0 | T25: ='Data Ocupacion'!AL79 -> 0 | U25: ='Data Ocupacion'!AN79 -> 36 | V25: ='Data Ocupacion'!AP79 -> 36 | W25: ='Data Ocupacion'!AR79 -> 0 | X25: ='Data Ocupacion'!AT79 -> 36 | Y25: ='Data Ocupacion'!AV79 -> 36 | Z25: ='Data Ocupacion'!AX79 -> 0 | AA25: ='Data Ocupacion'!AZ79 -> 0 | AB25: ='Data Ocupacion'!BB79 -> 36 | AC25: ='Data Ocupacion'!BD79 -> 36 | AD25: ='Data Ocupacion'!BF79 -> 36 | AE25: ='Data Ocupacion'!BH79 -> 35 | AF25: ='Data Ocupacion'!BJ79 -> 36 | AG25: ='Data Ocupacion'!BL79 -> 0
A26: Trenes EB-PU | B26: 25.4 | C26: ='Data Ocupacion'!D81 -> 0 | D26: ='Data Ocupacion'!F81 -> 1 | E26: ='Data Ocupacion'!H81 -> 0 | F26: ='Data Ocupacion'!J81 -> 0 | G26: ='Data Ocupacion'!L81 -> 1 | H26: ='Data Ocupacion'!N81 -> 1 | I26: ='Data Ocupacion'!P81 -> 1 | J26: ='Data Ocupacion'!R81 -> 1 | K26: ='Data Ocupacion'!T81 -> 1 | L26: ='Data Ocupacion'!V81 -> 0 | M26: ='Data Ocupacion'!X81 -> 0 | N26: ='Data Ocupacion'!Z81 -> 1 | O26: ='Data Ocupacion'!AB81 -> 1 | P26: ='Data Ocupacion'!AD81 -> 1 | Q26: ='Data Ocupacion'!AF81 -> 1 | R26: ='Data Ocupacion'!AH81 -> 1 | S26: ='Data Ocupacion'!AJ81 -> 0 | T26: ='Data Ocupacion'!AL81 -> 0 | U26: ='Data Ocupacion'!AN81 -> 1 | V26: ='Data Ocupacion'!AP81 -> 1 | W26: ='Data Ocupacion'!AR81 -> 0 | X26: ='Data Ocupacion'!AT81 -> 1 | Y26: ='Data Ocupacion'!AV81 -> 1 | Z26: ='Data Ocupacion'!AX81 -> 0 | AA26: ='Data Ocupacion'!AZ81 -> 0 | AB26: ='Data Ocupacion'!BB81 -> 1 | AC26: ='Data Ocupacion'!BD81 -> 1 | AD26: ='Data Ocupacion'!BF81 -> 1 | AE26: ='Data Ocupacion'!BH81 -> 1 | AF26: ='Data Ocupacion'!BJ81 -> 1 | AG26: ='Data Ocupacion'!BL81 -> 0
A27: Trenes PU-EB | B27: 25.4 | C27: 0 | D27: 0 | E27: 0 | F27: 0 | G27: 0 | H27: 0 | I27: 0 | K27: 0 | L27: 0 | M27: 0 | N27: 0 | O27: 0 | P27: 0 | Q27: 0 | R27: 0 | S27: 0 | T27: 0 | U27: 0 | V27: 0 | W27: 0 | X27: 0 | Y27: 0 | Z27: 0 | AA27: 0 | AB27: 0 | AC27: 0 | AD27: 0 | AE27: 0 | AF27: 0 | AG27: 0
A28: Trenes PU-ES | B28: 11.71
A29: Trenes LI-QU | B29: 21.7 | J29: ='Data Ocupacion'!R82 -> 7
A30: Trenes QU-LI | B30: 21.7 | J30: ='Data Ocupacion'!R83 -> 4
A31: Trenes LI-MI | B31: 35.73 | J31: ='Data Ocupacion'!R84 -> 10
A32: Trenes MI-LI | B32: 35.73 | J32: ='Data Ocupacion'!R85 -> 7
A33: Trenes SA-QU | B33: 7.68 | J33: ='Data Ocupacion'!R86 -> 3
A34: Trenes PU-CH | B34: 10.17 | J34: ='Data Ocupacion'!R87 -> 1
A35: Trenes PU-FR | B35: 1.42 | J35: ='Data Ocupacion'!R88 -> 1
A36: Trenes PU-RE | B36: 5.99 | J36: ='Data Ocupacion'!R89 -> 2
A37: Trenes LI-CH | B37: 32.96 | J37: ='Data Ocupacion'!R90 -> 2
A39: Corte EB (600) | B39: -17.73 | C39: ='KM-Servicio'!Q5 -> 0 | D39: ='KM-Servicio'!Q12 -> 4 | E39: ='KM-Servicio'!Q19 -> 0 | F39: ='KM-Servicio'!Q26 -> 0 | G39: ='KM-Servicio'!Q33 -> 2 | H39: ='KM-Servicio'!Q40 -> 0 | I39: ='KM-Servicio'!Q47 -> 0 | J39: ='KM-Servicio'!Q54 -> 0 | K39: ='KM-Servicio'!Q70 -> 1 | L39: ='KM-Servicio'!Q77 -> 0 | M39: ='KM-Servicio'!Q84 -> 0 | N39: ='KM-Servicio'!Q91 -> 3 | O39: ='KM-Servicio'!Q98 -> 3 | P39: ='KM-Servicio'!Q105 -> 4 | Q39: ='KM-Servicio'!Q112 -> 3 | R39: ='KM-Servicio'!Q119 -> 5 | S39: ='KM-Servicio'!Q126 -> 0 | T39: ='KM-Servicio'!Q133 -> 0 | U39: ='KM-Servicio'!Q140 -> 4 | V39: ='KM-Servicio'!Q147 -> 0 | W39: ='KM-Servicio'!Q154 -> 0 | X39: ='KM-Servicio'!Q161 -> 0 | Y39: ='KM-Servicio'!Q168 -> 0 | Z39: ='KM-Servicio'!Q175 -> 0 | AA39: ='KM-Servicio'!Q182 -> 0 | AB39: ='KM-Servicio'!Q189 -> 4 | AC39: ='KM-Servicio'!Q196 -> 3 | AD39: ='KM-Servicio'!Q203 -> 4 | AE39: ='KM-Servicio'!Q210 -> 1 | AF39: 0 | AG39: ='KM-Servicio'!Q224 -> 0
A40: Acople EB (600) | B40: -17.73 | C40: ='KM-Servicio'!T6 -> 0 | D40: ='KM-Servicio'!T13 -> 0 | E40: ='KM-Servicio'!T20 -> 0 | F40: ='KM-Servicio'!T27 -> 0 | G40: ='KM-Servicio'!T34 -> 0 | H40: ='KM-Servicio'!T41 -> 0 | I40: ='KM-Servicio'!T48 -> 0 | J40: ='KM-Servicio'!T55 -> 0 | K40: ='KM-Servicio'!T71 -> 0 | L40: ='KM-Servicio'!T78 -> 0 | M40: ='KM-Servicio'!T85 -> 0 | N40: ='KM-Servicio'!T92 -> 0 | O40: ='KM-Servicio'!T99 -> 0 | P40: ='KM-Servicio'!T106 -> 0 | Q40: ='KM-Servicio'!T113 -> 0 | R40: ='KM-Servicio'!T120 -> 0 | S40: ='KM-Servicio'!T127 -> 0 | T40: ='KM-Servicio'!T134 -> 0 | U40: ='KM-Servicio'!T141 -> 0 | V40: ='KM-Servicio'!T148 -> 0 | W40: ='KM-Servicio'!T155 -> 0 | X40: ='KM-Servicio'!T162 -> 0 | Y40: ='KM-Servicio'!T169 -> 0 | Z40: ='KM-Servicio'!T176 -> 0 | AA40: ='KM-Servicio'!T183 -> 0 | AB40: ='KM-Servicio'!T190 -> 0 | AC40: 0 | AD40: ='KM-Servicio'!T204 -> 0 | AE40: ='KM-Servicio'!T211 -> 0 | AF40: ='KM-Servicio'!T217 -> 3 | AG40: ='KM-Servicio'!Q225 -> 0
A41: Acople/Corte SA (600) | B41: -14.02 | C41: ='KM-Servicio'!U6 -> 0 | D41: ='KM-Servicio'!U13 -> 0 | E41: ='KM-Servicio'!U20 -> 0 | F41: ='KM-Servicio'!U27 -> 0 | G41: ='KM-Servicio'!U34 -> 0 | H41: ='KM-Servicio'!U41 -> 0 | I41: ='KM-Servicio'!U48 -> 0 | J41: ='KM-Servicio'!U55 -> 0 | K41: ='KM-Servicio'!U71 -> 0 | L41: ='KM-Servicio'!U78 -> 0 | M41: ='KM-Servicio'!U85 -> 0 | N41: ='KM-Servicio'!U92 -> 0 | O41: ='KM-Servicio'!U99 -> 0 | P41: ='KM-Servicio'!U106 -> 0 | Q41: ='KM-Servicio'!U113 -> 0 | R41: ='KM-Servicio'!U120 -> 0 | S41: ='KM-Servicio'!U127 -> 0 | T41: ='KM-Servicio'!U134 -> 0 | U41: ='KM-Servicio'!U141 -> 0 | V41: ='KM-Servicio'!U148 -> 0 | W41: ='KM-Servicio'!U155 -> 0 | X41: ='KM-Servicio'!U162 -> 0 | Y41: ='KM-Servicio'!U169 -> 0 | Z41: ='KM-Servicio'!U176 -> 0 | AA41: ='KM-Servicio'!U183 -> 0 | AB41: ='KM-Servicio'!U190 -> 0 | AC41: ='KM-Servicio'!U197 -> 0 | AD41: ='KM-Servicio'!U204 -> 0 | AE41: ='KM-Servicio'!U211 -> 0 | AF41: ='KM-Servicio'!U218 -> 0 | AG41: ='KM-Servicio'!Q226 -> 0
A42: Corte EB (400) | B42: -3.71 | E42: ='KM-Servicio'!Q21 -> 0 | G42: ='KM-Servicio'!Q35 -> 0 | N42: ='KM-Servicio'!Q93 -> 0
A43: Acople EB (600) vía 1 | B43: 17.73 | D43: 4 | G43: 3 | H43: 2 | I43: 4 | K43: 3 | N43: 2 | O43: 1 | P43: 1 | R43: 3 | U43: 5 | V43: 2 | W43: 2 | X43: 3 | Y43: 2 | AB43: 2 | AC43: 4 | AD43: 4 | AE43: 3 | AF43: 3
...

Sheet UMR Resumen
A1: Mayo 2025
A2: Fecha | B2: Odómetro | C2: Odómetro acum. | D2: Tren-Km | E2: Tren-Km Acum. | F2: UMR Diario | G2: Viajes Programados | H2: Viajes Realizados | I2: IR | J2: Indice Regularidad (QU-via 2) 7:10am a 8:10am | K2: TKB (no TKBC) | L2: Tipo Dia | M2: Comentarios
A3: 45778 | B3: ='KM-Servicio'!N11 -> 4943 | C3: =B3 -> 4943 | D3: ='KM-Servicio'!W11 -> 4916.82 | E3: =D3 -> 4916.82 | F3: ='KM-Servicio'!O11 -> 99.470362 | G3: =SUM('KM-Servicio'!B11:C11) -> 111 | H3: =SUM('KM-Servicio'!D11:E11) -> 111 | K3: ='Oferta Diaria'!C53 -> 389903.83 | L3: Dgo-Festivo
A4: 45779 | B4: ='KM-Servicio'!N18 -> 12128 | C4: =B4+C3 -> 17071 | D4: ='KM-Servicio'!W18 -> 11725.29 | E4: =D4+E3 -> 16642.11 | F4: ='KM-Servicio'!O18 -> 96.679502 | G4: =SUM('KM-Servicio'!B18:C18) -> 223 | H4: =SUM('KM-Servicio'!D18:E18) -> 223 | K4: ='Oferta Diaria'!D53 -> 929815.5 | L4: Laboral
A5: 45780 | B5: ='KM-Servicio'!N25 -> 6489 | C5: =B5+C4 -> 23560 | D5: ='KM-Servicio'!W25 -> 6469.5 | E5: =D5+E4 -> 23111.61 | F5: ='KM-Servicio'!O25 -> 99.699491 | G5: =SUM('KM-Servicio'!B25:C25) -> 147 | H5: =SUM('KM-Servicio'!D25:E25) -> 147 | K5: ='Oferta Diaria'!E53 -> 513031.35 | L5: Sábado
A6: 45781 | B6: ='KM-Servicio'!N32 -> 4955 | C6: =B6+C5 -> 28515 | D6: ='KM-Servicio'!W32 -> 4916.82 | E6: =D6+E5 -> 28028.43 | F6: ='KM-Servicio'!O32 -> 99.229465 | G6: =SUM('KM-Servicio'!B32:C32) -> 111 | H6: =SUM('KM-Servicio'!D32:E32) -> 111 | K6: ='Oferta Diaria'!F53 -> 389903.83 | L6: Dgo-Festivo
A7: 45782 | B7: ='KM-Servicio'!N39 -> 12105 | C7: =B7+C6 -> 40620 | D7: ='KM-Servicio'!W39 -> 11743.02 | E7: =D7+E6 -> 39771.45 | F7: ='KM-Servicio'!O39 -> 97.009665 | G7: =SUM('KM-Servicio'!B39:C39) -> 223 | H7: =SUM('KM-Servicio'!D39:E39) -> 223 | K7: ='Oferta Diaria'!G53 -> 931221.49 | L7: Laboral
A8: 45783 | B8: ='KM-Servicio'!N46 -> 12087 | C8: =B8+C7 -> 52707 | D8: ='KM-Servicio'!W46 -> 11760.75 | E8: =D8+E7 -> 51532.2 | F8: ='KM-Servicio'!O46 -> 97.300819 | G8: =SUM('KM-Servicio'!B46:C46) -> 223 | H8: =SUM('KM-Servicio'!D46:E46) -> 223 | K8: ='Oferta Diaria'!H53 -> 932627.47 | L8: Laboral
