Workbook

Sheet Odometro-Kilometraje
A1: Control Contador Kilometraje de Trenes
B2: 45717 | C2: 45718 | D2: 45719 | E2: 45720 | F2: 45721 | G2: 45722 | H2: 45723 | I2: 45724 | J2: 45725 | K2: 45726 | L2: 45727 | M2: 45728 | N2: 45729 | O2: 45730 | P2: 45731 | Q2: 45732 | R2: 45733 | S2: 45734 | T2: 45735 | U2: 45736 | V2: 45737 | W2: 45738 | X2: 45739 | Y2: 45740 | Z2: 45741 | AA2: 45742 | AB2: 45743 | AC2: 45744 | AD2: 45745 | AE2: 45746 | AF2: 45747
B3: Contador | C3: Contador | D3: Contador | E3: Contador | F3: Contador | G3: Contador | H3: Contador | I3: Contador | J3: Contador | K3: Contador | L3: Contador | M3: Contador | N3: Contador | O3: Contador | P3: Contador | Q3: Contador | R3: Contador | S3: Contador | T3: Contador | U3: Contador | V3: Contador | W3: Contador | X3: Contador | Y3: Contador | Z3: Contador | AA3: Contador | AB3: Contador | AC3: Contador | AD3: Contador | AE3: Contador | AF3: Contador
A4: Tren | B4: Odómetro | C4: Odómetro | D4: Odómetro | E4: Odómetro | F4: Odómetro | G4: Odómetro | H4: Odómetro | I4: Odómetro | J4: Odómetro | K4: Odómetro | L4: Odómetro | M4: Odómetro | N4: Odómetro | O4: Odómetro | P4: Odómetro | Q4: Odómetro | R4: Odómetro | S4: Odómetro | T4: Odómetro | U4: Odómetro | V4: Odómetro | W4: Odómetro | X4: Odómetro | Y4: Odómetro | Z4: Odómetro | AA4: Odómetro | AB4: Odómetro | AC4: Odómetro | AD4: Odómetro | AE4: Odómetro | AF4: Odómetro
A5: M01 | B5: 1987958 | C5: 1987958 | D5: 1988221 | E5: 1988747 | F5: 1989307 | G5: 1989823 | H5: 1990169 | I5: 1990729 | J5: 1990772 | K5: 1991044 | L5: 1991540 | M5: 1992058 | N5: 1992514 | O5: 1992763 | P5: 1992763 | Q5: 1992763 | R5: 1993013 | S5: 1993265 | T5: 1993851 | U5: 1994105 | V5: 1994356 | W5: 1994356 | X5: 1994356 | Y5: 1994550 | Z5: 1994718 | AA5: 1995008 | AB5: 1995430 | AC5: 1995714 | AD5: 1995714 | AE5: 1995714 | AF5: 1995898
A6: M02 | B6: 1973652 | C6: 1973652 | D6: 1974088 | E6: 1974394 | F6: 1974699 | G6: 1974962 | H6: 1975412 | I6: 1975412 | J6: 1975412 | K6: 1975616 | L6: 1975913 | M6: 1976430 | N6: 1976991 | O6: 1977551 | P6: 1977853 | Q6: 1977941 | R6: 1978144 | S6: 1978224 | T6: 1978485 | U6: 1978767 | V6: 1979019 | W6: 1979019 | X6: 1979019 | Y6: 1979275 | Z6: 1979790 | AA6: 1979993 | AB6: 1980244 | AC6: 1980435 | AD6: 1980435 | AE6: 1980435 | AF6: 1980980
A7: M03 | B7: 2042460 | C7: 2042979 | D7: 2043375 | E7: 2043849 | F7: 2044114 | G7: 2044719 | H7: 2044897 | I7: 2044897 | J7: 2044897 | K7: 2045416 | L7: 2045618 | M7: 2045809 | N7: 2046105 | O7: 2046580 | P7: 2046607 | Q7: 2047085 | R7: 2047391 | S7: 2047910 | T7: 2048471 | U7: 2048963 | V7: 2049158 | W7: 2049158 | X7: 2049158 | Y7: 2049410 | Z7: 2049666 | AA7: 2050097 | AB7: 2050384 | AC7: 2050971 | AD7: 2051492 | AE7: 2051924 | AF7: 2052441
A8: M04 | B8: 2044111 | C8: 2044111 | D8: 2044363 | E8: 2044615 | F8: 2045013 | G8: 2045271 | H8: 2045525 | I8: 2045784 | J8: 2045786 | K8: 2046091 | L8: 2046441 | M8: 2046935 | N8: 2047187 | O8: 2047390 | P8: 2047390 | Q8: 2047390 | R8: 2047642 | S8: 2047893 | T8: 2048145 | U8: 2048337 | V8: 2048838 | W8: 2049403 | X8: 2049446 | Y8: 2050007 | Z8: 2050525 | AA8: 2051010 | AB8: 2051178 | AC8: 2051568 | AD8: 2051612 | AE8: 2052132 | AF8: 2052736
A9: M05 | B9: 1952560 | C9: 1952561 | D9: 1953081 | E9: 1953531 | F9: 1953725 | G9: 1953977 | H9: 1954227 | I9: 1954227 | J9: 1954227 | K9: 1954479 | L9: 1954674 | M9: 1955186 | N9: 1955791 | O9: 1956310 | P9: 1956872 | Q9: 1957261 | R9: 1957498 | S9: 1957750 | T9: 1958063 | U9: 1958605 | V9: 1959230 | W9: 1959273 | X9: 1959792 | Y9: 1960114 | Z9: 1960562 | AA9: 1961020 | AB9: 1961264 | AC9: 1961516 | AD9: 1961516 | AE9: 1961516 | AF9: 1961768
A10: M06 | B10: 2063874 | C10: 2064377 | D10: 2064637 | E10: 2065155 | F10: 2065714 | G10: 2066274 | H10: 2066647 | I10: 2067207 | J10: 2067207 | K10: 2067728 | L10: 2068273 | M10: 2068765 | N10: 2068967 | O10: 2069486 | P10: 2070005 | Q10: 2070095 | R10: 2070612 | S10: 2070869 | T10: 2071055 | U10: 2071465 | V10: 2071939 | W10: 2072456 | X10: 2072499 | Y10: 2073015 | Z10: 2073460 | AA10: 2073651 | AB10: 2073902 | AC10: 2074153 | AD10: 2074153 | AE10: 2074153 | AF10: 2074404
A11: M07 | B11: 2089922 | C11: 2090400 | D11: 2091007 | E11: 2091571 | F11: 2092023 | G11: 2092193 | H11: 2092714 | I11: 2093235 | J11: 2093756 | K11: 2094018 | L11: 2094542 | M11: 2094798 | N11: 2095234 | O11: 2095758 | P11: 2096321 | Q11: 2096365 | R11: 2096649 | S11: 2096982 | T11: 2097176 | U11: 2097426 | V11: 2097678 | W11: 2097678 | X11: 2097678 | Y11: 2098209 | Z11: 2098558 | AA11: 2098870 | AB11: 2099393 | AC11: 2100003 | AD11: 2100570 | AE11: 2101004 | AF11: 2101568
A12: M08 | B12: 1994451 | C12: 1994453 | D12: 1994973 | E12: 1995356 | F12: 1995960 | G12: 1996565 | H12: 1997100 | I12: 1997100 | J12: 1997100 | K12: 1997500 | L12: 1997704 | M12: 1998188 | N12: 1998539 | O12: 1998992 | P12: 1998992 | Q12: 1998992 | R12: 1999194 | S12: 1999756 | T12: 2000235 | U12: 2000520 | V12: 2000772 | W12: 2000774 | X12: 2000774 | Y12: 2001294 | Z12: 2001849 | AA12: 2002126 | AB12: 2002424 | AC12: 2003028 | AD12: 2003073 | AE12: 2003549 | AF12: 2004153
A13: M09 | B13: 1978640 | C13: 1978683 | D13: 1978896 | E13: 1979165 | F13: 1979697 | G13: 1980224 | H13: 1980492 | I13: 1981060 | J13: 1981280 | K13: 1981483 | L13: 1981738 | M13: 1982248 | N13: 1982514 | O13: 1983128 | P13: 1983655 | Q13: 1984094 | R13: 1984446 | S13: 1985017 | T13: 1985414 | U13: 1985855 | V13: 1986423 | W13: 1986468 | X13: 1986950 | Y13: 1987451 | Z13: 1987707 | AA13: 1987901 | AB13: 1988157 | AC13: 1988351 | AD13: 1988351 | AE13: 1988351 | AF13: 1988548
A14: M10 | B14: 2055772 | C14: 2056248 | D14: 2056655 | E14: 2056867 | F14: 2057174 | G14: 2057693 | H14: 2057998 | I14: 2058516 | J14: 2058947 | K14: 2059426 | L14: 2059728 | M14: 2060160 | N14: 2060440 | O14: 2060634 | P14: 2060634 | Q14: 2060634 | R14: 2061202 | S14: 2061483 | T14: 2061677 | U14: 2062018 | V14: 2062581 | W14: 2063098 | X14: 2063573 | Y14: 2064177 | Z14: 2064378 | AA14: 2064770 | AB14: 2064850 | AC14: 2065193 | AD14: 2065713 | AE14: 2065801 | AF14: 2066252
A15: M11 | B15: 2071551 | C15: 2071551 | D15: 2071807 | E15: 2072415 | F15: 2072626 | G15: 2073192 | H15: 2073583 | I15: 2073847 | J15: 2074327 | K15: 2074738 | L15: 2074993 | M15: 2075235 | N15: 2075576 | O15: 2075826 | P15: 2075826 | Q15: 2075826 | R15: 2076158 | S15: 2076511 | T15: 2076993 | U15: 2077600 | V15: 2078163 | W15: 2078686 | X15: 2079164 | Y15: 2079411 | Z15: 2079894 | AA15: 2080300 | AB15: 2080608 | AC15: 2081172 | AD15: 2081260 | AE15: 2081261 | AF15: 2081458
A16: M12 | B16: 1911593 | C16: 1911637 | D16: 1912157 | E16: 1912503 | F16: 1912679 | G16: 1913241 | H16: 1913631 | I16: 1914151 | J16: 1914626 | K16: 1914817 | L16: 1915335 | M16: 1915854 | N16: 1916244 | O16: 1916805 | P16: 1917324 | Q16: 1917799 | R16: 1918403 | S16: 1918896 | T16: 1919160 | U16: 1919486 | V16: 1920090 | W16: 1920651 | X16: 1920875 | Y16: 1921307 | Z16: 1921509 | AA16: 1922043 | AB16: 1922495 | AC16: 1922661 | AD16: 1923184 | AE16: 1923662 | AF16: 1924155
... A39: XM35 | B39: 645879 | C39: 645879 | D39: 646049 | E39: 646396 | F39: 646761 | G39: 647012 | H39: 647213 | I39: 647213 | J39: 647213 | K39: 647456 | L39: 647858 | M39: 648111 | N39: 648383 | O39: 648634 | P39: 648634 | Q39: 648634 | R39: 648972 | S39: 649224 | T39: 649537 | U39: 649799 | V39: 650250 | W39: 650250 | X39: 650250 | Y39: 650502 | Z39: 650816 | AA39: 651023 | AB39: 651543 | AC39: 651805 | AD39: 651806 | AE39: 651809 | AF39: 652247
A41: Kilometraje Diario Recorrido
B42: 45717 | C42: 45718 | D42: 45719 | E42: 45720 | F42: 45721 | G42: 45722 | H42: 45723 | I42: 45724 | J42: 45725 | K42: 45726 | L42: 45727 | M42: 45728 | N42: 45729 | O42: 45730 | P42: 45731 | Q42: 45732 | R42: 45733 | S42: 45734 | T42: 45735 | U42: 45736 | V42: 45737 | W42: 45738 | X42: 45739 | Y42: 45740 | Z42: 45741 | AA42: 45742 | AB42: 45743 | AC42: 45744 | AD42: 45745 | AE42: 45746 | AF42: 45747
B43: Kilometraje | C43: Kilometraje | D43: Kilometraje | E43: Kilometraje | F43: Kilometraje | G43: Kilometraje | H43: Kilometraje | I43: Kilometraje | J43: Kilometraje | K43: Kilometraje | L43: Kilometraje | M43: Kilometraje | N43: Kilometraje | O43: Kilometraje | P43: Kilometraje | Q43: Kilometraje | R43: Kilometraje | S43: Kilometraje | T43: Kilometraje | U43: Kilometraje | V43: Kilometraje | W43: Kilometraje | X43: Kilometraje | Y43: Kilometraje | Z43: Kilometraje | AA43: Kilometraje | AB43: Kilometraje | AC43: Kilometraje | AD43: Kilometraje | AE43: Kilometraje | AF43: Kilometraje
A44: Tren | B44: Diario | C44: Diario | D44: Diario | E44: Diario | F44: Diario | G44: Diario | H44: Diario | I44: Diario | J44: Diario | K44: Diario | L44: Diario | M44: Diario | N44: Diario | O44: Diario | P44: Diario | Q44: Diario | R44: Diario | S44: Diario | T44: Diario | U44: Diario | V44: Diario | W44: Diario | X44: Diario | Y44: Diario | Z44: Diario | AA44: Diario | AB44: Diario | AC44: Diario | AD44: Diario | AE44: Diario | AF44: Diario
A45: M01 | B45: 449 | C45: =C5-B5 -> 0 | D45: =D5-C5 -> 263 | E45: =E5-D5 -> 526 | F45: =F5-E5 -> 560 | G45: =G5-F5 -> 516 | H45: =H5-G5 -> 346 | I45: =I5-H5 -> 560 | J45: =J5-I5 -> 43 | ... AF45: =AF5-AE5 -> 184
A46: M02 | B46: 0 | C46: =C6-B6 -> 0 | D46: =D6-C6 -> 436 | E46: =E6-D6 -> 306 | F46: =F6-E6 -> 305 | G46: =G6-F6 -> 263 | H46: =H6-G6 -> 450 | I46: =I6-H6 -> 0 | J46: =J6-I6 -> 0 | ... AF46: =AF6-AE6 -> 545
A47: M03 | B47: 573 | C47: =C7-B7 -> 519 | D47: =D7-C7 -> 396 | E47: =E7-D7 -> 474 | F47: =F7-E7 -> 265 | G47: =G7-F7 -> 605 | H47: =H7-G7 -> 178 | I47: =I7-H7 -> 0 | J47: =J7-I7 -> 0 | ... AF47: =AF7-AE7 -> 517
A48: M04 | B48: 174 | C48: =C8-B8 -> 0 | D48: =D8-C8 -> 252 | E48: =E8-D8 -> 252 | F48: =F8-E8 -> 398 | G48: =G8-F8 -> 258 | H48: =H8-G8 -> 254 | I48: =I8-H8 -> 259 | J48: =J8-I8 -> 2 | ... AF48: =AF8-AE8 -> 604
A49: M05 | B49: 279 | C49: =C9-B9 -> 1 | D49: =D9-C9 -> 520 | E49: =E9-D9 -> 450 | F49: =F9-E9 -> 194 | G49: =G9-F9 -> 252 | H49: =H9-G9 -> 250 | I49: =I9-H9 -> 0 | J49: =J9-I9 -> 0 | ... AF49: =AF9-AE9 -> 252
A50: M06 | B50: 259 | C50: =C10-B10 -> 503 | D50: =D10-C10 -> 260 | E50: =E10-D10 -> 518 | F50: =F10-E10 -> 559 | G50: =G10-F10 -> 560 | H50: =H10-G10 -> 373 | I50: =I10-H10 -> 560 | J50: =J10-I10 -> 0 | ... AF50: =AF10-AE10 -> 251
A51: M07 | B51: 282 | C51: =C11-B11 -> 478 | D51: =D11-C11 -> 607 | E51: =E11-D11 -> 564 | F51: =F11-E11 -> 452 | G51: =G11-F11 -> 170 | H51: =H11-G11 -> 521 | I51: =I11-H11 -> 521 | J51: =J11-I11 -> 521 | ... AF51: =AF11-AE11 -> 564
A52: M08 | B52: 0 | C52: =C12-B12 -> 2 | D52: =D12-C12 -> 520 | E52: =E12-D12 -> 383 | F52: =F12-E12 -> 604 | G52: =G12-F12 -> 605 | H52: =H12-G12 -> 535 | I52: =I12-H12 -> 0 | J52: =J12-I12 -> 0 | ... AF52: =AF12-AE12 -> 604
A53: M09 | B53: 220 | C53: =C13-B13 -> 43 | D53: =D13-C13 -> 213 | E53: =E13-D13 -> 269 | F53: =F13-E13 -> 532 | G53: =G13-F13 -> 527 | H53: =H13-G13 -> 268 | I53: =I13-H13 -> 568 | J53: =J13-I13 -> 220 | ... AF53: =AF13-AE13 -> 197
A54: M10 | B54: 158 | C54: =C14-B14 -> 476 | D54: =D14-C14 -> 407 | E54: =E14-D14 -> 212 | F54: =F14-E14 -> 307 | G54: =G14-F14 -> 519 | H54: =H14-G14 -> 305 | I54: =I14-H14 -> 518 | J54: =J14-I14 -> 431 | ... AF54: =AF14-AE14 -> 451
A55: M11 | B55: 0 | C55: =C15-B15 -> 0 | D55: =D15-C15 -> 256 | E55: =E15-D15 -> 608 | F55: =F15-E15 -> 211 | G55: =G15-F15 -> 566 | H55: =H15-G15 -> 391 | I55: =I15-H15 -> 264 | J55: =J15-I15 -> 480 | ... AF55: =AF15-AE15 -> 197
A56: M12 | B56: 621 | C56: =C16-B16 -> 44 | D56: =D16-C16 -> 520 | E56: =E16-D16 -> 346 | F56: =F16-E16 -> 176 | G56: =G16-F16 -> 562 | H56: =H16-G16 -> 390 | I56: =I16-H16 -> 520 | J56: =J16-I16 -> 475 | ... AF56: =AF16-AE16 -> 493
... A79: XM35 | B79: 0 | C79: =C39-B39 -> 0 | D79: =D39-C39 -> 170 | E79: =E39-D39 -> 347 | F79: =F39-E39 -> 365 | G79: =G39-F39 -> 251 | H79: =H39-G39 -> 201 | I79: =I39-H39 -> 0 | J79: =J39-I39 -> 0 | ... AF79: =AF39-AE39 -> 438
A81: Kilometraje Diario | B81: =SUM(B45:B79) -> 8422 | C81: =SUM(C45:C79) -> 5211 | D81: =SUM(D45:D79) -> 11744 | E81: =SUM(E45:E79) -> 11775 | F81: =SUM(F45:F79) -> 11732 | G81: =SUM(G45:G79) -> 11736 | H81: =SUM(H45:H79) -> 11720 | I81: =SUM(I45:I79) -> 6497 | ... AF81: =SUM(AF45:AF79) -> 12023

Sheet KM-Servicio
H1: SA-MI | I1: 21.7 | J1: EB-PU | K1: 25.4 | L1: PU-SA | M1: 29.11 | N1: QU-LI / LI-QU | O1: 21.7 | P1: VM-PU | Q1: 8.3 | R1: VM-LI | S1: 34.83 | T1: LI-PO | U1: 39.19 | W1: PU-ES/ES-PU | X1: 11.71
B2: CANTIDAD DE SERVICIOS | D2: CANTIDAD DE SERVICIOS | H2: PU-PE | I2: 30.4 | J2: PO-SA | K2: 25.4 | L2: PU-LI | M2: 43.13 | N2: MI-LI / LI-MI | O2: 35.73 | P2: HO-LI/LI-HO | Q2: 33.97 | R2: PU-MI | S2: 7.4 | T2: LI-PE | U2: 12.72 | W2: MI-SA | X2: 21.7
B3: PROGRAMADOS | D3: REALIZADOS | F3: Origen-Destino | G3: Total Trenes | H3: Total Trenes P | I3: Total Servicios | J3: Kms.xTrenes | K3: Kmsxservicios. | L3: Asientos x Kms. | M3: Disp x Km. | N3: Total Odómetro | O3: % Uso Trenes | Q3: Cortes | T3: Acoples | W3: KmTren R | X3: KmTren P
B4: Simples | C4: Dobles | D4: Simples | E4: Dobles | Q4: EB | R4: SA | S4: PE | T4: EB | U4: SA | V4: PE
A5: 45717 | B5: 53 | C5: 19 | D5: ='Data Ocupacion'!D42 -> 54 | E5: ='Data Ocupacion'!E42 -> 18 | F5: PU-LI | G5: =D5+E5*2 -> 90 | H5: =B5+C5*2 -> 91 | I5: =D5+E5 -> 72 | J5: =G5*M$2 -> 3881.7 | K5: =I5*M$2 -> 3105.36 | L5: =J5*104 -> 403696.8 | M5: =I5*104 -> 7488 | W5: =J5-(Q5*($M$2-$K$1)+(R5*($M$2-$M$1))+ (S5*($M$2-$I$2))) -> 3881.7 | X5: =H5*$M$2 -> 3924.83
A6: PLANILLA FESTIVAL VINA DEL MAR SABADO (SERVICIOS NOCTURNOS) | B6: 59 | C6: 16 | D6: ='Data Ocupacion'!D43 -> 58 | E6: ='Data Ocupacion'!E43 -> 17 | F6: LI-PU | G6: =D6+E6*2 -> 92 | H6: =B6+C6*2 -> 91 | I6: =D6+E6 -> 75 | J6: =G6*M$2 -> 3967.96 | K6: =I6*M$2 -> 3234.75 | L6: =J6*104 -> 412667.84 | M6: =I6*104 -> 7800 | T6: 4 | W6: =J6-(T6*($M$2-$K$1)+(U6*($M$2-$M$1))) -> 3897.04 | X6: =H6*$M$2 -> 3924.83
B7: 0 | C7: 0 | D7: ='Data Ocupacion'!D44 -> 0 | E7: ='Data Ocupacion'!E44 -> 0 | F7: PU-SA | G7: =D7+E7*2 -> 0 | H7: =B7+C7*2 -> 0 | I7: =D7+E7 -> 0 | J7: =G7*M$1 -> 0 | K7: =I7*M$1 -> 0 | L7: =J7*104 -> 0 | M7: =I7*104 -> 0 | W7: =J7-(Q7*($M$1-$K$1)) -> 0 | X7: =H7*$M$1 -> 0
B8: 0 | C8: 0 | D8: ='Data Ocupacion'!D45 -> 0 | E8: ='Data Ocupacion'!E45 -> 0 | F8: SA-PU | G8: =D8+E8*2 -> 0 | H8: =B8+C8*2 -> 0 | I8: =D8+E8 -> 0 | J8: =G8*M$1 -> 0 | K8: =I8*M$1 -> 0 | L8: =J8*104 -> 0 | M8: =I8*104 -> 0 | W8: =J8 -> 0 | X8: =H8*$M$1 -> 0
B9: 0 | C9: 0 | D9: ='Data Ocupacion'!D46 -> 0 | E9: ='Data Ocupacion'!E46 -> 0 | F9: PU-EB | G9: =D9+E9*2 -> 0 | H9: =B9+C9*2 -> 0 | I9: =D9+E9 -> 0 | J9: =G9*K$1 -> 0 | K9: =I9*K$1 -> 0 | L9: =J9*104 -> 0 | M9: =I9*104 -> 0 | W9: =J9 -> 0 | X9: =H9*$K$1 -> 0
B10: 0 | C10: 0 | D10: ='Data Ocupacion'!D47 -> 0 | E10: ='Data Ocupacion'!E47 -> 0 | F10: EB-PU | G10: =D10+E10*2 -> 0 | H10: =B10+C10*2 -> 0 | I10: =D10+E10 -> 0 | J10: =G10*K$1 -> 0 | K10: =I10*K$1 -> 0 | L10: =J10*104 -> 0 | M10: =I10*104 -> 0 | W10: =J10 -> 0 | X10: =H10*$K$1 -> 0
B11: 4 | C11: 0 | D11: ='Data Ocupacion'!D50 -> 3 | E11: ='Data Ocupacion'!E50 -> 1 | F11: VM-LI | G11: =D11+E11*2 -> 5 | H11: =B11+C11*2 -> 4 | I11: =D11+E11 -> 4 | J11: =G11*S$1 -> 174.15 | K11: =I11*S$1 -> 139.32 | L11: =J11*104 -> 18111.6 | M11: =I11*104 -> 416 | W11: =J11 -> 174.15 | X11: =H11*$S$1 -> 139.32
B12: 2 | C12: 0 | D12: ='Data Ocupacion'!D51 -> 2 | E12: ='Data Ocupacion'!E51 -> 0 | F12: VM-PU | G12: =D12+E12*2 -> 2 | H12: =B12+C12*2 -> 2 | I12: =D12+E12 -> 2 | J12: =G12*Q$1 -> 16.6 | K12: =I12*Q$1 -> 16.6 | L12: =J12*104 -> 1726.4 | M12: =I12*104 -> 208 | W12: =J12 -> 16.6 | X12: =H12*$Q$1 -> 16.6
B13: =SUM(B5:B12) -> 118 | C13: =SUM(C5:C12) -> 35 | D13: =SUM(D5:D12) -> 117 | E13: =SUM(E5:E12) -> 36 | G13: =SUM(G5:G12) -> 189 | H13: =SUM(H5:H12) -> 188 | I13: =SUM(I5:I12) -> 153 | J13: =SUM(J5:J12) -> 8040.41 | K13: =SUM(K5:K12) -> 6496.03 | L13: =SUM(L5:L12) -> 836202.64 | M13: =SUM(M5:M12) -> 15912 | N13: ='Odometro-Kilometraje'!B81 -> 8422 | O13: =(W13/N13)*100 -> 94.627048 | W13: =SUM(W5:W12) -> 7969.49 | X13: =SUM(X5:X12) -> 8005.58
A14: =A5+1 -> 45718 | B14: 51 | C14: 3 | D14: ='Data Ocupacion'!F42 -> 52 | E14: ='Data Ocupacion'!G42 -> 2 | F14: PU-LI | G14: =D14+E14*2 -> 56 | H14: =B14+C14*2 -> 57 | I14: =D14+E14 -> 54 | J14: =G14*M$2 -> 2415.28 | K14: =I14*M$2 -> 2329.02 | L14: =J14*104 -> 251189.12 | M14: =I14*104 -> 5616 | W14: =J14-(Q14*($M$2-$K$1)+(R14*($M$2-$M$1))+ (S14*($M$2-$I$2))+ (T14*($M$2-$K$1))) -> 2415.28 | X14: =H14*$M$2 -> 2458.41
A15: PLANILLA FESTIVAL VINA DEL MAR (SERVICIOS NOCTURNOS) | B15: 57 | C15: 0 | D15: ='Data Ocupacion'!F43 -> 57 | E15: ='Data Ocupacion'!G43 -> 0 | F15: LI-PU | G15: =D15+E15*2 -> 57 | H15: =B15+C15*2 -> 57 | I15: =D15+E15 -> 57 | J15: =G15*M$2 -> 2458.41 | K15: =I15*M$2 -> 2458.41 | L15: =J15*104 -> 255674.64 | M15: =I15*104 -> 5928 | W15: =J15-(T15*($M$2-$K$1)+(U15*($M$2-$M$1))) -> 2458.41 | X15: =H15*$M$2 -> 2458.41
B16: 0 | C16: 0 | D16: ='Data Ocupacion'!F44 -> 0 | E16: ='Data Ocupacion'!G44 -> 0 | F16: PU-SA | G16: =D16+E16*2 -> 0 | H16: =B16+C16*2 -> 0 | I16: =D16+E16 -> 0 | J16: =G16*M$1 -> 0 | K16: =I16*M$1 -> 0 | L16: =J16*104 -> 0 | M16: =I16*104 -> 0 | W16: =J16-(Q16*($M$1-$K$1)) -> 0 | X16: =H16*$M$1 -> 0
B17: 0 | C17: 0 | D17: ='Data Ocupacion'!F45 -> 0 | E17: ='Data Ocupacion'!G45 -> 0 | F17: SA-PU | G17: =D17+E17*2 -> 0 | H17: =B17+C17*2 -> 0 | I17: =D17+E17 -> 0 | J17: =G17*M$1 -> 0 | K17: =I17*M$1 -> 0 | L17: =J17*104 -> 0 | M17: =I17*104 -> 0 | W17: =J17 -> 0 | X17: =H17*$M$1 -> 0
B18: 0 | C18: 0 | D18: ='Data Ocupacion'!F46 -> 0 | E18: ='Data Ocupacion'!G46 -> 0 | F18: PU-EB | G18: =D18+E18*2 -> 0 | H18: =B18+C18*2 -> 0 | I18: =D18+E18 -> 0 | J18: =G18*K$1 -> 0 | K18: =I18*K$1 -> 0 | L18: =J18*104 -> 0 | M18: =I18*104 -> 0 | W18: =J18 -> 0 | X18: =H18*$K$1 -> 0
B19: 0 | C19: 0 | D19: ='Data Ocupacion'!F47 -> 0 | E19: ='Data Ocupacion'!G47 -> 0 | F19: EB-PU | G19: =D19+E19*2 -> 0 | H19: =B19+C19*2 -> 0 | I19: =D19+E19 -> 0 | J19: =G19*K$1 -> 0 | K19: =I19*K$1 -> 0 | L19: =J19*104 -> 0 | M19: =I19*104 -> 0 | W19: =J19 -> 0 | X19: =H19*$K$1 -> 0
B20: 4 | C20: 0 | D20: ='Data Ocupacion'!F50 -> 3 | E20: ='Data Ocupacion'!G50 -> 1 | F20: VM-LI | G20: =D20+E20*2 -> 5 | H20: =B20+C20*2 -> 4 | I20: =D20+E20 -> 4 | J20: =G20*S$1 -> 174.15 | K20: =I20*S$1 -> 139.32 | L20: =J20*104 -> 18111.6 | M20: =I20*104 -> 416 | W20: =J20 -> 174.15 | X20: =H20*$S$1 -> 139.32
B21: 2 | C21: 0 | D21: ='Data Ocupacion'!F51 -> 2 | E21: ='Data Ocupacion'!G51 -> 0 | F21: VM-PU | G21: =D21+E21*2 -> 2 | H21: =B21+C21*2 -> 2 | I21: =D21+E21 -> 2 | J21: =G21*Q$1 -> 16.6 | K21: =I21*Q$1 -> 16.6 | L21: =J21*104 -> 1726.4 | M21: =I21*104 -> 208 | W21: =J21 -> 16.6 | X21: =H21*$Q$1 -> 16.6
B22: =SUM(B14:B21) -> 114 | C22: =SUM(C14:C21) -> 3 | D22: =SUM(D14:D21) -> 114 | E22: =SUM(E14:E21) -> 3 | G22: =SUM(G14:G21) -> 120 | H22: =SUM(H14:H21) -> 120 | I22: =SUM(I14:I21) -> 117 | J22: =SUM(J14:J20) -> 5047.84 | K22: =SUM(K14:K21) -> 4943.35 | L22: =SUM(L14:L21) -> 526701.76 | M22: =SUM(M14:M21) -> 12168 | N22: ='Odometro-Kilometraje'!C81 -> 5211 | O22: =(W22/N22)*100 -> 97.187488 | W22: =SUM(W14:W21) -> 5064.44 | X22: =SUM(X14:X21) -> 5072.74
A23: =A14+1 -> 45719 | B23: 51 | C23: 28 | D23: ='Data Ocupacion'!H42 -> 51 | E23: ='Data Ocupacion'!I42 -> 28 | F23: PU-LI | G23: =D23+E23*2 -> 107 | H23: =B23+C23*2 -> 107 | I23: =D23+E23 -> 79 | J23: =G23*M$2 -> 4614.91 | K23: =I23*M$2 -> 3407.27 | L23: =J23*104 -> 479950.64 | M23: =I23*104 -> 8216 | Q23: 1 | W23: =J23-(Q23*($M$2-$K$1)+(R23*($M$2-$M$1))+ (S23*($M$2-$I$2))+(T23*$K$1)) -> 4597.18 | X23: =H23*$M$2 -> 4614.91
A24: Planila 025 Laboral Lun-Vie Ver 1 | B24: 49 | C24: 29 | D24: ='Data Ocupacion'!H43 -> 49 | E24: ='Data Ocupacion'!I43 -> 29 | F24: LI-PU | G24: =D24+E24*2 -> 107 | H24: =B24+C24*2 -> 107 | I24: =D24+E24 -> 78 | J24: =G24*M$2 -> 4614.91 | K24: =I24*M$2 -> 3364.14 | L24: =J24*104 -> 479950.64 | M24: =I24*104 -> 8112 | W24: =J24-(T24*($M$2-$K$1)+(U24*($M$2-$M$1))) -> 4614.91 | X24: =H24*$M$2 -> 4614.91
B25: 30 | C25: 3 | D25: ='Data Ocupacion'!H44 -> 30 | E25: ='Data Ocupacion'!I44 -> 3 | F25: PU-SA | G25: =D25+E25*2 -> 36 | H25: =B25+C25*2 -> 36 | I25: =D25+E25 -> 33 | J25: =G25*M$1 -> 1047.96 | K25: =I25*M$1 -> 960.63 | L25: =J25*104 -> 108987.84 | M25: =I25*104 -> 3432 | W25: =J25-(Q25*($M$1-$K$1)) -> 1047.96 | X25: =H25*$M$1 -> 1047.96
B26: 29 | C26: 3 | D26: ='Data Ocupacion'!H45 -> 29 | E26: ='Data Ocupacion'!I45 -> 3 | F26: SA-PU | G26: =D26+E26*2 -> 35 | H26: =B26+C26*2 -> 35 | I26: =D26+E26 -> 32 | J26: =G26*M$1 -> 1018.85 | K26: =I26*M$1 -> 931.52 | L26: =J26*104 -> 105960.4 | M26: =I26*104 -> 3328 | W26: =J26 -> 1018.85 | X26: =H26*$M$1 -> 1018.85
B27: 0 | C27: 0 | D27: ='Data Ocupacion'!H46 -> 0 | E27: ='Data Ocupacion'!I46 -> 0 | F27: PU-EB | G27: =D27+E27*2 -> 0 | H27: =B27+C27*2 -> 0 | I27: =D27+E27 -> 0 | J27: =G27*K$1 -> 0 | K27: =I27*K$1 -> 0 | L27: =J27*104 -> 0 | M27: =I27*104 -> 0 | W27: =J27 -> 0 | X27: =H27*$K$1 -> 0
B28: 1 | C28: 0 | D28: ='Data Ocupacion'!H47 -> 1 | E28: ='Data Ocupacion'!I47 -> 0 | F28: EB-PU | G28: =D28+E28*2 -> 1 | H28: =B28+C28*2 -> 1 | I28: =D28+E28 -> 1 | J28: =G28*K$1 -> 25.4 | K28: =I28*K$1 -> 25.4 | L28: =J28*104 -> 2641.6 | M28: =I28*104 -> 104 | W28: =J28 -> 25.4 | X28: =H28*$K$1 -> 25.4
B29: =SUM(B23:B28) -> 160 | C29: =SUM(C23:C28) -> 63 | D29: =SUM(D23:D28) -> 160 | E29: =SUM(E23:E28) -> 63 | G29: =SUM(G23:G28) -> 286 | H29: =SUM(H23:H28) -> 286 | I29: =SUM(I23:I28) -> 223 | J29: =SUM(J23:J28) -> 11322.03 | K29: =SUM(K23:K28) -> 8688.96 | L29: =SUM(L23:L28) -> 1177491.1 | M29: =SUM(M23:M28) -> 23192 | N29: ='Odometro-Kilometraje'!D81 -> 11744 | O29: =(W29/N29)*100 -> 96.25596 | W29: =SUM(W23:W28) -> 11304.3 | X29: =SUM(X23:X28) -> 11322.03
A30: =A23+1 -> 45720 | B30: 51 | C30: 28 | D30: ='Data Ocupacion'!J42 -> 51 | E30: ='Data Ocupacion'!K42 -> 28 | F30: PU-LI | G30: =D30+E30*2 -> 107 | H30: =B30+C30*2 -> 107 | I30: =D30+E30 -> 79 | J30: =G30*M$2 -> 4614.91 | K30: =I30*M$2 -> 3407.27 | L30: =J30*104 -> 479950.64 | M30: =I30*104 -> 8216 | Q30: 2 | W30: =J30-(Q30*($M$2-$K$1)+(R30*($M$2-$M$1))+ (S30*($M$2-$I$2))) -> 4579.45 | X30: =H30*$M$2 -> 4614.91
B31: 49 | C31: 29 | D31: ='Data Ocupacion'!J43 -> 49 | E31: ='Data Ocupacion'!K43 -> 29 | F31: LI-PU | G31: =D31+E31*2 -> 107 | H31: =B31+C31*2 -> 107 | I31: =D31+E31 -> 78 | J31: =G31*M$2 -> 4614.91 | K31: =I31*M$2 -> 3364.14 | L31: =J31*104 -> 479950.64 | M31: =I31*104 -> 8112 | W31: =J31-(T31*($M$2-$K$1)+(U31*($M$2-$M$1))+(V31*($M$2-$I$2))) -> 4614.91 | X31: =H31*$M$2 -> 4614.91
B32: 30 | C32: 3 | D32: ='Data Ocupacion'!J44 -> 30 | E32: ='Data Ocupacion'!K44 -> 3 | F32: PU-SA | G32: =D32+E32*2 -> 36 | H32: =B32+C32*2 -> 36 | I32: =D32+E32 -> 33 | J32: =G32*M$1 -> 1047.96 | K32: =I32*M$1 -> 960.63 | L32: =J32*104 -> 108987.84 | M32: =I32*104 -> 3432 | W32: =J32-(Q32*($M$1-$K$1)) -> 1047.96 | X32: =H32*$M$1 -> 1047.96
B33: 29 | C33: 3 | D33: ='Data Ocupacion'!J45 -> 29 | E33: ='Data Ocupacion'!K45 -> 3 | F33: SA-PU | G33: =D33+E33*2 -> 35 | H33: =B33+C33*2 -> 35 | I33: =D33+E33 -> 32 | J33: =G33*M$1 -> 1018.85 | K33: =I33*M$1 -> 931.52 | L33: =J33*104 -> 105960.4 | M33: =I33*104 -> 3328 | W33: =J33 -> 1018.85 | X33: =H33*$M$1 -> 1018.85
B34: 0 | C34: 0 | D34: ='Data Ocupacion'!J46 -> 0 | E34: ='Data Ocupacion'!K46 -> 0 | F34: PU-EB | G34: =D34+E34*2 -> 0 | H34: =B34+C34*2 -> 0 | I34: =D34+E34 -> 0 | J34: =G34*K$1 -> 0 | K34: =I34*K$1 -> 0 | L34: =J34*104 -> 0 | M34: =I34*104 -> 0 | W34: =J34 -> 0 | X34: =H34*$K$1 -> 0
B35: 1 | C35: 0 | D35: ='Data Ocupacion'!J47 -> 1 | E35: ='Data Ocupacion'!K47 -> 0 | F35: EB-PU | G35: =D35+E35*2 -> 1 | H35: =B35+C35*2 -> 1 | I35: =D35+E35 -> 1 | J35: =G35*K$1 -> 25.4 | K35: =I35*K$1 -> 25.4 | L35: =J35*104 -> 2641.6 | M35: =I35*104 -> 104 | W35: =J35 -> 25.4 | X35: =H35*$K$1 -> 25.4
B36: =SUM(B30:B35) -> 160 | C36: =SUM(C30:C35) -> 63 | D36: =SUM(D30:D35) -> 160 | E36: =SUM(E30:E35) -> 63 | G36: =SUM(G30:G35) -> 286 | H36: =SUM(H30:H35) -> 286 | I36: =SUM(I30:I35) -> 223 | J36: =SUM(J30:J35) -> 11322.03 | K36: =SUM(K30:K35) -> 8688.96 | L36: =SUM(L30:L35) -> 1177491.1 | M36: =SUM(M30:M35) -> 23192 | N36: ='Odometro-Kilometraje'!E81 -> 11775 | O36: =(W36/N36)*100 -> 95.851975 | W36: =SUM(W30:W35) -> 11286.57 | X36: =SUM(X30:X35) -> 11322.03
A37: =A30+1 -> 45721 | B37: 51 | C37: 28 | D37: ='Data Ocupacion'!L42 -> 51 | E37: ='Data Ocupacion'!M42 -> 28 | F37: PU-LI | G37: =D37+E37*2 -> 107 | H37: =B37+C37*2 -> 107 | I37: =D37+E37 -> 79 | J37: =G37*M$2 -> 4614.91 | K37: =I37*M$2 -> 3407.27 | L37: =J37*104 -> 479950.64 | M37: =I37*104 -> 8216 | Q37: 2 | T37: 1 | W37: =J37-(Q37*($M$2-$K$1)+(R37*($M$2-$M$1))+ (S37*($M$2-$I$2))+(T37*$K$1)) -> 4554.05 | X37: =H37*$M$2 -> 4614.91
B38: 49 | C38: 29 | D38: ='Data Ocupacion'!L43 -> 49 | E38: ='Data Ocupacion'!M43 -> 29 | F38: LI-PU | G38: =D38+E38*2 -> 107 | H38: =B38+C38*2 -> 107 | I38: =D38+E38 -> 78 | J38: =G38*M$2 -> 4614.91 | K38: =I38*M$2 -> 3364.14 | L38: =J38*104 -> 479950.64 | M38: =I38*104 -> 8112 | W38: =J38-(T38*($M$2-$K$1)+(U38*($M$2-$M$1))) -> 4614.91 | X38: =H38*$M$2 -> 4614.91
B39: 30 | C39: 3 | D39: ='Data Ocupacion'!L44 -> 30 | E39: ='Data Ocupacion'!M44 -> 3 | F39: PU-SA | G39: =D39+E39*2 -> 36 | H39: =B39+C39*2 -> 36 | I39: =D39+E39 -> 33 | J39: =G39*M$1 -> 1047.96 | K39: =I39*M$1 -> 960.63 | L39: =J39*104 -> 108987.84 | M39: =I39*104 -> 3432 | W39: =J39-(Q39*($M$1-$K$1)) -> 1047.96 | X39: =H39*$M$1 -> 1047.96
B40: 29 | C40: 3 | D40: ='Data Ocupacion'!L45 -> 29 | E40: ='Data Ocupacion'!M45 -> 3 | F40: SA-PU | G40: =D40+E40*2 -> 35 | H40: =B40+C40*2 -> 35 | I40: =D40+E40 -> 32 | J40: =G40*M$1 -> 1018.85 | K40: =I40*M$1 -> 931.52 | L40: =J40*104 -> 105960.4 | M40: =I40*104 -> 3328 | W40: =J40 -> 1018.85 | X40: =H40*$M$1 -> 1018.85
...

Sheet Data Ocupacion
D1: 45717 | F1: 45718 | H1: 45719 | J1: 45720 | L1: 45721 | N1: 45722 | P1: 45723 | R1: 45724 | T1: 45725 | V1: 45726 | X1: 45727 | Z1: 45728 | AB1: 45729 | AD1: 45730 | AF1: 45731 | AH1: 45732 | AJ1: 45733 | AL1: 45734 | AN1: 45735 | AP1: 45736 | AR1: 45737 | AT1: 45738 | AV1: 45739 | AX1: 45740 | AZ1: 45741 | BB1: 45742 | BD1: 45743 | BF1: 45744 | BH1: 45745 | BJ1: 45746 | BL1: 45747
D2: S | E2: M | F2: S | G2: M | H2: S | I2: M | J2: S | K2: M | L2: S | M2: M | N2: S | O2: M | P2: S | Q2: M | R2: S | S2: M | T2: S | U2: M | V2: S | W2: M | X2: S | Y2: M | Z2: S | AA2: M | AB2: S | AC2: M | AD2: S | AE2: M | AF2: S | AG2: M | AH2: S | AI2: M | AJ2: S | AK2: M | AL2: S | AM2: M | AN2: S | AO2: M | AP2: S | AQ2: M | AR2: S | AS2: M | AT2: S | AU2: M | AV2: S | AW2: M | AX2: S | AY2: M | AZ2: S | BA2: M | BB2: S | BC2: M | BD2: S | BE2: M | BF2: S | BG2: M | BH2: S | BI2: M | BJ2: S | BK2: M | BL2: S | BM2: M
A3: Servicios PU-SA | D3: 0 | E3: 0 | F3: 0 | G3: 0 | H3: 7 | I3: 3 | J3: 7 | K3: 3 | L3: 7 | M3: 3 | N3: 7 | O3: 3 | P3: 7 | Q3: 3 | R3: 0 | S3: 0 | T3: 0 | U3: 0 | V3: 7 | W3: 3 | X3: 7 | Y3: 3 | Z3: 7 | AA3: 3 | AB3: 7 | AC3: 3 | AD3: 7 | AE3: 3 | AF3: 0 | AG3: 0 | AH3: 0 | AI3: 0 | AJ3: 7 | AK3: 3 | AL3: 7 | AM3: 3 | AN3: 7 | AO3: 3 | AP3: 7 | AQ3: 3 | AR3: 7 | AS3: 3 | AT3: 0 | AU3: 0 | AV3: 0 | AW3: 0 | AX3: 7 | AY3: 3 | AZ3: 7 | BA3: 3 | BB3: 7 | BC3: 3 | BD3: 7 | BE3: 3 | BF3: 7 | BG3: 3 | BH3: 0 | BI3: 0 | BJ3: 0 | BK3: 0 | BL3: 7 | BM3: 3
A4: Servicios PU-EB | D4: 0 | E4: 0 | F4: 0 | G4: 0 | H4: 0 | I4: 0 | J4: 0 | K4: 0 | L4: 0 | M4: 0 | N4: 0 | O4: 0 | P4: 0 | Q4: 0 | R4: 0 | S4: 0 | T4: 0 | U4: 0 | V4: 0 | W4: 0 | X4: 0 | Y4: 0 | Z4: 0 | AA4: 0 | AB4: 0 | AC4: 0 | AD4: 0 | AE4: 0 | AF4: 0 | AG4: 0 | AH4: 0 | AI4: 0 | AJ4: 0 | AK4: 0 | AL4: 0 | AM4: 0 | AN4: 0 | AO4: 0 | AP4: 0 | AQ4: 0 | AR4: 0 | AS4: 0 | AT4: 0 | AU4: 0 | AV4: 0 | AW4: 0 | AX4: 0 | AY4: 0 | AZ4: 0 | BA4: 0 | BB4: 0 | BC4: 0 | BD4: 0 | BE4: 0 | BF4: 0 | BG4: 0 | BH4: 0 | BI4: 0 | BJ4: 0 | BK4: 0 | BL4: 0 | BM4: 0
A5: Servicios PU-LI | D5: 0 | E5: 0 | F5: 0 | G5: 0 | H5: 1 | I5: 9 | J5: 1 | K5: 9 | L5: 1 | M5: 9 | N5: 1 | O5: 9 | P5: 1 | Q5: 9 | R5: 0 | S5: 0 | T5: 0 | U5: 0 | V5: 1 | W5: 9 | X5: 1 | Y5: 8 | Z5: 2 | AA5: 8 | AB5: 1 | AC5: 9 | AD5: 1 | AE5: 9 | AF5: 0 | AG5: 0 | AH5: 0 | AI5: 0 | AJ5: 3 | AK5: 7 | AL5: 2 | AM5: 8 | AN5: 2 | AO5: 8 | AP5: 2 | AQ5: 8 | AR5: 1 | AS5: 9 | AT5: 0 | AU5: 0 | AV5: 0 | AW5: 0 | AX5: 1 | AY5: 9 | AZ5: 1 | BA5: 9 | BB5: 1 | BC5: 9 | BD5: 1 | BE5: 9 | BF5: 1 | BG5: 9 | BH5: 0 | BI5: 0 | BJ5: 0 | BK5: 0 | BL5: 2 | BM5: 8
A6: Servicios SA-PU | D6: 0 | E6: 0 | F6: 0 | G6: 0 | H6: 10 | I6: 0 | J6: 10 | K6: 0 | L6: 10 | M6: 0 | N6: 10 | O6: 0 | P6: 10 | Q6: 0 | R6: 0 | S6: 0 | T6: 0 | U6: 0 | V6: 10 | W6: 0 | X6: 10 | Y6: 0 | Z6: 10 | AA6: 0 | AB6: 10 | AC6: 0 | AD6: 10 | AE6: 0 | AF6: 0 | AG6: 0 | AH6: 0 | AI6: 0 | AJ6: 8 | AK6: 2 | AL6: 9 | AM6: 1 | AN6: 9 | AO6: 1 | AP6: 9 | AQ6: 1 | AR6: 9 | AS6: 1 | AT6: 0 | AU6: 0 | AV6: 0 | AW6: 0 | AX6: 9 | AY6: 1 | AZ6: 9 | BA6: 1 | BB6: 8 | BC6: 1 | BD6: 9 | BE6: 1 | BF6: 9 | BG6: 1 | BH6: 0 | BI6: 0 | BJ6: 0 | BK6: 0 | BL6: 8 | BM6: 2
A7: Servicios EB-PU | D7: 0 | E7: 0 | F7: 0 | G7: 0 | H7: 0 | I7: 0 | J7: 0 | K7: 0 | L7: 0 | M7: 0 | N7: 0 | O7: 0 | P7: 0 | Q7: 0 | R7: 0 | S7: 0 | T7: 0 | U7: 0 | V7: 0 | W7: 0 | X7: 0 | Y7: 0 | Z7: 0 | AA7: 0 | AB7: 0 | AC7: 0 | AD7: 0 | AE7: 0 | AF7: 0 | AG7: 0 | AH7: 0 | AI7: 0 | AJ7: 0 | AK7: 0 | AL7: 0 | AM7: 0 | AN7: 0 | AO7: 0 | AP7: 0 | AQ7: 0 | AR7: 0 | AS7: 0 | AT7: 0 | AU7: 0 | AV7: 0 | AW7: 0 | AX7: 0 | AY7: 0 | AZ7: 0 | BA7: 0 | BB7: 0 | BC7: 0 | BD7: 0 | BE7: 0 | BF7: 0 | BG7: 0 | BH7: 0 | BI7: 0 | BJ7: 0 | BK7: 0 | BL7: 0 | BM7: 0
A8: Servicios LI-PU | D8: 0 | E8: 0 | F8: 0 | G8: 0 | H8: 6 | I8: 4 | J8: 6 | K8: 4 | L8: 6 | M8: 4 | N8: 6 | O8: 4 | P8: 6 | Q8: 4 | R8: 0 | S8: 0 | T8: 0 | U8: 0 | V8: 6 | W8: 4 | X8: 5 | Y8: 5 | Z8: 5 | AA8: 5 | AB8: 4 | AC8: 6 | AD8: 4 | AE8: 6 | AF8: 0 | AG8: 0 | AH8: 0 | AI8: 0 | AJ8: 6 | AK8: 4 | AL8: 5 | AM8: 5 | AN8: 5 | AO8: 5 | AP8: 5 | AQ8: 5 | AR8: 4 | AS8: 6 | AT8: 0 | AU8: 0 | AV8: 0 | AW8: 0 | AX8: 4 | AY8: 6 | AZ8: 4 | BA8: 6 | BB8: 4 | BC8: 6 | BD8: 4 | BE8: 6 | BF8: 4 | BG8: 6 | BH8: 0 | BI8: 0 | BJ8: 0 | BK8: 0 | BL8: 5 | BM8: 5
A10: Servicios PU-SA | D10: 0 | E10: 0 | F10: 0 | G10: 0 | H10: 16 | I10: 0 | J10: 16 | K10: 0 | L10: 16 | M10: 0 | N10: 16 | O10: 0 | P10: 16 | Q10: 0 | R10: 0 | S10: 0 | T10: 0 | U10: 0 | V10: 16 | W10: 0 | X10: 13 | Y10: 0 | Z10: 16 | AA10: 0 | AB10: 16 | AC10: 0 | AD10: 16 | AE10: 0 | AF10: 0 | AG10: 0 | AH10: 0 | AI10: 0 | AJ10: 15 | AK10: 1 | AL10: 15 | AM10: 1 | AN10: 15 | AO10: 1 | AP10: 15 | AQ10: 1 | AR10: 15 | AS10: 1 | AT10: 0 | AU10: 0 | AV10: 0 | AW10: 0 | AX10: 15 | AY10: 1 | AZ10: 15 | BA10: 1 | BB10: 13 | BC10: 0 | BD10: 15 | BE10: 1 | BF10: 15 | BG10: 1 | BH10: 0 | BI10: 0 | BJ10: 0 | BK10: 0 | BL10: 15 | BM10: 1
A11: Servicios PU-EB | D11: 0 | E11: 0 | F11: 0 | G11: 0 | H11: 0 | I11: 0 | J11: 0 | K11: 0 | L11: 0 | M11: 0 | N11: 0 | O11: 0 | P11: 0 | Q11: 0 | R11: 0 | S11: 0 | T11: 0 | U11: 0 | V11: 0 | W11: 0 | X11: 0 | Y11: 0 | Z11: 0 | AA11: 0 | AB11: 0 | AC11: 0 | AD11: 0 | AE11: 0 | AF11: 0 | AG11: 0 | AH11: 0 | AI11: 0 | AJ11: 0 | AK11: 0 | AL11: 0 | AM11: 0 | AN11: 0 | AO11: 0 | AP11: 0 | AQ11: 0 | AR11: 0 | AS11: 0 | AT11: 0 | AU11: 0 | AV11: 0 | AW11: 0 | AX11: 0 | AY11: 0 | AZ11: 0 | BA11: 0 | BB11: 0 | BC11: 0 | BD11: 0 | BE11: 0 | BF11: 0 | BG11: 0 | BH11: 0 | BI11: 0 | BJ11: 0 | BK11: 0 | BL11: 0 | BM11: 0
A12: Servicios PU-LI | D12: 54 | E12: 18 | F12: 52 | G12: 2 | H12: 48 | I12: 13 | J12: 48 | K12: 13 | L12: 48 | M12: 13 | N12: 45 | O12: 16 | P12: 47 | Q12: 14 | R12: 69 | S12: 3 | T12: 51 | U12: 3 | V12: 48 | W12: 13 | X12: 38 | Y12: 13 | Z12: 46 | AA12: 15 | AB12: 44 | AC12: 17 | AD12: 44 | AE12: 17 | AF12: 69 | AG12: 3 | AH12: 51 | AI12: 3 | AJ12: 44 | AK12: 17 | AL12: 44 | AM12: 17 | AN12: 44 | AO12: 17 | AP12: 42 | AQ12: 19 | AR12: 42 | AS12: 19 | AT12: 69 | AU12: 3 | AV12: 51 | AW12: 3 | AX12: 44 | AY12: 17 | AZ12: 36 | BA12: 16 | BB12: 26 | BC12: 17 | BD12: 44 | BE12: 17 | BF12: 44 | BG12: 17 | BH12: 69 | BI12: 3 | BJ12: 51 | BK12: 3 | BL12: 39 | BM12: 22
A13: Servicios SA-PU | D13: 0 | E13: 0 | F13: 0 | G13: 0 | H13: 13 | I13: 3 | J13: 13 | K13: 3 | L13: 13 | M13: 3 | N13: 13 | O13: 3 | P13: 13 | Q13: 3 | R13: 0 | S13: 0 | T13: 0 | U13: 0 | V13: 13 | W13: 3 | X13: 9 | Y13: 3 | Z13: 13 | AA13: 3 | AB13: 13 | AC13: 3 | AD13: 13 | AE13: 3 | AF13: 0 | AG13: 0 | AH13: 0 | AI13: 0 | AJ13: 13 | AK13: 3 | AL13: 13 | AM13: 3 | AN13: 13 | AO13: 3 | AP13: 13 | AQ13: 3 | AR13: 13 | AS13: 3 | AT13: 0 | AU13: 0 | AV13: 0 | AW13: 0 | AX13: 13 | AY13: 3 | AZ13: 13 | BA13: 3 | BB13: 11 | BC13: 2 | BD13: 13 | BE13: 3 | BF13: 13 | BG13: 3 | BH13: 0 | BI13: 0 | BJ13: 0 | BK13: 0 | BL13: 13 | BM13: 3
A14: Servicios EB-PU | D14: 0 | E14: 0 | F14: 0 | G14: 0 | H14: 1 | I14: 0 | J14: 1 | K14: 0 | L14: 1 | M14: 0 | N14: 1 | O14: 0 | P14: 1 | Q14: 0 | R14: 0 | S14: 0 | T14: 0 | U14: 0 | V14: 1 | W14: 0 | X14: 1 | Y14: 0 | Z14: 1 | AA14: 0 | AB14: 1 | AC14: 0 | AD14: 1 | AE14: 0 | AF14: 0 | AG14: 0 | AH14: 0 | AI14: 0 | AJ14: 1 | AK14: 0 | AL14: 1 | AM14: 0 | AN14: 1 | AO14: 0 | AP14: 1 | AQ14: 0 | AR14: 1 | AS14: 0 | AT14: 0 | AU14: 0 | AV14: 0 | AW14: 0 | AX14: 1 | AY14: 0 | AZ14: 1 | BA14: 0 | BB14: 1 | BC14: 0 | BD14: 1 | BE14: 0 | BF14: 1 | BG14: 0 | BH14: 0 | BI14: 0 | BJ14: 0 | BK14: 0 | BL14: 1 | BM14: 0
A15: Servicios LI-PU | D15: 58 | E15: 17 | F15: 57 | G15: 0 | H15: 38 | I15: 23 | J15: 38 | K15: 23 | L15: 38 | M15: 23 | N15: 38 | O15: 23 | P15: 38 | Q15: 23 | R15: 75 | S15: 0 | T15: 57 | U15: 0 | V15: 38 | W15: 23 | X15: 28 | Y15: 21 | Z15: 38 | AA15: 23 | AB15: 36 | AC15: 25 | AD15: 36 | AE15: 25 | AF15: 75 | AG15: 0 | AH15: 57 | AI15: 0 | AJ15: 38 | AK15: 23 | AL15: 37 | AM15: 24 | AN15: 36 | AO15: 25 | AP15: 37 | AQ15: 24 | AR15: 36 | AS15: 25 | AT15: 75 | AU15: 0 | AV15: 57 | AW15: 0 | AX15: 36 | AY15: 25 | AZ15: 29 | BA15: 23 | BB15: 21 | BC15: 20 | BD15: 36 | BE15: 25 | BF15: 37 | BG15: 24 | BH15: 75 | BI15: 0 | BJ15: 57 | BK15: 0 | BL15: 36 | BM15: 25
A16: Servicios PU-ES
A17: Servicios ES-PU
A18: Servicios VM-LI | D18: 3 | E18: 1 | F18: 3 | G18: 1
A19: Servicios VM-PU | D19: 2 | E19: 0 | F19: 2 | G19: 0
A20: Servicios MI-SA | X20: 1 | Y20: 0 | BB20: 2 | BC20: 0
A21: Servicios SA-MI | X21: 4 | Y21: 0 | BB21: 2 | BC21: 1
A22: Servicios MI-LI | X22: 2 | Y22: 4 | BB22: 10 | BC22: 5
A23: Servicios LI-MI | X23: 10 | Y23: 2 | BB23: 11 | BC23: 5
A24: Servicios LI-PO | AZ24: 8 | BA24: 1
A25: Servicios PO-LI | AZ25: 8 | BA25: 1
A27: Servicios PU-SA | D27: 0 | E27: 0 | F27: 0 | G27: 0 | H27: 7 | I27: 0 | J27: 7 | K27: 0 | L27: 7 | M27: 0 | N27: 7 | O27: 0 | P27: 7 | Q27: 0 | R27: 0 | S27: 0 | T27: 0 | U27: 0 | V27: 7 | W27: 0 | X27: 7 | Y27: 0 | Z27: 7 | AA27: 0 | AB27: 7 | AC27: 0 | AD27: 7 | AE27: 0 | AF27: 0 | AG27: 0 | AH27: 0 | AI27: 0 | AJ27: 7 | AK27: 0 | AL27: 7 | AM27: 0 | AN27: 7 | AO27: 0 | AP27: 7 | AQ27: 0 | AR27: 6 | AS27: 0 | AT27: 0 | AU27: 0 | AV27: 0 | AW27: 0 | AX27: 7 | AY27: 0 | AZ27: 7 | BA27: 0 | BB27: 7 | BC27: 0 | BD27: 7 | BE27: 0 | BF27: 7 | BG27: 0 | BH27: 0 | BI27: 0 | BJ27: 0 | BK27: 0 | BL27: 7 | BM27: 0
A28: Servicios PU-EB | D28: 0 | E28: 0 | F28: 0 | G28: 0 | H28: 0 | I28: 0 | J28: 0 | K28: 0 | L28: 0 | M28: 0 | N28: 0 | O28: 0 | P28: 0 | Q28: 0 | R28: 0 | S28: 0 | T28: 0 | U28: 0 | V28: 0 | W28: 0 | X28: 0 | Y28: 0 | Z28: 0 | AA28: 0 | AB28: 0 | AC28: 0 | AD28: 0 | AE28: 0 | AF28: 0 | AG28: 0 | AH28: 0 | AI28: 0 | AJ28: 0 | AK28: 0 | AL28: 0 | AM28: 0 | AN28: 0 | AO28: 0 | AP28: 0 | AQ28: 0 | AR28: 0 | AS28: 0 | AT28: 0 | AU28: 0 | AV28: 0 | AW28: 0 | AX28: 0 | AY28: 0 | AZ28: 0 | BA28: 0 | BB28: 0 | BC28: 0 | BD28: 0 | BE28: 0 | BF28: 0 | BG28: 0 | BH28: 0 | BI28: 0 | BJ28: 0 | BK28: 0 | BL28: 0 | BM28: 0
A29: Servicios PU-LI | D29: 0 | E29: 0 | F29: 0 | G29: 0 | H29: 2 | I29: 6 | J29: 2 | K29: 6 | L29: 2 | M29: 6 | N29: 2 | O29: 6 | P29: 2 | Q29: 6 | R29: 0 | S29: 0 | T29: 0 | U29: 0 | V29: 2 | W29: 6 | X29: 2 | Y29: 6 | Z29: 2 | AA29: 6 | AB29: 2 | AC29: 6 | AD29: 2 | AE29: 6 | AF29: 0 | AG29: 0 | AH29: 0 | AI29: 0 | AJ29: 3 | AK29: 5 | AL29: 3 | AM29: 5 | AN29: 2 | AO29: 6 | AP29: 3 | AQ29: 5 | AR29: 3 | AS29: 6 | AT29: 0 | AU29: 0 | AV29: 0 | AW29: 0 | AX29: 2 | AY29: 6 | AZ29: 2 | BA29: 6 | BB29: 2 | BC29: 6 | BD29: 2 | BE29: 6 | BF29: 3 | BG29: 5 | BH29: 0 | BI29: 0 | BJ29: 0 | BK29: 0 | BL29: 2 | BM29: 6
A30: Servicios SA-PU | D30: 0 | E30: 0 | F30: 0 | G30: 0 | H30: 6 | I30: 0 | J30: 6 | K30: 0 | L30: 6 | M30: 0 | N30: 6 | O30: 0 | P30: 6 | Q30: 0 | R30: 0 | S30: 0 | T30: 0 | U30: 0 | V30: 6 | W30: 0 | X30: 6 | Y30: 0 | Z30: 6 | AA30: 0 | AB30: 6 | AC30: 0 | AD30: 6 | AE30: 0 | AF30: 0 | AG30: 0 | AH30: 0 | AI30: 0 | AJ30: 6 | AK30: 0 | AL30: 6 | AM30: 0 | AN30: 6 | AO30: 0 | AP30: 6 | AQ30: 0 | AR30: 6 | AS30: 0 | AT30: 0 | AU30: 0 | AV30: 0 | AW30: 0 | AX30: 6 | AY30: 0 | AZ30: 6 | BA30: 0 | BB30: 6 | BC30: 0 | BD30: 6 | BE30: 0 | BF30: 6 | BG30: 0 | BH30: 0 | BI30: 0 | BJ30: 0 | BK30: 0 | BL30: 6 | BM30: 0
A31: Servicios EB-PU | D31: 0 | E31: 0 | F31: 0 | G31: 0 | H31: 0 | I31: 0 | J31: 0 | K31: 0 | L31: 0 | M31: 0 | N31: 0 | O31: 0 | P31: 0 | Q31: 0 | R31: 0 | S31: 0 | T31: 0 | U31: 0 | V31: 0 | W31: 0 | X31: 0 | Y31: 0 | Z31: 0 | AA31: 0 | AB31: 0 | AC31: 0 | AD31: 0 | AE31: 0 | AF31: 0 | AG31: 0 | AH31: 0 | AI31: 0 | AJ31: 0 | AK31: 0 | AL31: 0 | AM31: 0 | AN31: 0 | AO31: 0 | AP31: 0 | AQ31: 0 | AR31: 0 | AS31: 0 | AT31: 0 | AU31: 0 | AV31: 0 | AW31: 0 | AX31: 0 | AY31: 0 | AZ31: 0 | BA31: 0 | BB31: 0 | BC31: 0 | BD31: 0 | BE31: 0 | BF31: 0 | BG31: 0 | BH31: 0 | BI31: 0 | BJ31: 0 | BK31: 0 | BL31: 0 | BM31: 0
A32: Servicios LI-PU | D32: 0 | E32: 0 | F32: 0 | G32: 0 | H32: 5 | I32: 2 | J32: 5 | K32: 2 | L32: 5 | M32: 2 | N32: 5 | O32: 2 | P32: 5 | Q32: 2 | R32: 0 | S32: 0 | T32: 0 | U32: 0 | V32: 5 | W32: 2 | X32: 5 | Y32: 2 | Z32: 5 | AA32: 2 | AB32: 5 | AC32: 2 | AD32: 5 | AE32: 2 | AF32: 0 | AG32: 0 | AH32: 0 | AI32: 0 | AJ32: 5 | AK32: 2 | AL32: 5 | AM32: 2 | AN32: 5 | AO32: 2 | AP32: 5 | AQ32: 2 | AR32: 5 | AS32: 2 | AT32: 0 | AU32: 0 | AV32: 0 | AW32: 0 | AX32: 5 | AY32: 2 | AZ32: 5 | BA32: 2 | BB32: 5 | BC32: 2 | BD32: 5 | BE32: 2 | BF32: 5 | BG32: 2 | BH32: 0 | BI32: 0 | BJ32: 0 | BK32: 0 | BL32: 5 | BM32: 2
D35: =SUM(D3:D32) -> 117 | E35: =SUM(E3:E32) -> 36 | F35: =SUM(F3:F32) -> 114 | G35: =SUM(G3:G32) -> 3 | H35: =SUM(H3:H32) -> 160 | I35: =SUM(I3:I32) -> 63 | J35: =SUM(J3:J32) -> 160 | K35: =SUM(K3:K32) -> 63 | ... BM35: =SUM(BM3:BM32) -> 77
A41: Km Servicio
A42: PU - LI | D42: =D5+D12+D29 -> 54 | E42: =E5+E12+E29 -> 18 | F42: =F5+F12+F29 -> 52 | G42: =G5+G12+G29 -> 2 | H42: =H5+H12+H29 -> 51 | I42: =I5+I12+I29 -> 28 | J42: =J5+J12+J29 -> 51 | K42: =K5+K12+K29 -> 28 | ... BM42: =BM5+BM12+BM29 -> 36
A43: LI - PU | D43: =D8+D15+D32 -> 58 | E43: =E8+E15+E32 -> 17 | F43: =F8+F15+F32 -> 57 | G43: =G8+G15+G32 -> 0 | H43: =H8+H15+H32 -> 49 | I43: =I8+I15+I32 -> 29 | J43: =J8+J15+J32 -> 49 | K43: =K8+K15+K32 -> 29 | ... BM43: =BM8+BM15+BM32 -> 32
A44: PU - SA | D44: =D3+D10+D27 -> 0 | E44: =E3+E10+E27 -> 0 | F44: =F3+F10+F27 -> 0 | G44: =G3+G10+G27 -> 0 | H44: =H3+H10+H27 -> 30 | I44: =I3+I10+I27 -> 3 | J44: =J3+J10+J27 -> 30 | K44: =K3+K10+K27 -> 3 | ... BM44: =BM3+BM10+BM27 -> 4
A45: SA - PU | D45: =D6+D13+D30 -> 0 | E45: =E6+E13+E30 -> 0 | F45: =F6+F13+F30 -> 0 | G45: =G6+G13+G30 -> 0 | H45: =H6+H13+H30 -> 29 | I45: =I6+I13+I30 -> 3 | J45: =J6+J13+J30 -> 29 | K45: =K6+K13+K30 -> 3 | ... BM45: =BM6+BM13+BM30 -> 5
A46: PU-EB | D46: =D4+D11+D28 -> 0 | E46: =E4+E11+E28 -> 0 | F46: =F4+F11+F28 -> 0 | G46: =G4+G11+G28 -> 0 | H46: =H4+H11+H28 -> 0 | I46: =I4+I11+I28 -> 0 | J46: =J4+J11+J28 -> 0 | K46: =K4+K11+K28 -> 0 | ... BM46: =BM4+BM11+BM28 -> 0
A47: EB-PU | D47: =D7+D14+D31 -> 0 | E47: =E7+E14+E31 -> 0 | F47: =F7+F14+F31 -> 0 | G47: =G7+G14+G31 -> 0 | H47: =H7+H14+H31 -> 1 | I47: =I7+I14+I31 -> 0 | J47: =J7+J14+J31 -> 1 | K47: =K7+K14+K31 -> 0 | ... BM47: =BM7+BM14+BM31 -> 0
A48: PU-ES | H48: =H16 -> 0 | I48: 0
A49: ES-PU | H49: =H17 -> 0 | I49: =I17 -> 0
...

Sheet Oferta Diaria
A1: Oferta Marzo 2025
C3: 45717 | D3: 45718 | E3: 45719 | F3: 45720 | G3: 45721 | H3: 45722 | I3: 45723 | J3: 45724 | K3: 45725 | L3: 45726 | M3: 45727 | N3: 45728 | O3: 45729 | P3: 45730 | Q3: 45731 | R3: 45732 | S3: 45733 | T3: 45734 | U3: 45735 | V3: 45736 | W3: 45737 | X3: 45738 | Y3: 45739 | Z3: 45740 | AA3: 45741 | AB3: 45742 | AC3: 45743 | AD3: 45744 | AE3: 45745 | AF3: 45746 | AG3: 45747
A4: HÁBIL | B4: km
A5: Servicios PU-LI | B5: 43.13 | C5: ='Data Ocupacion'!D62 -> 72 | D5: ='Data Ocupacion'!F62 -> 54 | E5: ='Data Ocupacion'!H62 -> 79 | F5: ='Data Ocupacion'!J62 -> 79 | G5: ='Data Ocupacion'!L62 -> 79 | H5: ='Data Ocupacion'!N62 -> 79 | I5: ='Data Ocupacion'!P62 -> 79 | J5: ='Data Ocupacion'!R62 -> 72 | K5: ='Data Ocupacion'!T62 -> 54 | L5: ='Data Ocupacion'!V62 -> 79 | M5: ='Data Ocupacion'!X62 -> 68 | N5: ='Data Ocupacion'!Z62 -> 79 | O5: ='Data Ocupacion'!AB62 -> 79 | P5: ='Data Ocupacion'!AD62 -> 79 | Q5: ='Data Ocupacion'!AF62 -> 72 | R5: ='Data Ocupacion'!AH62 -> 54 | S5: ='Data Ocupacion'!AJ62 -> 79 | T5: ='Data Ocupacion'!AL62 -> 79 | U5: ='Data Ocupacion'!AN62 -> 79 | V5: ='Data Ocupacion'!AP62 -> 79 | W5: ='Data Ocupacion'!AR62 -> 80 | X5: ='Data Ocupacion'!AT62 -> 72 | Y5: ='Data Ocupacion'!AV62 -> 54 | Z5: ='Data Ocupacion'!AX62 -> 79 | AA5: ='Data Ocupacion'!AZ62 -> 70 | AB5: ='Data Ocupacion'!BB62 -> 61 | AC5: ='Data Ocupacion'!BD62 -> 79 | AD5: ='Data Ocupacion'!BF62 -> 79 | AE5: ='Data Ocupacion'!BH62 -> 72 | AF5: ='Data Ocupacion'!BJ62 -> 54 | AG5: ='Data Ocupacion'!BL62 -> 79
A6: Servicios LI-PU | B6: 43.13 | C6: ='Data Ocupacion'!D63 -> 75 | D6: ='Data Ocupacion'!F63 -> 57 | E6: ='Data Ocupacion'!H63 -> 78 | F6: ='Data Ocupacion'!J63 -> 78 | G6: ='Data Ocupacion'!L63 -> 78 | H6: ='Data Ocupacion'!N63 -> 78 | I6: ='Data Ocupacion'!P63 -> 78 | J6: ='Data Ocupacion'!R63 -> 75 | K6: ='Data Ocupacion'!T63 -> 57 | L6: ='Data Ocupacion'!V63 -> 78 | M6: ='Data Ocupacion'!X63 -> 66 | N6: ='Data Ocupacion'!Z63 -> 78 | O6: ='Data Ocupacion'!AB63 -> 78 | P6: ='Data Ocupacion'!AD63 -> 78 | Q6: ='Data Ocupacion'!AF63 -> 75 | R6: ='Data Ocupacion'!AH63 -> 57 | S6: ='Data Ocupacion'!AJ63 -> 78 | T6: ='Data Ocupacion'!AL63 -> 78 | U6: ='Data Ocupacion'!AN63 -> 78 | V6: ='Data Ocupacion'!AP63 -> 78 | W6: ='Data Ocupacion'!AR63 -> 78 | X6: ='Data Ocupacion'!AT63 -> 75 | Y6: ='Data Ocupacion'!AV63 -> 57 | Z6: ='Data Ocupacion'!AX63 -> 78 | AA6: ='Data Ocupacion'!AZ63 -> 69 | AB6: ='Data Ocupacion'!BB63 -> 58 | AC6: ='Data Ocupacion'!BD63 -> 78 | AD6: ='Data Ocupacion'!BF63 -> 78 | AE6: ='Data Ocupacion'!BH63 -> 75 | AF6: ='Data Ocupacion'!BJ63 -> 57 | AG6: ='Data Ocupacion'!BL63 -> 78
A7: Servicios PU-SA | B7: 29.11 | C7: ='Data Ocupacion'!D64 -> 0 | D7: ='Data Ocupacion'!F64 -> 0 | E7: ='Data Ocupacion'!H64 -> 33 | F7: ='Data Ocupacion'!J64 -> 33 | G7: ='Data Ocupacion'!L64 -> 33 | H7: ='Data Ocupacion'!N64 -> 33 | I7: ='Data Ocupacion'!P64 -> 33 | J7: ='Data Ocupacion'!R64 -> 0 | K7: ='Data Ocupacion'!T64 -> 0 | L7: ='Data Ocupacion'!V64 -> 33 | M7: ='Data Ocupacion'!X64 -> 30 | N7: ='Data Ocupacion'!Z64 -> 33 | O7: ='Data Ocupacion'!AB64 -> 33 | P7: ='Data Ocupacion'!AD64 -> 33 | Q7: ='Data Ocupacion'!AF64 -> 0 | R7: ='Data Ocupacion'!AH64 -> 0 | S7: ='Data Ocupacion'!AJ64 -> 33 | T7: ='Data Ocupacion'!AL64 -> 33 | U7: ='Data Ocupacion'!AN64 -> 33 | V7: ='Data Ocupacion'!AP64 -> 33 | W7: ='Data Ocupacion'!AR64 -> 32 | X7: ='Data Ocupacion'!AT64 -> 0 | Y7: ='Data Ocupacion'!AV64 -> 0 | Z7: ='Data Ocupacion'!AX64 -> 33 | AA7: ='Data Ocupacion'!AZ64 -> 33 | AB7: ='Data Ocupacion'!BB64 -> 30 | AC7: ='Data Ocupacion'!BD64 -> 33 | AD7: ='Data Ocupacion'!BF64 -> 33 | AE7: ='Data Ocupacion'!BH64 -> 0 | AF7: ='Data Ocupacion'!BJ64 -> 0 | AG7: ='Data Ocupacion'!BL64 -> 33
A8: Servicios SA-PU | B8: 29.11 | C8: ='Data Ocupacion'!D65 -> 0 | D8: ='Data Ocupacion'!F65 -> 0 | E8: ='Data Ocupacion'!H65 -> 32 | F8: ='Data Ocupacion'!J65 -> 32 | G8: ='Data Ocupacion'!L65 -> 32 | H8: ='Data Ocupacion'!N65 -> 32 | I8: ='Data Ocupacion'!P65 -> 32 | J8: ='Data Ocupacion'!R65 -> 0 | K8: ='Data Ocupacion'!T65 -> 0 | L8: ='Data Ocupacion'!V65 -> 32 | M8: ='Data Ocupacion'!X65 -> 28 | N8: ='Data Ocupacion'!Z65 -> 32 | O8: ='Data Ocupacion'!AB65 -> 32 | P8: ='Data Ocupacion'!AD65 -> 32 | Q8: ='Data Ocupacion'!AF65 -> 0 | R8: ='Data Ocupacion'!AH65 -> 0 | S8: ='Data Ocupacion'!AJ65 -> 32 | T8: ='Data Ocupacion'!AL65 -> 32 | U8: ='Data Ocupacion'!AN65 -> 32 | V8: ='Data Ocupacion'!AP65 -> 32 | W8: ='Data Ocupacion'!AR65 -> 32 | X8: ='Data Ocupacion'!AT65 -> 0 | Y8: ='Data Ocupacion'!AV65 -> 0 | Z8: ='Data Ocupacion'!AX65 -> 32 | AA8: ='Data Ocupacion'!AZ65 -> 32 | AB8: ='Data Ocupacion'!BB65 -> 28 | AC8: ='Data Ocupacion'!BD65 -> 32 | AD8: ='Data Ocupacion'!BF65 -> 32 | AE8: ='Data Ocupacion'!BH65 -> 0 | AF8: ='Data Ocupacion'!BJ65 -> 0 | AG8: ='Data Ocupacion'!BL65 -> 32
A9: Servicios PU-EB | B9: 25.4 | C9: ='Data Ocupacion'!D66 -> 0 | D9: ='Data Ocupacion'!F66 -> 0 | E9: ='Data Ocupacion'!H66 -> 0 | F9: ='Data Ocupacion'!J66 -> 0 | G9: ='Data Ocupacion'!L66 -> 0 | H9: ='Data Ocupacion'!N66 -> 0 | I9: ='Data Ocupacion'!P66 -> 0 | J9: ='Data Ocupacion'!R66 -> 0 | K9: ='Data Ocupacion'!T66 -> 0 | L9: ='Data Ocupacion'!V66 -> 0 | M9: ='Data Ocupacion'!X66 -> 0 | N9: ='Data Ocupacion'!Z66 -> 0 | O9: ='Data Ocupacion'!AB66 -> 0 | P9: ='Data Ocupacion'!AD66 -> 0 | Q9: ='Data Ocupacion'!AF66 -> 0 | R9: ='Data Ocupacion'!AH66 -> 0 | S9: ='Data Ocupacion'!AJ66 -> 0 | T9: ='Data Ocupacion'!AL66 -> 0 | U9: ='Data Ocupacion'!AN66 -> 0 | V9: ='Data Ocupacion'!AP66 -> 0 | W9: ='Data Ocupacion'!AR66 -> 0 | X9: ='Data Ocupacion'!AT66 -> 0 | Y9: ='Data Ocupacion'!AV66 -> 0 | Z9: ='Data Ocupacion'!AX66 -> 0 | AA9: ='Data Ocupacion'!AZ66 -> 0 | AB9: ='Data Ocupacion'!BB66 -> 0 | AC9: ='Data Ocupacion'!BD66 -> 0 | AD9: ='Data Ocupacion'!BF66 -> 0 | AE9: ='Data Ocupacion'!BH66 -> 0 | AF9: ='Data Ocupacion'!BJ66 -> 0 | AG9: ='Data Ocupacion'!BL66 -> 0
A10: Servicios EB-PU | B10: 25.4 | C10: ='Data Ocupacion'!D67 -> 0 | D10: ='Data Ocupacion'!F67 -> 0 | E10: ='Data Ocupacion'!H67 -> 1 | F10: ='Data Ocupacion'!J67 -> 1 | G10: ='Data Ocupacion'!L67 -> 1 | H10: ='Data Ocupacion'!N67 -> 1 | I10: ='Data Ocupacion'!P67 -> 1 | J10: ='Data Ocupacion'!R67 -> 0 | K10: ='Data Ocupacion'!T67 -> 0 | L10: ='Data Ocupacion'!V67 -> 1 | M10: ='Data Ocupacion'!X67 -> 1 | N10: ='Data Ocupacion'!Z67 -> 1 | O10: ='Data Ocupacion'!AB67 -> 1 | P10: ='Data Ocupacion'!AD67 -> 1 | Q10: ='Data Ocupacion'!AF67 -> 0 | R10: ='Data Ocupacion'!AH67 -> 0 | S10: ='Data Ocupacion'!AJ67 -> 1 | T10: ='Data Ocupacion'!AL67 -> 1 | U10: ='Data Ocupacion'!AN67 -> 1 | V10: ='Data Ocupacion'!AP67 -> 1 | W10: ='Data Ocupacion'!AR67 -> 1 | X10: ='Data Ocupacion'!AT67 -> 0 | Y10: ='Data Ocupacion'!AV67 -> 0 | Z10: ='Data Ocupacion'!AX67 -> 1 | AA10: ='Data Ocupacion'!AZ67 -> 1 | AB10: ='Data Ocupacion'!BB67 -> 1 | AC10: ='Data Ocupacion'!BD67 -> 1 | AD10: ='Data Ocupacion'!BF67 -> 1 | AE10: ='Data Ocupacion'!BH67 -> 0 | AF10: ='Data Ocupacion'!BJ67 -> 0 | AG10: ='Data Ocupacion'!BL67 -> 1
A11: Servicios PU-ES | B11: 11.71
A12: Servicios ES-PU | B12: 11.71
A13: Servicios VM-LI | B13: 34.83 | C13: ='Data Ocupacion'!D70 -> 4 | D13: ='Data Ocupacion'!F70 -> 4
A14: Servicios VM-PU | B14: 8.3 | C14: ='Data Ocupacion'!D71 -> 2 | D14: ='Data Ocupacion'!F71 -> 2
A15: Servicios MI-SA | B15: 21.7 | M15: ='Data Ocupacion'!X72 -> 1 | AB15: ='Data Ocupacion'!BB72 -> 2
A16: Servicios SA-MI | B16: 21.7 | M16: ='Data Ocupacion'!X73 -> 4 | AB16: ='Data Ocupacion'!BB73 -> 3
A17: Servicios LI-PO | B17: 39.19 | AA17: ='Data Ocupacion'!AZ76 -> 9
A18: Servicios PO-LI | B18: 39.19 | AA18: ='Data Ocupacion'!AZ77 -> 9
A19: Servicios MI-LI | B19: 35.73 | M19: ='Data Ocupacion'!X74 -> 6 | AB19: ='Data Ocupacion'!BB74 -> 15
A20: Servicios LI-MI | B20: 35.73 | M20: ='Data Ocupacion'!X75 -> 12 | AB20: ='Data Ocupacion'!BB75 -> 16
A22: Trenes PU-LI | B22: 43.13 | C22: ='Data Ocupacion'!D80 -> 90 | D22: ='Data Ocupacion'!F80 -> 56 | E22: ='Data Ocupacion'!H80 -> 107 | F22: ='Data Ocupacion'!J80 -> 107 | G22: ='Data Ocupacion'!L80 -> 107 | H22: ='Data Ocupacion'!N80 -> 110 | I22: ='Data Ocupacion'!P80 -> 108 | J22: ='Data Ocupacion'!R80 -> 75 | K22: ='Data Ocupacion'!T80 -> 57 | L22: ='Data Ocupacion'!V80 -> 107 | M22: ='Data Ocupacion'!X80 -> 95 | N22: ='Data Ocupacion'!Z80 -> 108 | O22: ='Data Ocupacion'!AB80 -> 111 | P22: ='Data Ocupacion'!AD80 -> 111 | Q22: ='Data Ocupacion'!AF80 -> 75 | R22: ='Data Ocupacion'!AH80 -> 57 | S22: ='Data Ocupacion'!AJ80 -> 108 | T22: ='Data Ocupacion'!AL80 -> 109 | U22: ='Data Ocupacion'!AN80 -> 110 | V22: ='Data Ocupacion'!AP80 -> 111 | W22: ='Data Ocupacion'!AR80 -> 114 | X22: ='Data Ocupacion'!AT80 -> 75 | Y22: ='Data Ocupacion'!AV80 -> 57 | Z22: ='Data Ocupacion'!AX80 -> 111 | AA22: ='Data Ocupacion'!AZ80 -> 101 | AB22: ='Data Ocupacion'!BB80 -> 93 | AC22: ='Data Ocupacion'!BD80 -> 111 | AD22: ='Data Ocupacion'!BF80 -> 110 | AE22: ='Data Ocupacion'!BH80 -> 75 | AF22: ='Data Ocupacion'!BJ80 -> 57 | AG22: ='Data Ocupacion'!BL80 -> 115
A23: Trenes LI-PU | B23: 43.13 | C23: ='Data Ocupacion'!D81 -> 92 | D23: ='Data Ocupacion'!F81 -> 57 | E23: ='Data Ocupacion'!H81 -> 107 | F23: ='Data Ocupacion'!J81 -> 107 | G23: ='Data Ocupacion'!L81 -> 107 | H23: ='Data Ocupacion'!N81 -> 107 | I23: ='Data Ocupacion'!P81 -> 107 | J23: ='Data Ocupacion'!R81 -> 75 | K23: ='Data Ocupacion'!T81 -> 57 | L23: ='Data Ocupacion'!V81 -> 107 | M23: ='Data Ocupacion'!X81 -> 94 | N23: ='Data Ocupacion'!Z81 -> 108 | O23: ='Data Ocupacion'!AB81 -> 111 | P23: ='Data Ocupacion'!AD81 -> 111 | Q23: ='Data Ocupacion'!AF81 -> 75 | R23: ='Data Ocupacion'!AH81 -> 57 | S23: ='Data Ocupacion'!AJ81 -> 107 | T23: ='Data Ocupacion'!AL81 -> 109 | U23: ='Data Ocupacion'!AN81 -> 110 | V23: ='Data Ocupacion'!AP81 -> 109 | W23: ='Data Ocupacion'!AR81 -> 111 | X23: ='Data Ocupacion'!AT81 -> 75 | Y23: ='Data Ocupacion'!AV81 -> 57 | Z23: ='Data Ocupacion'!AX81 -> 111 | AA23: ='Data Ocupacion'!AZ81 -> 100 | AB23: ='Data Ocupacion'!BB81 -> 86 | AC23: ='Data Ocupacion'!BD81 -> 111 | AD23: ='Data Ocupacion'!BF81 -> 110 | AE23: ='Data Ocupacion'!BH81 -> 75 | AF23: ='Data Ocupacion'!BJ81 -> 57 | AG23: ='Data Ocupacion'!BL81 -> 110
A24: Trenes PU-SA | B24: 29.11 | C24: ='Data Ocupacion'!D82 -> 0 | D24: ='Data Ocupacion'!F82 -> 0 | E24: ='Data Ocupacion'!H82 -> 36 | F24: ='Data Ocupacion'!J82 -> 36 | G24: ='Data Ocupacion'!L82 -> 36 | H24: ='Data Ocupacion'!N82 -> 36 | I24: ='Data Ocupacion'!P82 -> 36 | J24: ='Data Ocupacion'!R82 -> 0 | K24: ='Data Ocupacion'!T82 -> 0 | L24: ='Data Ocupacion'!V82 -> 36 | M24: ='Data Ocupacion'!X82 -> 33 | N24: ='Data Ocupacion'!Z82 -> 36 | O24: ='Data Ocupacion'!AB82 -> 36 | P24: ='Data Ocupacion'!AD82 -> 36 | Q24: ='Data Ocupacion'!AF82 -> 0 | R24: ='Data Ocupacion'!AH82 -> 0 | S24: ='Data Ocupacion'!AJ82 -> 37 | T24: ='Data Ocupacion'!AL82 -> 37 | U24: ='Data Ocupacion'!AN82 -> 37 | V24: ='Data Ocupacion'!AP82 -> 37 | W24: ='Data Ocupacion'!AR82 -> 36 | X24: ='Data Ocupacion'!AT82 -> 0 | Y24: ='Data Ocupacion'!AV82 -> 0 | Z24: ='Data Ocupacion'!AX82 -> 37 | AA24: ='Data Ocupacion'!AZ82 -> 37 | AB24: ='Data Ocupacion'!BB82 -> 33 | AC24: ='Data Ocupacion'!BD82 -> 37 | AD24: ='Data Ocupacion'!BF82 -> 37 | AE24: ='Data Ocupacion'!BH82 -> 0 | AF24: ='Data Ocupacion'!BJ82 -> 0 | AG24: ='Data Ocupacion'!BL82 -> 37
A25: Trenes SA-PU | B25: 29.11 | C25: ='Data Ocupacion'!D83 -> 0 | D25: ='Data Ocupacion'!F83 -> 0 | E25: ='Data Ocupacion'!H83 -> 35 | F25: ='Data Ocupacion'!J83 -> 35 | G25: ='Data Ocupacion'!L83 -> 35 | H25: ='Data Ocupacion'!N83 -> 35 | I25: ='Data Ocupacion'!P83 -> 35 | J25: ='Data Ocupacion'!R83 -> 0 | K25: ='Data Ocupacion'!T83 -> 0 | L25: ='Data Ocupacion'!V83 -> 35 | M25: ='Data Ocupacion'!X83 -> 31 | N25: ='Data Ocupacion'!Z83 -> 35 | O25: ='Data Ocupacion'!AB83 -> 35 | P25: ='Data Ocupacion'!AD83 -> 35 | Q25: ='Data Ocupacion'!AF83 -> 0 | R25: ='Data Ocupacion'!AH83 -> 0 | S25: ='Data Ocupacion'!AJ83 -> 37 | T25: ='Data Ocupacion'!AL83 -> 36 | U25: ='Data Ocupacion'!AN83 -> 36 | V25: ='Data Ocupacion'!AP83 -> 36 | W25: ='Data Ocupacion'!AR83 -> 36 | X25: ='Data Ocupacion'!AT83 -> 0 | Y25: ='Data Ocupacion'!AV83 -> 0 | Z25: ='Data Ocupacion'!AX83 -> 36 | AA25: ='Data Ocupacion'!AZ83 -> 36 | AB25: ='Data Ocupacion'!BB83 -> 31 | AC25: ='Data Ocupacion'!BD83 -> 36 | AD25: ='Data Ocupacion'!BF83 -> 36 | AE25: ='Data Ocupacion'!BH83 -> 0 | AF25: ='Data Ocupacion'!BJ83 -> 0 | AG25: ='Data Ocupacion'!BL83 -> 37
A26: Trenes EB-PU | B26: 25.4 | C26: ='Data Ocupacion'!D85 -> 0 | D26: ='Data Ocupacion'!F85 -> 0 | E26: ='Data Ocupacion'!H85 -> 1 | F26: ='Data Ocupacion'!J85 -> 1 | G26: ='Data Ocupacion'!L85 -> 1 | H26: ='Data Ocupacion'!N85 -> 1 | I26: ='Data Ocupacion'!P85 -> 1 | J26: ='Data Ocupacion'!R85 -> 0 | K26: ='Data Ocupacion'!T85 -> 0 | L26: ='Data Ocupacion'!V85 -> 1 | M26: ='Data Ocupacion'!X85 -> 1 | N26: ='Data Ocupacion'!Z85 -> 1 | O26: ='Data Ocupacion'!AB85 -> 1 | P26: ='Data Ocupacion'!AD85 -> 1 | Q26: ='Data Ocupacion'!AF85 -> 0 | R26: ='Data Ocupacion'!AH85 -> 0 | S26: ='Data Ocupacion'!AJ85 -> 1 | T26: ='Data Ocupacion'!AL85 -> 1 | U26: ='Data Ocupacion'!AN85 -> 1 | V26: ='Data Ocupacion'!AP85 -> 1 | W26: ='Data Ocupacion'!AR85 -> 1 | X26: ='Data Ocupacion'!AT85 -> 0 | Y26: ='Data Ocupacion'!AV85 -> 0 | Z26: ='Data Ocupacion'!AX85 -> 1 | AA26: ='Data Ocupacion'!AZ85 -> 1 | AB26: ='Data Ocupacion'!BB85 -> 1 | AC26: ='Data Ocupacion'!BD85 -> 1 | AD26: ='Data Ocupacion'!BF85 -> 1 | AE26: ='Data Ocupacion'!BH85 -> 0 | AF26: ='Data Ocupacion'!BJ85 -> 0 | AG26: ='Data Ocupacion'!BL85 -> 1
A27: Trenes PU-EB | B27: 25.4 | C27: 0 | D27: 0 | E27: 0 | F27: 0 | G27: 0 | H27: 0 | I27: 0 | J27: 0 | K27: 0 | L27: 0 | M27: 0 | N27: 0 | O27: 0 | P27: 0 | Q27: 0 | R27: 0 | S27: 0 | T27: 0 | U27: 0 | V27: 0 | W27: 0 | X27: 0 | Y27: 0 | Z27: 0 | AA27: 0 | AB27: 0 | AC27: 0 | AD27: 0 | AE27: 0 | AF27: 0 | AG27: 0
A28: Trenes PU-ES | B28: 11.71
A29: Trenes ES-PU | B29: 11.71
A30: Trenes VM-LI | B30: 34.83 | C30: ='Data Ocupacion'!D88 -> 5 | D30: ='Data Ocupacion'!F88 -> 5
A31: Trenes VM-PU | B31: 8.3 | C31: ='Data Ocupacion'!D89 -> 2 | D31: ='Data Ocupacion'!F89 -> 2
A32: Trenes MI-SA | B32: 21.7 | M32: ='Data Ocupacion'!X90 -> 1 | AB32: ='Data Ocupacion'!BB90 -> 2
A33: Trenes SA-MI | B33: 21.7 | M33: ='Data Ocupacion'!X91 -> 4 | AB33: ='Data Ocupacion'!BB91 -> 4
A34: Trenes LI-PO | B34: 39.19 | AA34: ='Data Ocupacion'!AZ94 -> 10
A35: Trenes PO-LI | B35: 39.19 | AA35: ='Data Ocupacion'!AZ95 -> 10
A36: Trenes MI-LI | B36: 35.73 | M36: ='Data Ocupacion'!X92 -> 10 | AB36: ='Data Ocupacion'!BB92 -> 20
A37: Trenes LI-MI | B37: 35.73 | M37: ='Data Ocupacion'!X93 -> 14 | AB37: ='Data Ocupacion'!BB93 -> 21
A39: Corte EB (600) | B39: -17.73 | C39: ='KM-Servicio'!Q5 -> 0 | D39: ='KM-Servicio'!Q14 -> 0 | E39: ='KM-Servicio'!Q23 -> 1 | F39: ='KM-Servicio'!Q30 -> 2 | G39: ='KM-Servicio'!Q37 -> 2 | H39: ='KM-Servicio'!Q44 -> 1 | I39: ='KM-Servicio'!Q51 -> 1 | J39: ='KM-Servicio'!Q58 -> 0 | K39: ='KM-Servicio'!Q65 -> 0 | L39: ='KM-Servicio'!Q72 -> 2 | M39: ='KM-Servicio'!Q79 -> 0 | N39: ='KM-Servicio'!Q90 -> 3 | O39: ='KM-Servicio'!Q97 -> 3 | P39: ='KM-Servicio'!Q104 -> 0 | Q39: ='KM-Servicio'!Q111 -> 0 | R39: ='KM-Servicio'!Q118 -> 0 | S39: ='KM-Servicio'!Q125 -> 1 | T39: ='KM-Servicio'!Q132 -> 3 | U39: ='KM-Servicio'!Q139 -> 3 | V39: ='KM-Servicio'!Q146 -> 3 | W39: ='KM-Servicio'!Q153 -> 1 | X39: ='KM-Servicio'!Q160 -> 0 | Z39: ='KM-Servicio'!Q174 -> 3 | AA39: ='KM-Servicio'!Q181 -> 0 | AB39: ='KM-Servicio'!Q190 -> 0 | AC39: ='KM-Servicio'!Q201 -> 0 | AD39: ='KM-Servicio'!Q208 -> 0 | AE39: ='KM-Servicio'!Q215 -> 0 | AF39: ='KM-Servicio'!Q222 -> 0 | AG39: ='KM-Servicio'!Q229 -> 4
A40: Acople EB (600) | B40: -17.73 | C40: ='KM-Servicio'!T6 -> 4 | D40: ='KM-Servicio'!T15 -> 0 | E40: ='KM-Servicio'!T24 -> 0 | F40: ='KM-Servicio'!T31 -> 0 | G40: ='KM-Servicio'!T38 -> 0 | H40: ='KM-Servicio'!T45 -> 1 | I40: ='KM-Servicio'!T52 -> 0 | J40: ='KM-Servicio'!T59 -> 0 | K40: ='KM-Servicio'!T66 -> 0 | L40: ='KM-Servicio'!T73 -> 0 | M40: ='KM-Servicio'!T80 -> 0 | N40: ='KM-Servicio'!T91 -> 0 | O40: ='KM-Servicio'!T98 -> 0 | P40: ='KM-Servicio'!T105 -> 0 | Q40: ='KM-Servicio'!T112 -> 0 | R40: ='KM-Servicio'!T119 -> 0 | S40: ='KM-Servicio'!T126 -> 0 | T40: ='KM-Servicio'!T133 -> 0 | U40: ='KM-Servicio'!T140 -> 0 | V40: ='KM-Servicio'!T147 -> 0 | W40: ='KM-Servicio'!T154 -> 0 | X40: ='KM-Servicio'!T161 -> 0 | Y40: ='KM-Servicio'!T168 -> 0 | Z40: ='KM-Servicio'!T175 -> 0 | AA40: ='KM-Servicio'!T182 -> 0 | AB40: ='KM-Servicio'!T191 -> 0 | AC40: 0 | AD40: ='KM-Servicio'!T209 -> 0 | AE40: ='KM-Servicio'!T216 -> 0 | AF40: ='KM-Servicio'!T223 -> 0 | AG40: ='KM-Servicio'!T230 -> 0
A41: Acople/Corte SA (600) | B41: -14.02 | C41: ='KM-Servicio'!U6 -> 0 | D41: ='KM-Servicio'!U15 -> 0 | E41: ='KM-Servicio'!U24 -> 0 | F41: ='KM-Servicio'!U31 -> 0 | G41: ='KM-Servicio'!U38 -> 0 | H41: ='KM-Servicio'!U45 -> 0 | I41: ='KM-Servicio'!U52 -> 0 | J41: ='KM-Servicio'!U59 -> 0 | K41: ='KM-Servicio'!U66 -> 0 | L41: ='KM-Servicio'!U73 -> 0 | M41: ='KM-Servicio'!U80 -> 0 | N41: ='KM-Servicio'!U91 -> 0 | O41: ='KM-Servicio'!U98 -> 0 | P41: ='KM-Servicio'!U105 -> 0 | Q41: ='KM-Servicio'!U112 -> 0 | R41: ='KM-Servicio'!U119 -> 0 | S41: ='KM-Servicio'!U126 -> 0 | T41: ='KM-Servicio'!U133 -> 0 | U41: ='KM-Servicio'!U140 -> 0 | V41: ='KM-Servicio'!U147 -> 0 | W41: ='KM-Servicio'!U154 -> 0 | X41: ='KM-Servicio'!U161 -> 0 | Y41: ='KM-Servicio'!U168 -> 0 | Z41: ='KM-Servicio'!U175 -> 0 | AA41: ='KM-Servicio'!U182 -> 0 | AB41: ='KM-Servicio'!U191 -> 0 | AC41: ='KM-Servicio'!U202 -> 0 | AD41: ='KM-Servicio'!U209 -> 0 | AE41: ='KM-Servicio'!U216 -> 0 | AF41: ='KM-Servicio'!U223 -> 0 | AG41: ='KM-Servicio'!U230 -> 0
A42: Corte EB (400) | B42: -3.71 | E42: ='KM-Servicio'!Q25 -> 0 | G42: ='KM-Servicio'!Q39 -> 0 | N42: ='KM-Servicio'!Q92 -> 0
A43: Acople EB (600) vía 1 | B43: -25.4 | G43: 1 | H43: 3 | M43: 1 | N43: 3 | O43: 2 | P43: 1 | U43: 1 | V43: 2 | AC43: 4 | AD43: 3 | AG43: 5
...

Sheet UMR Resumen
A1: Marzo 2025
A2: Fecha | B2: Odómetro | C2: Odómetro acum. | D2: Tren-Km | E2: Tren-Km Acum. | F2: UMR Diario | G2: Viajes Programados | H2: Viajes Realizados | I2: IR | J2: Indice Regularidad (QU-via 2) 7:10am a 8:10am | K2: TKB (no TKBC) | L2: Tipo Dia | M2: Comentarios
A3: 45717 | B3: ='KM-Servicio'!N13 -> 8422 | C3: =B3 -> 8422 | D3: ='KM-Servicio'!W13 -> 7969.49 | E3: =D3 -> 7969.49 | F3: ='KM-Servicio'!O13 -> 94.627048 | G3: =SUM('KM-Servicio'!B13:C13) -> 153 | H3: =SUM('KM-Servicio'!D13:E13) -> 153 | K3: ='Oferta Diaria'!C53 -> 631980.56 | L3: Sábado
A4: 45718 | B4: ='KM-Servicio'!N22 -> 5211 | C4: =B4+C3 -> 13633 | D4: ='KM-Servicio'!W22 -> 5064.44 | E4: =D4+E3 -> 13033.93 | F4: ='KM-Servicio'!O22 -> 97.187488 | G4: =SUM('KM-Servicio'!B22:C22) -> 117 | H4: =SUM('KM-Servicio'!D22:E22) -> 117 | K4: ='Oferta Diaria'!D53 -> 401610.09 | L4: Dgo-Festivo
A5: 45719 | B5: ='KM-Servicio'!N29 -> 11744 | C5: =B5+C4 -> 25377 | D5: ='KM-Servicio'!W29 -> 11304.3 | E5: =D5+E4 -> 24338.23 | F5: ='KM-Servicio'!O29 -> 96.25596 | G5: =SUM('KM-Servicio'!B29:C29) -> 223 | H5: =SUM('KM-Servicio'!D29:E29) -> 223 | K5: ='Oferta Diaria'!E53 -> 896430.99 | L5: Laboral
A6: 45720 | B6: ='KM-Servicio'!N36 -> 11775 | C6: =B6+C5 -> 37152 | D6: ='KM-Servicio'!W36 -> 11286.57 | E6: =D6+E5 -> 35624.8 | F6: ='KM-Servicio'!O36 -> 95.851975 | G6: =SUM('KM-Servicio'!B36:C36) -> 223 | H6: =SUM('KM-Servicio'!D36:E36) -> 223 | K6: ='Oferta Diaria'!F53 -> 895025 | L6: Laboral
A7: 45721 | B7: ='KM-Servicio'!N43 -> 11732 | C7: =B7+C6 -> 48884 | D7: ='KM-Servicio'!W43 -> 11261.17 | E7: =D7+E6 -> 46885.97 | F7: ='KM-Servicio'!O43 -> 95.986788 | G7: =SUM('KM-Servicio'!B43:C43) -> 223 | H7: =SUM('KM-Servicio'!D43:E43) -> 223 | K7: ='Oferta Diaria'!G53 -> 893010.78 | L7: Laboral
A8: 45722 | B8: ='KM-Servicio'!N50 -> 11736 | C8: =B8+C7 -> 60620 | D8: ='KM-Servicio'!W50 -> 11339.76 | E8: =D8+E7 -> 58225.73 | F8: ='KM-Servicio'!O50 -> 96.623722 | G8: =SUM('KM-Servicio'!B50:C50) -> 223 | H8: =SUM('KM-Servicio'!D50:E50) -> 223 | K8: ='Oferta Diaria'!H53 -> 899242.97 | L8: Laboral
